File: data-files/mech3/WH13V.txt
""
"Test Method","Will_Huddleston_Disks.msm"
"Sample I. D.","WH13V.mss"
"Specimen Number","1"

"Load (N)","Time (s)","Extension (mm)","Stress (MPa)","Strain (mm/mm)"

4.52,0.200,-0.10494,0.695,-0.002
4.52,0.300,-0.10490,0.694,-0.002
4.52,0.400,-0.10490,0.695,-0.002
4.54,0.500,-0.10490,0.697,-0.002
4.54,0.600,-0.10485,0.698,-0.002
4.53,0.700,-0.10485,0.697,-0.002
4.53,0.800,-0.10485,0.696,-0.002
4.53,0.900,-0.10481,0.697,-0.002
4.54,1.000,-0.10481,0.698,-0.002
4.56,1.100,-0.10481,0.701,-0.002
4.55,1.200,-0.10477,0.699,-0.002
4.55,1.300,-0.10477,0.699,-0.002
4.55,1.400,-0.10473,0.699,-0.002
4.55,1.500,-0.10473,0.699,-0.002
4.57,1.600,-0.10473,0.702,-0.002
4.57,1.700,-0.10469,0.703,-0.002
4.61,1.800,-0.10465,0.708,-0.002
4.60,1.900,-0.10465,0.706,-0.002
4.62,2.000,-0.10460,0.709,-0.002
4.67,2.100,-0.10452,0.718,-0.002
4.80,2.200,-0.10440,0.737,-0.002
4.87,2.300,-0.10427,0.748,-0.002
5.00,2.400,-0.10406,0.769,-0.002
5.08,2.500,-0.10386,0.780,-0.002
5.20,2.600,-0.10365,0.799,-0.002
5.26,2.700,-0.10344,0.809,-0.002
5.34,2.800,-0.10327,0.821,-0.002
5.37,2.900,-0.10307,0.825,-0.002
5.43,3.000,-0.10286,0.834,-0.002
5.47,3.100,-0.10269,0.841,-0.002
5.53,3.200,-0.10248,0.849,-0.002
5.56,3.300,-0.10232,0.854,-0.002
5.62,3.400,-0.10211,0.863,-0.002
5.67,3.500,-0.10194,0.872,-0.002
5.73,3.600,-0.10174,0.880,-0.002
5.75,3.700,-0.10157,0.883,-0.002
5.77,3.800,-0.10140,0.886,-0.002
5.82,3.900,-0.10124,0.894,-0.002
5.86,4.000,-0.10107,0.901,-0.002
5.88,4.100,-0.10095,0.904,-0.002
5.92,4.200,-0.10078,0.910,-0.002
5.93,4.300,-0.10066,0.911,-0.002
5.96,4.400,-0.10049,0.916,-0.002
6.01,4.500,-0.10037,0.924,-0.002
6.04,4.600,-0.10020,0.929,-0.002
6.09,4.700,-0.10007,0.936,-0.002
6.11,4.800,-0.09991,0.939,-0.002
6.17,4.900,-0.09978,0.949,-0.002
6.18,5.000,-0.09966,0.950,-0.002
6.21,5.100,-0.09953,0.955,-0.002
6.23,5.200,-0.09941,0.957,-0.002
6.27,5.300,-0.09924,0.963,-0.002
6.30,5.400,-0.09912,0.967,-0.002
6.33,5.500,-0.09899,0.972,-0.002
6.35,5.600,-0.09887,0.976,-0.002
6.40,5.700,-0.09870,0.983,-0.002
6.42,5.800,-0.09858,0.987,-0.002
6.46,5.900,-0.09841,0.993,-0.002
6.48,6.000,-0.09829,0.996,-0.002
6.51,6.100,-0.09812,1.000,-0.002
6.54,6.200,-0.09800,1.006,-0.002
6.59,6.300,-0.09783,1.012,-0.002
6.60,6.400,-0.09771,1.014,-0.002
6.67,6.500,-0.09754,1.026,-0.002
6.67,6.600,-0.09737,1.025,-0.002
6.72,6.700,-0.09725,1.033,-0.002
6.77,6.800,-0.09708,1.040,-0.002
6.80,6.900,-0.09692,1.045,-0.002
6.83,7.000,-0.09679,1.049,-0.002
6.89,7.100,-0.09663,1.058,-0.002
6.92,7.200,-0.09646,1.063,-0.002
6.96,7.300,-0.09633,1.069,-0.002
6.98,7.400,-0.09617,1.073,-0.002
7.02,7.500,-0.09600,1.078,-0.002
7.06,7.600,-0.09584,1.085,-0.002
7.12,7.700,-0.09567,1.095,-0.002
7.16,7.800,-0.09546,1.100,-0.002
7.20,7.900,-0.09530,1.106,-0.002
7.26,8.000,-0.09509,1.116,-0.002
7.30,8.100,-0.09488,1.121,-0.002
7.36,8.200,-0.09467,1.131,-0.002
7.40,8.300,-0.09446,1.138,-0.002
7.46,8.400,-0.09426,1.147,-0.002
7.53,8.500,-0.09405,1.157,-0.002
7.58,8.600,-0.09384,1.165,-0.002
7.63,8.700,-0.09359,1.173,-0.002
7.69,8.800,-0.09338,1.182,-0.002
7.73,8.900,-0.09318,1.188,-0.002
7.78,9.000,-0.09297,1.195,-0.002
7.85,9.100,-0.09276,1.207,-0.002
7.88,9.200,-0.09259,1.211,-0.002
7.94,9.300,-0.09239,1.220,-0.002
7.99,9.400,-0.09218,1.228,-0.002
8.00,9.500,-0.09201,1.229,-0.002
8.05,9.600,-0.09185,1.237,-0.002
8.10,9.700,-0.09168,1.245,-0.002
8.14,9.800,-0.09151,1.251,-0.002
8.18,9.900,-0.09135,1.257,-0.002
8.23,10.000,-0.09122,1.265,-0.002
8.25,10.100,-0.09106,1.268,-0.002
8.30,10.200,-0.09093,1.275,-0.002
8.32,10.300,-0.09077,1.279,-0.002
8.35,10.400,-0.09064,1.283,-0.002
8.38,10.500,-0.09052,1.288,-0.002
8.42,10.600,-0.09035,1.294,-0.002
8.47,10.700,-0.09023,1.301,-0.002
8.49,10.800,-0.09010,1.305,-0.002
8.53,10.900,-0.08998,1.310,-0.002
8.57,11.000,-0.08981,1.317,-0.002
8.61,11.100,-0.08969,1.323,-0.002
8.64,11.200,-0.08956,1.328,-0.002
8.70,11.300,-0.08944,1.336,-0.002
8.74,11.400,-0.08927,1.342,-0.002
8.76,11.500,-0.08915,1.346,-0.002
8.80,11.600,-0.08898,1.352,-0.002
8.85,11.700,-0.08885,1.361,-0.002
8.91,11.800,-0.08869,1.369,-0.002
8.94,11.900,-0.08852,1.373,-0.002
8.97,12.000,-0.08840,1.378,-0.002
9.02,12.100,-0.08823,1.386,-0.002
9.07,12.200,-0.08811,1.393,-0.002
9.10,12.300,-0.08794,1.399,-0.002
9.13,12.400,-0.08777,1.403,-0.002
9.20,12.500,-0.08765,1.413,-0.002
9.25,12.600,-0.08748,1.421,-0.002
9.27,12.700,-0.08732,1.424,-0.002
9.34,12.800,-0.08715,1.435,-0.002
9.38,12.900,-0.08703,1.442,-0.002
9.44,13.000,-0.08686,1.450,-0.002
9.49,13.100,-0.08669,1.459,-0.002
9.53,13.200,-0.08653,1.464,-0.002
9.59,13.300,-0.08636,1.473,-0.002
9.63,13.400,-0.08619,1.480,-0.002
9.68,13.500,-0.08603,1.488,-0.002
9.76,13.600,-0.08582,1.499,-0.002
9.80,13.700,-0.08561,1.506,-0.002
9.89,13.800,-0.08541,1.519,-0.002
9.95,13.900,-0.08524,1.528,-0.002
9.99,14.000,-0.08503,1.535,-0.002
10.07,14.100,-0.08482,1.547,-0.002
10.14,14.200,-0.08457,1.558,-0.002
10.21,14.300,-0.08437,1.569,-0.002
10.26,14.400,-0.08416,1.577,-0.002
10.33,14.500,-0.08395,1.587,-0.002
10.38,14.600,-0.08374,1.596,-0.002
10.45,14.700,-0.08358,1.605,-0.002
10.52,14.800,-0.08337,1.616,-0.002
10.56,14.900,-0.08316,1.622,-0.002
10.63,15.000,-0.08295,1.633,-0.002
10.68,15.100,-0.08279,1.641,-0.002
10.76,15.200,-0.08262,1.653,-0.002
10.78,15.300,-0.08245,1.657,-0.002
10.83,15.400,-0.08229,1.664,-0.002
10.90,15.500,-0.08212,1.675,-0.002
10.93,15.600,-0.08196,1.679,-0.002
10.99,15.700,-0.08183,1.689,-0.002
11.02,15.800,-0.08167,1.694,-0.002
11.08,15.900,-0.08150,1.703,-0.002
11.12,16.000,-0.08137,1.708,-0.002
11.17,16.100,-0.08125,1.717,-0.002
11.22,16.200,-0.08108,1.723,-0.002
11.26,16.300,-0.08096,1.730,-0.002
11.29,16.400,-0.08083,1.734,-0.002
11.34,16.500,-0.08067,1.742,-0.002
11.37,16.600,-0.08054,1.748,-0.002
11.40,16.700,-0.08042,1.751,-0.002
11.47,16.800,-0.08029,1.763,-0.002
11.51,16.900,-0.08013,1.769,-0.002
11.56,17.000,-0.08000,1.777,-0.002
11.61,17.100,-0.07988,1.783,-0.002
11.64,17.200,-0.07971,1.789,-0.002
11.72,17.300,-0.07959,1.800,-0.002
11.76,17.400,-0.07942,1.807,-0.002
11.84,17.500,-0.07930,1.819,-0.002
11.87,17.600,-0.07913,1.823,-0.002
11.92,17.700,-0.07901,1.831,-0.002
11.99,17.800,-0.07884,1.842,-0.002
12.04,17.900,-0.07867,1.849,-0.002
12.10,18.000,-0.07855,1.859,-0.002
12.15,18.100,-0.07838,1.868,-0.002
12.20,18.200,-0.07822,1.875,-0.002
12.26,18.300,-0.07805,1.884,-0.002
12.30,18.400,-0.07793,1.890,-0.002
12.36,18.500,-0.07776,1.899,-0.002
12.43,18.600,-0.07759,1.910,-0.002
12.47,18.700,-0.07743,1.916,-0.002
12.54,18.800,-0.07726,1.928,-0.002
12.59,18.900,-0.07714,1.935,-0.002
12.67,19.000,-0.07697,1.946,-0.002
12.72,19.100,-0.07676,1.954,-0.002
12.78,19.200,-0.07660,1.963,-0.002
12.84,19.300,-0.07643,1.973,-0.002
12.94,19.400,-0.07622,1.988,-0.002
13.00,19.500,-0.07601,1.998,-0.001
13.06,19.600,-0.07585,2.007,-0.001
13.14,19.700,-0.07564,2.019,-0.001
13.23,19.800,-0.07543,2.033,-0.001
13.31,19.900,-0.07522,2.046,-0.001
13.40,20.000,-0.07502,2.059,-0.001
13.46,20.100,-0.07481,2.069,-0.001
13.56,20.200,-0.07460,2.084,-0.001
13.64,20.300,-0.07439,2.096,-0.001
13.69,20.400,-0.07419,2.104,-0.001
13.78,20.500,-0.07402,2.117,-0.001
13.85,20.600,-0.07381,2.128,-0.001
13.93,20.700,-0.07360,2.141,-0.001
14.02,20.800,-0.07344,2.154,-0.001
14.08,20.900,-0.07323,2.164,-0.001
14.13,21.000,-0.07306,2.171,-0.001
14.20,21.100,-0.07290,2.182,-0.001
14.26,21.200,-0.07273,2.191,-0.001
14.31,21.300,-0.07256,2.199,-0.001
14.37,21.400,-0.07240,2.208,-0.001
14.44,21.500,-0.07223,2.219,-0.001
14.49,21.600,-0.07211,2.227,-0.001
14.54,21.700,-0.07194,2.234,-0.001
14.61,21.800,-0.07182,2.245,-0.001
14.65,21.900,-0.07165,2.251,-0.001
14.72,22.000,-0.07153,2.262,-0.001
14.79,22.100,-0.07140,2.273,-0.001
14.82,22.200,-0.07128,2.278,-0.001
14.91,22.300,-0.07111,2.291,-0.001
14.95,22.400,-0.07099,2.297,-0.001
15.01,22.500,-0.07086,2.306,-0.001
15.07,22.600,-0.07069,2.316,-0.001
15.12,22.700,-0.07057,2.324,-0.001
15.18,22.800,-0.07045,2.332,-0.001
15.23,22.900,-0.07028,2.341,-0.001
15.30,23.000,-0.07015,2.351,-0.001
15.36,23.100,-0.06999,2.360,-0.001
15.44,23.200,-0.06986,2.373,-0.001
15.49,23.300,-0.06970,2.381,-0.001
15.54,23.400,-0.06957,2.388,-0.001
15.61,23.500,-0.06941,2.399,-0.001
15.67,23.600,-0.06928,2.409,-0.001
15.74,23.700,-0.06912,2.419,-0.001
15.80,23.800,-0.06895,2.428,-0.001
15.87,23.900,-0.06882,2.439,-0.001
15.94,24.000,-0.06866,2.450,-0.001
16.00,24.100,-0.06849,2.459,-0.001
16.08,24.200,-0.06837,2.471,-0.001
16.13,24.300,-0.06820,2.479,-0.001
16.23,24.400,-0.06804,2.494,-0.001
16.28,24.500,-0.06787,2.502,-0.001
16.35,24.600,-0.06774,2.513,-0.001
16.43,24.700,-0.06758,2.525,-0.001
16.51,24.800,-0.06741,2.536,-0.001
16.58,24.900,-0.06725,2.548,-0.001
16.68,25.000,-0.06704,2.563,-0.001
16.76,25.100,-0.06687,2.576,-0.001
16.84,25.200,-0.06666,2.588,-0.001
16.93,25.300,-0.06650,2.601,-0.001
17.03,25.400,-0.06629,2.616,-0.001
17.12,25.500,-0.06608,2.631,-0.001
17.23,25.600,-0.06587,2.648,-0.001
17.32,25.700,-0.06562,2.661,-0.001
17.41,25.800,-0.06542,2.675,-0.001
17.51,25.900,-0.06521,2.691,-0.001
17.60,26.000,-0.06500,2.705,-0.001
17.70,26.100,-0.06479,2.720,-0.001
17.79,26.200,-0.06459,2.734,-0.001
17.90,26.300,-0.06438,2.751,-0.001
18.00,26.400,-0.06417,2.766,-0.001
18.10,26.500,-0.06400,2.781,-0.001
18.19,26.600,-0.06380,2.795,-0.001
18.28,26.700,-0.06363,2.809,-0.001
18.34,26.800,-0.06346,2.819,-0.001
18.43,26.900,-0.06330,2.832,-0.001
18.50,27.000,-0.06313,2.843,-0.001
18.58,27.100,-0.06297,2.855,-0.001
18.63,27.200,-0.06284,2.863,-0.001
18.71,27.300,-0.06267,2.876,-0.001
18.79,27.400,-0.06255,2.887,-0.001
18.87,27.500,-0.06238,2.900,-0.001
18.94,27.600,-0.06226,2.911,-0.001
19.00,27.700,-0.06209,2.920,-0.001
19.07,27.800,-0.06197,2.931,-0.001
19.15,27.900,-0.06184,2.943,-0.001
19.21,28.000,-0.06172,2.952,-0.001
19.27,28.100,-0.06155,2.961,-0.001
19.35,28.200,-0.06143,2.973,-0.001
19.42,28.300,-0.06130,2.985,-0.001
19.49,28.400,-0.06114,2.996,-0.001
19.57,28.500,-0.06101,3.008,-0.001
19.65,28.600,-0.06089,3.019,-0.001
19.73,28.700,-0.06072,3.032,-0.001
19.80,28.800,-0.06060,3.043,-0.001
19.85,28.900,-0.06043,3.051,-0.001
19.94,29.000,-0.06031,3.065,-0.001
20.03,29.100,-0.06014,3.078,-0.001
20.11,29.200,-0.05997,3.089,-0.001
20.18,29.300,-0.05981,3.102,-0.001
20.28,29.400,-0.05968,3.116,-0.001
20.33,29.500,-0.05952,3.125,-0.001
20.42,29.600,-0.05935,3.138,-0.001
20.51,29.700,-0.05918,3.151,-0.001
20.59,29.800,-0.05906,3.164,-0.001
20.67,29.900,-0.05889,3.177,-0.001
20.76,30.000,-0.05873,3.190,-0.001
20.84,30.100,-0.05856,3.203,-0.001
20.94,30.200,-0.05839,3.218,-0.001
21.02,30.300,-0.05823,3.231,-0.001
21.11,30.400,-0.05806,3.244,-0.001
21.20,30.500,-0.05785,3.258,-0.001
21.31,30.600,-0.05769,3.275,-0.001
21.41,30.700,-0.05752,3.290,-0.001
21.52,30.800,-0.05731,3.307,-0.001
21.63,30.900,-0.05711,3.324,-0.001
21.73,31.000,-0.05690,3.340,-0.001
21.88,31.100,-0.05669,3.363,-0.001
21.99,31.200,-0.05648,3.379,-0.001
22.11,31.300,-0.05627,3.398,-0.001
22.27,31.400,-0.05603,3.422,-0.001
22.39,31.500,-0.05582,3.441,-0.001
22.51,31.600,-0.05561,3.459,-0.001
22.64,31.700,-0.05540,3.479,-0.001
22.74,31.800,-0.05519,3.495,-0.001
22.86,31.900,-0.05499,3.513,-0.001
23.00,32.000,-0.05478,3.534,-0.001
23.09,32.100,-0.05457,3.549,-0.001
23.20,32.200,-0.05436,3.565,-0.001
23.31,32.300,-0.05420,3.581,-0.001
23.40,32.400,-0.05403,3.596,-0.001
23.49,32.500,-0.05386,3.610,-0.001
23.57,32.600,-0.05370,3.623,-0.001
23.66,32.700,-0.05353,3.636,-0.001
23.76,32.800,-0.05337,3.651,-0.001
23.85,32.900,-0.05324,3.666,-0.001
23.93,33.000,-0.05307,3.677,-0.001
24.01,33.100,-0.05295,3.690,-0.001
24.09,33.200,-0.05278,3.701,-0.001
24.17,33.300,-0.05266,3.715,-0.001
24.27,33.400,-0.05249,3.729,-0.001
24.37,33.500,-0.05237,3.744,-0.001
24.41,33.600,-0.05224,3.751,-0.001
24.51,33.700,-0.05208,3.766,-0.001
24.59,33.800,-0.05195,3.778,-0.001
24.69,33.900,-0.05183,3.794,-0.001
24.78,34.000,-0.05166,3.808,-0.001
24.86,34.100,-0.05154,3.821,-0.001
24.94,34.200,-0.05137,3.832,-0.001
25.04,34.300,-0.05125,3.848,-0.001
25.14,34.400,-0.05108,3.862,-0.001
25.22,34.500,-0.05091,3.875,-0.001
25.31,34.600,-0.05079,3.890,-0.001
25.41,34.700,-0.05062,3.905,-0.001
25.50,34.800,-0.05046,3.918,-0.001
25.60,34.900,-0.05029,3.933,-0.001
25.71,35.000,-0.05017,3.951,-0.001
25.79,35.100,-0.05000,3.964,-0.001
25.89,35.200,-0.04983,3.979,-0.001
26.00,35.300,-0.04967,3.996,-0.001
26.08,35.400,-0.04954,4.008,-0.001
26.18,35.500,-0.04938,4.024,-0.001
26.30,35.600,-0.04921,4.042,-0.001
26.39,35.700,-0.04904,4.055,-0.001
26.51,35.800,-0.04888,4.074,-0.001
26.62,35.900,-0.04871,4.090,-0.001
26.72,36.000,-0.04855,4.106,-0.001
26.84,36.100,-0.04838,4.124,-0.001
26.96,36.200,-0.04821,4.143,-0.001
27.09,36.300,-0.04801,4.162,-0.001
27.22,36.400,-0.04780,4.183,-0.001
27.35,36.500,-0.04763,4.203,-0.001
27.48,36.600,-0.04742,4.223,-0.001
27.64,36.700,-0.04722,4.247,-0.001
27.78,36.800,-0.04697,4.269,-0.001
27.95,36.900,-0.04676,4.296,-0.001
28.07,37.000,-0.04655,4.314,-0.001
28.22,37.100,-0.04634,4.336,-0.001
28.35,37.200,-0.04614,4.357,-0.001
28.49,37.300,-0.04593,4.378,-0.001
28.62,37.400,-0.04572,4.398,-0.001
28.75,37.500,-0.04551,4.417,-0.001
28.91,37.600,-0.04535,4.443,-0.001
29.02,37.700,-0.04514,4.459,-0.001
29.14,37.800,-0.04497,4.478,-0.001
29.25,37.900,-0.04476,4.495,-0.001
29.36,38.000,-0.04460,4.511,-0.001
29.46,38.100,-0.04443,4.526,-0.001
29.55,38.200,-0.04427,4.542,-0.001
29.64,38.300,-0.04410,4.555,-0.001
29.76,38.400,-0.04397,4.573,-0.001
29.84,38.500,-0.04381,4.585,-0.001
29.98,38.600,-0.04368,4.607,-0.001
30.07,38.700,-0.04352,4.621,-0.001
30.16,38.800,-0.04339,4.634,-0.001
30.25,38.900,-0.04323,4.648,-0.001
30.33,39.000,-0.04310,4.661,-0.001
30.43,39.100,-0.04298,4.676,-0.001
30.53,39.200,-0.04281,4.692,-0.001
30.63,39.300,-0.04269,4.707,-0.001
30.71,39.400,-0.04256,4.719,-0.001
30.80,39.500,-0.04244,4.733,-0.001
30.91,39.600,-0.04227,4.750,-0.001
31.00,39.700,-0.04215,4.764,-0.001
31.09,39.800,-0.04202,4.778,-0.001
31.19,39.900,-0.04185,4.793,-0.001
31.30,40.000,-0.04173,4.810,-0.001
31.41,40.100,-0.04161,4.827,-0.001
31.52,40.200,-0.04144,4.844,-0.001
31.61,40.300,-0.04131,4.858,-0.001
31.71,40.400,-0.04115,4.872,-0.001
31.83,40.500,-0.04098,4.892,-0.001
31.95,40.600,-0.04086,4.910,-0.001
32.04,40.700,-0.04069,4.924,-0.001
32.19,40.800,-0.04053,4.946,-0.001
32.37,40.900,-0.04040,4.975,-0.001
32.43,41.000,-0.04023,4.983,-0.001
32.55,41.100,-0.04007,5.001,-0.001
32.63,41.200,-0.03990,5.014,-0.001
32.77,41.300,-0.03978,5.036,-0.001
32.89,41.400,-0.03961,5.054,-0.001
33.01,41.500,-0.03944,5.073,-0.001
33.12,41.600,-0.03928,5.090,-0.001
33.27,41.700,-0.03911,5.112,-0.001
33.38,41.800,-0.03895,5.129,-0.001
33.53,41.900,-0.03878,5.153,-0.001
33.68,42.000,-0.03857,5.176,-0.001
33.79,42.100,-0.03841,5.193,-0.001
33.95,42.200,-0.03820,5.218,-0.001
34.11,42.300,-0.03799,5.241,-0.001
34.25,42.400,-0.03782,5.263,-0.001
34.42,42.500,-0.03757,5.289,-0.001
34.62,42.600,-0.03737,5.320,-0.001
34.76,42.700,-0.03716,5.341,-0.001
34.91,42.800,-0.03695,5.365,-0.001
35.09,42.900,-0.03674,5.392,-0.001
35.22,43.000,-0.03654,5.412,-0.001
35.40,43.100,-0.03633,5.439,-0.001
35.55,43.200,-0.03612,5.463,-0.001
35.69,43.300,-0.03591,5.484,-0.001
35.85,43.400,-0.03575,5.509,-0.001
35.96,43.500,-0.03554,5.526,-0.001
36.10,43.600,-0.03537,5.547,-0.001
36.24,43.700,-0.03521,5.569,-0.001
36.34,43.800,-0.03500,5.584,-0.001
36.44,43.900,-0.03483,5.600,-0.001
36.55,44.000,-0.03471,5.616,-0.001
36.64,44.100,-0.03454,5.630,-0.001
36.76,44.200,-0.03437,5.649,-0.001
36.87,44.300,-0.03425,5.666,-0.001
36.98,44.400,-0.03408,5.682,-0.001
37.07,44.500,-0.03396,5.697,-0.001
37.15,44.600,-0.03383,5.709,-0.001
37.25,44.700,-0.03371,5.723,-0.001
37.35,44.800,-0.03354,5.739,-0.001
37.47,44.900,-0.03342,5.758,-0.001
37.54,45.000,-0.03329,5.768,-0.001
37.65,45.100,-0.03317,5.785,-0.001
37.77,45.200,-0.03300,5.803,-0.001
37.89,45.300,-0.03288,5.823,-0.001
37.98,45.400,-0.03275,5.837,-0.001
38.08,45.500,-0.03259,5.852,-0.001
38.22,45.600,-0.03246,5.873,-0.001
38.37,45.700,-0.03230,5.896,-0.001
38.47,45.800,-0.03217,5.912,-0.001
38.59,45.900,-0.03201,5.930,-0.001
38.70,46.000,-0.03188,5.947,-0.001
38.83,46.100,-0.03172,5.967,-0.001
38.92,46.200,-0.03155,5.981,-0.001
39.06,46.300,-0.03142,6.003,-0.001
39.15,46.400,-0.03126,6.016,-0.001
39.29,46.500,-0.03109,6.037,-0.001
39.44,46.600,-0.03097,6.061,-0.001
39.54,46.700,-0.03080,6.076,-0.001
39.67,46.800,-0.03063,6.096,-0.001
39.80,46.900,-0.03047,6.115,-0.001
39.94,47.000,-0.03030,6.137,-0.001
40.06,47.100,-0.03018,6.156,-0.001
40.16,47.200,-0.03001,6.172,-0.001
40.31,47.300,-0.02985,6.195,-0.001
40.43,47.400,-0.02968,6.213,-0.001
40.56,47.500,-0.02951,6.232,-0.001
40.73,47.600,-0.02930,6.259,-0.001
40.85,47.700,-0.02914,6.277,-0.001
41.00,47.800,-0.02893,6.300,-0.001
41.17,47.900,-0.02876,6.327,-0.001
41.32,48.000,-0.02856,6.350,-0.001
41.48,48.100,-0.02835,6.374,-0.001
41.64,48.200,-0.02814,6.398,-0.001
41.75,48.300,-0.02793,6.415,-0.001
41.90,48.400,-0.02773,6.439,-0.001
42.04,48.500,-0.02752,6.461,-0.001
42.10,48.600,-0.02731,6.470,-0.001
42.20,48.700,-0.02710,6.485,-0.001
42.25,48.800,-0.02689,6.492,-0.001
42.32,48.900,-0.02669,6.504,-0.001
42.40,49.000,-0.02648,6.516,-0.001
42.55,49.100,-0.02627,6.538,-0.001
42.66,49.200,-0.02611,6.555,-0.001
42.82,49.300,-0.02590,6.580,-0.001
42.97,49.400,-0.02573,6.604,-0.001
43.10,49.500,-0.02556,6.624,-0.001
43.22,49.600,-0.02536,6.641,0.000
43.32,49.700,-0.02523,6.656,0.000
43.42,49.800,-0.02507,6.673,0.000
43.53,49.900,-0.02490,6.689,0.000
43.62,50.000,-0.02478,6.703,0.000
43.75,50.100,-0.02461,6.723,0.000
43.86,50.200,-0.02448,6.740,0.000
43.95,50.300,-0.02432,6.754,0.000
44.06,50.400,-0.02419,6.771,0.000
44.19,50.500,-0.02407,6.790,0.000
44.29,50.600,-0.02394,6.806,0.000
44.41,50.700,-0.02378,6.824,0.000
44.49,50.800,-0.02365,6.836,0.000
44.58,50.900,-0.02353,6.851,0.000
44.71,51.000,-0.02340,6.870,0.000
44.84,51.100,-0.02328,6.891,0.000
44.95,51.200,-0.02311,6.908,0.000
45.06,51.300,-0.02299,6.924,0.000
45.16,51.400,-0.02282,6.940,0.000
45.28,51.500,-0.02270,6.958,0.000
45.40,51.600,-0.02253,6.977,0.000
45.51,51.700,-0.02241,6.993,0.000
45.62,51.800,-0.02224,7.011,0.000
45.75,51.900,-0.02212,7.030,0.000
45.91,52.000,-0.02195,7.055,0.000
46.00,52.100,-0.02178,7.068,0.000
46.13,52.200,-0.02166,7.089,0.000
46.19,52.300,-0.02149,7.097,0.000
46.29,52.400,-0.02133,7.113,0.000
46.41,52.500,-0.02120,7.132,0.000
46.56,52.600,-0.02104,7.154,0.000
46.66,52.700,-0.02087,7.171,0.000
46.79,52.800,-0.02070,7.189,0.000
46.88,52.900,-0.02054,7.203,0.000
47.02,53.000,-0.02041,7.225,0.000
47.18,53.100,-0.02020,7.250,0.000
47.29,53.200,-0.02004,7.267,0.000
47.44,53.300,-0.01987,7.291,0.000
47.60,53.400,-0.01971,7.315,0.000
47.74,53.500,-0.01950,7.336,0.000
47.90,53.600,-0.01933,7.361,0.000
48.06,53.700,-0.01912,7.385,0.000
48.24,53.800,-0.01892,7.413,0.000
48.40,53.900,-0.01871,7.438,0.000
48.60,54.000,-0.01850,7.468,0.000
48.76,54.100,-0.01829,7.493,0.000
48.94,54.200,-0.01808,7.520,0.000
49.12,54.300,-0.01788,7.548,0.000
49.25,54.400,-0.01767,7.568,0.000
49.47,54.500,-0.01746,7.602,0.000
49.61,54.600,-0.01725,7.624,0.000
49.77,54.700,-0.01705,7.647,0.000
49.93,54.800,-0.01684,7.672,0.000
50.08,54.900,-0.01667,7.696,0.000
50.24,55.000,-0.01651,7.721,0.000
50.36,55.100,-0.01630,7.738,0.000
50.49,55.200,-0.01613,7.759,0.000
50.62,55.300,-0.01597,7.778,0.000
50.74,55.400,-0.01584,7.798,0.000
50.86,55.500,-0.01567,7.815,0.000
51.01,55.600,-0.01551,7.838,0.000
51.12,55.700,-0.01538,7.855,0.000
51.21,55.800,-0.01522,7.870,0.000
51.34,55.900,-0.01509,7.890,0.000
51.45,56.000,-0.01493,7.906,0.000
51.56,56.100,-0.01480,7.923,0.000
51.69,56.200,-0.01468,7.943,0.000
51.79,56.300,-0.01451,7.958,0.000
51.89,56.400,-0.01439,7.973,0.000
52.01,56.500,-0.01426,7.993,0.000
52.12,56.600,-0.01410,8.009,0.000
52.24,56.700,-0.01397,8.027,0.000
52.35,56.800,-0.01385,8.045,0.000
52.48,56.900,-0.01372,8.064,0.000
52.61,57.000,-0.01356,8.084,0.000
52.72,57.100,-0.01343,8.102,0.000
52.82,57.200,-0.01326,8.116,0.000
52.96,57.300,-0.01314,8.138,0.000
53.03,57.400,-0.01297,8.149,0.000
53.21,57.500,-0.01285,8.177,0.000
53.32,57.600,-0.01268,8.193,0.000
53.43,57.700,-0.01252,8.210,0.000
53.56,57.800,-0.01239,8.230,0.000
53.70,57.900,-0.01223,8.251,0.000
53.82,58.000,-0.01206,8.270,0.000
53.92,58.100,-0.01193,8.286,0.000
54.05,58.200,-0.01177,8.306,0.000
54.18,58.300,-0.01160,8.325,0.000
54.30,58.400,-0.01148,8.344,0.000
54.45,58.500,-0.01131,8.367,0.000
54.56,58.600,-0.01115,8.384,0.000
54.68,58.700,-0.01098,8.403,0.000
54.83,58.800,-0.01081,8.426,0.000
54.98,58.900,-0.01065,8.449,0.000
55.10,59.000,-0.01048,8.467,0.000
55.25,59.100,-0.01031,8.490,0.000
55.43,59.200,-0.01011,8.517,0.000
55.63,59.300,-0.00990,8.548,0.000
55.75,59.400,-0.00973,8.566,0.000
55.99,59.500,-0.00948,8.604,0.000
56.18,59.600,-0.00928,8.633,0.000
56.35,59.700,-0.00907,8.659,0.000
56.58,59.800,-0.00886,8.694,0.000
56.75,59.900,-0.00861,8.720,0.000
56.93,60.000,-0.00840,8.748,0.000
57.10,60.100,-0.00819,8.774,0.000
57.29,60.200,-0.00799,8.803,0.000
57.44,60.300,-0.00778,8.827,0.000
57.63,60.400,-0.00757,8.855,0.000
57.72,60.500,-0.00741,8.869,0.000
57.92,60.600,-0.00720,8.900,0.000
58.07,60.700,-0.00703,8.924,0.000
58.18,60.800,-0.00686,8.941,0.000
58.32,60.900,-0.00670,8.962,0.000
58.45,61.000,-0.00653,8.982,0.000
58.55,61.100,-0.00637,8.997,0.000
58.67,61.200,-0.00624,9.015,0.000
58.82,61.300,-0.00608,9.039,0.000
58.90,61.400,-0.00595,9.052,0.000
59.00,61.500,-0.00578,9.066,0.000
59.12,61.600,-0.00566,9.085,0.000
59.21,61.700,-0.00549,9.098,0.000
59.33,61.800,-0.00537,9.117,0.000
59.43,61.900,-0.00524,9.132,0.000
59.54,62.000,-0.00512,9.150,0.000
59.65,62.100,-0.00495,9.166,0.000
59.75,62.200,-0.00483,9.181,0.000
59.84,62.300,-0.00470,9.195,0.000
59.94,62.400,-0.00458,9.211,0.000
60.07,62.500,-0.00441,9.231,0.000
60.16,62.600,-0.00429,9.245,0.000
60.29,62.700,-0.00412,9.264,0.000
60.40,62.800,-0.00400,9.282,0.000
60.51,62.900,-0.00387,9.298,0.000
60.60,63.000,-0.00371,9.313,0.000
60.73,63.100,-0.00358,9.332,0.000
60.85,63.200,-0.00342,9.351,0.000
61.00,63.300,-0.00325,9.374,0.000
61.12,63.400,-0.00308,9.392,0.000
61.24,63.500,-0.00292,9.411,0.000
61.36,63.600,-0.00279,9.429,0.000
61.53,63.700,-0.00263,9.455,0.000
61.67,63.800,-0.00246,9.477,0.000
61.77,63.900,-0.00229,9.492,0.000
61.90,64.000,-0.00213,9.513,0.000
62.05,64.100,-0.00196,9.535,0.000
62.16,64.200,-0.00180,9.553,0.000
62.31,64.300,-0.00163,9.574,0.000
62.44,64.400,-0.00146,9.595,0.000
62.57,64.500,-0.00130,9.615,0.000
62.70,64.600,-0.00113,9.635,0.000
62.86,64.700,-0.00096,9.660,0.000
63.00,64.800,-0.00076,9.680,0.000
63.17,64.900,-0.00059,9.707,0.000
63.34,65.000,-0.00038,9.734,0.000
63.52,65.100,-0.00017,9.760,0.000
63.71,65.200,0.00003,9.790,0.000
63.89,65.300,0.00028,9.818,0.000
64.05,65.400,0.00049,9.842,0.000
64.25,65.500,0.00074,9.873,0.000
64.41,65.600,0.00095,9.898,0.000
64.60,65.700,0.00116,9.926,0.000
64.76,65.800,0.00136,9.952,0.000
64.93,65.900,0.00157,9.977,0.000
65.02,66.000,0.00178,9.992,0.000
65.20,66.100,0.00199,10.019,0.000
65.35,66.200,0.00219,10.042,0.000
65.43,66.300,0.00236,10.054,0.000
65.61,66.400,0.00253,10.082,0.000
65.72,66.500,0.00273,10.099,0.000
65.82,66.600,0.00290,10.114,0.000
65.95,66.700,0.00307,10.135,0.000
66.07,66.800,0.00319,10.153,0.000
66.14,66.900,0.00336,10.164,0.000
66.27,67.000,0.00352,10.183,0.000
66.33,67.100,0.00365,10.193,0.000
66.44,67.200,0.00382,10.209,0.000
66.54,67.300,0.00394,10.225,0.000
66.64,67.400,0.00411,10.240,0.000
66.75,67.500,0.00423,10.257,0.000
66.82,67.600,0.00440,10.268,0.000
66.90,67.700,0.00452,10.280,0.000
66.99,67.800,0.00465,10.294,0.000
67.11,67.900,0.00477,10.312,0.000
67.20,68.000,0.00494,10.326,0.000
67.30,68.100,0.00506,10.342,0.000
67.42,68.200,0.00523,10.360,0.000
67.50,68.300,0.00535,10.373,0.000
67.61,68.400,0.00552,10.390,0.000
67.72,68.500,0.00564,10.407,0.000
67.86,68.600,0.00581,10.428,0.000
67.96,68.700,0.00593,10.444,0.000
68.10,68.800,0.00610,10.465,0.000
68.22,68.900,0.00627,10.483,0.000
68.30,69.000,0.00643,10.496,0.000
68.45,69.100,0.00656,10.519,0.000
68.60,69.200,0.00672,10.541,0.000
68.68,69.300,0.00689,10.553,0.000
68.83,69.400,0.00706,10.577,0.000
68.92,69.500,0.00722,10.590,0.000
69.08,69.600,0.00735,10.615,0.000
69.17,69.700,0.00751,10.629,0.000
69.29,69.800,0.00768,10.648,0.000
69.38,69.900,0.00785,10.661,0.000
69.53,70.000,0.00801,10.685,0.000
69.65,70.100,0.00818,10.702,0.000
69.79,70.200,0.00834,10.724,0.000
69.95,70.300,0.00855,10.750,0.000
70.07,70.400,0.00872,10.767,0.000
70.22,70.500,0.00893,10.790,0.000
70.37,70.600,0.00909,10.814,0.000
70.51,70.700,0.00930,10.836,0.000
70.69,70.800,0.00951,10.863,0.000
70.84,70.900,0.00972,10.885,0.000
70.99,71.000,0.00997,10.908,0.000
71.18,71.100,0.01017,10.938,0.000
71.36,71.200,0.01038,10.966,0.000
71.44,71.300,0.01059,10.978,0.000
71.62,71.400,0.01080,11.005,0.000
71.74,71.500,0.01100,11.024,0.000
71.89,71.600,0.01117,11.047,0.000
72.01,71.700,0.01138,11.066,0.000
72.13,71.800,0.01159,11.083,0.000
72.22,71.900,0.01175,11.097,0.000
72.35,72.000,0.01196,11.118,0.000
72.43,72.100,0.01213,11.130,0.000
72.56,72.200,0.01229,11.150,0.000
72.65,72.300,0.01246,11.165,0.000
72.72,72.400,0.01262,11.175,0.000
72.79,72.500,0.01279,11.186,0.000
72.92,72.600,0.01292,11.205,0.000
73.02,72.700,0.01308,11.220,0.000
73.11,72.800,0.01325,11.235,0.000
73.24,72.900,0.01337,11.255,0.000
73.28,73.000,0.01350,11.260,0.000
73.31,73.100,0.01366,11.266,0.000
73.40,73.200,0.01379,11.279,0.000
73.48,73.300,0.01391,11.291,0.000
73.56,73.400,0.01408,11.304,0.000
73.66,73.500,0.01420,11.319,0.000
73.74,73.600,0.01433,11.332,0.000
73.81,73.700,0.01449,11.342,0.000
73.90,73.800,0.01462,11.356,0.000
74.02,73.900,0.01474,11.375,0.000
74.07,74.000,0.01491,11.383,0.000
74.13,74.100,0.01504,11.391,0.000
74.23,74.200,0.01520,11.406,0.000
74.30,74.300,0.01537,11.418,0.000
74.39,74.400,0.01549,11.431,0.000
74.47,74.500,0.01562,11.444,0.000
74.56,74.600,0.01578,11.457,0.000
74.65,74.700,0.01595,11.471,0.000
74.67,74.800,0.01607,11.475,0.000
74.73,74.900,0.01624,11.484,0.000
74.83,75.000,0.01641,11.499,0.000
74.91,75.100,0.01657,11.512,0.000
74.93,75.200,0.01670,11.514,0.000
74.97,75.300,0.01686,11.521,0.000
75.03,75.400,0.01703,11.530,0.000
75.19,75.500,0.01720,11.554,0.000
75.18,75.600,0.01736,11.552,0.000
75.26,75.700,0.01749,11.565,0.000
75.37,75.800,0.01769,11.582,0.000
75.46,75.900,0.01786,11.595,0.000
75.50,76.000,0.01803,11.602,0.000
75.61,76.100,0.01819,11.619,0.000
75.69,76.200,0.01840,11.630,0.000
75.76,76.300,0.01861,11.642,0.000
75.84,76.400,0.01882,11.654,0.000
75.93,76.500,0.01902,11.669,0.000
76.03,76.600,0.01923,11.683,0.000
76.14,76.700,0.01944,11.700,0.000
76.18,76.800,0.01965,11.706,0.000
76.25,76.900,0.01986,11.716,0.000
76.35,77.000,0.02006,11.733,0.000
76.42,77.100,0.02027,11.744,0.000
76.49,77.200,0.02048,11.754,0.000
76.54,77.300,0.02069,11.761,0.000
76.61,77.400,0.02089,11.772,0.000
76.62,77.500,0.02106,11.774,0.000
76.71,77.600,0.02127,11.787,0.000
76.74,77.700,0.02143,11.793,0.000
76.76,77.800,0.02160,11.795,0.000
76.82,77.900,0.02177,11.804,0.000
76.85,78.000,0.02193,11.810,0.000
76.84,78.100,0.02210,11.808,0.000
76.82,78.200,0.02222,11.805,0.000
76.88,78.300,0.02239,11.813,0.000
76.83,78.400,0.02256,11.806,0.000
76.79,78.500,0.02268,11.800,0.000
76.76,78.600,0.02281,11.796,0.000
76.76,78.700,0.02297,11.795,0.000
76.71,78.800,0.02310,11.788,0.000
76.63,78.900,0.02322,11.776,0.000
76.61,79.000,0.02335,11.772,0.000
76.58,79.100,0.02351,11.769,0.000
76.54,79.200,0.02364,11.762,0.000
76.47,79.300,0.02376,11.751,0.000
76.42,79.400,0.02389,11.744,0.000
76.32,79.500,0.02405,11.728,0.000
76.30,79.600,0.02418,11.725,0.000
76.21,79.700,0.02434,11.710,0.000
76.11,79.800,0.02447,11.696,0.000
75.99,79.900,0.02463,11.677,0.000
75.86,80.000,0.02476,11.658,0.000
75.65,80.100,0.02493,11.625,0.000
75.30,80.200,0.02509,11.571,0.000
74.91,80.300,0.02522,11.511,0.000
74.50,80.400,0.02538,11.448,0.000
74.03,80.500,0.02555,11.377,0.001
73.37,80.600,0.02567,11.275,0.001
72.49,80.700,0.02584,11.139,0.001
71.63,80.800,0.02601,11.008,0.001
70.96,80.900,0.02617,10.904,0.001
70.41,81.000,0.02634,10.820,0.001
69.98,81.100,0.02646,10.754,0.001
69.55,81.200,0.02663,10.688,0.001
69.18,81.300,0.02680,10.630,0.001
68.87,81.400,0.02696,10.583,0.001
68.56,81.500,0.02717,10.536,0.001
68.30,81.600,0.02734,10.495,0.001
68.14,81.700,0.02750,10.470,0.001
67.98,81.800,0.02771,10.447,0.001
67.88,81.900,0.02788,10.431,0.001
67.67,82.000,0.02808,10.398,0.001
67.43,82.100,0.02829,10.362,0.001
67.16,82.200,0.02850,10.320,0.001
66.88,82.300,0.02875,10.278,0.001
66.59,82.400,0.02896,10.232,0.001
66.30,82.500,0.02921,10.189,0.001
65.88,82.600,0.02941,10.123,0.001
65.39,82.700,0.02962,10.049,0.001
64.79,82.800,0.02983,9.957,0.001
61.65,82.900,0.03008,9.474,0.001
53.69,83.000,0.03029,8.250,0.001
53.47,83.100,0.03049,8.217,0.001
53.54,83.200,0.03066,8.227,0.001
53.61,83.300,0.03087,8.238,0.001
53.71,83.400,0.03103,8.253,0.001
53.82,83.500,0.03120,8.270,0.001
53.92,83.600,0.03137,8.285,0.001
54.00,83.700,0.03153,8.297,0.001
54.08,83.800,0.03170,8.310,0.001
54.13,83.900,0.03182,8.318,0.001
54.23,84.000,0.03199,8.334,0.001
54.30,84.100,0.03216,8.345,0.001
54.37,84.200,0.03228,8.354,0.001
54.45,84.300,0.03241,8.367,0.001
54.50,84.400,0.03257,8.375,0.001
54.59,84.500,0.03270,8.389,0.001
54.67,84.600,0.03282,8.402,0.001
54.77,84.700,0.03299,8.416,0.001
54.84,84.800,0.03311,8.427,0.001
54.93,84.900,0.03324,8.442,0.001
55.01,85.000,0.03340,8.454,0.001
55.10,85.100,0.03353,8.467,0.001
55.17,85.200,0.03369,8.478,0.001
55.27,85.300,0.03386,8.493,0.001
55.35,85.400,0.03398,8.506,0.001
55.44,85.500,0.03415,8.520,0.001
55.54,85.600,0.03432,8.534,0.001
55.62,85.700,0.03444,8.547,0.001
55.73,85.800,0.03461,8.563,0.001
55.82,85.900,0.03473,8.577,0.001
55.88,86.000,0.03490,8.587,0.001
55.98,86.100,0.03507,8.603,0.001
56.07,86.200,0.03519,8.616,0.001
56.16,86.300,0.03536,8.630,0.001
56.22,86.400,0.03552,8.640,0.001
56.27,86.500,0.03569,8.647,0.001
56.32,86.600,0.03585,8.655,0.001
56.40,86.700,0.03602,8.667,0.001
56.47,86.800,0.03619,8.678,0.001
56.54,86.900,0.03635,8.688,0.001
56.61,87.000,0.03652,8.699,0.001
56.67,87.100,0.03669,8.709,0.001
56.74,87.200,0.03685,8.719,0.001
56.81,87.300,0.03706,8.731,0.001
56.85,87.400,0.03723,8.735,0.001
56.90,87.500,0.03743,8.744,0.001
56.95,87.600,0.03764,8.752,0.001
57.01,87.700,0.03785,8.760,0.001
57.06,87.800,0.03806,8.768,0.001
57.12,87.900,0.03826,8.778,0.001
57.19,88.000,0.03847,8.789,0.001
57.27,88.100,0.03868,8.800,0.001
57.30,88.200,0.03889,8.805,0.001
57.40,88.300,0.03910,8.821,0.001
57.50,88.400,0.03930,8.836,0.001
57.56,88.500,0.03951,8.845,0.001
57.63,88.600,0.03968,8.855,0.001
57.68,88.700,0.03989,8.864,0.001
57.74,88.800,0.04009,8.873,0.001
57.74,88.900,0.04026,8.873,0.001
57.78,89.000,0.04047,8.878,0.001
57.80,89.100,0.04059,8.882,0.001
57.79,89.200,0.04076,8.880,0.001
57.78,89.300,0.04092,8.879,0.001
57.82,89.400,0.04109,8.885,0.001
57.80,89.500,0.04126,8.882,0.001
57.78,89.600,0.04138,8.879,0.001
57.81,89.700,0.04155,8.883,0.001
57.80,89.800,0.04167,8.882,0.001
57.77,89.900,0.04184,8.878,0.001
57.71,90.000,0.04196,8.867,0.001
57.66,90.100,0.04213,8.861,0.001
57.61,90.200,0.04225,8.852,0.001
57.63,90.300,0.04238,8.855,0.001
57.62,90.400,0.04250,8.855,0.001
57.65,90.500,0.04267,8.859,0.001
57.67,90.600,0.04279,8.863,0.001
57.72,90.700,0.04296,8.869,0.001
57.72,90.800,0.04309,8.870,0.001
57.82,90.900,0.04321,8.885,0.001
57.89,91.000,0.04338,8.896,0.001
57.92,91.100,0.04350,8.900,0.001
57.99,91.200,0.04367,8.911,0.001
58.05,91.300,0.04379,8.920,0.001
58.15,91.400,0.04396,8.936,0.001
58.24,91.500,0.04408,8.949,0.001
58.31,91.600,0.04425,8.961,0.001
58.41,91.700,0.04442,8.976,0.001
58.46,91.800,0.04454,8.984,0.001
58.54,91.900,0.04471,8.996,0.001
58.67,92.000,0.04487,9.016,0.001
58.69,92.100,0.04500,9.019,0.001
58.76,92.200,0.04516,9.030,0.001
58.86,92.300,0.04533,9.045,0.001
58.95,92.400,0.04545,9.058,0.001
59.02,92.500,0.04562,9.069,0.001
59.09,92.600,0.04579,9.080,0.001
59.22,92.700,0.04595,9.100,0.001
59.35,92.800,0.04612,9.119,0.001
59.48,92.900,0.04633,9.139,0.001
59.62,93.000,0.04649,9.161,0.001
59.75,93.100,0.04670,9.182,0.001
59.90,93.200,0.04687,9.204,0.001
60.05,93.300,0.04707,9.228,0.001
60.18,93.400,0.04728,9.248,0.001
60.28,93.500,0.04753,9.263,0.001
60.35,93.600,0.04774,9.274,0.001
60.43,93.700,0.04795,9.285,0.001
60.50,93.800,0.04816,9.297,0.001
60.63,93.900,0.04840,9.317,0.001
60.74,94.000,0.04861,9.333,0.001
60.87,94.100,0.04882,9.354,0.001
61.05,94.200,0.04903,9.381,0.001
61.23,94.300,0.04924,9.409,0.001
61.34,94.400,0.04944,9.426,0.001
61.48,94.500,0.04965,9.448,0.001
61.65,94.600,0.04982,9.474,0.001
61.80,94.700,0.04998,9.497,0.001
61.93,94.800,0.05015,9.517,0.001
62.09,94.900,0.05036,9.542,0.001
62.23,95.000,0.05048,9.562,0.001
62.35,95.100,0.05065,9.582,0.001
62.49,95.200,0.05077,9.603,0.001
62.65,95.300,0.05094,9.627,0.001
62.73,95.400,0.05111,9.639,0.001
62.89,95.500,0.05123,9.664,0.001
62.98,95.600,0.05135,9.678,0.001
63.09,95.700,0.05152,9.694,0.001
63.19,95.800,0.05165,9.710,0.001
63.31,95.900,0.05177,9.729,0.001
63.42,96.000,0.05190,9.746,0.001
63.51,96.100,0.05206,9.759,0.001
63.58,96.200,0.05219,9.770,0.001
63.64,96.300,0.05231,9.779,0.001
63.68,96.400,0.05248,9.785,0.001
63.74,96.500,0.05260,9.795,0.001
63.79,96.600,0.05277,9.803,0.001
63.89,96.700,0.05289,9.818,0.001
64.02,96.800,0.05306,9.838,0.001
64.00,96.900,0.05322,9.835,0.001
64.06,97.000,0.05335,9.844,0.001
64.16,97.100,0.05352,9.860,0.001
64.28,97.200,0.05368,9.878,0.001
64.37,97.300,0.05381,9.891,0.001
64.56,97.400,0.05397,9.921,0.001
64.69,97.500,0.05414,9.941,0.001
64.84,97.600,0.05431,9.964,0.001
65.00,97.700,0.05447,9.989,0.001
65.19,97.800,0.05460,10.018,0.001
65.31,97.900,0.05476,10.036,0.001
65.50,98.000,0.05493,10.065,0.001
65.69,98.100,0.05509,10.094,0.001
65.86,98.200,0.05526,10.120,0.001
66.08,98.300,0.05543,10.154,0.001
66.24,98.400,0.05559,10.179,0.001
66.45,98.500,0.05576,10.210,0.001
66.67,98.600,0.05597,10.246,0.001
66.87,98.700,0.05613,10.276,0.001
67.15,98.800,0.05634,10.319,0.001
67.38,98.900,0.05655,10.355,0.001
67.65,99.000,0.05676,10.396,0.001
67.93,99.100,0.05696,10.439,0.001
68.15,99.200,0.05721,10.472,0.001
68.35,99.300,0.05742,10.503,0.001
68.63,99.400,0.05763,10.546,0.001
68.89,99.500,0.05788,10.586,0.001
69.18,99.600,0.05809,10.630,0.001
69.39,99.700,0.05829,10.664,0.001
69.65,99.800,0.05850,10.703,0.001
69.88,99.900,0.05871,10.738,0.001
70.13,100.000,0.05892,10.777,0.001
70.36,100.100,0.05913,10.812,0.001
70.57,100.200,0.05929,10.844,0.001
70.80,100.300,0.05946,10.879,0.001
70.98,100.400,0.05967,10.908,0.001
71.17,100.500,0.05983,10.937,0.001
71.38,100.600,0.05996,10.968,0.001
71.56,100.700,0.06012,10.997,0.001
71.75,100.800,0.06029,11.025,0.001
71.95,100.900,0.06046,11.057,0.001
72.11,101.000,0.06058,11.081,0.001
72.28,101.100,0.06075,11.107,0.001
72.47,101.200,0.06087,11.136,0.001
72.62,101.300,0.06104,11.160,0.001
72.85,101.400,0.06116,11.194,0.001
72.95,101.500,0.06129,11.210,0.001
73.18,101.600,0.06145,11.245,0.001
73.32,101.700,0.06158,11.267,0.001
73.52,101.800,0.06170,11.298,0.001
73.67,101.900,0.06187,11.320,0.001
73.86,102.000,0.06199,11.349,0.001
74.03,102.100,0.06216,11.376,0.001
74.23,102.200,0.06228,11.406,0.001
74.40,102.300,0.06245,11.432,0.001
74.58,102.400,0.06262,11.460,0.001
74.79,102.500,0.06274,11.492,0.001
74.92,102.600,0.06291,11.513,0.001
75.16,102.700,0.06307,11.550,0.001
75.33,102.800,0.06320,11.576,0.001
75.46,102.900,0.06336,11.596,0.001
75.67,103.000,0.06353,11.627,0.001
75.85,103.100,0.06366,11.656,0.001
76.02,103.200,0.06382,11.682,0.001
76.18,103.300,0.06399,11.706,0.001
76.36,103.400,0.06411,11.734,0.001
76.55,103.500,0.06428,11.763,0.001
76.76,103.600,0.06445,11.796,0.001
76.92,103.700,0.06461,11.819,0.001
77.14,103.800,0.06478,11.854,0.001
77.30,103.900,0.06494,11.878,0.001
77.52,104.000,0.06511,11.912,0.001
77.70,104.100,0.06532,11.940,0.001
77.97,104.200,0.06548,11.981,0.001
78.21,104.300,0.06569,12.019,0.001
78.45,104.400,0.06586,12.055,0.001
78.66,104.500,0.06607,12.087,0.001
78.93,104.600,0.06627,12.129,0.001
79.16,104.700,0.06648,12.165,0.001
79.44,104.800,0.06669,12.207,0.001
79.67,104.900,0.06690,12.243,0.001
79.94,105.000,0.06715,12.284,0.001
80.23,105.100,0.06735,12.329,0.001
80.40,105.200,0.06756,12.355,0.001
80.70,105.300,0.06777,12.401,0.001
80.94,105.400,0.06798,12.438,0.001
81.18,105.500,0.06819,12.475,0.001
81.46,105.600,0.06835,12.518,0.001
81.67,105.700,0.06856,12.550,0.001
81.90,105.800,0.06877,12.586,0.001
82.12,105.900,0.06893,12.619,0.001
82.33,106.000,0.06910,12.651,0.001
82.48,106.100,0.06927,12.674,0.001
82.68,106.200,0.06943,12.705,0.001
82.88,106.300,0.06960,12.736,0.001
83.09,106.400,0.06972,12.767,0.001
83.24,106.500,0.06989,12.790,0.001
83.43,106.600,0.07006,12.820,0.001
83.59,106.700,0.07018,12.846,0.001
83.75,106.800,0.07030,12.870,0.001
83.89,106.900,0.07047,12.890,0.001
84.08,107.000,0.07060,12.920,0.001
84.22,107.100,0.07072,12.942,0.001
84.40,107.200,0.07089,12.969,0.001
84.54,107.300,0.07101,12.991,0.001
84.72,107.400,0.07114,13.019,0.001
84.89,107.500,0.07126,13.044,0.001
85.06,107.600,0.07143,13.071,0.001
85.21,107.700,0.07155,13.094,0.001
85.38,107.800,0.07172,13.120,0.001
85.52,107.900,0.07184,13.142,0.001
85.72,108.000,0.07201,13.172,0.001
85.88,108.100,0.07213,13.196,0.001
86.08,108.200,0.07230,13.228,0.001
86.22,108.300,0.07247,13.249,0.001
86.39,108.400,0.07259,13.275,0.001
86.55,108.500,0.07276,13.300,0.001
86.72,108.600,0.07288,13.325,0.001
86.90,108.700,0.07305,13.354,0.001
87.10,108.800,0.07321,13.384,0.001
87.24,108.900,0.07334,13.406,0.001
87.41,109.000,0.07350,13.431,0.001
87.56,109.100,0.07363,13.455,0.001
87.76,109.200,0.07380,13.485,0.001
87.94,109.300,0.07396,13.513,0.001
88.11,109.400,0.07413,13.539,0.001
88.27,109.500,0.07429,13.564,0.001
88.45,109.600,0.07446,13.592,0.001
88.66,109.700,0.07463,13.624,0.001
88.90,109.800,0.07483,13.661,0.001
89.07,109.900,0.07500,13.687,0.001
89.28,110.000,0.07521,13.720,0.001
89.53,110.100,0.07537,13.757,0.001
89.76,110.200,0.07558,13.794,0.001
89.98,110.300,0.07579,13.826,0.001
90.18,110.400,0.07600,13.857,0.001
90.42,110.500,0.07621,13.894,0.002
90.63,110.600,0.07641,13.927,0.002
90.87,110.700,0.07662,13.964,0.002
91.08,110.800,0.07683,13.996,0.002
91.30,110.900,0.07704,14.030,0.002
91.48,111.000,0.07724,14.058,0.002
91.68,111.100,0.07745,14.089,0.002
91.87,111.200,0.07766,14.118,0.002
92.04,111.300,0.07787,14.143,0.002
92.16,111.400,0.07803,14.161,0.002
92.31,111.500,0.07820,14.185,0.002
92.43,111.600,0.07837,14.204,0.002
92.58,111.700,0.07853,14.226,0.002
92.72,111.800,0.07870,14.248,0.002
92.84,111.900,0.07886,14.266,0.002
92.98,112.000,0.07899,14.288,0.002
93.10,112.100,0.07916,14.306,0.002
93.21,112.200,0.07928,14.323,0.002
93.35,112.300,0.07941,14.345,0.002
93.43,112.400,0.07957,14.357,0.002
93.57,112.500,0.07970,14.378,0.002
93.70,112.600,0.07982,14.399,0.002
93.83,112.700,0.07995,14.418,0.002
93.94,112.800,0.08011,14.435,0.002
94.10,112.900,0.08024,14.459,0.002
94.22,113.000,0.08036,14.479,0.002
94.37,113.100,0.08053,14.501,0.002
94.50,113.200,0.08065,14.522,0.002
94.62,113.300,0.08078,14.540,0.002
94.78,113.400,0.08090,14.564,0.002
94.90,113.500,0.08107,14.583,0.002
95.04,113.600,0.08119,14.605,0.002
95.18,113.700,0.08136,14.626,0.002
95.30,113.800,0.08148,14.645,0.002
95.48,113.900,0.08165,14.671,0.002
95.63,114.000,0.08177,14.695,0.002
95.77,114.100,0.08194,14.717,0.002
95.93,114.200,0.08206,14.741,0.002
96.09,114.300,0.08223,14.766,0.002
96.21,114.400,0.08240,14.784,0.002
96.38,114.500,0.08252,14.811,0.002
96.54,114.600,0.08269,14.835,0.002
96.68,114.700,0.08285,14.856,0.002
96.81,114.800,0.08298,14.877,0.002
96.97,114.900,0.08315,14.900,0.002
97.11,115.000,0.08331,14.923,0.002
97.28,115.100,0.08344,14.948,0.002
97.02,115.200,0.08360,14.908,0.002
8.06,115.270,0.08373,1.239,0.002