File: data-files/mech3/WH13Z.txt
""
"Test Method","Will_Huddleston_Disks.msm"
"Sample I. D.","WH13Z.mss"
"Specimen Number","1"

"Load (N)","Time (s)","Extension (mm)","Stress (MPa)","Strain (mm/mm)"

13.43,0.200,-0.01566,1.790,0.000
13.39,0.300,-0.01566,1.784,0.000
13.41,0.400,-0.01562,1.787,0.000
13.40,0.500,-0.01562,1.786,0.000
13.42,0.600,-0.01562,1.788,0.000
13.42,0.700,-0.01562,1.788,0.000
13.41,0.800,-0.01557,1.787,0.000
13.41,0.900,-0.01557,1.787,0.000
13.45,1.000,-0.01557,1.792,0.000
13.43,1.100,-0.01553,1.789,0.000
13.42,1.200,-0.01553,1.789,0.000
13.43,1.300,-0.01553,1.790,0.000
13.42,1.400,-0.01549,1.788,0.000
13.43,1.500,-0.01549,1.790,0.000
13.44,1.600,-0.01549,1.791,0.000
13.46,1.700,-0.01545,1.794,0.000
13.45,1.800,-0.01545,1.793,0.000
13.46,1.900,-0.01541,1.794,0.000
13.47,2.000,-0.01541,1.795,0.000
13.49,2.100,-0.01537,1.798,0.000
13.53,2.200,-0.01532,1.803,0.000
13.64,2.300,-0.01520,1.818,0.000
13.78,2.400,-0.01503,1.837,0.000
14.01,2.500,-0.01478,1.867,0.000
14.18,2.600,-0.01462,1.890,0.000
14.34,2.700,-0.01441,1.911,0.000
14.46,2.800,-0.01420,1.927,0.000
14.57,2.900,-0.01404,1.941,0.000
14.63,3.000,-0.01383,1.950,0.000
14.74,3.100,-0.01366,1.965,0.000
14.85,3.200,-0.01345,1.978,0.000
14.95,3.300,-0.01325,1.992,0.000
15.05,3.400,-0.01308,2.006,0.000
15.08,3.500,-0.01291,2.010,0.000
15.16,3.600,-0.01271,2.021,0.000
15.23,3.700,-0.01254,2.030,0.000
15.30,3.800,-0.01242,2.039,0.000
15.36,3.900,-0.01225,2.047,0.000
15.43,4.000,-0.01208,2.057,0.000
15.49,4.100,-0.01196,2.064,0.000
15.56,4.200,-0.01179,2.073,0.000
15.60,4.300,-0.01167,2.079,0.000
15.65,4.400,-0.01150,2.086,0.000
15.73,4.500,-0.01138,2.096,0.000
15.80,4.600,-0.01121,2.105,0.000
15.85,4.700,-0.01109,2.112,0.000
15.89,4.800,-0.01096,2.118,0.000
15.96,4.900,-0.01079,2.127,0.000
16.01,5.000,-0.01067,2.133,0.000
16.05,5.100,-0.01055,2.139,0.000
16.08,5.200,-0.01042,2.143,0.000
16.16,5.300,-0.01030,2.153,0.000
16.21,5.400,-0.01013,2.161,0.000
16.28,5.500,-0.01001,2.169,0.000
16.37,5.600,-0.00984,2.181,0.000
16.45,5.700,-0.00971,2.192,0.000
16.46,5.800,-0.00955,2.193,0.000
16.54,5.900,-0.00942,2.204,0.000
16.62,6.000,-0.00926,2.214,0.000
16.67,6.100,-0.00909,2.221,0.000
16.74,6.200,-0.00897,2.231,0.000
16.78,6.300,-0.00880,2.236,0.000
16.87,6.400,-0.00868,2.248,0.000
16.96,6.500,-0.00851,2.261,0.000
17.02,6.600,-0.00834,2.268,0.000
17.06,6.700,-0.00818,2.273,0.000
17.15,6.800,-0.00801,2.285,0.000
17.20,6.900,-0.00789,2.291,0.000
17.27,7.000,-0.00772,2.301,0.000
17.33,7.100,-0.00755,2.309,0.000
17.41,7.200,-0.00739,2.320,0.000
17.46,7.300,-0.00722,2.326,0.000
17.57,7.400,-0.00705,2.342,0.000
17.63,7.500,-0.00689,2.349,0.000
17.73,7.600,-0.00672,2.362,0.000
17.81,7.700,-0.00656,2.374,0.000
17.87,7.800,-0.00635,2.381,0.000
17.96,7.900,-0.00618,2.393,0.000
18.05,8.000,-0.00597,2.405,0.000
18.13,8.100,-0.00577,2.416,0.000
18.22,8.200,-0.00556,2.428,0.000
18.32,8.300,-0.00535,2.441,0.000
18.43,8.400,-0.00514,2.457,0.000
18.53,8.500,-0.00494,2.469,0.000
18.60,8.600,-0.00473,2.479,0.000
18.72,8.700,-0.00452,2.494,0.000
18.82,8.800,-0.00431,2.509,0.000
18.91,8.900,-0.00410,2.520,0.000
18.97,9.000,-0.00390,2.528,0.000
19.05,9.100,-0.00369,2.538,0.000
19.12,9.200,-0.00352,2.548,0.000
19.23,9.300,-0.00331,2.563,0.000
19.30,9.400,-0.00315,2.572,0.000
19.39,9.500,-0.00298,2.584,0.000
19.49,9.600,-0.00282,2.597,0.000
19.52,9.700,-0.00265,2.601,0.000
19.64,9.800,-0.00248,2.617,0.000
19.68,9.900,-0.00236,2.622,0.000
19.73,10.000,-0.00219,2.629,0.000
19.81,10.100,-0.00203,2.639,0.000
19.87,10.200,-0.00190,2.648,0.000
19.95,10.300,-0.00174,2.659,0.000
20.00,10.400,-0.00161,2.665,0.000
20.08,10.500,-0.00149,2.676,0.000
20.14,10.600,-0.00132,2.683,0.000
20.21,10.700,-0.00120,2.693,0.000
20.25,10.800,-0.00107,2.698,0.000
20.35,10.900,-0.00095,2.712,0.000
20.40,11.000,-0.00078,2.719,0.000
20.46,11.100,-0.00066,2.727,0.000
20.53,11.200,-0.00053,2.735,0.000
20.60,11.300,-0.00041,2.746,0.000
20.67,11.400,-0.00024,2.755,0.000
20.75,11.500,-0.00011,2.765,0.000
20.82,11.600,0.00005,2.774,0.000
20.89,11.700,0.00018,2.784,0.000
20.95,11.800,0.00034,2.792,0.000
21.05,11.900,0.00047,2.805,0.000
21.10,12.000,0.00063,2.812,0.000
21.15,12.100,0.00080,2.818,0.000
21.28,12.200,0.00092,2.836,0.000
21.32,12.300,0.00109,2.841,0.000
21.40,12.400,0.00126,2.852,0.000
21.50,12.500,0.00142,2.866,0.000
21.54,12.600,0.00155,2.870,0.000
21.65,12.700,0.00171,2.885,0.000
21.72,12.800,0.00188,2.894,0.000
21.80,12.900,0.00205,2.905,0.000
21.88,13.000,0.00221,2.915,0.000
21.96,13.100,0.00238,2.926,0.000
22.02,13.200,0.00254,2.935,0.000
22.10,13.300,0.00271,2.945,0.000
22.23,13.400,0.00288,2.963,0.000
22.33,13.500,0.00308,2.976,0.000
22.42,13.600,0.00325,2.988,0.000
22.53,13.700,0.00346,3.003,0.000
22.63,13.800,0.00367,3.016,0.000
22.75,13.900,0.00387,3.031,0.000
22.83,14.000,0.00408,3.043,0.000
23.00,14.100,0.00433,3.064,0.000
23.10,14.200,0.00454,3.079,0.000
23.23,14.300,0.00475,3.095,0.000
23.33,14.400,0.00500,3.110,0.000
23.44,14.500,0.00520,3.123,0.000
23.50,14.600,0.00541,3.132,0.000
23.68,14.700,0.00562,3.156,0.000
23.76,14.800,0.00579,3.166,0.000
23.86,14.900,0.00599,3.180,0.000
23.96,15.000,0.00620,3.193,0.000
24.04,15.100,0.00637,3.203,0.000
24.15,15.200,0.00653,3.219,0.000
24.22,15.300,0.00670,3.228,0.000
24.31,15.400,0.00687,3.239,0.000
24.39,15.500,0.00699,3.250,0.000
24.44,15.600,0.00716,3.257,0.000
24.56,15.700,0.00728,3.273,0.000
24.64,15.800,0.00745,3.283,0.000
24.73,15.900,0.00757,3.295,0.000
24.81,16.000,0.00774,3.306,0.000
24.88,16.100,0.00786,3.316,0.000
24.95,16.200,0.00799,3.325,0.000
25.02,16.300,0.00815,3.335,0.000
25.12,16.400,0.00828,3.347,0.000
25.18,16.500,0.00840,3.355,0.000
25.26,16.600,0.00853,3.367,0.000
25.33,16.700,0.00869,3.376,0.000
25.39,16.800,0.00882,3.383,0.000
25.50,16.900,0.00899,3.398,0.000
25.57,17.000,0.00911,3.408,0.000
25.63,17.100,0.00928,3.416,0.000
25.74,17.200,0.00940,3.431,0.000
25.85,17.300,0.00957,3.445,0.000
25.88,17.400,0.00973,3.449,0.000
25.99,17.500,0.00986,3.463,0.000
26.08,17.600,0.01002,3.476,0.000
26.14,17.700,0.01019,3.483,0.000
26.25,17.800,0.01036,3.498,0.000
26.33,17.900,0.01048,3.509,0.000
26.44,18.000,0.01065,3.523,0.000
26.49,18.100,0.01081,3.530,0.000
26.63,18.200,0.01098,3.549,0.000
26.73,18.300,0.01115,3.563,0.000
26.79,18.400,0.01127,3.570,0.000
26.89,18.500,0.01144,3.584,0.000
26.97,18.600,0.01160,3.594,0.000
27.08,18.700,0.01177,3.609,0.000
27.19,18.800,0.01194,3.624,0.000
27.30,18.900,0.01214,3.638,0.000
27.41,19.000,0.01231,3.652,0.000
27.52,19.100,0.01252,3.667,0.000
27.64,19.200,0.01268,3.683,0.000
27.75,19.300,0.01289,3.699,0.000
27.87,19.400,0.01310,3.714,0.000
28.01,19.500,0.01331,3.733,0.000
28.16,19.600,0.01356,3.752,0.000
28.29,19.700,0.01376,3.770,0.000
28.41,19.800,0.01397,3.786,0.000
28.56,19.900,0.01422,3.806,0.000
28.67,20.000,0.01443,3.821,0.000
28.81,20.100,0.01464,3.839,0.000
28.94,20.200,0.01485,3.856,0.000
29.08,20.300,0.01505,3.875,0.000
29.20,20.400,0.01526,3.891,0.000
29.31,20.500,0.01547,3.906,0.000
29.42,20.600,0.01563,3.920,0.000
29.53,20.700,0.01584,3.935,0.000
29.62,20.800,0.01601,3.947,0.000
29.73,20.900,0.01617,3.962,0.000
29.83,21.000,0.01634,3.975,0.000
29.93,21.100,0.01651,3.988,0.000
30.01,21.200,0.01663,4.000,0.000
30.13,21.300,0.01680,4.015,0.000
30.20,21.400,0.01696,4.025,0.000
30.28,21.500,0.01709,4.035,0.000
30.36,21.600,0.01721,4.046,0.000
30.46,21.700,0.01738,4.060,0.000
30.54,21.800,0.01750,4.070,0.000
30.65,21.900,0.01763,4.084,0.000
30.71,22.000,0.01780,4.093,0.000
30.80,22.100,0.01792,4.104,0.000
30.88,22.200,0.01804,4.115,0.000
30.98,22.300,0.01821,4.128,0.000
31.07,22.400,0.01834,4.141,0.000
31.16,22.500,0.01850,4.152,0.000
31.25,22.600,0.01863,4.164,0.000
31.33,22.700,0.01879,4.175,0.000
31.42,22.800,0.01892,4.187,0.000
31.54,22.900,0.01908,4.202,0.000
31.64,23.000,0.01925,4.216,0.000
31.74,23.100,0.01937,4.230,0.000
31.83,23.200,0.01954,4.242,0.000
31.94,23.300,0.01971,4.256,0.000
32.02,23.400,0.01987,4.267,0.000
32.16,23.500,0.02000,4.286,0.000
32.23,23.600,0.02016,4.295,0.000
32.34,23.700,0.02033,4.309,0.000
32.42,23.800,0.02050,4.321,0.000
32.56,23.900,0.02062,4.338,0.000
32.64,24.000,0.02079,4.349,0.000
32.75,24.100,0.02095,4.365,0.000
32.88,24.200,0.02112,4.381,0.000
32.98,24.300,0.02129,4.394,0.000
33.10,24.400,0.02145,4.411,0.000
33.20,24.500,0.02166,4.425,0.000
33.37,24.600,0.02183,4.447,0.000
33.48,24.700,0.02199,4.461,0.000
33.60,24.800,0.02220,4.477,0.000
33.73,24.900,0.02241,4.494,0.000
33.85,25.000,0.02262,4.512,0.000
34.00,25.100,0.02282,4.531,0.000
34.15,25.200,0.02303,4.551,0.000
34.28,25.300,0.02324,4.568,0.000
34.46,25.400,0.02345,4.592,0.000
34.57,25.500,0.02365,4.607,0.000
34.75,25.600,0.02386,4.631,0.000
34.84,25.700,0.02407,4.644,0.000
34.97,25.800,0.02424,4.661,0.000
35.11,25.900,0.02444,4.679,0.000
35.25,26.000,0.02465,4.697,0.000
35.35,26.100,0.02482,4.711,0.000
35.49,26.200,0.02498,4.730,0.000
35.61,26.300,0.02519,4.745,0.000
35.71,26.400,0.02536,4.759,0.000
35.83,26.500,0.02552,4.775,0.001
35.92,26.600,0.02569,4.786,0.001
36.03,26.700,0.02582,4.802,0.001
36.11,26.800,0.02598,4.813,0.001
36.25,26.900,0.02615,4.830,0.001
36.38,27.000,0.02631,4.848,0.001
36.46,27.100,0.02644,4.859,0.001
36.55,27.200,0.02661,4.871,0.001
36.68,27.300,0.02673,4.888,0.001
36.77,27.400,0.02685,4.901,0.001
36.85,27.500,0.02702,4.911,0.001
36.97,27.600,0.02715,4.927,0.001
37.06,27.700,0.02727,4.939,0.001
37.10,27.800,0.02739,4.945,0.001
37.22,27.900,0.02756,4.960,0.001
37.31,28.000,0.02769,4.972,0.001
37.41,28.100,0.02781,4.985,0.001
37.53,28.200,0.02798,5.002,0.001
37.61,28.300,0.02810,5.012,0.001
37.73,28.400,0.02827,5.028,0.001
37.86,28.500,0.02839,5.045,0.001
37.93,28.600,0.02852,5.054,0.001
38.05,28.700,0.02868,5.071,0.001
38.15,28.800,0.02885,5.084,0.001
38.26,28.900,0.02897,5.098,0.001
38.37,29.000,0.02914,5.113,0.001
38.49,29.100,0.02927,5.130,0.001
38.59,29.200,0.02943,5.142,0.001
38.70,29.300,0.02956,5.157,0.001
38.77,29.400,0.02972,5.166,0.001
38.91,29.500,0.02989,5.186,0.001
38.99,29.600,0.03001,5.195,0.001
39.19,29.700,0.03018,5.222,0.001
39.27,29.800,0.03035,5.233,0.001
39.40,29.900,0.03051,5.250,0.001
39.51,30.000,0.03068,5.265,0.001
39.64,30.100,0.03084,5.282,0.001
39.77,30.200,0.03101,5.300,0.001
39.87,30.300,0.03118,5.313,0.001
40.02,30.400,0.03134,5.333,0.001
40.19,30.500,0.03155,5.356,0.001
40.37,30.600,0.03176,5.380,0.001
40.51,30.700,0.03197,5.398,0.001
40.65,30.800,0.03217,5.418,0.001
40.78,30.900,0.03238,5.435,0.001
40.98,31.000,0.03259,5.461,0.001
41.14,31.100,0.03280,5.482,0.001
41.32,31.200,0.03301,5.506,0.001
41.47,31.300,0.03325,5.526,0.001
41.63,31.400,0.03346,5.548,0.001
41.79,31.500,0.03367,5.568,0.001
41.92,31.600,0.03384,5.586,0.001
42.12,31.700,0.03404,5.612,0.001
42.24,31.800,0.03425,5.629,0.001
42.39,31.900,0.03442,5.649,0.001
42.52,32.000,0.03463,5.666,0.001
42.62,32.100,0.03479,5.680,0.001
42.76,32.200,0.03496,5.698,0.001
42.86,32.300,0.03512,5.712,0.001
43.00,32.400,0.03529,5.730,0.001
43.10,32.500,0.03542,5.743,0.001
43.20,32.600,0.03558,5.757,0.001
43.33,32.700,0.03571,5.774,0.001
43.46,32.800,0.03587,5.792,0.001
43.54,32.900,0.03600,5.803,0.001
43.65,33.000,0.03612,5.817,0.001
43.79,33.100,0.03625,5.836,0.001
43.85,33.200,0.03641,5.844,0.001
43.99,33.300,0.03654,5.862,0.001
44.09,33.400,0.03666,5.875,0.001
44.21,33.500,0.03683,5.892,0.001
44.32,33.600,0.03695,5.906,0.001
44.44,33.700,0.03708,5.922,0.001
44.56,33.800,0.03724,5.938,0.001
44.65,33.900,0.03737,5.950,0.001
44.79,34.000,0.03749,5.969,0.001
44.94,34.100,0.03766,5.988,0.001
45.07,34.200,0.03778,6.006,0.001
45.16,34.300,0.03795,6.018,0.001
45.29,34.400,0.03807,6.036,0.001
45.41,34.500,0.03824,6.052,0.001
45.56,34.600,0.03841,6.071,0.001
45.67,34.700,0.03853,6.086,0.001
45.75,34.800,0.03870,6.097,0.001
45.92,34.900,0.03886,6.119,0.001
46.06,35.000,0.03899,6.138,0.001
46.19,35.100,0.03916,6.155,0.001
46.34,35.200,0.03932,6.176,0.001
46.48,35.300,0.03949,6.194,0.001
46.59,35.400,0.03961,6.209,0.001
46.72,35.500,0.03978,6.226,0.001
46.88,35.600,0.03994,6.247,0.001
47.02,35.700,0.04011,6.266,0.001
47.20,35.800,0.04028,6.290,0.001
47.33,35.900,0.04049,6.307,0.001
47.49,36.000,0.04065,6.329,0.001
47.67,36.100,0.04082,6.352,0.001
47.83,36.200,0.04103,6.373,0.001
48.00,36.300,0.04123,6.396,0.001
48.19,36.400,0.04144,6.421,0.001
48.39,36.500,0.04165,6.448,0.001
48.54,36.600,0.04186,6.468,0.001
48.77,36.700,0.04206,6.500,0.001
48.94,36.800,0.04227,6.521,0.001
49.12,36.900,0.04252,6.546,0.001
49.31,37.000,0.04273,6.571,0.001
49.47,37.100,0.04294,6.593,0.001
49.66,37.200,0.04314,6.618,0.001
49.82,37.300,0.04331,6.639,0.001
50.02,37.400,0.04352,6.666,0.001
50.21,37.500,0.04373,6.691,0.001
50.39,37.600,0.04389,6.715,0.001
50.54,37.700,0.04410,6.735,0.001
50.71,37.800,0.04427,6.758,0.001
50.86,37.900,0.04443,6.777,0.001
51.02,38.000,0.04460,6.799,0.001
51.15,38.100,0.04477,6.816,0.001
51.30,38.200,0.04489,6.837,0.001
51.47,38.300,0.04506,6.859,0.001
51.55,38.400,0.04522,6.870,0.001
51.68,38.500,0.04535,6.887,0.001
51.86,38.600,0.04547,6.912,0.001
51.98,38.700,0.04564,6.927,0.001
52.11,38.800,0.04576,6.945,0.001
52.24,38.900,0.04589,6.962,0.001
52.37,39.000,0.04605,6.978,0.001
52.56,39.100,0.04618,7.004,0.001
52.64,39.200,0.04630,7.015,0.001
52.76,39.300,0.04643,7.031,0.001
52.91,39.400,0.04655,7.051,0.001
53.04,39.500,0.04672,7.068,0.001
53.17,39.600,0.04684,7.086,0.001
53.27,39.700,0.04697,7.099,0.001
53.47,39.800,0.04713,7.125,0.001
53.62,39.900,0.04730,7.145,0.001
53.75,40.000,0.04742,7.163,0.001
53.95,40.100,0.04759,7.189,0.001
54.08,40.200,0.04772,7.207,0.001
54.23,40.300,0.04788,7.226,0.001
54.36,40.400,0.04805,7.245,0.001
54.52,40.500,0.04817,7.265,0.001
54.67,40.600,0.04834,7.286,0.001
54.82,40.700,0.04851,7.305,0.001
54.98,40.800,0.04863,7.326,0.001
55.11,40.900,0.04880,7.344,0.001
55.27,41.000,0.04896,7.366,0.001
55.46,41.100,0.04913,7.390,0.001
55.58,41.200,0.04929,7.407,0.001
55.76,41.300,0.04946,7.431,0.001
55.95,41.400,0.04963,7.456,0.001
56.11,41.500,0.04979,7.478,0.001
56.27,41.600,0.04996,7.499,0.001
56.45,41.700,0.05013,7.523,0.001
56.63,41.800,0.05029,7.546,0.001
56.86,41.900,0.05050,7.578,0.001
57.04,42.000,0.05071,7.601,0.001
57.23,42.100,0.05087,7.626,0.001
57.43,42.200,0.05108,7.653,0.001
57.69,42.300,0.05129,7.688,0.001
57.88,42.400,0.05150,7.713,0.001
58.14,42.500,0.05175,7.748,0.001
58.35,42.600,0.05195,7.776,0.001
58.57,42.700,0.05216,7.805,0.001
58.79,42.800,0.05237,7.834,0.001
59.01,42.900,0.05254,7.863,0.001
59.20,43.000,0.05274,7.889,0.001
59.39,43.100,0.05295,7.915,0.001
59.60,43.200,0.05312,7.942,0.001
59.79,43.300,0.05333,7.968,0.001
59.98,43.400,0.05349,7.993,0.001
60.16,43.500,0.05366,8.017,0.001
60.34,43.600,0.05382,8.042,0.001
60.53,43.700,0.05399,8.067,0.001
60.67,43.800,0.05416,8.085,0.001
60.83,43.900,0.05432,8.106,0.001
60.96,44.000,0.05445,8.124,0.001
61.19,44.100,0.05461,8.154,0.001
61.33,44.200,0.05474,8.173,0.001
61.43,44.300,0.05490,8.187,0.001
61.62,44.400,0.05503,8.211,0.001
61.73,44.500,0.05515,8.227,0.001
61.92,44.600,0.05528,8.251,0.001
62.03,44.700,0.05545,8.266,0.001
62.15,44.800,0.05557,8.283,0.001
62.31,44.900,0.05569,8.303,0.001
62.45,45.000,0.05582,8.322,0.001
62.60,45.100,0.05594,8.342,0.001
62.77,45.200,0.05611,8.365,0.001
62.95,45.300,0.05623,8.389,0.001
63.00,45.400,0.05636,8.396,0.001
63.18,45.500,0.05653,8.419,0.001
63.33,45.600,0.05665,8.440,0.001
63.51,45.700,0.05682,8.463,0.001
63.67,45.800,0.05694,8.485,0.001
63.82,45.900,0.05711,8.505,0.001
63.98,46.000,0.05723,8.526,0.001
64.17,46.100,0.05740,8.551,0.001
64.32,46.200,0.05756,8.571,0.001
64.48,46.300,0.05769,8.593,0.001
64.68,46.400,0.05786,8.619,0.001
64.84,46.500,0.05802,8.641,0.001
65.01,46.600,0.05815,8.663,0.001
65.18,46.700,0.05831,8.686,0.001
65.34,46.800,0.05848,8.708,0.001
65.53,46.900,0.05864,8.732,0.001
65.71,47.000,0.05877,8.757,0.001
65.86,47.100,0.05894,8.776,0.001
66.09,47.200,0.05910,8.807,0.001
66.28,47.300,0.05927,8.833,0.001
66.49,47.400,0.05943,8.861,0.001
66.70,47.500,0.05964,8.889,0.001
66.89,47.600,0.05981,8.914,0.001
67.13,47.700,0.06002,8.946,0.001
67.33,47.800,0.06018,8.973,0.001
67.59,47.900,0.06039,9.007,0.001
67.84,48.000,0.06060,9.040,0.001
68.10,48.100,0.06085,9.075,0.001
68.33,48.200,0.06106,9.106,0.001
68.60,48.300,0.06126,9.142,0.001
68.86,48.400,0.06147,9.176,0.001
69.09,48.500,0.06168,9.208,0.001
69.36,48.600,0.06189,9.243,0.001
69.59,48.700,0.06214,9.273,0.001
69.82,48.800,0.06230,9.304,0.001
70.03,48.900,0.06251,9.332,0.001
70.28,49.000,0.06268,9.365,0.001
70.46,49.100,0.06288,9.389,0.001
70.65,49.200,0.06305,9.415,0.001
70.82,49.300,0.06322,9.437,0.001
71.02,49.400,0.06338,9.465,0.001
71.19,49.500,0.06355,9.488,0.001
71.37,49.600,0.06367,9.510,0.001
71.54,49.700,0.06384,9.533,0.001
71.68,49.800,0.06396,9.553,0.001
71.86,49.900,0.06409,9.576,0.001
72.04,50.000,0.06426,9.600,0.001
72.20,50.100,0.06438,9.621,0.001
72.34,50.200,0.06455,9.640,0.001
72.54,50.300,0.06467,9.667,0.001
72.67,50.400,0.06480,9.684,0.001
72.84,50.500,0.06496,9.707,0.001
72.89,50.600,0.06509,9.714,0.001
72.93,50.700,0.06521,9.718,0.001
73.04,50.800,0.06534,9.734,0.001
73.20,50.900,0.06550,9.755,0.001
73.29,51.000,0.06563,9.767,0.001
29.19,51.100,0.06579,3.890,0.001
32.91,51.200,0.06592,4.386,0.001
33.51,51.300,0.06608,4.466,0.001
33.58,51.400,0.06621,4.475,0.001
33.85,51.500,0.06637,4.510,0.001
34.13,51.600,0.06654,4.548,0.001
34.36,51.700,0.06667,4.578,0.001
34.62,51.800,0.06683,4.614,0.001
34.84,51.900,0.06700,4.642,0.001
35.10,52.000,0.06716,4.678,0.001
35.36,52.100,0.06729,4.712,0.001
35.61,52.200,0.06745,4.745,0.001
35.84,52.300,0.06762,4.776,0.001
36.10,52.400,0.06779,4.811,0.001
36.35,52.500,0.06795,4.844,0.001
36.57,52.600,0.06812,4.873,0.001
36.81,52.700,0.06829,4.905,0.001
37.08,52.800,0.06845,4.941,0.001
37.32,52.900,0.06862,4.973,0.001
37.56,53.000,0.06878,5.005,0.001
37.76,53.100,0.06899,5.032,0.001
38.01,53.200,0.06916,5.065,0.001
38.26,53.300,0.06937,5.098,0.001
38.52,53.400,0.06957,5.133,0.001
38.74,53.500,0.06978,5.163,0.001
38.97,53.600,0.06999,5.194,0.001
39.23,53.700,0.07020,5.228,0.001
39.49,53.800,0.07041,5.263,0.001
39.70,53.900,0.07065,5.291,0.001
39.94,54.000,0.07086,5.323,0.001
40.17,54.100,0.07107,5.353,0.001
40.36,54.200,0.07128,5.378,0.001
40.56,54.300,0.07149,5.405,0.001
40.73,54.400,0.07169,5.428,0.001
40.94,54.500,0.07190,5.456,0.001
41.13,54.600,0.07207,5.481,0.001
41.32,54.700,0.07228,5.506,0.001
41.48,54.800,0.07244,5.528,0.001
41.68,54.900,0.07261,5.555,0.001
41.81,55.000,0.07277,5.572,0.001
41.94,55.100,0.07294,5.589,0.001
42.10,55.200,0.07311,5.610,0.001
42.26,55.300,0.07327,5.632,0.001
42.41,55.400,0.07344,5.652,0.001
42.54,55.500,0.07356,5.669,0.001
42.69,55.600,0.07373,5.690,0.001
42.78,55.700,0.07385,5.701,0.001
42.93,55.800,0.07402,5.721,0.001
43.06,55.900,0.07415,5.739,0.001
43.21,56.000,0.07427,5.758,0.001
43.33,56.100,0.07444,5.775,0.001
43.46,56.200,0.07456,5.792,0.001
43.55,56.300,0.07469,5.803,0.001
43.68,56.400,0.07485,5.821,0.001
43.77,56.500,0.07498,5.833,0.001
43.90,56.600,0.07510,5.850,0.001
44.03,56.700,0.07527,5.868,0.001
44.16,56.800,0.07539,5.885,0.001
44.27,56.900,0.07556,5.900,0.001
44.49,57.000,0.07568,5.929,0.001
44.63,57.100,0.07585,5.947,0.001
44.78,57.200,0.07602,5.968,0.001
44.89,57.300,0.07614,5.982,0.001
45.06,57.400,0.07631,6.004,0.002
44.82,57.500,0.07647,5.973,0.002
44.85,57.600,0.07664,5.977,0.002
44.99,57.700,0.07676,5.996,0.002
45.11,57.800,0.07693,6.012,0.002
45.29,57.900,0.07710,6.035,0.002
45.40,58.000,0.07726,6.050,0.002
45.56,58.100,0.07743,6.071,0.002
45.67,58.200,0.07759,6.086,0.002
45.82,58.300,0.07776,6.106,0.002
45.95,58.400,0.07793,6.124,0.002
46.15,58.500,0.07809,6.150,0.002
46.31,58.600,0.07826,6.172,0.002
46.52,58.700,0.07843,6.199,0.002
46.68,58.800,0.07863,6.221,0.002
46.89,58.900,0.07884,6.249,0.002
47.07,59.000,0.07901,6.272,0.002
47.25,59.100,0.07922,6.296,0.002
47.42,59.200,0.07942,6.319,0.002
47.63,59.300,0.07967,6.347,0.002
47.83,59.400,0.07988,6.374,0.002
48.08,59.500,0.08009,6.408,0.002
48.27,59.600,0.08030,6.432,0.002
48.45,59.700,0.08050,6.456,0.002
48.65,59.800,0.08071,6.483,0.002
48.86,59.900,0.08092,6.511,0.002
49.05,60.000,0.08113,6.536,0.002
49.26,60.100,0.08133,6.565,0.002
49.48,60.200,0.08150,6.593,0.002
49.62,60.300,0.08171,6.612,0.002
49.78,60.400,0.08187,6.633,0.002
49.97,60.500,0.08204,6.660,0.002
50.14,60.600,0.08225,6.682,0.002
50.26,60.700,0.08241,6.697,0.002
50.16,60.800,0.08258,6.684,0.002
20.20,60.900,0.08271,2.692,0.002
21.29,61.000,0.08287,2.837,0.002
21.66,61.100,0.08304,2.886,0.002
21.88,61.200,0.08316,2.916,0.002
22.07,61.300,0.08333,2.942,0.002
22.26,61.400,0.08345,2.966,0.002
22.44,61.500,0.08358,2.990,0.002
22.58,61.600,0.08374,3.009,0.002
22.77,61.700,0.08387,3.034,0.002
22.97,61.800,0.08399,3.060,0.002
23.13,61.900,0.08416,3.083,0.002
23.27,62.000,0.08428,3.101,0.002
23.47,62.100,0.08441,3.127,0.002
23.61,62.200,0.08453,3.146,0.002
23.80,62.300,0.08470,3.172,0.002
23.98,62.400,0.08483,3.196,0.002
24.13,62.500,0.08499,3.215,0.002
24.25,62.600,0.08512,3.231,0.002
24.44,62.700,0.08528,3.257,0.002
24.59,62.800,0.08541,3.277,0.002
24.75,62.900,0.08557,3.298,0.002
24.89,63.000,0.08574,3.316,0.002
25.05,63.100,0.08586,3.338,0.002
25.18,63.200,0.08603,3.355,0.002
25.33,63.300,0.08620,3.376,0.002
25.51,63.400,0.08636,3.400,0.002
25.67,63.500,0.08649,3.421,0.002
25.81,63.600,0.08665,3.439,0.002
25.96,63.700,0.08682,3.460,0.002
26.11,63.800,0.08699,3.479,0.002
26.20,63.900,0.08715,3.491,0.002
26.29,64.000,0.08728,3.504,0.002
26.49,64.100,0.08744,3.530,0.002
26.57,64.160,0.08757,3.541,0.002