File: data-files/mech3/WH13T.txt
""
"Test Method","Will_Huddleston_Disks.msm"
"Sample I. D.","WH13T.mss"
"Specimen Number","1"

"Load (N)","Time (s)","Extension (mm)","Stress (MPa)","Strain (mm/mm)"

4.56,0.200,-0.05251,0.842,-0.001
4.58,0.300,-0.05251,0.846,-0.001
4.57,0.400,-0.05251,0.844,-0.001
4.57,0.500,-0.05251,0.845,-0.001
4.56,0.600,-0.05247,0.843,-0.001
4.55,0.700,-0.05247,0.841,-0.001
4.54,0.800,-0.05247,0.838,-0.001
4.57,0.900,-0.05243,0.845,-0.001
4.56,1.000,-0.05243,0.842,-0.001
4.55,1.100,-0.05238,0.842,-0.001
4.55,1.200,-0.05238,0.841,-0.001
4.58,1.300,-0.05238,0.847,-0.001
4.58,1.400,-0.05234,0.846,-0.001
4.58,1.500,-0.05234,0.845,-0.001
4.59,1.600,-0.05230,0.849,-0.001
4.57,1.700,-0.05226,0.844,-0.001
4.57,1.800,-0.05222,0.844,-0.001
4.60,1.900,-0.05218,0.849,-0.001
4.66,2.000,-0.05209,0.861,-0.001
4.68,2.100,-0.05197,0.864,-0.001
4.74,2.200,-0.05176,0.876,-0.001
4.83,2.300,-0.05155,0.893,-0.001
4.90,2.400,-0.05135,0.905,-0.001
4.95,2.500,-0.05114,0.915,-0.001
5.06,2.600,-0.05093,0.936,-0.001
5.06,2.700,-0.05076,0.936,-0.001
5.11,2.800,-0.05056,0.944,-0.001
5.16,2.900,-0.05039,0.953,-0.001
5.19,3.000,-0.05018,0.959,-0.001
5.24,3.100,-0.05002,0.968,-0.001
5.30,3.200,-0.04981,0.980,-0.001
5.30,3.300,-0.04964,0.980,-0.001
5.34,3.400,-0.04948,0.986,-0.001
5.37,3.500,-0.04931,0.992,-0.001
5.41,3.600,-0.04918,0.999,-0.001
5.45,3.700,-0.04902,1.008,-0.001
5.46,3.800,-0.04885,1.009,-0.001
5.51,3.900,-0.04873,1.018,-0.001
5.51,4.000,-0.04860,1.018,-0.001
5.52,4.100,-0.04844,1.020,-0.001
5.58,4.200,-0.04831,1.031,-0.001
5.59,4.300,-0.04815,1.032,-0.001
5.59,4.400,-0.04802,1.032,-0.001
5.66,4.500,-0.04790,1.045,-0.001
5.67,4.600,-0.04777,1.047,-0.001
5.70,4.700,-0.04765,1.053,-0.001
5.74,4.800,-0.04748,1.060,-0.001
5.75,4.900,-0.04736,1.063,-0.001
5.80,5.000,-0.04723,1.071,-0.001
5.83,5.100,-0.04706,1.077,-0.001
5.82,5.200,-0.04694,1.075,-0.001
5.85,5.300,-0.04682,1.082,-0.001
5.93,5.400,-0.04665,1.096,-0.001
5.91,5.500,-0.04652,1.092,-0.001
5.95,5.600,-0.04640,1.099,-0.001
5.97,5.700,-0.04623,1.103,-0.001
6.00,5.800,-0.04611,1.108,-0.001
6.05,5.900,-0.04594,1.118,-0.001
6.08,6.000,-0.04582,1.123,-0.001
6.14,6.100,-0.04565,1.134,-0.001
6.15,6.200,-0.04549,1.137,-0.001
6.19,6.300,-0.04536,1.144,-0.001
6.21,6.400,-0.04519,1.147,-0.001
6.23,6.500,-0.04503,1.152,-0.001
6.27,6.600,-0.04490,1.158,-0.001
6.25,6.700,-0.04474,1.155,-0.001
6.31,6.800,-0.04457,1.167,-0.001
6.33,6.900,-0.04441,1.170,-0.001
6.42,7.000,-0.04424,1.187,-0.001
6.44,7.100,-0.04407,1.189,-0.001
6.46,7.200,-0.04391,1.193,-0.001
6.49,7.300,-0.04374,1.199,-0.001
6.54,7.400,-0.04357,1.209,-0.001
6.60,7.500,-0.04337,1.219,-0.001
6.62,7.600,-0.04320,1.223,-0.001
6.67,7.700,-0.04299,1.232,-0.001
6.72,7.800,-0.04278,1.241,-0.001
6.77,7.900,-0.04258,1.251,-0.001
6.79,8.000,-0.04237,1.255,-0.001
6.81,8.100,-0.04216,1.258,-0.001
6.85,8.200,-0.04191,1.266,-0.001
6.92,8.300,-0.04170,1.279,-0.001
6.97,8.400,-0.04150,1.288,-0.001
6.99,8.500,-0.04129,1.292,-0.001
7.03,8.600,-0.04108,1.299,-0.001
7.08,8.700,-0.04087,1.308,-0.001
7.11,8.800,-0.04067,1.314,-0.001
7.19,8.900,-0.04050,1.328,-0.001
7.20,9.000,-0.04029,1.331,-0.001
7.25,9.100,-0.04013,1.339,-0.001
7.26,9.200,-0.03996,1.342,-0.001
7.32,9.300,-0.03979,1.352,-0.001
7.33,9.400,-0.03963,1.355,-0.001
7.33,9.500,-0.03946,1.355,-0.001
7.41,9.600,-0.03929,1.370,-0.001
7.40,9.700,-0.03917,1.368,-0.001
7.44,9.800,-0.03900,1.375,-0.001
7.47,9.900,-0.03888,1.379,-0.001
7.49,10.000,-0.03871,1.384,-0.001
7.54,10.100,-0.03859,1.393,-0.001
7.56,10.200,-0.03846,1.398,-0.001
7.58,10.300,-0.03830,1.401,-0.001
7.62,10.400,-0.03817,1.408,-0.001
7.64,10.500,-0.03805,1.413,-0.001
7.67,10.600,-0.03788,1.417,-0.001
7.72,10.700,-0.03776,1.427,-0.001
7.74,10.800,-0.03759,1.431,-0.001
7.76,10.900,-0.03747,1.434,-0.001
7.79,11.000,-0.03730,1.439,-0.001
7.82,11.100,-0.03717,1.445,-0.001
7.87,11.200,-0.03701,1.454,-0.001
7.88,11.300,-0.03688,1.457,-0.001
7.93,11.400,-0.03672,1.465,-0.001
7.93,11.500,-0.03655,1.466,-0.001
8.01,11.600,-0.03643,1.480,-0.001
8.04,11.700,-0.03626,1.485,-0.001
8.06,11.800,-0.03609,1.489,-0.001
8.10,11.900,-0.03593,1.496,-0.001
8.13,12.000,-0.03580,1.502,-0.001
8.15,12.100,-0.03564,1.506,-0.001
8.20,12.200,-0.03547,1.515,-0.001
8.23,12.300,-0.03535,1.520,-0.001
8.29,12.400,-0.03518,1.531,-0.001
8.27,12.500,-0.03501,1.529,-0.001
8.33,12.600,-0.03485,1.538,-0.001
8.37,12.700,-0.03468,1.546,-0.001
8.39,12.800,-0.03452,1.550,-0.001
8.43,12.900,-0.03435,1.558,-0.001
8.44,13.000,-0.03414,1.560,-0.001
8.48,13.100,-0.03397,1.566,-0.001
8.55,13.200,-0.03377,1.580,-0.001
8.59,13.300,-0.03356,1.587,-0.001
8.61,13.400,-0.03339,1.591,-0.001
8.67,13.500,-0.03319,1.602,-0.001
8.74,13.600,-0.03298,1.615,-0.001
8.78,13.700,-0.03273,1.622,-0.001
8.83,13.800,-0.03252,1.631,-0.001
8.86,13.900,-0.03231,1.637,-0.001
8.91,14.000,-0.03210,1.646,-0.001
8.95,14.100,-0.03190,1.655,-0.001
8.99,14.200,-0.03169,1.661,-0.001
9.02,14.300,-0.03148,1.667,-0.001
9.08,14.400,-0.03127,1.678,-0.001
9.12,14.500,-0.03107,1.684,-0.001
9.15,14.600,-0.03090,1.691,-0.001
9.21,14.700,-0.03069,1.701,-0.001
9.25,14.800,-0.03053,1.708,-0.001
9.28,14.900,-0.03036,1.715,-0.001
9.32,15.000,-0.03019,1.722,-0.001
9.34,15.100,-0.03003,1.725,-0.001
9.38,15.200,-0.02986,1.733,-0.001
9.43,15.300,-0.02969,1.742,-0.001
9.45,15.400,-0.02953,1.747,-0.001
9.49,15.500,-0.02940,1.754,-0.001
9.54,15.600,-0.02924,1.762,-0.001
9.55,15.700,-0.02911,1.764,-0.001
9.59,15.800,-0.02899,1.771,-0.001
9.61,15.900,-0.02882,1.776,-0.001
9.63,16.000,-0.02870,1.780,-0.001
9.67,16.100,-0.02853,1.787,-0.001
9.72,16.200,-0.02841,1.797,-0.001
9.74,16.300,-0.02828,1.799,-0.001
9.77,16.400,-0.02812,1.806,-0.001
9.81,16.500,-0.02799,1.812,-0.001
9.83,16.600,-0.02782,1.816,-0.001
9.86,16.700,-0.02770,1.822,-0.001
9.91,16.800,-0.02753,1.832,-0.001
9.94,16.900,-0.02737,1.837,-0.001
9.99,17.000,-0.02724,1.845,-0.001
10.03,17.100,-0.02708,1.853,-0.001
10.07,17.200,-0.02691,1.860,-0.001
10.08,17.300,-0.02674,1.863,-0.001
10.14,17.400,-0.02662,1.874,-0.001
10.17,17.500,-0.02645,1.880,-0.001
10.25,17.600,-0.02629,1.893,-0.001
10.27,17.700,-0.02612,1.899,-0.001
10.29,17.800,-0.02600,1.902,-0.001
10.32,17.900,-0.02583,1.907,-0.001
10.36,18.000,-0.02566,1.914,-0.001
10.41,18.100,-0.02550,1.923,-0.001
10.46,18.200,-0.02533,1.933,0.000
10.48,18.300,-0.02517,1.937,0.000
10.53,18.400,-0.02500,1.946,0.000
10.56,18.500,-0.02479,1.952,0.000
10.61,18.600,-0.02462,1.960,0.000
10.65,18.700,-0.02446,1.967,0.000
10.71,18.800,-0.02425,1.979,0.000
10.74,18.900,-0.02404,1.985,0.000
10.79,19.000,-0.02388,1.993,0.000
10.84,19.100,-0.02367,2.003,0.000
10.90,19.200,-0.02346,2.014,0.000
10.96,19.300,-0.02325,2.024,0.000
11.01,19.400,-0.02305,2.034,0.000
11.09,19.500,-0.02284,2.049,0.000
11.12,19.600,-0.02263,2.055,0.000
11.16,19.700,-0.02238,2.062,0.000
11.23,19.800,-0.02217,2.074,0.000
11.26,19.900,-0.02197,2.080,0.000
11.30,20.000,-0.02180,2.088,0.000
11.35,20.100,-0.02159,2.097,0.000
11.39,20.200,-0.02138,2.104,0.000
11.45,20.300,-0.02122,2.115,0.000
11.46,20.400,-0.02105,2.118,0.000
11.49,20.500,-0.02088,2.124,0.000
11.55,20.600,-0.02072,2.135,0.000
11.59,20.700,-0.02055,2.142,0.000
11.63,20.800,-0.02043,2.148,0.000
11.63,20.900,-0.02026,2.150,0.000
11.66,21.000,-0.02010,2.155,0.000
11.71,21.100,-0.01997,2.163,0.000
11.75,21.200,-0.01980,2.172,0.000
11.78,21.300,-0.01968,2.176,0.000
11.83,21.400,-0.01955,2.186,0.000
11.87,21.500,-0.01939,2.193,0.000
11.90,21.600,-0.01926,2.200,0.000
11.94,21.700,-0.01914,2.207,0.000
11.97,21.800,-0.01901,2.211,0.000
11.99,21.900,-0.01885,2.215,0.000
12.02,22.000,-0.01872,2.221,0.000
12.08,22.100,-0.01856,2.232,0.000
12.09,22.200,-0.01843,2.235,0.000
12.11,22.300,-0.01827,2.238,0.000
12.17,22.400,-0.01814,2.249,0.000
12.18,22.500,-0.01798,2.251,0.000
12.23,22.600,-0.01785,2.259,0.000
12.29,22.700,-0.01768,2.272,0.000
12.33,22.800,-0.01752,2.279,0.000
12.36,22.900,-0.01739,2.283,0.000
12.44,23.000,-0.01723,2.298,0.000
12.45,23.100,-0.01706,2.300,0.000
12.52,23.200,-0.01694,2.313,0.000
12.53,23.300,-0.01677,2.315,0.000
12.58,23.400,-0.01660,2.324,0.000
12.58,23.500,-0.01648,2.325,0.000
12.64,23.600,-0.01631,2.335,0.000
12.69,23.700,-0.01615,2.345,0.000
12.67,23.800,-0.01598,2.342,0.000
12.78,23.900,-0.01581,2.362,0.000
12.77,24.000,-0.01565,2.359,0.000
12.85,24.100,-0.01548,2.374,0.000
12.88,24.200,-0.01532,2.380,0.000
12.94,24.300,-0.01515,2.391,0.000
12.99,24.400,-0.01494,2.401,0.000
13.08,24.500,-0.01473,2.417,0.000
13.10,24.600,-0.01453,2.421,0.000
13.19,24.700,-0.01436,2.437,0.000
13.22,24.800,-0.01415,2.442,0.000
13.28,24.900,-0.01390,2.455,0.000
13.32,25.000,-0.01370,2.462,0.000
13.38,25.100,-0.01349,2.472,0.000
13.47,25.200,-0.01328,2.489,0.000
13.51,25.300,-0.01307,2.497,0.000
13.56,25.400,-0.01286,2.505,0.000
13.63,25.500,-0.01266,2.518,0.000
13.68,25.600,-0.01245,2.528,0.000
13.74,25.700,-0.01224,2.540,0.000
13.79,25.800,-0.01207,2.548,0.000
13.83,25.900,-0.01187,2.555,0.000
13.87,26.000,-0.01170,2.563,0.000
13.89,26.100,-0.01153,2.566,0.000
13.94,26.200,-0.01137,2.575,0.000
13.94,26.300,-0.01124,2.576,0.000
13.95,26.400,-0.01108,2.577,0.000
14.04,26.500,-0.01095,2.594,0.000
14.08,26.600,-0.01079,2.602,0.000
14.10,26.700,-0.01066,2.606,0.000
14.14,26.800,-0.01050,2.612,0.000
14.17,26.900,-0.01037,2.618,0.000
14.19,27.000,-0.01025,2.622,0.000
14.24,27.100,-0.01012,2.630,0.000
14.27,27.200,-0.00996,2.638,0.000
14.30,27.300,-0.00983,2.642,0.000
14.35,27.400,-0.00971,2.652,0.000
14.34,27.500,-0.00958,2.650,0.000
14.40,27.600,-0.00946,2.662,0.000
14.39,27.700,-0.00929,2.658,0.000
14.45,27.800,-0.00917,2.670,0.000
14.50,27.900,-0.00900,2.679,0.000
14.54,28.000,-0.00888,2.686,0.000
14.58,28.100,-0.00875,2.695,0.000
14.64,28.200,-0.00858,2.704,0.000
14.65,28.300,-0.00842,2.707,0.000
14.71,28.400,-0.00829,2.718,0.000
14.76,28.500,-0.00813,2.728,0.000
14.82,28.600,-0.00800,2.739,0.000
14.84,28.700,-0.00784,2.742,0.000
14.88,28.800,-0.00771,2.749,0.000
14.90,28.900,-0.00755,2.753,0.000
14.96,29.000,-0.00738,2.763,0.000
15.00,29.100,-0.00725,2.772,0.000
15.03,29.200,-0.00709,2.777,0.000
15.08,29.300,-0.00692,2.786,0.000
15.14,29.400,-0.00676,2.798,0.000
15.18,29.500,-0.00663,2.805,0.000
15.20,29.600,-0.00646,2.809,0.000
15.23,29.700,-0.00630,2.814,0.000
15.30,29.800,-0.00613,2.826,0.000
15.33,29.900,-0.00597,2.833,0.000
15.40,30.000,-0.00580,2.846,0.000
15.44,30.100,-0.00559,2.852,0.000
15.49,30.200,-0.00543,2.862,0.000
15.54,30.300,-0.00522,2.872,0.000
15.60,30.400,-0.00501,2.882,0.000
15.66,30.500,-0.00484,2.893,0.000
15.70,30.600,-0.00464,2.902,0.000
15.77,30.700,-0.00439,2.914,0.000
15.78,30.800,-0.00418,2.916,0.000
15.85,30.900,-0.00397,2.929,0.000
15.93,31.000,-0.00376,2.943,0.000
15.96,31.100,-0.00360,2.948,0.000
16.01,31.200,-0.00339,2.959,0.000
16.07,31.300,-0.00318,2.970,0.000
16.13,31.400,-0.00297,2.981,0.000
16.17,31.500,-0.00281,2.987,0.000
16.22,31.600,-0.00260,2.997,0.000
16.27,31.700,-0.00243,3.006,0.000
16.30,31.800,-0.00227,3.011,0.000
16.35,31.900,-0.00210,3.021,0.000
16.39,32.000,-0.00194,3.028,0.000
16.42,32.100,-0.00177,3.035,0.000
16.47,32.200,-0.00164,3.043,0.000
16.50,32.300,-0.00148,3.048,0.000
16.53,32.400,-0.00135,3.054,0.000
16.60,32.500,-0.00119,3.067,0.000
16.60,32.600,-0.00106,3.068,0.000
16.65,32.700,-0.00090,3.076,0.000
16.67,32.800,-0.00077,3.081,0.000
16.71,32.900,-0.00065,3.087,0.000
16.75,33.000,-0.00048,3.096,0.000
16.79,33.100,-0.00036,3.102,0.000
16.83,33.200,-0.00023,3.110,0.000
16.85,33.300,-0.00011,3.113,0.000
16.88,33.400,0.00006,3.119,0.000
16.95,33.500,0.00018,3.132,0.000
16.97,33.600,0.00031,3.136,0.000
17.02,33.700,0.00047,3.144,0.000
17.05,33.800,0.00060,3.151,0.000
17.08,33.900,0.00077,3.157,0.000
17.14,34.000,0.00089,3.168,0.000
17.17,34.100,0.00106,3.172,0.000
17.21,34.200,0.00118,3.181,0.000
17.28,34.300,0.00135,3.192,0.000
17.32,34.400,0.00151,3.201,0.000
17.36,34.500,0.00164,3.208,0.000
17.44,34.600,0.00180,3.223,0.000
17.48,34.700,0.00197,3.229,0.000
17.50,34.800,0.00210,3.234,0.000
17.52,34.900,0.00226,3.238,0.000
17.57,35.000,0.00243,3.246,0.000
17.61,35.100,0.00259,3.254,0.000
17.66,35.200,0.00272,3.263,0.000
17.70,35.300,0.00289,3.270,0.000
17.68,35.400,0.00305,3.267,0.000
17.82,35.500,0.00322,3.293,0.000
17.86,35.600,0.00338,3.300,0.000
17.91,35.700,0.00359,3.309,0.000
17.97,35.800,0.00376,3.321,0.000
18.02,35.900,0.00397,3.331,0.000
18.09,36.000,0.00413,3.343,0.000
18.16,36.100,0.00434,3.355,0.000
18.20,36.200,0.00451,3.363,0.000
18.25,36.300,0.00471,3.373,0.000
18.30,36.400,0.00492,3.382,0.000
18.38,36.500,0.00513,3.397,0.000
18.44,36.600,0.00534,3.407,0.000
18.51,36.700,0.00554,3.420,0.000
18.57,36.800,0.00575,3.431,0.000
18.66,36.900,0.00596,3.448,0.000
18.68,37.000,0.00617,3.451,0.000
18.77,37.100,0.00633,3.468,0.000
18.81,37.200,0.00654,3.476,0.000
18.87,37.300,0.00671,3.487,0.000
18.93,37.400,0.00692,3.497,0.000
18.96,37.500,0.00708,3.503,0.000
19.02,37.600,0.00725,3.514,0.000
19.06,37.700,0.00741,3.523,0.000
19.13,37.800,0.00758,3.534,0.000
19.16,37.900,0.00775,3.540,0.000
19.22,38.000,0.00787,3.552,0.000
19.24,38.100,0.00804,3.556,0.000
19.35,38.200,0.00820,3.575,0.000
19.39,38.300,0.00833,3.583,0.000
19.42,38.400,0.00845,3.589,0.000
19.45,38.500,0.00862,3.594,0.000
19.53,38.600,0.00874,3.608,0.000
19.53,38.700,0.00887,3.609,0.000
19.57,38.800,0.00904,3.616,0.000
19.61,38.900,0.00916,3.624,0.000
19.66,39.000,0.00928,3.633,0.000
19.75,39.100,0.00941,3.650,0.000
19.77,39.200,0.00953,3.654,0.000
19.83,39.300,0.00970,3.664,0.000
19.88,39.400,0.00982,3.673,0.000
19.93,39.500,0.00995,3.682,0.000
19.99,39.600,0.01012,3.695,0.000
20.02,39.700,0.01024,3.700,0.000
20.11,39.800,0.01041,3.715,0.000
20.14,39.900,0.01053,3.722,0.000
20.21,40.000,0.01070,3.734,0.000
20.29,40.100,0.01082,3.748,0.000
20.33,40.200,0.01099,3.757,0.000
20.36,40.300,0.01115,3.762,0.000
20.44,40.400,0.01128,3.777,0.000
20.47,40.500,0.01145,3.782,0.000
20.52,40.600,0.01157,3.792,0.000
20.59,40.700,0.01174,3.804,0.000
20.64,40.800,0.01190,3.813,0.000
20.70,40.900,0.01203,3.825,0.000
20.79,41.000,0.01219,3.842,0.000
20.83,41.100,0.01236,3.848,0.000
20.90,41.200,0.01253,3.862,0.000
20.95,41.300,0.01269,3.871,0.000
21.05,41.400,0.01286,3.889,0.000
21.13,41.500,0.01302,3.905,0.000
21.20,41.600,0.01323,3.917,0.000
21.27,41.700,0.01340,3.929,0.000
21.38,41.800,0.01361,3.950,0.000
21.45,41.900,0.01381,3.963,0.000
21.54,42.000,0.01398,3.980,0.000
21.64,42.100,0.01419,3.998,0.000
21.70,42.200,0.01440,4.010,0.000
21.79,42.300,0.01460,4.027,0.000
21.89,42.400,0.01485,4.044,0.000
21.99,42.500,0.01506,4.062,0.000
22.09,42.600,0.01527,4.082,0.000
22.16,42.700,0.01548,4.095,0.000
22.25,42.800,0.01568,4.111,0.000
22.34,42.900,0.01585,4.129,0.000
22.44,43.000,0.01606,4.147,0.000
22.49,43.100,0.01627,4.155,0.000
22.57,43.200,0.01643,4.170,0.000
22.64,43.300,0.01660,4.183,0.000
22.72,43.400,0.01676,4.199,0.000
22.79,43.500,0.01693,4.211,0.000
22.90,43.600,0.01710,4.231,0.000
22.92,43.700,0.01726,4.234,0.000
23.00,43.800,0.01739,4.249,0.000
23.06,43.900,0.01755,4.261,0.000
23.11,44.000,0.01768,4.271,0.000
23.17,44.100,0.01785,4.282,0.000
23.24,44.200,0.01797,4.294,0.000
23.32,44.300,0.01814,4.308,0.000
23.35,44.400,0.01826,4.315,0.000
23.40,44.500,0.01839,4.324,0.000
23.46,44.600,0.01851,4.335,0.000
23.55,44.700,0.01868,4.351,0.000
23.62,44.800,0.01880,4.364,0.000
23.69,44.900,0.01893,4.377,0.000
23.74,45.000,0.01909,4.386,0.000
23.84,45.100,0.01922,4.404,0.000
23.88,45.200,0.01934,4.412,0.000
23.96,45.300,0.01951,4.426,0.000
24.03,45.400,0.01963,4.441,0.000
24.12,45.500,0.01980,4.458,0.000
24.19,45.600,0.01996,4.469,0.000
24.27,45.700,0.02013,4.484,0.000
24.34,45.800,0.02026,4.497,0.000
24.41,45.900,0.02042,4.510,0.000
24.49,46.000,0.02059,4.525,0.000
24.57,46.100,0.02071,4.541,0.000
24.62,46.200,0.02088,4.550,0.000
24.73,46.300,0.02105,4.569,0.000
24.79,46.400,0.02121,4.581,0.000
24.86,46.500,0.02134,4.594,0.000
24.96,46.600,0.02150,4.613,0.000
25.03,46.700,0.02167,4.626,0.000
25.10,46.800,0.02183,4.637,0.000
25.17,46.900,0.02200,4.650,0.000
25.27,47.000,0.02217,4.669,0.000
25.34,47.100,0.02233,4.682,0.000
25.45,47.200,0.02254,4.702,0.000
25.56,47.300,0.02271,4.723,0.000
25.66,47.400,0.02292,4.742,0.000
25.79,47.500,0.02312,4.765,0.000
25.84,47.600,0.02333,4.774,0.000
25.97,47.700,0.02354,4.798,0.000
26.10,47.800,0.02375,4.822,0.000
26.21,47.900,0.02395,4.843,0.000
26.34,48.000,0.02420,4.868,0.000
26.47,48.100,0.02441,4.890,0.000
26.58,48.200,0.02462,4.911,0.000
26.68,48.300,0.02483,4.930,0.000
26.79,48.400,0.02503,4.951,0.000
26.90,48.500,0.02524,4.970,0.000
27.01,48.600,0.02545,4.990,0.001
27.11,48.700,0.02562,5.010,0.001
27.25,48.800,0.02582,5.035,0.001
27.32,48.900,0.02603,5.048,0.001
27.43,49.000,0.02620,5.067,0.001
27.49,49.100,0.02636,5.080,0.001
27.55,49.200,0.02653,5.091,0.001
27.67,49.300,0.02666,5.113,0.001
27.74,49.400,0.02682,5.127,0.001
27.81,49.500,0.02699,5.138,0.001
27.91,49.600,0.02711,5.156,0.001
27.97,49.700,0.02728,5.168,0.001
28.06,49.800,0.02740,5.184,0.001
28.13,49.900,0.02757,5.199,0.001
28.20,50.000,0.02769,5.210,0.001
28.27,50.100,0.02782,5.223,0.001
28.34,50.200,0.02794,5.237,0.001
28.43,50.300,0.02811,5.253,0.001
28.49,50.400,0.02823,5.264,0.001
28.60,50.500,0.02836,5.284,0.001
28.65,50.600,0.02853,5.295,0.001
28.73,50.700,0.02865,5.309,0.001
28.83,50.800,0.02882,5.327,0.001
28.90,50.900,0.02894,5.341,0.001
28.99,51.000,0.02911,5.356,0.001
29.07,51.100,0.02923,5.372,0.001
29.16,51.200,0.02940,5.388,0.001
29.25,51.300,0.02952,5.405,0.001
29.36,51.400,0.02969,5.425,0.001
29.44,51.500,0.02985,5.439,0.001
29.52,51.600,0.03002,5.455,0.001
29.63,51.700,0.03015,5.474,0.001
29.71,51.800,0.03031,5.490,0.001
29.77,51.900,0.03048,5.500,0.001
29.88,52.000,0.03060,5.521,0.001
29.99,52.100,0.03077,5.541,0.001
30.07,52.200,0.03094,5.556,0.001
30.17,52.300,0.03110,5.576,0.001
30.25,52.400,0.03127,5.590,0.001
30.39,52.500,0.03143,5.616,0.001
30.46,52.600,0.03160,5.628,0.001
30.55,52.700,0.03177,5.645,0.001
30.65,52.800,0.03193,5.663,0.001
30.76,52.900,0.03214,5.684,0.001
30.88,53.000,0.03231,5.705,0.001
31.04,53.100,0.03251,5.735,0.001
31.18,53.200,0.03272,5.761,0.001
31.26,53.300,0.03293,5.775,0.001
31.39,53.400,0.03314,5.800,0.001
31.54,53.500,0.03335,5.828,0.001
31.67,53.600,0.03355,5.851,0.001
31.79,53.700,0.03376,5.875,0.001
31.91,53.800,0.03397,5.897,0.001
32.03,53.900,0.03418,5.919,0.001
32.16,54.000,0.03434,5.942,0.001
32.27,54.100,0.03455,5.963,0.001
32.39,54.200,0.03476,5.985,0.001
32.49,54.300,0.03492,6.004,0.001
32.62,54.400,0.03513,6.027,0.001
32.69,54.500,0.03530,6.040,0.001
32.78,54.600,0.03546,6.057,0.001
32.92,54.700,0.03567,6.083,0.001
33.02,54.800,0.03580,6.102,0.001
33.08,54.900,0.03596,6.113,0.001
33.19,55.000,0.03613,6.133,0.001
33.27,55.100,0.03630,6.148,0.001
33.38,55.200,0.03642,6.168,0.001
33.44,55.300,0.03659,6.179,0.001
33.57,55.400,0.03675,6.204,0.001
33.62,55.500,0.03688,6.212,0.001
33.73,55.600,0.03700,6.232,0.001
33.80,55.700,0.03717,6.245,0.001
33.87,55.800,0.03729,6.259,0.001
33.97,55.900,0.03746,6.277,0.001
34.04,56.000,0.03758,6.290,0.001
34.14,56.100,0.03771,6.308,0.001
34.24,56.200,0.03783,6.326,0.001
34.32,56.300,0.03796,6.342,0.001
34.40,56.400,0.03812,6.355,0.001
34.49,56.500,0.03825,6.372,0.001
34.58,56.600,0.03842,6.389,0.001
34.67,56.700,0.03854,6.406,0.001
34.80,56.800,0.03871,6.429,0.001
34.87,56.900,0.03883,6.444,0.001
34.98,57.000,0.03900,6.463,0.001
35.07,57.100,0.03916,6.480,0.001
35.16,57.200,0.03929,6.497,0.001
35.27,57.300,0.03945,6.518,0.001
35.37,57.400,0.03958,6.536,0.001
35.47,57.500,0.03975,6.554,0.001
35.59,57.600,0.03991,6.576,0.001
35.67,57.700,0.04008,6.591,0.001
35.78,57.800,0.04024,6.612,0.001
35.87,57.900,0.04037,6.628,0.001
35.98,58.000,0.04053,6.649,0.001
36.09,58.100,0.04070,6.669,0.001
36.21,58.200,0.04087,6.690,0.001
36.31,58.300,0.04103,6.709,0.001
36.43,58.400,0.04120,6.730,0.001
36.55,58.500,0.04141,6.753,0.001
36.67,58.600,0.04157,6.776,0.001
36.79,58.700,0.04178,6.798,0.001
36.93,58.800,0.04195,6.824,0.001
37.07,58.900,0.04216,6.850,0.001
37.20,59.000,0.04236,6.874,0.001
37.33,59.100,0.04257,6.898,0.001
37.48,59.200,0.04278,6.926,0.001
37.63,59.300,0.04303,6.954,0.001
37.76,59.400,0.04324,6.977,0.001
37.90,59.500,0.04344,7.004,0.001
38.04,59.600,0.04365,7.030,0.001
38.18,59.700,0.04386,7.054,0.001
38.34,59.800,0.04407,7.083,0.001
38.47,59.900,0.04427,7.108,0.001
38.61,60.000,0.04448,7.135,0.001
38.73,60.100,0.04465,7.157,0.001
38.84,60.200,0.04486,7.177,0.001
38.95,60.300,0.04502,7.197,0.001
39.06,60.400,0.04519,7.216,0.001
39.16,60.500,0.04536,7.237,0.001
39.24,60.600,0.04552,7.251,0.001
39.39,60.700,0.04569,7.278,0.001
39.49,60.800,0.04581,7.297,0.001
39.59,60.900,0.04598,7.315,0.001
39.67,61.000,0.04610,7.329,0.001
39.77,61.100,0.04627,7.349,0.001
39.86,61.200,0.04639,7.364,0.001
39.97,61.300,0.04652,7.385,0.001
40.06,61.400,0.04669,7.402,0.001
40.15,61.500,0.04681,7.418,0.001
40.23,61.600,0.04693,7.433,0.001
40.32,61.700,0.04710,7.451,0.001
40.41,61.800,0.04723,7.467,0.001
40.55,61.900,0.04735,7.492,0.001
40.63,62.000,0.04747,7.507,0.001
40.74,62.100,0.04764,7.528,0.001
40.84,62.200,0.04777,7.547,0.001
40.94,62.300,0.04793,7.564,0.001
41.03,62.400,0.04806,7.581,0.001
41.15,62.500,0.04822,7.604,0.001
41.27,62.600,0.04839,7.625,0.001
41.39,62.700,0.04851,7.648,0.001
41.52,62.800,0.04868,7.671,0.001
41.61,62.900,0.04885,7.689,0.001
41.75,63.000,0.04897,7.714,0.001
41.86,63.100,0.04914,7.734,0.001
41.96,63.200,0.04930,7.753,0.001
42.09,63.300,0.04943,7.777,0.001
42.19,63.400,0.04959,7.796,0.001
42.30,63.500,0.04976,7.816,0.001
42.42,63.600,0.04993,7.838,0.001
42.53,63.700,0.05005,7.859,0.001
42.66,63.800,0.05022,7.882,0.001
42.78,63.900,0.05038,7.904,0.001
42.90,64.000,0.05055,7.927,0.001
43.03,64.100,0.05072,7.952,0.001
43.18,64.200,0.05092,7.979,0.001
43.32,64.300,0.05109,8.005,0.001
43.46,64.400,0.05130,8.031,0.001
43.62,64.500,0.05151,8.061,0.001
43.78,64.600,0.05167,8.090,0.001
43.93,64.700,0.05188,8.117,0.001
44.10,64.800,0.05209,8.149,0.001
44.25,64.900,0.05230,8.176,0.001
44.41,65.000,0.05254,8.206,0.001
44.57,65.100,0.05275,8.236,0.001
44.72,65.200,0.05296,8.263,0.001
44.88,65.300,0.05317,8.292,0.001
45.03,65.400,0.05338,8.320,0.001
45.21,65.500,0.05358,8.354,0.001
45.35,65.600,0.05375,8.380,0.001
45.50,65.700,0.05396,8.407,0.001
45.66,65.800,0.05417,8.437,0.001
45.77,65.900,0.05433,8.457,0.001
45.92,66.000,0.05450,8.485,0.001
46.07,66.100,0.05466,8.512,0.001
46.19,66.200,0.05483,8.534,0.001
46.32,66.300,0.05500,8.560,0.001
46.45,66.400,0.05516,8.583,0.001
46.56,66.500,0.05533,8.604,0.001
46.66,66.600,0.05545,8.622,0.001
46.81,66.700,0.05562,8.649,0.001
46.91,66.800,0.05574,8.668,0.001
47.06,66.900,0.05591,8.695,0.001
47.15,67.000,0.05604,8.712,0.001
47.23,67.100,0.05616,8.728,0.001
47.35,67.200,0.05628,8.749,0.001
47.48,67.300,0.05645,8.772,0.001
47.60,67.400,0.05658,8.796,0.001
47.71,67.500,0.05670,8.816,0.001
47.83,67.600,0.05687,8.838,0.001
47.96,67.700,0.05699,8.862,0.001
48.08,67.800,0.05716,8.884,0.001
48.18,67.900,0.05728,8.903,0.001
48.31,68.000,0.05745,8.926,0.001
48.46,68.100,0.05757,8.955,0.001
48.58,68.200,0.05774,8.977,0.001
48.69,68.300,0.05786,8.997,0.001
48.83,68.400,0.05803,9.022,0.001
48.95,68.500,0.05820,9.044,0.001
49.09,68.600,0.05832,9.071,0.001
49.22,68.700,0.05849,9.095,0.001
49.35,68.800,0.05865,9.119,0.001
49.47,68.900,0.05882,9.141,0.001
49.61,69.000,0.05899,9.167,0.001
49.75,69.100,0.05911,9.193,0.001
49.88,69.200,0.05928,9.216,0.001
50.01,69.300,0.05944,9.241,0.001
50.14,69.400,0.05961,9.265,0.001
50.29,69.500,0.05978,9.293,0.001
50.41,69.600,0.05994,9.314,0.001
50.56,69.700,0.06011,9.343,0.001
50.72,69.800,0.06027,9.372,0.001
50.90,69.900,0.06044,9.405,0.001
51.03,70.000,0.06065,9.430,0.001
51.20,70.100,0.06081,9.461,0.001
51.36,70.200,0.06102,9.490,0.001
51.54,70.300,0.06123,9.524,0.001
51.72,70.400,0.06144,9.556,0.001
51.88,70.500,0.06165,9.587,0.001
52.07,70.600,0.06185,9.622,0.001
52.26,70.700,0.06206,9.657,0.001
52.44,70.800,0.06227,9.689,0.001
52.64,70.900,0.06248,9.726,0.001
52.82,71.000,0.06268,9.759,0.001
52.98,71.100,0.06289,9.789,0.001
53.16,71.200,0.06306,9.823,0.001
53.33,71.300,0.06327,9.854,0.001
53.49,71.400,0.06347,9.884,0.001
53.63,71.500,0.06364,9.910,0.001
53.83,71.600,0.06381,9.946,0.001
53.98,71.700,0.06401,9.975,0.001
54.11,71.800,0.06418,9.998,0.001
54.25,71.900,0.06430,10.024,0.001
54.39,72.000,0.06447,10.049,0.001
54.50,72.100,0.06464,10.071,0.001
54.67,72.200,0.06476,10.102,0.001
54.79,72.300,0.06493,10.124,0.001
54.89,72.400,0.06509,10.143,0.001
55.03,72.500,0.06522,10.168,0.001
55.13,72.600,0.06534,10.187,0.001
55.24,72.700,0.06551,10.208,0.001
30.09,72.800,0.06563,5.560,0.001
22.93,72.900,0.06576,4.237,0.001
22.50,73.000,0.06588,4.157,0.001
22.59,73.100,0.06605,4.175,0.001
22.80,73.200,0.06617,4.212,0.001
22.98,73.300,0.06630,4.247,0.001
23.19,73.400,0.06647,4.284,0.001
23.40,73.500,0.06659,4.324,0.001
23.57,73.600,0.06671,4.354,0.001
23.77,73.700,0.06688,4.392,0.001
23.94,73.800,0.06701,4.423,0.001
24.13,73.900,0.06717,4.459,0.001
24.33,74.000,0.06730,4.495,0.001
24.52,74.100,0.06746,4.530,0.001
24.69,74.200,0.06759,4.562,0.001
24.88,74.300,0.06775,4.598,0.001
25.05,74.400,0.06792,4.628,0.001
25.23,74.500,0.06809,4.661,0.001
25.40,74.600,0.06821,4.693,0.001
25.57,74.700,0.06838,4.725,0.001
25.73,74.800,0.06854,4.755,0.001
25.88,74.900,0.06867,4.781,0.001
26.01,75.000,0.06883,4.807,0.001
26.16,75.100,0.06900,4.834,0.001
26.20,75.130,0.06904,4.842,0.001