File: data-files/mech3/WH13X.txt
""
"Test Method","Will_Huddleston_Disks.msm"
"Sample I. D.","WH13X.mss"
"Specimen Number","1"

"Load (N)","Time (s)","Extension (mm)","Stress (MPa)","Strain (mm/mm)"

4.79,0.200,-0.03225,0.874,-0.001
4.78,0.300,-0.03225,0.871,-0.001
4.81,0.400,-0.03225,0.878,-0.001
4.79,0.500,-0.03225,0.873,-0.001
4.82,0.600,-0.03225,0.880,-0.001
4.78,0.700,-0.03221,0.872,-0.001
4.82,0.800,-0.03221,0.879,-0.001
4.80,0.900,-0.03221,0.875,-0.001
4.80,1.000,-0.03221,0.876,-0.001
4.79,1.100,-0.03217,0.873,-0.001
4.81,1.200,-0.03217,0.876,-0.001
4.79,1.300,-0.03217,0.873,-0.001
4.80,1.400,-0.03213,0.876,-0.001
4.79,1.500,-0.03213,0.874,-0.001
4.83,1.600,-0.03209,0.881,-0.001
4.85,1.700,-0.03200,0.885,-0.001
4.87,1.800,-0.03192,0.889,-0.001
4.92,1.900,-0.03184,0.896,-0.001
4.96,2.000,-0.03171,0.905,-0.001
5.02,2.100,-0.03155,0.916,-0.001
5.08,2.200,-0.03142,0.926,-0.001
5.11,2.300,-0.03130,0.933,-0.001
5.16,2.400,-0.03113,0.942,-0.001
5.19,2.500,-0.03101,0.946,-0.001
5.20,2.600,-0.03088,0.949,-0.001
5.25,2.700,-0.03072,0.957,-0.001
5.27,2.800,-0.03059,0.961,-0.001
5.30,2.900,-0.03047,0.966,-0.001
5.32,3.000,-0.03030,0.970,-0.001
5.35,3.100,-0.03018,0.975,-0.001
5.39,3.200,-0.03001,0.983,-0.001
5.39,3.300,-0.02988,0.984,-0.001
5.42,3.400,-0.02972,0.989,-0.001
5.43,3.500,-0.02959,0.991,-0.001
5.50,3.600,-0.02943,1.002,-0.001
5.53,3.700,-0.02926,1.009,-0.001
5.52,3.800,-0.02910,1.006,-0.001
5.53,3.900,-0.02893,1.009,-0.001
5.56,4.000,-0.02876,1.014,-0.001
5.59,4.100,-0.02860,1.020,-0.001
5.58,4.200,-0.02839,1.018,-0.001
5.62,4.300,-0.02822,1.025,-0.001
5.64,4.400,-0.02801,1.029,-0.001
5.65,4.500,-0.02781,1.031,-0.001
5.70,4.600,-0.02760,1.040,-0.001
5.74,4.700,-0.02739,1.046,-0.001
5.76,4.800,-0.02722,1.050,-0.001
5.78,4.900,-0.02702,1.055,-0.001
5.80,5.000,-0.02681,1.058,-0.001
5.83,5.100,-0.02660,1.064,-0.001
5.87,5.200,-0.02639,1.070,-0.001
5.90,5.300,-0.02619,1.077,-0.001
5.89,5.400,-0.02602,1.075,-0.001
5.93,5.500,-0.02581,1.082,-0.001
5.95,5.600,-0.02565,1.085,-0.001
5.93,5.700,-0.02548,1.081,-0.001
5.96,5.800,-0.02531,1.087,0.000
6.00,5.900,-0.02515,1.094,0.000
6.01,6.000,-0.02498,1.096,0.000
6.04,6.100,-0.02486,1.102,0.000
6.03,6.200,-0.02469,1.100,0.000
6.10,6.300,-0.02457,1.112,0.000
6.07,6.400,-0.02440,1.107,0.000
6.09,6.500,-0.02427,1.112,0.000
6.10,6.600,-0.02411,1.113,0.000
6.14,6.700,-0.02398,1.120,0.000
6.13,6.800,-0.02386,1.117,0.000
6.13,6.900,-0.02373,1.118,0.000
6.16,7.000,-0.02361,1.124,0.000
6.17,7.100,-0.02348,1.125,0.000
6.19,7.200,-0.02332,1.128,0.000
6.20,7.300,-0.02319,1.131,0.000
6.24,7.400,-0.02307,1.137,0.000
6.24,7.500,-0.02294,1.139,0.000
6.24,7.600,-0.02278,1.138,0.000
6.27,7.700,-0.02265,1.144,0.000
6.26,7.800,-0.02249,1.142,0.000
6.34,7.900,-0.02236,1.157,0.000
6.29,8.000,-0.02220,1.148,0.000
6.34,8.100,-0.02207,1.156,0.000
6.36,8.200,-0.02191,1.160,0.000
6.33,8.300,-0.02174,1.154,0.000
6.41,8.400,-0.02161,1.169,0.000
6.39,8.500,-0.02145,1.165,0.000
6.42,8.600,-0.02132,1.171,0.000
6.45,8.700,-0.02116,1.176,0.000
6.45,8.800,-0.02099,1.177,0.000
6.48,8.900,-0.02087,1.183,0.000
6.51,9.000,-0.02070,1.187,0.000
6.50,9.100,-0.02053,1.185,0.000
6.55,9.200,-0.02037,1.194,0.000
6.56,9.300,-0.02020,1.195,0.000
6.59,9.400,-0.02004,1.201,0.000
6.62,9.500,-0.01987,1.207,0.000
6.63,9.600,-0.01970,1.208,0.000
6.60,9.700,-0.01954,1.204,0.000
6.69,9.800,-0.01937,1.220,0.000
6.68,9.900,-0.01916,1.218,0.000
6.69,10.000,-0.01900,1.221,0.000
6.76,10.100,-0.01879,1.233,0.000
6.80,10.200,-0.01858,1.240,0.000
6.81,10.300,-0.01837,1.242,0.000
6.81,10.400,-0.01812,1.243,0.000
6.84,10.500,-0.01792,1.248,0.000
6.87,10.600,-0.01771,1.253,0.000
6.89,10.700,-0.01750,1.256,0.000
6.94,10.800,-0.01729,1.266,0.000
6.96,10.900,-0.01709,1.269,0.000
6.99,11.000,-0.01688,1.274,0.000
7.00,11.100,-0.01671,1.277,0.000
7.05,11.200,-0.01650,1.285,0.000
7.04,11.300,-0.01634,1.284,0.000
7.09,11.400,-0.01613,1.293,0.000
7.13,11.500,-0.01596,1.300,0.000
7.11,11.600,-0.01580,1.296,0.000
7.12,11.700,-0.01563,1.299,0.000
7.13,11.800,-0.01546,1.300,0.000
7.18,11.900,-0.01530,1.310,0.000
7.19,12.000,-0.01513,1.311,0.000
7.20,12.100,-0.01501,1.313,0.000
7.25,12.200,-0.01484,1.322,0.000
7.25,12.300,-0.01472,1.322,0.000
7.25,12.400,-0.01459,1.321,0.000
7.31,12.500,-0.01443,1.333,0.000
7.29,12.600,-0.01430,1.330,0.000
7.34,12.700,-0.01418,1.338,0.000
7.36,12.800,-0.01405,1.342,0.000
7.37,12.900,-0.01389,1.344,0.000
7.38,13.000,-0.01376,1.346,0.000
7.39,13.100,-0.01364,1.347,0.000
7.43,13.200,-0.01347,1.355,0.000
7.44,13.300,-0.01335,1.356,0.000
7.47,13.400,-0.01318,1.363,0.000
7.48,13.500,-0.01305,1.365,0.000
7.52,13.600,-0.01289,1.371,0.000
7.54,13.700,-0.01276,1.375,0.000
7.55,13.800,-0.01260,1.376,0.000
7.54,13.900,-0.01247,1.376,0.000
7.58,14.000,-0.01231,1.383,0.000
7.63,14.100,-0.01214,1.391,0.000
7.66,14.200,-0.01202,1.396,0.000
7.66,14.300,-0.01185,1.397,0.000
7.70,14.400,-0.01168,1.403,0.000
7.70,14.500,-0.01156,1.404,0.000
7.73,14.600,-0.01139,1.409,0.000
7.75,14.700,-0.01123,1.414,0.000
7.76,14.800,-0.01106,1.416,0.000
7.77,14.900,-0.01094,1.416,0.000
7.78,15.000,-0.01077,1.419,0.000
7.83,15.100,-0.01060,1.428,0.000
7.80,15.200,-0.01044,1.422,0.000
7.86,15.300,-0.01027,1.433,0.000
7.91,15.400,-0.01006,1.442,0.000
7.92,15.500,-0.00990,1.444,0.000
8.00,15.600,-0.00973,1.458,0.000
8.01,15.700,-0.00952,1.460,0.000
8.01,15.800,-0.00931,1.461,0.000
8.06,15.900,-0.00911,1.469,0.000
8.08,16.000,-0.00890,1.474,0.000
8.10,16.100,-0.00869,1.478,0.000
8.13,16.200,-0.00848,1.483,0.000
8.17,16.300,-0.00832,1.490,0.000
8.19,16.400,-0.00811,1.494,0.000
8.21,16.500,-0.00790,1.497,0.000
8.26,16.600,-0.00769,1.507,0.000
8.26,16.700,-0.00749,1.506,0.000
8.30,16.800,-0.00728,1.513,0.000
8.31,16.900,-0.00711,1.516,0.000
8.36,17.000,-0.00690,1.524,0.000
8.39,17.100,-0.00674,1.529,0.000
8.42,17.200,-0.00657,1.536,0.000
8.43,17.300,-0.00641,1.538,0.000
8.45,17.400,-0.00624,1.541,0.000
8.48,17.500,-0.00607,1.546,0.000
8.51,17.600,-0.00591,1.551,0.000
8.53,17.700,-0.00578,1.556,0.000
8.54,17.800,-0.00562,1.557,0.000
8.55,17.900,-0.00545,1.559,0.000
8.59,18.000,-0.00533,1.566,0.000
8.60,18.100,-0.00520,1.569,0.000
8.62,18.200,-0.00503,1.572,0.000
8.62,18.300,-0.00491,1.573,0.000
8.66,18.400,-0.00478,1.579,0.000
8.70,18.500,-0.00462,1.587,0.000
8.74,18.600,-0.00449,1.593,0.000
8.70,18.700,-0.00437,1.586,0.000
8.74,18.800,-0.00424,1.594,0.000
8.79,18.900,-0.00408,1.602,0.000
8.79,19.000,-0.00395,1.603,0.000
8.86,19.100,-0.00383,1.616,0.000
8.83,19.200,-0.00366,1.611,0.000
8.85,19.300,-0.00354,1.615,0.000
8.88,19.400,-0.00337,1.619,0.000
8.89,19.500,-0.00325,1.622,0.000
8.92,19.600,-0.00308,1.627,0.000
8.99,19.700,-0.00296,1.639,0.000
8.98,19.800,-0.00279,1.637,0.000
8.99,19.900,-0.00262,1.639,0.000
9.08,20.000,-0.00250,1.656,0.000
9.08,20.100,-0.00233,1.656,0.000
9.11,20.200,-0.00221,1.662,0.000
9.09,20.300,-0.00204,1.658,0.000
9.13,20.400,-0.00188,1.666,0.000
9.16,20.500,-0.00175,1.671,0.000
9.20,20.600,-0.00159,1.678,0.000
9.19,20.700,-0.00142,1.675,0.000
9.25,20.800,-0.00125,1.687,0.000
9.28,20.900,-0.00109,1.693,0.000
9.28,21.000,-0.00092,1.692,0.000
9.34,21.100,-0.00075,1.704,0.000
9.37,21.200,-0.00059,1.709,0.000
9.39,21.300,-0.00038,1.713,0.000
9.43,21.400,-0.00017,1.720,0.000
9.45,21.500,-0.00001,1.724,0.000
9.52,21.600,0.00020,1.736,0.000
9.55,21.700,0.00041,1.741,0.000
9.58,21.800,0.00066,1.747,0.000
9.67,21.900,0.00087,1.764,0.000
9.67,22.000,0.00107,1.763,0.000
9.70,22.100,0.00128,1.768,0.000
9.75,22.200,0.00153,1.779,0.000
9.80,22.300,0.00174,1.788,0.000
9.84,22.400,0.00191,1.794,0.000
9.85,22.500,0.00211,1.797,0.000
9.88,22.600,0.00232,1.801,0.000
9.91,22.700,0.00253,1.808,0.000
9.94,22.800,0.00270,1.813,0.000
9.98,22.900,0.00286,1.819,0.000
10.00,23.000,0.00303,1.824,0.000
10.01,23.100,0.00319,1.826,0.000
10.08,23.200,0.00336,1.838,0.000
10.09,23.300,0.00348,1.839,0.000
10.12,23.400,0.00365,1.845,0.000
10.15,23.500,0.00378,1.852,0.000
10.14,23.600,0.00394,1.849,0.000
10.15,23.700,0.00407,1.851,0.000
10.19,23.800,0.00423,1.859,0.000
10.21,23.900,0.00436,1.862,0.000
10.29,24.000,0.00448,1.877,0.000
10.24,24.100,0.00461,1.868,0.000
10.27,24.200,0.00477,1.873,0.000
10.34,24.300,0.00490,1.885,0.000
10.32,24.400,0.00502,1.883,0.000
10.36,24.500,0.00519,1.889,0.000
10.38,24.600,0.00531,1.893,0.000
10.37,24.700,0.00544,1.891,0.000
10.43,24.800,0.00560,1.902,0.000
10.48,24.900,0.00573,1.911,0.000
10.49,25.000,0.00590,1.913,0.000
10.49,25.100,0.00602,1.913,0.000
10.55,25.200,0.00619,1.924,0.000
10.58,25.300,0.00631,1.929,0.000
10.61,25.400,0.00648,1.935,0.000
10.63,25.500,0.00664,1.938,0.000
10.68,25.600,0.00677,1.948,0.000
10.68,25.700,0.00693,1.947,0.000
10.72,25.800,0.00710,1.955,0.000
10.74,25.900,0.00722,1.959,0.000
10.78,26.000,0.00739,1.965,0.000
10.81,26.100,0.00756,1.972,0.000
10.82,26.200,0.00768,1.974,0.000
10.83,26.300,0.00785,1.975,0.000
10.91,26.400,0.00801,1.990,0.000
10.93,26.500,0.00818,1.993,0.000
10.98,26.600,0.00835,2.002,0.000
10.98,26.700,0.00851,2.003,0.000
11.03,26.800,0.00868,2.012,0.000
11.07,26.900,0.00885,2.019,0.000
11.11,27.000,0.00905,2.026,0.000
11.17,27.100,0.00926,2.037,0.000
11.21,27.200,0.00947,2.045,0.000
11.24,27.300,0.00964,2.049,0.000
11.28,27.400,0.00984,2.057,0.000
11.32,27.500,0.01009,2.064,0.000
11.37,27.600,0.01030,2.073,0.000
11.40,27.700,0.01051,2.079,0.000
11.48,27.800,0.01072,2.094,0.000
11.49,27.900,0.01092,2.096,0.000
11.55,28.000,0.01113,2.106,0.000
11.59,28.100,0.01134,2.113,0.000
11.60,28.200,0.01151,2.116,0.000
11.63,28.300,0.01171,2.122,0.000
11.69,28.400,0.01188,2.133,0.000
11.67,28.500,0.01209,2.128,0.000
11.72,28.600,0.01225,2.138,0.000
11.78,28.700,0.01242,2.148,0.000
11.80,28.800,0.01259,2.151,0.000
11.86,28.900,0.01275,2.163,0.000
11.86,29.000,0.01292,2.163,0.000
11.88,29.100,0.01308,2.167,0.000
11.95,29.200,0.01321,2.179,0.000
11.96,29.300,0.01338,2.181,0.000
11.99,29.400,0.01350,2.186,0.000
12.02,29.500,0.01367,2.193,0.000
12.07,29.600,0.01379,2.201,0.000
12.07,29.700,0.01392,2.202,0.000
12.08,29.800,0.01408,2.203,0.000
12.11,29.900,0.01421,2.208,0.000
12.10,30.000,0.01433,2.208,0.000
12.14,30.100,0.01450,2.214,0.000
12.21,30.200,0.01462,2.228,0.000
12.27,30.300,0.01475,2.237,0.000
12.29,30.400,0.01491,2.241,0.000
12.31,30.500,0.01504,2.245,0.000
12.34,30.600,0.01520,2.251,0.000
12.36,30.700,0.01533,2.255,0.000
12.40,30.800,0.01549,2.261,0.000
12.45,30.900,0.01562,2.271,0.000
12.50,31.000,0.01579,2.280,0.000
12.50,31.100,0.01595,2.280,0.000
12.56,31.200,0.01612,2.291,0.000
12.58,31.300,0.01624,2.295,0.000
12.60,31.400,0.01641,2.298,0.000
12.66,31.500,0.01657,2.308,0.000
12.69,31.600,0.01674,2.314,0.000
12.74,31.700,0.01691,2.323,0.000
12.72,31.800,0.01703,2.320,0.000
12.82,31.900,0.01720,2.338,0.000
12.83,32.000,0.01736,2.340,0.000
12.87,32.100,0.01753,2.347,0.000
12.89,32.200,0.01770,2.351,0.000
12.97,32.300,0.01786,2.366,0.000
12.97,32.400,0.01803,2.365,0.000
13.04,32.500,0.01820,2.378,0.000
13.07,32.600,0.01840,2.384,0.000
13.12,32.700,0.01857,2.393,0.000
13.17,32.800,0.01878,2.401,0.000
13.19,32.900,0.01899,2.405,0.000
13.26,33.000,0.01915,2.418,0.000
13.32,33.100,0.01936,2.429,0.000
13.36,33.200,0.01961,2.436,0.000
13.42,33.300,0.01982,2.447,0.000
13.45,33.400,0.02002,2.454,0.000
13.47,33.500,0.02023,2.457,0.000
13.53,33.600,0.02044,2.467,0.000
13.60,33.700,0.02061,2.480,0.000
13.62,33.800,0.02081,2.484,0.000
13.71,33.900,0.02102,2.500,0.000
13.73,34.000,0.02119,2.504,0.000
13.77,34.100,0.02140,2.511,0.000
13.79,34.200,0.02156,2.515,0.000
13.85,34.300,0.02173,2.526,0.000
13.87,34.400,0.02189,2.530,0.000
13.91,34.500,0.02206,2.537,0.000
13.93,34.600,0.02223,2.541,0.000
13.99,34.700,0.02239,2.551,0.000
14.01,34.800,0.02256,2.555,0.000
14.05,34.900,0.02268,2.561,0.000
14.07,35.000,0.02285,2.566,0.000
14.14,35.100,0.02297,2.579,0.000
14.16,35.200,0.02314,2.582,0.000
14.18,35.300,0.02327,2.586,0.000
14.25,35.400,0.02343,2.598,0.000
14.24,35.500,0.02356,2.598,0.000
14.28,35.600,0.02368,2.604,0.000
14.34,35.700,0.02381,2.615,0.000
14.36,35.800,0.02397,2.619,0.000
14.41,35.900,0.02410,2.628,0.000
14.44,36.000,0.02422,2.633,0.000
14.49,36.100,0.02439,2.642,0.000
14.51,36.200,0.02451,2.646,0.000
14.55,36.300,0.02464,2.653,0.000
14.57,36.400,0.02480,2.656,0.000
14.61,36.500,0.02493,2.664,0.000
14.65,36.600,0.02509,2.671,0.000
14.71,36.700,0.02526,2.682,0.000
14.72,36.800,0.02538,2.685,0.000
14.74,36.900,0.02555,2.688,0.001
14.80,37.000,0.02572,2.698,0.001
14.83,37.100,0.02584,2.705,0.001
14.87,37.200,0.02601,2.712,0.001
14.91,37.300,0.02617,2.719,0.001
14.91,37.400,0.02630,2.720,0.001
14.97,37.500,0.02647,2.730,0.001
15.01,37.600,0.02663,2.738,0.001
15.05,37.700,0.02680,2.745,0.001
15.10,37.800,0.02696,2.753,0.001
15.12,37.900,0.02713,2.757,0.001
15.18,38.000,0.02730,2.769,0.001
15.21,38.100,0.02746,2.774,0.001
15.26,38.200,0.02763,2.783,0.001
15.28,38.300,0.02779,2.787,0.001
15.36,38.400,0.02800,2.802,0.001
15.37,38.500,0.02817,2.803,0.001
15.44,38.600,0.02838,2.817,0.001
15.51,38.700,0.02858,2.829,0.001
15.56,38.800,0.02879,2.837,0.001
15.62,38.900,0.02900,2.849,0.001
15.69,39.000,0.02921,2.861,0.001
15.74,39.100,0.02946,2.870,0.001
15.76,39.200,0.02966,2.873,0.001
15.83,39.300,0.02987,2.887,0.001
15.83,39.400,0.03008,2.888,0.001
15.93,39.500,0.03029,2.905,0.001
15.97,39.600,0.03045,2.912,0.001
16.02,39.700,0.03066,2.921,0.001
16.08,39.800,0.03083,2.933,0.001
16.14,39.900,0.03104,2.943,0.001
16.16,40.000,0.03120,2.946,0.001
16.20,40.100,0.03137,2.955,0.001
16.24,40.200,0.03153,2.961,0.001
16.29,40.300,0.03170,2.972,0.001
16.31,40.400,0.03183,2.975,0.001
16.35,40.500,0.03199,2.981,0.001
16.40,40.600,0.03212,2.990,0.001
16.43,40.700,0.03228,2.997,0.001
16.47,40.800,0.03241,3.003,0.001
16.46,40.900,0.03257,3.002,0.001
16.53,41.000,0.03270,3.015,0.001
16.57,41.100,0.03282,3.022,0.001
16.62,41.200,0.03295,3.030,0.001
16.62,41.300,0.03307,3.031,0.001
16.67,41.400,0.03320,3.039,0.001
16.68,41.500,0.03336,3.041,0.001
16.74,41.600,0.03349,3.053,0.001
16.77,41.700,0.03361,3.058,0.001
16.82,41.800,0.03374,3.067,0.001
16.85,41.900,0.03390,3.073,0.001
16.89,42.000,0.03403,3.080,0.001
16.92,42.100,0.03419,3.085,0.001
16.96,42.200,0.03432,3.094,0.001
17.01,42.300,0.03449,3.102,0.001
17.04,42.400,0.03461,3.108,0.001
17.10,42.500,0.03478,3.119,0.001
17.13,42.600,0.03494,3.124,0.001
17.16,42.700,0.03507,3.130,0.001
17.21,42.800,0.03523,3.138,0.001
17.24,42.900,0.03540,3.145,0.001
17.29,43.000,0.03552,3.153,0.001
17.35,43.100,0.03569,3.164,0.001
17.43,43.200,0.03586,3.178,0.001
17.43,43.300,0.03602,3.179,0.001
17.46,43.400,0.03615,3.185,0.001
17.54,43.500,0.03631,3.198,0.001
17.58,43.600,0.03648,3.206,0.001
17.64,43.700,0.03665,3.217,0.001
17.64,43.800,0.03681,3.217,0.001
17.71,43.900,0.03698,3.230,0.001
17.76,44.000,0.03719,3.238,0.001
17.83,44.100,0.03735,3.252,0.001
17.89,44.200,0.03756,3.263,0.001
17.93,44.300,0.03773,3.270,0.001
18.00,44.400,0.03793,3.283,0.001
18.03,44.500,0.03814,3.288,0.001
18.09,44.600,0.03835,3.299,0.001
18.14,44.700,0.03856,3.309,0.001
18.20,44.800,0.03881,3.319,0.001
18.28,44.900,0.03902,3.333,0.001
18.33,45.000,0.03922,3.344,0.001
18.41,45.100,0.03943,3.357,0.001
18.48,45.200,0.03964,3.370,0.001
18.53,45.300,0.03985,3.379,0.001
18.59,45.400,0.04005,3.390,0.001
18.62,45.500,0.04022,3.396,0.001
18.69,45.600,0.04043,3.408,0.001
18.72,45.700,0.04059,3.414,0.001
18.80,45.800,0.04076,3.428,0.001
18.82,45.900,0.04093,3.432,0.001
18.90,46.000,0.04109,3.446,0.001
18.90,46.100,0.04126,3.446,0.001
18.93,46.200,0.04138,3.452,0.001
18.97,46.300,0.04155,3.459,0.001
19.01,46.400,0.04167,3.467,0.001
19.07,46.500,0.04184,3.477,0.001
19.08,46.600,0.04197,3.479,0.001
19.11,46.700,0.04209,3.486,0.001
19.14,46.800,0.04226,3.491,0.001
19.20,46.900,0.04238,3.501,0.001
19.23,47.000,0.04251,3.507,0.001
19.28,47.100,0.04263,3.517,0.001
19.30,47.200,0.04276,3.519,0.001
19.37,47.300,0.04292,3.532,0.001
19.40,47.400,0.04305,3.538,0.001
19.44,47.500,0.04317,3.544,0.001
19.47,47.600,0.04334,3.552,0.001
19.51,47.700,0.04346,3.558,0.001
19.56,47.800,0.04363,3.567,0.001
19.62,47.900,0.04375,3.578,0.001
19.66,48.000,0.04392,3.585,0.001
19.73,48.100,0.04408,3.598,0.001
19.76,48.200,0.04421,3.603,0.001
19.81,48.300,0.04438,3.612,0.001
19.84,48.400,0.04454,3.618,0.001
19.94,48.500,0.04467,3.636,0.001
19.92,48.600,0.04483,3.632,0.001
19.90,48.700,0.04500,3.629,0.001
20.00,48.800,0.04517,3.647,0.001
20.08,48.900,0.04529,3.663,0.001
20.07,49.000,0.04546,3.661,0.001
20.13,49.100,0.04562,3.671,0.001
20.18,49.200,0.04579,3.681,0.001
20.22,49.300,0.04595,3.687,0.001
20.29,49.400,0.04612,3.700,0.001
20.32,49.500,0.04629,3.707,0.001
20.38,49.600,0.04645,3.717,0.001
20.46,49.700,0.04662,3.732,0.001
20.50,49.800,0.04683,3.738,0.001
20.56,49.900,0.04699,3.749,0.001
20.67,50.000,0.04716,3.769,0.001
20.70,50.100,0.04737,3.776,0.001
20.78,50.200,0.04758,3.790,0.001
20.85,50.300,0.04778,3.802,0.001
20.93,50.400,0.04803,3.818,0.001
20.99,50.500,0.04824,3.828,0.001
21.05,50.600,0.04845,3.840,0.001
21.11,50.700,0.04866,3.851,0.001
21.15,50.800,0.04886,3.856,0.001
21.23,50.900,0.04903,3.872,0.001
21.29,51.000,0.04924,3.883,0.001
21.37,51.100,0.04945,3.898,0.001
21.39,51.200,0.04961,3.902,0.001
21.45,51.300,0.04978,3.912,0.001
21.50,51.400,0.04999,3.921,0.001
21.51,51.500,0.05015,3.923,0.001
21.59,51.600,0.05032,3.938,0.001
21.64,51.700,0.05048,3.947,0.001
21.68,51.800,0.05061,3.955,0.001
21.73,51.900,0.05078,3.964,0.001
21.76,52.000,0.05090,3.969,0.001
21.80,52.100,0.05107,3.975,0.001
21.83,52.200,0.05119,3.982,0.001
21.90,52.300,0.05136,3.993,0.001
21.94,52.400,0.05148,4.001,0.001
21.97,52.500,0.05161,4.007,0.001
22.02,52.600,0.05177,4.015,0.001
22.06,52.700,0.05190,4.022,0.001
22.09,52.800,0.05202,4.028,0.001
22.14,52.900,0.05215,4.037,0.001
22.19,53.000,0.05231,4.047,0.001
22.25,53.100,0.05244,4.058,0.001
22.24,53.200,0.05256,4.056,0.001
22.31,53.300,0.05269,4.069,0.001
22.34,53.400,0.05281,4.074,0.001
22.38,53.500,0.05298,4.081,0.001
22.46,53.600,0.05310,4.096,0.001
22.53,53.700,0.05327,4.109,0.001
22.53,53.800,0.05339,4.109,0.001
22.62,53.900,0.05356,4.124,0.001
22.62,54.000,0.05368,4.125,0.001
22.70,54.100,0.05385,4.139,0.001
22.76,54.200,0.05402,4.150,0.001
22.79,54.300,0.05414,4.156,0.001
22.85,54.400,0.05431,4.167,0.001
22.89,54.500,0.05447,4.174,0.001
22.94,54.600,0.05464,4.184,0.001
22.98,54.700,0.05481,4.191,0.001
23.04,54.800,0.05493,4.202,0.001
23.08,54.900,0.05510,4.210,0.001
23.14,55.000,0.05526,4.220,0.001
23.21,55.100,0.05543,4.232,0.001
23.27,55.200,0.05560,4.245,0.001
23.32,55.300,0.05576,4.252,0.001
23.39,55.400,0.05593,4.265,0.001
23.42,55.500,0.05614,4.271,0.001
23.50,55.600,0.05634,4.285,0.001
23.59,55.700,0.05651,4.302,0.001
23.64,55.800,0.05672,4.312,0.001
23.72,55.900,0.05693,4.326,0.001
23.81,56.000,0.05717,4.341,0.001
23.84,56.100,0.05738,4.348,0.001
23.95,56.200,0.05759,4.368,0.001
24.01,56.300,0.05780,4.378,0.001
24.05,56.400,0.05805,4.386,0.001
24.11,56.500,0.05826,4.397,0.001
24.18,56.600,0.05846,4.410,0.001
24.26,56.700,0.05867,4.423,0.001
24.30,56.800,0.05888,4.432,0.001
24.37,56.900,0.05909,4.444,0.001
24.46,57.000,0.05925,4.461,0.001
24.46,57.100,0.05942,4.461,0.001
24.56,57.200,0.05963,4.478,0.001
24.61,57.300,0.05979,4.488,0.001
24.67,57.400,0.05996,4.499,0.001
24.69,57.500,0.06013,4.503,0.001
24.76,57.600,0.06029,4.516,0.001
24.81,57.700,0.06042,4.524,0.001
24.85,57.800,0.06058,4.532,0.001
24.90,57.900,0.06071,4.542,0.001
24.95,58.000,0.06087,4.549,0.001
24.99,58.100,0.06100,4.557,0.001
25.03,58.200,0.06116,4.564,0.001
25.10,58.300,0.06129,4.578,0.001
25.12,58.400,0.06141,4.582,0.001
25.16,58.500,0.06154,4.589,0.001
25.21,58.600,0.06170,4.598,0.001
25.26,58.700,0.06183,4.606,0.001
25.32,58.800,0.06195,4.617,0.001
25.36,58.900,0.06212,4.626,0.001
25.42,59.000,0.06224,4.636,0.001
25.48,59.100,0.06241,4.646,0.001
25.49,59.200,0.06258,4.649,0.001
25.56,59.300,0.06270,4.662,0.001
25.63,59.400,0.06287,4.674,0.001
25.66,59.500,0.06303,4.679,0.001
25.74,59.600,0.06316,4.694,0.001
25.80,59.700,0.06333,4.705,0.001
25.86,59.800,0.06349,4.717,0.001
25.91,59.900,0.06366,4.725,0.001
25.98,60.000,0.06378,4.737,0.001
26.01,60.100,0.06395,4.743,0.001
26.09,60.200,0.06411,4.757,0.001
26.17,60.300,0.06428,4.773,0.001
26.19,60.400,0.06445,4.777,0.001
26.24,60.500,0.06461,4.786,0.001
26.30,60.600,0.06478,4.796,0.001
26.35,60.700,0.06495,4.806,0.001
26.42,60.800,0.06511,4.818,0.001
26.48,60.900,0.06532,4.830,0.001
26.59,61.000,0.06549,4.848,0.001
26.66,61.100,0.06565,4.862,0.001
26.73,61.200,0.06586,4.874,0.001
26.83,61.300,0.06607,4.892,0.001
26.86,61.400,0.06628,4.898,0.001
26.96,61.500,0.06648,4.917,0.001
27.04,61.600,0.06669,4.931,0.001
27.11,61.700,0.06690,4.944,0.001
27.20,61.800,0.06715,4.961,0.001
27.26,61.900,0.06736,4.972,0.001
27.36,62.000,0.06756,4.990,0.001
27.39,62.100,0.06777,4.994,0.001
27.46,62.200,0.06798,5.008,0.001
27.57,62.300,0.06819,5.028,0.001
27.57,62.400,0.06840,5.028,0.001
27.66,62.500,0.06856,5.043,0.001
27.73,62.600,0.06877,5.058,0.001
27.78,62.700,0.06894,5.066,0.001
27.83,62.800,0.06910,5.076,0.001
27.90,62.900,0.06927,5.088,0.001
27.98,63.000,0.06943,5.102,0.001
28.04,63.100,0.06960,5.114,0.001
28.09,63.200,0.06977,5.124,0.001
28.14,63.300,0.06993,5.133,0.001
28.19,63.400,0.07006,5.141,0.001
28.24,63.500,0.07022,5.150,0.001
28.28,63.600,0.07035,5.158,0.001
28.33,63.700,0.07051,5.167,0.001
28.37,63.800,0.07064,5.173,0.001
28.45,63.900,0.07076,5.188,0.001
28.48,64.000,0.07093,5.193,0.001
28.54,64.100,0.07105,5.205,0.001
28.58,64.200,0.07118,5.212,0.001
28.63,64.300,0.07135,5.221,0.001
28.68,64.400,0.07147,5.231,0.001
28.72,64.500,0.07159,5.238,0.001
28.79,64.600,0.07176,5.250,0.001
28.82,64.700,0.07189,5.257,0.001
28.87,64.800,0.07205,5.265,0.001
28.95,64.900,0.07222,5.279,0.001
29.00,65.000,0.07234,5.289,0.001
29.03,65.100,0.07251,5.295,0.001
29.13,65.200,0.07263,5.313,0.001
29.16,65.300,0.07280,5.319,0.001
29.25,65.400,0.07297,5.334,0.001
29.34,65.500,0.07313,5.351,0.001
29.37,65.600,0.07326,5.355,0.001
29.44,65.700,0.07342,5.368,0.001
29.50,65.800,0.07359,5.380,0.001
29.54,65.900,0.07371,5.387,0.001
29.62,66.000,0.07388,5.401,0.001
29.65,66.100,0.07405,5.407,0.001
29.72,66.200,0.07421,5.420,0.001
29.79,66.300,0.07438,5.433,0.001
29.83,66.400,0.07455,5.440,0.001
29.93,66.500,0.07475,5.458,0.001
29.96,66.600,0.07492,5.464,0.001
30.01,66.700,0.07509,5.473,0.001
30.09,66.800,0.07529,5.488,0.001
30.16,66.900,0.07546,5.499,0.001
30.24,67.000,0.07567,5.515,0.001
30.31,67.100,0.07588,5.528,0.001
30.39,67.200,0.07608,5.543,0.001
30.48,67.300,0.07633,5.559,0.002
30.57,67.400,0.07654,5.575,0.002
30.67,67.500,0.07675,5.592,0.002
30.73,67.600,0.07696,5.604,0.002
30.82,67.700,0.07716,5.620,0.002
30.89,67.800,0.07737,5.634,0.002
30.98,67.900,0.07758,5.650,0.002
31.05,68.000,0.07779,5.663,0.002
31.14,68.100,0.07799,5.679,0.002
31.20,68.200,0.07816,5.691,0.002
31.28,68.300,0.07837,5.704,0.002
31.33,68.400,0.07853,5.713,0.002
31.39,68.500,0.07870,5.725,0.002
31.46,68.600,0.07887,5.737,0.002
31.51,68.700,0.07903,5.747,0.002
31.55,68.800,0.07916,5.754,0.002
31.63,68.900,0.07932,5.769,0.002
31.67,69.000,0.07949,5.775,0.002
31.72,69.100,0.07962,5.784,0.002
31.77,69.200,0.07978,5.793,0.002
31.82,69.300,0.07991,5.802,0.002
31.86,69.400,0.08003,5.810,0.002
31.90,69.500,0.08020,5.818,0.002
31.95,69.600,0.08032,5.827,0.002
32.01,69.700,0.08045,5.837,0.002
32.06,69.800,0.08061,5.846,0.002
32.11,69.900,0.08074,5.856,0.002
32.15,70.000,0.08086,5.864,0.002
32.23,70.100,0.08103,5.877,0.002
32.27,70.200,0.08115,5.884,0.002
32.35,70.300,0.08132,5.900,0.002
32.38,70.400,0.08144,5.906,0.002
32.43,70.500,0.08161,5.915,0.002
32.51,70.600,0.08173,5.929,0.002
32.56,70.700,0.08190,5.939,0.002
32.60,70.800,0.08203,5.945,0.002
32.68,70.900,0.08219,5.959,0.002
32.78,71.000,0.08236,5.978,0.002
32.82,71.100,0.08248,5.986,0.002
32.87,71.200,0.08265,5.995,0.002
32.95,71.300,0.08281,6.010,0.002
33.01,71.400,0.08298,6.019,0.002
33.07,71.500,0.08315,6.032,0.002
33.13,71.600,0.08327,6.042,0.002
33.19,71.700,0.08344,6.053,0.002
33.26,71.800,0.08360,6.065,0.002
33.32,71.900,0.08377,6.077,0.002
33.39,72.000,0.08394,6.089,0.002
33.47,72.100,0.08410,6.104,0.002
33.53,72.200,0.08427,6.115,0.002
33.59,72.300,0.08444,6.125,0.002
33.68,72.400,0.08464,6.143,0.002
33.78,72.500,0.08485,6.161,0.002
33.85,72.600,0.08506,6.174,0.002
33.95,72.700,0.08527,6.192,0.002
34.04,72.800,0.08547,6.207,0.002
34.12,72.900,0.08568,6.223,0.002
34.21,73.000,0.08589,6.240,0.002
34.29,73.100,0.08614,6.254,0.002
34.37,73.200,0.08635,6.268,0.002
34.44,73.300,0.08655,6.281,0.002
34.54,73.400,0.08676,6.299,0.002
34.62,73.500,0.08697,6.314,0.002
34.65,73.600,0.08718,6.319,0.002
34.74,73.700,0.08734,6.336,0.002
34.80,73.800,0.08755,6.347,0.002
34.89,73.900,0.08772,6.363,0.002
34.95,74.000,0.08788,6.374,0.002
35.00,74.100,0.08805,6.383,0.002
35.04,74.200,0.08822,6.391,0.002
35.11,74.300,0.08838,6.403,0.002
35.16,74.400,0.08855,6.413,0.002
35.21,74.500,0.08872,6.421,0.002
35.24,74.600,0.08884,6.428,0.002
35.29,74.700,0.08901,6.435,0.002
35.36,74.800,0.08913,6.449,0.002
35.39,74.900,0.08926,6.454,0.002
35.45,75.000,0.08942,6.465,0.002
35.49,75.100,0.08955,6.472,0.002
35.53,75.200,0.08967,6.480,0.002
35.59,75.300,0.08980,6.491,0.002
35.65,75.400,0.08992,6.501,0.002
35.69,75.500,0.09009,6.508,0.002
35.75,75.600,0.09021,6.520,0.002
35.80,75.700,0.09034,6.529,0.002
35.86,75.800,0.09050,6.540,0.002
35.93,75.900,0.09063,6.553,0.002
35.99,76.000,0.09075,6.563,0.002
36.04,76.100,0.09092,6.573,0.002
36.11,76.200,0.09104,6.586,0.002
36.15,76.300,0.09121,6.593,0.002
36.23,76.400,0.09138,6.606,0.002
36.28,76.500,0.09150,6.616,0.002
36.34,76.600,0.09167,6.627,0.002
36.39,76.700,0.09183,6.636,0.002
36.45,76.800,0.09196,6.647,0.002
36.51,76.900,0.09212,6.659,0.002
36.57,77.000,0.09229,6.670,0.002
36.62,77.100,0.09241,6.679,0.002
36.70,77.200,0.09258,6.694,0.002
36.78,77.300,0.09275,6.707,0.002
36.81,77.400,0.09291,6.713,0.002
36.90,77.500,0.09304,6.730,0.002
36.97,77.600,0.09320,6.742,0.002
37.05,77.700,0.09337,6.756,0.002
37.14,77.800,0.09354,6.772,0.002
37.19,77.900,0.09374,6.783,0.002
37.27,78.000,0.09391,6.797,0.002
37.37,78.100,0.09412,6.815,0.002
37.44,78.200,0.09428,6.827,0.002
37.54,78.300,0.09449,6.845,0.002
37.64,78.400,0.09470,6.864,0.002
37.74,78.500,0.09491,6.883,0.002
37.83,78.600,0.09512,6.899,0.002
37.93,78.700,0.09532,6.916,0.002
38.03,78.800,0.09557,6.936,0.002
38.12,78.900,0.09578,6.951,0.002
38.21,79.000,0.09599,6.968,0.002
38.30,79.100,0.09620,6.985,0.002
38.37,79.200,0.09640,6.997,0.002
38.44,79.300,0.09661,7.010,0.002
38.52,79.400,0.09678,7.025,0.002
38.55,79.500,0.09699,7.030,0.002
38.64,79.600,0.09715,7.047,0.002
38.71,79.700,0.09732,7.060,0.002
38.79,79.800,0.09753,7.074,0.002
38.86,79.900,0.09769,7.086,0.002
38.91,80.000,0.09786,7.096,0.002
38.95,80.100,0.09798,7.103,0.002
39.03,80.200,0.09815,7.118,0.002
39.10,80.300,0.09827,7.130,0.002
39.14,80.400,0.09844,7.139,0.002
39.21,80.500,0.09856,7.150,0.002
39.24,80.600,0.09873,7.156,0.002
39.30,80.700,0.09886,7.167,0.002
39.37,80.800,0.09898,7.180,0.002
39.42,80.900,0.09915,7.189,0.002
39.47,81.000,0.09927,7.198,0.002
39.53,81.100,0.09940,7.209,0.002
39.58,81.200,0.09952,7.217,0.002
39.65,81.300,0.09969,7.231,0.002
39.70,81.400,0.09981,7.241,0.002
39.77,81.500,0.09994,7.252,0.002
39.84,81.600,0.10010,7.265,0.002
39.89,81.700,0.10023,7.274,0.002
39.95,81.800,0.10039,7.286,0.002
40.00,81.900,0.10052,7.296,0.002
40.08,82.000,0.10068,7.310,0.002
40.14,82.100,0.10081,7.320,0.002
4.19,82.200,0.10097,0.764,0.002
2.45,82.210,0.10097,0.448,0.002