File: data-files/mech3/WH13U.txt
""
"Test Method","Will_Huddleston_Disks.msm"
"Sample I. D.","WH13U.mss"
"Specimen Number","1"

"Load (N)","Time (s)","Extension (mm)","Stress (MPa)","Strain (mm/mm)"

5.05,0.200,-0.02650,0.921,-0.001
5.05,0.400,-0.02650,0.922,-0.001
5.06,0.600,-0.02646,0.924,-0.001
5.06,0.800,-0.02642,0.923,-0.001
5.05,1.000,-0.02638,0.922,-0.001
5.05,1.200,-0.02638,0.922,-0.001
5.05,1.400,-0.02633,0.921,-0.001
5.05,1.600,-0.02629,0.922,-0.001
5.07,1.800,-0.02625,0.925,-0.001
5.08,2.000,-0.02617,0.927,-0.001
5.14,2.200,-0.02604,0.939,-0.001
5.28,2.400,-0.02571,0.963,-0.001
5.38,2.600,-0.02542,0.981,-0.001
5.48,2.800,-0.02513,1.000,0.000
5.55,3.000,-0.02484,1.013,0.000
5.62,3.200,-0.02455,1.026,0.000
5.68,3.400,-0.02426,1.037,0.000
5.73,3.600,-0.02397,1.047,0.000
5.80,3.800,-0.02363,1.059,0.000
5.90,4.000,-0.02330,1.078,0.000
5.95,4.200,-0.02297,1.087,0.000
6.02,4.400,-0.02259,1.099,0.000
6.12,4.600,-0.02222,1.118,0.000
6.21,4.800,-0.02180,1.134,0.000
6.25,5.000,-0.02139,1.140,0.000
6.34,5.200,-0.02102,1.157,0.000
6.39,5.400,-0.02060,1.167,0.000
6.44,5.600,-0.02023,1.177,0.000
6.50,5.800,-0.01985,1.187,0.000
6.56,6.000,-0.01952,1.197,0.000
6.62,6.200,-0.01919,1.209,0.000
6.68,6.400,-0.01885,1.220,0.000
6.71,6.600,-0.01856,1.226,0.000
6.74,6.800,-0.01827,1.231,0.000
6.79,7.000,-0.01802,1.240,0.000
6.84,7.200,-0.01773,1.249,0.000
6.89,7.400,-0.01744,1.257,0.000
6.92,7.600,-0.01719,1.264,0.000
6.98,7.800,-0.01690,1.274,0.000
7.01,8.000,-0.01661,1.280,0.000
7.07,8.200,-0.01632,1.292,0.000
7.10,8.400,-0.01603,1.296,0.000
7.17,8.600,-0.01570,1.308,0.000
7.22,8.800,-0.01541,1.318,0.000
7.27,9.000,-0.01511,1.328,0.000
7.33,9.200,-0.01478,1.338,0.000
7.38,9.400,-0.01449,1.347,0.000
7.42,9.600,-0.01416,1.356,0.000
7.49,9.800,-0.01378,1.367,0.000
7.57,10.000,-0.01341,1.381,0.000
7.64,10.200,-0.01304,1.395,0.000
7.71,10.400,-0.01262,1.408,0.000
7.77,10.600,-0.01216,1.419,0.000
7.84,10.800,-0.01175,1.431,0.000
7.93,11.000,-0.01129,1.447,0.000
7.96,11.200,-0.01088,1.454,0.000
8.03,11.400,-0.01050,1.466,0.000
8.09,11.600,-0.01013,1.477,0.000
8.14,11.800,-0.00980,1.487,0.000
8.19,12.000,-0.00946,1.495,0.000
8.22,12.200,-0.00917,1.501,0.000
8.26,12.400,-0.00888,1.509,0.000
8.30,12.600,-0.00863,1.516,0.000
8.35,12.800,-0.00834,1.525,0.000
8.41,13.000,-0.00809,1.535,0.000
8.44,13.200,-0.00780,1.541,0.000
8.49,13.400,-0.00751,1.550,0.000
8.53,13.600,-0.00722,1.557,0.000
8.60,13.800,-0.00693,1.570,0.000
8.65,14.000,-0.00664,1.579,0.000
8.72,14.200,-0.00635,1.592,0.000
8.76,14.400,-0.00606,1.599,0.000
8.80,14.600,-0.00572,1.606,0.000
8.87,14.800,-0.00543,1.620,0.000
8.91,15.000,-0.00510,1.627,0.000
8.97,15.200,-0.00477,1.638,0.000
9.03,15.400,-0.00443,1.649,0.000
9.14,15.600,-0.00406,1.668,0.000
9.18,15.800,-0.00369,1.675,0.000
9.22,16.000,-0.00331,1.683,0.000
9.30,16.200,-0.00286,1.697,0.000
9.41,16.400,-0.00244,1.718,0.000
9.48,16.600,-0.00202,1.732,0.000
9.54,16.800,-0.00161,1.742,0.000
9.62,17.000,-0.00123,1.756,0.000
9.67,17.200,-0.00086,1.765,0.000
9.74,17.400,-0.00049,1.778,0.000
9.81,17.600,-0.00015,1.790,0.000
9.82,17.800,0.00014,1.793,0.000
9.89,18.000,0.00043,1.805,0.000
9.93,18.200,0.00072,1.813,0.000
9.98,18.400,0.00101,1.823,0.000
10.03,18.600,0.00126,1.832,0.000
10.12,18.800,0.00155,1.847,0.000
10.13,19.000,0.00184,1.850,0.000
10.20,19.200,0.00213,1.861,0.000
10.25,19.400,0.00242,1.871,0.000
10.29,19.600,0.00271,1.878,0.000
10.35,19.800,0.00300,1.889,0.000
10.41,20.000,0.00334,1.900,0.000
10.49,20.200,0.00363,1.915,0.000
10.55,20.400,0.00392,1.926,0.000
10.61,20.600,0.00425,1.937,0.000
10.66,20.800,0.00454,1.945,0.000
10.74,21.000,0.00487,1.960,0.000
10.79,21.200,0.00525,1.970,0.000
10.87,21.400,0.00562,1.985,0.000
10.94,21.600,0.00600,1.998,0.000
11.03,21.800,0.00641,2.014,0.000
11.14,22.000,0.00683,2.034,0.000
11.21,22.200,0.00724,2.047,0.000
11.27,22.400,0.00762,2.057,0.000
11.38,22.600,0.00803,2.078,0.000
11.45,22.800,0.00841,2.090,0.000
11.53,23.000,0.00874,2.105,0.000
11.53,23.200,0.00911,2.105,0.000
11.60,23.400,0.00940,2.119,0.000
11.67,23.600,0.00969,2.131,0.000
11.75,23.800,0.00999,2.145,0.000
11.82,24.000,0.01028,2.159,0.000
11.83,24.200,0.01053,2.159,0.000
11.89,24.400,0.01082,2.171,0.000
11.96,24.600,0.01107,2.183,0.000
12.03,24.800,0.01136,2.197,0.000
12.08,25.000,0.01165,2.205,0.000
12.16,25.200,0.01194,2.220,0.000
12.19,25.400,0.01223,2.226,0.000
12.26,25.600,0.01252,2.239,0.000
12.32,25.800,0.01281,2.249,0.000
12.40,26.000,0.01314,2.264,0.000
12.49,26.200,0.01343,2.280,0.000
12.53,26.400,0.01377,2.287,0.000
12.60,26.600,0.01406,2.300,0.000
12.70,26.800,0.01439,2.318,0.000
12.78,27.000,0.01476,2.333,0.000
12.89,27.200,0.01514,2.353,0.000
12.98,27.400,0.01555,2.370,0.000
13.10,27.600,0.01597,2.392,0.000
13.22,27.800,0.01639,2.413,0.000
13.30,28.000,0.01684,2.429,0.000
13.38,28.200,0.01726,2.443,0.000
13.48,28.400,0.01763,2.460,0.000
13.55,28.600,0.01801,2.474,0.000
13.64,28.800,0.01834,2.490,0.000
13.70,29.000,0.01867,2.501,0.000
13.78,29.200,0.01896,2.515,0.000
13.84,29.400,0.01925,2.527,0.000
13.91,29.600,0.01954,2.539,0.000
13.96,29.800,0.01983,2.549,0.000
14.01,30.000,0.02008,2.558,0.000
14.08,30.200,0.02037,2.571,0.000
14.19,30.400,0.02062,2.591,0.000
14.23,30.600,0.02091,2.598,0.000
14.32,30.800,0.02121,2.614,0.000
14.38,31.000,0.02154,2.625,0.000
14.47,31.200,0.02183,2.641,0.000
14.52,31.400,0.02212,2.652,0.000
14.63,31.600,0.02245,2.671,0.000
14.70,31.800,0.02274,2.684,0.000
14.79,32.000,0.02308,2.700,0.000
14.84,32.200,0.02341,2.710,0.000
14.97,32.400,0.02374,2.733,0.000
15.07,32.600,0.02407,2.751,0.000
15.18,32.800,0.02445,2.771,0.000
15.28,33.000,0.02486,2.790,0.000
15.39,33.200,0.02528,2.811,0.000
15.52,33.400,0.02574,2.834,0.001
15.65,33.600,0.02615,2.858,0.001
15.76,33.800,0.02657,2.878,0.001
15.87,34.000,0.02694,2.897,0.001
15.97,34.200,0.02731,2.915,0.001
16.06,34.400,0.02769,2.932,0.001
16.14,34.600,0.02802,2.947,0.001
16.21,34.800,0.02835,2.960,0.001
16.30,35.000,0.02864,2.976,0.001
16.41,35.200,0.02893,2.995,0.001
16.45,35.400,0.02918,3.004,0.001
16.51,35.600,0.02948,3.015,0.001
16.61,35.800,0.02977,3.032,0.001
16.67,36.000,0.03002,3.044,0.001
16.75,36.200,0.03031,3.057,0.001
16.86,36.400,0.03060,3.078,0.001
16.94,36.600,0.03089,3.093,0.001
17.05,36.800,0.03122,3.113,0.001
17.14,37.000,0.03151,3.130,0.001
17.24,37.200,0.03184,3.148,0.001
17.34,37.400,0.03218,3.165,0.001
17.45,37.600,0.03247,3.186,0.001
17.53,37.800,0.03280,3.200,0.001
17.62,38.000,0.03313,3.216,0.001
17.78,38.200,0.03351,3.245,0.001
17.87,38.400,0.03384,3.262,0.001
18.00,38.600,0.03425,3.286,0.001
18.12,38.800,0.03467,3.309,0.001
18.26,39.000,0.03509,3.334,0.001
18.40,39.200,0.03550,3.360,0.001
18.55,39.400,0.03592,3.386,0.001
18.68,39.600,0.03629,3.410,0.001
18.79,39.800,0.03666,3.431,0.001
18.91,40.000,0.03704,3.452,0.001
19.01,40.200,0.03737,3.471,0.001
19.13,40.400,0.03770,3.493,0.001
19.23,40.600,0.03799,3.511,0.001
19.35,40.800,0.03828,3.533,0.001
19.43,41.000,0.03858,3.548,0.001
19.54,41.200,0.03887,3.568,0.001
19.64,41.400,0.03912,3.585,0.001
19.75,41.600,0.03941,3.605,0.001
19.82,41.800,0.03970,3.619,0.001
19.97,42.000,0.03995,3.646,0.001
20.03,42.200,0.04028,3.658,0.001
20.14,42.400,0.04057,3.677,0.001
20.26,42.600,0.04086,3.700,0.001
20.39,42.800,0.04115,3.722,0.001
20.54,43.000,0.04148,3.750,0.001
20.65,43.200,0.04182,3.770,0.001
20.79,43.400,0.04211,3.796,0.001
20.87,43.600,0.04244,3.810,0.001
21.00,43.800,0.04277,3.834,0.001
21.15,44.000,0.04311,3.862,0.001
21.29,44.200,0.04352,3.886,0.001
21.53,44.400,0.04389,3.931,0.001
21.68,44.600,0.04435,3.959,0.001
21.85,44.800,0.04477,3.989,0.001
21.99,45.000,0.04518,4.015,0.001
22.15,45.200,0.04560,4.044,0.001
22.34,45.400,0.04601,4.079,0.001
22.45,45.600,0.04639,4.099,0.001
22.62,45.800,0.04672,4.131,0.001
22.76,46.000,0.04705,4.156,0.001
22.89,46.200,0.04734,4.179,0.001
22.96,46.400,0.04764,4.192,0.001
23.14,46.600,0.04793,4.225,0.001
23.23,46.800,0.04818,4.241,0.001
23.34,47.000,0.04847,4.261,0.001
23.46,47.200,0.04872,4.283,0.001
23.59,47.400,0.04901,4.308,0.001
23.70,47.600,0.04926,4.328,0.001
23.82,47.800,0.04955,4.349,0.001
23.96,48.000,0.04984,4.375,0.001
24.08,48.200,0.05013,4.396,0.001
24.22,48.400,0.05042,4.421,0.001
24.34,48.600,0.05075,4.445,0.001
24.54,48.800,0.05104,4.480,0.001
24.61,49.000,0.05138,4.493,0.001
24.81,49.200,0.05167,4.530,0.001
24.90,49.400,0.05200,4.546,0.001
25.05,49.600,0.05233,4.573,0.001
25.24,49.800,0.05270,4.609,0.001
25.45,50.000,0.05308,4.646,0.001
25.59,50.200,0.05349,4.673,0.001
25.82,50.400,0.05391,4.714,0.001
26.01,50.600,0.05437,4.748,0.001
26.19,50.800,0.05478,4.781,0.001
26.42,51.000,0.05520,4.823,0.001
26.60,51.200,0.05557,4.857,0.001
26.75,51.400,0.05595,4.883,0.001
26.92,51.600,0.05628,4.914,0.001
27.04,51.800,0.05657,4.937,0.001
27.15,52.000,0.05690,4.956,0.001
27.27,52.200,0.05719,4.979,0.001
27.41,52.400,0.05744,5.005,0.001
27.54,52.600,0.05773,5.027,0.001
27.68,52.800,0.05798,5.054,0.001
27.80,53.000,0.05827,5.076,0.001
27.95,53.200,0.05856,5.103,0.001
28.08,53.400,0.05881,5.127,0.001
28.21,53.600,0.05910,5.150,0.001
28.36,53.800,0.05940,5.178,0.001
28.50,54.000,0.05973,5.203,0.001
28.66,54.200,0.06002,5.233,0.001
28.81,54.400,0.06035,5.261,0.001
28.98,54.600,0.06064,5.291,0.001
29.10,54.800,0.06097,5.314,0.001
29.26,55.000,0.06127,5.343,0.001
29.46,55.200,0.06164,5.379,0.001
29.63,55.400,0.06197,5.410,0.001
29.82,55.600,0.06235,5.445,0.001
30.04,55.800,0.06272,5.484,0.001
30.23,56.000,0.06314,5.519,0.001
30.43,56.200,0.06355,5.556,0.001
30.67,56.400,0.06401,5.600,0.001
30.86,56.600,0.06438,5.633,0.001
31.05,56.800,0.06480,5.669,0.001
31.28,57.000,0.06517,5.711,0.001
31.41,57.200,0.06550,5.734,0.001
31.57,57.400,0.06584,5.764,0.001
31.71,57.600,0.06617,5.789,0.001
31.87,57.800,0.06646,5.819,0.001
31.98,58.000,0.06675,5.840,0.001
32.12,58.200,0.06700,5.864,0.001
32.23,58.400,0.06729,5.884,0.001
32.34,58.600,0.06754,5.904,0.001
32.49,58.800,0.06783,5.931,0.001
8.02,59.000,0.06808,1.464,0.001
7.63,59.200,0.06837,1.393,0.001
7.86,59.400,0.06866,1.435,0.001
8.11,59.600,0.06895,1.481,0.001
8.35,59.800,0.06924,1.524,0.001
8.53,60.000,0.06953,1.558,0.001
8.81,60.200,0.06987,1.608,0.001
8.92,60.400,0.07016,1.629,0.001
9.08,60.600,0.07049,1.658,0.001
9.24,60.800,0.07082,1.687,0.001
9.40,61.000,0.07116,1.717,0.001
9.54,61.200,0.07153,1.742,0.001
9.69,61.400,0.07190,1.770,0.001
9.90,61.600,0.07232,1.808,0.001
10.06,61.800,0.07278,1.837,0.001
10.23,62.000,0.07319,1.868,0.001
10.41,62.200,0.07365,1.901,0.001
10.56,62.400,0.07406,1.927,0.001
10.64,62.600,0.07444,1.942,0.001
10.81,62.800,0.07481,1.973,0.001
10.90,63.000,0.07519,1.991,0.001
11.03,63.200,0.07548,2.015,0.001
11.10,63.400,0.07581,2.026,0.001
11.19,63.600,0.07610,2.044,0.001
11.24,63.800,0.07635,2.053,0.002
11.30,64.000,0.07664,2.063,0.002
11.38,64.200,0.07693,2.078,0.002
11.45,64.400,0.07718,2.091,0.002
11.50,64.600,0.07747,2.099,0.002
11.58,64.800,0.07776,2.113,0.002
11.59,65.000,0.07805,2.117,0.002
11.68,65.200,0.07839,2.133,0.002
11.76,65.400,0.07868,2.147,0.002
11.81,65.600,0.07901,2.157,0.002
11.87,65.800,0.07930,2.167,0.002
11.89,66.000,0.07963,2.172,0.002
11.98,66.200,0.07997,2.187,0.002
12.01,66.400,0.08030,2.194,0.002
12.08,66.600,0.08063,2.205,0.002
12.16,66.800,0.08100,2.220,0.002
12.20,67.000,0.08142,2.228,0.002
12.26,67.200,0.08179,2.238,0.002
12.33,67.400,0.08225,2.252,0.002
12.37,67.600,0.08267,2.258,0.002
12.44,67.800,0.08312,2.270,0.002
12.44,68.000,0.08350,2.272,0.002
12.48,68.200,0.08391,2.279,0.002
12.52,68.400,0.08429,2.286,0.002
12.58,68.600,0.08462,2.297,0.002
12.57,68.800,0.08495,2.294,0.002
12.63,69.000,0.08524,2.306,0.002
12.66,69.200,0.08553,2.311,0.002
12.68,69.400,0.08582,2.316,0.002
12.68,69.600,0.08612,2.316,0.002
12.73,69.800,0.08637,2.324,0.002
12.75,70.000,0.08666,2.327,0.002
12.77,70.200,0.08695,2.332,0.002
12.81,70.400,0.08724,2.339,0.002
12.81,70.600,0.08753,2.339,0.002
12.89,70.800,0.08782,2.353,0.002
12.93,71.000,0.08815,2.360,0.002
12.95,71.200,0.08844,2.364,0.002
13.05,71.400,0.08878,2.383,0.002
13.09,71.600,0.08907,2.390,0.002
13.10,71.800,0.08940,2.392,0.002
13.12,72.000,0.08973,2.395,0.002
13.20,72.200,0.09006,2.410,0.002
13.25,72.400,0.09044,2.419,0.002
13.31,72.600,0.09081,2.430,0.002
13.38,72.800,0.09119,2.443,0.002
13.42,73.000,0.09164,2.450,0.002
13.49,73.200,0.09206,2.464,0.002
13.54,73.400,0.09247,2.472,0.002
13.59,73.600,0.09289,2.482,0.002
13.66,73.800,0.09326,2.494,0.002
13.73,74.000,0.09368,2.506,0.002
13.74,74.200,0.09401,2.509,0.002
13.78,74.400,0.09434,2.516,0.002
13.83,74.600,0.09463,2.525,0.002
13.88,74.800,0.09493,2.534,0.002
13.93,75.000,0.09522,2.543,0.002
13.97,75.200,0.09551,2.550,0.002
13.99,75.400,0.09576,2.555,0.002
14.04,75.600,0.09605,2.563,0.002
14.10,75.800,0.09634,2.574,0.002
14.15,76.000,0.09663,2.583,0.002
14.19,76.200,0.09692,2.590,0.002
14.26,76.400,0.09721,2.603,0.002
14.28,76.600,0.09750,2.608,0.002
14.39,76.800,0.09779,2.627,0.002
14.46,77.000,0.09813,2.640,0.002
14.45,77.200,0.09842,2.639,0.002
14.54,77.400,0.09875,2.654,0.002
14.56,77.600,0.09904,2.658,0.002
14.64,77.800,0.09937,2.673,0.002
14.73,78.000,0.09975,2.688,0.002
14.79,78.200,0.10012,2.701,0.002
14.82,78.400,0.10054,2.706,0.002
14.93,78.600,0.10095,2.725,0.002
14.99,78.800,0.10141,2.737,0.002
15.09,79.000,0.10182,2.756,0.002
15.14,79.200,0.10224,2.764,0.002
15.26,79.400,0.10261,2.786,0.002
15.32,79.600,0.10303,2.797,0.002
15.35,79.800,0.10336,2.802,0.002
15.38,80.000,0.10365,2.809,0.002
15.40,80.200,0.10398,2.811,0.002
15.48,80.400,0.10428,2.827,0.002
15.50,80.600,0.10452,2.830,0.002
15.55,80.800,0.10482,2.840,0.002
15.60,81.000,0.10507,2.847,0.002
15.61,81.200,0.10536,2.850,0.002
15.71,81.400,0.10565,2.868,0.002
15.74,81.600,0.10590,2.875,0.002
15.79,81.800,0.10619,2.882,0.002
15.87,82.000,0.10648,2.897,0.002
15.92,82.200,0.10677,2.907,0.002
15.95,82.400,0.10710,2.912,0.002
16.05,82.600,0.10739,2.930,0.002
16.10,82.800,0.10772,2.939,0.002
16.15,83.000,0.10802,2.949,0.002
16.22,83.200,0.10831,2.962,0.002
16.29,83.400,0.10868,2.974,0.002
16.35,83.600,0.10901,2.986,0.002
16.44,83.800,0.10935,3.002,0.002
16.54,84.000,0.10976,3.019,0.002
16.58,84.200,0.11018,3.026,0.002
16.65,84.400,0.11059,3.040,0.002
16.76,84.600,0.11101,3.060,0.002
16.83,84.800,0.11142,3.072,0.002
16.89,85.000,0.11184,3.084,0.002
16.96,85.200,0.11221,3.097,0.002
17.00,85.400,0.11259,3.104,0.002
17.07,85.600,0.11292,3.117,0.002
17.13,85.800,0.11325,3.127,0.002
17.20,86.000,0.11354,3.140,0.002
17.22,86.200,0.11383,3.145,0.002
17.25,86.400,0.11412,3.150,0.002
17.33,86.600,0.11437,3.164,0.002
17.39,86.800,0.11466,3.175,0.002
17.42,87.000,0.11491,3.181,0.002
17.49,87.200,0.11520,3.192,0.002
17.52,87.400,0.11550,3.198,0.002
17.60,87.600,0.11579,3.213,0.002
17.63,87.800,0.11608,3.219,0.002
17.71,88.000,0.11637,3.234,0.002
17.75,88.200,0.11666,3.241,0.002
17.80,88.400,0.11699,3.250,0.002
17.85,88.600,0.11728,3.260,0.002
17.91,88.800,0.11762,3.269,0.002
17.98,89.000,0.11791,3.283,0.002
18.06,89.200,0.11824,3.298,0.002
18.13,89.400,0.11857,3.310,0.002
18.23,89.600,0.11894,3.328,0.002
18.28,89.800,0.11932,3.338,0.002
18.41,90.000,0.11973,3.361,0.002
18.45,90.200,0.12015,3.369,0.002
18.52,90.400,0.12057,3.381,0.002
18.61,90.600,0.12098,3.398,0.002
18.66,90.800,0.12140,3.407,0.002
18.71,91.000,0.12177,3.417,0.002
18.80,91.200,0.12214,3.432,0.002
18.88,91.400,0.12248,3.447,0.002
18.89,91.600,0.12277,3.449,0.002
18.93,91.800,0.12310,3.456,0.002
18.99,92.000,0.12339,3.468,0.002
19.05,92.200,0.12368,3.478,0.002
19.12,92.400,0.12393,3.491,0.002
19.15,92.600,0.12422,3.497,0.002
19.19,92.800,0.12447,3.503,0.002
19.26,93.000,0.12476,3.517,0.002
19.33,93.200,0.12501,3.530,0.002
19.40,93.400,0.12530,3.543,0.002
19.40,93.600,0.12559,3.542,0.002
19.47,93.800,0.12593,3.554,0.002
19.54,94.000,0.12622,3.568,0.002
19.58,94.200,0.12655,3.576,0.002
19.62,94.400,0.12684,3.582,0.002
19.75,94.600,0.12717,3.605,0.003
19.76,94.800,0.12746,3.608,0.003
19.84,95.000,0.12780,3.622,0.003
19.93,95.200,0.12817,3.639,0.003
20.03,95.400,0.12854,3.656,0.003
20.13,95.600,0.12896,3.675,0.003
20.17,95.800,0.12938,3.683,0.003
20.28,96.000,0.12979,3.702,0.003
20.34,96.200,0.13025,3.714,0.003
20.46,96.400,0.13066,3.735,0.003
20.49,96.600,0.13104,3.741,0.003
20.55,96.800,0.13141,3.753,0.003
20.59,97.000,0.13179,3.759,0.003
20.65,97.200,0.13208,3.771,0.003
20.70,97.400,0.13237,3.779,0.003
20.75,97.600,0.13266,3.789,0.003
20.82,97.800,0.13295,3.802,0.003
20.86,98.000,0.13324,3.808,0.003
20.92,98.200,0.13349,3.819,0.003
20.95,98.400,0.13378,3.826,0.003
21.02,98.600,0.13403,3.838,0.003
21.07,98.800,0.13432,3.848,0.003
21.12,99.000,0.13461,3.857,0.003
21.18,99.200,0.13490,3.866,0.003
21.25,99.400,0.13519,3.880,0.003
21.34,99.600,0.13553,3.896,0.003
21.39,99.800,0.13582,3.905,0.003
21.46,100.000,0.13611,3.918,0.003
21.53,100.200,0.13644,3.930,0.003
21.57,100.400,0.13677,3.938,0.003
21.64,100.600,0.13710,3.951,0.003
21.74,100.800,0.13744,3.969,0.003
21.84,101.000,0.13781,3.987,0.003
21.94,101.200,0.13823,4.006,0.003
22.02,101.400,0.13864,4.020,0.003
22.11,101.600,0.13906,4.036,0.003
22.23,101.800,0.13952,4.058,0.003
22.32,102.000,0.13993,4.075,0.003
22.39,102.200,0.14035,4.087,0.003
22.47,102.400,0.14072,4.102,0.003
22.53,102.600,0.14109,4.114,0.003
22.61,102.800,0.14143,4.128,0.003
22.67,103.000,0.14172,4.138,0.003
22.70,103.200,0.14205,4.144,0.003
22.75,103.400,0.14234,4.154,0.003
22.81,103.600,0.14263,4.165,0.003
22.87,103.800,0.14288,4.176,0.003
22.93,104.000,0.14317,4.186,0.003
23.00,104.200,0.14342,4.199,0.003
23.05,104.400,0.14371,4.209,0.003
23.11,104.600,0.14400,4.219,0.003
23.17,104.800,0.14429,4.231,0.003
23.23,105.000,0.14463,4.241,0.003
23.29,105.200,0.14492,4.251,0.003
23.37,105.400,0.14525,4.266,0.003
23.46,105.600,0.14554,4.282,0.003
23.48,105.800,0.14587,4.286,0.003
23.55,106.000,0.14621,4.299,0.003
23.65,106.200,0.14654,4.317,0.003
23.78,106.400,0.14687,4.342,0.003
23.76,106.600,0.14724,4.337,0.003
23.90,106.800,0.14762,4.364,0.003
23.96,107.000,0.14803,4.374,0.003
24.08,107.200,0.14845,4.397,0.003
24.14,107.400,0.14887,4.408,0.003
24.23,107.600,0.14932,4.425,0.003
24.33,107.800,0.14970,4.442,0.003
24.44,108.000,0.15011,4.462,0.003
24.50,108.200,0.15044,4.474,0.003
24.55,108.400,0.15082,4.483,0.003
24.64,108.600,0.15111,4.498,0.003
24.71,108.800,0.15140,4.512,0.003
24.76,109.000,0.15173,4.520,0.003
24.81,109.200,0.15198,4.529,0.003
24.84,109.400,0.15227,4.535,0.003
24.87,109.600,0.15256,4.541,0.003
24.94,109.800,0.15281,4.553,0.003
25.01,110.000,0.15310,4.566,0.003
25.10,110.200,0.15335,4.582,0.003
25.18,110.400,0.15364,4.597,0.003
25.22,110.600,0.15393,4.605,0.003
25.31,110.800,0.15427,4.621,0.003
25.39,111.000,0.15456,4.635,0.003
25.46,111.200,0.15485,4.648,0.003
25.54,111.400,0.15518,4.662,0.003
25.63,111.600,0.15547,4.679,0.003
25.66,111.800,0.15580,4.686,0.003
25.78,112.000,0.15614,4.707,0.003
25.80,112.200,0.15647,4.711,0.003
25.94,112.400,0.15684,4.736,0.003
26.06,112.600,0.15726,4.758,0.003
26.15,112.800,0.15767,4.775,0.003
26.25,113.000,0.15813,4.793,0.003
26.36,113.200,0.15855,4.812,0.003
26.43,113.400,0.15896,4.825,0.003
26.53,113.600,0.15938,4.844,0.003
26.60,113.800,0.15971,4.856,0.003
26.63,114.000,0.16009,4.862,0.003
26.72,114.200,0.16042,4.878,0.003
26.80,114.400,0.16071,4.893,0.003
26.82,114.600,0.16100,4.897,0.003
26.91,114.800,0.16129,4.913,0.003
26.94,115.000,0.16154,4.919,0.003
27.00,115.200,0.16183,4.930,0.003
27.08,115.400,0.16208,4.944,0.003
27.16,115.600,0.16237,4.958,0.003
27.20,115.800,0.16262,4.965,0.003
27.28,116.000,0.16291,4.981,0.003
27.36,116.200,0.16320,4.996,0.003
27.43,116.400,0.16349,5.009,0.003
27.51,116.600,0.16383,5.023,0.003
27.56,116.800,0.16412,5.031,0.003
27.61,117.000,0.16441,5.041,0.003
27.71,117.200,0.16474,5.059,0.003
27.79,117.400,0.16507,5.074,0.003
27.87,117.600,0.16536,5.088,0.003
27.94,117.800,0.16574,5.102,0.003
28.01,118.000,0.16607,5.114,0.003
28.11,118.200,0.16644,5.132,0.003
28.21,118.400,0.16686,5.150,0.003
28.34,118.600,0.16727,5.173,0.003
28.40,118.800,0.16769,5.186,0.003
28.47,119.000,0.16811,5.197,0.003
28.55,119.200,0.16852,5.213,0.003
28.61,119.400,0.16894,5.223,0.003
28.71,119.600,0.16927,5.242,0.003
28.76,119.800,0.16964,5.250,0.003
28.81,120.000,0.16993,5.259,0.003
28.88,120.200,0.17027,5.273,0.003
28.93,120.400,0.17056,5.282,0.003
28.97,120.600,0.17081,5.289,0.003
29.06,120.800,0.17110,5.306,0.003
29.12,121.000,0.17135,5.316,0.003
29.15,121.200,0.17164,5.322,0.003
29.20,121.400,0.17189,5.332,0.003
29.30,121.600,0.17218,5.349,0.003
29.40,121.800,0.17247,5.367,0.003
29.45,122.000,0.17276,5.376,0.003
29.54,122.200,0.17309,5.392,0.003
29.64,122.400,0.17338,5.411,0.003
29.64,122.600,0.17372,5.412,0.003
29.72,122.800,0.17401,5.426,0.003
29.77,123.000,0.17434,5.435,0.003
29.87,123.200,0.17467,5.453,0.003
29.94,123.400,0.17500,5.466,0.003
30.02,123.600,0.17534,5.481,0.003
30.08,123.800,0.17571,5.492,0.003
30.22,124.000,0.17608,5.518,0.003
30.33,124.200,0.17650,5.537,0.003
30.41,124.400,0.17692,5.551,0.003
30.48,124.600,0.17733,5.565,0.003
30.58,124.800,0.17775,5.582,0.003
30.65,125.000,0.17812,5.597,0.004
30.77,125.200,0.17849,5.618,0.004
30.80,125.400,0.17887,5.623,0.004
30.84,125.600,0.17920,5.630,0.004
30.96,125.800,0.17949,5.653,0.004
30.99,126.000,0.17982,5.659,0.004
31.06,126.200,0.18012,5.671,0.004
31.15,126.400,0.18036,5.687,0.004
31.20,126.600,0.18066,5.696,0.004
31.23,126.800,0.18090,5.702,0.004
31.29,127.000,0.18120,5.712,0.004
31.37,127.200,0.18144,5.727,0.004
31.44,127.400,0.18174,5.740,0.004
31.49,127.600,0.18203,5.749,0.004
31.59,127.800,0.18232,5.767,0.004
31.66,128.000,0.18265,5.780,0.004
31.73,128.200,0.18294,5.794,0.004
31.80,128.400,0.18323,5.805,0.004
31.87,128.600,0.18356,5.818,0.004
31.95,128.800,0.18386,5.833,0.004
32.04,129.000,0.18419,5.849,0.004
32.14,129.200,0.18452,5.868,0.004
32.23,129.400,0.18485,5.885,0.004
32.33,129.600,0.18527,5.902,0.004
32.43,129.800,0.18564,5.921,0.004
32.53,130.000,0.18606,5.939,0.004
32.68,130.200,0.18651,5.966,0.004
32.76,130.400,0.18693,5.981,0.004
32.84,130.600,0.18735,5.996,0.004
32.93,130.800,0.18776,6.012,0.004
32.99,131.000,0.18814,6.024,0.004
33.09,131.200,0.18847,6.041,0.004
33.12,131.400,0.18880,6.046,0.004
33.15,131.600,0.18909,6.052,0.004
33.25,131.800,0.18938,6.070,0.004
33.29,132.000,0.18967,6.078,0.004
33.33,132.200,0.18996,6.086,0.004
33.40,132.400,0.19021,6.097,0.004
33.45,132.600,0.19050,6.106,0.004
33.53,132.800,0.19079,6.121,0.004
33.60,133.000,0.19104,6.135,0.004
33.66,133.200,0.19134,6.146,0.004
33.75,133.400,0.19167,6.161,0.004
33.83,133.600,0.19196,6.176,0.004
33.89,133.800,0.19225,6.188,0.004
33.99,134.000,0.19258,6.206,0.004
34.08,134.200,0.19291,6.222,0.004
34.15,134.400,0.19321,6.235,0.004
34.23,134.600,0.19354,6.249,0.004
34.31,134.800,0.19387,6.263,0.004
34.40,135.000,0.19424,6.280,0.004
34.51,135.200,0.19462,6.301,0.004
34.62,135.400,0.19503,6.321,0.004
34.74,135.600,0.19545,6.342,0.004
34.85,135.800,0.19591,6.364,0.004
34.97,136.000,0.19636,6.384,0.004
35.05,136.200,0.19678,6.399,0.004
35.16,136.400,0.19715,6.419,0.004
35.23,136.600,0.19757,6.432,0.004
35.32,136.800,0.19790,6.448,0.004
35.37,137.000,0.19823,6.457,0.004
35.42,137.200,0.19857,6.467,0.004
35.52,137.400,0.19886,6.485,0.004
35.57,137.600,0.19915,6.494,0.004
35.64,137.800,0.19944,6.507,0.004
35.69,138.000,0.19973,6.516,0.004
35.74,138.200,0.19998,6.525,0.004
35.82,138.400,0.20027,6.539,0.004
35.90,138.600,0.20056,6.555,0.004
35.98,138.800,0.20085,6.568,0.004
36.07,139.000,0.20118,6.586,0.004
36.18,139.200,0.20147,6.605,0.004
36.23,139.400,0.20181,6.615,0.004
36.33,139.600,0.20210,6.633,0.004
36.40,139.800,0.20243,6.646,0.004
36.49,140.000,0.20272,6.661,0.004
36.58,140.200,0.20305,6.678,0.004
36.67,140.400,0.20339,6.695,0.004
36.74,140.600,0.20376,6.707,0.004
36.86,140.800,0.20413,6.729,0.004
36.95,141.000,0.20451,6.746,0.004
37.06,141.200,0.20492,6.766,0.004
37.19,141.400,0.20538,6.789,0.004
37.27,141.600,0.20580,6.804,0.004
37.39,141.800,0.20621,6.826,0.004
37.47,142.000,0.20659,6.841,0.004
37.55,142.200,0.20696,6.855,0.004
37.62,142.400,0.20733,6.868,0.004
37.67,142.600,0.20767,6.877,0.004
37.74,142.800,0.20796,6.891,0.004
37.81,143.000,0.20825,6.904,0.004
37.88,143.200,0.20854,6.916,0.004
37.92,143.400,0.20883,6.924,0.004
38.00,143.600,0.20912,6.938,0.004
38.07,143.800,0.20937,6.950,0.004
38.12,144.000,0.20966,6.960,0.004
38.21,144.200,0.20991,6.975,0.004
38.27,144.400,0.21020,6.986,0.004
38.36,144.600,0.21049,7.003,0.004
38.44,144.800,0.21082,7.017,0.004
38.52,145.000,0.21112,7.032,0.004
38.59,145.200,0.21145,7.045,0.004
38.68,145.400,0.21174,7.062,0.004
38.77,145.600,0.21207,7.078,0.004
38.84,145.800,0.21240,7.092,0.004
38.94,146.000,0.21274,7.110,0.004
39.02,146.200,0.21307,7.124,0.004
39.16,146.400,0.21344,7.149,0.004
39.23,146.600,0.21382,7.163,0.004
39.35,146.800,0.21423,7.184,0.004
39.50,147.000,0.21469,7.212,0.004
39.63,147.200,0.21511,7.235,0.004
39.74,147.400,0.21552,7.255,0.004
39.83,147.600,0.21594,7.273,0.004
39.91,147.800,0.21635,7.287,0.004
40.01,148.000,0.21673,7.305,0.004
40.07,148.200,0.21706,7.315,0.004
40.15,148.400,0.21735,7.330,0.004
40.20,148.600,0.21768,7.339,0.004
40.27,148.800,0.21797,7.352,0.004
40.31,149.000,0.21822,7.360,0.004
40.40,149.200,0.21851,7.377,0.004
40.45,149.400,0.21876,7.385,0.004
40.55,149.600,0.21905,7.403,0.004
40.62,149.800,0.21934,7.416,0.004
40.69,150.000,0.21963,7.429,0.004
40.76,150.200,0.21993,7.442,0.004
40.85,150.400,0.22022,7.457,0.004
40.92,150.600,0.22051,7.471,0.004
41.03,150.800,0.22084,7.491,0.004
41.10,151.000,0.22113,7.504,0.004
41.19,151.200,0.22146,7.520,0.004
41.29,151.400,0.22180,7.538,0.004
41.37,151.600,0.22213,7.553,0.004
41.47,151.800,0.22246,7.571,0.004
41.57,152.000,0.22283,7.589,0.004
41.67,152.200,0.22325,7.608,0.004
41.83,152.400,0.22367,7.636,0.004
41.93,152.600,0.22408,7.655,0.004
42.06,152.800,0.22454,7.678,0.004
42.19,153.000,0.22500,7.702,0.004
42.25,153.200,0.22541,7.714,0.004
42.34,153.400,0.22578,7.730,0.004
42.40,153.600,0.22616,7.742,0.004
42.47,153.800,0.22649,7.754,0.004
42.52,154.000,0.22678,7.763,0.004
42.59,154.200,0.22707,7.775,0.004
42.66,154.400,0.22741,7.789,0.004
42.71,154.600,0.22765,7.799,0.004
42.78,154.800,0.22795,7.811,0.004
19.15,155.000,0.22820,3.497,0.004
2.94,155.030,0.22824,0.537,0.004