File: data-files/mech3/WH15Y.txt
""
"Test Method","Will_Huddleston_Disks.msm"
"Sample I. D.","WH15Y.mss"
"Specimen Number","1"

"Load (N)","Time (s)","Extension (mm)","Stress (MPa)","Strain (mm/mm)"

6.81,0.200,-0.00740,1.258,0.000
6.81,0.400,-0.00735,1.259,0.000
6.80,0.600,-0.00735,1.256,0.000
6.79,0.800,-0.00731,1.255,0.000
6.83,1.000,-0.00727,1.262,0.000
6.83,1.200,-0.00727,1.262,0.000
6.84,1.400,-0.00723,1.263,0.000
6.88,1.600,-0.00719,1.271,0.000
6.81,1.800,-0.00710,1.258,0.000
6.88,2.000,-0.00690,1.272,0.000
7.03,2.200,-0.00661,1.299,0.000
7.12,2.400,-0.00627,1.317,0.000
7.22,2.600,-0.00598,1.334,0.000
7.28,2.800,-0.00569,1.345,0.000
7.32,3.000,-0.00544,1.352,0.000
7.36,3.200,-0.00515,1.360,0.000
7.42,3.400,-0.00490,1.371,0.000
7.46,3.600,-0.00465,1.378,0.000
7.50,3.800,-0.00440,1.386,0.000
7.53,4.000,-0.00415,1.392,0.000
7.63,4.200,-0.00386,1.410,0.000
7.65,4.400,-0.00361,1.414,0.000
7.71,4.600,-0.00332,1.425,0.000
7.72,4.800,-0.00303,1.427,0.000
7.74,5.000,-0.00278,1.431,0.000
7.81,5.200,-0.00245,1.443,0.000
7.84,5.400,-0.00216,1.448,0.000
7.90,5.600,-0.00187,1.461,0.000
7.96,5.800,-0.00154,1.472,0.000
7.97,6.000,-0.00125,1.474,0.000
8.05,6.200,-0.00087,1.487,0.000
8.07,6.400,-0.00054,1.492,0.000
8.13,6.600,-0.00016,1.503,0.000
8.18,6.800,0.00021,1.512,0.000
8.22,7.000,0.00062,1.519,0.000
8.28,7.200,0.00104,1.531,0.000
8.35,7.400,0.00146,1.542,0.000
8.40,7.600,0.00183,1.552,0.000
8.45,7.800,0.00225,1.562,0.000
8.50,8.000,0.00262,1.570,0.000
8.56,8.200,0.00295,1.582,0.000
8.57,8.400,0.00328,1.585,0.000
8.60,8.600,0.00358,1.589,0.000
8.64,8.800,0.00387,1.597,0.000
8.65,9.000,0.00416,1.599,0.000
8.69,9.200,0.00445,1.605,0.000
8.72,9.400,0.00470,1.611,0.000
8.76,9.600,0.00499,1.620,0.000
8.78,9.800,0.00524,1.622,0.000
8.85,10.000,0.00553,1.635,0.000
8.85,10.200,0.00582,1.636,0.000
8.90,10.400,0.00611,1.646,0.000
8.95,10.600,0.00644,1.654,0.000
9.03,10.800,0.00673,1.669,0.000
9.09,11.000,0.00707,1.681,0.000
9.10,11.200,0.00736,1.682,0.000
9.14,11.400,0.00769,1.690,0.000
9.20,11.600,0.00802,1.700,0.000
9.25,11.800,0.00835,1.709,0.000
9.32,12.000,0.00873,1.722,0.000
9.35,12.200,0.00910,1.728,0.000
9.40,12.400,0.00952,1.738,0.000
9.45,12.600,0.00993,1.747,0.000
9.53,12.800,0.01039,1.761,0.000
9.57,13.000,0.01081,1.769,0.000
9.64,13.200,0.01122,1.781,0.000
9.70,13.400,0.01164,1.792,0.000
9.73,13.600,0.01201,1.799,0.000
9.80,13.800,0.01234,1.811,0.000
9.79,14.000,0.01268,1.810,0.000
9.83,14.200,0.01301,1.817,0.000
9.88,14.400,0.01330,1.825,0.000
9.92,14.600,0.01359,1.833,0.000
9.93,14.800,0.01384,1.835,0.000
9.93,15.000,0.01413,1.835,0.000
9.97,15.200,0.01438,1.843,0.000
9.99,15.400,0.01467,1.845,0.000
9.96,15.600,0.01492,1.841,0.000
10.02,15.800,0.01521,1.851,0.000
10.02,16.000,0.01550,1.852,0.000
10.10,16.200,0.01579,1.867,0.000
10.11,16.400,0.01613,1.869,0.000
10.14,16.600,0.01642,1.874,0.000
10.18,16.800,0.01675,1.882,0.000
10.19,17.000,0.01704,1.883,0.000
10.25,17.200,0.01737,1.895,0.000
10.31,17.400,0.01770,1.906,0.000
10.32,17.600,0.01804,1.907,0.000
10.42,17.800,0.01841,1.926,0.000
10.45,18.000,0.01878,1.931,0.000
10.52,18.200,0.01924,1.944,0.000
10.58,18.400,0.01966,1.955,0.000
10.64,18.600,0.02011,1.966,0.000
10.72,18.800,0.02053,1.981,0.000
10.76,19.000,0.02095,1.988,0.000
10.78,19.200,0.02132,1.992,0.000
10.83,19.400,0.02169,2.001,0.000
10.85,19.600,0.02203,2.006,0.000
10.90,19.800,0.02232,2.014,0.000
10.93,20.000,0.02261,2.020,0.000
10.97,20.200,0.02286,2.027,0.000
11.00,20.400,0.02315,2.033,0.000
11.06,20.600,0.02340,2.044,0.000
11.03,20.800,0.02369,2.039,0.000
11.12,21.000,0.02394,2.055,0.000
11.17,21.200,0.02423,2.063,0.000
11.20,21.400,0.02452,2.070,0.000
11.26,21.600,0.02481,2.081,0.000
11.29,21.800,0.02510,2.087,0.000
11.34,22.000,0.02539,2.096,0.000
11.40,22.200,0.02568,2.107,0.001
11.41,22.400,0.02597,2.108,0.001
11.52,22.600,0.02631,2.128,0.001
11.52,22.800,0.02664,2.128,0.001
11.57,23.000,0.02697,2.137,0.001
11.61,23.200,0.02726,2.145,0.001
11.70,23.400,0.02764,2.162,0.001
11.74,23.600,0.02801,2.169,0.001
11.82,23.800,0.02843,2.184,0.001
11.86,24.000,0.02884,2.191,0.001
11.94,24.200,0.02930,2.206,0.001
11.97,24.400,0.02971,2.213,0.001
12.06,24.600,0.03013,2.229,0.001
12.10,24.800,0.03055,2.236,0.001
12.13,25.000,0.03092,2.242,0.001
12.21,25.200,0.03125,2.256,0.001
12.23,25.400,0.03158,2.260,0.001
12.27,25.600,0.03192,2.267,0.001
12.32,25.800,0.03221,2.278,0.001
12.35,26.000,0.03250,2.282,0.001
12.37,26.200,0.03275,2.286,0.001
12.44,26.400,0.03304,2.300,0.001
12.44,26.600,0.03329,2.298,0.001
12.52,26.800,0.03358,2.314,0.001
12.59,27.000,0.03387,2.327,0.001
12.62,27.200,0.03416,2.332,0.001
12.68,27.400,0.03445,2.344,0.001
12.74,27.600,0.03478,2.355,0.001
12.78,27.800,0.03507,2.362,0.001
12.82,28.000,0.03541,2.369,0.001
12.87,28.200,0.03570,2.378,0.001
12.96,28.400,0.03603,2.394,0.001
12.98,28.600,0.03632,2.399,0.001
13.03,28.800,0.03665,2.408,0.001
13.10,29.000,0.03703,2.421,0.001
13.18,29.200,0.03740,2.436,0.001
13.17,29.400,0.03778,2.435,0.001
13.30,29.600,0.03819,2.458,0.001
13.39,29.800,0.03861,2.474,0.001
13.50,30.000,0.03906,2.495,0.001
13.51,30.200,0.03948,2.497,0.001
13.58,30.400,0.03985,2.510,0.001
13.63,30.600,0.04023,2.519,0.001
13.68,30.800,0.04060,2.529,0.001
13.73,31.000,0.04093,2.538,0.001
13.80,31.200,0.04122,2.550,0.001
13.82,31.400,0.04156,2.555,0.001
13.87,31.600,0.04181,2.563,0.001
13.92,31.800,0.04210,2.573,0.001
13.94,32.000,0.04239,2.577,0.001
13.97,32.200,0.04264,2.581,0.001
14.04,32.400,0.04289,2.595,0.001
14.10,32.600,0.04318,2.605,0.001
14.18,32.800,0.04347,2.621,0.001
14.23,33.000,0.04372,2.629,0.001
14.27,33.200,0.04401,2.638,0.001
14.32,33.400,0.04434,2.646,0.001
14.39,33.600,0.04463,2.660,0.001
14.40,33.800,0.04492,2.660,0.001
14.47,34.000,0.04526,2.674,0.001
14.57,34.200,0.04555,2.693,0.001
14.60,34.400,0.04588,2.699,0.001
14.64,34.600,0.04621,2.706,0.001
14.71,34.800,0.04654,2.719,0.001
14.78,35.000,0.04692,2.732,0.001
14.87,35.200,0.04733,2.748,0.001
14.92,35.400,0.04771,2.756,0.001
15.03,35.600,0.04816,2.777,0.001
15.12,35.800,0.04858,2.795,0.001
15.18,36.000,0.04900,2.805,0.001
15.25,36.200,0.04941,2.819,0.001
15.31,36.400,0.04974,2.830,0.001
15.36,36.600,0.05012,2.838,0.001
15.44,36.800,0.05045,2.853,0.001
15.48,37.000,0.05074,2.861,0.001
15.55,37.200,0.05103,2.873,0.001
15.58,37.400,0.05128,2.878,0.001
15.65,37.600,0.05157,2.892,0.001
15.66,37.800,0.05182,2.895,0.001
15.75,38.000,0.05207,2.911,0.001
15.79,38.200,0.05236,2.918,0.001
15.86,38.400,0.05265,2.930,0.001
15.90,38.600,0.05294,2.938,0.001
15.95,38.800,0.05323,2.948,0.001
16.03,39.000,0.05353,2.963,0.001
16.07,39.200,0.05386,2.970,0.001
16.19,39.400,0.05415,2.991,0.001
16.20,39.600,0.05448,2.995,0.001
16.28,39.800,0.05481,3.009,0.001
16.34,40.000,0.05515,3.019,0.001
16.41,40.200,0.05548,3.032,0.001
16.48,40.400,0.05581,3.045,0.001
16.58,40.600,0.05618,3.064,0.001
16.69,40.800,0.05660,3.084,0.001
16.76,41.000,0.05702,3.098,0.001
16.90,41.200,0.05747,3.123,0.001
16.97,41.400,0.05793,3.136,0.001
17.09,41.600,0.05835,3.159,0.001
17.15,41.800,0.05876,3.169,0.001
17.21,42.000,0.05914,3.181,0.001
17.28,42.200,0.05951,3.194,0.001
17.36,42.400,0.05980,3.208,0.001
17.43,42.600,0.06013,3.221,0.001
17.47,42.800,0.06042,3.229,0.001
17.57,43.000,0.06071,3.247,0.001
17.61,43.200,0.06101,3.255,0.001
17.66,43.400,0.06125,3.264,0.001
17.75,43.600,0.06155,3.281,0.001
17.81,43.800,0.06180,3.291,0.001
17.87,44.000,0.06209,3.303,0.001
17.97,44.200,0.06238,3.321,0.001
17.99,44.400,0.06267,3.325,0.001
18.09,44.600,0.06300,3.343,0.001
18.14,44.800,0.06329,3.353,0.001
18.22,45.000,0.06362,3.368,0.001
18.29,45.200,0.06391,3.380,0.001
18.36,45.400,0.06425,3.393,0.001
18.47,45.600,0.06458,3.413,0.001
18.51,45.800,0.06491,3.420,0.001
18.61,46.000,0.06529,3.439,0.001
18.73,46.200,0.06562,3.461,0.001
18.83,46.400,0.06603,3.480,0.001
18.92,46.600,0.06645,3.496,0.001
19.01,46.800,0.06686,3.513,0.001
19.15,47.000,0.06728,3.539,0.001
19.24,47.200,0.06770,3.556,0.001
19.31,47.400,0.06811,3.568,0.001
19.40,47.600,0.06849,3.585,0.001
19.52,47.800,0.06886,3.607,0.001
19.52,48.000,0.06919,3.607,0.001
19.69,48.200,0.06952,3.638,0.001
19.70,48.400,0.06982,3.640,0.001
19.82,48.600,0.07011,3.662,0.001
19.87,48.800,0.07040,3.672,0.001
19.93,49.000,0.07065,3.683,0.001
19.98,49.200,0.07094,3.693,0.001
20.04,49.400,0.07119,3.703,0.001
20.10,49.600,0.07148,3.714,0.001
20.19,49.800,0.07173,3.731,0.001
20.22,50.000,0.07202,3.736,0.001
20.34,50.200,0.07231,3.760,0.001
20.43,50.400,0.07260,3.775,0.001
20.47,50.600,0.07293,3.783,0.001
20.60,50.800,0.07322,3.806,0.001
20.63,51.000,0.07356,3.812,0.001
20.73,51.200,0.07385,3.830,0.001
20.82,51.400,0.07418,3.847,0.001
20.94,51.600,0.07451,3.870,0.001
20.98,51.800,0.07484,3.877,0.001
21.11,52.000,0.07522,3.902,0.001
21.23,52.200,0.07563,3.923,0.001
21.29,52.400,0.07605,3.935,0.001
21.44,52.600,0.07651,3.962,0.002
21.55,52.800,0.07692,3.982,0.002
21.68,53.000,0.07734,4.006,0.002
21.75,53.200,0.07771,4.019,0.002
21.83,53.400,0.07808,4.035,0.002
21.95,53.600,0.07842,4.056,0.002
22.01,53.800,0.07875,4.068,0.002
22.06,54.000,0.07908,4.077,0.002
22.16,54.200,0.07937,4.095,0.002
22.22,54.400,0.07962,4.107,0.002
22.29,54.600,0.07991,4.118,0.002
22.34,54.800,0.08016,4.128,0.002
22.44,55.000,0.08041,4.148,0.002
22.51,55.200,0.08070,4.160,0.002
22.57,55.400,0.08095,4.171,0.002
22.65,55.600,0.08124,4.186,0.002
22.74,55.800,0.08153,4.202,0.002
22.84,56.000,0.08182,4.221,0.002
22.93,56.200,0.08212,4.237,0.002
22.98,56.400,0.08241,4.247,0.002
23.08,56.600,0.08274,4.266,0.002
23.17,56.800,0.08303,4.283,0.002
23.27,57.000,0.08336,4.301,0.002
23.37,57.200,0.08369,4.318,0.002
23.43,57.400,0.08403,4.330,0.002
23.54,57.600,0.08440,4.351,0.002
23.70,57.800,0.08478,4.380,0.002
23.79,58.000,0.08515,4.396,0.002
23.89,58.200,0.08556,4.415,0.002
24.03,58.400,0.08602,4.440,0.002
24.12,58.600,0.08644,4.458,0.002
24.26,58.800,0.08685,4.483,0.002
24.38,59.000,0.08723,4.505,0.002
24.48,59.200,0.08760,4.524,0.002
24.57,59.400,0.08798,4.541,0.002
24.61,59.600,0.08827,4.549,0.002
24.73,59.800,0.08860,4.570,0.002
24.81,60.000,0.08889,4.586,0.002
24.90,60.200,0.08918,4.601,0.002
24.96,60.400,0.08947,4.614,0.002
25.03,60.600,0.08972,4.625,0.002
25.14,60.800,0.08997,4.645,0.002
25.18,61.000,0.09026,4.654,0.002
25.27,61.200,0.09051,4.670,0.002
25.35,61.400,0.09080,4.686,0.002
25.44,61.600,0.09109,4.702,0.002
25.52,61.800,0.09138,4.716,0.002
25.63,62.000,0.09172,4.737,0.002
25.72,62.200,0.09201,4.754,0.002
25.81,62.400,0.09234,4.769,0.002
25.91,62.600,0.09263,4.788,0.002
25.99,62.800,0.09296,4.803,0.002
26.10,63.000,0.09329,4.824,0.002
26.20,63.200,0.09363,4.841,0.002
26.25,63.400,0.09400,4.852,0.002
26.38,63.600,0.09437,4.876,0.002
26.49,63.800,0.09479,4.895,0.002
26.62,64.000,0.09521,4.919,0.002
26.75,64.200,0.09562,4.944,0.002
26.87,64.400,0.09604,4.966,0.002
26.99,64.600,0.09641,4.988,0.002
27.11,64.800,0.09679,5.010,0.002
27.19,65.000,0.09716,5.025,0.002
27.26,65.200,0.09749,5.038,0.002
27.37,65.400,0.09782,5.059,0.002
27.45,65.600,0.09811,5.073,0.002
27.53,65.800,0.09841,5.088,0.002
27.61,66.000,0.09870,5.102,0.002
27.68,66.200,0.09895,5.116,0.002
27.76,66.400,0.09924,5.130,0.002
27.82,66.600,0.09949,5.142,0.002
27.89,66.800,0.09978,5.154,0.002
27.97,67.000,0.10007,5.168,0.002
22.53,67.200,0.10032,4.164,0.002
23.12,67.400,0.10061,4.272,0.002
23.29,67.600,0.10094,4.303,0.002
23.46,67.800,0.10123,4.335,0.002
23.64,68.000,0.10152,4.369,0.002
23.80,68.200,0.10185,4.398,0.002
24.00,68.400,0.10219,4.435,0.002
24.14,68.600,0.10248,4.462,0.002
24.32,68.800,0.10281,4.494,0.002
24.50,69.000,0.10318,4.528,0.002
24.72,69.200,0.10356,4.568,0.002
24.89,69.400,0.10397,4.599,0.002
25.11,69.600,0.10439,4.640,0.002
25.30,69.800,0.10485,4.676,0.002
25.49,70.000,0.10526,4.710,0.002
25.65,70.200,0.10568,4.740,0.002
25.82,70.400,0.10609,4.772,0.002
25.97,70.600,0.10647,4.799,0.002
26.10,70.800,0.10680,4.823,0.002
26.23,71.000,0.10713,4.847,0.002
26.32,71.200,0.10742,4.865,0.002
26.46,71.400,0.10771,4.891,0.002
26.58,71.600,0.10801,4.913,0.002
26.68,71.800,0.10830,4.931,0.002
26.76,72.000,0.10855,4.945,0.002
26.91,72.200,0.10879,4.973,0.002
27.03,72.400,0.10909,4.995,0.002
27.12,72.600,0.10938,5.011,0.002
27.19,72.800,0.10963,5.024,0.002
27.30,73.000,0.10996,5.045,0.002
27.42,73.200,0.11025,5.068,0.002
27.51,73.400,0.11054,5.084,0.002
27.66,73.600,0.11087,5.111,0.002
27.80,73.800,0.11120,5.138,0.002
27.93,74.000,0.11154,5.161,0.002
28.06,74.200,0.11183,5.186,0.002
28.16,74.400,0.11216,5.205,0.002
28.32,74.600,0.11253,5.234,0.002
28.44,74.800,0.11291,5.256,0.002
28.61,75.000,0.11332,5.287,0.002
28.77,75.200,0.11374,5.317,0.002
28.95,75.400,0.11416,5.350,0.002
29.10,75.600,0.11461,5.378,0.002
29.25,75.800,0.11503,5.405,0.002
29.38,76.000,0.11544,5.430,0.002
29.51,76.200,0.11582,5.453,0.002
29.57,76.400,0.11615,5.464,0.002
9.64,76.600,0.11652,1.782,0.002
10.02,76.800,0.11681,1.852,0.002
10.22,77.000,0.11715,1.889,0.002
10.41,77.200,0.11744,1.925,0.002
10.59,77.400,0.11769,1.957,0.002
10.68,77.600,0.11798,1.974,0.002
10.80,77.800,0.11823,1.995,0.002
10.89,78.000,0.11852,2.013,0.002
11.02,78.200,0.11881,2.036,0.002
11.12,78.400,0.11910,2.056,0.002
11.23,78.600,0.11939,2.075,0.002
11.35,78.800,0.11968,2.097,0.002
11.45,79.000,0.12001,2.116,0.002
11.55,79.200,0.12031,2.134,0.002
11.67,79.400,0.12064,2.156,0.002
11.76,79.600,0.12093,2.174,0.002
11.85,79.800,0.12126,2.190,0.002
11.97,80.000,0.12159,2.212,0.002
12.07,80.200,0.12197,2.231,0.002
12.19,80.400,0.12234,2.254,0.002
12.30,80.600,0.12272,2.274,0.002
12.44,80.800,0.12313,2.299,0.002
12.52,81.000,0.12355,2.313,0.002
12.65,81.200,0.12400,2.338,0.002
12.72,81.400,0.12442,2.351,0.002
12.84,81.600,0.12479,2.373,0.002
12.94,81.800,0.12521,2.392,0.002
13.04,82.000,0.12554,2.409,0.002
13.12,82.200,0.12587,2.425,0.002
13.17,82.400,0.12621,2.434,0.002
13.27,82.600,0.12654,2.452,0.002
13.33,82.800,0.12683,2.463,0.002
13.35,83.000,0.12712,2.468,0.003
13.43,83.200,0.12737,2.482,0.003
13.50,83.400,0.12766,2.495,0.003
13.57,83.600,0.12791,2.508,0.003
13.63,83.800,0.12820,2.520,0.003
13.67,84.000,0.12849,2.526,0.003
13.79,84.200,0.12878,2.548,0.003
13.87,84.400,0.12907,2.564,0.003
13.92,84.600,0.12936,2.573,0.003
13.95,84.800,0.12970,2.578,0.003
14.07,85.000,0.12999,2.601,0.003
14.13,85.200,0.13032,2.612,0.003
14.16,85.400,0.13065,2.617,0.003
14.28,85.600,0.13099,2.638,0.003
14.33,85.800,0.13132,2.648,0.003
14.47,86.000,0.13169,2.674,0.003
14.51,86.200,0.13211,2.681,0.003
14.60,86.400,0.13248,2.697,0.003
14.69,86.600,0.13294,2.715,0.003
14.79,86.800,0.13335,2.734,0.003
14.90,87.000,0.13381,2.754,0.003
14.99,87.200,0.13423,2.771,0.003
15.05,87.400,0.13460,2.781,0.003
15.12,87.600,0.13497,2.794,0.003
15.19,87.800,0.13531,2.808,0.003
15.24,88.000,0.13564,2.817,0.003
15.33,88.200,0.13593,2.833,0.003
15.39,88.400,0.13622,2.844,0.003
15.40,88.600,0.13651,2.846,0.003
15.48,88.800,0.13680,2.861,0.003
15.55,89.000,0.13705,2.874,0.003
15.58,89.200,0.13730,2.879,0.003
15.64,89.400,0.13759,2.890,0.003
15.68,89.600,0.13788,2.898,0.003
15.78,89.800,0.13817,2.916,0.003
15.84,90.000,0.13847,2.927,0.003
15.88,90.200,0.13880,2.935,0.003
15.94,90.400,0.13909,2.947,0.003
15.99,90.600,0.13942,2.956,0.003
16.06,90.800,0.13971,2.968,0.003
16.15,91.000,0.14004,2.985,0.003
16.21,91.200,0.14038,2.997,0.003
16.33,91.400,0.14071,3.018,0.003
16.39,91.600,0.14108,3.029,0.003
16.48,91.800,0.14150,3.045,0.003
16.57,92.000,0.14191,3.062,0.003
16.65,92.200,0.14233,3.077,0.003
16.74,92.400,0.14279,3.094,0.003
16.83,92.600,0.14320,3.110,0.003
16.92,92.800,0.14362,3.127,0.003
16.99,93.000,0.14403,3.140,0.003
17.02,93.200,0.14441,3.146,0.003
17.07,93.400,0.14474,3.155,0.003
17.16,93.600,0.14507,3.171,0.003
17.20,93.800,0.14541,3.179,0.003
17.24,94.000,0.14570,3.186,0.003
17.34,94.200,0.14599,3.204,0.003
17.36,94.400,0.14624,3.207,0.003
17.38,94.600,0.14653,3.212,0.003
17.45,94.800,0.14678,3.224,0.003
17.49,95.000,0.14707,3.232,0.003
17.54,95.200,0.14736,3.241,0.003
17.59,95.400,0.14765,3.251,0.003
17.65,95.600,0.14798,3.263,0.003
17.73,95.800,0.14827,3.276,0.003
17.79,96.000,0.14861,3.287,0.003
17.84,96.200,0.14890,3.298,0.003
17.89,96.400,0.14923,3.307,0.003
17.98,96.600,0.14956,3.322,0.003
18.03,96.800,0.14985,3.332,0.003
18.10,97.000,0.15023,3.346,0.003
18.16,97.200,0.15056,3.356,0.003
18.23,97.400,0.15093,3.369,0.003
18.32,97.600,0.15135,3.385,0.003
18.42,97.800,0.15180,3.404,0.003
18.54,98.000,0.15222,3.426,0.003
18.61,98.200,0.15264,3.439,0.003
18.67,98.400,0.15305,3.450,0.003
18.77,98.600,0.15347,3.468,0.003
18.79,98.800,0.15384,3.472,0.003
18.81,99.000,0.15417,3.476,0.003
18.86,99.200,0.15451,3.485,0.003
17.79,99.400,0.15480,3.288,0.003
17.94,99.600,0.15509,3.316,0.003
18.03,99.800,0.15538,3.331,0.003
18.14,100.000,0.15567,3.352,0.003
18.20,100.200,0.15592,3.363,0.003
18.28,100.400,0.15621,3.379,0.003
18.31,100.600,0.15650,3.384,0.003
18.40,100.800,0.15675,3.400,0.003
18.49,101.000,0.15704,3.417,0.003
18.56,101.200,0.15733,3.431,0.003
18.62,101.400,0.15766,3.441,0.003
18.68,101.600,0.15796,3.453,0.003
18.75,101.800,0.15829,3.465,0.003
18.79,102.000,0.15862,3.473,0.003
18.88,102.200,0.15891,3.488,0.003
18.93,102.400,0.15924,3.498,0.003
19.02,102.600,0.15958,3.515,0.003
19.06,102.800,0.15991,3.523,0.003
19.13,103.000,0.16028,3.535,0.003
19.21,103.200,0.16070,3.550,0.003
19.25,103.400,0.16111,3.557,0.003
19.34,103.600,0.16157,3.575,0.003
19.39,103.800,0.16199,3.584,0.003
19.44,104.000,0.16240,3.593,0.003
19.53,104.200,0.16282,3.610,0.003
19.59,104.400,0.16319,3.620,0.003
19.60,104.600,0.16357,3.622,0.003
19.64,104.800,0.16390,3.629,0.003
19.61,105.000,0.16419,3.625,0.003
19.68,105.200,0.16448,3.637,0.003
19.74,105.400,0.16477,3.648,0.003
19.76,105.600,0.16506,3.652,0.003
19.80,105.800,0.16531,3.659,0.003
19.81,106.000,0.16560,3.662,0.003
19.85,106.200,0.16585,3.669,0.003
19.90,106.400,0.16614,3.678,0.003
19.91,106.600,0.16643,3.680,0.003
19.96,106.800,0.16672,3.688,0.003
20.04,107.000,0.16701,3.703,0.003
20.10,107.200,0.16735,3.715,0.003
20.12,107.400,0.16764,3.717,0.003
20.19,107.600,0.16797,3.732,0.003
20.28,107.800,0.16826,3.747,0.003
20.30,108.000,0.16859,3.751,0.003
20.38,108.200,0.16893,3.766,0.003
20.45,108.400,0.16926,3.779,0.003
20.51,108.600,0.16967,3.791,0.003
20.60,108.800,0.17005,3.807,0.003
20.66,109.000,0.17046,3.818,0.003
20.72,109.200,0.17088,3.830,0.003
20.79,109.400,0.17134,3.841,0.003
20.88,109.600,0.17175,3.858,0.003
20.95,109.800,0.17213,3.871,0.003
21.00,110.000,0.17254,3.881,0.003
21.07,110.200,0.17292,3.893,0.003
21.09,110.400,0.17321,3.898,0.003
21.10,110.600,0.17354,3.899,0.003
21.19,110.800,0.17387,3.915,0.003
21.24,111.000,0.17416,3.926,0.003
21.27,111.200,0.17441,3.931,0.003
21.33,111.400,0.17470,3.942,0.003
21.41,111.600,0.17495,3.956,0.003
21.43,111.800,0.17524,3.960,0.003
21.47,112.000,0.17549,3.969,0.003
21.49,112.200,0.17578,3.972,0.003
21.53,112.400,0.17607,3.980,0.003
21.63,112.600,0.17641,3.998,0.003
21.69,112.800,0.17670,4.008,0.003
21.75,113.000,0.17703,4.019,0.003
21.81,113.200,0.17732,4.031,0.003
21.89,113.400,0.17765,4.045,0.003
21.94,113.600,0.17799,4.055,0.004
21.99,113.800,0.17832,4.063,0.004
22.06,114.000,0.17865,4.077,0.004
22.16,114.200,0.17902,4.094,0.004
22.23,114.400,0.17940,4.108,0.004
22.29,114.600,0.17981,4.120,0.004
22.37,114.800,0.18027,4.134,0.004
22.47,115.000,0.18069,4.152,0.004
22.53,115.200,0.18110,4.164,0.004
22.60,115.400,0.18152,4.177,0.004
22.68,115.600,0.18193,4.191,0.004
22.75,115.800,0.18231,4.205,0.004
22.81,116.000,0.18264,4.216,0.004
22.84,116.200,0.18297,4.220,0.004
22.90,116.400,0.18326,4.232,0.004
22.95,116.600,0.18360,4.241,0.004
22.99,116.800,0.18384,4.249,0.004
23.05,117.000,0.18414,4.259,0.004
23.09,117.200,0.18438,4.267,0.004
23.15,117.400,0.18468,4.277,0.004
23.19,117.600,0.18497,4.285,0.004
23.24,117.800,0.18522,4.295,0.004
23.29,118.000,0.18551,4.305,0.004
23.34,118.200,0.18580,4.313,0.004
23.39,118.400,0.18609,4.322,0.004
23.44,118.600,0.18642,4.333,0.004
23.53,118.800,0.18671,4.349,0.004
23.57,119.000,0.18704,4.356,0.004
23.59,119.200,0.18738,4.360,0.004
23.70,119.400,0.18767,4.380,0.004
23.77,119.600,0.18800,4.393,0.004
23.85,119.800,0.18837,4.407,0.004
23.93,120.000,0.18875,4.422,0.004
24.03,120.200,0.18916,4.441,0.004
24.11,120.400,0.18958,4.456,0.004
24.21,120.600,0.19004,4.474,0.004
24.31,120.800,0.19049,4.492,0.004
24.37,121.000,0.19091,4.504,0.004
24.46,121.200,0.19128,4.520,0.004
24.49,121.400,0.19166,4.527,0.004
24.58,121.600,0.19199,4.543,0.004
24.62,121.800,0.19232,4.550,0.004
24.65,122.000,0.19261,4.556,0.004
24.70,122.200,0.19290,4.565,0.004
24.79,122.400,0.19319,4.581,0.004
24.80,122.600,0.19349,4.583,0.004
24.85,122.800,0.19373,4.593,0.004
24.90,123.000,0.19398,4.603,0.004
24.94,123.200,0.19428,4.609,0.004
25.01,123.400,0.19457,4.622,0.004
25.10,123.600,0.19486,4.638,0.004
25.16,123.800,0.19515,4.650,0.004
25.22,124.000,0.19544,4.660,0.004
25.29,124.200,0.19577,4.674,0.004
25.36,124.400,0.19606,4.687,0.004
25.40,124.600,0.19635,4.694,0.004
25.48,124.800,0.19669,4.708,0.004
25.55,125.000,0.19702,4.722,0.004
25.60,125.200,0.19735,4.732,0.004
25.66,125.400,0.19768,4.743,0.004
25.75,125.600,0.19806,4.759,0.004
25.83,125.800,0.19843,4.774,0.004
25.95,126.000,0.19885,4.795,0.004
26.01,126.200,0.19930,4.808,0.004
26.11,126.400,0.19972,4.825,0.004
26.22,126.600,0.20013,4.845,0.004
26.25,126.800,0.20055,4.851,0.004
26.31,127.000,0.20092,4.862,0.004
26.37,127.200,0.20126,4.874,0.004
26.47,127.400,0.20159,4.891,0.004
26.49,127.600,0.20192,4.895,0.004
26.57,127.800,0.20221,4.910,0.004
26.57,128.000,0.20250,4.910,0.004
26.63,128.200,0.20279,4.921,0.004
26.71,128.400,0.20304,4.936,0.004
26.75,128.600,0.20333,4.943,0.004
26.84,128.800,0.20358,4.961,0.004
26.83,129.000,0.20387,4.959,0.004
26.98,129.200,0.20417,4.986,0.004
26.99,129.400,0.20446,4.988,0.004
27.05,129.600,0.20475,4.999,0.004
27.12,129.800,0.20504,5.012,0.004
27.17,130.000,0.20537,5.022,0.004
27.25,130.200,0.20566,5.036,0.004
27.31,130.400,0.20599,5.048,0.004
27.38,130.600,0.20628,5.059,0.004
27.46,130.800,0.20662,5.075,0.004
27.53,131.000,0.20695,5.089,0.004
27.61,131.200,0.20732,5.103,0.004
27.70,131.400,0.20770,5.120,0.004
27.79,131.600,0.20807,5.136,0.004
27.90,131.800,0.20849,5.157,0.004
27.97,132.000,0.20890,5.169,0.004
28.06,132.200,0.20932,5.185,0.004
28.15,132.400,0.20973,5.202,0.004
28.24,132.600,0.21011,5.219,0.004
28.29,132.800,0.21048,5.228,0.004
28.39,133.000,0.21081,5.246,0.004
28.42,133.200,0.21115,5.253,0.004
28.48,133.400,0.21148,5.262,0.004
28.51,133.600,0.21177,5.268,0.004
28.58,133.800,0.21206,5.281,0.004
28.62,134.000,0.21231,5.289,0.004
28.68,134.200,0.21260,5.301,0.004
28.72,134.400,0.21285,5.308,0.004
28.80,134.600,0.21314,5.323,0.004
28.86,134.800,0.21339,5.334,0.004
28.88,135.000,0.21368,5.336,0.004
29.02,135.200,0.21397,5.363,0.004
29.07,135.400,0.21426,5.372,0.004
29.13,135.600,0.21455,5.384,0.004
29.17,135.800,0.21485,5.390,0.004
29.24,136.000,0.21518,5.403,0.004
29.33,136.200,0.21547,5.420,0.004
29.39,136.400,0.21580,5.431,0.004
29.46,136.600,0.21609,5.445,0.004
29.54,136.800,0.21642,5.460,0.004
29.62,137.000,0.21680,5.474,0.004
29.70,137.200,0.21717,5.489,0.004
29.82,137.400,0.21759,5.510,0.004
29.92,137.600,0.21800,5.530,0.004
29.97,137.800,0.21842,5.539,0.004
30.04,138.000,0.21883,5.551,0.004
30.13,138.200,0.21925,5.569,0.004
30.21,138.400,0.21967,5.583,0.004
30.33,138.600,0.22004,5.606,0.004
30.37,138.800,0.22037,5.612,0.004
30.37,139.000,0.22070,5.612,0.004
30.47,139.200,0.22100,5.631,0.004
30.48,139.400,0.22129,5.633,0.004
30.55,139.600,0.22158,5.646,0.004
30.59,139.800,0.22183,5.653,0.004
30.66,140.000,0.22212,5.667,0.004
30.67,140.200,0.22237,5.668,0.004
30.71,140.400,0.22262,5.675,0.004
30.80,140.600,0.22291,5.692,0.004
30.84,140.800,0.22320,5.700,0.004
30.92,141.000,0.22349,5.714,0.004
31.00,141.200,0.22382,5.729,0.004
31.08,141.400,0.22411,5.744,0.004
31.13,141.600,0.22440,5.753,0.004
31.18,141.800,0.22474,5.762,0.004
31.27,142.000,0.22507,5.779,0.004
31.32,142.200,0.22536,5.788,0.004
31.40,142.400,0.22573,5.803,0.004
31.49,142.600,0.22607,5.819,0.004
31.58,142.800,0.22644,5.836,0.004
31.69,143.000,0.22681,5.856,0.004
31.75,143.200,0.22727,5.867,0.004
31.85,143.400,0.22769,5.886,0.004
31.96,143.600,0.22810,5.907,0.004
32.01,143.800,0.22852,5.916,0.004
32.11,144.000,0.22893,5.934,0.005
32.19,144.200,0.22935,5.950,0.005
32.22,144.400,0.22968,5.954,0.005
32.23,144.600,0.23001,5.956,0.005
32.28,144.800,0.23035,5.966,0.005
32.33,145.000,0.23064,5.974,0.005
32.38,145.200,0.23093,5.984,0.005
32.43,145.400,0.23122,5.994,0.005
32.47,145.600,0.23147,6.000,0.005
32.52,145.800,0.23176,6.009,0.005
32.57,146.000,0.23201,6.019,0.005
32.63,146.200,0.23230,6.031,0.005
32.67,146.400,0.23259,6.037,0.005
32.70,146.600,0.23288,6.044,0.005
32.78,146.800,0.23317,6.058,0.005
32.86,147.000,0.23350,6.073,0.005
32.88,147.200,0.23384,6.077,0.005
32.97,147.400,0.23413,6.092,0.005
33.04,147.600,0.23446,6.107,0.005
33.09,147.800,0.23479,6.115,0.005
33.18,148.000,0.23512,6.132,0.005
33.24,148.200,0.23546,6.143,0.005
33.29,148.400,0.23583,6.153,0.005
33.40,148.600,0.23620,6.173,0.005
33.47,148.800,0.23662,6.186,0.005
33.58,149.000,0.23708,6.206,0.005
33.70,149.200,0.23749,6.227,0.005
33.73,149.400,0.23791,6.234,0.005
33.81,149.600,0.23828,6.249,0.005
33.90,149.800,0.23870,6.265,0.005
33.91,150.000,0.23903,6.267,0.005
33.98,150.200,0.23940,6.279,0.005
34.02,150.400,0.23970,6.287,0.005
34.07,150.600,0.24003,6.297,0.005
34.11,150.800,0.24032,6.303,0.005
34.20,151.000,0.24061,6.320,0.005
34.22,151.200,0.24086,6.323,0.005
34.23,151.400,0.24115,6.326,0.005
34.27,151.600,0.24144,6.333,0.005
34.33,151.800,0.24169,6.344,0.005
34.40,152.000,0.24198,6.358,0.005
34.46,152.200,0.24227,6.368,0.005
34.53,152.400,0.24256,6.382,0.005
34.60,152.600,0.24285,6.394,0.005
34.65,152.800,0.24319,6.404,0.005
34.67,153.000,0.24348,6.407,0.005
34.78,153.200,0.24381,6.427,0.005
34.84,153.400,0.24410,6.438,0.005
34.91,153.600,0.24443,6.452,0.005
34.97,153.800,0.24477,6.464,0.005
35.06,154.000,0.24510,6.479,0.005
35.14,154.200,0.24551,6.495,0.005
35.26,154.400,0.24589,6.515,0.005
35.33,154.600,0.24634,6.528,0.005
35.40,154.800,0.24676,6.542,0.005
9.08,155.000,0.24718,1.679,0.005
10.39,155.200,0.24759,1.919,0.005
10.64,155.400,0.24797,1.967,0.005
10.89,155.600,0.24838,2.012,0.005
11.09,155.800,0.24871,2.049,0.005
11.23,156.000,0.24905,2.076,0.005
11.36,156.200,0.24934,2.099,0.005
11.46,156.400,0.24963,2.117,0.005
11.52,156.600,0.24992,2.130,0.005
11.65,156.800,0.25021,2.154,0.005
11.72,157.000,0.25046,2.166,0.005
11.75,157.200,0.25071,2.172,0.005
11.84,157.400,0.25100,2.187,0.005
11.91,157.600,0.25125,2.202,0.005
11.97,157.800,0.25154,2.212,0.005
12.04,158.000,0.25183,2.225,0.005
12.11,158.200,0.25212,2.238,0.005
12.15,158.300,0.25229,2.245,0.005