File: data-files/mech3/WH38Y.txt
""
"Test Method","Will_Huddleston_Disks.msm"
"Sample I. D.","WH38Z.mss"
"Specimen Number","2"

"Load (N)","Time (s)","Extension (mm)","Stress (MPa)","Strain (mm/mm)"

4.07,0.200,-0.01345,0.765,0.000
4.04,0.300,-0.01345,0.758,0.000
4.06,0.400,-0.01345,0.763,0.000
4.04,0.500,-0.01341,0.758,0.000
4.06,0.600,-0.01341,0.762,0.000
4.04,0.700,-0.01341,0.760,0.000
4.07,0.800,-0.01337,0.764,0.000
4.05,0.900,-0.01337,0.761,0.000
4.07,1.000,-0.01333,0.764,0.000
4.05,1.100,-0.01333,0.761,0.000
4.09,1.200,-0.01333,0.768,0.000
4.05,1.300,-0.01328,0.761,0.000
4.08,1.400,-0.01328,0.766,0.000
4.07,1.500,-0.01324,0.765,0.000
4.09,1.600,-0.01324,0.768,0.000
4.06,1.700,-0.01320,0.763,0.000
4.09,1.800,-0.01320,0.769,0.000
4.07,1.900,-0.01316,0.766,0.000
4.11,2.000,-0.01312,0.772,0.000
4.12,2.100,-0.01303,0.775,0.000
4.21,2.200,-0.01295,0.790,0.000
4.26,2.300,-0.01283,0.800,0.000
4.37,2.400,-0.01262,0.822,0.000
4.46,2.500,-0.01241,0.838,0.000
4.57,2.600,-0.01220,0.859,0.000
4.62,2.700,-0.01204,0.869,0.000
4.70,2.800,-0.01187,0.882,0.000
4.76,2.900,-0.01166,0.894,0.000
4.81,3.000,-0.01154,0.904,0.000
4.84,3.100,-0.01137,0.910,0.000
4.88,3.200,-0.01121,0.918,0.000
4.91,3.300,-0.01104,0.923,0.000
4.96,3.400,-0.01091,0.932,0.000
4.96,3.500,-0.01075,0.933,0.000
5.00,3.600,-0.01062,0.940,0.000
5.02,3.700,-0.01050,0.943,0.000
5.05,3.800,-0.01033,0.950,0.000
5.07,3.900,-0.01021,0.953,0.000
5.11,4.000,-0.01008,0.960,0.000
5.14,4.100,-0.00996,0.966,0.000
5.17,4.200,-0.00983,0.971,0.000
5.19,4.300,-0.00971,0.975,0.000
5.22,4.400,-0.00954,0.980,0.000
5.22,4.500,-0.00942,0.981,0.000
5.26,4.600,-0.00929,0.989,0.000
5.27,4.700,-0.00917,0.989,0.000
5.30,4.800,-0.00904,0.996,0.000
5.33,4.900,-0.00892,1.002,0.000
5.34,5.000,-0.00880,1.004,0.000
5.37,5.100,-0.00863,1.010,0.000
5.40,5.200,-0.00850,1.014,0.000
5.43,5.300,-0.00838,1.020,0.000
5.45,5.400,-0.00821,1.025,0.000
5.47,5.500,-0.00809,1.028,0.000
5.50,5.600,-0.00792,1.033,0.000
5.52,5.700,-0.00780,1.037,0.000
5.56,5.800,-0.00763,1.044,0.000
5.57,5.900,-0.00751,1.047,0.000
5.59,6.000,-0.00734,1.051,0.000
5.61,6.100,-0.00722,1.054,0.000
5.64,6.200,-0.00705,1.060,0.000
5.68,6.300,-0.00688,1.067,0.000
5.70,6.400,-0.00676,1.071,0.000
5.72,6.500,-0.00659,1.075,0.000
5.74,6.600,-0.00643,1.079,0.000
5.77,6.700,-0.00630,1.084,0.000
5.79,6.800,-0.00614,1.088,0.000
5.80,6.900,-0.00597,1.089,0.000
5.84,7.000,-0.00580,1.096,0.000
5.85,7.100,-0.00564,1.100,0.000
5.86,7.200,-0.00547,1.102,0.000
5.89,7.300,-0.00526,1.106,0.000
5.94,7.400,-0.00510,1.116,0.000
5.98,7.500,-0.00489,1.123,0.000
6.00,7.600,-0.00468,1.128,0.000
6.06,7.700,-0.00447,1.139,0.000
6.07,7.800,-0.00422,1.141,0.000
6.09,7.900,-0.00402,1.144,0.000
6.15,8.000,-0.00381,1.155,0.000
6.16,8.100,-0.00356,1.157,0.000
6.18,8.200,-0.00335,1.162,0.000
6.23,8.300,-0.00314,1.170,0.000
6.27,8.400,-0.00294,1.177,0.000
6.28,8.500,-0.00273,1.180,0.000
6.33,8.600,-0.00252,1.190,0.000
6.34,8.700,-0.00235,1.191,0.000
6.37,8.800,-0.00215,1.197,0.000
6.39,8.900,-0.00198,1.200,0.000
6.40,9.000,-0.00181,1.203,0.000
6.41,9.100,-0.00165,1.205,0.000
6.43,9.200,-0.00148,1.209,0.000
6.43,9.300,-0.00136,1.208,0.000
6.45,9.400,-0.00119,1.212,0.000
6.47,9.500,-0.00107,1.216,0.000
6.48,9.600,-0.00090,1.218,0.000
6.52,9.700,-0.00078,1.225,0.000
6.53,9.800,-0.00065,1.227,0.000
6.55,9.900,-0.00048,1.232,0.000
6.55,10.000,-0.00036,1.230,0.000
6.57,10.100,-0.00024,1.235,0.000
6.59,10.200,-0.00011,1.238,0.000
6.58,10.300,0.00001,1.237,0.000
6.62,10.400,0.00014,1.244,0.000
6.64,10.500,0.00031,1.247,0.000
6.67,10.600,0.00043,1.253,0.000
6.68,10.700,0.00055,1.255,0.000
6.71,10.800,0.00072,1.261,0.000
6.73,10.900,0.00085,1.265,0.000
6.75,11.000,0.00101,1.269,0.000
6.78,11.100,0.00114,1.273,0.000
6.79,11.200,0.00130,1.276,0.000
6.82,11.300,0.00143,1.282,0.000
6.84,11.400,0.00159,1.285,0.000
6.87,11.500,0.00176,1.291,0.000
6.88,11.600,0.00188,1.292,0.000
6.89,11.700,0.00205,1.295,0.000
6.92,11.800,0.00222,1.301,0.000
6.94,11.900,0.00238,1.304,0.000
6.97,12.000,0.00251,1.310,0.000
7.00,12.100,0.00267,1.316,0.000
7.02,12.200,0.00284,1.319,0.000
7.04,12.300,0.00301,1.323,0.000
7.06,12.400,0.00317,1.327,0.000
7.08,12.500,0.00334,1.330,0.000
7.10,12.600,0.00350,1.334,0.000
7.12,12.700,0.00367,1.337,0.000
7.15,12.800,0.00384,1.344,0.000
7.17,12.900,0.00400,1.347,0.000
7.21,13.000,0.00421,1.355,0.000
7.24,13.100,0.00438,1.361,0.000
7.26,13.200,0.00459,1.365,0.000
7.31,13.300,0.00479,1.373,0.000
7.34,13.400,0.00500,1.380,0.000
7.36,13.500,0.00525,1.382,0.000
7.40,13.600,0.00546,1.390,0.000
7.43,13.700,0.00571,1.397,0.000
7.45,13.800,0.00592,1.399,0.000
7.49,13.900,0.00612,1.407,0.000
7.51,14.000,0.00637,1.412,0.000
7.53,14.100,0.00658,1.415,0.000
7.57,14.200,0.00679,1.422,0.000
7.58,14.300,0.00695,1.424,0.000
7.61,14.400,0.00716,1.431,0.000
7.62,14.500,0.00733,1.432,0.000
7.65,14.600,0.00749,1.437,0.000
7.66,14.700,0.00766,1.439,0.000
7.68,14.800,0.00783,1.442,0.000
7.68,14.900,0.00799,1.443,0.000
7.68,15.000,0.00812,1.444,0.000
7.71,15.100,0.00828,1.448,0.000
7.72,15.200,0.00841,1.450,0.000
7.74,15.300,0.00857,1.455,0.000
7.77,15.400,0.00870,1.460,0.000
7.78,15.500,0.00882,1.461,0.000
7.81,15.600,0.00899,1.467,0.000
7.81,15.700,0.00912,1.467,0.000
7.79,15.800,0.00924,1.464,0.000
7.78,15.900,0.00936,1.461,0.000
7.77,16.000,0.00949,1.460,0.000
7.78,16.100,0.00966,1.461,0.000
7.77,16.200,0.00978,1.460,0.000
7.80,16.300,0.00990,1.465,0.000
7.82,16.400,0.01007,1.469,0.000
7.84,16.500,0.01020,1.473,0.000
7.85,16.600,0.01036,1.475,0.000
7.88,16.700,0.01049,1.481,0.000
7.90,16.800,0.01065,1.484,0.000
7.92,16.900,0.01078,1.489,0.000
7.94,17.000,0.01094,1.492,0.000
7.95,17.100,0.01111,1.495,0.000
7.98,17.200,0.01123,1.500,0.000
8.01,17.300,0.01140,1.504,0.000
8.02,17.400,0.01157,1.507,0.000
8.04,17.500,0.01169,1.510,0.000
8.06,17.600,0.01186,1.514,0.000
8.09,17.700,0.01202,1.520,0.000
8.11,17.800,0.01219,1.524,0.000
8.13,17.900,0.01231,1.528,0.000
8.13,18.000,0.01248,1.528,0.000
8.14,18.100,0.01265,1.530,0.000
8.17,18.200,0.01281,1.536,0.000
8.21,18.300,0.01298,1.542,0.000
8.22,18.400,0.01315,1.545,0.000
8.25,18.500,0.01331,1.550,0.000
8.29,18.600,0.01352,1.557,0.000
8.33,18.700,0.01369,1.565,0.000
8.33,18.800,0.01385,1.564,0.000
8.34,18.900,0.01406,1.566,0.000
8.37,19.000,0.01427,1.573,0.000
8.41,19.100,0.01448,1.580,0.000
8.45,19.200,0.01473,1.588,0.000
8.49,19.300,0.01493,1.595,0.000
8.52,19.400,0.01514,1.601,0.000
8.55,19.500,0.01539,1.607,0.000
8.60,19.600,0.01560,1.615,0.000
8.60,19.700,0.01581,1.617,0.000
8.64,19.800,0.01601,1.623,0.000
8.65,19.900,0.01618,1.626,0.000
8.67,20.000,0.01639,1.630,0.000
8.70,20.100,0.01660,1.634,0.000
8.72,20.200,0.01676,1.638,0.000
8.74,20.300,0.01693,1.642,0.000
8.74,20.400,0.01709,1.643,0.000
8.77,20.500,0.01726,1.649,0.000
8.80,20.600,0.01743,1.653,0.000
8.79,20.700,0.01755,1.653,0.000
8.83,20.800,0.01772,1.659,0.000
8.85,20.900,0.01784,1.662,0.000
8.86,21.000,0.01801,1.664,0.000
8.88,21.100,0.01813,1.668,0.000
8.90,21.200,0.01830,1.672,0.000
8.92,21.300,0.01842,1.676,0.000
8.93,21.400,0.01859,1.679,0.000
8.94,21.500,0.01871,1.680,0.000
8.95,21.600,0.01884,1.682,0.000
8.98,21.700,0.01896,1.687,0.000
8.99,21.800,0.01913,1.689,0.000
9.00,21.900,0.01925,1.692,0.000
9.03,22.000,0.01938,1.696,0.000
9.05,22.100,0.01955,1.701,0.000
9.08,22.200,0.01967,1.706,0.000
9.10,22.300,0.01979,1.709,0.000
9.12,22.400,0.01996,1.714,0.000
9.14,22.500,0.02009,1.717,0.000
9.16,22.600,0.02025,1.721,0.000
9.21,22.700,0.02038,1.731,0.000
9.22,22.800,0.02054,1.732,0.000
9.25,22.900,0.02071,1.737,0.000
9.27,23.000,0.02083,1.742,0.000
9.30,23.100,0.02100,1.747,0.000
9.34,23.200,0.02112,1.755,0.000
9.36,23.300,0.02129,1.760,0.000
9.39,23.400,0.02146,1.765,0.000
9.39,23.500,0.02158,1.765,0.000
9.44,23.600,0.02175,1.773,0.000
9.45,23.700,0.02191,1.775,0.000
9.47,23.800,0.02208,1.780,0.000
9.51,23.900,0.02225,1.786,0.000
9.54,24.000,0.02241,1.792,0.000
9.56,24.100,0.02258,1.796,0.000
9.59,24.200,0.02275,1.801,0.000
9.61,24.300,0.02291,1.806,0.000
9.64,24.400,0.02312,1.811,0.000
9.66,24.500,0.02329,1.814,0.000
9.71,24.600,0.02349,1.824,0.000
9.75,24.700,0.02370,1.833,0.000
9.79,24.800,0.02395,1.839,0.000
9.82,24.900,0.02416,1.846,0.000
9.86,25.000,0.02441,1.852,0.000
9.89,25.100,0.02462,1.859,0.000
9.95,25.200,0.02486,1.869,0.000
9.98,25.300,0.02507,1.876,0.000
10.01,25.400,0.02528,1.882,0.000
10.04,25.500,0.02549,1.887,0.001
10.09,25.600,0.02574,1.895,0.001
10.11,25.700,0.02590,1.900,0.001
10.15,25.800,0.02611,1.908,0.001
10.18,25.900,0.02632,1.912,0.001
10.20,26.000,0.02649,1.916,0.001
10.22,26.100,0.02665,1.920,0.001
10.25,26.200,0.02682,1.926,0.001
10.27,26.300,0.02698,1.930,0.001
10.29,26.400,0.02711,1.934,0.001
10.31,26.500,0.02727,1.937,0.001
10.35,26.600,0.02740,1.944,0.001
10.35,26.700,0.02757,1.945,0.001
10.39,26.800,0.02769,1.951,0.001
10.40,26.900,0.02782,1.954,0.001
10.42,27.000,0.02798,1.957,0.001
10.45,27.100,0.02811,1.963,0.001
10.47,27.200,0.02823,1.967,0.001
10.49,27.300,0.02840,1.970,0.001
10.51,27.400,0.02852,1.975,0.001
10.52,27.500,0.02865,1.977,0.001
10.56,27.600,0.02881,1.983,0.001
10.58,27.700,0.02894,1.989,0.001
10.60,27.800,0.02910,1.992,0.001
10.61,27.900,0.02923,1.994,0.001
10.64,28.000,0.02939,1.999,0.001
10.67,28.100,0.02952,2.005,0.001
10.68,28.200,0.02969,2.006,0.001
10.69,28.300,0.02985,2.008,0.001
10.74,28.400,0.02998,2.017,0.001
10.75,28.500,0.03014,2.019,0.001
10.76,28.600,0.03031,2.022,0.001
10.79,28.700,0.03047,2.027,0.001
10.79,28.800,0.03064,2.028,0.001
10.81,28.900,0.03077,2.032,0.001
10.83,29.000,0.03093,2.036,0.001
10.87,29.100,0.03110,2.042,0.001
10.90,29.200,0.03126,2.047,0.001
10.91,29.300,0.03143,2.050,0.001
10.93,29.400,0.03160,2.054,0.001
10.94,29.500,0.03176,2.056,0.001
10.98,29.600,0.03197,2.063,0.001
10.99,29.700,0.03214,2.065,0.001
11.02,29.800,0.03230,2.071,0.001
11.05,29.900,0.03251,2.076,0.001
11.08,30.000,0.03268,2.082,0.001
11.10,30.100,0.03288,2.086,0.001
11.15,30.200,0.03309,2.095,0.001
11.19,30.300,0.03330,2.103,0.001
11.23,30.400,0.03355,2.111,0.001
11.27,30.500,0.03376,2.117,0.001
11.30,30.600,0.03397,2.123,0.001
11.35,30.700,0.03421,2.132,0.001
11.37,30.800,0.03442,2.137,0.001
11.42,30.900,0.03467,2.145,0.001
11.44,31.000,0.03488,2.150,0.001
11.45,31.100,0.03509,2.152,0.001
11.48,31.200,0.03530,2.157,0.001
11.50,31.300,0.03550,2.161,0.001
11.54,31.400,0.03567,2.168,0.001
11.56,31.500,0.03588,2.172,0.001
11.59,31.600,0.03604,2.177,0.001
11.60,31.700,0.03621,2.180,0.001
11.61,31.800,0.03638,2.182,0.001
11.65,31.900,0.03650,2.189,0.001
11.66,32.000,0.03667,2.192,0.001
11.68,32.100,0.03679,2.194,0.001
11.70,32.200,0.03696,2.198,0.001
11.71,32.300,0.03708,2.201,0.001
11.74,32.400,0.03725,2.207,0.001
11.76,32.500,0.03737,2.209,0.001
11.77,32.600,0.03750,2.212,0.001
11.79,32.700,0.03766,2.216,0.001
11.82,32.800,0.03779,2.221,0.001
11.84,32.900,0.03791,2.226,0.001
11.87,33.000,0.03804,2.230,0.001
11.89,33.100,0.03820,2.234,0.001
11.93,33.200,0.03833,2.241,0.001
11.94,33.300,0.03850,2.243,0.001
11.98,33.400,0.03862,2.251,0.001
12.00,33.500,0.03879,2.255,0.001
12.02,33.600,0.03891,2.259,0.001
12.05,33.700,0.03908,2.265,0.001
12.08,33.800,0.03924,2.269,0.001
12.10,33.900,0.03937,2.274,0.001
12.13,34.000,0.03953,2.278,0.001
12.16,34.100,0.03970,2.285,0.001
12.17,34.200,0.03987,2.287,0.001
12.20,34.300,0.03999,2.293,0.001
12.22,34.400,0.04016,2.297,0.001
12.26,34.500,0.04032,2.303,0.001
12.27,34.600,0.04049,2.305,0.001
12.30,34.700,0.04061,2.312,0.001
12.32,34.800,0.04078,2.314,0.001
12.34,34.900,0.04095,2.318,0.001
12.39,35.000,0.04111,2.328,0.001
12.40,35.100,0.04128,2.329,0.001
12.44,35.200,0.04145,2.337,0.001
12.47,35.300,0.04161,2.342,0.001
12.50,35.400,0.04178,2.349,0.001
12.52,35.500,0.04199,2.353,0.001
12.54,35.600,0.04215,2.357,0.001
12.60,35.700,0.04236,2.368,0.001
12.62,35.800,0.04257,2.372,0.001
12.64,35.900,0.04273,2.376,0.001
12.70,36.000,0.04298,2.386,0.001
12.75,36.100,0.04319,2.395,0.001
12.77,36.200,0.04340,2.399,0.001
12.82,36.300,0.04365,2.409,0.001
12.86,36.400,0.04386,2.416,0.001
12.87,36.500,0.04406,2.419,0.001
12.92,36.600,0.04427,2.427,0.001
12.94,36.700,0.04448,2.431,0.001
12.94,36.800,0.04469,2.432,0.001
12.98,36.900,0.04489,2.440,0.001
13.01,37.000,0.04506,2.445,0.001
13.03,37.100,0.04527,2.449,0.001
13.08,37.200,0.04543,2.457,0.001
13.11,37.300,0.04560,2.463,0.001
13.15,37.400,0.04573,2.471,0.001
13.18,37.500,0.04589,2.476,0.001
13.18,37.600,0.04606,2.477,0.001
13.20,37.700,0.04618,2.481,0.001
13.23,37.800,0.04635,2.486,0.001
13.24,37.900,0.04647,2.489,0.001
13.27,38.000,0.04664,2.493,0.001
13.29,38.100,0.04676,2.498,0.001
13.33,38.200,0.04689,2.504,0.001
13.36,38.300,0.04706,2.511,0.001
13.39,38.400,0.04718,2.517,0.001
13.42,38.500,0.04730,2.522,0.001
13.45,38.600,0.04743,2.526,0.001
13.47,38.700,0.04760,2.532,0.001
13.49,38.800,0.04772,2.535,0.001
13.52,38.900,0.04785,2.540,0.001
13.54,39.000,0.04801,2.544,0.001
13.56,39.100,0.04814,2.548,0.001
13.58,39.200,0.04826,2.552,0.001
13.60,39.300,0.04843,2.556,0.001
13.63,39.400,0.04855,2.561,0.001
13.66,39.500,0.04872,2.567,0.001
13.67,39.600,0.04884,2.569,0.001
13.71,39.700,0.04901,2.575,0.001
13.72,39.800,0.04917,2.578,0.001
13.75,39.900,0.04930,2.583,0.001
13.77,40.000,0.04947,2.587,0.001
13.78,40.100,0.04959,2.589,0.001
13.82,40.200,0.04976,2.596,0.001
13.83,40.300,0.04992,2.599,0.001
13.86,40.400,0.05005,2.604,0.001
13.90,40.500,0.05021,2.612,0.001
13.94,40.600,0.05038,2.619,0.001
13.96,40.700,0.05055,2.623,0.001
14.00,40.800,0.05071,2.631,0.001
14.04,40.900,0.05088,2.638,0.001
14.06,41.000,0.05104,2.642,0.001
14.11,41.100,0.05121,2.651,0.001
14.14,41.200,0.05138,2.657,0.001
14.17,41.300,0.05159,2.663,0.001
14.21,41.400,0.05179,2.671,0.001
14.24,41.500,0.05196,2.675,0.001
14.29,41.600,0.05221,2.685,0.001
14.34,41.700,0.05242,2.694,0.001
14.39,41.800,0.05267,2.703,0.001
14.44,41.900,0.05287,2.713,0.001
14.45,42.000,0.05308,2.716,0.001
14.49,42.100,0.05333,2.723,0.001
14.54,42.200,0.05354,2.732,0.001
14.58,42.300,0.05375,2.739,0.001
14.61,42.400,0.05395,2.744,0.001
14.65,42.500,0.05416,2.753,0.001
14.66,42.600,0.05437,2.755,0.001
14.67,42.700,0.05454,2.757,0.001
14.72,42.800,0.05470,2.765,0.001
14.75,42.900,0.05491,2.772,0.001
14.76,43.000,0.05503,2.773,0.001
14.79,43.100,0.05520,2.779,0.001
14.79,43.200,0.05537,2.780,0.001
14.81,43.300,0.05549,2.783,0.001
14.83,43.400,0.05566,2.787,0.001
14.85,43.500,0.05578,2.791,0.001
14.88,43.600,0.05595,2.795,0.001
14.90,43.700,0.05607,2.800,0.001
14.90,43.800,0.05620,2.800,0.001
14.94,43.900,0.05632,2.807,0.001
14.94,44.000,0.05645,2.808,0.001
14.97,44.100,0.05661,2.813,0.001
15.00,44.200,0.05674,2.819,0.001
15.02,44.300,0.05686,2.822,0.001
15.05,44.400,0.05699,2.827,0.001
15.06,44.500,0.05715,2.830,0.001
15.09,44.600,0.05728,2.836,0.001
15.12,44.700,0.05740,2.840,0.001
15.15,44.800,0.05757,2.846,0.001
15.17,44.900,0.05769,2.849,0.001
15.20,45.000,0.05786,2.855,0.001
15.23,45.100,0.05798,2.861,0.001
15.26,45.200,0.05815,2.868,0.001
15.29,45.300,0.05828,2.873,0.001
15.31,45.400,0.05844,2.876,0.001
15.37,45.500,0.05861,2.887,0.001
15.38,45.600,0.05873,2.889,0.001
15.41,45.700,0.05890,2.895,0.001
15.44,45.800,0.05907,2.901,0.001
15.48,45.900,0.05919,2.909,0.001
15.49,46.000,0.05936,2.911,0.001
15.51,46.100,0.05952,2.914,0.001
15.55,46.200,0.05969,2.922,0.001
15.57,46.300,0.05981,2.926,0.001
15.62,46.400,0.05998,2.936,0.001
15.66,46.500,0.06015,2.943,0.001
15.70,46.600,0.06031,2.949,0.001
15.73,46.700,0.06048,2.956,0.001
15.75,46.800,0.06069,2.960,0.001
15.81,46.900,0.06085,2.970,0.001
15.84,47.000,0.06106,2.977,0.001
15.89,47.100,0.06127,2.986,0.001
15.91,47.200,0.06148,2.990,0.001
15.96,47.300,0.06168,2.998,0.001
16.01,47.400,0.06189,3.008,0.001
16.06,47.500,0.06210,3.017,0.001
16.12,47.600,0.06235,3.029,0.001
16.16,47.700,0.06256,3.036,0.001
16.19,47.800,0.06281,3.043,0.001
16.25,47.900,0.06301,3.052,0.001
16.27,48.000,0.06322,3.057,0.001
16.32,48.100,0.06343,3.067,0.001
16.36,48.200,0.06364,3.073,0.001
16.39,48.300,0.06380,3.080,0.001
16.42,48.400,0.06401,3.085,0.001
16.46,48.500,0.06418,3.093,0.001
16.48,48.600,0.06434,3.096,0.001
16.52,48.700,0.06451,3.104,0.001
16.55,48.800,0.06468,3.110,0.001
16.58,48.900,0.06484,3.116,0.001
16.60,49.000,0.06497,3.119,0.001
16.64,49.100,0.06513,3.127,0.001
16.67,49.200,0.06526,3.132,0.001
16.68,49.300,0.06542,3.135,0.001
16.71,49.400,0.06555,3.140,0.001
16.74,49.500,0.06567,3.145,0.001
16.76,49.600,0.06580,3.149,0.001
16.78,49.700,0.06596,3.153,0.001
16.82,49.800,0.06609,3.161,0.001
16.84,49.900,0.06621,3.165,0.001
16.87,50.000,0.06634,3.169,0.001
16.88,50.100,0.06646,3.172,0.001
16.93,50.200,0.06663,3.181,0.001
16.95,50.300,0.06675,3.184,0.001
16.97,50.400,0.06692,3.189,0.001
16.98,50.500,0.06704,3.191,0.001
17.03,50.600,0.06717,3.199,0.001
17.07,50.700,0.06733,3.207,0.001
17.09,50.800,0.06750,3.211,0.001
17.11,50.900,0.06763,3.215,0.001
17.13,51.000,0.06779,3.218,0.001
17.16,51.100,0.06792,3.224,0.001
17.20,51.200,0.06808,3.232,0.001
17.24,51.300,0.06825,3.238,0.001
17.26,51.400,0.06837,3.244,0.001
17.30,51.500,0.06854,3.250,0.001
17.34,51.600,0.06871,3.257,0.001
17.37,51.700,0.06883,3.263,0.001
17.40,51.800,0.06900,3.270,0.001
17.43,51.900,0.06916,3.276,0.001
17.47,52.000,0.06933,3.283,0.001
17.51,52.100,0.06950,3.290,0.001
17.55,52.200,0.06962,3.297,0.001
17.58,52.300,0.06979,3.303,0.001
17.63,52.400,0.06999,3.313,0.001
17.67,52.500,0.07016,3.320,0.001
17.72,52.600,0.07033,3.330,0.001
17.75,52.700,0.07049,3.336,0.001
17.80,52.800,0.07070,3.345,0.001
17.84,52.900,0.07091,3.353,0.001
17.89,53.000,0.07112,3.361,0.001
17.94,53.100,0.07132,3.370,0.001
17.99,53.200,0.07153,3.379,0.001
18.03,53.300,0.07174,3.388,0.001
18.07,53.400,0.07199,3.396,0.001
18.13,53.500,0.07220,3.406,0.001
18.16,53.600,0.07240,3.413,0.001
18.18,53.700,0.07261,3.417,0.001
18.25,53.800,0.07282,3.429,0.001
18.28,53.900,0.07299,3.434,0.001
18.32,54.000,0.07319,3.442,0.001
18.35,54.100,0.07336,3.448,0.001
18.39,54.200,0.07357,3.456,0.001
18.42,54.300,0.07373,3.462,0.001
18.46,54.400,0.07390,3.468,0.001
18.48,54.500,0.07407,3.472,0.001
18.52,54.600,0.07419,3.480,0.001
18.54,54.700,0.07436,3.483,0.001
18.59,54.800,0.07452,3.493,0.001
18.61,54.900,0.07465,3.496,0.001
18.64,55.000,0.07477,3.501,0.001
18.66,55.100,0.07494,3.506,0.001
18.70,55.200,0.07506,3.514,0.001
18.73,55.300,0.07519,3.519,0.001
18.75,55.400,0.07536,3.522,0.001
18.78,55.500,0.07548,3.528,0.001
18.81,55.600,0.07560,3.534,0.001
18.83,55.700,0.07573,3.537,0.001
18.85,55.800,0.07585,3.542,0.001
18.89,55.900,0.07602,3.549,0.001
18.90,56.000,0.07614,3.552,0.001
18.95,56.100,0.07627,3.560,0.002
18.98,56.200,0.07644,3.566,0.002
19.00,56.300,0.07656,3.571,0.002
19.04,56.400,0.07673,3.577,0.002
19.07,56.500,0.07685,3.583,0.002
19.11,56.600,0.07702,3.591,0.002
19.14,56.700,0.07714,3.596,0.002
19.18,56.800,0.07731,3.603,0.002
19.21,56.900,0.07743,3.610,0.002
19.24,57.000,0.07760,3.615,0.002
19.26,57.100,0.07777,3.619,0.002
19.31,57.200,0.07789,3.628,0.002
19.35,57.300,0.07806,3.636,0.002
19.39,57.400,0.07822,3.643,0.002
19.43,57.500,0.07839,3.651,0.002
19.47,57.600,0.07851,3.659,0.002
19.52,57.700,0.07868,3.668,0.002
19.56,57.800,0.07885,3.674,0.002
19.60,57.900,0.07901,3.682,0.002
19.65,58.000,0.07918,3.692,0.002
19.69,58.100,0.07934,3.700,0.002
19.73,58.200,0.07951,3.706,0.002
19.76,58.300,0.07968,3.713,0.002
19.82,58.400,0.07988,3.723,0.002
19.86,58.500,0.08005,3.731,0.002
19.88,58.600,0.08026,3.735,0.002
19.93,58.700,0.08047,3.744,0.002
19.98,58.800,0.08067,3.753,0.002
20.02,58.900,0.08088,3.761,0.002
20.08,59.000,0.08113,3.773,0.002
20.13,59.100,0.08134,3.782,0.002
20.18,59.200,0.08155,3.792,0.002
20.22,59.300,0.08180,3.800,0.002
20.28,59.400,0.08200,3.810,0.002
20.34,59.500,0.08221,3.821,0.002
20.37,59.600,0.08242,3.828,0.002
20.43,59.700,0.08263,3.839,0.002
20.47,59.800,0.08284,3.846,0.002
20.50,59.900,0.08300,3.852,0.002
20.54,60.000,0.08317,3.859,0.002
20.57,60.100,0.08333,3.865,0.002
20.61,60.200,0.08350,3.872,0.002
20.63,60.300,0.08367,3.877,0.002
20.67,60.400,0.08379,3.884,0.002
20.69,60.500,0.08396,3.887,0.002
20.71,60.600,0.08408,3.891,0.002
20.74,60.700,0.08421,3.897,0.002
20.79,60.800,0.08437,3.906,0.002
20.81,60.900,0.08450,3.909,0.002
20.83,61.000,0.08462,3.914,0.002
20.87,61.100,0.08475,3.921,0.002
20.89,61.200,0.08487,3.925,0.002
20.92,61.300,0.08504,3.931,0.002
20.95,61.400,0.08516,3.937,0.002
20.99,61.500,0.08529,3.944,0.002
21.02,61.600,0.08541,3.950,0.002
21.07,61.700,0.08558,3.959,0.002
21.09,61.800,0.08570,3.962,0.002
21.13,61.900,0.08583,3.970,0.002
21.17,62.000,0.08599,3.979,0.002
21.19,62.100,0.08616,3.982,0.002
21.25,62.200,0.08628,3.992,0.002
21.29,62.300,0.08645,4.000,0.002
21.33,62.400,0.08658,4.008,0.002
21.37,62.500,0.08674,4.015,0.002
21.41,62.600,0.08691,4.023,0.002
21.44,62.700,0.08703,4.028,0.002
21.47,62.800,0.08720,4.035,0.002
21.52,62.900,0.08736,4.044,0.002
21.57,63.000,0.08749,4.052,0.002
21.59,63.100,0.08766,4.057,0.002
21.63,63.200,0.08782,4.065,0.002
21.69,63.300,0.08799,4.076,0.002
21.72,63.400,0.08815,4.081,0.002
21.76,63.500,0.08828,4.088,0.002
21.80,63.600,0.08845,4.097,0.002
21.85,63.700,0.08861,4.105,0.002
21.89,63.800,0.08882,4.112,0.002
21.93,63.900,0.08899,4.120,0.002
21.96,64.000,0.08915,4.127,0.002
22.01,64.100,0.08936,4.135,0.002
22.05,64.200,0.08953,4.144,0.002
22.12,64.300,0.08973,4.156,0.002
22.18,64.400,0.08998,4.167,0.002
22.23,64.500,0.09019,4.177,0.002
22.29,64.600,0.09040,4.187,0.002
22.35,64.700,0.09065,4.200,0.002
22.42,64.800,0.09086,4.212,0.002
22.48,64.900,0.09110,4.225,0.002
22.55,65.000,0.09131,4.237,0.002
22.60,65.100,0.09156,4.247,0.002
22.65,65.200,0.09177,4.257,0.002
22.72,65.300,0.09198,4.269,0.002
22.76,65.400,0.09219,4.277,0.002
22.82,65.500,0.09235,4.287,0.002
22.86,65.600,0.09256,4.296,0.002
22.89,65.700,0.09273,4.302,0.002
22.93,65.800,0.09289,4.308,0.002
22.96,65.900,0.09302,4.314,0.002
22.99,66.000,0.09318,4.319,0.002
23.03,66.100,0.09335,4.328,0.002
23.07,66.200,0.09347,4.335,0.002
23.12,66.300,0.09364,4.345,0.002
23.17,66.400,0.09376,4.354,0.002
23.19,66.500,0.09393,4.357,0.002
23.23,66.600,0.09406,4.364,0.002
23.25,66.700,0.09418,4.369,0.002
23.29,66.800,0.09430,4.375,0.002
23.32,66.900,0.09447,4.382,0.002
23.34,67.000,0.09460,4.386,0.002
23.38,67.100,0.09472,4.394,0.002
23.43,67.200,0.09489,4.403,0.002
23.48,67.300,0.09501,4.412,0.002
23.53,67.400,0.09514,4.421,0.002
23.57,67.500,0.09526,4.429,0.002
23.61,67.600,0.09543,4.436,0.002
23.66,67.700,0.09559,4.445,0.002
23.71,67.800,0.09572,4.455,0.002
23.75,67.900,0.09588,4.463,0.002
23.78,68.000,0.09605,4.469,0.002
23.85,68.100,0.09617,4.481,0.002
23.88,68.200,0.09634,4.487,0.002
23.94,68.300,0.09651,4.498,0.002
23.99,68.400,0.09663,4.508,0.002
24.03,68.500,0.09680,4.514,0.002
24.07,68.600,0.09696,4.523,0.002
24.11,68.700,0.09709,4.530,0.002
24.16,68.800,0.09725,4.539,0.002
24.16,68.900,0.09742,4.539,0.002
5.87,69.000,0.09759,1.104,0.002
6.73,69.100,0.09775,1.265,0.002
6.86,69.200,0.09792,1.288,0.002
6.88,69.300,0.09809,1.294,0.002
6.91,69.400,0.09825,1.298,0.002
6.94,69.500,0.09842,1.305,0.002
6.98,69.600,0.09863,1.312,0.002
7.03,69.700,0.09879,1.321,0.002
7.06,69.800,0.09900,1.327,0.002
7.12,69.900,0.09917,1.338,0.002
7.14,70.000,0.09942,1.341,0.002
7.19,70.100,0.09962,1.352,0.002
7.23,70.200,0.09983,1.358,0.002
7.28,70.300,0.10004,1.368,0.002
7.34,70.400,0.10029,1.379,0.002
7.38,70.500,0.10050,1.387,0.002
7.42,70.600,0.10070,1.394,0.002
7.46,70.700,0.10091,1.402,0.002
7.50,70.800,0.10112,1.409,0.002
7.53,70.900,0.10133,1.414,0.002
7.58,71.000,0.10154,1.424,0.002
7.60,71.100,0.10170,1.428,0.002
7.63,71.200,0.10191,1.433,0.002
7.65,71.300,0.10208,1.438,0.002
7.66,71.370,0.10216,1.439,0.002