File: data-files/mech3/WH38X.txt
""
"Test Method","Will_Huddleston_Disks.msm"
"Sample I. D.","WH38X.mss"
"Specimen Number","1"

"Load (N)","Time (s)","Extension (mm)","Stress (MPa)","Strain (mm/mm)"

3.91,0.200,-0.01013,0.729,0.000
3.92,0.300,-0.01013,0.730,0.000
3.92,0.400,-0.01013,0.730,0.000
3.93,0.500,-0.01013,0.731,0.000
3.92,0.600,-0.01009,0.731,0.000
3.92,0.700,-0.01009,0.730,0.000
3.93,0.800,-0.01009,0.732,0.000
3.93,0.900,-0.01004,0.733,0.000
3.93,1.000,-0.01004,0.733,0.000
3.94,1.100,-0.01004,0.733,0.000
3.92,1.200,-0.01000,0.731,0.000
3.93,1.300,-0.01000,0.732,0.000
3.94,1.400,-0.00996,0.733,0.000
3.95,1.500,-0.00996,0.737,0.000
3.97,1.600,-0.00992,0.740,0.000
4.00,1.700,-0.00988,0.746,0.000
4.06,1.800,-0.00984,0.756,0.000
4.14,1.900,-0.00975,0.772,0.000
4.22,2.000,-0.00963,0.787,0.000
4.30,2.100,-0.00950,0.801,0.000
4.39,2.200,-0.00934,0.819,0.000
4.45,2.300,-0.00921,0.829,0.000
4.51,2.400,-0.00909,0.840,0.000
4.56,2.500,-0.00896,0.850,0.000
4.61,2.600,-0.00884,0.859,0.000
4.65,2.700,-0.00867,0.867,0.000
4.69,2.800,-0.00855,0.874,0.000
4.73,2.900,-0.00842,0.882,0.000
4.78,3.000,-0.00826,0.890,0.000
4.82,3.100,-0.00813,0.897,0.000
4.84,3.200,-0.00801,0.903,0.000
4.90,3.300,-0.00784,0.914,0.000
4.91,3.400,-0.00772,0.916,0.000
4.94,3.500,-0.00755,0.921,0.000
4.98,3.600,-0.00743,0.929,0.000
4.99,3.700,-0.00730,0.930,0.000
5.03,3.800,-0.00714,0.937,0.000
5.05,3.900,-0.00701,0.940,0.000
5.08,4.000,-0.00684,0.946,0.000
5.11,4.100,-0.00668,0.952,0.000
5.14,4.200,-0.00655,0.958,0.000
5.16,4.300,-0.00639,0.962,0.000
5.20,4.400,-0.00622,0.968,0.000
5.23,4.500,-0.00610,0.975,0.000
5.25,4.600,-0.00593,0.979,0.000
5.28,4.700,-0.00576,0.983,0.000
5.30,4.800,-0.00560,0.987,0.000
5.33,4.900,-0.00539,0.994,0.000
5.36,5.000,-0.00522,0.998,0.000
5.39,5.100,-0.00506,1.004,0.000
5.42,5.200,-0.00485,1.010,0.000
5.44,5.300,-0.00464,1.014,0.000
5.50,5.400,-0.00443,1.025,0.000
5.53,5.500,-0.00423,1.030,0.000
5.54,5.600,-0.00402,1.033,0.000
5.58,5.700,-0.00381,1.040,0.000
5.59,5.800,-0.00360,1.042,0.000
5.61,5.900,-0.00340,1.046,0.000
5.63,6.000,-0.00319,1.050,0.000
5.67,6.100,-0.00298,1.057,0.000
5.70,6.200,-0.00277,1.062,0.000
5.73,6.300,-0.00261,1.067,0.000
5.74,6.400,-0.00240,1.070,0.000
5.76,6.500,-0.00219,1.073,0.000
5.81,6.600,-0.00202,1.082,0.000
5.82,6.700,-0.00186,1.084,0.000
5.84,6.800,-0.00169,1.088,0.000
5.82,6.900,-0.00157,1.085,0.000
5.85,7.000,-0.00140,1.090,0.000
5.86,7.100,-0.00123,1.091,0.000
5.88,7.200,-0.00111,1.096,0.000
5.90,7.300,-0.00094,1.099,0.000
5.90,7.400,-0.00082,1.100,0.000
5.93,7.500,-0.00069,1.105,0.000
5.95,7.600,-0.00053,1.108,0.000
5.95,7.700,-0.00040,1.110,0.000
5.98,7.800,-0.00028,1.115,0.000
6.00,7.900,-0.00011,1.118,0.000
6.00,8.000,0.00001,1.118,0.000
6.02,8.100,0.00014,1.122,0.000
6.03,8.200,0.00026,1.124,0.000
6.06,8.300,0.00043,1.128,0.000
6.06,8.400,0.00055,1.130,0.000
6.07,8.500,0.00072,1.131,0.000
6.09,8.600,0.00084,1.135,0.000
6.12,8.700,0.00101,1.141,0.000
6.14,8.800,0.00113,1.145,0.000
6.15,8.900,0.00130,1.147,0.000
6.17,9.000,0.00147,1.150,0.000
6.19,9.100,0.00159,1.154,0.000
6.22,9.200,0.00176,1.158,0.000
6.21,9.300,0.00192,1.158,0.000
6.24,9.400,0.00205,1.164,0.000
6.25,9.500,0.00221,1.165,0.000
6.28,9.600,0.00238,1.171,0.000
6.29,9.700,0.00251,1.172,0.000
6.32,9.800,0.00267,1.177,0.000
6.34,9.900,0.00284,1.181,0.000
6.35,10.000,0.00300,1.184,0.000
6.37,10.100,0.00317,1.188,0.000
6.39,10.200,0.00334,1.190,0.000
6.41,10.300,0.00350,1.195,0.000
6.43,10.400,0.00367,1.198,0.000
6.45,10.500,0.00384,1.202,0.000
6.46,10.600,0.00400,1.203,0.000
6.49,10.700,0.00421,1.209,0.000
6.51,10.800,0.00438,1.213,0.000
6.55,10.900,0.00458,1.221,0.000
6.57,11.000,0.00479,1.224,0.000
6.61,11.100,0.00500,1.231,0.000
6.63,11.200,0.00521,1.236,0.000
6.67,11.300,0.00546,1.243,0.000
6.69,11.400,0.00566,1.247,0.000
6.73,11.500,0.00587,1.253,0.000
6.73,11.600,0.00608,1.254,0.000
6.77,11.700,0.00629,1.262,0.000
6.79,11.800,0.00649,1.265,0.000
6.81,11.900,0.00670,1.269,0.000
6.84,12.000,0.00691,1.274,0.000
6.85,12.100,0.00712,1.277,0.000
6.89,12.200,0.00728,1.284,0.000
6.91,12.300,0.00745,1.288,0.000
6.93,12.400,0.00762,1.292,0.000
6.95,12.500,0.00778,1.296,0.000
6.95,12.600,0.00795,1.295,0.000
6.98,12.700,0.00807,1.300,0.000
6.98,12.800,0.00824,1.302,0.000
7.02,12.900,0.00841,1.308,0.000
7.01,13.000,0.00853,1.307,0.000
7.05,13.100,0.00866,1.314,0.000
7.08,13.200,0.00882,1.319,0.000
7.10,13.300,0.00895,1.322,0.000
7.12,13.400,0.00907,1.327,0.000
7.14,13.500,0.00924,1.331,0.000
7.15,13.600,0.00936,1.333,0.000
7.16,13.700,0.00949,1.334,0.000
7.17,13.800,0.00961,1.336,0.000
7.18,13.900,0.00978,1.338,0.000
7.20,14.000,0.00990,1.342,0.000
7.22,14.100,0.01007,1.345,0.000
7.25,14.200,0.01019,1.351,0.000
7.27,14.300,0.01032,1.355,0.000
7.31,14.400,0.01048,1.362,0.000
7.31,14.500,0.01061,1.363,0.000
7.34,14.600,0.01077,1.368,0.000
7.36,14.700,0.01090,1.371,0.000
7.39,14.800,0.01107,1.377,0.000
7.40,14.900,0.01123,1.378,0.000
7.43,15.000,0.01136,1.384,0.000
7.45,15.100,0.01152,1.388,0.000
7.48,15.200,0.01165,1.394,0.000
7.50,15.300,0.01181,1.398,0.000
7.52,15.400,0.01198,1.401,0.000
7.55,15.500,0.01210,1.407,0.000
7.57,15.600,0.01227,1.410,0.000
7.60,15.700,0.01244,1.417,0.000
7.63,15.800,0.01260,1.421,0.000
7.65,15.900,0.01277,1.426,0.000
7.68,16.000,0.01294,1.432,0.000
7.71,16.100,0.01310,1.438,0.000
7.72,16.200,0.01327,1.439,0.000
7.76,16.300,0.01343,1.446,0.000
7.80,16.400,0.01364,1.453,0.000
7.84,16.500,0.01385,1.461,0.000
7.90,16.600,0.01406,1.472,0.000
7.93,16.700,0.01427,1.478,0.000
7.98,16.800,0.01447,1.487,0.000
8.03,16.900,0.01472,1.496,0.000
8.06,17.000,0.01493,1.502,0.000
8.09,17.100,0.01514,1.508,0.000
8.15,17.200,0.01539,1.518,0.000
8.17,17.300,0.01560,1.523,0.000
8.20,17.400,0.01580,1.527,0.000
8.25,17.500,0.01601,1.537,0.000
8.28,17.600,0.01626,1.544,0.000
8.30,17.700,0.01643,1.546,0.000
8.31,17.800,0.01663,1.549,0.000
8.35,17.900,0.01680,1.556,0.000
8.36,18.000,0.01697,1.559,0.000
8.38,18.100,0.01713,1.562,0.000
8.40,18.200,0.01730,1.565,0.000
8.42,18.300,0.01742,1.570,0.000
8.43,18.400,0.01759,1.571,0.000
8.46,18.500,0.01771,1.576,0.000
8.47,18.600,0.01788,1.578,0.000
8.50,18.700,0.01801,1.585,0.000
8.53,18.800,0.01813,1.589,0.000
8.56,18.900,0.01830,1.594,0.000
8.55,19.000,0.01842,1.594,0.000
8.56,19.100,0.01855,1.596,0.000
8.59,19.200,0.01867,1.601,0.000
8.61,19.300,0.01880,1.605,0.000
8.63,19.400,0.01896,1.608,0.000
8.65,19.500,0.01909,1.611,0.000
8.68,19.600,0.01921,1.618,0.000
8.71,19.700,0.01938,1.622,0.000
8.71,19.800,0.01950,1.624,0.000
8.76,19.900,0.01963,1.632,0.000
8.77,20.000,0.01979,1.635,0.000
8.79,20.100,0.01992,1.639,0.000
8.82,20.200,0.02008,1.643,0.000
8.85,20.300,0.02025,1.650,0.000
8.88,20.400,0.02037,1.654,0.000
8.90,20.500,0.02054,1.659,0.000
8.91,20.600,0.02067,1.661,0.000
8.94,20.700,0.02083,1.667,0.000
8.95,20.800,0.02096,1.669,0.000
8.99,20.900,0.02112,1.674,0.000
9.02,21.000,0.02129,1.681,0.000
9.05,21.100,0.02141,1.686,0.000
9.07,21.200,0.02158,1.691,0.000
9.07,21.300,0.02175,1.691,0.000
9.12,21.400,0.02191,1.700,0.000
9.15,21.500,0.02208,1.706,0.000
9.15,21.600,0.02224,1.704,0.000
9.20,21.700,0.02241,1.714,0.000
9.24,21.800,0.02258,1.722,0.000
9.28,21.900,0.02274,1.729,0.000
9.30,22.000,0.02295,1.733,0.000
9.34,22.100,0.02312,1.741,0.000
9.39,22.200,0.02332,1.750,0.000
9.45,22.300,0.02353,1.760,0.000
9.48,22.400,0.02374,1.767,0.000
9.52,22.500,0.02399,1.773,0.000
9.56,22.600,0.02420,1.781,0.000
9.59,22.700,0.02441,1.788,0.000
9.64,22.800,0.02461,1.796,0.000
9.67,22.900,0.02482,1.801,0.000
9.70,23.000,0.02507,1.807,0.000
9.74,23.100,0.02528,1.815,0.000
9.77,23.200,0.02549,1.820,0.001
9.80,23.300,0.02565,1.826,0.001
9.83,23.400,0.02586,1.831,0.001
9.86,23.500,0.02607,1.838,0.001
9.87,23.600,0.02623,1.839,0.001
9.91,23.700,0.02640,1.846,0.001
9.92,23.800,0.02657,1.849,0.001
9.94,23.900,0.02673,1.852,0.001
9.95,24.000,0.02686,1.854,0.001
9.97,24.100,0.02702,1.857,0.001
9.98,24.200,0.02715,1.859,0.001
10.00,24.300,0.02731,1.864,0.001
10.00,24.400,0.02744,1.864,0.001
10.04,24.500,0.02761,1.870,0.001
10.05,24.600,0.02773,1.873,0.001
10.07,24.700,0.02785,1.877,0.001
10.08,24.800,0.02798,1.879,0.001
10.09,24.900,0.02810,1.881,0.001
10.13,25.000,0.02827,1.887,0.001
10.14,25.100,0.02839,1.889,0.001
10.15,25.200,0.02852,1.891,0.001
10.18,25.300,0.02869,1.897,0.001
10.20,25.400,0.02881,1.902,0.001
10.22,25.500,0.02893,1.904,0.001
10.27,25.600,0.02910,1.913,0.001
10.28,25.700,0.02923,1.917,0.001
10.31,25.800,0.02939,1.922,0.001
10.34,25.900,0.02952,1.927,0.001
10.39,26.000,0.02968,1.936,0.001
10.41,26.100,0.02981,1.941,0.001
10.45,26.200,0.02997,1.948,0.001
10.48,26.300,0.03014,1.952,0.001
10.51,26.400,0.03026,1.959,0.001
10.53,26.500,0.03043,1.963,0.001
10.56,26.600,0.03056,1.967,0.001
10.60,26.700,0.03072,1.976,0.001
10.62,26.800,0.03089,1.979,0.001
10.67,26.900,0.03105,1.988,0.001
10.69,27.000,0.03118,1.993,0.001
10.72,27.100,0.03135,1.998,0.001
10.75,27.200,0.03151,2.004,0.001
10.78,27.300,0.03168,2.008,0.001
10.81,27.400,0.03184,2.015,0.001
10.85,27.500,0.03201,2.022,0.001
10.87,27.600,0.03218,2.026,0.001
10.92,27.700,0.03238,2.035,0.001
10.95,27.800,0.03255,2.040,0.001
11.00,27.900,0.03276,2.049,0.001
11.05,28.000,0.03297,2.058,0.001
11.09,28.100,0.03317,2.067,0.001
11.13,28.200,0.03338,2.074,0.001
11.16,28.300,0.03359,2.080,0.001
11.21,28.400,0.03380,2.088,0.001
11.24,28.500,0.03400,2.095,0.001
11.29,28.600,0.03421,2.104,0.001
11.34,28.700,0.03442,2.113,0.001
11.38,28.800,0.03463,2.120,0.001
11.40,28.900,0.03484,2.125,0.001
11.44,29.000,0.03504,2.131,0.001
11.48,29.100,0.03525,2.139,0.001
11.50,29.200,0.03542,2.143,0.001
11.53,29.300,0.03563,2.148,0.001
11.58,29.400,0.03579,2.158,0.001
11.61,29.500,0.03596,2.163,0.001
11.64,29.600,0.03612,2.169,0.001
11.64,29.700,0.03625,2.170,0.001
11.68,29.800,0.03641,2.177,0.001
11.70,29.900,0.03658,2.181,0.001
11.73,30.000,0.03671,2.186,0.001
11.76,30.100,0.03683,2.191,0.001
11.79,30.200,0.03700,2.196,0.001
11.82,30.300,0.03712,2.202,0.001
11.85,30.400,0.03729,2.208,0.001
11.87,30.500,0.03741,2.212,0.001
11.90,30.600,0.03754,2.217,0.001
11.93,30.700,0.03766,2.223,0.001
11.96,30.800,0.03779,2.228,0.001
11.98,30.900,0.03795,2.233,0.001
11.99,31.000,0.03808,2.235,0.001
12.04,31.100,0.03820,2.243,0.001
12.06,31.200,0.03833,2.248,0.001
12.09,31.300,0.03849,2.252,0.001
12.12,31.400,0.03862,2.259,0.001
12.15,31.500,0.03878,2.265,0.001
12.18,31.600,0.03891,2.270,0.001
12.23,31.700,0.03903,2.279,0.001
12.24,31.800,0.03920,2.282,0.001
12.27,31.900,0.03932,2.287,0.001
12.31,32.000,0.03949,2.294,0.001
12.33,32.100,0.03966,2.297,0.001
12.38,32.200,0.03978,2.307,0.001
12.41,32.300,0.03995,2.313,0.001
12.45,32.400,0.04011,2.319,0.001
12.48,32.500,0.04024,2.325,0.001
12.52,32.600,0.04040,2.332,0.001
12.54,32.700,0.04057,2.337,0.001
12.57,32.800,0.04070,2.342,0.001
12.60,32.900,0.04086,2.348,0.001
12.65,33.000,0.04103,2.357,0.001
12.67,33.100,0.04119,2.362,0.001
12.72,33.200,0.04136,2.370,0.001
12.74,33.300,0.04153,2.374,0.001
12.77,33.400,0.04173,2.380,0.001
12.82,33.500,0.04190,2.389,0.001
12.88,33.600,0.04207,2.400,0.001
12.93,33.700,0.04227,2.409,0.001
12.97,33.800,0.04248,2.418,0.001
13.03,33.900,0.04269,2.428,0.001
13.07,34.000,0.04294,2.435,0.001
13.14,34.100,0.04315,2.448,0.001
13.18,34.200,0.04335,2.457,0.001
13.22,34.300,0.04360,2.464,0.001
13.27,34.400,0.04381,2.473,0.001
13.32,34.500,0.04402,2.482,0.001
13.36,34.600,0.04427,2.490,0.001
13.43,34.700,0.04448,2.502,0.001
13.46,34.800,0.04464,2.508,0.001
13.50,34.900,0.04485,2.515,0.001
13.54,35.000,0.04502,2.524,0.001
13.57,35.100,0.04522,2.529,0.001
13.60,35.200,0.04539,2.534,0.001
13.62,35.300,0.04556,2.539,0.001
13.66,35.400,0.04568,2.546,0.001
13.69,35.500,0.04585,2.550,0.001
13.72,35.600,0.04601,2.556,0.001
13.73,35.700,0.04614,2.559,0.001
13.77,35.800,0.04626,2.566,0.001
13.79,35.900,0.04643,2.570,0.001
13.83,36.000,0.04655,2.578,0.001
13.86,36.100,0.04668,2.582,0.001
13.89,36.200,0.04680,2.589,0.001
13.92,36.300,0.04697,2.594,0.001
13.95,36.400,0.04709,2.599,0.001
13.97,36.500,0.04722,2.603,0.001
14.02,36.600,0.04734,2.612,0.001
14.05,36.700,0.04751,2.618,0.001
14.08,36.800,0.04764,2.623,0.001
14.10,36.900,0.04776,2.628,0.001
14.14,37.000,0.04793,2.634,0.001
14.18,37.100,0.04805,2.643,0.001
14.21,37.200,0.04822,2.649,0.001
14.25,37.300,0.04834,2.655,0.001
14.28,37.400,0.04851,2.661,0.001
14.32,37.500,0.04867,2.668,0.001
14.35,37.600,0.04880,2.673,0.001
14.37,37.700,0.04896,2.678,0.001
14.42,37.800,0.04913,2.688,0.001
14.45,37.900,0.04926,2.692,0.001
14.48,38.000,0.04942,2.698,0.001
14.53,38.100,0.04959,2.707,0.001
14.55,38.200,0.04971,2.712,0.001
14.60,38.300,0.04988,2.720,0.001
14.62,38.400,0.05005,2.725,0.001
14.66,38.500,0.05021,2.731,0.001
14.72,38.600,0.05034,2.743,0.001
14.74,38.700,0.05050,2.747,0.001
14.80,38.800,0.05071,2.758,0.001
14.84,38.900,0.05088,2.766,0.001
14.88,39.000,0.05104,2.772,0.001
14.92,39.100,0.05121,2.780,0.001
14.97,39.200,0.05142,2.790,0.001
15.02,39.300,0.05162,2.799,0.001
15.06,39.400,0.05179,2.807,0.001
15.14,39.500,0.05200,2.821,0.001
15.18,39.600,0.05225,2.830,0.001
15.26,39.700,0.05246,2.845,0.001
15.33,39.800,0.05270,2.856,0.001
15.37,39.900,0.05291,2.865,0.001
15.45,40.000,0.05316,2.879,0.001
15.49,40.100,0.05337,2.887,0.001
15.55,40.200,0.05358,2.898,0.001
15.60,40.300,0.05379,2.907,0.001
15.65,40.400,0.05399,2.916,0.001
15.69,40.500,0.05420,2.923,0.001
15.73,40.600,0.05437,2.930,0.001
15.77,40.700,0.05457,2.939,0.001
15.80,40.800,0.05474,2.945,0.001
15.84,40.900,0.05491,2.952,0.001
15.88,41.000,0.05507,2.958,0.001
15.90,41.100,0.05520,2.963,0.001
15.93,41.200,0.05536,2.969,0.001
15.96,41.300,0.05549,2.974,0.001
15.98,41.400,0.05566,2.978,0.001
16.02,41.500,0.05578,2.985,0.001
16.06,41.600,0.05590,2.993,0.001
16.09,41.700,0.05607,2.998,0.001
16.11,41.800,0.05620,3.002,0.001
16.14,41.900,0.05632,3.008,0.001
16.19,42.000,0.05644,3.017,0.001
16.21,42.100,0.05661,3.021,0.001
16.24,42.200,0.05674,3.026,0.001
16.27,42.300,0.05686,3.032,0.001
16.29,42.400,0.05699,3.037,0.001
16.33,42.500,0.05715,3.042,0.001
16.35,42.600,0.05728,3.047,0.001
16.38,42.700,0.05740,3.053,0.001
16.43,42.800,0.05757,3.063,0.001
16.48,42.900,0.05769,3.071,0.001
16.51,43.000,0.05786,3.077,0.001
16.55,43.100,0.05798,3.083,0.001
16.58,43.200,0.05815,3.091,0.001
16.64,43.300,0.05831,3.101,0.001
16.66,43.400,0.05844,3.104,0.001
16.68,43.500,0.05861,3.109,0.001
16.73,43.600,0.05877,3.118,0.001
16.76,43.700,0.05890,3.123,0.001
16.81,43.800,0.05906,3.132,0.001
16.84,43.900,0.05923,3.138,0.001
16.88,44.000,0.05935,3.146,0.001
16.92,44.100,0.05952,3.153,0.001
16.97,44.200,0.05969,3.163,0.001
16.99,44.300,0.05985,3.167,0.001
17.05,44.400,0.06002,3.177,0.001
17.09,44.500,0.06018,3.184,0.001
17.11,44.600,0.06035,3.189,0.001
17.16,44.700,0.06056,3.199,0.001
17.21,44.800,0.06073,3.207,0.001
17.25,44.900,0.06093,3.215,0.001
17.31,45.000,0.06110,3.226,0.001
17.37,45.100,0.06131,3.237,0.001
17.44,45.200,0.06156,3.249,0.001
17.49,45.300,0.06176,3.259,0.001
17.57,45.400,0.06201,3.273,0.001
17.63,45.500,0.06222,3.286,0.001
17.68,45.600,0.06247,3.295,0.001
17.76,45.700,0.06268,3.309,0.001
17.79,45.800,0.06289,3.315,0.001
17.81,45.900,0.06309,3.320,0.001
17.86,46.000,0.06330,3.328,0.001
17.90,46.100,0.06351,3.335,0.001
17.94,46.200,0.06368,3.344,0.001
18.00,46.300,0.06388,3.353,0.001
18.03,46.400,0.06405,3.360,0.001
18.05,46.500,0.06422,3.364,0.001
18.10,46.600,0.06438,3.372,0.001
18.14,46.700,0.06455,3.381,0.001
18.17,46.800,0.06471,3.386,0.001
18.19,46.900,0.06484,3.390,0.001
18.23,47.000,0.06501,3.398,0.001
18.24,47.100,0.06513,3.399,0.001
18.29,47.200,0.06525,3.408,0.001
18.32,47.300,0.06542,3.414,0.001
18.36,47.400,0.06555,3.421,0.001
18.39,47.500,0.06571,3.426,0.001
18.42,47.600,0.06584,3.433,0.001
18.45,47.700,0.06596,3.439,0.001
18.48,47.800,0.06609,3.443,0.001
18.53,47.900,0.06625,3.453,0.001
18.54,48.000,0.06638,3.455,0.001
18.58,48.100,0.06650,3.462,0.001
18.62,48.200,0.06663,3.470,0.001
18.65,48.300,0.06679,3.476,0.001
18.69,48.400,0.06692,3.484,0.001
18.72,48.500,0.06708,3.489,0.001
18.76,48.600,0.06721,3.496,0.001
18.81,48.700,0.06737,3.505,0.001
18.85,48.800,0.06750,3.512,0.001
18.89,48.900,0.06766,3.521,0.001
18.94,49.000,0.06783,3.529,0.001
18.98,49.100,0.06796,3.538,0.001
19.02,49.200,0.06812,3.544,0.001
19.07,49.300,0.06829,3.553,0.001
19.10,49.400,0.06845,3.560,0.001
19.16,49.500,0.06858,3.570,0.001
19.18,49.600,0.06875,3.575,0.001
19.24,49.700,0.06891,3.586,0.001
19.28,49.800,0.06908,3.594,0.001
19.32,49.900,0.06920,3.601,0.001
19.38,50.000,0.06937,3.611,0.001
19.43,50.100,0.06953,3.620,0.001
19.46,50.200,0.06970,3.626,0.001
19.51,50.300,0.06987,3.636,0.001
19.57,50.400,0.07008,3.647,0.001
19.62,50.500,0.07024,3.657,0.001
19.67,50.600,0.07045,3.665,0.001
19.73,50.700,0.07062,3.676,0.001
19.78,50.800,0.07082,3.687,0.001
19.85,50.900,0.07103,3.699,0.001
19.93,51.000,0.07128,3.714,0.001
19.98,51.100,0.07149,3.723,0.001
20.04,51.200,0.07174,3.734,0.001
20.11,51.300,0.07195,3.747,0.001
20.16,51.400,0.07215,3.757,0.001
20.21,51.500,0.07236,3.767,0.001
20.26,51.600,0.07257,3.776,0.001
20.32,51.700,0.07278,3.786,0.001
20.37,51.800,0.07294,3.797,0.001
20.43,51.900,0.07315,3.808,0.001
20.48,52.000,0.07332,3.817,0.001
20.53,52.100,0.07352,3.826,0.001
20.57,52.200,0.07369,3.833,0.001
20.61,52.300,0.07386,3.840,0.001
20.64,52.400,0.07398,3.847,0.001
20.68,52.500,0.07415,3.854,0.001
20.71,52.600,0.07427,3.860,0.001
20.74,52.700,0.07444,3.865,0.001
20.77,52.800,0.07460,3.870,0.001
20.80,52.900,0.07473,3.876,0.001
20.83,53.000,0.07485,3.881,0.001
20.88,53.100,0.07498,3.890,0.001
20.90,53.200,0.07510,3.895,0.001
20.94,53.300,0.07527,3.902,0.001
20.97,53.400,0.07539,3.908,0.001
21.00,53.500,0.07552,3.914,0.001
21.04,53.600,0.07564,3.922,0.001
21.09,53.700,0.07577,3.931,0.001
21.14,53.800,0.07589,3.940,0.001
21.18,53.900,0.07606,3.946,0.001
21.20,54.000,0.07618,3.951,0.001
21.25,54.100,0.07631,3.960,0.002
21.28,54.200,0.07647,3.965,0.002
21.32,54.300,0.07660,3.973,0.002
21.38,54.400,0.07677,3.983,0.002
21.41,54.500,0.07689,3.990,0.002
21.45,54.600,0.07706,3.997,0.002
21.48,54.700,0.07722,4.003,0.002
21.54,54.800,0.07735,4.013,0.002
21.56,54.900,0.07751,4.018,0.002
21.61,55.000,0.07764,4.027,0.002
21.66,55.100,0.07780,4.036,0.002
21.70,55.200,0.07797,4.044,0.002
21.74,55.300,0.07810,4.052,0.002
21.79,55.400,0.07826,4.060,0.002
21.82,55.500,0.07843,4.067,0.002
21.88,55.600,0.07859,4.078,0.002
21.93,55.700,0.07872,4.086,0.002
21.96,55.800,0.07889,4.093,0.002
22.01,55.900,0.07905,4.101,0.002
22.07,56.000,0.07922,4.112,0.002
22.10,56.100,0.07938,4.119,0.002
22.14,56.200,0.07955,4.126,0.002
22.19,56.300,0.07976,4.135,0.002
22.24,56.400,0.07992,4.145,0.002
22.30,56.500,0.08013,4.156,0.002
22.35,56.600,0.08030,4.166,0.002
22.42,56.700,0.08051,4.178,0.002
22.48,56.800,0.08076,4.189,0.002
22.55,56.900,0.08096,4.203,0.002
22.61,57.000,0.08117,4.214,0.002
22.67,57.100,0.08138,4.224,0.002
22.74,57.200,0.08159,4.238,0.002
22.78,57.300,0.08184,4.245,0.002
22.85,57.400,0.08204,4.258,0.002
22.89,57.500,0.08221,4.265,0.002
22.96,57.600,0.08242,4.278,0.002
23.01,57.700,0.08263,4.288,0.002
23.07,57.800,0.08279,4.299,0.002
23.11,57.900,0.08300,4.306,0.002
23.16,58.000,0.08317,4.317,0.002
23.20,58.100,0.08329,4.324,0.002
23.24,58.200,0.08346,4.331,0.002
23.29,58.300,0.08362,4.340,0.002
23.32,58.400,0.08375,4.345,0.002
23.35,58.500,0.08391,4.351,0.002
23.40,58.600,0.08404,4.360,0.002
23.45,58.700,0.08420,4.369,0.002
23.47,58.800,0.08433,4.374,0.002
23.51,58.900,0.08445,4.380,0.002
23.54,59.000,0.08458,4.387,0.002
23.57,59.100,0.08470,4.393,0.002
23.63,59.200,0.08483,4.403,0.002
23.65,59.300,0.08499,4.407,0.002
23.69,59.400,0.08512,4.415,0.002
23.72,59.500,0.08524,4.421,0.002
23.77,59.600,0.08537,4.430,0.002
23.79,59.700,0.08553,4.433,0.002
23.83,59.800,0.08566,4.440,0.002
23.88,59.900,0.08582,4.451,0.002
23.92,60.000,0.08595,4.457,0.002
23.94,60.100,0.08612,4.462,0.002
23.99,60.200,0.08624,4.471,0.002
24.03,60.300,0.08641,4.479,0.002
24.08,60.400,0.08653,4.487,0.002
24.12,60.500,0.08670,4.495,0.002
24.17,60.600,0.08682,4.504,0.002
24.20,60.700,0.08699,4.510,0.002
24.24,60.800,0.08715,4.517,0.002
24.27,60.900,0.08728,4.523,0.002
24.32,61.000,0.08745,4.532,0.002
24.36,61.100,0.08761,4.540,0.002
24.40,61.200,0.08774,4.548,0.002
24.45,61.300,0.08790,4.557,0.002
24.49,61.400,0.08807,4.564,0.002
24.54,61.500,0.08824,4.573,0.002
24.59,61.600,0.08840,4.582,0.002
24.64,61.700,0.08857,4.591,0.002
24.68,61.800,0.08873,4.599,0.002
24.71,61.900,0.08890,4.606,0.002
24.76,62.000,0.08907,4.615,0.002
24.82,62.100,0.08927,4.625,0.002
24.87,62.200,0.08944,4.635,0.002
24.94,62.300,0.08965,4.647,0.002
25.00,62.400,0.08986,4.659,0.002
25.06,62.500,0.09006,4.669,0.002
25.12,62.600,0.09027,4.681,0.002
25.19,62.700,0.09052,4.693,0.002
25.24,62.800,0.09073,4.704,0.002
25.30,62.900,0.09094,4.715,0.002
25.35,63.000,0.09114,4.725,0.002
25.42,63.100,0.09135,4.737,0.002
25.46,63.200,0.09156,4.745,0.002
25.51,63.300,0.09177,4.754,0.002
25.57,63.400,0.09193,4.765,0.002
25.63,63.500,0.09214,4.776,0.002
25.68,63.600,0.09231,4.785,0.002
25.72,63.700,0.09247,4.793,0.002
25.76,63.800,0.09264,4.801,0.002
25.80,63.900,0.09281,4.808,0.002
25.84,64.000,0.09293,4.816,0.002
25.88,64.100,0.09310,4.823,0.002
25.92,64.200,0.09326,4.831,0.002
25.97,64.300,0.09339,4.839,0.002
26.00,64.400,0.09351,4.846,0.002
26.06,64.500,0.09368,4.856,0.002
26.09,64.600,0.09380,4.862,0.002
26.14,64.700,0.09393,4.871,0.002
26.17,64.800,0.09405,4.877,0.002
26.22,64.900,0.09418,4.886,0.002
26.25,65.000,0.09434,4.891,0.002
26.29,65.100,0.09447,4.900,0.002
26.34,65.200,0.09459,4.909,0.002
26.37,65.300,0.09472,4.914,0.002
26.41,65.400,0.09484,4.921,0.002
26.46,65.500,0.09501,4.931,0.002
26.50,65.600,0.09513,4.939,0.002
26.56,65.700,0.09526,4.949,0.002
26.58,65.800,0.09542,4.954,0.002
26.64,65.900,0.09555,4.964,0.002
26.69,66.000,0.09572,4.974,0.002
26.74,66.100,0.09584,4.982,0.002
26.77,66.200,0.09601,4.989,0.002
26.84,66.300,0.09613,5.001,0.002
26.88,66.400,0.09630,5.009,0.002
26.92,66.500,0.09646,5.017,0.002
11.94,66.600,0.09659,2.225,0.002
13.42,66.700,0.09675,2.501,0.002
13.61,66.800,0.09692,2.537,0.002
13.68,66.900,0.09704,2.550,0.002
13.77,67.000,0.09721,2.565,0.002
13.86,67.100,0.09738,2.583,0.002
13.94,67.200,0.09754,2.597,0.002
14.00,67.300,0.09771,2.609,0.002
14.06,67.400,0.09788,2.619,0.002
14.13,67.500,0.09804,2.633,0.002
14.21,67.600,0.09821,2.648,0.002
14.27,67.700,0.09837,2.659,0.002
14.34,67.800,0.09858,2.673,0.002
14.43,67.900,0.09875,2.689,0.002
14.51,68.000,0.09896,2.704,0.002
14.58,68.100,0.09916,2.718,0.002
14.67,68.200,0.09941,2.734,0.002
14.76,68.300,0.09962,2.750,0.002
14.84,68.400,0.09983,2.765,0.002
14.91,68.500,0.10008,2.779,0.002
14.99,68.600,0.10029,2.794,0.002
15.06,68.700,0.10049,2.806,0.002
15.12,68.800,0.10070,2.817,0.002
15.21,68.900,0.10091,2.834,0.002
15.27,69.000,0.10112,2.845,0.002
15.34,69.100,0.10133,2.860,0.002
15.40,69.200,0.10149,2.869,0.002
15.46,69.300,0.10170,2.881,0.002
15.52,69.400,0.10187,2.892,0.002
15.57,69.500,0.10203,2.901,0.002
15.61,69.600,0.10220,2.909,0.002
15.65,69.700,0.10232,2.917,0.002
15.69,69.800,0.10249,2.924,0.002
15.72,69.900,0.10261,2.930,0.002
15.77,70.000,0.10278,2.939,0.002
15.82,70.100,0.10290,2.948,0.002
15.85,70.200,0.10307,2.953,0.002
15.89,70.300,0.10320,2.962,0.002
15.94,70.400,0.10332,2.971,0.002
15.97,70.500,0.10344,2.977,0.002
16.01,70.600,0.10357,2.983,0.002
16.04,70.700,0.10369,2.989,0.002
16.07,70.800,0.10386,2.995,0.002
16.11,70.900,0.10398,3.002,0.002
16.15,71.000,0.10411,3.010,0.002
16.20,71.100,0.10423,3.019,0.002
16.23,71.200,0.10440,3.024,0.002
16.28,71.300,0.10452,3.034,0.002
16.32,71.400,0.10469,3.040,0.002
16.34,71.500,0.10482,3.046,0.002
16.38,71.600,0.10494,3.053,0.002
16.41,71.700,0.10511,3.059,0.002
16.47,71.800,0.10527,3.069,0.002
16.50,71.900,0.10540,3.075,0.002
16.54,72.000,0.10556,3.083,0.002
16.59,72.100,0.10573,3.091,0.002
16.61,72.200,0.10585,3.096,0.002
16.64,72.300,0.10602,3.101,0.002
16.70,72.400,0.10619,3.112,0.002
16.74,72.500,0.10635,3.119,0.002
16.77,72.600,0.10652,3.126,0.002
16.82,72.700,0.10664,3.135,0.002
16.87,72.800,0.10681,3.144,0.002
16.89,72.900,0.10698,3.148,0.002
16.93,73.000,0.10714,3.155,0.002
16.98,73.100,0.10731,3.164,0.002
17.01,73.200,0.10748,3.170,0.002
17.05,73.300,0.10764,3.177,0.002
17.11,73.400,0.10785,3.189,0.002
17.16,73.500,0.10806,3.197,0.002
17.20,73.600,0.10822,3.204,0.002
17.25,73.700,0.10843,3.214,0.002
17.31,73.800,0.10864,3.226,0.002
17.36,73.900,0.10889,3.235,0.002
17.42,74.000,0.10910,3.246,0.002
17.46,74.100,0.10930,3.253,0.002
17.51,74.200,0.10955,3.263,0.002
17.57,74.300,0.10976,3.273,0.002
17.62,74.400,0.11001,3.283,0.002
17.65,74.500,0.11022,3.288,0.002
17.70,74.600,0.11043,3.299,0.002
17.74,74.700,0.11063,3.305,0.002
17.77,74.800,0.11084,3.312,0.002
17.81,74.900,0.11101,3.319,0.002
17.85,75.000,0.11122,3.326,0.002
17.89,75.100,0.11138,3.334,0.002
17.91,75.200,0.11155,3.337,0.002
17.96,75.300,0.11171,3.346,0.002
17.97,75.400,0.11188,3.349,0.002
18.00,75.500,0.11201,3.354,0.002
18.00,75.600,0.11217,3.355,0.002
18.04,75.700,0.11234,3.362,0.002
18.08,75.800,0.11246,3.368,0.002
18.11,75.900,0.11263,3.375,0.002
18.12,76.000,0.11275,3.377,0.002
18.15,76.100,0.11288,3.383,0.002
18.17,76.200,0.11304,3.386,0.002
18.20,76.300,0.11317,3.391,0.002
18.21,76.400,0.11329,3.394,0.002
18.26,76.500,0.11342,3.403,0.002
18.28,76.600,0.11358,3.406,0.002
18.28,76.700,0.11371,3.407,0.002
18.33,76.800,0.11383,3.416,0.002
18.36,76.900,0.11400,3.421,0.002
18.39,77.000,0.11412,3.427,0.002
18.40,77.100,0.11429,3.429,0.002
18.45,77.200,0.11442,3.438,0.002
18.48,77.300,0.11458,3.444,0.002
18.51,77.400,0.11475,3.450,0.002
18.55,77.500,0.11487,3.457,0.002
18.59,77.600,0.11504,3.465,0.002
18.61,77.700,0.11520,3.468,0.002
18.64,77.800,0.11537,3.473,0.002
18.66,77.900,0.11550,3.478,0.002
18.70,78.000,0.11566,3.485,0.002
18.73,78.100,0.11583,3.490,0.002
18.76,78.200,0.11599,3.496,0.002
18.79,78.300,0.11616,3.502,0.002
18.82,78.400,0.11633,3.507,0.002
18.86,78.500,0.11649,3.514,0.002
18.90,78.600,0.11666,3.522,0.002
18.93,78.700,0.11683,3.529,0.002
18.96,78.800,0.11699,3.533,0.002
19.00,78.900,0.11716,3.541,0.002
19.05,79.000,0.11737,3.550,0.002
19.10,79.100,0.11753,3.559,0.002
19.13,79.200,0.11774,3.566,0.002
19.19,79.300,0.11795,3.576,0.002
19.22,79.400,0.11816,3.582,0.002
19.26,79.500,0.11836,3.589,0.002
19.31,79.600,0.11857,3.599,0.002
19.35,79.700,0.11878,3.605,0.002
19.38,79.800,0.11903,3.612,0.002
19.41,79.900,0.11924,3.618,0.002
19.44,80.000,0.11944,3.622,0.002
19.45,80.100,0.11965,3.624,0.002
19.48,80.200,0.11986,3.630,0.002
19.27,80.300,0.12007,3.591,0.002
19.13,80.400,0.12027,3.566,0.002
19.17,80.500,0.12044,3.572,0.002
19.21,80.600,0.12065,3.579,0.002
19.26,80.700,0.12081,3.589,0.002
19.30,80.800,0.12098,3.596,0.002
19.34,80.900,0.12115,3.604,0.002
19.38,81.000,0.12127,3.611,0.002
19.41,81.100,0.12144,3.616,0.002
19.45,81.200,0.12160,3.625,0.002
19.48,81.300,0.12173,3.630,0.002
19.51,81.400,0.12190,3.637,0.002
19.53,81.500,0.12202,3.640,0.002
19.57,81.600,0.12219,3.647,0.002
19.61,81.700,0.12231,3.654,0.002
19.63,81.800,0.12244,3.659,0.002
19.67,81.900,0.12256,3.666,0.002
19.70,82.000,0.12273,3.670,0.002
19.73,82.100,0.12285,3.677,0.002
19.76,82.200,0.12298,3.682,0.002
19.80,82.300,0.12310,3.691,0.002
19.83,82.400,0.12323,3.696,0.002
19.86,82.500,0.12339,3.701,0.002
19.89,82.600,0.12352,3.707,0.002
19.94,82.700,0.12364,3.715,0.002
19.97,82.800,0.12381,3.721,0.002
20.00,82.900,0.12393,3.727,0.002
20.04,83.000,0.12410,3.735,0.002
20.08,83.100,0.12422,3.741,0.002
20.12,83.200,0.12439,3.749,0.002
20.14,83.300,0.12455,3.754,0.002
20.19,83.400,0.12468,3.763,0.002
20.22,83.500,0.12485,3.768,0.002
20.25,83.600,0.12501,3.774,0.002
20.30,83.700,0.12514,3.783,0.002
20.34,83.800,0.12530,3.790,0.002
20.38,83.900,0.12547,3.798,0.002
20.41,84.000,0.12564,3.804,0.002
20.47,84.100,0.12580,3.815,0.002
20.50,84.200,0.12597,3.821,0.002
20.55,84.300,0.12613,3.829,0.002
20.60,84.400,0.12630,3.839,0.002
20.65,84.500,0.12647,3.848,0.002
20.70,84.600,0.12663,3.857,0.002
20.73,84.700,0.12684,3.862,0.002
20.78,84.800,0.12701,3.872,0.003
20.81,84.900,0.12721,3.879,0.003
20.87,85.000,0.12742,3.890,0.003
20.93,85.100,0.12763,3.901,0.003
21.00,85.200,0.12788,3.913,0.003
21.05,85.300,0.12809,3.922,0.003
21.12,85.400,0.12834,3.935,0.003
21.18,85.500,0.12854,3.946,0.003
21.22,85.600,0.12879,3.955,0.003
21.25,85.700,0.12900,3.959,0.003
21.31,85.800,0.12921,3.971,0.003
21.36,85.900,0.12942,3.980,0.003
21.41,86.000,0.12962,3.991,0.003
21.45,86.100,0.12983,3.997,0.003
21.49,86.200,0.13004,4.004,0.003
21.51,86.300,0.13021,4.009,0.003
21.57,86.400,0.13037,4.019,0.003
21.59,86.500,0.13054,4.023,0.003
21.62,86.600,0.13071,4.029,0.003
21.64,86.700,0.13083,4.033,0.003
21.68,86.800,0.13100,4.040,0.003
21.71,86.900,0.13112,4.046,0.003
21.75,87.000,0.13129,4.052,0.003
21.78,87.100,0.13141,4.058,0.003
21.80,87.200,0.13158,4.063,0.003
21.83,87.300,0.13170,4.069,0.003
21.86,87.400,0.13183,4.075,0.003
21.90,87.500,0.13195,4.081,0.003
21.92,87.600,0.13212,4.085,0.003
21.95,87.700,0.13224,4.090,0.003
21.99,87.800,0.13237,4.098,0.003
22.02,87.900,0.13249,4.103,0.003
22.04,88.000,0.13266,4.108,0.003
22.06,88.100,0.13278,4.111,0.003
22.09,88.200,0.13291,4.117,0.003
22.11,88.300,0.13307,4.121,0.003
22.17,88.400,0.13324,4.131,0.003
22.19,88.500,0.13336,4.135,0.003
22.22,88.600,0.13353,4.141,0.003
22.26,88.700,0.13366,4.148,0.003
22.30,88.800,0.13382,4.156,0.003
22.33,88.900,0.13399,4.160,0.003
22.36,89.000,0.13411,4.167,0.003
22.39,89.100,0.13428,4.173,0.003
22.42,89.200,0.13445,4.178,0.003
22.44,89.300,0.13461,4.181,0.003
22.48,89.400,0.13478,4.189,0.003
22.50,89.500,0.13490,4.193,0.003
22.55,89.600,0.13507,4.202,0.003
22.57,89.700,0.13523,4.206,0.003
22.61,89.800,0.13540,4.213,0.003
22.64,89.900,0.13557,4.219,0.003
22.69,90.000,0.13577,4.229,0.003
22.73,90.100,0.13594,4.236,0.003
22.75,90.200,0.13611,4.240,0.003
22.79,90.300,0.13632,4.248,0.003
22.83,90.400,0.13648,4.255,0.003
22.88,90.500,0.13669,4.263,0.003
22.92,90.600,0.13690,4.272,0.003
22.99,90.700,0.13710,4.284,0.003
23.06,90.800,0.13735,4.297,0.003
23.13,90.900,0.13756,4.311,0.003
23.18,91.000,0.13781,4.319,0.003
19.61,91.100,0.13806,3.655,0.003
9.87,91.200,0.13827,1.839,0.003
9.61,91.300,0.13852,1.791,0.003
9.67,91.400,0.13873,1.801,0.003
9.74,91.500,0.13893,1.815,0.003
9.79,91.600,0.13914,1.824,0.003
9.84,91.700,0.13935,1.833,0.003
9.92,91.800,0.13956,1.848,0.003
9.95,91.900,0.13972,1.855,0.003
10.00,92.000,0.13989,1.864,0.003
10.05,92.100,0.14006,1.872,0.003
10.07,92.200,0.14022,1.877,0.003
10.11,92.300,0.14035,1.885,0.003
10.12,92.400,0.14051,1.887,0.003
10.16,92.500,0.14068,1.893,0.003
10.18,92.600,0.14080,1.898,0.003
10.20,92.700,0.14093,1.901,0.003
10.21,92.800,0.14109,1.903,0.003
10.25,92.900,0.14122,1.911,0.003
10.27,93.000,0.14134,1.915,0.003
10.29,93.100,0.14147,1.918,0.003
10.33,93.200,0.14163,1.926,0.003
10.37,93.300,0.14176,1.932,0.003
10.40,93.400,0.14188,1.937,0.003
10.43,93.500,0.14201,1.943,0.003
10.46,93.600,0.14217,1.949,0.003
10.48,93.700,0.14230,1.953,0.003
10.50,93.800,0.14247,1.957,0.003
10.53,93.900,0.14259,1.963,0.003
10.57,94.000,0.14276,1.971,0.003
10.60,94.100,0.14288,1.976,0.003
10.63,94.200,0.14305,1.982,0.003
10.67,94.300,0.14321,1.988,0.003
10.70,94.400,0.14334,1.994,0.003
10.74,94.500,0.14350,2.001,0.003
10.77,94.600,0.14367,2.007,0.003
10.81,94.700,0.14380,2.015,0.003
10.85,94.800,0.14396,2.022,0.003
10.88,94.900,0.14413,2.027,0.003
10.90,95.000,0.14429,2.031,0.003
10.93,95.100,0.14442,2.036,0.003
10.96,95.200,0.14458,2.042,0.003
10.98,95.300,0.14475,2.046,0.003
11.03,95.400,0.14492,2.055,0.003
11.03,95.410,0.14492,2.055,0.003