File: data-files/CWRU/0700-10-10C.txt
""
"Test Method","Will_Huddleston_Disks.msm"
"Sample I. D.","700-10-10C.mss"
"Specimen Number","1"

"Load (N)","Time (s)","Extension (mm)","Stress (MPa)","Strain (mm/mm)"

2.71,0.200,0.01324,0.373,0.000
2.70,0.300,0.01324,0.371,0.000
2.71,0.400,0.01324,0.373,0.000
2.69,0.500,0.01324,0.369,0.000
2.70,0.600,0.01324,0.372,0.000
2.71,0.700,0.01328,0.373,0.000
2.69,0.800,0.01328,0.370,0.000
2.71,0.900,0.01328,0.373,0.000
2.69,1.000,0.01332,0.370,0.000
2.69,1.100,0.01332,0.371,0.000
2.69,1.200,0.01332,0.370,0.000
2.69,1.300,0.01336,0.370,0.000
2.71,1.400,0.01336,0.372,0.000
2.70,1.500,0.01340,0.372,0.000
2.71,1.600,0.01340,0.372,0.000
2.72,1.700,0.01344,0.375,0.000
2.76,1.800,0.01349,0.379,0.000
2.79,1.900,0.01357,0.383,0.000
2.89,2.000,0.01369,0.397,0.000
2.97,2.100,0.01386,0.409,0.000
3.10,2.200,0.01407,0.426,0.000
3.18,2.300,0.01428,0.437,0.000
3.25,2.400,0.01448,0.447,0.000
3.30,2.500,0.01465,0.454,0.000
3.36,2.600,0.01486,0.462,0.000
3.40,2.700,0.01502,0.468,0.000
3.44,2.800,0.01519,0.473,0.000
3.46,2.900,0.01540,0.477,0.000
3.50,3.000,0.01552,0.482,0.000
3.54,3.100,0.01569,0.487,0.000
3.57,3.200,0.01586,0.491,0.000
3.60,3.300,0.01602,0.496,0.000
3.63,3.400,0.01615,0.499,0.000
3.67,3.500,0.01631,0.504,0.000
3.69,3.600,0.01644,0.508,0.000
3.73,3.700,0.01660,0.513,0.000
3.77,3.800,0.01673,0.518,0.000
3.79,3.900,0.01685,0.521,0.000
3.82,4.000,0.01702,0.525,0.000
3.83,4.100,0.01714,0.527,0.000
3.84,4.200,0.01727,0.529,0.000
3.88,4.300,0.01739,0.534,0.000
3.90,4.400,0.01752,0.536,0.000
3.92,4.500,0.01768,0.539,0.000
3.95,4.600,0.01781,0.543,0.000
3.98,4.700,0.01793,0.547,0.000
4.00,4.800,0.01806,0.550,0.000
4.02,4.900,0.01822,0.553,0.000
4.05,5.000,0.01835,0.557,0.000
4.08,5.100,0.01847,0.561,0.000
4.11,5.200,0.01860,0.565,0.000
4.13,5.300,0.01876,0.568,0.000
4.17,5.400,0.01889,0.574,0.000
4.18,5.500,0.01905,0.576,0.000
4.22,5.600,0.01918,0.581,0.000
4.25,5.700,0.01935,0.585,0.000
4.28,5.800,0.01947,0.589,0.000
4.31,5.900,0.01964,0.593,0.000
4.35,6.000,0.01976,0.598,0.000
4.36,6.100,0.01993,0.599,0.000
4.40,6.200,0.02009,0.605,0.000
4.43,6.300,0.02022,0.610,0.000
4.45,6.400,0.02038,0.612,0.000
4.49,6.500,0.02055,0.618,0.000
4.52,6.600,0.02068,0.622,0.000
4.55,6.700,0.02084,0.626,0.000
4.60,6.800,0.02101,0.632,0.000
4.62,6.900,0.02117,0.636,0.000
4.66,7.000,0.02134,0.641,0.000
4.69,7.100,0.02151,0.645,0.000
4.74,7.200,0.02171,0.652,0.000
4.78,7.300,0.02188,0.657,0.000
4.81,7.400,0.02209,0.661,0.000
4.85,7.500,0.02230,0.667,0.000
4.89,7.600,0.02250,0.673,0.000
4.93,7.700,0.02271,0.679,0.000
4.98,7.800,0.02292,0.685,0.000
5.02,7.900,0.02313,0.690,0.000
5.05,8.000,0.02334,0.695,0.000
5.10,8.100,0.02354,0.702,0.000
5.14,8.200,0.02379,0.707,0.000
5.20,8.300,0.02400,0.715,0.000
5.24,8.400,0.02421,0.720,0.000
5.27,8.500,0.02437,0.726,0.000
5.30,8.600,0.02458,0.730,0.000
5.35,8.700,0.02479,0.736,0.000
5.38,8.800,0.02496,0.740,0.000
5.40,8.900,0.02512,0.743,0.000
5.43,9.000,0.02529,0.747,0.000
5.46,9.100,0.02545,0.752,0.001
5.50,9.200,0.02562,0.756,0.001
5.52,9.300,0.02579,0.760,0.001
5.56,9.400,0.02595,0.764,0.001
5.57,9.500,0.02608,0.767,0.001
5.58,9.600,0.02624,0.767,0.001
5.62,9.700,0.02637,0.773,0.001
5.67,9.800,0.02654,0.780,0.001
5.67,9.900,0.02666,0.780,0.001
5.70,10.000,0.02678,0.784,0.001
5.74,10.100,0.02691,0.790,0.001
5.75,10.200,0.02703,0.791,0.001
5.78,10.300,0.02720,0.795,0.001
5.80,10.400,0.02732,0.797,0.001
5.83,10.500,0.02749,0.802,0.001
5.85,10.600,0.02762,0.804,0.001
5.89,10.700,0.02774,0.810,0.001
5.91,10.800,0.02791,0.813,0.001
5.93,10.900,0.02803,0.816,0.001
5.98,11.000,0.02820,0.822,0.001
5.98,11.100,0.02836,0.823,0.001
6.01,11.200,0.02853,0.827,0.001
6.04,11.300,0.02865,0.831,0.001
6.06,11.400,0.02878,0.833,0.001
6.09,11.500,0.02895,0.838,0.001
6.12,11.600,0.02911,0.842,0.001
6.15,11.700,0.02928,0.845,0.001
6.19,11.800,0.02944,0.851,0.001
6.20,11.900,0.02957,0.853,0.001
6.23,12.000,0.02973,0.856,0.001
6.24,12.100,0.02990,0.859,0.001
6.28,12.200,0.03007,0.863,0.001
6.30,12.300,0.03023,0.866,0.001
6.33,12.400,0.03040,0.870,0.001
6.34,12.500,0.03057,0.872,0.001
6.37,12.600,0.03073,0.876,0.001
6.40,12.700,0.03090,0.881,0.001
6.43,12.800,0.03111,0.884,0.001
6.46,12.900,0.03127,0.889,0.001
6.48,13.000,0.03148,0.891,0.001
6.50,13.100,0.03165,0.894,0.001
6.54,13.200,0.03185,0.899,0.001
6.56,13.300,0.03206,0.902,0.001
6.58,13.400,0.03227,0.905,0.001
6.63,13.500,0.03248,0.912,0.001
6.64,13.600,0.03269,0.914,0.001
6.68,13.700,0.03289,0.919,0.001
6.70,13.800,0.03310,0.921,0.001
6.74,13.900,0.03331,0.927,0.001
6.78,14.000,0.03352,0.933,0.001
6.80,14.100,0.03372,0.935,0.001
6.82,14.200,0.03393,0.939,0.001
6.85,14.300,0.03414,0.942,0.001
6.87,14.400,0.03431,0.944,0.001
6.90,14.500,0.03451,0.949,0.001
6.91,14.600,0.03468,0.951,0.001
6.93,14.700,0.03485,0.953,0.001
6.93,14.800,0.03501,0.954,0.001
6.97,14.900,0.03518,0.959,0.001
6.98,15.000,0.03530,0.961,0.001
7.02,15.100,0.03547,0.965,0.001
7.04,15.200,0.03564,0.968,0.001
7.05,15.300,0.03576,0.969,0.001
7.06,15.400,0.03593,0.972,0.001
7.07,15.500,0.03605,0.972,0.001
7.09,15.600,0.03622,0.975,0.001
7.10,15.700,0.03634,0.977,0.001
7.13,15.800,0.03647,0.980,0.001
7.15,15.900,0.03659,0.983,0.001
7.17,16.000,0.03676,0.987,0.001
7.18,16.100,0.03688,0.988,0.001
7.21,16.200,0.03705,0.992,0.001
7.22,16.300,0.03717,0.993,0.001
7.26,16.400,0.03734,0.999,0.001
7.27,16.500,0.03746,1.000,0.001
7.28,16.600,0.03763,1.001,0.001
7.31,16.700,0.03780,1.006,0.001
7.35,16.800,0.03792,1.011,0.001
7.36,16.900,0.03809,1.012,0.001
7.37,17.000,0.03825,1.014,0.001
7.40,17.100,0.03838,1.018,0.001
7.42,17.200,0.03854,1.020,0.001
7.42,17.300,0.03871,1.020,0.001
7.47,17.400,0.03884,1.027,0.001
7.46,17.500,0.03900,1.027,0.001
7.49,17.600,0.03917,1.030,0.001
7.50,17.700,0.03933,1.031,0.001
7.52,17.800,0.03950,1.034,0.001
7.55,17.900,0.03963,1.038,0.001
7.57,18.000,0.03979,1.041,0.001
7.59,18.100,0.03996,1.044,0.001
7.61,18.200,0.04012,1.046,0.001
7.62,18.300,0.04033,1.049,0.001
7.66,18.400,0.04050,1.054,0.001
7.68,18.500,0.04071,1.057,0.001
7.71,18.600,0.04087,1.061,0.001
7.74,18.700,0.04108,1.064,0.001
7.77,18.800,0.04129,1.069,0.001
7.80,18.900,0.04150,1.073,0.001
7.84,19.000,0.04170,1.078,0.001
7.87,19.100,0.04191,1.083,0.001
7.90,19.200,0.04216,1.087,0.001
7.95,19.300,0.04237,1.094,0.001
7.98,19.400,0.04258,1.097,0.001
8.00,19.500,0.04278,1.101,0.001
8.05,19.600,0.04299,1.107,0.001
8.07,19.700,0.04320,1.110,0.001
8.11,19.800,0.04337,1.116,0.001
8.15,19.900,0.04357,1.121,0.001
8.18,20.000,0.04378,1.125,0.001
8.20,20.100,0.04395,1.128,0.001
8.22,20.200,0.04411,1.131,0.001
8.26,20.300,0.04428,1.136,0.001
8.29,20.400,0.04445,1.141,0.001
8.30,20.500,0.04461,1.142,0.001
8.34,20.600,0.04474,1.147,0.001
8.37,20.700,0.04490,1.151,0.001
8.39,20.800,0.04507,1.154,0.001
8.41,20.900,0.04519,1.157,0.001
8.43,21.000,0.04532,1.160,0.001
8.45,21.100,0.04548,1.163,0.001
8.48,21.200,0.04561,1.166,0.001
8.50,21.300,0.04578,1.170,0.001
8.52,21.400,0.04590,1.172,0.001
8.57,21.500,0.04602,1.179,0.001
8.58,21.600,0.04615,1.181,0.001
8.60,21.700,0.04632,1.184,0.001
8.62,21.800,0.04644,1.186,0.001
8.65,21.900,0.04661,1.190,0.001
8.67,22.000,0.04673,1.193,0.001
8.69,22.100,0.04686,1.196,0.001
8.71,22.200,0.04702,1.198,0.001
8.74,22.300,0.04719,1.203,0.001
8.76,22.400,0.04731,1.205,0.001
8.80,22.500,0.04748,1.211,0.001
8.82,22.600,0.04760,1.213,0.001
8.85,22.700,0.04777,1.218,0.001
8.86,22.800,0.04794,1.219,0.001
8.89,22.900,0.04806,1.223,0.001
8.90,23.000,0.04823,1.225,0.001
8.93,23.100,0.04839,1.228,0.001
8.94,23.200,0.04852,1.230,0.001
8.98,23.300,0.04868,1.235,0.001
9.01,23.400,0.04885,1.239,0.001
9.03,23.500,0.04898,1.242,0.001
9.05,23.600,0.04914,1.244,0.001
9.08,23.700,0.04931,1.249,0.001
9.08,23.800,0.04947,1.248,0.001
9.12,23.900,0.04964,1.255,0.001
9.13,24.000,0.04981,1.256,0.001
9.15,24.100,0.04997,1.259,0.001
9.18,24.200,0.05018,1.262,0.001
9.18,24.300,0.05039,1.263,0.001
9.22,24.400,0.05055,1.268,0.001
9.22,24.500,0.05076,1.268,0.001
9.24,24.600,0.05097,1.271,0.001
9.27,24.700,0.05118,1.275,0.001
9.29,24.800,0.05143,1.277,0.001
9.30,24.900,0.05163,1.279,0.001
9.32,25.000,0.05184,1.281,0.001
9.33,25.100,0.05205,1.283,0.001
9.35,25.200,0.05226,1.286,0.001
9.35,25.300,0.05247,1.286,0.001
9.37,25.400,0.05267,1.289,0.001
9.40,25.500,0.05288,1.292,0.001
9.39,25.600,0.05305,1.292,0.001
9.41,25.700,0.05326,1.294,0.001
9.43,25.800,0.05342,1.297,0.001
9.44,25.900,0.05359,1.298,0.001
9.48,26.000,0.05375,1.304,0.001
9.49,26.100,0.05388,1.306,0.001
9.53,26.200,0.05404,1.310,0.001
9.54,26.300,0.05421,1.313,0.001
9.58,26.400,0.05434,1.317,0.001
9.60,26.500,0.05446,1.321,0.001
9.64,26.600,0.05463,1.325,0.001
9.65,26.700,0.05475,1.328,0.001
9.67,26.800,0.05492,1.331,0.001
9.69,26.900,0.05504,1.333,0.001
9.73,27.000,0.05517,1.338,0.001
9.74,27.100,0.05529,1.340,0.001
9.78,27.200,0.05542,1.345,0.001
9.80,27.300,0.05558,1.348,0.001
9.86,27.400,0.05571,1.356,0.001
9.87,27.500,0.05583,1.357,0.001
9.90,27.600,0.05600,1.362,0.001
9.93,27.700,0.05612,1.366,0.001
9.96,27.800,0.05625,1.369,0.001
9.99,27.900,0.05641,1.375,0.001
10.02,28.000,0.05654,1.378,0.001
10.05,28.100,0.05670,1.382,0.001
10.08,28.200,0.05683,1.386,0.001
10.12,28.300,0.05700,1.392,0.001
10.15,28.400,0.05716,1.395,0.001
10.19,28.500,0.05729,1.401,0.001
10.23,28.600,0.05745,1.407,0.001
10.25,28.700,0.05762,1.410,0.001
10.28,28.800,0.05774,1.415,0.001
10.32,28.900,0.05791,1.420,0.001
10.34,29.000,0.05808,1.422,0.001
10.37,29.100,0.05820,1.426,0.001
10.42,29.200,0.05837,1.433,0.001
10.44,29.300,0.05853,1.436,0.001
10.48,29.400,0.05870,1.441,0.001
10.52,29.500,0.05887,1.447,0.001
10.56,29.600,0.05903,1.452,0.001
10.59,29.700,0.05920,1.457,0.001
10.62,29.800,0.05936,1.461,0.001
10.68,29.900,0.05957,1.469,0.001
10.74,30.000,0.05974,1.477,0.001
10.78,30.100,0.05995,1.483,0.001
10.83,30.200,0.06015,1.490,0.001
10.87,30.300,0.06036,1.496,0.001
10.93,30.400,0.06057,1.504,0.001
10.97,30.500,0.06078,1.510,0.001
11.03,30.600,0.06098,1.517,0.001
11.08,30.700,0.06119,1.523,0.001
11.10,30.800,0.06140,1.527,0.001
11.15,30.900,0.06161,1.534,0.001
11.19,31.000,0.06182,1.539,0.001
11.23,31.100,0.06202,1.544,0.001
11.28,31.200,0.06223,1.551,0.001
11.31,31.300,0.06240,1.556,0.001
11.35,31.400,0.06256,1.561,0.001
11.37,31.500,0.06277,1.563,0.001
11.40,31.600,0.06294,1.568,0.001
11.44,31.700,0.06310,1.573,0.001
11.46,31.800,0.06327,1.577,0.001
11.50,31.900,0.06344,1.582,0.001
11.52,32.000,0.06356,1.585,0.001
11.55,32.100,0.06373,1.589,0.001
11.58,32.200,0.06385,1.592,0.001
11.60,32.300,0.06402,1.596,0.001
11.64,32.400,0.06414,1.601,0.001
11.65,32.500,0.06431,1.603,0.001
11.69,32.600,0.06443,1.608,0.001
11.71,32.700,0.06456,1.610,0.001
11.72,32.800,0.06468,1.612,0.001
11.77,32.900,0.06485,1.619,0.001
11.80,33.000,0.06497,1.624,0.001
11.82,33.100,0.06510,1.626,0.001
11.85,33.200,0.06527,1.629,0.001
11.87,33.300,0.06539,1.632,0.001
11.92,33.400,0.06551,1.640,0.001
11.95,33.500,0.06568,1.643,0.001
11.96,33.600,0.06581,1.646,0.001
12.00,33.700,0.06597,1.650,0.001
12.02,33.800,0.06614,1.653,0.001
12.06,33.900,0.06626,1.658,0.001
12.07,34.000,0.06643,1.660,0.001
12.12,34.100,0.06659,1.667,0.001
12.12,34.200,0.06672,1.667,0.001
12.14,34.300,0.06689,1.670,0.001
12.21,34.400,0.06701,1.679,0.001
12.23,34.500,0.06718,1.682,0.001
12.28,34.600,0.06734,1.689,0.001
12.29,34.700,0.06751,1.691,0.001
12.33,34.800,0.06768,1.696,0.001
12.36,34.900,0.06780,1.701,0.001
12.41,35.000,0.06797,1.707,0.001
12.43,35.100,0.06813,1.710,0.001
12.47,35.200,0.06830,1.715,0.001
12.49,35.300,0.06846,1.718,0.001
12.51,35.400,0.06863,1.721,0.001
12.55,35.500,0.06884,1.727,0.001
12.58,35.600,0.06901,1.731,0.001
12.62,35.700,0.06917,1.736,0.001
12.67,35.800,0.06938,1.743,0.001
12.71,35.900,0.06959,1.748,0.001
12.75,36.000,0.06979,1.754,0.001
12.79,36.100,0.07000,1.759,0.001
12.83,36.200,0.07021,1.765,0.001
12.86,36.300,0.07042,1.768,0.001
12.90,36.400,0.07063,1.774,0.001
12.93,36.500,0.07083,1.779,0.001
12.97,36.600,0.07104,1.785,0.001
13.02,36.700,0.07125,1.790,0.001
13.04,36.800,0.07146,1.793,0.001
13.07,36.900,0.07162,1.798,0.001
13.10,37.000,0.07183,1.802,0.001
13.13,37.100,0.07200,1.806,0.001
13.16,37.200,0.07220,1.810,0.001
13.16,37.300,0.07237,1.811,0.001
13.19,37.400,0.07254,1.815,0.001
13.24,37.500,0.07270,1.821,0.001
13.24,37.600,0.07287,1.821,0.001
13.27,37.700,0.07299,1.825,0.001
13.29,37.800,0.07316,1.828,0.001
13.33,37.900,0.07333,1.833,0.001
13.35,38.000,0.07345,1.836,0.001
13.36,38.100,0.07362,1.837,0.001
13.40,38.200,0.07374,1.843,0.001
13.41,38.300,0.07391,1.845,0.001
13.43,38.400,0.07403,1.847,0.001
13.46,38.500,0.07416,1.851,0.001
13.48,38.600,0.07428,1.854,0.001
13.50,38.700,0.07441,1.857,0.001
13.54,38.800,0.07457,1.862,0.001
13.55,38.900,0.07470,1.864,0.001
13.59,39.000,0.07482,1.869,0.001
13.61,39.100,0.07499,1.872,0.001
13.62,39.200,0.07511,1.874,0.001
13.66,39.300,0.07528,1.879,0.001
13.70,39.400,0.07540,1.884,0.001
13.73,39.500,0.07553,1.888,0.001
13.74,39.600,0.07570,1.890,0.001
13.77,39.700,0.07582,1.894,0.001
13.82,39.800,0.07599,1.901,0.001
13.83,39.900,0.07615,1.903,0.001
13.86,40.000,0.07628,1.906,0.002
13.91,40.100,0.07644,1.913,0.002
13.94,40.200,0.07661,1.918,0.002
14.00,40.300,0.07673,1.926,0.002
14.01,40.400,0.07690,1.927,0.002
14.05,40.500,0.07707,1.932,0.002
14.09,40.600,0.07719,1.938,0.002
14.13,40.700,0.07736,1.944,0.002
14.15,40.800,0.07752,1.946,0.002
14.20,40.900,0.07769,1.953,0.002
14.24,41.000,0.07786,1.959,0.002
14.27,41.100,0.07802,1.963,0.002
14.31,41.200,0.07819,1.968,0.002
14.38,41.300,0.07836,1.977,0.002
14.42,41.400,0.07856,1.984,0.002
14.47,41.500,0.07873,1.991,0.002
14.52,41.600,0.07894,1.997,0.002
14.54,41.700,0.07914,2.000,0.002
14.62,41.800,0.07935,2.012,0.002
14.67,41.900,0.07960,2.018,0.002
14.72,42.000,0.07981,2.025,0.002
14.78,42.100,0.08002,2.033,0.002
14.84,42.200,0.08023,2.042,0.002
14.89,42.300,0.08043,2.048,0.002
14.93,42.400,0.08064,2.053,0.002
14.98,42.500,0.08085,2.060,0.002
15.05,42.600,0.08106,2.070,0.002
15.09,42.700,0.08126,2.076,0.002
15.14,42.800,0.08147,2.082,0.002
15.18,42.900,0.08164,2.089,0.002
15.23,43.000,0.08180,2.095,0.002
15.28,43.100,0.08201,2.102,0.002
15.32,43.200,0.08218,2.107,0.002
15.33,43.300,0.08230,2.108,0.002
15.39,43.400,0.08247,2.117,0.002
15.41,43.500,0.08264,2.119,0.002
15.44,43.600,0.08276,2.124,0.002
15.49,43.700,0.08293,2.131,0.002
15.52,43.800,0.08305,2.134,0.002
8.05,43.900,0.08322,1.107,0.002
8.32,44.000,0.08334,1.144,0.002
8.39,44.100,0.08347,1.154,0.002
8.44,44.200,0.08359,1.160,0.002
8.51,44.300,0.08376,1.171,0.002
8.57,44.400,0.08388,1.179,0.002
8.62,44.500,0.08401,1.185,0.002
8.68,44.600,0.08413,1.194,0.002
8.74,44.700,0.08430,1.202,0.002
8.78,44.800,0.08442,1.208,0.002
8.82,44.900,0.08459,1.213,0.002
8.90,45.000,0.08471,1.224,0.002
8.96,45.100,0.08488,1.232,0.002
9.00,45.200,0.08505,1.238,0.002
9.04,45.300,0.08517,1.243,0.002
9.11,45.400,0.08534,1.253,0.002
9.14,45.500,0.08550,1.257,0.002
9.18,45.600,0.08563,1.262,0.002
9.23,45.700,0.08579,1.269,0.002
9.31,45.800,0.08596,1.280,0.002
9.36,45.900,0.08608,1.287,0.002
9.37,46.000,0.08625,1.289,0.002
9.41,46.100,0.08642,1.294,0.002
9.48,46.200,0.08654,1.304,0.002
9.52,46.300,0.08671,1.310,0.002
9.57,46.400,0.08687,1.316,0.002
9.64,46.500,0.08704,1.325,0.002
9.69,46.600,0.08721,1.333,0.002
9.74,46.700,0.08737,1.340,0.002
9.79,46.800,0.08758,1.347,0.002
9.83,46.900,0.08775,1.353,0.002
9.93,47.000,0.08795,1.365,0.002
9.96,47.100,0.08812,1.370,0.002
10.00,47.200,0.08833,1.376,0.002
10.08,47.300,0.08854,1.387,0.002
10.15,47.400,0.08879,1.396,0.002
10.22,47.500,0.08899,1.405,0.002
10.25,47.600,0.08920,1.410,0.002
10.33,47.700,0.08945,1.421,0.002
10.39,47.800,0.08966,1.429,0.002
10.46,47.900,0.08987,1.438,0.002
10.51,48.000,0.09007,1.445,0.002
10.57,48.100,0.09028,1.454,0.002
10.62,48.200,0.09049,1.461,0.002
10.67,48.300,0.09070,1.467,0.002
10.70,48.400,0.09091,1.471,0.002
10.75,48.500,0.09107,1.479,0.002
10.79,48.600,0.09128,1.485,0.002
10.82,48.700,0.09145,1.488,0.002
10.86,48.800,0.09161,1.494,0.002
10.91,48.900,0.09178,1.500,0.002
10.94,49.000,0.09190,1.505,0.002
10.98,49.100,0.09207,1.510,0.002
11.01,49.200,0.09223,1.514,0.002
11.07,49.300,0.09236,1.523,0.002
11.09,49.400,0.09253,1.526,0.002
11.13,49.500,0.09265,1.531,0.002
11.15,49.600,0.09282,1.534,0.002
11.20,49.700,0.09294,1.541,0.002
11.23,49.800,0.09307,1.545,0.002
11.25,49.900,0.09323,1.548,0.002
11.29,50.000,0.09336,1.554,0.002
11.33,50.100,0.09348,1.559,0.002
11.35,50.200,0.09365,1.561,0.002
11.40,50.300,0.09377,1.568,0.002
11.45,50.400,0.09394,1.574,0.002
11.46,50.500,0.09406,1.576,0.002
11.51,50.600,0.09423,1.583,0.002
11.55,50.700,0.09435,1.588,0.002
11.59,50.800,0.09452,1.594,0.002
11.63,50.900,0.09469,1.599,0.002
11.66,51.000,0.09481,1.604,0.002
11.71,51.100,0.09498,1.611,0.002
11.73,51.200,0.09514,1.614,0.002
11.79,51.300,0.09531,1.621,0.002
11.84,51.400,0.09543,1.628,0.002
11.86,51.500,0.09560,1.631,0.002
11.93,51.600,0.09577,1.640,0.002
11.96,51.700,0.09593,1.645,0.002
11.99,51.800,0.09606,1.649,0.002
12.04,51.900,0.09622,1.656,0.002
12.07,52.000,0.09639,1.660,0.002
12.10,52.100,0.09656,1.664,0.002
12.15,52.200,0.09672,1.671,0.002
12.18,52.300,0.09689,1.676,0.002
12.24,52.400,0.09706,1.683,0.002
12.28,52.500,0.09726,1.690,0.002
12.33,52.600,0.09743,1.696,0.002
12.40,52.700,0.09764,1.705,0.002
12.44,52.800,0.09784,1.712,0.002
12.51,52.900,0.09805,1.721,0.002
12.58,53.000,0.09826,1.730,0.002
12.61,53.100,0.09847,1.735,0.002
12.68,53.200,0.09868,1.744,0.002
12.72,53.300,0.09888,1.750,0.002
12.77,53.400,0.09909,1.757,0.002
12.83,53.500,0.09930,1.765,0.002
12.88,53.600,0.09951,1.771,0.002
12.94,53.700,0.09971,1.780,0.002
12.99,53.800,0.09992,1.786,0.002
13.03,53.900,0.10013,1.792,0.002
13.08,54.000,0.10030,1.799,0.002
13.10,54.100,0.10050,1.802,0.002
13.15,54.200,0.10067,1.809,0.002
13.19,54.300,0.10084,1.814,0.002
13.23,54.400,0.10104,1.819,0.002
13.25,54.500,0.10121,1.822,0.002
13.30,54.600,0.10134,1.829,0.002
13.33,54.700,0.10150,1.834,0.002
13.35,54.800,0.10167,1.836,0.002
13.36,54.900,0.10179,1.838,0.002
13.41,55.000,0.10196,1.844,0.002
13.45,55.100,0.10208,1.850,0.002
13.48,55.200,0.10225,1.854,0.002
13.50,55.300,0.10237,1.857,0.002
13.55,55.400,0.10250,1.863,0.002
13.57,55.500,0.10267,1.867,0.002
13.59,55.600,0.10279,1.869,0.002
13.64,55.700,0.10291,1.876,0.002
13.69,55.800,0.10308,1.884,0.002
13.71,55.900,0.10321,1.886,0.002
13.73,56.000,0.10333,1.889,0.002
13.77,56.100,0.10350,1.894,0.002
13.81,56.200,0.10362,1.900,0.002
13.83,56.300,0.10379,1.902,0.002
13.87,56.400,0.10391,1.908,0.002
13.91,56.500,0.10408,1.913,0.002
13.93,56.600,0.10420,1.916,0.002
13.96,56.700,0.10437,1.920,0.002
14.00,56.800,0.10449,1.925,0.002
14.04,56.900,0.10466,1.931,0.002
14.06,57.000,0.10483,1.934,0.002
14.11,57.100,0.10495,1.941,0.002
14.13,57.200,0.10512,1.944,0.002
14.17,57.300,0.10528,1.948,0.002
14.19,57.400,0.10541,1.952,0.002
14.24,57.500,0.10557,1.959,0.002
14.27,57.600,0.10574,1.963,0.002
14.29,57.700,0.10591,1.966,0.002
14.34,57.800,0.10603,1.973,0.002
14.38,57.900,0.10620,1.978,0.002
14.43,58.000,0.10636,1.985,0.002
14.48,58.100,0.10657,1.991,0.002
14.50,58.200,0.10674,1.994,0.002
14.55,58.300,0.10695,2.001,0.002
14.61,58.400,0.10711,2.009,0.002
14.65,58.500,0.10732,2.015,0.002
14.71,58.600,0.10753,2.024,0.002
14.76,58.700,0.10774,2.031,0.002
14.79,58.800,0.10794,2.035,0.002
14.85,58.900,0.10815,2.043,0.002
14.91,59.000,0.10836,2.051,0.002
14.95,59.100,0.10857,2.056,0.002
15.00,59.200,0.10877,2.063,0.002
15.03,59.300,0.10898,2.067,0.002
15.09,59.400,0.10919,2.076,0.002
15.12,59.500,0.10940,2.080,0.002
15.15,59.600,0.10961,2.084,0.002
15.20,59.700,0.10977,2.091,0.002
15.23,59.800,0.10998,2.095,0.002
15.25,59.900,0.11015,2.098,0.002
15.31,60.000,0.11031,2.106,0.002
15.30,60.100,0.11048,2.104,0.002
7.36,60.200,0.11064,1.012,0.002
7.99,60.300,0.11081,1.100,0.002
8.08,60.400,0.11098,1.111,0.002
8.09,60.500,0.11110,1.113,0.002
8.15,60.600,0.11127,1.121,0.002
8.18,60.700,0.11139,1.126,0.002
8.21,60.800,0.11152,1.130,0.002
8.26,60.900,0.11168,1.137,0.002
8.29,61.000,0.11181,1.140,0.002
8.33,61.100,0.11193,1.146,0.002
8.36,61.200,0.11206,1.151,0.002
8.40,61.300,0.11222,1.155,0.002
8.43,61.400,0.11235,1.160,0.002
8.48,61.500,0.11247,1.166,0.002
8.50,61.600,0.11260,1.169,0.002
8.53,61.700,0.11276,1.173,0.002
8.57,61.800,0.11289,1.179,0.002
8.62,61.900,0.11301,1.185,0.002
8.63,62.000,0.11318,1.186,0.002
8.68,62.100,0.11330,1.193,0.002
8.70,62.200,0.11347,1.196,0.002
8.75,62.300,0.11364,1.203,0.002
8.76,62.400,0.11376,1.205,0.002
8.79,62.500,0.11393,1.209,0.002
8.84,62.600,0.11409,1.216,0.002
8.87,62.700,0.11422,1.219,0.002
8.90,62.800,0.11438,1.224,0.002
8.94,62.900,0.11455,1.230,0.002
8.97,63.000,0.11467,1.234,0.002
8.98,63.100,0.11484,1.235,0.002
8.98,63.100,0.11484,1.235,0.002