File: data-files/CWRU/0700-10-24A.txt
""
"Test Method","Will_Huddleston_Disks.msm"
"Sample I. D.","700-10-24A.mss"
"Specimen Number","1"

"Load (N)","Time (s)","Extension (mm)","Stress (MPa)","Strain (mm/mm)"

1.50,0.200,-0.01787,0.232,0.000
1.49,0.300,-0.01783,0.232,0.000
1.49,0.400,-0.01783,0.232,0.000
1.48,0.500,-0.01783,0.229,0.000
1.49,0.600,-0.01779,0.231,0.000
1.50,0.700,-0.01779,0.232,0.000
1.48,0.800,-0.01779,0.231,0.000
1.50,0.900,-0.01775,0.233,0.000
1.49,1.000,-0.01775,0.232,0.000
1.49,1.100,-0.01775,0.231,0.000
1.50,1.200,-0.01770,0.233,0.000
1.49,1.300,-0.01770,0.231,0.000
1.49,1.400,-0.01766,0.232,0.000
1.49,1.500,-0.01766,0.231,0.000
1.51,1.600,-0.01762,0.235,0.000
1.52,1.700,-0.01762,0.235,0.000
1.53,1.800,-0.01758,0.238,0.000
1.54,1.900,-0.01754,0.238,0.000
1.57,2.000,-0.01745,0.243,0.000
1.66,2.100,-0.01725,0.257,0.000
1.74,2.200,-0.01708,0.270,0.000
1.82,2.300,-0.01696,0.282,0.000
1.84,2.400,-0.01683,0.286,0.000
1.88,2.500,-0.01671,0.292,0.000
1.90,2.600,-0.01654,0.295,0.000
1.94,2.700,-0.01642,0.301,0.000
1.95,2.800,-0.01629,0.304,0.000
1.97,2.900,-0.01617,0.306,0.000
2.01,3.000,-0.01604,0.311,0.000
2.03,3.100,-0.01588,0.315,0.000
2.03,3.200,-0.01575,0.315,0.000
2.07,3.300,-0.01563,0.322,0.000
2.09,3.400,-0.01546,0.325,0.000
2.11,3.500,-0.01534,0.328,0.000
2.14,3.600,-0.01517,0.332,0.000
2.15,3.700,-0.01504,0.335,0.000
2.20,3.800,-0.01492,0.342,0.000
2.22,3.900,-0.01475,0.345,0.000
2.23,4.000,-0.01459,0.347,0.000
2.27,4.100,-0.01446,0.353,0.000
2.29,4.200,-0.01430,0.356,0.000
2.31,4.300,-0.01417,0.359,0.000
2.33,4.400,-0.01401,0.363,0.000
2.37,4.500,-0.01384,0.368,0.000
2.39,4.600,-0.01371,0.372,0.000
2.42,4.700,-0.01355,0.375,0.000
2.44,4.800,-0.01338,0.379,0.000
2.47,4.900,-0.01326,0.384,0.000
2.49,5.000,-0.01309,0.387,0.000
2.50,5.100,-0.01292,0.388,0.000
2.53,5.200,-0.01276,0.394,0.000
2.56,5.300,-0.01259,0.398,0.000
2.58,5.400,-0.01243,0.401,0.000
2.62,5.500,-0.01222,0.407,0.000
2.65,5.600,-0.01201,0.411,0.000
2.68,5.700,-0.01180,0.416,0.000
2.71,5.800,-0.01160,0.420,0.000
2.73,5.900,-0.01139,0.424,0.000
2.76,6.000,-0.01118,0.429,0.000
2.79,6.100,-0.01097,0.434,0.000
2.85,6.200,-0.01076,0.443,0.000
2.87,6.300,-0.01056,0.446,0.000
2.90,6.400,-0.01035,0.450,0.000
2.93,6.500,-0.01014,0.455,0.000
2.96,6.600,-0.00993,0.459,0.000
2.98,6.700,-0.00973,0.463,0.000
3.00,6.800,-0.00952,0.466,0.000
3.03,6.900,-0.00935,0.471,0.000
3.04,7.000,-0.00914,0.471,0.000
3.05,7.100,-0.00898,0.474,0.000
3.06,7.200,-0.00881,0.475,0.000
3.09,7.300,-0.00864,0.480,0.000
3.09,7.400,-0.00848,0.479,0.000
3.11,7.500,-0.00835,0.483,0.000
3.12,7.600,-0.00819,0.485,0.000
3.14,7.700,-0.00806,0.488,0.000
3.16,7.800,-0.00790,0.490,0.000
3.16,7.900,-0.00777,0.491,0.000
3.17,8.000,-0.00765,0.493,0.000
3.18,8.100,-0.00748,0.494,0.000
3.20,8.200,-0.00736,0.496,0.000
3.20,8.300,-0.00723,0.498,0.000
3.22,8.400,-0.00711,0.500,0.000
3.24,8.500,-0.00698,0.503,0.000
3.25,8.600,-0.00682,0.504,0.000
3.27,8.700,-0.00669,0.507,0.000
3.28,8.800,-0.00657,0.510,0.000
3.30,8.900,-0.00640,0.513,0.000
3.32,9.000,-0.00628,0.515,0.000
3.32,9.100,-0.00615,0.515,0.000
3.32,9.200,-0.00599,0.516,0.000
3.34,9.300,-0.00586,0.518,0.000
3.38,9.400,-0.00569,0.525,0.000
3.37,9.500,-0.00553,0.523,0.000
3.41,9.600,-0.00540,0.529,0.000
3.40,9.700,-0.00524,0.528,0.000
3.42,9.800,-0.00511,0.531,0.000
3.42,9.900,-0.00495,0.532,0.000
3.44,10.000,-0.00478,0.534,0.000
3.44,10.100,-0.00466,0.535,0.000
3.46,10.200,-0.00449,0.538,0.000
3.46,10.300,-0.00432,0.538,0.000
3.48,10.400,-0.00420,0.541,0.000
3.48,10.500,-0.00403,0.540,0.000
3.51,10.600,-0.00387,0.545,0.000
3.52,10.700,-0.00370,0.546,0.000
3.54,10.800,-0.00353,0.549,0.000
3.55,10.900,-0.00337,0.551,0.000
3.56,11.000,-0.00320,0.553,0.000
3.57,11.100,-0.00299,0.554,0.000
3.59,11.200,-0.00283,0.558,0.000
3.61,11.300,-0.00262,0.560,0.000
3.63,11.400,-0.00241,0.563,0.000
3.65,11.500,-0.00225,0.566,0.000
3.66,11.600,-0.00200,0.569,0.000
3.68,11.700,-0.00179,0.572,0.000
3.69,11.800,-0.00158,0.573,0.000
3.71,11.900,-0.00137,0.577,0.000
3.72,12.000,-0.00116,0.578,0.000
3.74,12.100,-0.00092,0.581,0.000
3.77,12.200,-0.00075,0.585,0.000
3.77,12.300,-0.00054,0.586,0.000
3.80,12.400,-0.00033,0.589,0.000
3.79,12.500,-0.00013,0.589,0.000
3.79,12.600,0.00008,0.589,0.000
3.82,12.700,0.00025,0.593,0.000
3.81,12.800,0.00041,0.591,0.000
3.83,12.900,0.00058,0.595,0.000
3.85,13.000,0.00075,0.598,0.000
3.87,13.100,0.00091,0.601,0.000
3.87,13.200,0.00108,0.600,0.000
3.89,13.300,0.00125,0.604,0.000
3.88,13.400,0.00137,0.602,0.000
3.91,13.500,0.00154,0.607,0.000
3.92,13.600,0.00170,0.608,0.000
3.92,13.700,0.00183,0.609,0.000
3.92,13.800,0.00195,0.609,0.000
3.94,13.900,0.00208,0.611,0.000
3.94,14.000,0.00224,0.611,0.000
3.97,14.100,0.00237,0.616,0.000
3.96,14.200,0.00249,0.615,0.000
3.98,14.300,0.00266,0.619,0.000
3.98,14.400,0.00278,0.618,0.000
4.00,14.500,0.00291,0.622,0.000
4.00,14.600,0.00303,0.622,0.000
4.01,14.700,0.00320,0.623,0.000
4.01,14.800,0.00332,0.623,0.000
4.03,14.900,0.00349,0.626,0.000
4.04,15.000,0.00361,0.627,0.000
4.05,15.100,0.00378,0.630,0.000
4.06,15.200,0.00395,0.630,0.000
4.08,15.300,0.00407,0.634,0.000
4.08,15.400,0.00424,0.634,0.000
4.12,15.500,0.00436,0.639,0.000
4.11,15.600,0.00453,0.638,0.000
4.14,15.700,0.00469,0.642,0.000
4.14,15.800,0.00486,0.642,0.000
4.16,15.900,0.00499,0.646,0.000
4.16,16.000,0.00515,0.646,0.000
4.18,16.100,0.00532,0.649,0.000
4.18,16.200,0.00548,0.649,0.000
4.20,16.300,0.00565,0.653,0.000
4.20,16.400,0.00578,0.652,0.000
4.23,16.500,0.00594,0.657,0.000
4.24,16.600,0.00611,0.659,0.000
4.27,16.700,0.00632,0.662,0.000
4.27,16.800,0.00648,0.663,0.000
4.29,16.900,0.00665,0.666,0.000
4.32,17.000,0.00686,0.671,0.000
4.34,17.100,0.00702,0.674,0.000
4.37,17.200,0.00723,0.678,0.000
4.40,17.300,0.00744,0.683,0.000
4.41,17.400,0.00765,0.685,0.000
4.44,17.500,0.00785,0.690,0.000
4.45,17.600,0.00806,0.691,0.000
4.48,17.700,0.00827,0.695,0.000
4.49,17.800,0.00848,0.698,0.000
4.52,17.900,0.00868,0.701,0.000
4.54,18.000,0.00885,0.705,0.000
4.56,18.100,0.00906,0.708,0.000
4.57,18.200,0.00927,0.709,0.000
4.59,18.300,0.00943,0.713,0.000
4.59,18.400,0.00964,0.712,0.000
4.60,18.500,0.00981,0.715,0.000
4.63,18.600,0.01001,0.719,0.000
4.62,18.700,0.01014,0.718,0.000
4.65,18.800,0.01030,0.721,0.000
4.66,18.900,0.01047,0.724,0.000
4.68,19.000,0.01064,0.727,0.000
4.68,19.100,0.01080,0.726,0.000
4.71,19.200,0.01093,0.731,0.000
4.71,19.300,0.01109,0.731,0.000
4.73,19.400,0.01122,0.735,0.000
4.73,19.500,0.01139,0.735,0.000
4.75,19.600,0.01151,0.738,0.000
4.75,19.700,0.01163,0.737,0.000
4.76,19.800,0.01176,0.739,0.000
4.76,19.900,0.01193,0.739,0.000
4.78,20.000,0.01205,0.742,0.000
4.80,20.100,0.01217,0.745,0.000
4.81,20.200,0.01230,0.747,0.000
4.82,20.300,0.01247,0.749,0.000
4.83,20.400,0.01259,0.751,0.000
4.85,20.500,0.01271,0.753,0.000
4.88,20.600,0.01288,0.758,0.000
4.87,20.700,0.01301,0.757,0.000
4.89,20.800,0.01317,0.759,0.000
4.89,20.900,0.01330,0.759,0.000
4.91,21.000,0.01346,0.762,0.000
4.93,21.100,0.01359,0.765,0.000
4.95,21.200,0.01375,0.769,0.000
4.96,21.300,0.01392,0.770,0.000
4.98,21.400,0.01404,0.773,0.000
4.99,21.500,0.01421,0.776,0.000
4.99,21.600,0.01434,0.775,0.000
5.02,21.700,0.01450,0.779,0.000
5.02,21.800,0.01467,0.780,0.000
5.06,21.900,0.01479,0.785,0.000
5.07,22.000,0.01496,0.788,0.000
5.08,22.100,0.01513,0.789,0.000
5.09,22.200,0.01529,0.790,0.000
5.11,22.300,0.01546,0.793,0.000
5.13,22.400,0.01562,0.797,0.000
5.14,22.500,0.01579,0.798,0.000
5.16,22.600,0.01596,0.802,0.000
5.18,22.700,0.01616,0.804,0.000
5.20,22.800,0.01637,0.808,0.000
5.23,22.900,0.01654,0.812,0.000
5.25,23.000,0.01675,0.815,0.000
5.28,23.100,0.01695,0.820,0.000
5.29,23.200,0.01720,0.822,0.000
5.33,23.300,0.01741,0.828,0.000
5.34,23.400,0.01762,0.830,0.000
5.38,23.500,0.01783,0.835,0.000
5.41,23.600,0.01808,0.841,0.000
5.43,23.700,0.01828,0.844,0.000
5.46,23.800,0.01849,0.848,0.000
5.47,23.900,0.01870,0.850,0.000
5.50,24.000,0.01887,0.854,0.000
5.53,24.100,0.01907,0.859,0.000
5.54,24.200,0.01928,0.860,0.000
5.58,24.300,0.01945,0.866,0.000
5.60,24.400,0.01961,0.870,0.000
5.61,24.500,0.01978,0.872,0.000
5.63,24.600,0.01995,0.875,0.000
5.66,24.700,0.02007,0.879,0.000
5.66,24.800,0.02024,0.878,0.000
5.69,24.900,0.02036,0.884,0.000
5.71,25.000,0.02053,0.886,0.000
5.73,25.100,0.02065,0.890,0.000
5.76,25.200,0.02082,0.894,0.000
5.77,25.300,0.02094,0.896,0.000
5.76,25.400,0.02107,0.895,0.000
5.78,25.500,0.02123,0.898,0.000
5.79,25.600,0.02136,0.900,0.000
5.84,25.700,0.02148,0.907,0.000
5.84,25.800,0.02161,0.907,0.000
5.85,25.900,0.02177,0.909,0.000
5.89,26.000,0.02190,0.915,0.000
5.91,26.100,0.02207,0.917,0.000
5.93,26.200,0.02219,0.921,0.000
5.95,26.300,0.02236,0.923,0.000
5.97,26.400,0.02248,0.928,0.000
5.99,26.500,0.02265,0.930,0.000
6.01,26.600,0.02277,0.934,0.000
6.04,26.700,0.02294,0.937,0.000
6.06,26.800,0.02310,0.941,0.000
6.08,26.900,0.02323,0.944,0.000
6.10,27.000,0.02339,0.947,0.000
6.12,27.100,0.02356,0.951,0.000
6.13,27.200,0.02369,0.952,0.000
6.16,27.300,0.02385,0.957,0.000
6.19,27.400,0.02402,0.961,0.000
6.21,27.500,0.02418,0.965,0.000
6.23,27.600,0.02431,0.968,0.000
6.25,27.700,0.02448,0.971,0.000
6.28,27.800,0.02464,0.975,0.000
6.30,27.900,0.02481,0.979,0.000
6.33,28.000,0.02502,0.983,0.000
6.35,28.100,0.02518,0.986,0.000
6.37,28.200,0.02535,0.989,0.000
6.42,28.300,0.02551,0.997,0.001
6.44,28.400,0.02572,1.000,0.001
6.47,28.500,0.02593,1.005,0.001
6.51,28.600,0.02614,1.011,0.001
6.53,28.700,0.02635,1.014,0.001
6.56,28.800,0.02655,1.019,0.001
6.60,28.900,0.02676,1.025,0.001
6.62,29.000,0.02701,1.028,0.001
6.68,29.100,0.02722,1.038,0.001
6.70,29.200,0.02743,1.041,0.001
6.73,29.300,0.02763,1.045,0.001
6.76,29.400,0.02784,1.050,0.001
6.79,29.500,0.02805,1.054,0.001
6.81,29.600,0.02826,1.058,0.001
6.83,29.700,0.02846,1.061,0.001
6.86,29.800,0.02867,1.065,0.001
6.88,29.900,0.02884,1.069,0.001
6.90,30.000,0.02900,1.072,0.001
6.92,30.100,0.02917,1.075,0.001
6.96,30.200,0.02934,1.081,0.001
6.97,30.300,0.02950,1.082,0.001
7.00,30.400,0.02963,1.087,0.001
7.00,30.500,0.02979,1.087,0.001
7.03,30.600,0.02996,1.092,0.001
7.06,30.700,0.03009,1.096,0.001
7.07,30.800,0.03025,1.099,0.001
7.09,30.900,0.03038,1.101,0.001
7.12,31.000,0.03050,1.106,0.001
7.10,31.100,0.03063,1.103,0.001
7.15,31.200,0.03079,1.110,0.001
7.16,31.300,0.03092,1.112,0.001
7.19,31.400,0.03104,1.116,0.001
7.22,31.500,0.03121,1.121,0.001
7.22,31.600,0.03133,1.122,0.001
7.26,31.700,0.03146,1.127,0.001
7.28,31.800,0.03162,1.131,0.001
7.28,31.900,0.03175,1.131,0.001
7.32,32.000,0.03191,1.137,0.001
7.33,32.100,0.03204,1.139,0.001
7.37,32.200,0.03220,1.145,0.001
7.39,32.300,0.03237,1.147,0.001
7.41,32.400,0.03250,1.151,0.001
7.45,32.500,0.03266,1.157,0.001
7.46,32.600,0.03283,1.159,0.001
7.47,32.700,0.03299,1.160,0.001
7.50,32.800,0.03312,1.164,0.001
7.53,32.900,0.03329,1.170,0.001
7.56,33.000,0.03345,1.174,0.001
7.57,33.100,0.03362,1.175,0.001
7.59,33.200,0.03378,1.179,0.001
7.63,33.300,0.03395,1.185,0.001
7.65,33.400,0.03412,1.188,0.001
7.68,33.500,0.03428,1.193,0.001
7.69,33.600,0.03445,1.195,0.001
7.72,33.700,0.03461,1.199,0.001
7.76,33.800,0.03478,1.205,0.001
7.78,33.900,0.03499,1.208,0.001
7.82,34.000,0.03516,1.214,0.001
7.85,34.100,0.03536,1.220,0.001
7.88,34.200,0.03557,1.224,0.001
7.93,34.300,0.03578,1.231,0.001
7.95,34.400,0.03599,1.235,0.001
7.98,34.500,0.03624,1.240,0.001
8.02,34.600,0.03644,1.246,0.001
8.04,34.700,0.03665,1.248,0.001
8.09,34.800,0.03686,1.256,0.001
8.12,34.900,0.03707,1.261,0.001
8.16,35.000,0.03727,1.267,0.001
8.19,35.100,0.03748,1.272,0.001
8.22,35.200,0.03769,1.277,0.001
8.24,35.300,0.03786,1.279,0.001
8.27,35.400,0.03806,1.284,0.001
8.28,35.500,0.03823,1.286,0.001
8.32,35.600,0.03840,1.291,0.001
8.34,35.700,0.03860,1.295,0.001
8.36,35.800,0.03873,1.298,0.001
8.38,35.900,0.03890,1.301,0.001
8.41,36.000,0.03906,1.306,0.001
8.43,36.100,0.03923,1.309,0.001
8.45,36.200,0.03939,1.312,0.001
8.46,36.300,0.03952,1.314,0.001
8.49,36.400,0.03968,1.319,0.001
8.52,36.500,0.03981,1.323,0.001
8.55,36.600,0.03998,1.329,0.001
8.57,36.700,0.04010,1.330,0.001
8.58,36.800,0.04022,1.333,0.001
8.60,36.900,0.04039,1.335,0.001
8.63,37.000,0.04052,1.341,0.001
8.66,37.100,0.04064,1.345,0.001
8.68,37.200,0.04077,1.349,0.001
8.70,37.300,0.04093,1.351,0.001
8.72,37.400,0.04106,1.355,0.001
8.75,37.500,0.04122,1.359,0.001
8.77,37.600,0.04135,1.363,0.001
8.79,37.700,0.04151,1.364,0.001
8.82,37.800,0.04164,1.370,0.001
8.85,37.900,0.04180,1.374,0.001
8.88,38.000,0.04193,1.380,0.001
8.91,38.100,0.04209,1.384,0.001
8.94,38.200,0.04226,1.388,0.001
8.96,38.300,0.04239,1.392,0.001
9.01,38.400,0.04255,1.399,0.001
9.04,38.500,0.04272,1.404,0.001
9.06,38.600,0.04288,1.407,0.001
9.09,38.700,0.04301,1.412,0.001
9.13,38.800,0.04318,1.417,0.001
9.16,38.900,0.04334,1.423,0.001
9.18,39.000,0.04351,1.426,0.001
9.21,39.100,0.04367,1.431,0.001
9.25,39.200,0.04384,1.436,0.001
9.28,39.300,0.04401,1.441,0.001
9.34,39.400,0.04417,1.451,0.001
9.38,39.500,0.04438,1.457,0.001
9.41,39.600,0.04455,1.462,0.001
9.45,39.700,0.04475,1.467,0.001
9.49,39.800,0.04496,1.474,0.001
9.54,39.900,0.04517,1.482,0.001
9.57,40.000,0.04538,1.486,0.001
9.63,40.100,0.04559,1.496,0.001
9.67,40.200,0.04579,1.502,0.001
9.72,40.300,0.04600,1.509,0.001
9.76,40.400,0.04621,1.515,0.001
9.80,40.500,0.04646,1.522,0.001
9.86,40.600,0.04667,1.532,0.001
9.89,40.700,0.04687,1.536,0.001
9.93,40.800,0.04704,1.542,0.001
9.98,40.900,0.04725,1.550,0.001
10.02,41.000,0.04746,1.556,0.001
10.06,41.100,0.04762,1.562,0.001
10.10,41.200,0.04783,1.568,0.001
10.11,41.300,0.04800,1.570,0.001
10.14,41.400,0.04812,1.575,0.001
10.16,41.500,0.04829,1.578,0.001
10.20,41.600,0.04845,1.583,0.001
10.22,41.700,0.04862,1.588,0.001
10.25,41.800,0.04874,1.592,0.001
10.29,41.900,0.04891,1.597,0.001
10.30,42.000,0.04903,1.600,0.001
10.36,42.100,0.04920,1.609,0.001
10.39,42.200,0.04933,1.614,0.001
10.40,42.300,0.04945,1.616,0.001
10.44,42.400,0.04958,1.621,0.001
10.46,42.500,0.04974,1.624,0.001
10.48,42.600,0.04987,1.628,0.001
10.53,42.700,0.04999,1.636,0.001
10.55,42.800,0.05012,1.639,0.001
10.58,42.900,0.05024,1.643,0.001
10.63,43.000,0.05041,1.650,0.001
10.64,43.100,0.05053,1.653,0.001
10.69,43.200,0.05070,1.660,0.001
10.72,43.300,0.05082,1.665,0.001
10.76,43.400,0.05099,1.672,0.001
10.79,43.500,0.05111,1.676,0.001
10.83,43.600,0.05128,1.681,0.001
10.86,43.700,0.05140,1.687,0.001
10.90,43.800,0.05157,1.693,0.001
10.94,43.900,0.05174,1.699,0.001
10.97,44.000,0.05186,1.703,0.001
11.00,44.100,0.05203,1.708,0.001
11.06,44.200,0.05219,1.717,0.001
11.09,44.300,0.05236,1.722,0.001
11.11,44.400,0.05248,1.726,0.001
11.16,44.500,0.05265,1.733,0.001
11.20,44.600,0.05282,1.739,0.001
11.22,44.700,0.05298,1.742,0.001
5.88,44.800,0.05315,0.914,0.001
6.24,44.900,0.05332,0.970,0.001
6.34,45.000,0.05348,0.984,0.001
6.39,45.100,0.05365,0.993,0.001
6.45,45.200,0.05381,1.001,0.001
6.50,45.300,0.05402,1.010,0.001
6.56,45.400,0.05423,1.018,0.001
6.60,45.500,0.05440,1.025,0.001
6.66,45.600,0.05460,1.035,0.001
6.73,45.700,0.05481,1.045,0.001
6.77,45.800,0.05502,1.052,0.001
6.82,45.900,0.05523,1.060,0.001
6.88,46.000,0.05548,1.068,0.001
6.92,46.100,0.05568,1.075,0.001
6.96,46.200,0.05589,1.081,0.001
7.01,46.300,0.05610,1.089,0.001
7.07,46.400,0.05631,1.098,0.001
7.11,46.500,0.05647,1.104,0.001
7.15,46.600,0.05668,1.110,0.001
7.20,46.700,0.05689,1.118,0.001
7.24,46.800,0.05706,1.124,0.001
7.28,46.900,0.05726,1.130,0.001
7.31,47.000,0.05743,1.135,0.001
7.34,47.100,0.05760,1.139,0.001
7.38,47.200,0.05776,1.147,0.001
7.41,47.300,0.05793,1.151,0.001
7.44,47.400,0.05805,1.156,0.001
7.47,47.500,0.05822,1.161,0.001
7.51,47.600,0.05838,1.167,0.001
7.54,47.700,0.05851,1.170,0.001
7.58,47.800,0.05863,1.177,0.001
7.60,47.900,0.05880,1.181,0.001
7.65,48.000,0.05893,1.188,0.001
7.66,48.100,0.05905,1.190,0.001
7.70,48.200,0.05922,1.196,0.001
7.73,48.300,0.05934,1.200,0.001
7.74,48.400,0.05947,1.202,0.001
7.77,48.500,0.05959,1.206,0.001
7.81,48.600,0.05976,1.213,0.001
7.84,48.700,0.05988,1.218,0.001
7.87,48.800,0.06005,1.222,0.001
7.91,48.900,0.06017,1.229,0.001
7.92,49.000,0.06034,1.230,0.001
7.95,49.100,0.06046,1.235,0.001
8.00,49.200,0.06063,1.243,0.001
8.02,49.300,0.06080,1.246,0.001
8.04,49.400,0.06092,1.249,0.001
8.08,49.500,0.06109,1.255,0.001
8.12,49.600,0.06125,1.261,0.001
8.16,49.700,0.06138,1.267,0.001
8.18,49.800,0.06154,1.270,0.001
8.21,49.900,0.06171,1.275,0.001
8.24,50.000,0.06188,1.279,0.001
8.28,50.100,0.06200,1.286,0.001
8.30,50.200,0.06217,1.289,0.001
8.35,50.300,0.06233,1.297,0.001
8.38,50.400,0.06250,1.301,0.001
8.40,50.500,0.06267,1.305,0.001
8.43,50.600,0.06283,1.309,0.001
8.48,50.700,0.06300,1.316,0.001
8.51,50.800,0.06316,1.322,0.001
8.54,50.900,0.06337,1.326,0.001
8.58,51.000,0.06354,1.332,0.001
8.60,51.100,0.06375,1.336,0.001
8.65,51.200,0.06395,1.344,0.001
8.70,51.300,0.06416,1.351,0.001
8.73,51.400,0.06437,1.356,0.001
8.77,51.500,0.06458,1.362,0.001
8.80,51.600,0.06478,1.367,0.001
8.85,51.700,0.06499,1.375,0.001
8.88,51.800,0.06520,1.378,0.001
8.92,51.900,0.06541,1.386,0.001
8.95,52.000,0.06562,1.391,0.001
8.99,52.100,0.06582,1.396,0.001
9.03,52.200,0.06603,1.402,0.001
9.07,52.300,0.06620,1.409,0.001
9.11,52.400,0.06641,1.415,0.001
9.15,52.500,0.06657,1.421,0.001
9.17,52.600,0.06678,1.424,0.001
9.19,52.700,0.06690,1.427,0.001
9.22,52.800,0.06707,1.433,0.001
9.24,52.900,0.06724,1.436,0.001
9.26,53.000,0.06740,1.439,0.001
9.29,53.100,0.06757,1.444,0.001
9.31,53.200,0.06769,1.446,0.001
9.35,53.300,0.06786,1.452,0.001
9.36,53.400,0.06798,1.454,0.001
9.40,53.500,0.06811,1.460,0.001
9.43,53.600,0.06828,1.464,0.001
9.44,53.700,0.06840,1.467,0.001
9.47,53.800,0.06857,1.470,0.001
9.48,53.900,0.06869,1.472,0.001
9.52,54.000,0.06882,1.479,0.001
9.53,54.100,0.06894,1.481,0.001
9.55,54.200,0.06906,1.483,0.001
9.59,54.300,0.06923,1.489,0.001
9.61,54.400,0.06936,1.492,0.001
9.63,54.500,0.06952,1.496,0.001
9.66,54.600,0.06965,1.500,0.001
9.67,54.700,0.06977,1.502,0.001
9.72,54.800,0.06994,1.510,0.001
9.74,54.900,0.07006,1.513,0.001
9.77,55.000,0.07023,1.517,0.001
9.81,55.100,0.07039,1.523,0.001
9.83,55.200,0.07052,1.527,0.001
9.85,55.300,0.07069,1.530,0.001
9.87,55.400,0.07085,1.533,0.001
9.91,55.500,0.07098,1.539,0.001
9.93,55.600,0.07114,1.542,0.001
9.97,55.700,0.07131,1.548,0.001
10.02,55.800,0.07143,1.556,0.001
10.02,55.900,0.07160,1.557,0.001
10.07,56.000,0.07177,1.563,0.001
10.09,56.100,0.07193,1.566,0.001
10.12,56.200,0.07210,1.572,0.001
10.16,56.300,0.07226,1.578,0.001
10.19,56.400,0.07243,1.583,0.001
10.22,56.500,0.07260,1.587,0.001
10.27,56.600,0.07280,1.595,0.001
10.28,56.700,0.07297,1.597,0.001
10.35,56.800,0.07318,1.607,0.001
10.37,56.900,0.07339,1.611,0.001
10.43,57.000,0.07359,1.620,0.001
10.47,57.100,0.07384,1.625,0.001
10.51,57.200,0.07405,1.632,0.001
10.56,57.300,0.07426,1.640,0.001
10.58,57.400,0.07451,1.643,0.001
10.61,57.500,0.07472,1.648,0.001
10.65,57.600,0.07492,1.654,0.001
10.68,57.700,0.07513,1.658,0.001
10.72,57.800,0.07534,1.665,0.001
10.75,57.900,0.07555,1.669,0.001
10.79,58.000,0.07571,1.675,0.001
10.81,58.100,0.07592,1.679,0.001
10.85,58.200,0.07609,1.684,0.001
6.60,58.300,0.07625,1.025,0.002
7.04,58.400,0.07642,1.094,0.002
7.10,58.500,0.07659,1.103,0.002
7.13,58.600,0.07675,1.108,0.002
7.15,58.700,0.07688,1.110,0.002
7.16,58.800,0.07704,1.112,0.002
7.20,58.900,0.07717,1.118,0.002
7.23,59.000,0.07733,1.123,0.002
7.25,59.100,0.07746,1.126,0.002
7.26,59.200,0.07763,1.127,0.002
7.28,59.300,0.07775,1.131,0.002
7.31,59.400,0.07787,1.135,0.002
7.33,59.500,0.07800,1.138,0.002
7.35,59.600,0.07817,1.141,0.002
7.38,59.700,0.07829,1.146,0.002
7.40,59.800,0.07841,1.149,0.002
7.44,59.900,0.07858,1.155,0.002
7.43,60.000,0.07871,1.153,0.002
7.47,60.100,0.07883,1.160,0.002
7.49,60.200,0.07900,1.163,0.002
7.51,60.300,0.07916,1.166,0.002
7.54,60.400,0.07929,1.171,0.002
7.55,60.500,0.07945,1.173,0.002
7.60,60.600,0.07958,1.180,0.002
7.59,60.700,0.07974,1.179,0.002
7.61,60.800,0.07987,1.182,0.002
7.65,60.900,0.08004,1.189,0.002
7.66,61.000,0.08020,1.190,0.002
7.69,61.100,0.08037,1.194,0.002
7.70,61.200,0.08053,1.196,0.002
7.74,61.300,0.08066,1.202,0.002
7.76,61.400,0.08083,1.205,0.002
7.78,61.500,0.08099,1.209,0.002
7.81,61.600,0.08116,1.213,0.002
7.82,61.700,0.08132,1.214,0.002
7.83,61.800,0.08149,1.217,0.002
7.87,61.900,0.08166,1.222,0.002
7.62,62.000,0.08182,1.183,0.002
4.52,62.100,0.08199,0.702,0.002
4.52,62.200,0.08215,0.702,0.002
4.55,62.300,0.08236,0.707,0.002
4.58,62.400,0.08257,0.711,0.002
4.60,62.500,0.08274,0.714,0.002
4.64,62.600,0.08294,0.720,0.002
4.67,62.700,0.08319,0.725,0.002
4.69,62.800,0.08340,0.728,0.002
4.73,62.900,0.08361,0.735,0.002
4.75,63.000,0.08382,0.738,0.002
4.76,63.100,0.08402,0.740,0.002
4.80,63.200,0.08423,0.745,0.002
4.82,63.300,0.08444,0.748,0.002
4.83,63.400,0.08465,0.751,0.002
4.86,63.500,0.08486,0.755,0.002
4.88,63.600,0.08506,0.757,0.002
4.89,63.700,0.08527,0.760,0.002
4.91,63.800,0.08544,0.763,0.002
4.93,63.900,0.08565,0.766,0.002
4.95,64.000,0.08581,0.768,0.002
4.96,64.100,0.08598,0.770,0.002
4.97,64.200,0.08614,0.773,0.002
4.97,64.250,0.08619,0.771,0.002