File: data-files/CWRU/0800-05-28A.txt
""
"Test Method","Will_Huddleston_Disks.msm"
"Sample I. D.","800-5-28A.mss"
"Specimen Number","1"

"Load (N)","Time (s)","Extension (mm)","Stress (MPa)","Strain (mm/mm)"

1.98,0.200,-0.04416,0.336,-0.001
1.96,0.300,-0.04416,0.333,-0.001
1.97,0.400,-0.04416,0.335,-0.001
1.99,0.500,-0.04416,0.337,-0.001
1.98,0.600,-0.04412,0.337,-0.001
1.97,0.700,-0.04412,0.334,-0.001
1.98,0.800,-0.04412,0.337,-0.001
1.97,0.900,-0.04408,0.334,-0.001
1.98,1.000,-0.04408,0.336,-0.001
1.99,1.100,-0.04408,0.337,-0.001
1.98,1.200,-0.04404,0.337,-0.001
1.98,1.300,-0.04404,0.336,-0.001
2.00,1.400,-0.04400,0.339,-0.001
2.00,1.500,-0.04400,0.340,-0.001
2.00,1.600,-0.04396,0.339,-0.001
2.01,1.700,-0.04396,0.341,-0.001
2.03,1.800,-0.04391,0.344,-0.001
2.05,1.900,-0.04391,0.348,-0.001
2.06,2.000,-0.04387,0.350,-0.001
2.13,2.100,-0.04379,0.362,-0.001
2.22,2.200,-0.04367,0.377,-0.001
2.30,2.300,-0.04354,0.391,-0.001
2.38,2.400,-0.04337,0.404,-0.001
2.44,2.500,-0.04325,0.414,-0.001
2.50,2.600,-0.04308,0.424,-0.001
2.56,2.700,-0.04296,0.434,-0.001
2.59,2.800,-0.04279,0.440,-0.001
2.64,2.900,-0.04267,0.447,-0.001
2.67,3.000,-0.04250,0.453,-0.001
2.70,3.100,-0.04238,0.459,-0.001
2.76,3.200,-0.04221,0.468,-0.001
2.80,3.300,-0.04209,0.474,-0.001
2.82,3.400,-0.04192,0.479,-0.001
2.88,3.500,-0.04175,0.488,-0.001
2.89,3.600,-0.04163,0.490,-0.001
2.93,3.700,-0.04146,0.497,-0.001
2.97,3.800,-0.04130,0.504,-0.001
3.02,3.900,-0.04113,0.513,-0.001
3.06,4.000,-0.04092,0.520,-0.001
3.10,4.100,-0.04076,0.526,-0.001
3.14,4.200,-0.04059,0.532,-0.001
3.17,4.300,-0.04038,0.537,-0.001
3.22,4.400,-0.04017,0.546,-0.001
3.26,4.500,-0.04001,0.552,-0.001
3.31,4.600,-0.03980,0.561,-0.001
3.35,4.700,-0.03959,0.568,-0.001
3.39,4.800,-0.03939,0.575,-0.001
3.44,4.900,-0.03918,0.584,-0.001
3.48,5.000,-0.03897,0.591,-0.001
3.51,5.100,-0.03880,0.596,-0.001
3.57,5.200,-0.03860,0.606,-0.001
3.61,5.300,-0.03839,0.612,-0.001
3.65,5.400,-0.03818,0.620,-0.001
3.69,5.500,-0.03801,0.626,-0.001
3.72,5.600,-0.03781,0.631,-0.001
3.77,5.700,-0.03764,0.640,-0.001
3.82,5.800,-0.03747,0.648,-0.001
3.85,5.900,-0.03731,0.653,-0.001
3.92,6.000,-0.03714,0.664,-0.001
3.94,6.100,-0.03697,0.669,-0.001
3.99,6.200,-0.03681,0.676,-0.001
4.01,6.300,-0.03668,0.681,-0.001
4.06,6.400,-0.03652,0.689,-0.001
4.09,6.500,-0.03639,0.694,-0.001
4.13,6.600,-0.03623,0.701,-0.001
4.18,6.700,-0.03606,0.709,-0.001
4.21,6.800,-0.03594,0.714,-0.001
4.25,6.900,-0.03581,0.721,-0.001
4.29,7.000,-0.03565,0.728,-0.001
4.32,7.100,-0.03552,0.732,-0.001
4.35,7.200,-0.03540,0.738,-0.001
4.39,7.300,-0.03527,0.745,-0.001
4.44,7.400,-0.03510,0.753,-0.001
4.49,7.500,-0.03498,0.761,-0.001
4.52,7.600,-0.03486,0.766,-0.001
4.55,7.700,-0.03469,0.772,-0.001
4.59,7.800,-0.03456,0.779,-0.001
4.62,7.900,-0.03440,0.784,-0.001
4.66,8.000,-0.03427,0.790,-0.001
4.70,8.100,-0.03411,0.798,-0.001
4.73,8.200,-0.03398,0.803,-0.001
4.78,8.300,-0.03382,0.810,-0.001
4.82,8.400,-0.03365,0.818,-0.001
4.86,8.500,-0.03353,0.825,-0.001
4.91,8.600,-0.03336,0.833,-0.001
4.96,8.700,-0.03323,0.841,-0.001
5.00,8.800,-0.03307,0.848,-0.001
5.04,8.900,-0.03290,0.855,-0.001
5.08,9.000,-0.03278,0.863,-0.001
5.13,9.100,-0.03261,0.871,-0.001
5.18,9.200,-0.03245,0.879,-0.001
5.21,9.300,-0.03228,0.885,-0.001
5.26,9.400,-0.03211,0.892,-0.001
5.28,9.500,-0.03195,0.896,-0.001
5.33,9.600,-0.03178,0.904,-0.001
5.38,9.700,-0.03161,0.913,-0.001
5.40,9.800,-0.03145,0.917,-0.001
5.46,9.900,-0.03124,0.926,-0.001
5.50,10.000,-0.03107,0.933,-0.001
5.55,10.100,-0.03087,0.942,-0.001
5.59,10.200,-0.03066,0.948,-0.001
5.64,10.300,-0.03045,0.957,-0.001
5.67,10.400,-0.03024,0.962,-0.001
5.71,10.500,-0.03003,0.968,-0.001
5.76,10.600,-0.02983,0.977,-0.001
5.79,10.700,-0.02958,0.983,-0.001
5.83,10.800,-0.02937,0.989,-0.001
5.88,10.900,-0.02916,0.998,-0.001
5.91,11.000,-0.02895,1.002,-0.001
5.95,11.100,-0.02879,1.010,-0.001
6.00,11.200,-0.02858,1.018,-0.001
6.02,11.300,-0.02837,1.021,-0.001
6.05,11.400,-0.02821,1.027,-0.001
6.08,11.500,-0.02804,1.032,-0.001
6.10,11.600,-0.02783,1.035,-0.001
6.12,11.700,-0.02767,1.039,-0.001
6.16,11.800,-0.02754,1.045,-0.001
6.19,11.900,-0.02738,1.050,-0.001
6.22,12.000,-0.02721,1.055,-0.001
6.26,12.100,-0.02708,1.062,-0.001
6.30,12.200,-0.02692,1.069,-0.001
6.32,12.300,-0.02679,1.072,-0.001
6.36,12.400,-0.02667,1.078,-0.001
6.38,12.500,-0.02650,1.082,-0.001
6.42,12.600,-0.02638,1.089,-0.001
6.46,12.700,-0.02625,1.095,-0.001
6.48,12.800,-0.02613,1.100,-0.001
6.50,12.900,-0.02596,1.102,-0.001
6.54,13.000,-0.02584,1.110,-0.001
6.58,13.100,-0.02571,1.116,-0.001
6.62,13.200,-0.02555,1.122,-0.001
6.65,13.300,-0.02542,1.129,-0.001
6.69,13.400,-0.02526,1.135,0.000
6.73,13.500,-0.02513,1.143,0.000
6.77,13.600,-0.02497,1.149,0.000
6.81,13.700,-0.02484,1.155,0.000
6.86,13.800,-0.02467,1.163,0.000
6.88,13.900,-0.02451,1.167,0.000
6.92,14.000,-0.02438,1.174,0.000
6.96,14.100,-0.02422,1.182,0.000
7.00,14.200,-0.02405,1.188,0.000
7.04,14.300,-0.02393,1.194,0.000
7.09,14.400,-0.02376,1.203,0.000
7.13,14.500,-0.02359,1.210,0.000
7.18,14.600,-0.02343,1.217,0.000
7.22,14.700,-0.02330,1.225,0.000
7.26,14.800,-0.02314,1.232,0.000
7.30,14.900,-0.02297,1.239,0.000
7.34,15.000,-0.02280,1.246,0.000
7.39,15.100,-0.02264,1.254,0.000
7.46,15.200,-0.02247,1.265,0.000
7.50,15.300,-0.02231,1.272,0.000
7.53,15.400,-0.02210,1.278,0.000
7.59,15.500,-0.02193,1.287,0.000
7.64,15.600,-0.02172,1.296,0.000
7.68,15.700,-0.02152,1.303,0.000
7.73,15.800,-0.02131,1.311,0.000
7.77,15.900,-0.02110,1.318,0.000
7.81,16.000,-0.02089,1.326,0.000
7.83,16.100,-0.02068,1.328,0.000
7.89,16.200,-0.02048,1.339,0.000
7.93,16.300,-0.02027,1.345,0.000
7.96,16.400,-0.02006,1.351,0.000
8.00,16.500,-0.01981,1.358,0.000
8.01,16.600,-0.01960,1.359,0.000
8.05,16.700,-0.01940,1.366,0.000
8.07,16.800,-0.01923,1.370,0.000
8.08,16.900,-0.01902,1.371,0.000
8.10,17.000,-0.01881,1.374,0.000
8.10,17.100,-0.01865,1.375,0.000
8.12,17.200,-0.01848,1.377,0.000
8.12,17.300,-0.01832,1.378,0.000
8.13,17.400,-0.01815,1.379,0.000
8.14,17.500,-0.01798,1.381,0.000
8.15,17.600,-0.01786,1.382,0.000
8.15,17.700,-0.01769,1.383,0.000
8.15,17.800,-0.01753,1.383,0.000
8.16,17.900,-0.01740,1.385,0.000
8.16,18.000,-0.01724,1.384,0.000
8.18,18.100,-0.01711,1.388,0.000
8.17,18.200,-0.01699,1.386,0.000
8.18,18.300,-0.01682,1.389,0.000
8.18,18.400,-0.01670,1.389,0.000
8.20,18.500,-0.01657,1.392,0.000
8.20,18.600,-0.01640,1.392,0.000
8.21,18.700,-0.01628,1.394,0.000
8.21,18.800,-0.01611,1.394,0.000
8.23,18.900,-0.01599,1.396,0.000
8.21,19.000,-0.01582,1.394,0.000
8.22,19.100,-0.01570,1.395,0.000
8.23,19.200,-0.01553,1.396,0.000
8.24,19.300,-0.01541,1.398,0.000
8.23,19.400,-0.01524,1.396,0.000
8.23,19.500,-0.01507,1.397,0.000
8.22,19.600,-0.01495,1.395,0.000
8.22,19.700,-0.01478,1.395,0.000
8.24,19.800,-0.01462,1.398,0.000
8.24,19.900,-0.01445,1.399,0.000
8.24,20.000,-0.01433,1.399,0.000
8.26,20.100,-0.01416,1.402,0.000
8.26,20.200,-0.01399,1.401,0.000
8.25,20.300,-0.01387,1.399,0.000
8.26,20.400,-0.01370,1.401,0.000
8.27,20.500,-0.01354,1.404,0.000
8.28,20.600,-0.01337,1.405,0.000
8.29,20.700,-0.01320,1.407,0.000
8.29,20.800,-0.01304,1.407,0.000
8.30,20.900,-0.01287,1.408,0.000
8.33,21.000,-0.01271,1.413,0.000
8.34,21.100,-0.01250,1.415,0.000
8.39,21.200,-0.01233,1.423,0.000
8.40,21.300,-0.01212,1.424,0.000
8.43,21.400,-0.01192,1.430,0.000
8.46,21.500,-0.01171,1.435,0.000
8.50,21.600,-0.01150,1.442,0.000
8.52,21.700,-0.01129,1.446,0.000
8.55,21.800,-0.01109,1.451,0.000
8.58,21.900,-0.01088,1.456,0.000
8.61,22.000,-0.01067,1.461,0.000
8.63,22.100,-0.01046,1.463,0.000
8.66,22.200,-0.01025,1.470,0.000
8.67,22.300,-0.01005,1.472,0.000
8.71,22.400,-0.00984,1.478,0.000
8.74,22.500,-0.00967,1.482,0.000
8.77,22.600,-0.00946,1.488,0.000
8.79,22.700,-0.00930,1.491,0.000
8.82,22.800,-0.00909,1.496,0.000
8.83,22.900,-0.00892,1.498,0.000
8.85,23.000,-0.00880,1.502,0.000
8.87,23.100,-0.00863,1.504,0.000
8.90,23.200,-0.00847,1.511,0.000
8.90,23.300,-0.00830,1.510,0.000
8.92,23.400,-0.00818,1.514,0.000
8.93,23.500,-0.00801,1.515,0.000
8.95,23.600,-0.00789,1.519,0.000
8.96,23.700,-0.00772,1.520,0.000
8.98,23.800,-0.00759,1.524,0.000
8.99,23.900,-0.00747,1.525,0.000
9.00,24.000,-0.00730,1.526,0.000
9.01,24.100,-0.00718,1.528,0.000
9.02,24.200,-0.00705,1.530,0.000
9.03,24.300,-0.00689,1.533,0.000
9.06,24.400,-0.00676,1.536,0.000
9.06,24.500,-0.00664,1.537,0.000
9.06,24.600,-0.00651,1.537,0.000
9.10,24.700,-0.00635,1.544,0.000
9.10,24.800,-0.00622,1.544,0.000
9.13,24.900,-0.00606,1.549,0.000
9.13,25.000,-0.00593,1.549,0.000
9.15,25.100,-0.00577,1.552,0.000
9.17,25.200,-0.00564,1.555,0.000
9.19,25.300,-0.00548,1.559,0.000
9.22,25.400,-0.00531,1.564,0.000
9.25,25.500,-0.00518,1.569,0.000
9.28,25.600,-0.00502,1.574,0.000
9.31,25.700,-0.00485,1.579,0.000
9.34,25.800,-0.00473,1.584,0.000
9.38,25.900,-0.00456,1.591,0.000
9.40,26.000,-0.00440,1.594,0.000
9.44,26.100,-0.00427,1.602,0.000
9.46,26.200,-0.00410,1.606,0.000
9.51,26.300,-0.00394,1.613,0.000
9.55,26.400,-0.00377,1.620,0.000
9.59,26.500,-0.00361,1.628,0.000
9.62,26.600,-0.00344,1.633,0.000
9.68,26.700,-0.00327,1.643,0.000
9.71,26.800,-0.00311,1.648,0.000
9.75,26.900,-0.00290,1.654,0.000
9.82,27.000,-0.00269,1.666,0.000
9.89,27.100,-0.00248,1.678,0.000
9.92,27.200,-0.00232,1.683,0.000
9.98,27.300,-0.00211,1.694,0.000
10.03,27.400,-0.00186,1.703,0.000
10.10,27.500,-0.00165,1.714,0.000
10.16,27.600,-0.00144,1.724,0.000
10.22,27.700,-0.00124,1.734,0.000
10.27,27.800,-0.00103,1.742,0.000
10.34,27.900,-0.00082,1.754,0.000
10.37,28.000,-0.00061,1.760,0.000
10.44,28.100,-0.00041,1.772,0.000
10.48,28.200,-0.00020,1.778,0.000
10.54,28.300,0.00001,1.789,0.000
10.56,28.400,0.00018,1.791,0.000
10.61,28.500,0.00034,1.801,0.000
10.64,28.600,0.00051,1.805,0.000
10.69,28.700,0.00067,1.813,0.000
10.72,28.800,0.00084,1.820,0.000
10.78,28.900,0.00101,1.829,0.000
10.81,29.000,0.00113,1.834,0.000
10.84,29.100,0.00130,1.840,0.000
10.88,29.200,0.00142,1.845,0.000
10.92,29.300,0.00159,1.853,0.000
10.95,29.400,0.00171,1.859,0.000
10.99,29.500,0.00188,1.865,0.000
11.01,29.600,0.00200,1.867,0.000
11.06,29.700,0.00213,1.877,0.000
11.09,29.800,0.00225,1.881,0.000
11.14,29.900,0.00242,1.891,0.000
11.16,30.000,0.00254,1.894,0.000
11.21,30.100,0.00267,1.902,0.000
11.23,30.200,0.00284,1.905,0.000
11.25,30.300,0.00296,1.910,0.000
11.32,30.400,0.00309,1.920,0.000
11.34,30.500,0.00325,1.925,0.000
11.38,30.600,0.00342,1.930,0.000
11.42,30.700,0.00354,1.937,0.000
11.46,30.800,0.00371,1.945,0.000
11.51,30.900,0.00383,1.953,0.000
11.55,31.000,0.00400,1.960,0.000
11.59,31.100,0.00417,1.966,0.000
11.63,31.200,0.00433,1.973,0.000
11.66,31.300,0.00446,1.979,0.000
11.68,31.400,0.00462,1.982,0.000
11.74,31.500,0.00479,1.991,0.000
11.77,31.600,0.00491,1.996,0.000
11.80,31.700,0.00508,2.003,0.000
11.84,31.800,0.00525,2.009,0.000
11.88,31.900,0.00541,2.016,0.000
11.94,32.000,0.00558,2.025,0.000
11.97,32.100,0.00574,2.031,0.000
12.00,32.200,0.00591,2.036,0.000
12.04,32.300,0.00608,2.043,0.000
12.09,32.400,0.00624,2.051,0.000
12.11,32.500,0.00641,2.055,0.000
12.18,32.600,0.00658,2.066,0.000
12.22,32.700,0.00678,2.073,0.000
12.28,32.800,0.00699,2.083,0.000
12.31,32.900,0.00716,2.089,0.000
12.38,33.000,0.00737,2.100,0.000
12.41,33.100,0.00757,2.105,0.000
12.47,33.200,0.00778,2.116,0.000
12.52,33.300,0.00799,2.124,0.000
12.56,33.400,0.00820,2.131,0.000
12.60,33.500,0.00840,2.138,0.000
12.65,33.600,0.00861,2.146,0.000
12.69,33.700,0.00882,2.154,0.000
12.75,33.800,0.00903,2.163,0.000
12.80,33.900,0.00924,2.172,0.000
12.84,34.000,0.00940,2.178,0.000
12.87,34.100,0.00961,2.184,0.000
12.94,34.200,0.00978,2.196,0.000
12.95,34.300,0.00994,2.197,0.000
13.00,34.400,0.01011,2.206,0.000
13.03,34.500,0.01027,2.211,0.000
13.08,34.600,0.01044,2.219,0.000
13.11,34.700,0.01061,2.224,0.000
13.15,34.800,0.01073,2.231,0.000
13.16,34.900,0.01090,2.233,0.000
13.22,35.000,0.01102,2.242,0.000
13.24,35.100,0.01119,2.247,0.000
13.28,35.200,0.01131,2.254,0.000
13.31,35.300,0.01144,2.257,0.000
13.34,35.400,0.01156,2.263,0.000
13.39,35.500,0.01173,2.271,0.000
13.41,35.600,0.01185,2.276,0.000
13.45,35.700,0.01198,2.282,0.000
13.50,35.800,0.01210,2.290,0.000
13.53,35.900,0.01227,2.296,0.000
13.58,36.000,0.01239,2.304,0.000
13.62,36.100,0.01252,2.310,0.000
13.66,36.200,0.01268,2.318,0.000
13.70,36.300,0.01281,2.324,0.000
13.75,36.400,0.01298,2.333,0.000
13.78,36.500,0.01310,2.339,0.000
13.85,36.600,0.01327,2.349,0.000
13.89,36.700,0.01343,2.357,0.000
13.95,36.800,0.01356,2.366,0.000
13.98,36.900,0.01372,2.371,0.000
14.03,37.000,0.01389,2.381,0.000
14.09,37.100,0.01401,2.391,0.000
14.13,37.200,0.01418,2.397,0.000
14.17,37.300,0.01435,2.404,0.000
14.22,37.400,0.01447,2.413,0.000
14.27,37.500,0.01464,2.422,0.000
14.32,37.600,0.01480,2.429,0.000
14.37,37.700,0.01493,2.437,0.000
14.43,37.800,0.01509,2.449,0.000
14.48,37.900,0.01526,2.457,0.000
14.53,38.000,0.01543,2.466,0.000
14.58,38.100,0.01563,2.474,0.000
14.63,38.200,0.01580,2.482,0.000
14.71,38.300,0.01597,2.496,0.000
14.77,38.400,0.01618,2.507,0.000
14.84,38.500,0.01634,2.518,0.000
14.92,38.600,0.01655,2.531,0.000
15.01,38.700,0.01676,2.546,0.000
15.08,38.800,0.01696,2.559,0.000
15.16,38.900,0.01717,2.571,0.000
15.24,39.000,0.01738,2.586,0.000
15.31,39.100,0.01759,2.598,0.000
15.38,39.200,0.01780,2.609,0.000
15.46,39.300,0.01800,2.623,0.000
15.53,39.400,0.01821,2.634,0.000
15.59,39.500,0.01842,2.645,0.000
15.67,39.600,0.01859,2.658,0.000
15.73,39.700,0.01879,2.670,0.000
15.79,39.800,0.01896,2.678,0.000
15.84,39.900,0.01917,2.688,0.000
15.89,40.000,0.01933,2.696,0.000
15.95,40.100,0.01950,2.706,0.000
16.02,40.200,0.01967,2.718,0.000
16.06,40.300,0.01979,2.725,0.000
16.10,40.400,0.01996,2.732,0.000
16.15,40.500,0.02008,2.741,0.000
16.20,40.600,0.02025,2.749,0.000
16.24,40.700,0.02041,2.756,0.000
16.27,40.800,0.02054,2.761,0.000
16.34,40.900,0.02066,2.773,0.000
16.38,41.000,0.02083,2.779,0.000
16.44,41.100,0.02095,2.790,0.000
16.46,41.200,0.02108,2.794,0.000
16.53,41.300,0.02120,2.804,0.000
16.56,41.400,0.02137,2.810,0.000
16.61,41.500,0.02149,2.819,0.000
16.66,41.600,0.02162,2.827,0.000
16.72,41.700,0.02179,2.838,0.000
16.78,41.800,0.02191,2.846,0.000
16.82,41.900,0.02203,2.854,0.000
16.87,42.000,0.02220,2.862,0.000
16.93,42.100,0.02233,2.873,0.000
16.99,42.200,0.02249,2.883,0.000
17.03,42.300,0.02262,2.889,0.000
17.08,42.400,0.02278,2.899,0.000
17.14,42.500,0.02295,2.908,0.000
17.19,42.600,0.02307,2.916,0.000
17.26,42.700,0.02324,2.929,0.000
17.31,42.800,0.02341,2.937,0.000
17.35,42.900,0.02353,2.944,0.000
17.43,43.000,0.02370,2.957,0.000
17.47,43.100,0.02386,2.964,0.000
17.53,43.200,0.02403,2.975,0.000
17.60,43.300,0.02415,2.986,0.000
17.66,43.400,0.02432,2.997,0.000
17.72,43.500,0.02449,3.007,0.000
17.78,43.600,0.02465,3.017,0.000
17.85,43.700,0.02482,3.028,0.000
17.90,43.800,0.02498,3.037,0.000
17.95,43.900,0.02519,3.046,0.000
18.08,44.000,0.02536,3.067,0.000
18.13,44.100,0.02557,3.077,0.001
18.22,44.200,0.02577,3.091,0.001
18.30,44.300,0.02598,3.105,0.001
18.39,44.400,0.02619,3.121,0.001
18.47,44.500,0.02644,3.133,0.001
18.58,44.600,0.02665,3.152,0.001
18.66,44.700,0.02685,3.166,0.001
18.76,44.800,0.02710,3.183,0.001
18.83,44.900,0.02731,3.195,0.001
18.93,45.000,0.02752,3.211,0.001
18.99,45.100,0.02773,3.222,0.001
19.07,45.200,0.02794,3.236,0.001
19.16,45.300,0.02814,3.251,0.001
19.23,45.400,0.02831,3.263,0.001
19.30,45.500,0.02852,3.274,0.001
19.35,45.600,0.02868,3.284,0.001
19.41,45.700,0.02885,3.294,0.001
19.49,45.800,0.02902,3.307,0.001
19.54,45.900,0.02918,3.315,0.001
19.59,46.000,0.02931,3.324,0.001
19.63,46.100,0.02947,3.331,0.001
19.71,46.200,0.02960,3.343,0.001
19.73,46.300,0.02976,3.348,0.001
19.81,46.400,0.02989,3.361,0.001
19.87,46.500,0.03005,3.371,0.001
19.91,46.600,0.03018,3.378,0.001
19.95,46.700,0.03030,3.384,0.001
20.01,46.800,0.03043,3.395,0.001
20.06,46.900,0.03060,3.403,0.001
20.11,47.000,0.03072,3.413,0.001
20.15,47.100,0.03084,3.419,0.001
20.21,47.200,0.03101,3.430,0.001
20.26,47.300,0.03114,3.438,0.001
20.33,47.400,0.03126,3.450,0.001
20.38,47.500,0.03143,3.458,0.001
20.43,47.600,0.03155,3.467,0.001
20.49,47.700,0.03172,3.476,0.001
20.56,47.800,0.03184,3.488,0.001
20.62,47.900,0.03201,3.499,0.001
20.68,48.000,0.03217,3.508,0.001
20.75,48.100,0.03230,3.521,0.001
20.79,48.200,0.03247,3.528,0.001
20.87,48.300,0.03263,3.541,0.001
20.93,48.400,0.03276,3.552,0.001
20.99,48.500,0.03292,3.561,0.001
21.04,48.600,0.03309,3.570,0.001
21.14,48.700,0.03325,3.586,0.001
21.18,48.800,0.03342,3.593,0.001
21.25,48.900,0.03359,3.605,0.001
21.31,49.000,0.03371,3.616,0.001
21.38,49.100,0.03388,3.628,0.001
21.45,49.200,0.03404,3.639,0.001
21.54,49.300,0.03421,3.654,0.001
21.59,49.400,0.03442,3.663,0.001
21.68,49.500,0.03458,3.678,0.001
21.76,49.600,0.03479,3.692,0.001
21.85,49.700,0.03496,3.707,0.001
21.92,49.800,0.03517,3.719,0.001
22.02,49.900,0.03537,3.737,0.001
22.10,50.000,0.03562,3.750,0.001
22.22,50.100,0.03583,3.770,0.001
22.29,50.200,0.03604,3.783,0.001
22.39,50.300,0.03629,3.798,0.001
22.47,50.400,0.03650,3.812,0.001
22.55,50.500,0.03670,3.827,0.001
22.63,50.600,0.03691,3.839,0.001
22.73,50.700,0.03712,3.856,0.001
22.78,50.800,0.03733,3.866,0.001
22.87,50.900,0.03753,3.880,0.001
22.92,51.000,0.03770,3.889,0.001
23.03,51.100,0.03791,3.907,0.001
23.09,51.200,0.03808,3.917,0.001
23.16,51.300,0.03824,3.929,0.001
23.19,51.400,0.03841,3.935,0.001
23.29,51.500,0.03857,3.952,0.001
23.34,51.600,0.03874,3.960,0.001
23.42,51.700,0.03891,3.974,0.001
23.49,51.800,0.03907,3.986,0.001
23.54,51.900,0.03920,3.995,0.001
23.59,52.000,0.03936,4.002,0.001
23.65,52.100,0.03949,4.013,0.001
23.73,52.200,0.03965,4.026,0.001
23.78,52.300,0.03978,4.035,0.001
23.84,52.400,0.03990,4.045,0.001
23.90,52.500,0.04007,4.055,0.001
23.97,52.600,0.04019,4.067,0.001
24.04,52.700,0.04032,4.080,0.001
24.11,52.800,0.04049,4.090,0.001
24.17,52.900,0.04061,4.101,0.001
24.24,53.000,0.04078,4.112,0.001
24.32,53.100,0.04090,4.126,0.001
24.38,53.200,0.04107,4.137,0.001
24.43,53.300,0.04119,4.146,0.001
24.53,53.400,0.04136,4.162,0.001
24.62,53.500,0.04152,4.177,0.001
24.68,53.600,0.04165,4.188,0.001
24.76,53.700,0.04182,4.201,0.001
24.85,53.800,0.04198,4.215,0.001
24.91,53.900,0.04215,4.227,0.001
25.00,54.000,0.04227,4.242,0.001
25.06,54.100,0.04244,4.252,0.001
25.14,54.200,0.04260,4.266,0.001
25.21,54.300,0.04277,4.278,0.001
25.32,54.400,0.04294,4.295,0.001
25.38,54.500,0.04310,4.306,0.001
25.46,54.600,0.04327,4.319,0.001
25.53,54.700,0.04344,4.332,0.001
25.63,54.800,0.04360,4.348,0.001
25.70,54.900,0.04377,4.361,0.001
25.80,55.000,0.04393,4.378,0.001
25.86,55.100,0.04410,4.388,0.001
25.97,55.200,0.04431,4.406,0.001
26.08,55.300,0.04447,4.424,0.001
26.17,55.400,0.04468,4.440,0.001
26.25,55.500,0.04489,4.454,0.001
26.35,55.600,0.04510,4.471,0.001
26.46,55.700,0.04531,4.490,0.001
26.56,55.800,0.04551,4.507,0.001
26.66,55.900,0.04572,4.524,0.001
26.77,56.000,0.04593,4.542,0.001
26.85,56.100,0.04614,4.556,0.001
26.97,56.200,0.04634,4.576,0.001
27.05,56.300,0.04655,4.590,0.001
27.16,56.400,0.04676,4.608,0.001
27.25,56.500,0.04693,4.623,0.001
27.35,56.600,0.04713,4.640,0.001
27.44,56.700,0.04730,4.656,0.001
27.52,56.800,0.04751,4.669,0.001
27.62,56.900,0.04767,4.687,0.001
27.67,57.000,0.04784,4.695,0.001
27.76,57.100,0.04801,4.710,0.001
27.83,57.200,0.04817,4.721,0.001
27.90,57.300,0.04830,4.734,0.001
27.97,57.400,0.04846,4.746,0.001
28.05,57.500,0.04863,4.759,0.001
28.11,57.600,0.04875,4.770,0.001
28.19,57.700,0.04892,4.782,0.001
28.25,57.800,0.04905,4.794,0.001
28.33,57.900,0.04921,4.807,0.001
28.38,58.000,0.04934,4.815,0.001
28.45,58.100,0.04946,4.828,0.001
28.53,58.200,0.04963,4.841,0.001
28.60,58.300,0.04975,4.853,0.001
28.67,58.400,0.04992,4.864,0.001
28.74,58.500,0.05004,4.877,0.001
28.82,58.600,0.05017,4.890,0.001
28.87,58.700,0.05033,4.899,0.001
28.95,58.800,0.05046,4.913,0.001
29.03,58.900,0.05062,4.925,0.001
29.10,59.000,0.05075,4.938,0.001
29.19,59.100,0.05092,4.953,0.001
29.28,59.200,0.05108,4.967,0.001
29.35,59.300,0.05121,4.979,0.001
29.41,59.400,0.05137,4.990,0.001
29.47,59.500,0.05150,5.001,0.001
29.55,59.600,0.05166,5.013,0.001
29.63,59.700,0.05183,5.028,0.001
29.73,59.800,0.05195,5.044,0.001
29.80,59.900,0.05212,5.057,0.001
29.87,60.000,0.05229,5.068,0.001
29.94,60.100,0.05241,5.081,0.001
30.03,60.200,0.05258,5.095,0.001
30.11,60.300,0.05274,5.109,0.001
30.20,60.400,0.05291,5.124,0.001
30.29,60.500,0.05308,5.139,0.001
30.37,60.600,0.05324,5.153,0.001
30.46,60.700,0.05341,5.169,0.001
30.56,60.800,0.05362,5.185,0.001
30.68,60.900,0.05378,5.205,0.001
30.78,61.000,0.05399,5.222,0.001
30.89,61.100,0.05420,5.241,0.001
31.00,61.200,0.05441,5.259,0.001
31.12,61.300,0.05461,5.280,0.001
31.23,61.400,0.05482,5.299,0.001
31.35,61.500,0.05503,5.318,0.001
31.46,61.600,0.05524,5.338,0.001
31.57,61.700,0.05545,5.357,0.001
31.69,61.800,0.05565,5.377,0.001
31.77,61.900,0.05586,5.391,0.001
31.91,62.000,0.05607,5.414,0.001
32.00,62.100,0.05628,5.430,0.001
32.12,62.200,0.05648,5.450,0.001
32.22,62.300,0.05665,5.466,0.001
32.31,62.400,0.05686,5.483,0.001
32.41,62.500,0.05702,5.499,0.001
32.51,62.600,0.05719,5.515,0.001
32.58,62.700,0.05736,5.527,0.001
32.67,62.800,0.05752,5.544,0.001
32.76,62.900,0.05769,5.558,0.001
32.85,63.000,0.05786,5.574,0.001
32.91,63.100,0.05798,5.584,0.001
33.01,63.200,0.05815,5.600,0.001
33.07,63.300,0.05827,5.611,0.001
33.14,63.400,0.05844,5.623,0.001
33.21,63.500,0.05856,5.635,0.001
33.28,63.600,0.05869,5.647,0.001
33.35,63.700,0.05885,5.659,0.001
33.44,63.800,0.05898,5.673,0.001
33.50,63.900,0.05910,5.685,0.001
33.58,64.000,0.05923,5.697,0.001
33.66,64.100,0.05939,5.711,0.001
33.73,64.200,0.05952,5.723,0.001
33.80,64.300,0.05968,5.735,0.001
33.89,64.400,0.05981,5.750,0.001
33.96,64.500,0.05997,5.762,0.001
34.04,64.600,0.06010,5.776,0.001
34.13,64.700,0.06027,5.792,0.001
34.23,64.800,0.06039,5.808,0.001
34.30,64.900,0.06056,5.820,0.001
34.39,65.000,0.06072,5.834,0.001
34.47,65.100,0.06085,5.848,0.001
34.54,65.200,0.06101,5.861,0.001
34.62,65.300,0.06118,5.874,0.001
34.70,65.400,0.06135,5.887,0.001
34.79,65.500,0.06147,5.903,0.001
34.89,65.600,0.06164,5.919,0.001
34.97,65.700,0.06180,5.933,0.001
35.07,65.800,0.06197,5.950,0.001
35.15,65.900,0.06214,5.964,0.001
35.24,66.000,0.06230,5.980,0.001
35.33,66.100,0.06247,5.994,0.001
35.41,66.200,0.06263,6.008,0.001
35.52,66.300,0.06280,6.027,0.001
35.59,66.400,0.06297,6.039,0.001
35.72,66.500,0.06317,6.061,0.001
35.82,66.600,0.06334,6.078,0.001
35.95,66.700,0.06355,6.100,0.001
36.06,66.800,0.06376,6.118,0.001
36.18,66.900,0.06392,6.139,0.001
36.29,67.000,0.06417,6.157,0.001
36.42,67.100,0.06438,6.179,0.001
36.55,67.200,0.06459,6.201,0.001
36.66,67.300,0.06480,6.221,0.001
36.78,67.400,0.06500,6.241,0.001
36.92,67.500,0.06521,6.264,0.001
37.01,67.600,0.06542,6.280,0.001
37.14,67.700,0.06563,6.301,0.001
37.24,67.800,0.06583,6.318,0.001
37.37,67.900,0.06604,6.340,0.001
37.44,68.000,0.06621,6.353,0.001
37.56,68.100,0.06637,6.372,0.001
37.63,68.200,0.06658,6.384,0.001
37.73,68.300,0.06675,6.402,0.001
37.82,68.400,0.06691,6.417,0.001
37.92,68.500,0.06704,6.433,0.001
37.98,68.600,0.06721,6.444,0.001
38.08,68.700,0.06737,6.461,0.001
38.15,68.800,0.06750,6.472,0.001
38.25,68.900,0.06766,6.490,0.001
38.30,69.000,0.06779,6.499,0.001
38.40,69.100,0.06795,6.515,0.001
38.46,69.200,0.06808,6.525,0.001
38.54,69.300,0.06820,6.539,0.001
38.58,69.400,0.06833,6.547,0.001
38.67,69.500,0.06849,6.562,0.001
38.74,69.600,0.06862,6.573,0.001
38.83,69.700,0.06874,6.588,0.001
38.90,69.800,0.06891,6.600,0.001
38.98,69.900,0.06903,6.614,0.001
39.07,70.000,0.06920,6.628,0.001
39.15,70.100,0.06933,6.642,0.001
39.23,70.200,0.06949,6.656,0.001
39.31,70.300,0.06962,6.670,0.001
39.40,70.400,0.06978,6.686,0.001
39.49,70.500,0.06991,6.701,0.001
39.59,70.600,0.07007,6.717,0.001
39.67,70.700,0.07024,6.731,0.001
39.75,70.800,0.07036,6.745,0.001
39.85,70.900,0.07053,6.761,0.001
39.93,71.000,0.07070,6.775,0.001
40.01,71.100,0.07082,6.788,0.001
40.11,71.200,0.07099,6.805,0.001
40.19,71.300,0.07115,6.819,0.001
40.28,71.400,0.07128,6.835,0.001
40.36,71.500,0.07144,6.847,0.001
40.47,71.600,0.07161,6.866,0.001
40.55,71.700,0.07178,6.880,0.001
40.66,71.800,0.07194,6.898,0.001
40.74,71.900,0.07211,6.913,0.001
40.86,72.000,0.07228,6.933,0.001
40.94,72.100,0.07244,6.946,0.001
41.07,72.200,0.07265,6.967,0.001
41.16,72.300,0.07282,6.983,0.001
41.31,72.400,0.07302,7.009,0.001
41.41,72.500,0.07319,7.026,0.001
41.54,72.600,0.07340,7.047,0.001
41.66,72.700,0.07361,7.068,0.001
41.80,72.800,0.07381,7.092,0.001
41.92,72.900,0.07402,7.112,0.001
42.06,73.000,0.07427,7.136,0.001
42.17,73.100,0.07448,7.155,0.001
42.30,73.200,0.07469,7.176,0.001
42.41,73.300,0.07485,7.195,0.001
42.52,73.400,0.07506,7.214,0.001
42.62,73.500,0.07527,7.232,0.001
42.74,73.600,0.07548,7.252,0.001
42.83,73.700,0.07564,7.267,0.001
42.93,73.800,0.07581,7.284,0.001
43.01,73.900,0.07602,7.297,0.001
42.00,74.000,0.07618,7.126,0.001
29.15,74.100,0.07631,4.946,0.002
29.34,74.200,0.07647,4.977,0.002
29.53,74.300,0.07664,5.011,0.002
29.66,74.400,0.07676,5.033,0.002
29.80,74.500,0.07693,5.057,0.002
29.94,74.600,0.07710,5.080,0.002
30.07,74.700,0.07722,5.102,0.002
30.18,74.800,0.07735,5.120,0.002
30.28,74.900,0.07751,5.138,0.002
30.39,75.000,0.07764,5.156,0.002
30.48,75.100,0.07776,5.172,0.002
30.59,75.200,0.07793,5.190,0.002
30.68,75.300,0.07805,5.205,0.002
30.76,75.400,0.07818,5.220,0.002
30.90,75.500,0.07830,5.242,0.002
30.97,75.600,0.07847,5.255,0.002
31.08,75.700,0.07859,5.273,0.002
31.17,75.800,0.07876,5.289,0.002
31.28,75.900,0.07888,5.306,0.002
31.34,76.000,0.07905,5.318,0.002
31.46,76.100,0.07917,5.338,0.002
31.53,76.200,0.07930,5.349,0.002
31.64,76.300,0.07946,5.369,0.002
31.73,76.400,0.07959,5.384,0.002
31.82,76.500,0.07976,5.399,0.002
31.90,76.600,0.07988,5.413,0.002
32.03,76.700,0.08005,5.434,0.002
32.09,76.800,0.08021,5.444,0.002
32.21,76.900,0.08034,5.465,0.002
32.28,77.000,0.08050,5.478,0.002
32.39,77.100,0.08067,5.495,0.002
32.47,77.200,0.08079,5.509,0.002
32.59,77.300,0.08096,5.529,0.002
32.66,77.400,0.08113,5.542,0.002
32.77,77.500,0.08129,5.560,0.002
32.85,77.600,0.08146,5.574,0.002
32.98,77.700,0.08163,5.596,0.002
33.05,77.800,0.08179,5.608,0.002
33.20,77.900,0.08196,5.633,0.002
33.29,78.000,0.08217,5.649,0.002
33.43,78.100,0.08237,5.672,0.002
33.54,78.200,0.08254,5.690,0.002
33.66,78.300,0.08279,5.711,0.002
33.78,78.400,0.08300,5.732,0.002
33.92,78.500,0.08320,5.755,0.002
34.03,78.600,0.08341,5.773,0.002
34.17,78.700,0.08362,5.797,0.002
34.29,78.800,0.08383,5.817,0.002
34.41,78.900,0.08404,5.838,0.002
34.51,79.000,0.08424,5.856,0.002
34.65,79.100,0.08445,5.879,0.002
34.74,79.200,0.08466,5.895,0.002
34.86,79.300,0.08487,5.915,0.002
34.96,79.400,0.08503,5.931,0.002
35.06,79.500,0.08524,5.948,0.002
35.16,79.600,0.08541,5.965,0.002
35.23,79.700,0.08557,5.978,0.002
35.32,79.800,0.08574,5.993,0.002
35.41,79.900,0.08591,6.008,0.002
35.49,80.000,0.08607,6.022,0.002
35.58,80.100,0.08624,6.037,0.002
35.67,80.200,0.08636,6.051,0.002
35.74,80.300,0.08653,6.065,0.002
35.81,80.400,0.08665,6.075,0.002
35.88,80.500,0.08678,6.087,0.002
35.97,80.600,0.08694,6.102,0.002
36.03,80.700,0.08707,6.113,0.002
36.11,80.800,0.08719,6.126,0.002
36.17,80.900,0.08732,6.136,0.002
36.25,81.000,0.08748,6.150,0.002
36.32,81.100,0.08761,6.162,0.002
36.40,81.200,0.08773,6.177,0.002
36.47,81.300,0.08790,6.188,0.002
36.57,81.400,0.08803,6.204,0.002
36.63,81.500,0.08819,6.215,0.002
36.71,81.600,0.08832,6.229,0.002
36.78,81.700,0.08844,6.241,0.002
36.88,81.800,0.08861,6.258,0.002
36.96,81.900,0.08877,6.270,0.002
37.05,82.000,0.08890,6.286,0.002
37.13,82.100,0.08906,6.299,0.002
37.23,82.200,0.08923,6.317,0.002
37.29,82.300,0.08935,6.327,0.002
37.40,82.400,0.08952,6.346,0.002
37.47,82.500,0.08969,6.357,0.002
37.57,82.600,0.08985,6.375,0.002
37.64,82.700,0.08998,6.387,0.002
37.74,82.800,0.09014,6.403,0.002
37.81,82.900,0.09031,6.414,0.002
37.93,83.000,0.09048,6.435,0.002
38.00,83.100,0.09064,6.447,0.002
38.10,83.200,0.09081,6.465,0.002
38.19,83.300,0.09098,6.480,0.002
38.30,83.400,0.09114,6.498,0.002
38.37,83.500,0.09135,6.511,0.002
38.51,83.600,0.09152,6.533,0.002
38.61,83.700,0.09172,6.551,0.002
38.72,83.800,0.09193,6.569,0.002
38.83,83.900,0.09214,6.588,0.002
38.97,84.000,0.09231,6.612,0.002
39.04,84.100,0.09255,6.624,0.002
39.20,84.200,0.09276,6.650,0.002
39.30,84.300,0.09297,6.667,0.002
39.42,84.400,0.09318,6.688,0.002
34.06,84.500,0.09339,5.779,0.002
18.61,84.600,0.09359,3.158,0.002
18.32,84.700,0.09380,3.109,0.002
18.50,84.800,0.09401,3.139,0.002
18.62,84.900,0.09422,3.159,0.002
18.76,85.000,0.09442,3.183,0.002
18.89,85.100,0.09459,3.205,0.002
19.03,85.200,0.09480,3.229,0.002
19.16,85.300,0.09497,3.250,0.002
19.27,85.400,0.09513,3.269,0.002
19.36,85.500,0.09530,3.285,0.002
19.45,85.600,0.09546,3.300,0.002
19.56,85.700,0.09563,3.318,0.002
19.65,85.800,0.09580,3.334,0.002
19.72,85.900,0.09592,3.346,0.002
19.81,86.000,0.09609,3.361,0.002
19.89,86.100,0.09621,3.375,0.002
19.96,86.200,0.09638,3.387,0.002
20.05,86.300,0.09650,3.401,0.002
20.12,86.400,0.09663,3.414,0.002
20.19,86.500,0.09679,3.425,0.002
20.25,86.600,0.09692,3.437,0.002
20.35,86.700,0.09704,3.452,0.002
20.41,86.800,0.09721,3.462,0.002
20.48,86.900,0.09733,3.475,0.002
20.55,87.000,0.09750,3.486,0.002
20.62,87.100,0.09762,3.499,0.002
20.70,87.200,0.09779,3.512,0.002
20.78,87.300,0.09792,3.525,0.002
20.85,87.400,0.09808,3.537,0.002
20.95,87.500,0.09825,3.554,0.002
21.00,87.600,0.09837,3.563,0.002
21.07,87.700,0.09854,3.575,0.002
21.15,87.800,0.09871,3.588,0.002
21.22,87.900,0.09887,3.601,0.002
21.30,88.000,0.09900,3.614,0.002
21.38,88.100,0.09916,3.628,0.002
21.46,88.200,0.09933,3.641,0.002
21.52,88.300,0.09949,3.651,0.002
21.58,88.400,0.09962,3.662,0.002
21.67,88.500,0.09979,3.677,0.002
21.73,88.600,0.09995,3.686,0.002
21.82,88.700,0.10012,3.702,0.002
21.88,88.800,0.10028,3.713,0.002
21.96,88.900,0.10045,3.726,0.002
21.96,88.900,0.10045,3.726,0.002