File: data-files/CWRU/0800-10-24B.txt
""
"Test Method","Will_Huddleston_Disks.msm"
"Sample I. D.","800-10-24B.mss"
"Specimen Number","1"

"Load (N)","Time (s)","Extension (mm)","Stress (MPa)","Strain (mm/mm)"

3.17,0.200,-0.07456,0.388,-0.001
3.17,0.300,-0.07456,0.388,-0.001
3.17,0.400,-0.07456,0.388,-0.001
3.17,0.500,-0.07456,0.387,-0.001
3.17,0.600,-0.07452,0.388,-0.001
3.18,0.700,-0.07452,0.389,-0.001
3.17,0.800,-0.07452,0.387,-0.001
3.18,0.900,-0.07452,0.389,-0.001
3.17,1.000,-0.07448,0.388,-0.001
3.17,1.100,-0.07448,0.388,-0.001
3.19,1.200,-0.07448,0.390,-0.001
3.17,1.300,-0.07448,0.388,-0.001
3.18,1.400,-0.07443,0.389,-0.001
3.18,1.500,-0.07443,0.389,-0.001
3.17,1.600,-0.07443,0.388,-0.001
3.17,1.700,-0.07439,0.388,-0.001
3.18,1.800,-0.07439,0.389,-0.001
3.18,1.900,-0.07435,0.389,-0.001
3.16,2.000,-0.07435,0.387,-0.001
3.19,2.100,-0.07431,0.391,-0.001
3.21,2.200,-0.07427,0.393,-0.001
3.27,2.300,-0.07419,0.400,-0.001
3.33,2.400,-0.07406,0.407,-0.001
3.37,2.500,-0.07389,0.412,-0.001
3.39,2.600,-0.07377,0.414,-0.001
3.42,2.700,-0.07360,0.418,-0.001
3.42,2.800,-0.07348,0.419,-0.001
3.43,2.900,-0.07331,0.419,-0.001
3.45,3.000,-0.07319,0.422,-0.001
3.45,3.100,-0.07302,0.422,-0.001
3.47,3.200,-0.07286,0.424,-0.001
3.47,3.300,-0.07273,0.425,-0.001
3.48,3.400,-0.07256,0.426,-0.001
3.48,3.500,-0.07240,0.426,-0.001
3.51,3.600,-0.07223,0.429,-0.001
3.50,3.700,-0.07207,0.428,-0.001
3.47,3.800,-0.07186,0.425,-0.001
3.51,3.900,-0.07169,0.429,-0.001
3.53,4.000,-0.07148,0.431,-0.001
3.55,4.100,-0.07128,0.434,-0.001
3.52,4.200,-0.07107,0.431,-0.001
3.55,4.300,-0.07086,0.434,-0.001
3.55,4.400,-0.07065,0.434,-0.001
3.56,4.500,-0.07040,0.435,-0.001
3.58,4.600,-0.07020,0.438,-0.001
3.58,4.700,-0.06999,0.438,-0.001
3.60,4.800,-0.06978,0.440,-0.001
3.61,4.900,-0.06957,0.441,-0.001
3.64,5.000,-0.06941,0.446,-0.001
3.66,5.100,-0.06920,0.448,-0.001
3.68,5.200,-0.06899,0.451,-0.001
3.66,5.300,-0.06882,0.448,-0.001
3.70,5.400,-0.06866,0.452,-0.001
3.71,5.500,-0.06849,0.453,-0.001
3.72,5.600,-0.06833,0.455,-0.001
3.73,5.700,-0.06816,0.456,-0.001
3.73,5.800,-0.06804,0.456,-0.001
3.74,5.900,-0.06787,0.458,-0.001
3.74,6.000,-0.06774,0.457,-0.001
3.76,6.100,-0.06758,0.460,-0.001
3.76,6.200,-0.06745,0.459,-0.001
3.75,6.300,-0.06733,0.459,-0.001
3.74,6.400,-0.06720,0.458,-0.001
3.76,6.500,-0.06704,0.460,-0.001
3.74,6.600,-0.06691,0.458,-0.001
3.77,6.700,-0.06679,0.461,-0.001
3.79,6.800,-0.06666,0.463,-0.001
3.77,6.900,-0.06650,0.462,-0.001
3.79,7.000,-0.06637,0.464,-0.001
3.79,7.100,-0.06625,0.464,-0.001
3.79,7.200,-0.06608,0.464,-0.001
3.82,7.300,-0.06596,0.467,-0.001
3.82,7.400,-0.06579,0.467,-0.001
3.83,7.500,-0.06567,0.468,-0.001
3.83,7.600,-0.06550,0.469,-0.001
3.84,7.700,-0.06538,0.469,-0.001
3.85,7.800,-0.06521,0.471,-0.001
3.85,7.900,-0.06504,0.471,-0.001
3.88,8.000,-0.06492,0.474,-0.001
3.88,8.100,-0.06475,0.474,-0.001
3.89,8.200,-0.06459,0.476,-0.001
3.90,8.300,-0.06442,0.477,-0.001
3.90,8.400,-0.06430,0.477,-0.001
3.90,8.500,-0.06413,0.477,-0.001
3.93,8.600,-0.06396,0.481,-0.001
3.91,8.700,-0.06380,0.479,-0.001
3.92,8.800,-0.06363,0.479,-0.001
3.94,8.900,-0.06346,0.482,-0.001
3.93,9.000,-0.06330,0.481,-0.001
3.96,9.100,-0.06313,0.484,-0.001
3.95,9.200,-0.06297,0.483,-0.001
3.97,9.300,-0.06276,0.485,-0.001
3.98,9.400,-0.06259,0.487,-0.001
4.00,9.500,-0.06238,0.489,-0.001
4.01,9.600,-0.06218,0.490,-0.001
4.02,9.700,-0.06197,0.491,-0.001
4.05,9.800,-0.06176,0.496,-0.001
4.07,9.900,-0.06155,0.497,-0.001
4.07,10.000,-0.06130,0.498,-0.001
4.10,10.100,-0.06110,0.502,-0.001
4.13,10.200,-0.06089,0.505,-0.001
4.13,10.300,-0.06068,0.506,-0.001
4.18,10.400,-0.06047,0.511,-0.001
4.18,10.500,-0.06026,0.511,-0.001
4.20,10.600,-0.06006,0.514,-0.001
4.22,10.700,-0.05989,0.516,-0.001
4.24,10.800,-0.05968,0.518,-0.001
4.24,10.900,-0.05952,0.519,-0.001
4.27,11.000,-0.05935,0.522,-0.001
4.29,11.100,-0.05918,0.525,-0.001
4.29,11.200,-0.05898,0.525,-0.001
4.30,11.300,-0.05885,0.526,-0.001
4.32,11.400,-0.05869,0.528,-0.001
4.33,11.500,-0.05852,0.530,-0.001
4.34,11.600,-0.05839,0.531,-0.001
4.37,11.700,-0.05823,0.534,-0.001
4.37,11.800,-0.05810,0.535,-0.001
4.38,11.900,-0.05794,0.536,-0.001
4.40,12.000,-0.05781,0.538,-0.001
4.43,12.100,-0.05769,0.542,-0.001
4.45,12.200,-0.05752,0.544,-0.001
4.48,12.300,-0.05740,0.548,-0.001
4.50,12.400,-0.05727,0.550,-0.001
4.56,12.500,-0.05715,0.558,-0.001
4.61,12.600,-0.05702,0.564,-0.001
4.65,12.700,-0.05686,0.569,-0.001
4.68,12.800,-0.05673,0.572,-0.001
4.73,12.900,-0.05661,0.578,-0.001
4.76,13.000,-0.05644,0.583,-0.001
4.81,13.100,-0.05632,0.588,-0.001
4.84,13.200,-0.05615,0.592,-0.001
4.91,13.300,-0.05603,0.601,-0.001
4.93,13.400,-0.05586,0.603,-0.001
4.97,13.500,-0.05573,0.608,-0.001
5.03,13.600,-0.05557,0.615,-0.001
5.09,13.700,-0.05540,0.622,-0.001
5.13,13.800,-0.05528,0.628,-0.001
5.18,13.900,-0.05511,0.634,-0.001
5.21,14.000,-0.05499,0.638,-0.001
5.29,14.100,-0.05482,0.647,-0.001
5.31,14.200,-0.05465,0.650,-0.001
5.36,14.300,-0.05449,0.656,-0.001
5.42,14.400,-0.05436,0.663,-0.001
5.45,14.500,-0.05420,0.667,-0.001
5.49,14.600,-0.05403,0.672,-0.001
5.56,14.700,-0.05386,0.680,-0.001
5.62,14.800,-0.05370,0.687,-0.001
5.67,14.900,-0.05353,0.694,-0.001
5.71,15.000,-0.05337,0.698,-0.001
5.75,15.100,-0.05316,0.704,-0.001
5.83,15.200,-0.05299,0.713,-0.001
5.88,15.300,-0.05278,0.720,-0.001
5.94,15.400,-0.05258,0.726,-0.001
5.99,15.500,-0.05237,0.733,-0.001
6.07,15.600,-0.05216,0.742,-0.001
6.13,15.700,-0.05191,0.749,-0.001
6.18,15.800,-0.05170,0.756,-0.001
6.26,15.900,-0.05150,0.765,-0.001
6.32,16.000,-0.05129,0.773,-0.001
6.37,16.100,-0.05108,0.779,-0.001
6.44,16.200,-0.05087,0.788,-0.001
6.48,16.300,-0.05066,0.792,-0.001
6.55,16.400,-0.05050,0.801,-0.001
6.61,16.500,-0.05029,0.808,-0.001
6.68,16.600,-0.05008,0.817,-0.001
6.70,16.700,-0.04992,0.820,-0.001
6.76,16.800,-0.04975,0.827,-0.001
6.81,16.900,-0.04958,0.833,-0.001
6.85,17.000,-0.04942,0.838,-0.001
6.90,17.100,-0.04929,0.843,-0.001
6.94,17.200,-0.04913,0.849,-0.001
6.98,17.300,-0.04900,0.854,-0.001
7.02,17.400,-0.04884,0.858,-0.001
7.05,17.500,-0.04871,0.862,-0.001
7.10,17.600,-0.04855,0.868,-0.001
7.15,17.700,-0.04842,0.874,-0.001
7.18,17.800,-0.04830,0.878,-0.001
7.21,17.900,-0.04817,0.882,-0.001
7.26,18.000,-0.04801,0.888,-0.001
7.30,18.100,-0.04788,0.893,-0.001
7.33,18.200,-0.04776,0.896,-0.001
7.37,18.300,-0.04763,0.902,-0.001
7.42,18.400,-0.04751,0.908,-0.001
7.44,18.500,-0.04734,0.910,-0.001
7.50,18.600,-0.04722,0.917,-0.001
7.54,18.700,-0.04709,0.922,-0.001
7.58,18.800,-0.04692,0.927,-0.001
7.64,18.900,-0.04680,0.934,-0.001
7.68,19.000,-0.04663,0.940,-0.001
7.74,19.100,-0.04651,0.946,-0.001
7.77,19.200,-0.04634,0.950,-0.001
7.82,19.300,-0.04618,0.957,-0.001
7.87,19.400,-0.04605,0.962,-0.001
7.92,19.500,-0.04589,0.968,-0.001
7.97,19.600,-0.04572,0.974,-0.001
8.01,19.700,-0.04560,0.980,-0.001
8.06,19.800,-0.04543,0.986,-0.001
8.12,19.900,-0.04526,0.993,-0.001
8.16,20.000,-0.04510,0.998,-0.001
8.20,20.100,-0.04497,1.003,-0.001
8.25,20.200,-0.04481,1.008,-0.001
8.30,20.300,-0.04464,1.016,-0.001
8.34,20.400,-0.04447,1.021,-0.001
8.41,20.500,-0.04431,1.028,-0.001
8.46,20.600,-0.04414,1.035,-0.001
8.52,20.700,-0.04397,1.042,-0.001
8.55,20.800,-0.04377,1.046,-0.001
8.63,20.900,-0.04360,1.056,-0.001
8.69,21.000,-0.04339,1.063,-0.001
8.76,21.100,-0.04323,1.072,-0.001
8.81,21.200,-0.04302,1.078,-0.001
8.88,21.300,-0.04281,1.086,-0.001
8.94,21.400,-0.04260,1.093,-0.001
9.01,21.500,-0.04240,1.102,-0.001
9.08,21.600,-0.04215,1.110,-0.001
9.14,21.700,-0.04194,1.118,-0.001
9.22,21.800,-0.04173,1.128,-0.001
9.29,21.900,-0.04152,1.136,-0.001
9.34,22.000,-0.04136,1.143,-0.001
9.39,22.100,-0.04115,1.149,-0.001
9.44,22.200,-0.04094,1.154,-0.001
9.53,22.300,-0.04077,1.166,-0.001
9.58,22.400,-0.04057,1.172,-0.001
9.64,22.500,-0.04040,1.179,-0.001
9.68,22.600,-0.04023,1.183,-0.001
9.75,22.700,-0.04007,1.192,-0.001
9.78,22.800,-0.03990,1.196,-0.001
9.83,22.900,-0.03978,1.202,-0.001
9.88,23.000,-0.03961,1.208,-0.001
9.93,23.100,-0.03949,1.215,-0.001
9.96,23.200,-0.03932,1.218,-0.001
10.01,23.300,-0.03920,1.224,-0.001
10.07,23.400,-0.03903,1.232,-0.001
10.11,23.500,-0.03890,1.237,-0.001
10.15,23.600,-0.03878,1.241,-0.001
10.20,23.700,-0.03866,1.248,-0.001
10.25,23.800,-0.03853,1.254,-0.001
10.29,23.900,-0.03836,1.258,-0.001
10.34,24.000,-0.03824,1.265,-0.001
10.39,24.100,-0.03812,1.270,-0.001
10.43,24.200,-0.03799,1.275,-0.001
10.47,24.300,-0.03782,1.281,-0.001
10.53,24.400,-0.03770,1.287,-0.001
10.58,24.500,-0.03757,1.295,-0.001
10.62,24.600,-0.03741,1.299,-0.001
10.67,24.700,-0.03728,1.305,-0.001
10.72,24.800,-0.03712,1.311,-0.001
10.78,24.900,-0.03699,1.318,-0.001
10.83,25.000,-0.03683,1.324,-0.001
10.89,25.100,-0.03666,1.332,-0.001
10.95,25.200,-0.03654,1.340,-0.001
11.00,25.300,-0.03637,1.345,-0.001
11.05,25.400,-0.03620,1.351,-0.001
11.10,25.500,-0.03604,1.358,-0.001
11.16,25.600,-0.03591,1.365,-0.001
11.22,25.700,-0.03575,1.372,-0.001
11.26,25.800,-0.03558,1.377,-0.001
11.31,25.900,-0.03541,1.384,-0.001
11.38,26.000,-0.03525,1.392,-0.001
11.42,26.100,-0.03508,1.397,-0.001
11.49,26.200,-0.03492,1.405,-0.001
11.53,26.300,-0.03475,1.411,-0.001
11.60,26.400,-0.03458,1.419,-0.001
11.67,26.500,-0.03442,1.427,-0.001
11.72,26.600,-0.03421,1.434,-0.001
11.80,26.700,-0.03404,1.443,-0.001
11.86,26.800,-0.03383,1.451,-0.001
11.94,26.900,-0.03363,1.460,-0.001
12.04,27.000,-0.03342,1.472,-0.001
12.12,27.100,-0.03321,1.483,-0.001
12.18,27.200,-0.03300,1.490,-0.001
12.26,27.300,-0.03280,1.500,-0.001
12.33,27.400,-0.03255,1.508,-0.001
12.40,27.500,-0.03234,1.517,-0.001
12.50,27.600,-0.03213,1.529,-0.001
12.57,27.700,-0.03192,1.537,-0.001
12.62,27.800,-0.03172,1.544,-0.001
12.70,27.900,-0.03155,1.553,-0.001
12.74,28.000,-0.03134,1.559,-0.001
12.82,28.100,-0.03118,1.568,-0.001
12.88,28.200,-0.03101,1.576,-0.001
12.94,28.300,-0.03080,1.583,-0.001
12.98,28.400,-0.03068,1.588,-0.001
13.06,28.500,-0.03051,1.597,-0.001
13.10,28.600,-0.03034,1.602,-0.001
13.16,28.700,-0.03022,1.609,-0.001
13.21,28.800,-0.03005,1.616,-0.001
13.27,28.900,-0.02993,1.623,-0.001
13.31,29.000,-0.02976,1.628,-0.001
13.35,29.100,-0.02964,1.633,-0.001
13.42,29.200,-0.02947,1.641,-0.001
13.47,29.300,-0.02935,1.648,-0.001
13.51,29.400,-0.02922,1.652,-0.001
13.56,29.500,-0.02906,1.659,-0.001
13.61,29.600,-0.02893,1.665,-0.001
13.65,29.700,-0.02881,1.670,-0.001
13.69,29.800,-0.02868,1.675,-0.001
13.74,29.900,-0.02856,1.680,-0.001
13.80,30.000,-0.02839,1.688,-0.001
13.85,30.100,-0.02827,1.694,-0.001
13.90,30.200,-0.02810,1.701,-0.001
13.96,30.300,-0.02798,1.707,-0.001
14.02,30.400,-0.02781,1.714,-0.001
14.06,30.500,-0.02768,1.720,-0.001
14.13,30.600,-0.02752,1.728,-0.001
14.18,30.700,-0.02739,1.734,-0.001
14.23,30.800,-0.02723,1.740,-0.001
14.27,30.900,-0.02710,1.746,-0.001
14.35,31.000,-0.02694,1.755,-0.001
14.40,31.100,-0.02677,1.761,-0.001
14.45,31.200,-0.02660,1.767,-0.001
14.50,31.300,-0.02644,1.774,-0.001
14.56,31.400,-0.02631,1.781,-0.001
14.63,31.500,-0.02615,1.789,-0.001
14.66,31.600,-0.02598,1.794,-0.001
14.75,31.700,-0.02581,1.804,-0.001
14.82,31.800,-0.02565,1.812,-0.001
14.86,31.900,-0.02548,1.818,-0.001
14.92,32.000,-0.02532,1.825,0.000
15.02,32.100,-0.02515,1.837,0.000
15.09,32.200,-0.02498,1.845,0.000
15.13,32.300,-0.02478,1.851,0.000
15.21,32.400,-0.02457,1.861,0.000
15.30,32.500,-0.02440,1.872,0.000
15.38,32.600,-0.02419,1.881,0.000
15.48,32.700,-0.02394,1.893,0.000
15.56,32.800,-0.02374,1.903,0.000
15.64,32.900,-0.02349,1.913,0.000
15.72,33.000,-0.02328,1.923,0.000
15.81,33.100,-0.02307,1.933,0.000
15.91,33.200,-0.02282,1.946,0.000
15.98,33.300,-0.02261,1.955,0.000
16.05,33.400,-0.02241,1.962,0.000
16.12,33.500,-0.02224,1.971,0.000
16.20,33.600,-0.02203,1.981,0.000
16.25,33.700,-0.02183,1.987,0.000
16.32,33.800,-0.02166,1.996,0.000
16.38,33.900,-0.02149,2.004,0.000
16.43,34.000,-0.02133,2.010,0.000
16.49,34.100,-0.02116,2.017,0.000
16.54,34.200,-0.02099,2.023,0.000
16.59,34.300,-0.02083,2.030,0.000
16.65,34.400,-0.02070,2.037,0.000
16.70,34.500,-0.02054,2.043,0.000
16.74,34.600,-0.02041,2.048,0.000
16.79,34.700,-0.02029,2.054,0.000
16.85,34.800,-0.02012,2.061,0.000
16.90,34.900,-0.02000,2.067,0.000
16.95,35.000,-0.01987,2.073,0.000
17.00,35.100,-0.01975,2.079,0.000
17.03,35.200,-0.01958,2.083,0.000
17.09,35.300,-0.01946,2.090,0.000
17.15,35.400,-0.01933,2.098,0.000
17.21,35.500,-0.01917,2.104,0.000
17.25,35.600,-0.01904,2.110,0.000
17.31,35.700,-0.01887,2.117,0.000
17.37,35.800,-0.01875,2.124,0.000
17.41,35.900,-0.01863,2.130,0.000
17.47,36.000,-0.01846,2.137,0.000
17.53,36.100,-0.01829,2.145,0.000
17.48,36.200,-0.01817,2.138,0.000
17.52,36.300,-0.01800,2.143,0.000
17.61,36.400,-0.01784,2.154,0.000
17.72,36.500,-0.01771,2.167,0.000
17.80,36.600,-0.01754,2.177,0.000
17.87,36.700,-0.01738,2.185,0.000
17.93,36.800,-0.01721,2.193,0.000
17.99,36.900,-0.01705,2.200,0.000
18.06,37.000,-0.01692,2.208,0.000
18.13,37.100,-0.01676,2.217,0.000
18.17,37.200,-0.01659,2.223,0.000
18.25,37.300,-0.01642,2.232,0.000
18.32,37.400,-0.01626,2.240,0.000
18.40,37.500,-0.01609,2.250,0.000
18.47,37.600,-0.01592,2.259,0.000
18.55,37.700,-0.01576,2.269,0.000
18.63,37.800,-0.01555,2.279,0.000
18.71,37.900,-0.01538,2.288,0.000
18.78,38.000,-0.01518,2.297,0.000
18.88,38.100,-0.01497,2.309,0.000
18.95,38.200,-0.01476,2.318,0.000
19.05,38.300,-0.01455,2.330,0.000
19.14,38.400,-0.01435,2.341,0.000
19.25,38.500,-0.01410,2.354,0.000
19.34,38.600,-0.01389,2.365,0.000
19.43,38.700,-0.01364,2.376,0.000
19.51,38.800,-0.01343,2.386,0.000
19.60,38.900,-0.01322,2.397,0.000
19.67,39.000,-0.01302,2.406,0.000
19.76,39.100,-0.01281,2.417,0.000
19.84,39.200,-0.01260,2.426,0.000
19.90,39.300,-0.01243,2.434,0.000
19.98,39.400,-0.01223,2.444,0.000
20.05,39.500,-0.01206,2.452,0.000
20.13,39.600,-0.01185,2.462,0.000
20.19,39.700,-0.01169,2.469,0.000
20.22,39.800,-0.01152,2.474,0.000
20.28,39.900,-0.01139,2.481,0.000
20.34,40.000,-0.01123,2.488,0.000
20.40,40.100,-0.01106,2.495,0.000
20.48,40.200,-0.01094,2.505,0.000
20.53,40.300,-0.01077,2.511,0.000
20.57,40.400,-0.01065,2.516,0.000
20.63,40.500,-0.01048,2.523,0.000
20.67,40.600,-0.01036,2.528,0.000
20.74,40.700,-0.01019,2.537,0.000
20.79,40.800,-0.01006,2.543,0.000
20.86,40.900,-0.00994,2.551,0.000
20.92,41.000,-0.00982,2.558,0.000
20.98,41.100,-0.00965,2.566,0.000
21.04,41.200,-0.00952,2.574,0.000
21.10,41.300,-0.00936,2.581,0.000
21.15,41.400,-0.00923,2.587,0.000
21.21,41.500,-0.00907,2.595,0.000
21.28,41.600,-0.00894,2.603,0.000
21.37,41.700,-0.00878,2.613,0.000
21.44,41.800,-0.00861,2.622,0.000
21.50,41.900,-0.00844,2.629,0.000
21.55,42.000,-0.00832,2.636,0.000
21.62,42.100,-0.00815,2.644,0.000
21.71,42.200,-0.00799,2.656,0.000
21.77,42.300,-0.00782,2.663,0.000
21.84,42.400,-0.00765,2.671,0.000
21.91,42.500,-0.00749,2.680,0.000
21.97,42.600,-0.00736,2.687,0.000
22.04,42.700,-0.00720,2.695,0.000
22.11,42.800,-0.00703,2.704,0.000
22.19,42.900,-0.00687,2.714,0.000
22.25,43.000,-0.00670,2.721,0.000
22.32,43.100,-0.00653,2.730,0.000
22.40,43.200,-0.00637,2.740,0.000
22.48,43.300,-0.00616,2.750,0.000
22.57,43.400,-0.00599,2.761,0.000
22.67,43.500,-0.00578,2.773,0.000
22.75,43.600,-0.00562,2.782,0.000
22.84,43.700,-0.00541,2.793,0.000
22.91,43.800,-0.00520,2.802,0.000
23.03,43.900,-0.00500,2.816,0.000
23.12,44.000,-0.00479,2.828,0.000
23.21,44.100,-0.00454,2.839,0.000
23.31,44.200,-0.00433,2.851,0.000
23.38,44.300,-0.00412,2.860,0.000
23.47,44.400,-0.00391,2.870,0.000
23.56,44.500,-0.00371,2.881,0.000
23.64,44.600,-0.00354,2.891,0.000
23.71,44.700,-0.00333,2.900,0.000
23.80,44.800,-0.00313,2.912,0.000
23.87,44.900,-0.00296,2.920,0.000
23.96,45.000,-0.00275,2.930,0.000
24.04,45.100,-0.00258,2.940,0.000
24.10,45.200,-0.00242,2.947,0.000
24.18,45.300,-0.00225,2.957,0.000
24.24,45.400,-0.00209,2.964,0.000
24.31,45.500,-0.00192,2.973,0.000
24.37,45.600,-0.00175,2.981,0.000
24.43,45.700,-0.00163,2.988,0.000
24.51,45.800,-0.00146,2.997,0.000
24.56,45.900,-0.00134,3.004,0.000
24.61,46.000,-0.00117,3.010,0.000
24.68,46.100,-0.00105,3.018,0.000
24.75,46.200,-0.00092,3.027,0.000
24.80,46.300,-0.00076,3.033,0.000
24.85,46.400,-0.00063,3.040,0.000
24.92,46.500,-0.00051,3.048,0.000
24.97,46.600,-0.00038,3.054,0.000
25.05,46.700,-0.00022,3.064,0.000
25.10,46.800,-0.00009,3.070,0.000
25.17,46.900,0.00003,3.078,0.000
25.24,47.000,0.00020,3.088,0.000
25.31,47.100,0.00032,3.096,0.000
25.39,47.200,0.00049,3.105,0.000
25.45,47.300,0.00062,3.112,0.000
25.53,47.400,0.00078,3.122,0.000
25.60,47.500,0.00091,3.131,0.000
25.68,47.600,0.00107,3.141,0.000
25.75,47.700,0.00124,3.149,0.000
25.81,47.800,0.00136,3.156,0.000
25.89,47.900,0.00153,3.166,0.000
25.95,48.000,0.00170,3.174,0.000
26.03,48.100,0.00186,3.184,0.000
26.11,48.200,0.00199,3.194,0.000
26.19,48.300,0.00215,3.203,0.000
26.27,48.400,0.00232,3.213,0.000
26.35,48.500,0.00249,3.223,0.000
26.39,48.600,0.00265,3.228,0.000
26.48,48.700,0.00278,3.238,0.000
26.56,48.800,0.00298,3.248,0.000
26.63,48.900,0.00315,3.258,0.000
26.71,49.000,0.00332,3.267,0.000
26.81,49.100,0.00348,3.279,0.000
26.91,49.200,0.00369,3.292,0.000
27.01,49.300,0.00390,3.304,0.000
27.09,49.400,0.00406,3.313,0.000
27.20,49.500,0.00427,3.327,0.000
27.31,49.600,0.00448,3.341,0.000
27.43,49.700,0.00469,3.354,0.000
27.54,49.800,0.00494,3.368,0.000
27.64,49.900,0.00514,3.380,0.000
27.75,50.000,0.00535,3.394,0.000
27.85,50.100,0.00556,3.406,0.000
27.92,50.200,0.00577,3.415,0.000
28.02,50.300,0.00598,3.427,0.000
28.12,50.400,0.00618,3.440,0.000
28.21,50.500,0.00635,3.450,0.000
28.31,50.600,0.00656,3.462,0.000
28.39,50.700,0.00672,3.472,0.000
28.47,50.800,0.00693,3.482,0.000
28.55,50.900,0.00710,3.492,0.000
28.62,51.000,0.00726,3.500,0.000
28.71,51.100,0.00739,3.511,0.000
28.76,51.200,0.00755,3.518,0.000
28.82,51.300,0.00772,3.525,0.000
28.89,51.400,0.00785,3.534,0.000
28.96,51.500,0.00801,3.542,0.000
29.02,51.600,0.00814,3.550,0.000
29.08,51.700,0.00826,3.556,0.000
29.13,51.800,0.00843,3.563,0.000
29.21,51.900,0.00855,3.573,0.000
29.27,52.000,0.00868,3.579,0.000
29.34,52.100,0.00880,3.589,0.000
29.41,52.200,0.00893,3.597,0.000
29.49,52.300,0.00909,3.607,0.000
29.54,52.400,0.00922,3.613,0.000
29.62,52.500,0.00934,3.623,0.000
29.68,52.600,0.00951,3.630,0.000
29.73,52.700,0.00963,3.637,0.000
29.84,52.800,0.00980,3.650,0.000
29.91,52.900,0.00992,3.659,0.000
30.00,53.000,0.01009,3.669,0.000
30.08,53.100,0.01021,3.679,0.000
30.16,53.200,0.01038,3.689,0.000
30.23,53.300,0.01055,3.697,0.000
30.30,53.400,0.01067,3.706,0.000
30.38,53.500,0.01084,3.715,0.000
30.46,53.600,0.01096,3.725,0.000
30.54,53.700,0.01113,3.735,0.000
30.62,53.800,0.01129,3.745,0.000
30.70,53.900,0.01146,3.755,0.000
30.77,54.000,0.01163,3.763,0.000
30.85,54.100,0.01175,3.774,0.000
30.93,54.200,0.01192,3.783,0.000
31.02,54.300,0.01208,3.794,0.000
31.11,54.400,0.01225,3.805,0.000
31.20,54.500,0.01242,3.816,0.000
31.29,54.600,0.01258,3.827,0.000
31.39,54.700,0.01275,3.840,0.000
31.49,54.800,0.01296,3.851,0.000
31.57,54.900,0.01312,3.861,0.000
31.70,55.000,0.01333,3.877,0.000
31.80,55.100,0.01354,3.889,0.000
31.91,55.200,0.01375,3.903,0.000
32.04,55.300,0.01391,3.919,0.000
32.15,55.400,0.01416,3.932,0.000
32.27,55.500,0.01437,3.947,0.000
32.40,55.600,0.01458,3.963,0.000
32.52,55.700,0.01479,3.977,0.000
32.63,55.800,0.01503,3.991,0.000
32.74,55.900,0.01524,4.004,0.000
32.84,56.000,0.01545,4.017,0.000
32.94,56.100,0.01562,4.029,0.000
33.05,56.200,0.01582,4.042,0.000
33.14,56.300,0.01603,4.054,0.000
33.24,56.400,0.01620,4.065,0.000
33.32,56.500,0.01636,4.075,0.000
33.40,56.600,0.01653,4.085,0.000
33.49,56.700,0.01670,4.096,0.000
33.57,56.800,0.01686,4.106,0.000
33.64,56.900,0.01703,4.115,0.000
33.73,57.000,0.01715,4.125,0.000
33.79,57.100,0.01732,4.132,0.000
33.87,57.200,0.01749,4.142,0.000
33.95,57.300,0.01761,4.152,0.000
34.01,57.400,0.01774,4.159,0.000
34.08,57.500,0.01790,4.168,0.000
34.16,57.600,0.01803,4.178,0.000
34.21,57.700,0.01815,4.184,0.000
34.28,57.800,0.01828,4.193,0.000
34.37,57.900,0.01844,4.204,0.000
34.42,58.000,0.01857,4.210,0.000
34.51,58.100,0.01869,4.221,0.000
34.59,58.200,0.01886,4.230,0.000
34.66,58.300,0.01898,4.240,0.000
34.73,58.400,0.01911,4.248,0.000
34.82,58.500,0.01927,4.259,0.000
34.91,58.600,0.01940,4.269,0.000
35.00,58.700,0.01956,4.281,0.000
35.08,58.800,0.01973,4.291,0.000
35.17,58.900,0.01986,4.302,0.000
35.27,59.000,0.02002,4.314,0.000
35.34,59.100,0.02019,4.323,0.000
35.43,59.200,0.02031,4.334,0.000
35.51,59.300,0.02048,4.344,0.000
35.63,59.400,0.02064,4.357,0.000
35.69,59.500,0.02081,4.365,0.000
35.78,59.600,0.02098,4.376,0.000
35.88,59.700,0.02110,4.389,0.000
35.98,59.800,0.02127,4.401,0.000
36.08,59.900,0.02143,4.413,0.000
36.18,60.000,0.02160,4.425,0.000
36.28,60.100,0.02177,4.437,0.000
36.38,60.200,0.02193,4.450,0.000
36.48,60.300,0.02210,4.461,0.000
36.59,60.400,0.02227,4.476,0.000
36.71,60.500,0.02247,4.490,0.000
36.82,60.600,0.02264,4.503,0.000
36.93,60.700,0.02285,4.517,0.000
37.06,60.800,0.02306,4.532,0.000
37.19,60.900,0.02326,4.549,0.000
37.33,61.000,0.02347,4.566,0.000
37.47,61.100,0.02368,4.582,0.000
37.60,61.200,0.02389,4.599,0.000
37.75,61.300,0.02414,4.617,0.000
37.85,61.400,0.02434,4.629,0.000
37.98,61.500,0.02455,4.645,0.000
38.08,61.600,0.02472,4.657,0.000
38.19,61.700,0.02493,4.671,0.000
38.30,61.800,0.02513,4.685,0.000
38.40,61.900,0.02530,4.697,0.000
38.51,62.000,0.02551,4.710,0.001
38.61,62.100,0.02567,4.722,0.001
38.69,62.200,0.02584,4.732,0.001
38.79,62.300,0.02601,4.744,0.001
38.87,62.400,0.02617,4.754,0.001
38.94,62.500,0.02634,4.763,0.001
39.03,62.600,0.02650,4.774,0.001
39.10,62.700,0.02663,4.782,0.001
39.18,62.800,0.02680,4.792,0.001
39.27,62.900,0.02692,4.803,0.001
39.36,63.000,0.02709,4.814,0.001
39.44,63.100,0.02721,4.824,0.001
39.51,63.200,0.02734,4.833,0.001
39.57,63.300,0.02750,4.839,0.001
39.66,63.400,0.02763,4.851,0.001
39.73,63.500,0.02775,4.860,0.001
39.81,63.600,0.02788,4.870,0.001
39.90,63.700,0.02800,4.881,0.001
39.99,63.800,0.02817,4.891,0.001
40.07,63.900,0.02829,4.901,0.001
40.16,64.000,0.02842,4.912,0.001
40.23,64.100,0.02858,4.921,0.001
40.35,64.200,0.02871,4.935,0.001
40.44,64.300,0.02887,4.947,0.001
40.52,64.400,0.02900,4.956,0.001
40.61,64.500,0.02916,4.967,0.001
40.72,64.600,0.02933,4.980,0.001
40.82,64.700,0.02945,4.993,0.001
40.91,64.800,0.02962,5.004,0.001
41.00,64.900,0.02975,5.015,0.001
41.10,65.000,0.02991,5.027,0.001
41.21,65.100,0.03008,5.040,0.001
41.31,65.200,0.03020,5.052,0.001
41.41,65.300,0.03037,5.065,0.001
41.51,65.400,0.03054,5.077,0.001
41.60,65.500,0.03070,5.088,0.001
41.71,65.600,0.03087,5.101,0.001
41.79,65.700,0.03099,5.111,0.001
41.91,65.800,0.03116,5.125,0.001
42.04,65.900,0.03132,5.142,0.001
42.14,66.000,0.03149,5.154,0.001
42.25,66.100,0.03170,5.168,0.001
42.38,66.200,0.03187,5.183,0.001
42.52,66.300,0.03203,5.201,0.001
42.65,66.400,0.03224,5.216,0.001
42.78,66.500,0.03245,5.232,0.001
42.91,66.600,0.03265,5.248,0.001
43.05,66.700,0.03286,5.266,0.001
43.20,66.800,0.03307,5.284,0.001
43.34,66.900,0.03328,5.301,0.001
43.48,67.000,0.03349,5.319,0.001
43.63,67.100,0.03374,5.336,0.001
43.77,67.200,0.03394,5.354,0.001
43.88,67.300,0.03415,5.367,0.001
44.00,67.400,0.03436,5.381,0.001
44.13,67.500,0.03452,5.397,0.001
44.27,67.600,0.03473,5.415,0.001
44.38,67.700,0.03494,5.428,0.001
44.48,67.800,0.03511,5.441,0.001
44.57,67.900,0.03527,5.452,0.001
44.69,68.000,0.03544,5.466,0.001
44.78,68.100,0.03561,5.477,0.001
44.86,68.200,0.03577,5.487,0.001
44.97,68.300,0.03594,5.500,0.001
45.06,68.400,0.03606,5.512,0.001
45.14,68.500,0.03623,5.521,0.001
45.25,68.600,0.03635,5.534,0.001
45.33,68.700,0.03652,5.545,0.001
45.42,68.800,0.03664,5.555,0.001
45.51,68.900,0.03681,5.566,0.001
45.61,69.000,0.03693,5.578,0.001
45.68,69.100,0.03706,5.587,0.001
45.77,69.200,0.03718,5.599,0.001
45.86,69.300,0.03735,5.609,0.001
45.95,69.400,0.03748,5.620,0.001
46.06,69.500,0.03760,5.633,0.001
46.17,69.600,0.03777,5.647,0.001
46.25,69.700,0.03789,5.657,0.001
46.36,69.800,0.03806,5.670,0.001
46.46,69.900,0.03818,5.682,0.001
46.56,70.000,0.03835,5.695,0.001
46.67,70.100,0.03847,5.708,0.001
46.77,70.200,0.03864,5.721,0.001
46.87,70.300,0.03876,5.733,0.001
46.98,70.400,0.03893,5.746,0.001
47.11,70.500,0.03910,5.762,0.001
47.22,70.600,0.03926,5.776,0.001
47.32,70.700,0.03939,5.787,0.001
47.44,70.800,0.03955,5.803,0.001
47.58,70.900,0.03972,5.819,0.001
47.68,71.000,0.03989,5.831,0.001
47.78,71.100,0.04005,5.844,0.001
47.91,71.200,0.04022,5.859,0.001
48.04,71.300,0.04034,5.875,0.001
48.14,71.400,0.04051,5.888,0.001
48.26,71.500,0.04072,5.902,0.001
48.39,71.600,0.04088,5.919,0.001
48.51,71.700,0.04105,5.933,0.001
48.65,71.800,0.04122,5.950,0.001
48.79,71.900,0.04142,5.967,0.001
48.92,72.000,0.04159,5.983,0.001
49.07,72.100,0.04180,6.001,0.001
49.23,72.200,0.04200,6.021,0.001
49.38,72.300,0.04221,6.040,0.001
49.55,72.400,0.04242,6.060,0.001
49.73,72.500,0.04267,6.083,0.001
49.89,72.600,0.04288,6.102,0.001
50.06,72.700,0.04313,6.122,0.001
50.22,72.800,0.04333,6.142,0.001
50.36,72.900,0.04354,6.159,0.001
50.50,73.000,0.04375,6.177,0.001
50.62,73.100,0.04396,6.192,0.001
50.77,73.200,0.04417,6.210,0.001
50.92,73.300,0.04437,6.228,0.001
51.05,73.400,0.04454,6.243,0.001
51.20,73.500,0.04475,6.262,0.001
51.29,73.600,0.04491,6.274,0.001
51.41,73.700,0.04508,6.288,0.001
51.52,73.800,0.04525,6.301,0.001
51.65,73.900,0.04537,6.317,0.001
51.74,74.000,0.04554,6.328,0.001
51.84,74.100,0.04570,6.341,0.001
51.94,74.200,0.04583,6.353,0.001
52.06,74.300,0.04599,6.367,0.001
52.15,74.400,0.04612,6.379,0.001
52.27,74.500,0.04628,6.393,0.001
52.36,74.600,0.04641,6.405,0.001
52.46,74.700,0.04653,6.416,0.001
52.55,74.800,0.04670,6.427,0.001
52.62,74.900,0.04683,6.436,0.001
52.75,75.000,0.04695,6.452,0.001
52.87,75.100,0.04712,6.466,0.001
52.97,75.200,0.04724,6.478,0.001
53.08,75.300,0.04741,6.493,0.001
53.19,75.400,0.04753,6.506,0.001
53.30,75.500,0.04770,6.520,0.001
53.42,75.600,0.04782,6.533,0.001
53.53,75.700,0.04799,6.547,0.001
53.66,75.800,0.04811,6.563,0.001
53.79,75.900,0.04828,6.579,0.001
53.90,76.000,0.04845,6.592,0.001
54.02,76.100,0.04857,6.607,0.001
54.13,76.200,0.04874,6.620,0.001
54.24,76.300,0.04890,6.634,0.001
54.38,76.400,0.04907,6.651,0.001
54.49,76.500,0.04919,6.665,0.001
54.60,76.600,0.04936,6.678,0.001
54.72,76.700,0.04953,6.693,0.001
54.83,76.800,0.04969,6.706,0.001
54.97,76.900,0.04986,6.723,0.001
55.11,77.000,0.04998,6.740,0.001
55.23,77.100,0.05019,6.755,0.001
55.37,77.200,0.05036,6.773,0.001
55.50,77.300,0.05052,6.789,0.001
55.65,77.400,0.05069,6.807,0.001
55.81,77.500,0.05090,6.826,0.001
55.98,77.600,0.05106,6.847,0.001
56.14,77.700,0.05127,6.866,0.001
56.31,77.800,0.05148,6.887,0.001
56.49,77.900,0.05169,6.910,0.001
56.64,78.000,0.05189,6.928,0.001
56.84,78.100,0.05214,6.952,0.001
57.04,78.200,0.05235,6.976,0.001
57.21,78.300,0.05256,6.997,0.001
57.39,78.400,0.05277,7.019,0.001
57.54,78.500,0.05298,7.037,0.001
57.71,78.600,0.05318,7.059,0.001
57.84,78.700,0.05339,7.075,0.001
57.99,78.800,0.05356,7.093,0.001
58.15,78.900,0.05376,7.112,0.001
58.32,79.000,0.05397,7.133,0.001
58.48,79.100,0.05414,7.153,0.001
58.63,79.200,0.05431,7.170,0.001
58.75,79.300,0.05447,7.186,0.001
58.86,79.400,0.05464,7.199,0.001
58.95,79.500,0.05480,7.210,0.001
59.08,79.600,0.05497,7.227,0.001
59.22,79.700,0.05509,7.243,0.001
59.33,79.800,0.05526,7.257,0.001
59.44,79.900,0.05539,7.270,0.001
59.55,80.000,0.05555,7.283,0.001
59.67,80.100,0.05568,7.298,0.001
59.78,80.200,0.05580,7.311,0.001
59.91,80.300,0.05597,7.328,0.001
60.01,80.400,0.05609,7.339,0.001
60.10,80.500,0.05622,7.351,0.001
60.21,80.600,0.05638,7.364,0.001
60.34,80.700,0.05651,7.380,0.001
60.46,80.800,0.05663,7.395,0.001
60.58,80.900,0.05680,7.409,0.001
60.69,81.000,0.05692,7.423,0.001
60.82,81.100,0.05709,7.438,0.001
60.93,81.200,0.05721,7.452,0.001
61.07,81.300,0.05738,7.470,0.001
61.20,81.400,0.05750,7.485,0.001
61.33,81.500,0.05767,7.502,0.001
61.46,81.600,0.05784,7.517,0.001
61.60,81.700,0.05796,7.534,0.001
61.72,81.800,0.05813,7.548,0.001
61.86,81.900,0.05825,7.566,0.001
61.99,82.000,0.05842,7.581,0.001
62.13,82.100,0.05859,7.599,0.001
62.26,82.200,0.05871,7.615,0.001
62.40,82.300,0.05888,7.632,0.001
62.53,82.400,0.05904,7.648,0.001
62.66,82.500,0.05921,7.664,0.001
62.81,82.600,0.05933,7.682,0.001
62.95,82.700,0.05950,7.699,0.001
63.10,82.800,0.05967,7.717,0.001
63.25,82.900,0.05983,7.737,0.001
63.42,83.000,0.06000,7.757,0.001
63.57,83.100,0.06021,7.776,0.001
63.78,83.200,0.06037,7.801,0.001
63.97,83.300,0.06058,7.824,0.001
64.16,83.400,0.06079,7.847,0.001
64.37,83.500,0.06100,7.873,0.001
64.57,83.600,0.06120,7.898,0.001
64.79,83.700,0.06141,7.924,0.001
65.01,83.800,0.06166,7.951,0.001
65.24,83.900,0.06187,7.979,0.001
65.43,84.000,0.06212,8.003,0.001
65.63,84.100,0.06233,8.027,0.001
65.82,84.200,0.06253,8.050,0.001
66.00,84.300,0.06270,8.072,0.001
66.19,84.400,0.06291,8.095,0.001
66.36,84.500,0.06312,8.116,0.001
66.52,84.600,0.06328,8.136,0.001
66.66,84.700,0.06349,8.153,0.001
66.82,84.800,0.06366,8.172,0.001
66.98,84.900,0.06382,8.192,0.001
67.11,85.000,0.06399,8.208,0.001
67.24,85.100,0.06411,8.224,0.001
67.37,85.200,0.06428,8.240,0.001
67.50,85.300,0.06440,8.256,0.001
67.63,85.400,0.06457,8.271,0.001
67.74,85.500,0.06469,8.285,0.001
67.84,85.600,0.06486,8.298,0.001
68.00,85.700,0.06499,8.316,0.001
68.12,85.800,0.06511,8.332,0.001
68.25,85.900,0.06523,8.347,0.001
68.35,86.000,0.06540,8.360,0.001
68.48,86.100,0.06553,8.376,0.001
68.62,86.200,0.06565,8.393,0.001
68.75,86.300,0.06577,8.408,0.001
68.88,86.400,0.06594,8.425,0.001
69.01,86.500,0.06607,8.440,0.001
69.14,86.600,0.06619,8.456,0.001
69.28,86.700,0.06636,8.474,0.001
69.44,86.800,0.06648,8.494,0.001
69.59,86.900,0.06665,8.512,0.001
69.74,87.000,0.06677,8.529,0.001
69.89,87.100,0.06694,8.548,0.001
70.02,87.200,0.06706,8.565,0.001
70.19,87.300,0.06723,8.585,0.001
70.37,87.400,0.06740,8.607,0.001
70.50,87.500,0.06752,8.623,0.001
70.66,87.600,0.06769,8.642,0.001
70.83,87.700,0.06785,8.663,0.001
70.98,87.800,0.06798,8.681,0.001
71.14,87.900,0.06814,8.701,0.001
71.31,88.000,0.06831,8.722,0.001
71.47,88.100,0.06843,8.742,0.001
71.63,88.200,0.06860,8.760,0.001
71.81,88.300,0.06877,8.783,0.001
71.98,88.400,0.06893,8.804,0.001
72.16,88.500,0.06910,8.826,0.001
72.36,88.600,0.06927,8.850,0.001
72.56,88.700,0.06943,8.874,0.001
72.78,88.800,0.06964,8.902,0.001
73.00,88.900,0.06981,8.928,0.001
73.21,89.000,0.07001,8.954,0.001
73.45,89.100,0.07022,8.983,0.001
73.71,89.200,0.07043,9.015,0.001
73.94,89.300,0.07064,9.044,0.001
74.19,89.400,0.07084,9.074,0.001
74.42,89.500,0.07109,9.103,0.001
74.69,89.600,0.07130,9.136,0.001
74.94,89.700,0.07151,9.165,0.001
75.19,89.800,0.07172,9.197,0.001
75.43,89.900,0.07192,9.226,0.001
75.66,90.000,0.07213,9.253,0.001
75.89,90.100,0.07234,9.282,0.001
76.10,90.200,0.07255,9.308,0.001
76.32,90.300,0.07271,9.334,0.001
76.52,90.400,0.07292,9.360,0.001
76.72,90.500,0.07309,9.383,0.001
76.92,90.600,0.07325,9.408,0.001
77.11,90.700,0.07342,9.431,0.001
77.29,90.800,0.07359,9.453,0.001
77.44,90.900,0.07375,9.472,0.001
77.61,91.000,0.07388,9.492,0.001
77.76,91.100,0.07404,9.511,0.001
77.95,91.200,0.07417,9.534,0.001
78.13,91.300,0.07434,9.556,0.001
78.28,91.400,0.07446,9.574,0.001
78.45,91.500,0.07463,9.595,0.001
78.60,91.600,0.07475,9.614,0.001
78.76,91.700,0.07488,9.633,0.001
78.92,91.800,0.07500,9.653,0.001
79.10,91.900,0.07517,9.674,0.001
79.26,92.000,0.07529,9.694,0.001
79.42,92.100,0.07542,9.714,0.001
79.61,92.200,0.07558,9.737,0.001
79.78,92.300,0.07571,9.757,0.001
52.27,92.400,0.07583,6.393,0.001
41.94,92.500,0.07600,5.129,0.001
41.50,92.600,0.07612,5.076,0.001
41.74,92.700,0.07629,5.105,0.002
42.08,92.800,0.07645,5.147,0.002
42.39,92.900,0.07658,5.185,0.002
42.69,93.000,0.07675,5.222,0.002
42.98,93.100,0.07687,5.256,0.002
43.30,93.200,0.07704,5.296,0.002
43.60,93.300,0.07720,5.332,0.002
43.89,93.400,0.07733,5.368,0.002
44.20,93.500,0.07749,5.406,0.002
44.48,93.600,0.07766,5.440,0.002
44.77,93.700,0.07783,5.476,0.002
45.08,93.800,0.07795,5.514,0.002
45.36,93.900,0.07812,5.548,0.002
45.66,94.000,0.07828,5.584,0.002
45.93,94.100,0.07845,5.617,0.002
46.20,94.200,0.07862,5.651,0.002
46.46,94.300,0.07878,5.683,0.002
46.74,94.400,0.07895,5.717,0.002
47.00,94.500,0.07916,5.749,0.002
47.27,94.600,0.07932,5.781,0.002
47.54,94.700,0.07953,5.814,0.002
47.79,94.800,0.07970,5.846,0.002
48.04,94.900,0.07990,5.876,0.002
48.34,95.000,0.08011,5.912,0.002
48.62,95.100,0.08036,5.947,0.002
48.89,95.200,0.08057,5.980,0.002
49.14,95.300,0.08078,6.011,0.002
49.40,95.400,0.08098,6.042,0.002
49.64,95.500,0.08119,6.071,0.002
49.88,95.600,0.08140,6.101,0.002
50.11,95.700,0.08161,6.129,0.002
50.36,95.800,0.08182,6.159,0.002
50.56,95.900,0.08202,6.184,0.002
50.79,96.000,0.08219,6.212,0.002
50.98,96.100,0.08236,6.236,0.002
51.19,96.200,0.08256,6.261,0.002
51.37,96.300,0.08273,6.284,0.002
51.54,96.400,0.08290,6.304,0.002
51.73,96.500,0.08306,6.327,0.002
51.92,96.600,0.08319,6.351,0.002
52.08,96.700,0.08335,6.369,0.002
52.26,96.800,0.08348,6.392,0.002
52.41,96.900,0.08364,6.410,0.002
52.58,97.000,0.08377,6.431,0.002
52.73,97.100,0.08393,6.450,0.002
52.90,97.200,0.08406,6.470,0.002
53.06,97.300,0.08418,6.489,0.002
53.20,97.400,0.08435,6.507,0.002
53.34,97.500,0.08447,6.524,0.002
53.50,97.600,0.08460,6.544,0.002
53.66,97.700,0.08472,6.563,0.002
53.80,97.800,0.08489,6.580,0.002
53.94,97.900,0.08501,6.597,0.002
54.12,98.000,0.08514,6.620,0.002
54.26,98.100,0.08526,6.637,0.002
54.44,98.200,0.08543,6.658,0.002
54.60,98.300,0.08556,6.678,0.002
54.77,98.400,0.08572,6.699,0.002
54.93,98.500,0.08585,6.718,0.002
55.09,98.600,0.08601,6.739,0.002
55.27,98.700,0.08614,6.759,0.002
55.42,98.800,0.08630,6.779,0.002
55.60,98.900,0.08647,6.800,0.002
55.79,99.000,0.08659,6.823,0.002
55.95,99.100,0.08676,6.843,0.002
56.13,99.200,0.08693,6.865,0.002
56.31,99.300,0.08709,6.887,0.002
56.50,99.400,0.08722,6.910,0.002
56.65,99.500,0.08738,6.929,0.002
56.83,99.600,0.08755,6.951,0.002
57.00,99.700,0.08767,6.971,0.002
57.18,99.800,0.08784,6.994,0.002
57.37,99.900,0.08801,7.017,0.002
57.56,100.000,0.08817,7.040,0.002
57.74,100.100,0.08834,7.062,0.002
57.95,100.200,0.08855,7.088,0.002
58.15,100.300,0.08871,7.112,0.002
58.37,100.400,0.08892,7.139,0.002
58.59,100.500,0.08909,7.166,0.002
58.83,100.600,0.08930,7.195,0.002
59.05,100.700,0.08950,7.223,0.002
59.29,100.800,0.08971,7.252,0.002
59.52,100.900,0.08996,7.280,0.002
59.74,101.000,0.09017,7.306,0.002
59.98,101.100,0.09038,7.336,0.002
60.21,101.200,0.09058,7.365,0.002
60.43,101.300,0.09079,7.391,0.002
60.66,101.400,0.09100,7.420,0.002
60.89,101.500,0.09117,7.447,0.002
61.10,101.600,0.09137,7.473,0.002
61.33,101.700,0.09158,7.501,0.002
61.52,101.800,0.09175,7.524,0.002
61.71,101.900,0.09191,7.548,0.002
61.87,102.000,0.09208,7.568,0.002
62.06,102.100,0.09225,7.591,0.002
62.24,102.200,0.09241,7.613,0.002
62.42,102.300,0.09258,7.635,0.002
62.58,102.400,0.09270,7.654,0.002
43.41,102.500,0.09287,5.309,0.002
5.81,102.540,0.09291,0.711,0.002