File: data-files/CWRU/0800-05-28C.txt
""
"Test Method","Will_Huddleston_Disks.msm"
"Sample I. D.","800-5-28C.mss"
"Specimen Number","2"

"Load (N)","Time (s)","Extension (mm)","Stress (MPa)","Strain (mm/mm)"

4.22,0.200,-0.01243,0.733,0.000
4.22,0.300,-0.01239,0.733,0.000
4.22,0.400,-0.01239,0.733,0.000
4.21,0.500,-0.01239,0.732,0.000
4.22,0.600,-0.01235,0.732,0.000
4.22,0.700,-0.01235,0.732,0.000
4.21,0.800,-0.01235,0.731,0.000
4.21,0.900,-0.01231,0.731,0.000
4.22,1.000,-0.01231,0.733,0.000
4.22,1.100,-0.01231,0.733,0.000
4.24,1.200,-0.01227,0.736,0.000
4.23,1.300,-0.01227,0.735,0.000
4.23,1.400,-0.01223,0.734,0.000
4.24,1.500,-0.01223,0.735,0.000
4.23,1.600,-0.01223,0.735,0.000
4.25,1.700,-0.01218,0.738,0.000
4.25,1.800,-0.01218,0.738,0.000
4.25,1.900,-0.01214,0.738,0.000
4.28,2.000,-0.01210,0.742,0.000
4.32,2.100,-0.01206,0.750,0.000
4.39,2.200,-0.01198,0.762,0.000
4.44,2.300,-0.01189,0.770,0.000
4.52,2.400,-0.01181,0.784,0.000
4.59,2.500,-0.01168,0.798,0.000
4.65,2.600,-0.01156,0.807,0.000
4.74,2.700,-0.01139,0.823,0.000
4.84,2.800,-0.01127,0.840,0.000
4.89,2.900,-0.01110,0.850,0.000
4.95,3.000,-0.01098,0.859,0.000
4.99,3.100,-0.01081,0.867,0.000
5.03,3.200,-0.01069,0.873,0.000
5.06,3.300,-0.01052,0.878,0.000
5.09,3.400,-0.01040,0.884,0.000
5.11,3.500,-0.01023,0.887,0.000
5.14,3.600,-0.01006,0.892,0.000
5.16,3.700,-0.00990,0.897,0.000
5.18,3.800,-0.00973,0.900,0.000
5.20,3.900,-0.00957,0.904,0.000
5.23,4.000,-0.00940,0.909,0.000
5.25,4.100,-0.00923,0.912,0.000
5.28,4.200,-0.00903,0.916,0.000
5.32,4.300,-0.00882,0.923,0.000
5.33,4.400,-0.00865,0.926,0.000
5.37,4.500,-0.00844,0.931,0.000
5.41,4.600,-0.00824,0.939,0.000
5.42,4.700,-0.00803,0.940,0.000
5.44,4.800,-0.00782,0.944,0.000
5.46,4.900,-0.00761,0.947,0.000
5.49,5.000,-0.00745,0.952,0.000
5.50,5.100,-0.00724,0.955,0.000
5.52,5.200,-0.00707,0.959,0.000
5.55,5.300,-0.00686,0.963,0.000
5.58,5.400,-0.00670,0.968,0.000
5.61,5.500,-0.00649,0.973,0.000
5.60,5.600,-0.00632,0.972,0.000
5.63,5.700,-0.00616,0.978,0.000
5.68,5.800,-0.00599,0.987,0.000
5.67,5.900,-0.00583,0.984,0.000
5.69,6.000,-0.00570,0.988,0.000
5.71,6.100,-0.00553,0.990,0.000
5.72,6.200,-0.00537,0.993,0.000
5.74,6.300,-0.00524,0.996,0.000
5.75,6.400,-0.00508,0.998,0.000
5.76,6.500,-0.00495,1.000,0.000
5.77,6.600,-0.00479,1.001,0.000
5.78,6.700,-0.00466,1.003,0.000
5.80,6.800,-0.00454,1.007,0.000
5.83,6.900,-0.00437,1.011,0.000
5.83,7.000,-0.00425,1.013,0.000
5.84,7.100,-0.00412,1.013,0.000
5.85,7.200,-0.00400,1.016,0.000
5.87,7.300,-0.00387,1.019,0.000
5.88,7.400,-0.00371,1.021,0.000
5.90,7.500,-0.00358,1.025,0.000
5.90,7.600,-0.00342,1.025,0.000
5.93,7.700,-0.00329,1.029,0.000
5.94,7.800,-0.00312,1.032,0.000
5.97,7.900,-0.00300,1.036,0.000
5.98,8.000,-0.00283,1.039,0.000
6.01,8.100,-0.00271,1.044,0.000
6.01,8.200,-0.00254,1.043,0.000
6.04,8.300,-0.00238,1.049,0.000
6.08,8.400,-0.00221,1.055,0.000
6.10,8.500,-0.00209,1.059,0.000
6.13,8.600,-0.00192,1.064,0.000
6.15,8.700,-0.00175,1.068,0.000
6.18,8.800,-0.00163,1.073,0.000
6.22,8.900,-0.00146,1.080,0.000
6.23,9.000,-0.00130,1.081,0.000
6.27,9.100,-0.00113,1.088,0.000
6.30,9.200,-0.00101,1.093,0.000
6.32,9.300,-0.00084,1.097,0.000
6.36,9.400,-0.00067,1.104,0.000
6.39,9.500,-0.00051,1.109,0.000
6.42,9.600,-0.00030,1.115,0.000
6.45,9.700,-0.00013,1.120,0.000
6.51,9.800,0.00008,1.130,0.000
6.55,9.900,0.00028,1.137,0.000
6.59,10.000,0.00049,1.144,0.000
6.64,10.100,0.00070,1.152,0.000
6.68,10.200,0.00091,1.160,0.000
6.73,10.300,0.00116,1.169,0.000
6.78,10.400,0.00136,1.177,0.000
6.83,10.500,0.00157,1.186,0.000
6.88,10.600,0.00178,1.195,0.000
6.91,10.700,0.00199,1.200,0.000
6.97,10.800,0.00219,1.209,0.000
7.01,10.900,0.00240,1.217,0.000
7.04,11.000,0.00261,1.223,0.000
7.09,11.100,0.00278,1.230,0.000
7.12,11.200,0.00298,1.236,0.000
7.17,11.300,0.00315,1.244,0.000
7.19,11.400,0.00332,1.248,0.000
7.22,11.500,0.00348,1.253,0.000
7.25,11.600,0.00365,1.259,0.000
7.28,11.700,0.00377,1.264,0.000
7.30,11.800,0.00394,1.267,0.000
7.32,11.900,0.00406,1.271,0.000
7.34,12.000,0.00423,1.275,0.000
7.38,12.100,0.00436,1.281,0.000
7.39,12.200,0.00448,1.282,0.000
7.42,12.300,0.00465,1.288,0.000
7.46,12.400,0.00477,1.295,0.000
7.47,12.500,0.00490,1.297,0.000
7.49,12.600,0.00506,1.301,0.000
7.51,12.700,0.00519,1.304,0.000
7.55,12.800,0.00531,1.310,0.000
7.56,12.900,0.00544,1.313,0.000
7.59,13.000,0.00560,1.317,0.000
7.63,13.100,0.00573,1.324,0.000
7.64,13.200,0.00589,1.326,0.000
7.67,13.300,0.00602,1.332,0.000
7.70,13.400,0.00618,1.338,0.000
7.72,13.500,0.00631,1.340,0.000
7.74,13.600,0.00647,1.344,0.000
7.78,13.700,0.00664,1.350,0.000
7.80,13.800,0.00677,1.354,0.000
7.80,13.900,0.00693,1.355,0.000
7.84,14.000,0.00710,1.362,0.000
7.87,14.100,0.00726,1.366,0.000
7.91,14.200,0.00739,1.373,0.000
7.94,14.300,0.00756,1.378,0.000
7.97,14.400,0.00772,1.384,0.000
7.99,14.500,0.00789,1.388,0.000
8.04,14.600,0.00805,1.395,0.000
8.05,14.700,0.00822,1.398,0.000
8.09,14.800,0.00839,1.405,0.000
8.13,14.900,0.00855,1.411,0.000
8.17,15.000,0.00872,1.418,0.000
8.20,15.100,0.00889,1.423,0.000
8.22,15.200,0.00905,1.428,0.000
8.27,15.300,0.00926,1.436,0.000
8.31,15.400,0.00947,1.442,0.000
8.36,15.500,0.00963,1.451,0.000
8.41,15.600,0.00984,1.459,0.000
8.47,15.700,0.01005,1.470,0.000
8.51,15.800,0.01030,1.478,0.000
8.57,15.900,0.01051,1.487,0.000
8.63,16.000,0.01071,1.498,0.000
8.68,16.100,0.01096,1.506,0.000
8.72,16.200,0.01117,1.513,0.000
8.76,16.300,0.01138,1.520,0.000
8.82,16.400,0.01159,1.531,0.000
8.88,16.500,0.01179,1.541,0.000
8.90,16.600,0.01200,1.545,0.000
8.96,16.700,0.01217,1.555,0.000
8.97,16.800,0.01238,1.558,0.000
9.02,16.900,0.01254,1.566,0.000
9.06,17.000,0.01275,1.572,0.000
9.10,17.100,0.01287,1.579,0.000
9.14,17.200,0.01304,1.587,0.000
9.18,17.300,0.01321,1.593,0.000
9.21,17.400,0.01337,1.598,0.000
9.25,17.500,0.01354,1.605,0.000
9.28,17.600,0.01371,1.611,0.000
9.31,17.700,0.01383,1.616,0.000
9.35,17.800,0.01400,1.622,0.000
9.38,17.900,0.01412,1.629,0.000
9.42,18.000,0.01425,1.636,0.000
9.45,18.100,0.01441,1.640,0.000
9.48,18.200,0.01454,1.645,0.000
9.52,18.300,0.01466,1.652,0.000
9.55,18.400,0.01483,1.659,0.000
9.59,18.500,0.01495,1.665,0.000
9.64,18.600,0.01512,1.673,0.000
9.67,18.700,0.01524,1.678,0.000
9.71,18.800,0.01541,1.685,0.000
9.75,18.900,0.01553,1.692,0.000
9.78,19.000,0.01570,1.698,0.000
9.83,19.100,0.01583,1.706,0.000
9.89,19.200,0.01599,1.717,0.000
9.91,19.300,0.01616,1.720,0.000
9.95,19.400,0.01632,1.727,0.000
10.00,19.500,0.01645,1.736,0.000
10.04,19.600,0.01661,1.743,0.000
10.08,19.700,0.01678,1.750,0.000
10.12,19.800,0.01695,1.757,0.000
10.17,19.900,0.01711,1.765,0.000
10.19,20.000,0.01728,1.769,0.000
10.23,20.100,0.01745,1.776,0.000
10.29,20.200,0.01757,1.785,0.000
10.33,20.300,0.01778,1.794,0.000
10.37,20.400,0.01790,1.801,0.000
10.41,20.500,0.01811,1.807,0.000
10.44,20.600,0.01828,1.813,0.000
10.50,20.700,0.01844,1.823,0.000
10.56,20.800,0.01861,1.833,0.000
10.62,20.900,0.01882,1.843,0.000
10.67,21.000,0.01902,1.852,0.000
10.71,21.100,0.01919,1.859,0.000
10.77,21.200,0.01940,1.870,0.000
10.81,21.300,0.01961,1.877,0.000
10.87,21.400,0.01981,1.887,0.000
10.94,21.500,0.02002,1.898,0.000
10.99,21.600,0.02027,1.908,0.000
11.04,21.700,0.02048,1.917,0.000
11.09,21.800,0.02069,1.925,0.000
11.14,21.900,0.02085,1.934,0.000
11.20,22.000,0.02106,1.944,0.000
11.24,22.100,0.02127,1.950,0.000
11.29,22.200,0.02148,1.960,0.000
11.34,22.300,0.02164,1.968,0.000
11.40,22.400,0.02185,1.979,0.000
11.45,22.500,0.02206,1.988,0.000
11.49,22.600,0.02222,1.994,0.000
11.53,22.700,0.02239,2.001,0.000
11.57,22.800,0.02256,2.009,0.000
11.61,22.900,0.02272,2.016,0.000
11.65,23.000,0.02285,2.023,0.000
11.69,23.100,0.02301,2.029,0.000
11.74,23.200,0.02318,2.038,0.000
11.77,23.300,0.02331,2.043,0.000
11.82,23.400,0.02347,2.053,0.000
11.86,23.500,0.02360,2.059,0.000
11.91,23.600,0.02372,2.067,0.000
11.93,23.700,0.02389,2.071,0.000
11.97,23.800,0.02401,2.078,0.000
12.02,23.900,0.02414,2.087,0.000
12.05,24.000,0.02430,2.091,0.000
12.10,24.100,0.02443,2.101,0.000
12.14,24.200,0.02455,2.108,0.000
12.18,24.300,0.02472,2.115,0.000
12.23,24.400,0.02484,2.122,0.000
12.25,24.500,0.02497,2.127,0.000
12.32,24.600,0.02513,2.138,0.000
12.36,24.700,0.02530,2.145,0.000
12.40,24.800,0.02542,2.153,0.001
12.45,24.900,0.02559,2.161,0.001
12.49,25.000,0.02572,2.168,0.001
12.53,25.100,0.02588,2.175,0.001
12.58,25.200,0.02605,2.183,0.001
12.62,25.300,0.02617,2.191,0.001
12.67,25.400,0.02634,2.200,0.001
12.72,25.500,0.02650,2.207,0.001
12.76,25.600,0.02663,2.216,0.001
12.81,25.700,0.02680,2.224,0.001
12.85,25.800,0.02696,2.230,0.001
12.89,25.900,0.02709,2.238,0.001
12.94,26.000,0.02729,2.247,0.001
13.00,26.100,0.02746,2.257,0.001
13.06,26.200,0.02763,2.267,0.001
13.11,26.300,0.02779,2.275,0.001
13.15,26.400,0.02796,2.283,0.001
13.22,26.500,0.02813,2.295,0.001
13.28,26.600,0.02833,2.305,0.001
13.36,26.700,0.02850,2.318,0.001
13.40,26.800,0.02871,2.327,0.001
13.47,26.900,0.02892,2.338,0.001
13.53,27.000,0.02912,2.350,0.001
13.62,27.100,0.02933,2.364,0.001
13.67,27.200,0.02954,2.373,0.001
13.75,27.300,0.02975,2.387,0.001
13.80,27.400,0.02995,2.395,0.001
13.88,27.500,0.03016,2.409,0.001
13.94,27.600,0.03037,2.420,0.001
14.01,27.700,0.03058,2.432,0.001
14.07,27.800,0.03079,2.442,0.001
14.14,27.900,0.03099,2.454,0.001
14.18,28.000,0.03120,2.462,0.001
14.26,28.100,0.03137,2.476,0.001
14.31,28.200,0.03153,2.484,0.001
14.36,28.300,0.03174,2.492,0.001
14.41,28.400,0.03191,2.502,0.001
14.45,28.500,0.03203,2.509,0.001
14.51,28.600,0.03220,2.518,0.001
14.56,28.700,0.03236,2.528,0.001
14.61,28.800,0.03249,2.535,0.001
14.65,28.900,0.03266,2.544,0.001
14.69,29.000,0.03278,2.550,0.001
14.75,29.100,0.03290,2.560,0.001
14.79,29.200,0.03307,2.567,0.001
14.83,29.300,0.03320,2.574,0.001
14.88,29.400,0.03332,2.583,0.001
14.92,29.500,0.03344,2.590,0.001
14.95,29.600,0.03357,2.596,0.001
15.00,29.700,0.03374,2.604,0.001
15.05,29.800,0.03386,2.612,0.001
15.09,29.900,0.03398,2.619,0.001
15.16,30.000,0.03415,2.632,0.001
15.19,30.100,0.03428,2.637,0.001
15.25,30.200,0.03440,2.648,0.001
15.30,30.300,0.03457,2.656,0.001
15.36,30.400,0.03473,2.667,0.001
15.42,30.500,0.03486,2.676,0.001
15.45,30.600,0.03502,2.682,0.001
15.49,30.700,0.03515,2.689,0.001
15.54,30.800,0.03531,2.698,0.001
15.59,30.900,0.03548,2.706,0.001
15.64,31.000,0.03561,2.715,0.001
15.71,31.100,0.03577,2.728,0.001
15.76,31.200,0.03594,2.736,0.001
15.80,31.300,0.03606,2.744,0.001
15.86,31.400,0.03623,2.754,0.001
15.91,31.500,0.03640,2.762,0.001
15.95,31.600,0.03652,2.769,0.001
16.01,31.700,0.03669,2.780,0.001
16.08,31.800,0.03685,2.792,0.001
16.14,31.900,0.03702,2.802,0.001
16.20,32.000,0.03718,2.813,0.001
16.23,32.100,0.03739,2.817,0.001
16.29,32.200,0.03756,2.829,0.001
16.37,32.300,0.03777,2.842,0.001
16.44,32.400,0.03793,2.854,0.001
16.51,32.500,0.03814,2.867,0.001
16.58,32.600,0.03835,2.879,0.001
16.66,32.700,0.03856,2.893,0.001
16.74,32.800,0.03876,2.906,0.001
16.81,32.900,0.03897,2.918,0.001
16.88,33.000,0.03918,2.931,0.001
16.98,33.100,0.03939,2.947,0.001
17.04,33.200,0.03959,2.959,0.001
17.12,33.300,0.03980,2.972,0.001
17.20,33.400,0.04001,2.985,0.001
17.28,33.500,0.04022,2.999,0.001
17.34,33.600,0.04038,3.010,0.001
17.41,33.700,0.04059,3.022,0.001
17.48,33.800,0.04080,3.035,0.001
17.54,33.900,0.04097,3.045,0.001
17.59,34.000,0.04113,3.053,0.001
17.65,34.100,0.04130,3.064,0.001
17.71,34.200,0.04146,3.074,0.001
17.75,34.300,0.04159,3.082,0.001
17.81,34.400,0.04176,3.092,0.001
17.85,34.500,0.04192,3.099,0.001
17.90,34.600,0.04205,3.107,0.001
17.96,34.700,0.04221,3.118,0.001
18.03,34.800,0.04234,3.129,0.001
18.07,34.900,0.04246,3.137,0.001
18.12,35.000,0.04263,3.145,0.001
18.17,35.100,0.04275,3.154,0.001
18.20,35.200,0.04288,3.160,0.001
18.24,35.300,0.04304,3.166,0.001
18.29,35.400,0.04317,3.176,0.001
18.36,35.500,0.04329,3.188,0.001
18.41,35.600,0.04342,3.195,0.001
18.45,35.700,0.04358,3.203,0.001
18.51,35.800,0.04371,3.214,0.001
18.57,35.900,0.04388,3.223,0.001
18.61,36.000,0.04400,3.231,0.001
18.67,36.100,0.04417,3.240,0.001
18.73,36.200,0.04429,3.252,0.001
18.77,36.300,0.04446,3.259,0.001
18.83,36.400,0.04462,3.268,0.001
18.89,36.500,0.04475,3.280,0.001
18.94,36.600,0.04491,3.288,0.001
19.00,36.700,0.04504,3.298,0.001
19.06,36.800,0.04521,3.309,0.001
19.11,36.900,0.04537,3.318,0.001
19.16,37.000,0.04550,3.327,0.001
19.22,37.100,0.04566,3.337,0.001
19.30,37.200,0.04583,3.350,0.001
19.34,37.300,0.04599,3.357,0.001
19.40,37.400,0.04616,3.368,0.001
19.46,37.500,0.04629,3.378,0.001
19.52,37.600,0.04645,3.389,0.001
19.59,37.700,0.04662,3.401,0.001
19.67,37.800,0.04683,3.414,0.001
19.75,37.900,0.04699,3.428,0.001
19.80,38.000,0.04716,3.437,0.001
19.86,38.100,0.04737,3.448,0.001
19.96,38.200,0.04753,3.465,0.001
20.03,38.300,0.04774,3.477,0.001
20.12,38.400,0.04795,3.494,0.001
20.21,38.500,0.04816,3.509,0.001
20.30,38.600,0.04836,3.524,0.001
20.38,38.700,0.04857,3.539,0.001
20.45,38.800,0.04878,3.550,0.001
20.54,38.900,0.04899,3.566,0.001
20.61,39.000,0.04919,3.578,0.001
20.70,39.100,0.04940,3.593,0.001
20.77,39.200,0.04961,3.605,0.001
20.82,39.300,0.04982,3.614,0.001
20.90,39.400,0.04998,3.629,0.001
20.96,39.500,0.05015,3.639,0.001
21.02,39.600,0.05036,3.650,0.001
21.08,39.700,0.05052,3.660,0.001
21.15,39.800,0.05069,3.671,0.001
21.21,39.900,0.05086,3.682,0.001
21.26,40.000,0.05102,3.690,0.001
21.32,40.100,0.05115,3.701,0.001
21.38,40.200,0.05131,3.711,0.001
21.43,40.300,0.05148,3.720,0.001
21.49,40.400,0.05160,3.730,0.001
21.53,40.500,0.05177,3.738,0.001
21.58,40.600,0.05190,3.747,0.001
21.62,40.700,0.05206,3.753,0.001
21.68,40.800,0.05219,3.764,0.001
21.73,40.900,0.05231,3.772,0.001
21.79,41.000,0.05244,3.783,0.001
21.84,41.100,0.05260,3.791,0.001
21.90,41.200,0.05273,3.802,0.001
21.94,41.300,0.05285,3.809,0.001
22.01,41.400,0.05302,3.821,0.001
22.06,41.500,0.05314,3.829,0.001
22.13,41.600,0.05327,3.842,0.001
22.18,41.700,0.05343,3.850,0.001
22.23,41.800,0.05356,3.860,0.001
22.29,41.900,0.05372,3.870,0.001
22.35,42.000,0.05385,3.880,0.001
22.39,42.100,0.05401,3.888,0.001
22.47,42.200,0.05418,3.901,0.001
22.53,42.300,0.05431,3.911,0.001
22.59,42.400,0.05447,3.921,0.001
22.64,42.500,0.05460,3.931,0.001
22.72,42.600,0.05476,3.945,0.001
22.77,42.700,0.05493,3.952,0.001
22.84,42.800,0.05510,3.964,0.001
22.90,42.900,0.05522,3.974,0.001
22.97,43.000,0.05539,3.988,0.001
23.04,43.100,0.05555,3.999,0.001
23.09,43.200,0.05572,4.009,0.001
23.16,43.300,0.05588,4.020,0.001
23.21,43.400,0.05605,4.029,0.001
23.29,43.500,0.05622,4.044,0.001
23.38,43.600,0.05638,4.058,0.001
23.46,43.700,0.05659,4.073,0.001
23.52,43.800,0.05676,4.083,0.001
23.62,43.900,0.05697,4.101,0.001
23.70,44.000,0.05717,4.114,0.001
23.80,44.100,0.05738,4.131,0.001
23.88,44.200,0.05759,4.146,0.001
23.97,44.300,0.05780,4.161,0.001
24.05,44.400,0.05805,4.174,0.001
24.17,44.500,0.05825,4.195,0.001
24.22,44.600,0.05846,4.205,0.001
24.32,44.700,0.05867,4.222,0.001
24.40,44.800,0.05888,4.236,0.001
24.49,44.900,0.05908,4.252,0.001
24.57,45.000,0.05929,4.266,0.001
24.66,45.100,0.05946,4.282,0.001
24.71,45.200,0.05967,4.289,0.001
24.78,45.300,0.05983,4.301,0.001
24.85,45.400,0.06000,4.313,0.001
24.92,45.500,0.06017,4.326,0.001
24.98,45.600,0.06033,4.336,0.001
25.04,45.700,0.06050,4.347,0.001
25.10,45.800,0.06066,4.357,0.001
25.16,45.900,0.06079,4.368,0.001
25.20,46.000,0.06095,4.374,0.001
25.27,46.100,0.06108,4.387,0.001
25.33,46.200,0.06125,4.397,0.001
25.40,46.300,0.06137,4.410,0.001
25.45,46.400,0.06154,4.418,0.001
25.50,46.500,0.06166,4.427,0.001
25.55,46.600,0.06179,4.435,0.001
25.61,46.700,0.06191,4.445,0.001
25.66,46.800,0.06204,4.454,0.001
25.74,46.900,0.06220,4.469,0.001
25.78,47.000,0.06233,4.476,0.001
25.86,47.100,0.06245,4.489,0.001
25.91,47.200,0.06262,4.499,0.001
25.99,47.300,0.06274,4.512,0.001
26.04,47.400,0.06291,4.521,0.001
26.12,47.500,0.06303,4.534,0.001
26.18,47.600,0.06320,4.544,0.001
26.25,47.700,0.06336,4.556,0.001
26.30,47.800,0.06349,4.566,0.001
26.37,47.900,0.06366,4.578,0.001
26.44,48.000,0.06382,4.591,0.001
26.52,48.100,0.06395,4.604,0.001
26.59,48.200,0.06411,4.615,0.001
26.67,48.300,0.06428,4.629,0.001
26.75,48.400,0.06445,4.644,0.001
26.82,48.500,0.06461,4.655,0.001
26.90,48.600,0.06478,4.670,0.001
26.97,48.700,0.06494,4.682,0.001
27.02,48.800,0.06507,4.691,0.001
27.11,48.900,0.06528,4.707,0.001
27.19,49.000,0.06544,4.720,0.001
27.26,49.100,0.06561,4.733,0.001
27.35,49.200,0.06582,4.747,0.001
27.43,49.300,0.06598,4.763,0.001
27.53,49.400,0.06619,4.779,0.001
15.76,49.500,0.06636,2.737,0.001
14.13,49.600,0.06656,2.453,0.001
14.13,49.700,0.06677,2.452,0.001
14.27,49.800,0.06698,2.478,0.001
14.46,49.900,0.06719,2.510,0.001
14.64,50.000,0.06744,2.542,0.001
14.77,50.100,0.06765,2.564,0.001
14.92,50.200,0.06785,2.590,0.001
15.03,50.300,0.06806,2.609,0.001
15.16,50.400,0.06827,2.632,0.001
15.26,50.500,0.06848,2.649,0.001
15.36,50.600,0.06868,2.667,0.001
15.50,50.700,0.06889,2.691,0.001
15.56,50.800,0.06906,2.702,0.001
15.66,50.900,0.06927,2.719,0.001
15.75,51.000,0.06943,2.735,0.001
15.82,51.100,0.06964,2.746,0.001
15.90,51.200,0.06981,2.760,0.001
15.98,51.300,0.06997,2.774,0.001
16.06,51.400,0.07010,2.789,0.001
16.14,51.500,0.07026,2.801,0.001
16.20,51.600,0.07043,2.812,0.001
16.26,51.700,0.07055,2.823,0.001
16.31,51.800,0.07072,2.832,0.001
16.38,51.900,0.07084,2.843,0.001
16.46,52.000,0.07097,2.857,0.001
16.50,52.100,0.07114,2.864,0.001
16.56,52.200,0.07126,2.874,0.001
16.62,52.300,0.07139,2.886,0.001
16.67,52.400,0.07155,2.894,0.001
16.75,52.500,0.07168,2.907,0.001
16.80,52.600,0.07180,2.917,0.001
16.87,52.700,0.07197,2.929,0.001
16.94,52.800,0.07209,2.940,0.001
16.99,52.900,0.07226,2.949,0.001
17.06,53.000,0.07242,2.962,0.001
17.12,53.100,0.07255,2.973,0.001
17.18,53.200,0.07271,2.983,0.001
17.25,53.300,0.07284,2.995,0.001
17.29,53.400,0.07301,3.002,0.001
17.38,53.500,0.07317,3.017,0.001
17.43,53.600,0.07334,3.026,0.001
17.49,53.700,0.07346,3.036,0.001
17.57,53.800,0.07363,3.050,0.001
17.61,53.900,0.07380,3.057,0.001
17.70,54.000,0.07396,3.072,0.001
17.74,54.100,0.07409,3.080,0.001
17.81,54.200,0.07425,3.093,0.001
17.88,54.300,0.07442,3.105,0.001
17.93,54.400,0.07458,3.112,0.001
18.00,54.500,0.07475,3.124,0.001
18.05,54.600,0.07492,3.134,0.001
18.11,54.700,0.07508,3.144,0.001
18.18,54.800,0.07525,3.156,0.001
18.26,54.900,0.07546,3.170,0.001
18.36,55.000,0.07562,3.187,0.001
18.41,55.100,0.07583,3.196,0.001
18.49,55.200,0.07604,3.209,0.001
18.57,55.300,0.07625,3.224,0.002
18.64,55.400,0.07646,3.236,0.002
18.72,55.500,0.07666,3.250,0.002
18.81,55.600,0.07687,3.266,0.002
18.88,55.700,0.07708,3.278,0.002
18.97,55.800,0.07729,3.292,0.002
19.05,55.900,0.07749,3.307,0.002
19.12,56.000,0.07770,3.319,0.002
19.19,56.100,0.07791,3.331,0.002
19.27,56.200,0.07808,3.345,0.002
19.34,56.300,0.07828,3.358,0.002
19.42,56.400,0.07849,3.371,0.002
19.50,56.500,0.07866,3.384,0.002
19.55,56.600,0.07887,3.394,0.002
19.61,56.700,0.07903,3.405,0.002
19.67,56.800,0.07920,3.415,0.002
19.73,56.900,0.07936,3.425,0.002
19.81,57.000,0.07949,3.439,0.002
19.85,57.100,0.07965,3.446,0.002
19.90,57.200,0.07982,3.454,0.002
19.96,57.300,0.07995,3.464,0.002
20.00,57.400,0.08011,3.472,0.002
20.05,57.500,0.08024,3.481,0.002
20.12,57.600,0.08040,3.492,0.002
20.14,57.700,0.08053,3.497,0.002
20.21,57.800,0.08065,3.509,0.002
20.26,57.900,0.08082,3.516,0.002
20.29,58.000,0.08094,3.523,0.002
20.36,58.100,0.08107,3.534,0.002
20.40,58.200,0.08119,3.542,0.002
20.46,58.300,0.08136,3.552,0.002
20.52,58.400,0.08148,3.562,0.002
20.56,58.500,0.08161,3.569,0.002
20.62,58.600,0.08177,3.580,0.002
20.69,58.700,0.08190,3.592,0.002
20.73,58.800,0.08207,3.598,0.002
20.79,58.900,0.08219,3.608,0.002
20.84,59.000,0.08236,3.618,0.002
20.90,59.100,0.08248,3.628,0.002
20.95,59.200,0.08265,3.637,0.002
21.01,59.300,0.08281,3.647,0.002
21.07,59.400,0.08294,3.658,0.002
21.12,59.500,0.08310,3.666,0.002
21.18,59.600,0.08327,3.676,0.002
21.24,59.700,0.08339,3.688,0.002
21.30,59.800,0.08356,3.697,0.002
21.35,59.900,0.08373,3.706,0.002
21.41,60.000,0.08385,3.717,0.002
21.46,60.100,0.08402,3.726,0.002
21.53,60.200,0.08418,3.737,0.002
21.59,60.300,0.08435,3.749,0.002
21.66,60.400,0.08452,3.759,0.002
21.72,60.500,0.08468,3.770,0.002
21.79,60.600,0.08485,3.783,0.002
21.86,60.700,0.08506,3.795,0.002
21.95,60.800,0.08526,3.811,0.002
22.02,60.900,0.08547,3.822,0.002
22.11,61.000,0.08568,3.838,0.002
22.19,61.100,0.08589,3.852,0.002
22.27,61.200,0.08610,3.865,0.002
22.36,61.300,0.08630,3.882,0.002
22.44,61.400,0.08655,3.895,0.002
22.52,61.500,0.08676,3.909,0.002
22.60,61.600,0.08697,3.923,0.002
22.67,61.700,0.08718,3.935,0.002
22.76,61.800,0.08738,3.951,0.002
22.83,61.900,0.08759,3.963,0.002
22.90,62.000,0.08780,3.976,0.002
22.97,62.100,0.08797,3.987,0.002
23.04,62.200,0.08817,3.999,0.002
23.11,62.300,0.08834,4.011,0.002
23.15,62.400,0.08851,4.019,0.002
23.22,62.500,0.08867,4.030,0.002
23.26,62.600,0.08880,4.039,0.002
23.31,62.700,0.08896,4.047,0.002
23.38,62.800,0.08909,4.058,0.002
14.62,62.900,0.08925,2.538,0.002
7.59,63.000,0.08938,1.318,0.002
7.27,63.100,0.08955,1.262,0.002
7.33,63.200,0.08967,1.273,0.002
7.43,63.300,0.08979,1.290,0.002
7.52,63.400,0.08992,1.305,0.002
7.57,63.500,0.09009,1.314,0.002
7.65,63.600,0.09021,1.328,0.002
7.70,63.700,0.09033,1.337,0.002
7.77,63.800,0.09046,1.350,0.002
7.80,63.900,0.09063,1.355,0.002
7.87,64.000,0.09075,1.365,0.002
7.91,64.100,0.09092,1.374,0.002
7.96,64.200,0.09104,1.382,0.002
8.02,64.300,0.09117,1.393,0.002
8.05,64.400,0.09133,1.398,0.002
8.08,64.500,0.09146,1.402,0.002
8.14,64.600,0.09162,1.413,0.002
8.18,64.700,0.09179,1.420,0.002
8.23,64.800,0.09191,1.428,0.002
8.26,64.900,0.09208,1.434,0.002
8.31,65.000,0.09225,1.443,0.002
8.37,65.100,0.09237,1.453,0.002
8.40,65.200,0.09254,1.458,0.002
8.45,65.300,0.09270,1.467,0.002
8.49,65.400,0.09287,1.474,0.002
8.52,65.500,0.09299,1.479,0.002
8.57,65.600,0.09316,1.487,0.002
8.63,65.700,0.09333,1.497,0.002
8.66,65.800,0.09349,1.503,0.002
8.70,65.900,0.09366,1.510,0.002
8.74,66.000,0.09383,1.517,0.002
8.80,66.100,0.09399,1.528,0.002
8.84,66.200,0.09416,1.534,0.002
8.89,66.300,0.09437,1.543,0.002
8.92,66.400,0.09457,1.549,0.002
8.99,66.500,0.09474,1.560,0.002
9.03,66.600,0.09495,1.568,0.002
9.11,66.700,0.09516,1.581,0.002
9.16,66.800,0.09536,1.589,0.002
9.21,66.900,0.09557,1.599,0.002
9.26,67.000,0.09582,1.608,0.002
9.32,67.100,0.09603,1.618,0.002
9.37,67.200,0.09624,1.626,0.002
9.42,67.300,0.09644,1.636,0.002
9.47,67.400,0.09665,1.643,0.002
9.53,67.500,0.09686,1.655,0.002
9.56,67.600,0.09707,1.659,0.002
9.61,67.700,0.09723,1.669,0.002
9.66,67.800,0.09744,1.676,0.002
9.71,67.900,0.09761,1.685,0.002
9.75,68.000,0.09781,1.692,0.002
9.76,68.100,0.09798,1.695,0.002
9.81,68.200,0.09815,1.704,0.002
9.85,68.300,0.09831,1.710,0.002
9.88,68.400,0.09844,1.715,0.002
9.93,68.500,0.09860,1.723,0.002
9.94,68.600,0.09873,1.725,0.002
9.98,68.700,0.09890,1.732,0.002
10.01,68.800,0.09902,1.737,0.002
10.04,68.900,0.09919,1.743,0.002
10.08,69.000,0.09931,1.750,0.002
10.09,69.100,0.09944,1.752,0.002
10.14,69.200,0.09956,1.761,0.002
10.15,69.300,0.09973,1.763,0.002
10.20,69.400,0.09985,1.771,0.002
10.23,69.500,0.09998,1.776,0.002
10.25,69.600,0.10014,1.779,0.002
10.30,69.700,0.10027,1.787,0.002
10.33,69.800,0.10039,1.793,0.002
10.36,69.900,0.10056,1.798,0.002
10.39,70.000,0.10068,1.804,0.002
10.42,70.100,0.10085,1.809,0.002
10.46,70.200,0.10097,1.815,0.002
10.49,70.300,0.10114,1.821,0.002
10.54,70.400,0.10131,1.829,0.002
10.57,70.500,0.10143,1.834,0.002
10.62,70.600,0.10160,1.843,0.002
10.65,70.700,0.10176,1.848,0.002
10.70,70.800,0.10193,1.857,0.002
10.70,70.900,0.10205,1.858,0.002
10.75,71.000,0.10222,1.867,0.002
10.78,71.100,0.10239,1.871,0.002
10.82,71.200,0.10255,1.878,0.002
10.87,71.300,0.10268,1.887,0.002
10.92,71.400,0.10284,1.895,0.002
10.93,71.500,0.10301,1.898,0.002
10.97,71.600,0.10318,1.904,0.002
11.03,71.700,0.10334,1.914,0.002
11.05,71.800,0.10351,1.918,0.002
11.09,71.900,0.10372,1.925,0.002
11.13,72.000,0.10388,1.933,0.002
11.18,72.100,0.10405,1.940,0.002
11.22,72.200,0.10426,1.948,0.002
11.27,72.300,0.10446,1.956,0.002
11.31,72.400,0.10467,1.963,0.002
11.37,72.500,0.10488,1.974,0.002
11.41,72.600,0.10509,1.980,0.002
11.45,72.700,0.10529,1.988,0.002
11.49,72.800,0.10550,1.994,0.002
11.54,72.900,0.10571,2.003,0.002
11.61,73.000,0.10592,2.015,0.002
11.64,73.100,0.10613,2.021,0.002
11.67,73.200,0.10629,2.026,0.002
11.72,73.300,0.10650,2.035,0.002
11.76,73.400,0.10671,2.042,0.002
11.80,73.500,0.10687,2.048,0.002
11.84,73.600,0.10708,2.055,0.002
11.86,73.700,0.10725,2.059,0.002
11.90,73.800,0.10741,2.066,0.002
11.95,73.900,0.10758,2.074,0.002
11.98,74.000,0.10775,2.079,0.002
12.00,74.100,0.10787,2.083,0.002
12.03,74.200,0.10804,2.089,0.002
12.06,74.300,0.10820,2.094,0.002
12.11,74.400,0.10833,2.103,0.002
12.13,74.500,0.10849,2.106,0.002
12.16,74.600,0.10862,2.111,0.002
12.19,74.700,0.10874,2.117,0.002
12.22,74.800,0.10891,2.121,0.002
12.23,74.900,0.10903,2.124,0.002
12.25,75.000,0.10916,2.126,0.002
12.29,75.100,0.10928,2.134,0.002
12.33,75.200,0.10941,2.141,0.002
12.36,75.300,0.10958,2.145,0.002
12.39,75.400,0.10970,2.151,0.002
12.42,75.500,0.10982,2.157,0.002
12.47,75.600,0.10999,2.165,0.002
12.49,75.700,0.11012,2.169,0.002
12.53,75.800,0.11028,2.175,0.002
12.57,75.900,0.11041,2.181,0.002
12.59,76.000,0.11057,2.186,0.002
12.63,76.100,0.11070,2.193,0.002
12.66,76.200,0.11086,2.198,0.002
12.69,76.300,0.11099,2.204,0.002
12.74,76.400,0.11115,2.211,0.002
12.76,76.500,0.11132,2.215,0.002
12.78,76.600,0.11145,2.218,0.002
12.83,76.700,0.11161,2.227,0.002
12.87,76.800,0.11178,2.235,0.002
12.91,76.900,0.11190,2.241,0.002
12.93,77.000,0.11207,2.245,0.002
12.97,77.100,0.11223,2.252,0.002
13.01,77.200,0.11240,2.258,0.002
13.05,77.300,0.11257,2.265,0.002
13.09,77.400,0.11273,2.272,0.002
13.14,77.500,0.11290,2.281,0.002
13.15,77.600,0.11307,2.284,0.002
13.19,77.700,0.11323,2.290,0.002
13.23,77.800,0.11344,2.297,0.002
13.29,77.900,0.11361,2.308,0.002
13.32,78.000,0.11381,2.313,0.002
13.38,78.100,0.11402,2.323,0.002
13.42,78.200,0.11423,2.330,0.002
13.49,78.300,0.11448,2.341,0.002
13.54,78.400,0.11469,2.350,0.002
13.58,78.500,0.11489,2.358,0.002
13.63,78.600,0.11510,2.367,0.002
13.67,78.700,0.11531,2.374,0.002
13.72,78.800,0.11552,2.382,0.002
13.76,78.900,0.11573,2.388,0.002
13.81,79.000,0.11593,2.398,0.002
13.84,79.100,0.11614,2.403,0.002
13.89,79.200,0.11635,2.411,0.002
13.93,79.300,0.11651,2.419,0.002
13.95,79.400,0.11672,2.422,0.002
13.98,79.500,0.11689,2.427,0.002
14.04,79.600,0.11706,2.437,0.002
14.06,79.700,0.11718,2.441,0.002
14.10,79.800,0.11735,2.449,0.002
14.12,79.900,0.11751,2.451,0.002
14.16,80.000,0.11764,2.457,0.002
14.19,80.100,0.11776,2.464,0.002
14.23,80.200,0.11793,2.470,0.002
14.26,80.300,0.11805,2.475,0.002
14.28,80.400,0.11822,2.480,0.002
14.29,80.500,0.11834,2.481,0.002
14.36,80.600,0.11847,2.492,0.002
14.37,80.700,0.11859,2.494,0.002
14.40,80.800,0.11872,2.500,0.002
14.42,80.900,0.11884,2.504,0.002
14.45,81.000,0.11897,2.509,0.002
14.49,81.100,0.11913,2.516,0.002
14.53,81.200,0.11926,2.522,0.002
14.56,81.300,0.11942,2.528,0.002
14.61,81.400,0.11955,2.536,0.002
14.62,81.500,0.11971,2.539,0.002
14.67,81.600,0.11984,2.546,0.002
14.69,81.700,0.12001,2.550,0.002
14.74,81.800,0.12017,2.558,0.002
14.77,81.900,0.12030,2.564,0.002
14.79,82.000,0.12046,2.568,0.002
14.82,82.100,0.12059,2.572,0.002
14.87,82.200,0.12075,2.581,0.002
14.90,82.300,0.12092,2.587,0.002
14.95,82.400,0.12109,2.595,0.002
14.98,82.500,0.12125,2.601,0.002
15.02,82.600,0.12138,2.607,0.002
15.05,82.700,0.12154,2.613,0.002
15.10,82.800,0.12171,2.621,0.002
15.11,82.900,0.12188,2.622,0.002
15.15,83.000,0.12204,2.630,0.002
15.19,83.100,0.12221,2.636,0.002
15.23,83.200,0.12237,2.644,0.002
15.26,83.300,0.12258,2.649,0.002
15.33,83.400,0.12275,2.661,0.002
15.36,83.500,0.12296,2.667,0.002
15.42,83.600,0.12316,2.677,0.002
15.46,83.700,0.12333,2.684,0.002
15.52,83.800,0.12358,2.694,0.002
15.57,83.900,0.12379,2.703,0.002
15.63,84.000,0.12399,2.713,0.002
15.67,84.100,0.12420,2.721,0.002
15.73,84.200,0.12445,2.730,0.002
15.77,84.300,0.12466,2.737,0.002
15.82,84.400,0.12487,2.746,0.002
15.87,84.500,0.12508,2.754,0.002
15.92,84.600,0.12528,2.764,0.002
15.94,84.700,0.12549,2.768,0.002
15.99,84.800,0.12566,2.775,0.002
16.04,84.900,0.12586,2.784,0.002
16.08,85.000,0.12603,2.791,0.002
16.10,85.100,0.12620,2.795,0.002
16.13,85.200,0.12636,2.801,0.002
16.17,85.300,0.12653,2.807,0.002
16.21,85.400,0.12670,2.814,0.002
16.23,85.500,0.12686,2.818,0.002
16.27,85.600,0.12699,2.824,0.002
16.31,85.700,0.12715,2.831,0.003
16.32,85.800,0.12728,2.834,0.003
16.35,85.900,0.12744,2.839,0.003
16.39,86.000,0.12757,2.846,0.003
16.43,86.100,0.12773,2.852,0.003
16.46,86.200,0.12786,2.857,0.003
16.47,86.300,0.12798,2.860,0.003
16.50,86.400,0.12815,2.864,0.003
16.55,86.500,0.12828,2.872,0.003
16.57,86.600,0.12840,2.876,0.003
15.93,86.700,0.12857,2.765,0.003
10.60,86.800,0.12869,1.840,0.003
10.62,86.900,0.12882,1.843,0.003
10.68,87.000,0.12898,1.854,0.003
10.72,87.100,0.12911,1.861,0.003
10.80,87.200,0.12927,1.875,0.003
10.83,87.300,0.12944,1.880,0.003
10.87,87.400,0.12956,1.887,0.003
10.93,87.500,0.12973,1.898,0.003
10.95,87.600,0.12990,1.901,0.003
10.99,87.700,0.13002,1.908,0.003
11.04,87.800,0.13019,1.916,0.003
11.06,87.900,0.13035,1.920,0.003
11.12,88.000,0.13052,1.930,0.003
11.14,88.100,0.13069,1.933,0.003
11.18,88.200,0.13085,1.942,0.003
11.21,88.300,0.13102,1.946,0.003
11.25,88.400,0.13114,1.952,0.003
11.29,88.500,0.13131,1.960,0.003
11.32,88.600,0.13147,1.965,0.003
11.36,88.700,0.13168,1.972,0.003
11.39,88.800,0.13185,1.977,0.003
11.41,88.900,0.13202,1.981,0.003
11.47,89.000,0.13218,1.992,0.003
11.50,89.100,0.13239,1.996,0.003
11.55,89.200,0.13256,2.005,0.003
11.60,89.300,0.13276,2.013,0.003
11.65,89.400,0.13297,2.022,0.003
11.67,89.500,0.13318,2.026,0.003
11.72,89.600,0.13343,2.035,0.003
11.75,89.700,0.13364,2.040,0.003
11.79,89.800,0.13384,2.048,0.003
11.85,89.900,0.13405,2.057,0.003
11.89,90.000,0.13426,2.064,0.003
11.93,90.100,0.13447,2.071,0.003
11.97,90.200,0.13467,2.078,0.003
11.99,90.300,0.13488,2.082,0.003
12.02,90.400,0.13505,2.087,0.003
12.05,90.500,0.13526,2.093,0.003
12.09,90.600,0.13542,2.099,0.003
12.12,90.700,0.13563,2.105,0.003
12.13,90.800,0.13580,2.106,0.003
12.18,90.900,0.13596,2.114,0.003
12.19,91.000,0.13613,2.116,0.003
12.23,91.100,0.13630,2.124,0.003
12.24,91.200,0.13642,2.126,0.003
12.27,91.300,0.13659,2.129,0.003
12.30,91.400,0.13675,2.136,0.003
12.32,91.500,0.13688,2.140,0.003
12.35,91.600,0.13700,2.145,0.003
12.38,91.700,0.13717,2.150,0.003
12.40,91.800,0.13729,2.153,0.003
12.42,91.900,0.13746,2.156,0.003
12.43,92.000,0.13758,2.158,0.003
12.46,92.100,0.13771,2.162,0.003
12.49,92.200,0.13787,2.168,0.003
12.50,92.300,0.13800,2.171,0.003
12.54,92.400,0.13812,2.177,0.003
12.57,92.500,0.13825,2.182,0.003
12.59,92.600,0.13841,2.186,0.003
12.63,92.700,0.13854,2.193,0.003
12.65,92.800,0.13871,2.196,0.003
12.68,92.900,0.13883,2.200,0.003
12.70,93.000,0.13900,2.205,0.003
12.72,93.100,0.13912,2.209,0.003
12.76,93.200,0.13929,2.215,0.003
12.80,93.300,0.13945,2.221,0.003
12.81,93.400,0.13958,2.223,0.003
12.85,93.500,0.13974,2.230,0.003
12.88,93.600,0.13991,2.236,0.003
12.91,93.700,0.14004,2.240,0.003
12.94,93.800,0.14020,2.246,0.003
12.96,93.900,0.14037,2.250,0.003
12.98,94.000,0.14049,2.253,0.003
13.01,94.100,0.14066,2.258,0.003
13.04,94.200,0.14083,2.264,0.003
13.07,94.300,0.14099,2.269,0.003
13.11,94.400,0.14116,2.276,0.003
13.13,94.500,0.14132,2.280,0.003
13.17,94.600,0.14149,2.286,0.003
13.21,94.700,0.14170,2.294,0.003
13.25,94.800,0.14186,2.300,0.003
13.28,94.900,0.14207,2.305,0.003
13.33,95.000,0.14228,2.314,0.003
13.36,95.100,0.14249,2.319,0.003
13.41,95.200,0.14270,2.328,0.003
13.45,95.300,0.14290,2.335,0.003
13.50,95.400,0.14315,2.343,0.003
13.53,95.500,0.14336,2.349,0.003
13.55,95.600,0.14357,2.353,0.003
13.60,95.700,0.14378,2.361,0.003
13.65,95.800,0.14398,2.370,0.003
13.68,95.900,0.14415,2.374,0.003
13.70,96.000,0.14436,2.378,0.003
13.74,96.100,0.14457,2.386,0.003
13.78,96.200,0.14473,2.392,0.003
13.79,96.300,0.14490,2.394,0.003
13.83,96.400,0.14511,2.400,0.003
13.85,96.500,0.14527,2.404,0.003
13.89,96.600,0.14544,2.412,0.003
13.91,96.700,0.14556,2.414,0.003
13.93,96.800,0.14573,2.419,0.003
13.96,96.900,0.14589,2.423,0.003
13.99,97.000,0.14602,2.428,0.003
14.01,97.100,0.14614,2.431,0.003
14.03,97.200,0.14631,2.436,0.003
14.05,97.300,0.14644,2.439,0.003
14.07,97.400,0.14656,2.442,0.003
14.09,97.500,0.14668,2.445,0.003
14.10,97.600,0.14685,2.448,0.003
14.14,97.700,0.14698,2.454,0.003
14.17,97.800,0.14710,2.460,0.003
14.17,97.900,0.14722,2.461,0.003
14.20,98.000,0.14735,2.466,0.003
14.23,98.100,0.14752,2.470,0.003
14.26,98.200,0.14764,2.475,0.003
14.30,98.300,0.14776,2.483,0.003
14.33,98.400,0.14793,2.487,0.003
14.35,98.500,0.14806,2.491,0.003
14.39,98.600,0.14822,2.498,0.003
14.39,98.620,0.14822,2.499,0.003