File: data-files/CWRU/0900-15-35B.txt
""
"Test Method","Will_Huddleston_Disks.msm"
"Sample I. D.","900-150-35B.mss"
"Specimen Number","1"

"Load (N)","Time (s)","Extension (mm)","Stress (MPa)","Strain (mm/mm)"

3.28,0.200,0.00259,0.613,0.000
3.29,0.300,0.00259,0.614,0.000
3.29,0.400,0.00263,0.614,0.000
3.28,0.500,0.00263,0.613,0.000
3.27,0.600,0.00263,0.611,0.000
3.29,0.700,0.00263,0.614,0.000
3.28,0.800,0.00267,0.612,0.000
3.29,0.900,0.00267,0.614,0.000
3.29,1.000,0.00267,0.615,0.000
3.30,1.100,0.00272,0.616,0.000
3.30,1.200,0.00272,0.616,0.000
3.30,1.300,0.00276,0.617,0.000
3.32,1.400,0.00276,0.620,0.000
3.33,1.500,0.00276,0.622,0.000
3.33,1.600,0.00280,0.623,0.000
3.38,1.700,0.00284,0.631,0.000
3.41,1.800,0.00288,0.637,0.000
3.50,1.900,0.00296,0.653,0.000
3.61,2.000,0.00305,0.675,0.000
3.75,2.100,0.00317,0.699,0.000
3.86,2.200,0.00330,0.721,0.000
3.93,2.300,0.00342,0.735,0.000
4.02,2.400,0.00359,0.751,0.000
4.09,2.500,0.00371,0.764,0.000
4.16,2.600,0.00384,0.777,0.000
4.20,2.700,0.00400,0.783,0.000
4.26,2.800,0.00413,0.796,0.000
4.30,2.900,0.00429,0.803,0.000
4.33,3.000,0.00442,0.809,0.000
4.37,3.100,0.00454,0.816,0.000
4.40,3.200,0.00471,0.821,0.000
4.43,3.300,0.00483,0.828,0.000
4.46,3.400,0.00500,0.832,0.000
4.50,3.500,0.00517,0.840,0.000
4.54,3.600,0.00529,0.848,0.000
4.57,3.700,0.00546,0.854,0.000
4.59,3.800,0.00558,0.856,0.000
4.62,3.900,0.00575,0.863,0.000
4.66,4.000,0.00587,0.870,0.000
4.66,4.100,0.00604,0.871,0.000
4.71,4.200,0.00621,0.880,0.000
4.73,4.300,0.00633,0.884,0.000
4.76,4.400,0.00650,0.889,0.000
4.80,4.500,0.00666,0.897,0.000
4.85,4.600,0.00683,0.906,0.000
4.87,4.700,0.00700,0.910,0.000
4.90,4.800,0.00716,0.915,0.000
4.93,4.900,0.00737,0.921,0.000
4.97,5.000,0.00754,0.928,0.000
5.01,5.100,0.00774,0.936,0.000
5.04,5.200,0.00795,0.941,0.000
5.08,5.300,0.00812,0.949,0.000
5.13,5.400,0.00833,0.958,0.000
5.15,5.500,0.00853,0.962,0.000
5.20,5.600,0.00874,0.970,0.000
5.22,5.700,0.00895,0.974,0.000
5.27,5.800,0.00916,0.984,0.000
5.31,5.900,0.00936,0.991,0.000
5.34,6.000,0.00957,0.997,0.000
5.37,6.100,0.00978,1.003,0.000
5.40,6.200,0.00999,1.008,0.000
5.45,6.300,0.01015,1.017,0.000
5.47,6.400,0.01036,1.022,0.000
5.51,6.500,0.01053,1.028,0.000
5.53,6.600,0.01069,1.032,0.000
5.56,6.700,0.01086,1.039,0.000
5.59,6.800,0.01103,1.043,0.000
5.62,6.900,0.01119,1.048,0.000
5.63,7.000,0.01136,1.052,0.000
5.66,7.100,0.01148,1.057,0.000
5.68,7.200,0.01165,1.061,0.000
5.70,7.300,0.01177,1.064,0.000
5.72,7.400,0.01194,1.069,0.000
5.75,7.500,0.01207,1.073,0.000
5.77,7.600,0.01219,1.078,0.000
5.79,7.700,0.01231,1.081,0.000
5.82,7.800,0.01248,1.087,0.000
5.83,7.900,0.01261,1.089,0.000
5.85,8.000,0.01273,1.093,0.000
5.88,8.100,0.01285,1.098,0.000
5.92,8.200,0.01302,1.105,0.000
5.93,8.300,0.01315,1.107,0.000
5.95,8.400,0.01331,1.111,0.000
5.98,8.500,0.01344,1.116,0.000
6.01,8.600,0.01356,1.122,0.000
6.03,8.700,0.01373,1.126,0.000
6.06,8.800,0.01389,1.131,0.000
6.09,8.900,0.01402,1.136,0.000
6.12,9.000,0.01418,1.144,0.000
6.13,9.100,0.01431,1.145,0.000
6.16,9.200,0.01448,1.150,0.000
6.18,9.300,0.01464,1.154,0.000
6.22,9.400,0.01477,1.161,0.000
6.24,9.500,0.01493,1.165,0.000
6.28,9.600,0.01510,1.173,0.000
6.30,9.700,0.01527,1.175,0.000
6.32,9.800,0.01539,1.180,0.000
6.35,9.900,0.01556,1.186,0.000
6.38,10.000,0.01572,1.191,0.000
6.41,10.100,0.01589,1.196,0.000
6.44,10.200,0.01605,1.203,0.000
6.47,10.300,0.01622,1.209,0.000
6.51,10.400,0.01639,1.215,0.000
6.54,10.500,0.01655,1.221,0.000
6.55,10.600,0.01672,1.224,0.000
6.61,10.700,0.01693,1.234,0.000
6.65,10.800,0.01714,1.242,0.000
6.67,10.900,0.01730,1.246,0.000
6.73,11.000,0.01751,1.257,0.000
6.76,11.100,0.01772,1.262,0.000
6.80,11.200,0.01792,1.269,0.000
6.84,11.300,0.01817,1.277,0.000
6.88,11.400,0.01838,1.284,0.000
6.91,11.500,0.01859,1.291,0.000
6.95,11.600,0.01876,1.297,0.000
6.98,11.700,0.01896,1.303,0.000
7.03,11.800,0.01917,1.312,0.000
7.07,11.900,0.01938,1.320,0.000
7.07,12.000,0.01959,1.321,0.000
7.11,12.100,0.01975,1.328,0.000
7.15,12.200,0.01996,1.335,0.000
7.19,12.300,0.02013,1.342,0.000
7.19,12.400,0.02029,1.343,0.000
7.22,12.500,0.02046,1.349,0.000
7.26,12.600,0.02058,1.355,0.000
7.27,12.700,0.02075,1.357,0.000
7.30,12.800,0.02092,1.364,0.000
7.32,12.900,0.02104,1.366,0.000
7.34,13.000,0.02121,1.371,0.000
7.36,13.100,0.02133,1.375,0.000
7.39,13.200,0.02150,1.381,0.000
7.42,13.300,0.02162,1.385,0.000
7.43,13.400,0.02175,1.388,0.000
7.47,13.500,0.02191,1.395,0.000
7.49,13.600,0.02204,1.399,0.000
7.52,13.700,0.02216,1.403,0.000
7.54,13.800,0.02233,1.408,0.000
7.56,13.900,0.02245,1.413,0.000
7.60,14.000,0.02258,1.419,0.000
7.62,14.100,0.02275,1.422,0.000
7.65,14.200,0.02287,1.428,0.000
7.68,14.300,0.02304,1.433,0.000
7.70,14.400,0.02316,1.437,0.000
7.73,14.500,0.02333,1.443,0.000
7.75,14.600,0.02349,1.448,0.000
7.79,14.700,0.02362,1.455,0.000
7.81,14.800,0.02378,1.459,0.000
7.85,14.900,0.02395,1.465,0.000
7.87,15.000,0.02407,1.470,0.000
7.89,15.100,0.02424,1.474,0.000
7.91,15.200,0.02441,1.477,0.000
7.95,15.300,0.02453,1.484,0.000
8.00,15.400,0.02470,1.493,0.000
8.01,15.500,0.02486,1.496,0.000
8.06,15.600,0.02503,1.505,0.000
8.08,15.700,0.02520,1.509,0.000
8.12,15.800,0.02536,1.516,0.000
8.15,15.900,0.02553,1.523,0.001
8.18,16.000,0.02570,1.527,0.001
8.21,16.100,0.02586,1.534,0.001
8.24,16.200,0.02603,1.539,0.001
8.29,16.300,0.02624,1.548,0.001
8.34,16.400,0.02644,1.557,0.001
8.38,16.500,0.02661,1.564,0.001
8.42,16.600,0.02682,1.572,0.001
8.46,16.700,0.02703,1.580,0.001
8.49,16.800,0.02727,1.585,0.001
8.53,16.900,0.02748,1.593,0.001
8.58,17.000,0.02769,1.602,0.001
8.61,17.100,0.02790,1.608,0.001
8.67,17.200,0.02811,1.619,0.001
8.72,17.300,0.02831,1.628,0.001
8.76,17.400,0.02852,1.636,0.001
8.78,17.500,0.02873,1.639,0.001
8.82,17.600,0.02894,1.647,0.001
8.85,17.700,0.02914,1.652,0.001
8.88,17.800,0.02931,1.658,0.001
8.92,17.900,0.02952,1.666,0.001
8.94,18.000,0.02969,1.670,0.001
8.96,18.100,0.02985,1.674,0.001
8.99,18.200,0.03002,1.679,0.001
9.04,18.300,0.03014,1.687,0.001
9.05,18.400,0.03031,1.690,0.001
9.08,18.500,0.03043,1.696,0.001
9.09,18.600,0.03060,1.698,0.001
9.13,18.700,0.03072,1.705,0.001
9.15,18.800,0.03089,1.708,0.001
9.18,18.900,0.03101,1.714,0.001
9.21,19.000,0.03114,1.719,0.001
9.24,19.100,0.03131,1.725,0.001
9.26,19.200,0.03143,1.729,0.001
9.28,19.300,0.03156,1.733,0.001
9.30,19.400,0.03168,1.737,0.001
9.34,19.500,0.03185,1.743,0.001
9.36,19.600,0.03197,1.748,0.001
9.40,19.700,0.03214,1.755,0.001
9.42,19.800,0.03226,1.759,0.001
9.46,19.900,0.03243,1.766,0.001
9.48,20.000,0.03255,1.771,0.001
9.53,20.100,0.03272,1.779,0.001
9.54,20.200,0.03284,1.782,0.001
9.57,20.300,0.03301,1.788,0.001
9.60,20.400,0.03318,1.793,0.001
9.64,20.500,0.03330,1.799,0.001
9.66,20.600,0.03347,1.805,0.001
9.70,20.700,0.03363,1.812,0.001
9.71,20.800,0.03380,1.814,0.001
9.76,20.900,0.03392,1.822,0.001
9.80,21.000,0.03409,1.830,0.001
9.83,21.100,0.03426,1.835,0.001
9.86,21.200,0.03442,1.841,0.001
9.89,21.300,0.03459,1.847,0.001
9.92,21.400,0.03471,1.853,0.001
9.96,21.500,0.03488,1.859,0.001
9.98,21.600,0.03505,1.864,0.001
10.04,21.700,0.03525,1.874,0.001
10.07,21.800,0.03542,1.880,0.001
10.11,21.900,0.03563,1.888,0.001
10.15,22.000,0.03579,1.894,0.001
10.19,22.100,0.03600,1.902,0.001
10.24,22.200,0.03621,1.912,0.001
10.29,22.300,0.03642,1.920,0.001
10.32,22.400,0.03662,1.927,0.001
10.36,22.500,0.03683,1.934,0.001
10.41,22.600,0.03704,1.944,0.001
10.46,22.700,0.03725,1.953,0.001
10.49,22.800,0.03746,1.959,0.001
10.54,22.900,0.03766,1.969,0.001
10.57,23.000,0.03787,1.975,0.001
10.63,23.100,0.03808,1.985,0.001
10.67,23.200,0.03829,1.992,0.001
10.72,23.300,0.03849,2.002,0.001
10.76,23.400,0.03870,2.009,0.001
10.79,23.500,0.03887,2.015,0.001
10.83,23.600,0.03908,2.022,0.001
10.87,23.700,0.03924,2.030,0.001
10.89,23.800,0.03941,2.034,0.001
10.93,23.900,0.03958,2.041,0.001
10.95,24.000,0.03970,2.044,0.001
11.00,24.100,0.03987,2.054,0.001
11.04,24.200,0.04003,2.061,0.001
11.06,24.300,0.04016,2.065,0.001
11.09,24.400,0.04032,2.072,0.001
11.12,24.500,0.04045,2.076,0.001
11.15,24.600,0.04061,2.082,0.001
11.16,24.700,0.04074,2.084,0.001
11.20,24.800,0.04086,2.091,0.001
11.23,24.900,0.04103,2.096,0.001
11.26,25.000,0.04115,2.102,0.001
11.28,25.100,0.04128,2.107,0.001
11.31,25.200,0.04145,2.112,0.001
11.35,25.300,0.04157,2.120,0.001
11.36,25.400,0.04174,2.122,0.001
11.41,25.500,0.04186,2.131,0.001
11.44,25.600,0.04203,2.136,0.001
11.48,25.700,0.04219,2.143,0.001
11.50,25.800,0.04232,2.147,0.001
11.55,25.900,0.04248,2.156,0.001
11.59,26.000,0.04265,2.164,0.001
11.61,26.100,0.04278,2.168,0.001
11.65,26.200,0.04294,2.175,0.001
11.68,26.300,0.04311,2.182,0.001
11.73,26.400,0.04327,2.190,0.001
11.74,26.500,0.04340,2.193,0.001
11.79,26.600,0.04356,2.201,0.001
11.82,26.700,0.04373,2.208,0.001
11.85,26.800,0.04390,2.213,0.001
11.87,26.900,0.04406,2.217,0.001
11.93,27.000,0.04423,2.228,0.001
11.96,27.100,0.04440,2.233,0.001
12.00,27.200,0.04456,2.240,0.001
12.05,27.300,0.04473,2.251,0.001
12.09,27.400,0.04494,2.258,0.001
12.13,27.500,0.04510,2.264,0.001
12.17,27.600,0.04527,2.272,0.001
12.22,27.700,0.04548,2.282,0.001
12.28,27.800,0.04568,2.292,0.001
12.31,27.900,0.04589,2.298,0.001
12.36,28.000,0.04610,2.308,0.001
12.42,28.100,0.04631,2.318,0.001
12.47,28.200,0.04652,2.329,0.001
12.51,28.300,0.04672,2.335,0.001
12.56,28.400,0.04693,2.345,0.001
12.62,28.500,0.04714,2.356,0.001
12.65,28.600,0.04735,2.363,0.001
12.71,28.700,0.04755,2.372,0.001
12.76,28.800,0.04776,2.383,0.001
12.81,28.900,0.04797,2.392,0.001
12.84,29.000,0.04814,2.397,0.001
12.86,29.100,0.04834,2.402,0.001
12.90,29.200,0.04851,2.409,0.001
12.95,29.300,0.04868,2.418,0.001
12.99,29.400,0.04884,2.426,0.001
13.02,29.500,0.04901,2.431,0.001
13.05,29.600,0.04917,2.437,0.001
13.09,29.700,0.04930,2.445,0.001
13.13,29.800,0.04947,2.451,0.001
13.15,29.900,0.04959,2.456,0.001
13.18,30.000,0.04976,2.462,0.001
13.22,30.100,0.04988,2.468,0.001
13.25,30.200,0.05005,2.474,0.001
13.28,30.300,0.05017,2.480,0.001
13.31,30.400,0.05030,2.486,0.001
13.35,30.500,0.05042,2.492,0.001
13.38,30.600,0.05059,2.499,0.001
13.43,30.700,0.05071,2.507,0.001
13.45,30.800,0.05084,2.512,0.001
13.49,30.900,0.05100,2.518,0.001
13.52,31.000,0.05113,2.525,0.001
13.56,31.100,0.05129,2.531,0.001
13.58,31.200,0.05142,2.536,0.001
13.61,31.300,0.05158,2.542,0.001
13.65,31.400,0.05171,2.549,0.001
13.69,31.500,0.05188,2.556,0.001
13.72,31.600,0.05204,2.562,0.001
13.75,31.700,0.05217,2.567,0.001
13.79,31.800,0.05233,2.576,0.001
13.82,31.900,0.05250,2.581,0.001
13.86,32.000,0.05262,2.588,0.001
13.91,32.100,0.05279,2.597,0.001
13.95,32.200,0.05296,2.604,0.001
13.98,32.300,0.05308,2.611,0.001
14.00,32.400,0.05325,2.614,0.001
14.03,32.500,0.05341,2.620,0.001
14.08,32.600,0.05358,2.629,0.001
14.11,32.700,0.05370,2.635,0.001
14.16,32.800,0.05387,2.645,0.001
14.21,32.900,0.05404,2.653,0.001
14.26,33.000,0.05424,2.662,0.001
14.30,33.100,0.05441,2.671,0.001
14.38,33.200,0.05458,2.685,0.001
14.39,33.300,0.05478,2.688,0.001
14.46,33.400,0.05499,2.700,0.001
14.52,33.500,0.05520,2.711,0.001
14.57,33.600,0.05541,2.721,0.001
14.63,33.700,0.05562,2.731,0.001
14.69,33.800,0.05582,2.743,0.001
14.73,33.900,0.05607,2.751,0.001
14.78,34.000,0.05628,2.760,0.001
14.84,34.100,0.05649,2.771,0.001
14.89,34.200,0.05670,2.780,0.001
14.94,34.300,0.05690,2.789,0.001
14.99,34.400,0.05711,2.798,0.001
15.03,34.500,0.05732,2.806,0.001
15.08,34.600,0.05749,2.816,0.001
15.10,34.700,0.05769,2.820,0.001
15.16,34.800,0.05786,2.830,0.001
15.18,34.900,0.05803,2.835,0.001
15.24,35.000,0.05819,2.845,0.001
15.25,35.100,0.05836,2.848,0.001
15.30,35.200,0.05852,2.858,0.001
15.33,35.300,0.05865,2.862,0.001
15.36,35.400,0.05882,2.869,0.001
15.40,35.500,0.05894,2.876,0.001
15.42,35.600,0.05911,2.880,0.001
15.46,35.700,0.05923,2.887,0.001
15.47,35.800,0.05936,2.889,0.001
15.50,35.900,0.05948,2.894,0.001
15.54,36.000,0.05965,2.903,0.001
15.57,36.100,0.05977,2.907,0.001
15.60,36.200,0.05990,2.913,0.001
15.63,36.300,0.06002,2.919,0.001
15.67,36.400,0.06019,2.925,0.001
15.72,36.500,0.06031,2.935,0.001
15.74,36.600,0.06044,2.938,0.001
15.78,36.700,0.06060,2.947,0.001
15.83,36.800,0.06073,2.955,0.001
15.85,36.900,0.06089,2.959,0.001
15.90,37.000,0.06102,2.969,0.001
15.92,37.100,0.06118,2.973,0.001
15.97,37.200,0.06131,2.981,0.001
16.01,37.300,0.06148,2.989,0.001
16.04,37.400,0.06164,2.996,0.001
16.10,37.500,0.06177,3.005,0.001
16.13,37.600,0.06193,3.012,0.001
16.16,37.700,0.06210,3.018,0.001
16.21,37.800,0.06222,3.027,0.001
16.24,37.900,0.06239,3.032,0.001
16.27,38.000,0.06256,3.039,0.001
16.32,38.100,0.06272,3.046,0.001
16.36,38.200,0.06285,3.055,0.001
16.41,38.300,0.06301,3.063,0.001
16.45,38.400,0.06318,3.071,0.001
16.48,38.500,0.06335,3.078,0.001
16.55,38.600,0.06351,3.089,0.001
16.59,38.700,0.06368,3.099,0.001
16.65,38.800,0.06384,3.108,0.001
16.69,38.900,0.06405,3.116,0.001
16.73,39.000,0.06426,3.124,0.001
16.79,39.100,0.06443,3.135,0.001
16.84,39.200,0.06463,3.145,0.001
16.91,39.300,0.06484,3.157,0.001
16.95,39.400,0.06505,3.164,0.001
17.02,39.500,0.06526,3.178,0.001
17.05,39.600,0.06546,3.184,0.001
17.13,39.700,0.06567,3.199,0.001
17.20,39.800,0.06588,3.212,0.001
17.24,39.900,0.06609,3.219,0.001
17.28,40.000,0.06630,3.226,0.001
17.34,40.100,0.06650,3.238,0.001
17.37,40.200,0.06671,3.244,0.001
17.44,40.300,0.06688,3.256,0.001
17.48,40.400,0.06709,3.263,0.001
17.51,40.500,0.06725,3.269,0.001
17.57,40.600,0.06746,3.280,0.001
17.59,40.700,0.06763,3.285,0.001
17.64,40.800,0.06779,3.294,0.001
17.66,40.900,0.06792,3.298,0.001
17.70,41.000,0.06808,3.306,0.001
17.73,41.100,0.06825,3.310,0.001
17.77,41.200,0.06837,3.317,0.001
17.79,41.300,0.06854,3.321,0.001
17.84,41.400,0.06866,3.331,0.001
17.86,41.500,0.06879,3.335,0.001
17.89,41.600,0.06896,3.340,0.001
17.93,41.700,0.06908,3.347,0.001
17.95,41.800,0.06920,3.353,0.001
17.99,41.900,0.06933,3.358,0.001
18.02,42.000,0.06950,3.365,0.001
18.06,42.100,0.06962,3.371,0.001
18.10,42.200,0.06974,3.379,0.001
18.12,42.300,0.06991,3.383,0.001
18.16,42.400,0.07004,3.391,0.001
18.19,42.500,0.07020,3.396,0.001
18.23,42.600,0.07033,3.405,0.001
18.27,42.700,0.07045,3.412,0.001
18.32,42.800,0.07062,3.420,0.001
18.34,42.900,0.07078,3.425,0.001
18.39,43.000,0.07091,3.435,0.001
18.44,43.100,0.07107,3.444,0.001
18.47,43.200,0.07124,3.449,0.001
18.53,43.300,0.07137,3.461,0.001
18.56,43.400,0.07153,3.466,0.001
18.60,43.500,0.07170,3.473,0.001
18.64,43.600,0.07182,3.481,0.001
18.69,43.700,0.07199,3.489,0.001
18.73,43.800,0.07216,3.497,0.001
18.76,43.900,0.07232,3.503,0.001
18.82,44.000,0.07245,3.514,0.001
18.86,44.100,0.07261,3.521,0.001
18.91,44.200,0.07278,3.531,0.001
18.94,44.300,0.07294,3.537,0.001
19.00,44.400,0.07315,3.548,0.001
19.05,44.500,0.07332,3.557,0.001
19.11,44.600,0.07348,3.568,0.001
19.15,44.700,0.07369,3.576,0.001
19.19,44.800,0.07390,3.584,0.001
19.25,44.900,0.07411,3.594,0.001
19.30,45.000,0.07427,3.604,0.001
19.36,45.100,0.07448,3.615,0.001
19.43,45.200,0.07469,3.629,0.001
19.47,45.300,0.07490,3.635,0.001
19.52,45.400,0.07511,3.646,0.001
19.57,45.500,0.07531,3.653,0.001
19.62,45.600,0.07552,3.663,0.001
19.69,45.700,0.07573,3.676,0.001
19.74,45.800,0.07594,3.686,0.001
19.80,45.900,0.07610,3.696,0.001
19.84,46.000,0.07631,3.704,0.002
19.88,46.100,0.07652,3.713,0.002
19.92,46.200,0.07668,3.719,0.002
19.97,46.300,0.07685,3.728,0.002
20.00,46.400,0.07702,3.735,0.002
20.05,46.500,0.07718,3.744,0.002
20.08,46.600,0.07735,3.750,0.002
20.11,46.700,0.07752,3.756,0.002
20.14,46.800,0.07768,3.762,0.002
20.19,46.900,0.07781,3.769,0.002
20.22,47.000,0.07797,3.775,0.002
20.25,47.100,0.07810,3.781,0.002
20.29,47.200,0.07826,3.789,0.002
20.33,47.300,0.07839,3.795,0.002
20.35,47.400,0.07855,3.800,0.002
20.38,47.500,0.07868,3.806,0.002
20.44,47.600,0.07880,3.816,0.002
20.45,47.700,0.07893,3.819,0.002
20.48,47.800,0.07909,3.825,0.002
20.53,47.900,0.07922,3.834,0.002
20.57,48.000,0.07934,3.841,0.002
20.60,48.100,0.07951,3.847,0.002
20.63,48.200,0.07964,3.851,0.002
20.68,48.300,0.07980,3.861,0.002
20.72,48.400,0.07993,3.869,0.002
20.78,48.500,0.08009,3.880,0.002
20.81,48.600,0.08022,3.886,0.002
20.85,48.700,0.08038,3.893,0.002
20.89,48.800,0.08051,3.901,0.002
20.94,48.900,0.08067,3.909,0.002
20.97,49.000,0.08084,3.916,0.002
21.01,49.100,0.08096,3.923,0.002
21.05,49.200,0.08113,3.931,0.002
21.08,49.300,0.08130,3.937,0.002
21.14,49.400,0.08142,3.947,0.002
21.18,49.500,0.08159,3.954,0.002
21.22,49.600,0.08175,3.962,0.002
21.27,49.700,0.08188,3.971,0.002
21.31,49.800,0.08205,3.980,0.002
21.37,49.900,0.08221,3.990,0.002
21.40,50.000,0.08238,3.997,0.002
21.45,50.100,0.08254,4.005,0.002
21.51,50.200,0.08275,4.016,0.002
21.56,50.300,0.08292,4.026,0.002
21.62,50.400,0.08313,4.036,0.002
21.67,50.500,0.08333,4.046,0.002
21.73,50.600,0.08354,4.057,0.002
21.79,50.700,0.08375,4.069,0.002
21.84,50.800,0.08396,4.077,0.002
21.89,50.900,0.08416,4.088,0.002
21.95,51.000,0.08437,4.099,0.002
22.00,51.100,0.08458,4.107,0.002
22.06,51.200,0.08483,4.119,0.002
22.12,51.300,0.08504,4.131,0.002
22.19,51.400,0.08525,4.143,0.002
22.23,51.500,0.08545,4.151,0.002
22.29,51.600,0.08566,4.162,0.002
22.34,51.700,0.08583,4.172,0.002
22.38,51.800,0.08603,4.180,0.002
22.41,51.900,0.08620,4.185,0.002
22.45,52.000,0.08641,4.191,0.002
22.48,52.100,0.08653,4.198,0.002
22.53,52.200,0.08674,4.207,0.002
22.58,52.300,0.08687,4.215,0.002
22.60,52.400,0.08703,4.221,0.002
22.63,52.500,0.08716,4.226,0.002
22.66,52.600,0.08732,4.231,0.002
22.69,52.700,0.08745,4.237,0.002
22.72,52.800,0.08757,4.242,0.002
22.76,52.900,0.08774,4.251,0.002
22.78,53.000,0.08786,4.254,0.002
22.83,53.100,0.08799,4.262,0.002
22.87,53.200,0.08815,4.271,0.002
22.89,53.300,0.08828,4.275,0.002
22.92,53.400,0.08840,4.281,0.002
22.96,53.500,0.08857,4.287,0.002
22.99,53.600,0.08869,4.293,0.002
23.02,53.700,0.08882,4.299,0.002
23.06,53.800,0.08899,4.307,0.002
23.11,53.900,0.08911,4.314,0.002
23.15,54.000,0.08928,4.322,0.002
23.19,54.100,0.08944,4.331,0.002
23.22,54.200,0.08957,4.335,0.002
23.27,54.300,0.08973,4.345,0.002
23.29,54.400,0.08986,4.349,0.002
23.34,54.500,0.09002,4.359,0.002
23.38,54.600,0.09019,4.365,0.002
23.42,54.700,0.09036,4.373,0.002
23.46,54.800,0.09048,4.381,0.002
23.50,54.900,0.09065,4.389,0.002
23.53,55.000,0.09081,4.393,0.002
23.56,55.100,0.09094,4.399,0.002
23.61,55.200,0.09110,4.408,0.002
23.64,55.300,0.09127,4.414,0.002
23.69,55.400,0.09144,4.424,0.002
23.72,55.500,0.09160,4.430,0.002
23.78,55.600,0.09177,4.441,0.002
23.84,55.700,0.09194,4.451,0.002
23.86,55.800,0.09210,4.455,0.002
23.92,55.900,0.09231,4.466,0.002
23.96,56.000,0.09252,4.475,0.002
24.02,56.100,0.09268,4.484,0.002
24.08,56.200,0.09289,4.495,0.002
24.13,56.300,0.09310,4.505,0.002
24.19,56.400,0.09331,4.516,0.002
24.25,56.500,0.09351,4.528,0.002
24.31,56.600,0.09376,4.540,0.002
24.37,56.700,0.09397,4.550,0.002
24.42,56.800,0.09418,4.559,0.002
24.47,56.900,0.09439,4.568,0.002
24.52,57.000,0.09460,4.578,0.002
24.58,57.100,0.09480,4.589,0.002
24.63,57.200,0.09501,4.600,0.002
24.67,57.300,0.09518,4.606,0.002
24.71,57.400,0.09538,4.614,0.002
24.75,57.500,0.09559,4.622,0.002
24.79,57.600,0.09576,4.629,0.002
24.84,57.700,0.09593,4.638,0.002
24.87,57.800,0.09609,4.643,0.002
24.90,57.900,0.09626,4.649,0.002
24.91,58.000,0.09638,4.652,0.002
24.93,58.100,0.09655,4.655,0.002
24.97,58.200,0.09671,4.662,0.002
25.00,58.300,0.09684,4.668,0.002
25.01,58.400,0.09701,4.670,0.002
25.05,58.500,0.09713,4.678,0.002
25.07,58.600,0.09730,4.682,0.002
25.10,58.700,0.09742,4.688,0.002
25.12,58.800,0.09755,4.690,0.002
25.15,58.900,0.09767,4.696,0.002
25.18,59.000,0.09784,4.702,0.002
25.21,59.100,0.09796,4.707,0.002
25.24,59.200,0.09809,4.712,0.002
25.28,59.300,0.09825,4.720,0.002
25.31,59.400,0.09838,4.726,0.002
25.33,59.500,0.09854,4.730,0.002
25.38,59.600,0.09867,4.738,0.002
25.41,59.700,0.09883,4.745,0.002
25.44,59.800,0.09896,4.750,0.002
25.46,59.900,0.09912,4.754,0.002
25.51,60.000,0.09929,4.763,0.002
25.54,60.100,0.09946,4.770,0.002
25.59,60.200,0.09958,4.777,0.002
25.62,60.300,0.09975,4.784,0.002
25.66,60.400,0.09991,4.791,0.002
25.68,60.500,0.10004,4.795,0.002
25.72,60.600,0.10021,4.802,0.002
25.76,60.700,0.10037,4.809,0.002
25.79,60.800,0.10054,4.815,0.002
25.82,60.900,0.10070,4.821,0.002
25.84,61.000,0.10083,4.825,0.002
25.88,61.100,0.10099,4.833,0.002
25.92,61.200,0.10116,4.839,0.002
25.95,61.300,0.10137,4.846,0.002
25.99,61.400,0.10154,4.853,0.002
26.05,61.500,0.10170,4.864,0.002
26.09,61.600,0.10191,4.871,0.002
26.14,61.700,0.10208,4.881,0.002
26.17,61.800,0.10228,4.887,0.002
26.23,61.900,0.10249,4.898,0.002
26.28,62.000,0.10270,4.908,0.002
26.31,62.100,0.10291,4.912,0.002
26.37,62.200,0.10311,4.924,0.002
26.42,62.300,0.10332,4.933,0.002
26.45,62.400,0.10353,4.940,0.002
26.50,62.500,0.10374,4.948,0.002
26.53,62.600,0.10390,4.953,0.002
26.55,62.700,0.10411,4.958,0.002
26.59,62.800,0.10432,4.966,0.002
26.62,62.900,0.10453,4.971,0.002
26.67,63.000,0.10469,4.979,0.002
26.70,63.100,0.10490,4.986,0.002
26.72,63.200,0.10511,4.990,0.002
26.76,63.300,0.10528,4.997,0.002
26.79,63.400,0.10544,5.002,0.002
26.80,63.500,0.10561,5.005,0.002
26.85,63.600,0.10577,5.013,0.002
26.86,63.700,0.10590,5.016,0.002
26.91,63.800,0.10606,5.025,0.002
26.92,63.900,0.10623,5.027,0.002
26.94,64.000,0.10636,5.031,0.002
26.96,64.100,0.10652,5.035,0.002
26.99,64.200,0.10665,5.040,0.002
27.02,64.300,0.10681,5.045,0.002
27.03,64.400,0.10694,5.047,0.002
27.06,64.500,0.10706,5.052,0.002
27.08,64.600,0.10719,5.056,0.002
27.09,64.700,0.10735,5.059,0.002
27.11,64.800,0.10748,5.063,0.002
27.13,64.900,0.10760,5.066,0.002
27.16,65.000,0.10777,5.071,0.002
27.18,65.100,0.10789,5.074,0.002
27.22,65.200,0.10806,5.082,0.002
27.24,65.300,0.10818,5.086,0.002
27.25,65.400,0.10835,5.089,0.002
27.28,65.500,0.10847,5.095,0.002
27.30,65.600,0.10864,5.098,0.002
27.33,65.700,0.10877,5.103,0.002
27.36,65.800,0.10893,5.109,0.002
27.38,65.900,0.10910,5.112,0.002
27.40,66.000,0.10922,5.117,0.002
27.44,66.100,0.10939,5.124,0.002
27.46,66.200,0.10956,5.127,0.002
27.48,66.300,0.10968,5.132,0.002
27.52,66.400,0.10985,5.139,0.002
27.54,66.500,0.11001,5.143,0.002
27.58,66.600,0.11018,5.150,0.002
27.63,66.700,0.11034,5.159,0.002
27.65,66.800,0.11047,5.163,0.002
27.66,66.900,0.11064,5.166,0.002
27.69,67.000,0.11080,5.170,0.002
27.73,67.100,0.11101,5.178,0.002
27.75,67.200,0.11118,5.181,0.002
27.78,67.300,0.11134,5.187,0.002
27.81,67.400,0.11155,5.193,0.002
27.85,67.500,0.11172,5.201,0.002
27.89,67.600,0.11192,5.207,0.002
27.92,67.700,0.11213,5.213,0.002
27.97,67.800,0.11234,5.222,0.002
28.01,67.900,0.11255,5.231,0.002
28.05,68.000,0.11276,5.237,0.002
28.07,68.100,0.11296,5.241,0.002
28.12,68.200,0.11321,5.250,0.002
28.14,68.300,0.11338,5.255,0.002
28.16,68.400,0.11359,5.258,0.002
28.19,68.500,0.11379,5.264,0.002
28.21,68.600,0.11400,5.268,0.002
28.23,68.700,0.11417,5.271,0.002
28.27,68.800,0.11438,5.279,0.002
28.27,68.900,0.11454,5.279,0.002
28.29,69.000,0.11471,5.282,0.002
28.30,69.100,0.11492,5.285,0.002
28.33,69.200,0.11508,5.290,0.002
28.34,69.300,0.11521,5.291,0.002
28.32,69.400,0.11537,5.289,0.002
28.32,69.500,0.11550,5.289,0.002
28.35,69.600,0.11566,5.294,0.002
28.36,69.700,0.11579,5.296,0.002
28.37,69.800,0.11595,5.297,0.002
28.37,69.900,0.11608,5.298,0.002
28.38,70.000,0.11620,5.300,0.002
28.38,70.100,0.11633,5.300,0.002
28.38,70.200,0.11645,5.299,0.002
28.40,70.300,0.11662,5.303,0.002
28.41,70.400,0.11674,5.304,0.002
28.41,70.500,0.11687,5.304,0.002
28.41,70.600,0.11699,5.305,0.002
28.42,70.700,0.11712,5.306,0.002
28.43,70.800,0.11728,5.309,0.002
28.44,70.900,0.11741,5.311,0.002
28.45,71.000,0.11758,5.311,0.002
28.46,71.100,0.11770,5.315,0.002
28.45,71.200,0.11787,5.313,0.002
28.47,71.300,0.11799,5.316,0.002
28.48,71.400,0.11816,5.318,0.002
28.49,71.500,0.11832,5.319,0.002
28.48,71.600,0.11845,5.319,0.002
28.49,71.700,0.11861,5.321,0.002
28.51,71.800,0.11878,5.324,0.002
28.52,71.900,0.11891,5.325,0.002
28.53,72.000,0.11907,5.327,0.002
28.55,72.100,0.11924,5.331,0.002
28.53,72.200,0.11936,5.327,0.002
28.53,72.300,0.11953,5.328,0.002
28.56,72.400,0.11970,5.332,0.002
28.57,72.500,0.11986,5.334,0.002
28.58,72.600,0.12003,5.336,0.002
28.57,72.700,0.12019,5.334,0.002
28.54,72.800,0.12036,5.329,0.002
28.49,72.900,0.12053,5.320,0.002
28.42,73.000,0.12069,5.306,0.002
28.32,73.100,0.12090,5.287,0.002
28.13,73.200,0.12111,5.253,0.002
27.83,73.300,0.12127,5.197,0.002
27.53,73.400,0.12148,5.141,0.002
27.37,73.500,0.12169,5.111,0.002
27.27,73.600,0.12190,5.092,0.002
27.21,73.700,0.12211,5.080,0.002
27.15,73.800,0.12231,5.070,0.002
27.12,73.900,0.12252,5.065,0.002
27.08,74.000,0.12273,5.056,0.002
27.07,74.100,0.12294,5.054,0.002
27.04,74.200,0.12314,5.049,0.002
27.01,74.300,0.12335,5.044,0.002
26.97,74.400,0.12352,5.035,0.002
26.93,74.500,0.12373,5.029,0.002
26.91,74.600,0.12389,5.025,0.002
26.89,74.700,0.12410,5.021,0.002
26.86,74.800,0.12427,5.015,0.002
26.83,74.900,0.12443,5.011,0.002
26.80,75.000,0.12460,5.004,0.002
26.78,75.100,0.12472,5.001,0.002
26.75,75.200,0.12489,4.994,0.002
26.70,75.300,0.12506,4.986,0.002
26.68,75.400,0.12518,4.982,0.002
26.65,75.500,0.12535,4.977,0.002
26.63,75.600,0.12547,4.972,0.002
26.62,75.700,0.12560,4.970,0.002
26.58,75.800,0.12576,4.964,0.002
26.58,75.900,0.12589,4.963,0.002
26.53,76.000,0.12601,4.954,0.002
26.51,76.100,0.12614,4.950,0.002
26.46,76.200,0.12630,4.941,0.002
26.44,76.300,0.12643,4.937,0.002
26.41,76.400,0.12655,4.931,0.002
26.39,76.500,0.12672,4.928,0.002
26.36,76.600,0.12684,4.921,0.002
26.36,76.700,0.12701,4.921,0.003
26.34,76.800,0.12713,4.918,0.003
26.33,76.900,0.12730,4.916,0.003
26.33,77.000,0.12747,4.916,0.003
26.30,77.100,0.12759,4.910,0.003
26.31,77.200,0.12776,4.913,0.003
26.29,77.300,0.12792,4.910,0.003
26.28,77.400,0.12805,4.907,0.003
26.29,77.500,0.12821,4.908,0.003
26.26,77.600,0.12838,4.903,0.003
26.25,77.700,0.12855,4.902,0.003
26.25,77.800,0.12867,4.901,0.003
26.24,77.900,0.12884,4.900,0.003
26.24,78.000,0.12900,4.900,0.003
26.24,78.100,0.12917,4.900,0.003
26.23,78.200,0.12934,4.898,0.003
26.22,78.300,0.12946,4.896,0.003
26.21,78.400,0.12963,4.894,0.003
26.20,78.500,0.12983,4.893,0.003
26.20,78.600,0.13000,4.892,0.003
26.20,78.700,0.13017,4.892,0.003
26.19,78.800,0.13037,4.890,0.003
26.22,78.900,0.13054,4.895,0.003
26.19,79.000,0.13075,4.891,0.003
26.20,79.100,0.13096,4.892,0.003
26.17,79.200,0.13116,4.886,0.003
26.15,79.300,0.13137,4.883,0.003
26.13,79.400,0.13158,4.880,0.003
26.09,79.500,0.13175,4.872,0.003
26.01,79.600,0.13200,4.856,0.003
25.97,79.700,0.13216,4.850,0.003
25.85,79.800,0.13237,4.827,0.003
25.21,79.900,0.13258,4.707,0.003
24.73,80.000,0.13279,4.617,0.003
24.58,80.100,0.13295,4.590,0.003
24.51,80.200,0.13316,4.576,0.003
24.46,80.300,0.13333,4.567,0.003
24.44,80.400,0.13349,4.563,0.003
24.40,80.500,0.13370,4.557,0.003
24.39,80.600,0.13382,4.554,0.003
24.35,80.700,0.13399,4.547,0.003
24.35,80.800,0.13416,4.546,0.003
24.33,80.900,0.13432,4.542,0.003
24.31,81.000,0.13445,4.540,0.003
24.31,81.100,0.13461,4.538,0.003
24.29,81.200,0.13474,4.536,0.003
24.29,81.300,0.13490,4.535,0.003
24.27,81.400,0.13503,4.532,0.003
24.27,81.500,0.13515,4.531,0.003
24.26,81.600,0.13532,4.530,0.003
24.24,81.700,0.13544,4.526,0.003
24.24,81.800,0.13557,4.526,0.003
24.24,81.900,0.13569,4.526,0.003
24.23,82.000,0.13582,4.525,0.003
24.24,82.100,0.13598,4.526,0.003
24.23,82.200,0.13611,4.525,0.003
24.22,82.300,0.13623,4.522,0.003
24.22,82.400,0.13640,4.522,0.003
24.20,82.500,0.13653,4.519,0.003
24.21,82.600,0.13669,4.520,0.003
24.19,82.700,0.13682,4.517,0.003
24.20,82.800,0.13698,4.518,0.003
24.19,82.900,0.13711,4.516,0.003
24.20,83.000,0.13727,4.518,0.003
24.18,83.100,0.13744,4.514,0.003
24.18,83.200,0.13756,4.515,0.003
24.16,83.300,0.13773,4.512,0.003
24.17,83.400,0.13790,4.514,0.003
24.15,83.500,0.13802,4.509,0.003
24.14,83.600,0.13819,4.507,0.003
24.12,83.700,0.13835,4.505,0.003
24.11,83.800,0.13848,4.502,0.003
24.09,83.900,0.13864,4.498,0.003
23.95,84.000,0.13881,4.472,0.003
23.81,84.100,0.13898,4.446,0.003
23.71,84.200,0.13914,4.426,0.003
23.65,84.300,0.13931,4.416,0.003
23.60,84.400,0.13948,4.406,0.003
23.56,84.500,0.13968,4.399,0.003
23.54,84.600,0.13989,4.396,0.003
23.52,84.700,0.14006,4.391,0.003
23.47,84.800,0.14027,4.382,0.003
23.44,84.900,0.14047,4.376,0.003
23.40,85.000,0.14072,4.370,0.003
23.37,85.100,0.14093,4.365,0.003
23.32,85.200,0.14114,4.354,0.003
23.28,85.300,0.14135,4.347,0.003
23.22,85.400,0.14155,4.335,0.003
23.14,85.500,0.14176,4.320,0.003
23.05,85.600,0.14197,4.304,0.003
22.95,85.700,0.14218,4.286,0.003
22.88,85.800,0.14238,4.272,0.003
22.74,85.900,0.14255,4.247,0.003
22.62,86.000,0.14272,4.223,0.003
22.54,86.100,0.14292,4.208,0.003
22.45,86.200,0.14309,4.192,0.003
22.38,86.300,0.14326,4.180,0.003
22.30,86.400,0.14338,4.164,0.003
22.27,86.500,0.14355,4.158,0.003
22.22,86.600,0.14371,4.149,0.003
22.16,86.700,0.14384,4.138,0.003
22.12,86.800,0.14401,4.130,0.003
22.07,86.900,0.14413,4.121,0.003
22.00,87.000,0.14425,4.108,0.003
21.92,87.100,0.14442,4.093,0.003
21.48,87.200,0.14455,4.012,0.003
21.29,87.300,0.14467,3.976,0.003
21.16,87.400,0.14479,3.951,0.003
21.09,87.500,0.14496,3.938,0.003
21.05,87.600,0.14509,3.930,0.003
21.01,87.700,0.14521,3.922,0.003
20.97,87.800,0.14538,3.916,0.003
20.97,87.900,0.14550,3.916,0.003
20.94,88.000,0.14567,3.910,0.003
20.92,88.100,0.14579,3.905,0.003
20.91,88.200,0.14592,3.904,0.003
20.91,88.300,0.14608,3.904,0.003
20.90,88.400,0.14625,3.903,0.003
20.87,88.500,0.14637,3.897,0.003
20.88,88.600,0.14654,3.899,0.003
20.88,88.700,0.14671,3.899,0.003
20.85,88.800,0.14683,3.894,0.003
20.85,88.900,0.14700,3.893,0.003
20.84,89.000,0.14716,3.892,0.003
20.83,89.100,0.14729,3.890,0.003
20.82,89.200,0.14745,3.887,0.003
20.82,89.300,0.14762,3.888,0.003
20.81,89.400,0.14779,3.886,0.003
20.81,89.500,0.14795,3.885,0.003
20.80,89.600,0.14812,3.884,0.003
20.81,89.700,0.14829,3.887,0.003
20.79,89.800,0.14845,3.883,0.003
20.80,89.900,0.14862,3.885,0.003
20.80,90.000,0.14878,3.883,0.003
20.80,90.100,0.14899,3.884,0.003
20.80,90.200,0.14916,3.884,0.003
20.82,90.300,0.14937,3.888,0.003
20.81,90.400,0.14957,3.886,0.003
20.80,90.500,0.14978,3.883,0.003
20.79,90.600,0.14999,3.883,0.003
20.78,90.700,0.15020,3.881,0.003
20.77,90.800,0.15045,3.879,0.003
20.77,90.900,0.15065,3.877,0.003
20.75,91.000,0.15086,3.874,0.003
20.71,91.100,0.15111,3.867,0.003
20.68,91.200,0.15132,3.861,0.003
20.65,91.300,0.15153,3.856,0.003
20.60,91.400,0.15169,3.847,0.003
20.56,91.500,0.15190,3.839,0.003
20.53,91.600,0.15211,3.833,0.003
20.49,91.700,0.15227,3.826,0.003
20.41,91.800,0.15248,3.812,0.003
20.38,91.900,0.15265,3.806,0.003
20.31,92.000,0.15282,3.792,0.003
20.24,92.100,0.15298,3.780,0.003
20.18,92.200,0.15311,3.768,0.003
20.13,92.300,0.15327,3.760,0.003
20.08,92.400,0.15344,3.749,0.003
20.03,92.500,0.15360,3.740,0.003
19.99,92.600,0.15373,3.732,0.003
19.96,92.700,0.15390,3.727,0.003
19.91,92.800,0.15402,3.719,0.003
19.88,92.900,0.15414,3.712,0.003
19.85,93.000,0.15431,3.706,0.003
19.82,93.100,0.15444,3.702,0.003
19.77,93.200,0.15456,3.692,0.003
19.76,93.300,0.15469,3.689,0.003
19.74,93.400,0.15485,3.686,0.003
19.71,93.500,0.15498,3.680,0.003
19.68,93.600,0.15514,3.675,0.003
19.67,93.700,0.15527,3.672,0.003
19.63,93.800,0.15543,3.665,0.003
19.60,93.900,0.15556,3.661,0.003
19.57,94.000,0.15572,3.655,0.003
19.54,94.100,0.15589,3.649,0.003
19.49,94.200,0.15601,3.640,0.003
19.46,94.300,0.15618,3.634,0.003
19.42,94.400,0.15635,3.626,0.003
19.40,94.500,0.15651,3.622,0.003
19.35,94.600,0.15668,3.613,0.003
19.31,94.700,0.15680,3.605,0.003
19.25,94.800,0.15697,3.595,0.003
19.20,94.900,0.15714,3.585,0.003
19.16,95.000,0.15730,3.578,0.003
19.12,95.100,0.15747,3.570,0.003
19.09,95.200,0.15764,3.564,0.003
19.04,95.300,0.15780,3.554,0.003
18.96,95.400,0.15797,3.541,0.003
18.89,95.500,0.15813,3.527,0.003
18.81,95.600,0.15830,3.512,0.003
18.71,95.700,0.15851,3.493,0.003
18.60,95.800,0.15867,3.473,0.003
18.50,95.900,0.15888,3.455,0.003
18.39,96.000,0.15905,3.433,0.003
18.29,96.100,0.15926,3.415,0.003
18.20,96.200,0.15946,3.399,0.003
18.08,96.300,0.15967,3.376,0.003
17.88,96.400,0.15992,3.339,0.003
17.41,96.500,0.16013,3.250,0.003
15.95,96.600,0.16034,2.978,0.003
14.22,96.700,0.16054,2.656,0.003
13.53,96.800,0.16075,2.527,0.003
13.22,96.900,0.16096,2.469,0.003
13.03,97.000,0.16113,2.433,0.003
12.87,97.100,0.16133,2.403,0.003
12.78,97.200,0.16154,2.386,0.003
12.67,97.300,0.16171,2.365,0.003
12.56,97.400,0.16187,2.345,0.003
12.46,97.500,0.16208,2.326,0.003
12.38,97.600,0.16225,2.311,0.003
12.28,97.700,0.16241,2.293,0.003
12.19,97.800,0.16254,2.276,0.003
12.11,97.900,0.16271,2.261,0.003
12.03,98.000,0.16287,2.246,0.003
11.93,98.100,0.16300,2.227,0.003
11.85,98.200,0.16316,2.213,0.003
11.77,98.300,0.16329,2.198,0.003
11.69,98.400,0.16345,2.183,0.003
11.64,98.500,0.16358,2.173,0.003
11.57,98.600,0.16370,2.160,0.003
11.52,98.700,0.16387,2.151,0.003
11.49,98.800,0.16399,2.146,0.003
11.43,98.900,0.16412,2.134,0.003
11.40,99.000,0.16428,2.129,0.003
11.35,99.100,0.16441,2.119,0.003
11.31,99.200,0.16453,2.112,0.003
11.26,99.300,0.16470,2.103,0.003
11.22,99.400,0.16482,2.096,0.003
11.19,99.500,0.16499,2.090,0.003
11.16,99.600,0.16512,2.084,0.003
11.13,99.700,0.16528,2.078,0.003
11.11,99.800,0.16541,2.074,0.003
11.08,99.900,0.16557,2.069,0.003
11.05,100.000,0.16574,2.063,0.003
11.02,100.100,0.16586,2.058,0.003
11.00,100.200,0.16603,2.053,0.003
10.97,100.300,0.16620,2.049,0.003
10.94,100.400,0.16636,2.043,0.003
10.91,100.500,0.16649,2.038,0.003
10.89,100.600,0.16665,2.033,0.003
10.85,100.700,0.16682,2.027,0.003
10.83,100.800,0.16699,2.021,0.003
10.81,100.900,0.16715,2.018,0.003
10.76,101.000,0.16732,2.009,0.003
10.47,101.100,0.16748,1.956,0.003
10.18,101.200,0.16765,1.901,0.003
10.07,101.300,0.16782,1.880,0.003
10.01,101.400,0.16802,1.870,0.003
9.96,101.500,0.16819,1.860,0.003
9.94,101.600,0.16840,1.856,0.003
9.90,101.700,0.16861,1.849,0.003
9.86,101.800,0.16881,1.841,0.003
9.82,101.900,0.16902,1.833,0.003
9.78,102.000,0.16923,1.827,0.003
9.71,102.100,0.16944,1.814,0.003
9.66,102.200,0.16965,1.805,0.003
9.61,102.300,0.16989,1.795,0.003
9.56,102.400,0.17006,1.786,0.003
9.53,102.500,0.17027,1.779,0.003
9.46,102.600,0.17052,1.766,0.003
9.40,102.700,0.17068,1.755,0.003
9.31,102.800,0.17089,1.738,0.003
9.19,102.900,0.17110,1.716,0.003
9.11,103.000,0.17127,1.701,0.003
9.02,103.100,0.17143,1.685,0.003
8.93,103.200,0.17160,1.668,0.003
8.86,103.300,0.17176,1.655,0.003
8.78,103.400,0.17193,1.639,0.003
8.73,103.500,0.17210,1.629,0.003
8.67,103.600,0.17226,1.620,0.003
8.62,103.700,0.17239,1.609,0.003
8.58,103.800,0.17255,1.603,0.003
8.54,103.900,0.17268,1.596,0.003
8.51,104.000,0.17280,1.589,0.003
8.49,104.100,0.17297,1.585,0.003
8.46,104.200,0.17309,1.580,0.003
8.46,104.300,0.17322,1.579,0.003
8.43,104.400,0.17334,1.573,0.003
8.41,104.500,0.17351,1.571,0.003
8.38,104.600,0.17363,1.564,0.003
8.36,104.700,0.17376,1.562,0.003
8.35,104.800,0.17393,1.558,0.003
8.33,104.900,0.17405,1.555,0.003
8.31,105.000,0.17417,1.551,0.003
8.31,105.100,0.17434,1.551,0.003
8.28,105.200,0.17451,1.545,0.003
8.28,105.300,0.17463,1.546,0.003
8.27,105.400,0.17480,1.544,0.003
8.24,105.500,0.17492,1.539,0.003
8.23,105.600,0.17509,1.536,0.003
8.23,105.700,0.17526,1.537,0.003
8.21,105.800,0.17538,1.533,0.003
8.21,105.900,0.17555,1.533,0.003
8.20,106.000,0.17571,1.531,0.003
8.17,106.100,0.17584,1.525,0.003
8.16,106.200,0.17600,1.524,0.003
8.15,106.300,0.17617,1.521,0.003
8.12,106.400,0.17634,1.517,0.003
8.11,106.500,0.17646,1.514,0.003
8.11,106.600,0.17663,1.514,0.003
8.10,106.700,0.17679,1.512,0.003
8.09,106.800,0.17696,1.510,0.003
8.09,106.900,0.17717,1.510,0.003
8.08,107.000,0.17733,1.509,0.003
8.09,107.100,0.17750,1.510,0.003
8.08,107.200,0.17771,1.508,0.003
8.11,107.300,0.17787,1.514,0.004
8.09,107.400,0.17808,1.511,0.004
8.10,107.500,0.17829,1.513,0.004
8.09,107.600,0.17854,1.510,0.004
8.09,107.700,0.17875,1.511,0.004
8.10,107.800,0.17895,1.512,0.004
8.10,107.900,0.17916,1.512,0.004
8.09,108.000,0.17937,1.511,0.004
8.08,108.100,0.17958,1.509,0.004
8.08,108.200,0.17978,1.509,0.004
8.08,108.300,0.17999,1.509,0.004
8.06,108.400,0.18020,1.506,0.004
8.07,108.500,0.18037,1.507,0.004
8.05,108.600,0.18057,1.503,0.004
8.03,108.700,0.18074,1.499,0.004
8.03,108.800,0.18091,1.500,0.004
8.03,108.900,0.18107,1.499,0.004
8.00,109.000,0.18124,1.494,0.004
7.99,109.100,0.18141,1.492,0.004
7.98,109.200,0.18153,1.490,0.004
7.97,109.300,0.18170,1.488,0.004
7.98,109.400,0.18182,1.489,0.004
7.98,109.500,0.18199,1.490,0.004
7.96,109.600,0.18211,1.487,0.004
7.96,109.700,0.18228,1.486,0.004
7.95,109.800,0.18240,1.485,0.004
7.94,109.900,0.18253,1.483,0.004
7.94,110.000,0.18265,1.483,0.004
7.95,110.100,0.18282,1.484,0.004
7.94,110.200,0.18294,1.483,0.004
7.94,110.300,0.18307,1.482,0.004
7.94,110.400,0.18319,1.482,0.004
7.94,110.500,0.18336,1.482,0.004
7.93,110.600,0.18348,1.480,0.004
7.91,110.700,0.18365,1.477,0.004
7.91,110.800,0.18377,1.476,0.004
7.91,110.900,0.18394,1.478,0.004
7.89,111.000,0.18407,1.474,0.004
7.91,111.100,0.18423,1.476,0.004
7.91,111.200,0.18440,1.477,0.004
7.90,111.300,0.18452,1.474,0.004
7.89,111.400,0.18469,1.473,0.004
7.88,111.500,0.18485,1.472,0.004
7.88,111.600,0.18498,1.471,0.004
7.86,111.700,0.18515,1.467,0.004
7.86,111.800,0.18531,1.468,0.004
7.87,111.900,0.18544,1.469,0.004
7.86,112.000,0.18560,1.468,0.004
7.85,112.100,0.18577,1.465,0.004
7.85,112.200,0.18594,1.466,0.004
7.85,112.300,0.18610,1.466,0.004
7.85,112.400,0.18627,1.466,0.004
7.84,112.500,0.18643,1.464,0.004
7.86,112.600,0.18660,1.467,0.004
7.85,112.700,0.18677,1.465,0.004
7.86,112.800,0.18693,1.468,0.004
7.87,112.900,0.18714,1.469,0.004
7.86,113.000,0.18731,1.468,0.004
7.86,113.100,0.18751,1.468,0.004
7.86,113.200,0.18772,1.469,0.004
7.85,113.300,0.18793,1.467,0.004
7.87,113.400,0.18814,1.469,0.004
7.86,113.500,0.18835,1.467,0.004
7.86,113.600,0.18855,1.468,0.004
7.84,113.700,0.18872,1.464,0.004
7.86,113.800,0.18893,1.468,0.004
7.86,113.900,0.18913,1.467,0.004
7.85,114.000,0.18934,1.465,0.004
7.84,114.100,0.18951,1.464,0.004
7.83,114.200,0.18972,1.463,0.004
7.84,114.300,0.18988,1.464,0.004
7.83,114.400,0.19009,1.462,0.004
7.84,114.500,0.19026,1.465,0.004
7.84,114.600,0.19042,1.464,0.004
7.81,114.700,0.19059,1.459,0.004
7.82,114.800,0.19076,1.461,0.004
7.82,114.900,0.19092,1.461,0.004
7.81,115.000,0.19105,1.458,0.004
7.81,115.100,0.19121,1.458,0.004
7.79,115.200,0.19134,1.455,0.004
7.81,115.300,0.19150,1.458,0.004
7.80,115.400,0.19163,1.457,0.004
7.81,115.500,0.19175,1.458,0.004
7.80,115.600,0.19188,1.456,0.004
7.81,115.700,0.19204,1.458,0.004
7.80,115.800,0.19217,1.456,0.004
7.80,115.900,0.19229,1.456,0.004
7.80,116.000,0.19242,1.457,0.004
7.81,116.100,0.19258,1.458,0.004
7.80,116.200,0.19271,1.457,0.004
7.81,116.300,0.19283,1.458,0.004
7.81,116.400,0.19300,1.459,0.004
7.82,116.500,0.19312,1.460,0.004
7.82,116.600,0.19325,1.460,0.004
7.82,116.700,0.19342,1.460,0.004
7.82,116.800,0.19354,1.461,0.004
7.81,116.900,0.19371,1.459,0.004
7.81,117.000,0.19383,1.459,0.004
7.84,117.100,0.19396,1.463,0.004
7.85,117.200,0.19412,1.465,0.004
7.85,117.300,0.19429,1.465,0.004
7.86,117.400,0.19441,1.467,0.004
7.86,117.500,0.19458,1.468,0.004
7.86,117.600,0.19474,1.468,0.004
7.86,117.700,0.19487,1.468,0.004
7.88,117.800,0.19504,1.471,0.004
7.87,117.900,0.19520,1.469,0.004
7.87,118.000,0.19533,1.470,0.004
7.88,118.100,0.19549,1.471,0.004
7.87,118.200,0.19566,1.470,0.004
7.90,118.300,0.19583,1.475,0.004
7.89,118.400,0.19599,1.474,0.004
7.90,118.500,0.19616,1.475,0.004
7.90,118.600,0.19632,1.475,0.004
7.92,118.700,0.19653,1.479,0.004
7.92,118.800,0.19674,1.479,0.004
7.92,118.900,0.19691,1.479,0.004
7.94,119.000,0.19711,1.482,0.004
7.95,119.100,0.19736,1.484,0.004
7.95,119.200,0.19757,1.484,0.004
7.97,119.300,0.19778,1.488,0.004
7.96,119.400,0.19799,1.487,0.004
7.99,119.500,0.19819,1.493,0.004
7.98,119.600,0.19840,1.490,0.004
8.02,119.700,0.19861,1.497,0.004
8.00,119.800,0.19882,1.494,0.004
8.02,119.900,0.19903,1.497,0.004
8.03,120.000,0.19919,1.499,0.004
8.03,120.100,0.19940,1.499,0.004
8.02,120.200,0.19957,1.497,0.004
8.01,120.300,0.19973,1.495,0.004
8.00,120.400,0.19990,1.494,0.004
8.01,120.500,0.20006,1.496,0.004
8.02,120.600,0.20023,1.497,0.004
8.02,120.700,0.20040,1.498,0.004
8.02,120.800,0.20056,1.498,0.004
8.03,120.900,0.20069,1.499,0.004
8.03,121.000,0.20085,1.499,0.004
8.05,121.100,0.20098,1.502,0.004
8.02,121.200,0.20110,1.498,0.004
8.02,121.300,0.20123,1.497,0.004
8.04,121.400,0.20139,1.502,0.004
8.04,121.500,0.20152,1.502,0.004
8.04,121.600,0.20164,1.501,0.004
8.05,121.700,0.20181,1.504,0.004
8.06,121.800,0.20193,1.506,0.004
8.07,121.900,0.20206,1.507,0.004
8.07,122.000,0.20222,1.507,0.004
8.09,122.100,0.20235,1.510,0.004
8.09,122.200,0.20247,1.510,0.004
8.08,122.300,0.20264,1.509,0.004
8.08,122.400,0.20277,1.509,0.004
8.08,122.500,0.20293,1.509,0.004
8.10,122.600,0.20310,1.512,0.004
8.10,122.700,0.20322,1.512,0.004
8.11,122.800,0.20339,1.515,0.004
8.11,122.900,0.20355,1.514,0.004
8.12,123.000,0.20372,1.517,0.004
8.12,123.100,0.20385,1.516,0.004
8.12,123.200,0.20401,1.517,0.004
8.11,123.300,0.20418,1.515,0.004
8.14,123.400,0.20434,1.519,0.004
8.15,123.500,0.20451,1.523,0.004
8.17,123.600,0.20468,1.525,0.004
8.15,123.700,0.20484,1.522,0.004
8.16,123.800,0.20501,1.524,0.004
8.16,123.900,0.20518,1.524,0.004
8.19,124.000,0.20534,1.530,0.004
8.20,124.100,0.20551,1.531,0.004
8.21,124.200,0.20572,1.534,0.004
8.21,124.300,0.20588,1.533,0.004
8.24,124.400,0.20605,1.538,0.004
8.24,124.500,0.20626,1.538,0.004
8.24,124.600,0.20646,1.539,0.004
8.25,124.700,0.20667,1.540,0.004
8.26,124.800,0.20688,1.542,0.004
8.27,124.900,0.20709,1.545,0.004
8.27,125.000,0.20734,1.545,0.004
8.28,125.100,0.20754,1.546,0.004
8.30,125.200,0.20775,1.549,0.004
8.30,125.300,0.20796,1.550,0.004
8.31,125.400,0.20817,1.552,0.004
8.32,125.500,0.20838,1.553,0.004
8.32,125.600,0.20858,1.554,0.004
8.32,125.700,0.20875,1.554,0.004
8.34,125.800,0.20896,1.558,0.004
8.35,125.900,0.20912,1.559,0.004
8.34,126.000,0.20929,1.557,0.004
8.33,126.100,0.20946,1.555,0.004
8.33,126.200,0.20962,1.555,0.004
8.36,126.300,0.20979,1.560,0.004
8.34,126.400,0.20995,1.558,0.004
8.36,126.500,0.21012,1.560,0.004
8.34,126.600,0.21025,1.558,0.004
8.35,126.700,0.21041,1.559,0.004
8.36,126.800,0.21054,1.561,0.004
8.35,126.900,0.21070,1.560,0.004
8.37,127.000,0.21083,1.562,0.004
8.36,127.100,0.21095,1.562,0.004
8.36,127.200,0.21112,1.561,0.004
8.37,127.300,0.21124,1.564,0.004
8.39,127.400,0.21137,1.567,0.004
8.39,127.500,0.21153,1.567,0.004
8.40,127.600,0.21166,1.568,0.004
8.41,127.700,0.21178,1.570,0.004
8.39,127.800,0.21195,1.567,0.004
8.39,127.900,0.21207,1.566,0.004
8.40,128.000,0.21224,1.569,0.004
8.42,128.100,0.21241,1.572,0.004
8.41,128.200,0.21253,1.570,0.004
8.42,128.300,0.21270,1.572,0.004
8.42,128.400,0.21286,1.573,0.004
8.45,128.500,0.21299,1.577,0.004
8.44,128.600,0.21315,1.576,0.004
8.45,128.700,0.21332,1.577,0.004
8.47,128.800,0.21349,1.582,0.004
8.47,128.900,0.21365,1.581,0.004
8.47,129.000,0.21378,1.581,0.004
8.46,129.100,0.21394,1.581,0.004
8.48,129.200,0.21411,1.584,0.004
8.49,129.300,0.21428,1.586,0.004
8.49,129.400,0.21444,1.585,0.004
8.50,129.500,0.21461,1.587,0.004
8.51,129.600,0.21477,1.589,0.004
8.51,129.700,0.21494,1.588,0.004
8.51,129.800,0.21515,1.590,0.004
8.53,129.900,0.21532,1.594,0.004
8.52,130.000,0.21548,1.592,0.004
8.54,130.100,0.21569,1.594,0.004
8.55,130.200,0.21590,1.597,0.004
8.56,130.300,0.21606,1.599,0.004
8.54,130.400,0.21627,1.595,0.004
8.55,130.500,0.21652,1.597,0.004
8.57,130.600,0.21673,1.599,0.004
8.59,130.700,0.21694,1.603,0.004
8.58,130.800,0.21714,1.602,0.004
8.60,130.900,0.21735,1.606,0.004
8.61,131.000,0.21756,1.607,0.004
8.61,131.100,0.21777,1.607,0.004
8.61,131.200,0.21793,1.608,0.004
8.61,131.300,0.21814,1.609,0.004
8.61,131.400,0.21831,1.608,0.004
8.59,131.500,0.21851,1.605,0.004
8.61,131.600,0.21868,1.608,0.004
8.59,131.700,0.21885,1.605,0.004
8.61,131.800,0.21901,1.608,0.004
8.62,131.900,0.21914,1.610,0.004
8.61,132.000,0.21930,1.608,0.004
8.61,132.100,0.21947,1.608,0.004
8.62,132.200,0.21960,1.610,0.004
8.62,132.300,0.21976,1.609,0.004
8.61,132.400,0.21989,1.608,0.004
8.61,132.500,0.22005,1.608,0.004
8.61,132.600,0.22018,1.608,0.004
8.61,132.700,0.22030,1.607,0.004
8.61,132.800,0.22047,1.608,0.004
8.59,132.900,0.22059,1.603,0.004
8.58,133.000,0.22072,1.602,0.004
8.58,133.100,0.22088,1.601,0.004
8.57,133.200,0.22101,1.601,0.004
8.58,133.300,0.22113,1.602,0.004
8.55,133.400,0.22130,1.597,0.004
8.52,133.500,0.22142,1.591,0.004
8.53,133.600,0.22159,1.592,0.004
8.53,133.700,0.22171,1.592,0.004
8.53,133.800,0.22188,1.593,0.004
8.55,133.900,0.22201,1.596,0.004
8.57,134.000,0.22217,1.600,0.004
8.57,134.100,0.22230,1.601,0.004
8.58,134.200,0.22246,1.601,0.004
8.58,134.300,0.22263,1.602,0.004
8.60,134.400,0.22275,1.606,0.004
8.61,134.500,0.22292,1.608,0.004
8.61,134.600,0.22309,1.608,0.004
8.62,134.700,0.22321,1.609,0.004
8.61,134.800,0.22338,1.607,0.004
8.61,134.900,0.22354,1.609,0.004
8.65,135.000,0.22371,1.615,0.004
8.64,135.100,0.22388,1.613,0.004
8.64,135.200,0.22404,1.613,0.004
8.65,135.300,0.22421,1.614,0.004
8.66,135.400,0.22437,1.617,0.004
8.67,135.500,0.22454,1.619,0.004
8.67,135.600,0.22475,1.619,0.004
8.69,135.700,0.22491,1.623,0.004
8.70,135.800,0.22512,1.624,0.004
8.73,135.900,0.22533,1.631,0.004
8.72,136.000,0.22554,1.629,0.004
8.76,136.100,0.22575,1.635,0.004
8.78,136.200,0.22595,1.639,0.004
8.80,136.300,0.22620,1.643,0.004
8.81,136.400,0.22641,1.646,0.004
8.84,136.500,0.22662,1.651,0.004
8.85,136.600,0.22683,1.653,0.004
8.86,136.700,0.22703,1.654,0.004
8.87,136.800,0.22724,1.657,0.004
8.89,136.900,0.22741,1.660,0.004
8.90,137.000,0.22762,1.662,0.004
8.89,137.100,0.22778,1.661,0.004
8.90,137.200,0.22799,1.661,0.004
8.87,137.300,0.22816,1.657,0.004
8.89,137.400,0.22832,1.660,0.004
8.87,137.500,0.22849,1.657,0.004
8.86,137.600,0.22861,1.655,0.005
8.89,137.700,0.22878,1.660,0.005
8.91,137.800,0.22890,1.663,0.005
8.91,137.900,0.22907,1.665,0.005
8.91,138.000,0.22919,1.665,0.005
8.91,138.100,0.22932,1.664,0.005
8.93,138.200,0.22949,1.667,0.005
8.94,138.300,0.22961,1.668,0.005
8.94,138.400,0.22973,1.668,0.005
8.95,138.470,0.22982,1.671,0.005