File: data-files/CWRU/0900-15-35A.txt
""
"Test Method","Will_Huddleston_Disks.msm"
"Sample I. D.","900-150-35A.mss"
"Specimen Number","1"

"Load (N)","Time (s)","Extension (mm)","Stress (MPa)","Strain (mm/mm)"

5.38,0.200,-0.02886,1.005,-0.001
5.38,0.300,-0.02886,1.006,-0.001
5.40,0.400,-0.02882,1.008,-0.001
5.39,0.500,-0.02882,1.006,-0.001
5.39,0.600,-0.02882,1.006,-0.001
5.39,0.700,-0.02877,1.006,-0.001
5.38,0.800,-0.02877,1.004,-0.001
5.38,0.900,-0.02877,1.005,-0.001
5.38,1.000,-0.02873,1.005,-0.001
5.39,1.100,-0.02873,1.006,-0.001
5.38,1.200,-0.02873,1.005,-0.001
5.39,1.300,-0.02869,1.007,-0.001
5.39,1.400,-0.02869,1.006,-0.001
5.39,1.500,-0.02865,1.007,-0.001
5.40,1.600,-0.02865,1.008,-0.001
5.41,1.700,-0.02861,1.009,-0.001
5.40,1.800,-0.02861,1.009,-0.001
5.41,1.900,-0.02857,1.010,-0.001
5.41,2.000,-0.02857,1.011,-0.001
5.41,2.100,-0.02852,1.011,-0.001
5.44,2.200,-0.02844,1.016,-0.001
5.51,2.300,-0.02832,1.030,-0.001
5.60,2.400,-0.02815,1.047,-0.001
5.68,2.500,-0.02798,1.061,-0.001
5.77,2.600,-0.02782,1.077,-0.001
5.81,2.700,-0.02769,1.086,-0.001
5.87,2.800,-0.02753,1.096,-0.001
5.89,2.900,-0.02736,1.101,-0.001
5.93,3.000,-0.02719,1.107,-0.001
5.96,3.100,-0.02703,1.113,-0.001
5.98,3.200,-0.02682,1.117,-0.001
6.02,3.300,-0.02665,1.125,-0.001
6.05,3.400,-0.02645,1.130,-0.001
6.07,3.500,-0.02624,1.133,-0.001
6.11,3.600,-0.02607,1.141,-0.001
6.13,3.700,-0.02586,1.145,-0.001
6.14,3.800,-0.02566,1.147,-0.001
6.16,3.900,-0.02549,1.151,-0.001
6.21,4.000,-0.02528,1.159,0.000
6.22,4.100,-0.02508,1.162,0.000
6.25,4.200,-0.02487,1.168,0.000
6.29,4.300,-0.02466,1.174,0.000
6.31,4.400,-0.02449,1.178,0.000
6.32,4.500,-0.02429,1.180,0.000
6.35,4.600,-0.02412,1.185,0.000
6.37,4.700,-0.02395,1.190,0.000
6.39,4.800,-0.02375,1.193,0.000
6.39,4.900,-0.02358,1.194,0.000
6.42,5.000,-0.02341,1.199,0.000
6.44,5.100,-0.02329,1.202,0.000
6.47,5.200,-0.02312,1.209,0.000
6.48,5.300,-0.02300,1.209,0.000
6.49,5.400,-0.02283,1.211,0.000
6.52,5.500,-0.02271,1.217,0.000
6.52,5.600,-0.02258,1.217,0.000
6.55,5.700,-0.02242,1.222,0.000
6.55,5.800,-0.02229,1.224,0.000
6.57,5.900,-0.02217,1.226,0.000
6.58,6.000,-0.02204,1.229,0.000
6.59,6.100,-0.02192,1.230,0.000
6.60,6.200,-0.02175,1.232,0.000
6.62,6.300,-0.02163,1.236,0.000
6.63,6.400,-0.02150,1.238,0.000
6.65,6.500,-0.02134,1.242,0.000
6.68,6.600,-0.02121,1.247,0.000
6.69,6.700,-0.02109,1.250,0.000
6.70,6.800,-0.02092,1.251,0.000
6.71,6.900,-0.02075,1.254,0.000
6.73,7.000,-0.02063,1.258,0.000
6.75,7.100,-0.02046,1.261,0.000
6.75,7.200,-0.02034,1.261,0.000
6.78,7.300,-0.02017,1.266,0.000
6.79,7.400,-0.02001,1.269,0.000
6.83,7.500,-0.01984,1.275,0.000
6.84,7.600,-0.01971,1.277,0.000
6.85,7.700,-0.01955,1.279,0.000
6.86,7.800,-0.01938,1.281,0.000
6.88,7.900,-0.01926,1.284,0.000
6.90,8.000,-0.01909,1.289,0.000
6.92,8.100,-0.01892,1.292,0.000
6.93,8.200,-0.01876,1.294,0.000
6.97,8.300,-0.01863,1.301,0.000
6.98,8.400,-0.01847,1.304,0.000
6.99,8.500,-0.01830,1.306,0.000
7.02,8.600,-0.01809,1.310,0.000
7.03,8.700,-0.01793,1.314,0.000
7.07,8.800,-0.01776,1.320,0.000
7.09,8.900,-0.01755,1.323,0.000
7.11,9.000,-0.01735,1.327,0.000
7.14,9.100,-0.01714,1.332,0.000
7.19,9.200,-0.01693,1.342,0.000
7.21,9.300,-0.01672,1.346,0.000
7.23,9.400,-0.01651,1.351,0.000
7.26,9.500,-0.01631,1.355,0.000
7.27,9.600,-0.01610,1.358,0.000
7.30,9.700,-0.01589,1.363,0.000
7.32,9.800,-0.01564,1.366,0.000
7.35,9.900,-0.01543,1.373,0.000
7.37,10.000,-0.01523,1.376,0.000
7.39,10.100,-0.01506,1.381,0.000
7.41,10.200,-0.01485,1.384,0.000
7.43,10.300,-0.01464,1.387,0.000
7.45,10.400,-0.01448,1.392,0.000
7.47,10.500,-0.01431,1.395,0.000
7.51,10.600,-0.01415,1.402,0.000
7.51,10.700,-0.01398,1.403,0.000
7.53,10.800,-0.01381,1.405,0.000
7.55,10.900,-0.01365,1.410,0.000
7.57,11.000,-0.01348,1.413,0.000
7.59,11.100,-0.01331,1.417,0.000
7.63,11.200,-0.01319,1.424,0.000
7.64,11.300,-0.01302,1.426,0.000
7.63,11.400,-0.01290,1.424,0.000
7.66,11.500,-0.01277,1.430,0.000
7.67,11.600,-0.01261,1.433,0.000
7.68,11.700,-0.01248,1.435,0.000
7.71,11.800,-0.01236,1.440,0.000
7.72,11.900,-0.01219,1.441,0.000
7.72,12.000,-0.01207,1.441,0.000
7.74,12.100,-0.01190,1.445,0.000
7.77,12.200,-0.01178,1.451,0.000
7.77,12.300,-0.01161,1.451,0.000
7.78,12.400,-0.01149,1.454,0.000
7.81,12.500,-0.01132,1.459,0.000
7.83,12.600,-0.01120,1.463,0.000
7.84,12.700,-0.01103,1.464,0.000
7.86,12.800,-0.01086,1.468,0.000
7.87,12.900,-0.01070,1.471,0.000
7.89,13.000,-0.01057,1.474,0.000
7.90,13.100,-0.01041,1.475,0.000
7.93,13.200,-0.01024,1.480,0.000
7.94,13.300,-0.01007,1.483,0.000
7.96,13.400,-0.00995,1.486,0.000
7.97,13.500,-0.00978,1.487,0.000
8.00,13.600,-0.00962,1.494,0.000
8.02,13.700,-0.00945,1.498,0.000
8.04,13.800,-0.00928,1.501,0.000
8.06,13.900,-0.00912,1.505,0.000
8.09,14.000,-0.00895,1.512,0.000
8.09,14.100,-0.00879,1.511,0.000
8.14,14.200,-0.00862,1.520,0.000
8.15,14.300,-0.00841,1.523,0.000
8.17,14.400,-0.00825,1.525,0.000
8.18,14.500,-0.00808,1.528,0.000
8.21,14.600,-0.00787,1.532,0.000
8.24,14.700,-0.00766,1.538,0.000
8.26,14.800,-0.00746,1.543,0.000
8.29,14.900,-0.00725,1.549,0.000
8.32,15.000,-0.00704,1.553,0.000
8.34,15.100,-0.00683,1.558,0.000
8.36,15.200,-0.00662,1.561,0.000
8.39,15.300,-0.00642,1.567,0.000
8.41,15.400,-0.00621,1.570,0.000
8.43,15.500,-0.00600,1.574,0.000
8.46,15.600,-0.00579,1.580,0.000
8.48,15.700,-0.00559,1.583,0.000
8.49,15.800,-0.00542,1.586,0.000
8.52,15.900,-0.00521,1.590,0.000
8.51,16.000,-0.00505,1.590,0.000
8.54,16.100,-0.00488,1.594,0.000
8.57,16.200,-0.00471,1.600,0.000
8.59,16.300,-0.00455,1.604,0.000
8.60,16.400,-0.00438,1.605,0.000
8.63,16.500,-0.00421,1.611,0.000
8.65,16.600,-0.00405,1.615,0.000
8.67,16.700,-0.00392,1.618,0.000
8.68,16.800,-0.00376,1.621,0.000
8.69,16.900,-0.00363,1.624,0.000
8.71,17.000,-0.00347,1.627,0.000
8.73,17.100,-0.00334,1.630,0.000
8.75,17.200,-0.00322,1.634,0.000
8.76,17.300,-0.00305,1.636,0.000
8.78,17.400,-0.00293,1.639,0.000
8.80,17.500,-0.00280,1.643,0.000
8.82,17.600,-0.00263,1.647,0.000
8.85,17.700,-0.00251,1.652,0.000
8.85,17.800,-0.00239,1.652,0.000
8.88,17.900,-0.00222,1.659,0.000
8.91,18.000,-0.00209,1.664,0.000
8.93,18.100,-0.00193,1.668,0.000
8.96,18.200,-0.00180,1.674,0.000
8.97,18.300,-0.00164,1.675,0.000
9.01,18.400,-0.00151,1.683,0.000
9.04,18.500,-0.00135,1.688,0.000
9.04,18.600,-0.00122,1.689,0.000
9.07,18.700,-0.00106,1.693,0.000
9.08,18.800,-0.00093,1.695,0.000
9.11,18.900,-0.00076,1.701,0.000
9.13,19.000,-0.00060,1.705,0.000
9.17,19.100,-0.00047,1.712,0.000
9.19,19.200,-0.00031,1.715,0.000
9.19,19.300,-0.00014,1.717,0.000
9.21,19.400,0.00002,1.720,0.000
9.25,19.500,0.00015,1.728,0.000
9.26,19.600,0.00032,1.729,0.000
9.30,19.700,0.00048,1.736,0.000
9.31,19.800,0.00065,1.738,0.000
9.36,19.900,0.00081,1.748,0.000
9.37,20.000,0.00098,1.749,0.000
9.41,20.100,0.00119,1.757,0.000
9.42,20.200,0.00135,1.759,0.000
9.45,20.300,0.00156,1.764,0.000
9.48,20.400,0.00173,1.771,0.000
9.49,20.500,0.00194,1.773,0.000
9.51,20.600,0.00214,1.777,0.000
9.58,20.700,0.00239,1.789,0.000
9.59,20.800,0.00260,1.791,0.000
9.66,20.900,0.00281,1.804,0.000
9.67,21.000,0.00302,1.805,0.000
9.71,21.100,0.00322,1.813,0.000
9.73,21.200,0.00343,1.817,0.000
9.75,21.300,0.00364,1.820,0.000
9.80,21.400,0.00385,1.830,0.000
9.83,21.500,0.00401,1.836,0.000
9.84,21.600,0.00422,1.838,0.000
9.88,21.700,0.00439,1.846,0.000
9.89,21.800,0.00460,1.846,0.000
9.92,21.900,0.00476,1.853,0.000
9.96,22.000,0.00493,1.860,0.000
9.98,22.100,0.00505,1.864,0.000
10.00,22.200,0.00522,1.867,0.000
10.03,22.300,0.00539,1.873,0.000
10.03,22.400,0.00551,1.873,0.000
10.04,22.500,0.00568,1.875,0.000
10.08,22.600,0.00580,1.882,0.000
10.10,22.700,0.00593,1.887,0.000
10.13,22.800,0.00609,1.892,0.000
10.13,22.900,0.00622,1.891,0.000
10.16,23.000,0.00634,1.898,0.000
10.18,23.100,0.00647,1.901,0.000
10.16,23.200,0.00659,1.897,0.000
10.21,23.300,0.00676,1.906,0.000
10.23,23.400,0.00688,1.909,0.000
10.24,23.500,0.00701,1.912,0.000
10.29,23.600,0.00713,1.921,0.000
10.30,23.700,0.00730,1.924,0.000
10.32,23.800,0.00742,1.926,0.000
10.36,23.900,0.00759,1.935,0.000
10.36,24.000,0.00771,1.935,0.000
10.39,24.100,0.00788,1.940,0.000
10.42,24.200,0.00800,1.946,0.000
10.43,24.300,0.00817,1.948,0.000
10.47,24.400,0.00829,1.954,0.000
10.48,24.500,0.00846,1.957,0.000
10.49,24.600,0.00859,1.960,0.000
10.54,24.700,0.00875,1.969,0.000
10.55,24.800,0.00892,1.971,0.000
10.58,24.900,0.00908,1.976,0.000
10.61,25.000,0.00921,1.981,0.000
10.63,25.100,0.00937,1.985,0.000
10.67,25.200,0.00954,1.993,0.000
10.71,25.300,0.00971,1.999,0.000
10.71,25.400,0.00987,2.001,0.000
10.75,25.500,0.01004,2.008,0.000
10.77,25.600,0.01021,2.011,0.000
10.80,25.700,0.01037,2.017,0.000
10.83,25.800,0.01054,2.023,0.000
10.85,25.900,0.01075,2.027,0.000
10.92,26.000,0.01091,2.039,0.000
10.94,26.100,0.01112,2.044,0.000
10.96,26.200,0.01133,2.047,0.000
11.01,26.300,0.01154,2.056,0.000
11.04,26.400,0.01174,2.061,0.000
11.07,26.500,0.01195,2.068,0.000
11.11,26.600,0.01216,2.075,0.000
11.13,26.700,0.01237,2.079,0.000
11.15,26.800,0.01257,2.083,0.000
11.18,26.900,0.01278,2.087,0.000
11.21,27.000,0.01299,2.093,0.000
11.24,27.100,0.01320,2.100,0.000
11.27,27.200,0.01336,2.105,0.000
11.29,27.300,0.01357,2.109,0.000
11.32,27.400,0.01378,2.114,0.000
11.33,27.500,0.01395,2.115,0.000
11.35,27.600,0.01411,2.120,0.000
11.39,27.700,0.01428,2.126,0.000
11.39,27.800,0.01444,2.128,0.000
11.43,27.900,0.01461,2.135,0.000
11.45,28.000,0.01478,2.139,0.000
11.47,28.100,0.01490,2.142,0.000
11.51,28.200,0.01507,2.149,0.000
11.54,28.300,0.01523,2.154,0.000
11.53,28.400,0.01536,2.154,0.000
11.57,28.500,0.01548,2.161,0.000
11.57,28.600,0.01565,2.160,0.000
11.60,28.700,0.01577,2.165,0.000
11.61,28.800,0.01590,2.169,0.000
11.61,28.900,0.01607,2.168,0.000
11.63,29.000,0.01619,2.173,0.000
11.66,29.100,0.01631,2.178,0.000
11.66,29.200,0.01644,2.177,0.000
11.72,29.300,0.01661,2.188,0.000
11.72,29.400,0.01673,2.189,0.000
11.75,29.500,0.01690,2.194,0.000
11.79,29.600,0.01702,2.202,0.000
11.79,29.700,0.01719,2.201,0.000
11.84,29.800,0.01731,2.211,0.000
11.85,29.900,0.01748,2.214,0.000
11.86,30.000,0.01760,2.216,0.000
11.92,30.100,0.01777,2.225,0.000
11.93,30.200,0.01794,2.227,0.000
11.93,30.300,0.01806,2.227,0.000
11.98,30.400,0.01823,2.236,0.000
11.98,30.500,0.01839,2.238,0.000
12.01,30.600,0.01856,2.242,0.000
12.05,30.700,0.01868,2.249,0.000
12.04,30.800,0.01885,2.249,0.000
12.10,30.900,0.01902,2.259,0.000
12.11,31.000,0.01918,2.261,0.000
12.14,31.100,0.01935,2.266,0.000
12.18,31.200,0.01947,2.274,0.000
12.18,31.300,0.01964,2.274,0.000
12.22,31.400,0.01985,2.282,0.000
12.26,31.500,0.02001,2.289,0.000
12.27,31.600,0.02018,2.292,0.000
12.32,31.700,0.02039,2.300,0.000
12.35,31.800,0.02055,2.306,0.000
12.36,31.900,0.02076,2.309,0.000
12.44,32.000,0.02097,2.324,0.000
12.45,32.100,0.02118,2.324,0.000
12.50,32.200,0.02138,2.334,0.000
12.54,32.300,0.02159,2.341,0.000
12.57,32.400,0.02180,2.347,0.000
12.61,32.500,0.02201,2.355,0.000
12.63,32.600,0.02222,2.359,0.000
12.68,32.700,0.02242,2.368,0.000
12.72,32.800,0.02263,2.375,0.000
12.72,32.900,0.02280,2.376,0.000
12.74,33.000,0.02300,2.379,0.000
12.80,33.100,0.02321,2.390,0.000
12.81,33.200,0.02338,2.392,0.000
12.85,33.300,0.02355,2.399,0.000
12.88,33.400,0.02371,2.405,0.000
12.89,33.500,0.02388,2.408,0.000
12.92,33.600,0.02404,2.412,0.000
12.91,33.700,0.02421,2.412,0.000
12.96,33.800,0.02433,2.420,0.000
12.98,33.900,0.02450,2.425,0.000
12.99,34.000,0.02463,2.426,0.000
13.03,34.100,0.02479,2.433,0.000
13.06,34.200,0.02492,2.438,0.000
13.05,34.300,0.02504,2.438,0.000
13.07,34.400,0.02521,2.441,0.000
13.10,34.500,0.02533,2.447,0.000
13.13,34.600,0.02546,2.453,0.001
13.15,34.700,0.02562,2.456,0.001
13.16,34.800,0.02575,2.458,0.001
13.19,34.900,0.02587,2.464,0.001
13.24,35.000,0.02600,2.473,0.001
13.24,35.100,0.02616,2.472,0.001
13.28,35.200,0.02629,2.480,0.001
13.31,35.300,0.02645,2.486,0.001
13.34,35.400,0.02658,2.491,0.001
13.36,35.500,0.02670,2.494,0.001
13.38,35.600,0.02687,2.499,0.001
13.42,35.700,0.02699,2.505,0.001
13.43,35.800,0.02716,2.509,0.001
13.45,35.900,0.02733,2.512,0.001
13.49,36.000,0.02745,2.518,0.001
13.53,36.100,0.02762,2.527,0.001
13.55,36.200,0.02778,2.531,0.001
13.56,36.300,0.02791,2.533,0.001
13.59,36.400,0.02807,2.537,0.001
13.62,36.500,0.02820,2.544,0.001
13.65,36.600,0.02837,2.549,0.001
13.66,36.700,0.02853,2.551,0.001
13.71,36.800,0.02870,2.560,0.001
13.75,36.900,0.02886,2.567,0.001
13.78,37.000,0.02903,2.573,0.001
13.80,37.100,0.02920,2.577,0.001
13.84,37.200,0.02936,2.585,0.001
13.88,37.300,0.02953,2.592,0.001
13.90,37.400,0.02974,2.595,0.001
13.96,37.500,0.02994,2.607,0.001
14.03,37.600,0.03011,2.620,0.001
14.06,37.700,0.03032,2.625,0.001
14.10,37.800,0.03057,2.633,0.001
14.15,37.900,0.03078,2.642,0.001
14.21,38.000,0.03098,2.653,0.001
14.21,38.100,0.03123,2.653,0.001
14.26,38.200,0.03144,2.664,0.001
14.31,38.300,0.03165,2.673,0.001
14.33,38.400,0.03186,2.676,0.001
14.37,38.500,0.03206,2.684,0.001
14.40,38.600,0.03223,2.690,0.001
14.43,38.700,0.03244,2.695,0.001
14.48,38.800,0.03265,2.704,0.001
14.50,38.900,0.03281,2.708,0.001
14.55,39.000,0.03298,2.717,0.001
14.58,39.100,0.03314,2.722,0.001
14.58,39.200,0.03331,2.723,0.001
14.62,39.300,0.03348,2.729,0.001
14.65,39.400,0.03360,2.736,0.001
14.67,39.500,0.03377,2.739,0.001
14.71,39.600,0.03389,2.748,0.001
14.74,39.700,0.03406,2.753,0.001
14.75,39.800,0.03418,2.755,0.001
14.78,39.900,0.03435,2.760,0.001
14.79,40.000,0.03447,2.762,0.001
14.84,40.100,0.03460,2.770,0.001
14.84,40.200,0.03472,2.771,0.001
14.87,40.300,0.03489,2.777,0.001
14.90,40.400,0.03501,2.783,0.001
14.91,40.500,0.03514,2.784,0.001
14.95,40.600,0.03531,2.791,0.001
15.00,40.700,0.03543,2.801,0.001
14.98,40.800,0.03560,2.797,0.001
15.05,40.900,0.03572,2.810,0.001
15.09,41.000,0.03589,2.818,0.001
15.10,41.100,0.03605,2.820,0.001
15.12,41.200,0.03618,2.824,0.001
15.18,41.300,0.03634,2.834,0.001
15.17,41.400,0.03647,2.834,0.001
15.23,41.500,0.03664,2.844,0.001
15.26,41.600,0.03680,2.850,0.001
15.27,41.700,0.03693,2.851,0.001
15.31,41.800,0.03709,2.859,0.001
15.33,41.900,0.03726,2.862,0.001
15.38,42.000,0.03742,2.872,0.001
15.42,42.100,0.03755,2.879,0.001
15.44,42.200,0.03772,2.883,0.001
15.49,42.300,0.03788,2.893,0.001
15.52,42.400,0.03805,2.899,0.001
15.56,42.500,0.03821,2.906,0.001
15.61,42.600,0.03838,2.915,0.001
15.62,42.700,0.03855,2.917,0.001
15.66,42.800,0.03871,2.925,0.001
15.71,42.900,0.03892,2.934,0.001
15.76,43.000,0.03913,2.943,0.001
15.82,43.100,0.03929,2.953,0.001
15.87,43.200,0.03950,2.963,0.001
15.89,43.300,0.03971,2.968,0.001
15.96,43.400,0.03996,2.981,0.001
16.02,43.500,0.04017,2.992,0.001
16.06,43.600,0.04038,3.000,0.001
16.11,43.700,0.04062,3.009,0.001
16.14,43.800,0.04083,3.014,0.001
16.20,43.900,0.04104,3.025,0.001
16.24,44.000,0.04125,3.032,0.001
16.24,44.100,0.04146,3.033,0.001
16.31,44.200,0.04166,3.046,0.001
16.34,44.300,0.04187,3.052,0.001
16.39,44.400,0.04204,3.061,0.001
16.43,44.500,0.04225,3.068,0.001
16.45,44.600,0.04241,3.071,0.001
16.48,44.700,0.04262,3.077,0.001
16.53,44.800,0.04274,3.086,0.001
16.53,44.900,0.04291,3.086,0.001
16.58,45.000,0.04308,3.096,0.001
16.61,45.100,0.04324,3.101,0.001
16.63,45.200,0.04337,3.106,0.001
16.68,45.300,0.04353,3.114,0.001
16.70,45.400,0.04370,3.119,0.001
16.71,45.500,0.04382,3.121,0.001
16.77,45.600,0.04399,3.132,0.001
16.79,45.700,0.04412,3.135,0.001
16.81,45.800,0.04424,3.139,0.001
16.85,45.900,0.04441,3.147,0.001
16.86,46.000,0.04453,3.149,0.001
16.88,46.100,0.04466,3.152,0.001
16.93,46.200,0.04478,3.162,0.001
16.97,46.300,0.04495,3.168,0.001
17.00,46.400,0.04507,3.175,0.001
17.03,46.500,0.04524,3.180,0.001
17.08,46.600,0.04540,3.189,0.001
17.11,46.700,0.04553,3.195,0.001
17.12,46.800,0.04569,3.197,0.001
17.18,46.900,0.04586,3.209,0.001
17.22,47.000,0.04599,3.216,0.001
17.25,47.100,0.04615,3.221,0.001
17.32,47.200,0.04632,3.234,0.001
17.33,47.300,0.04648,3.236,0.001
17.37,47.400,0.04661,3.244,0.001
17.40,47.500,0.04677,3.250,0.001
17.44,47.600,0.04694,3.257,0.001
17.50,47.700,0.04711,3.268,0.001
17.51,47.800,0.04727,3.270,0.001
17.55,47.900,0.04744,3.278,0.001
17.63,48.000,0.04761,3.292,0.001
17.65,48.100,0.04777,3.295,0.001
17.68,48.200,0.04794,3.301,0.001
17.74,48.300,0.04810,3.312,0.001
17.79,48.400,0.04827,3.323,0.001
17.84,48.500,0.04848,3.331,0.001
17.87,48.600,0.04864,3.337,0.001
17.94,48.700,0.04885,3.350,0.001
17.98,48.800,0.04906,3.357,0.001
18.02,48.900,0.04927,3.365,0.001
18.07,49.000,0.04948,3.375,0.001
18.16,49.100,0.04968,3.392,0.001
18.18,49.200,0.04989,3.394,0.001
18.25,49.300,0.05010,3.408,0.001
18.30,49.400,0.05031,3.417,0.001
18.33,49.500,0.05051,3.423,0.001
18.40,49.600,0.05068,3.435,0.001
18.43,49.700,0.05089,3.442,0.001
18.48,49.800,0.05110,3.451,0.001
18.52,49.900,0.05130,3.459,0.001
18.55,50.000,0.05147,3.463,0.001
18.63,50.100,0.05168,3.479,0.001
18.66,50.200,0.05184,3.485,0.001
18.71,50.300,0.05201,3.493,0.001
18.74,50.400,0.05222,3.499,0.001
18.76,50.500,0.05238,3.504,0.001
18.79,50.600,0.05251,3.509,0.001
18.86,50.700,0.05268,3.522,0.001
18.88,50.800,0.05284,3.526,0.001
18.92,50.900,0.05301,3.534,0.001
18.96,51.000,0.05313,3.540,0.001
18.99,51.100,0.05330,3.546,0.001
19.02,51.200,0.05342,3.552,0.001
19.06,51.300,0.05355,3.560,0.001
19.09,51.400,0.05371,3.564,0.001
19.13,51.500,0.05384,3.572,0.001
19.15,51.600,0.05396,3.576,0.001
19.20,51.700,0.05413,3.586,0.001
19.24,51.800,0.05425,3.593,0.001
19.25,51.900,0.05438,3.595,0.001
19.30,52.000,0.05455,3.605,0.001
19.35,52.100,0.05467,3.613,0.001
19.37,52.200,0.05484,3.617,0.001
19.42,52.300,0.05496,3.626,0.001
19.45,52.400,0.05513,3.633,0.001
19.49,52.500,0.05525,3.639,0.001
19.55,52.600,0.05542,3.650,0.001
19.59,52.700,0.05558,3.658,0.001
19.61,52.800,0.05571,3.662,0.001
19.69,52.900,0.05588,3.677,0.001
19.69,53.000,0.05604,3.677,0.001
19.75,53.100,0.05621,3.687,0.001
19.79,53.200,0.05633,3.696,0.001
19.80,53.300,0.05650,3.698,0.001
19.88,53.400,0.05667,3.712,0.001
19.89,53.500,0.05683,3.715,0.001
19.93,53.600,0.05696,3.723,0.001
20.01,53.700,0.05712,3.736,0.001
20.03,53.800,0.05729,3.740,0.001
20.09,53.900,0.05745,3.751,0.001
20.14,54.000,0.05762,3.762,0.001
20.19,54.100,0.05779,3.771,0.001
20.25,54.200,0.05800,3.782,0.001
20.30,54.300,0.05820,3.791,0.001
20.35,54.400,0.05837,3.800,0.001
20.43,54.500,0.05858,3.814,0.001
20.48,54.600,0.05878,3.824,0.001
20.54,54.700,0.05899,3.835,0.001
20.63,54.800,0.05920,3.853,0.001
20.67,54.900,0.05945,3.859,0.001
20.73,55.000,0.05966,3.871,0.001
20.79,55.100,0.05987,3.882,0.001
20.85,55.200,0.06007,3.893,0.001
20.91,55.300,0.06028,3.905,0.001
20.96,55.400,0.06049,3.914,0.001
21.03,55.500,0.06070,3.927,0.001
21.09,55.600,0.06090,3.938,0.001
21.12,55.700,0.06107,3.943,0.001
21.17,55.800,0.06128,3.953,0.001
21.23,55.900,0.06144,3.965,0.001
21.25,56.000,0.06161,3.968,0.001
21.29,56.100,0.06178,3.977,0.001
21.36,56.200,0.06194,3.989,0.001
21.40,56.300,0.06211,3.995,0.001
21.44,56.400,0.06223,4.003,0.001
21.45,56.500,0.06240,4.006,0.001
21.50,56.600,0.06252,4.015,0.001
21.55,56.700,0.06269,4.025,0.001
21.56,56.800,0.06282,4.026,0.001
21.60,56.900,0.06294,4.034,0.001
21.65,57.000,0.06306,4.043,0.001
21.67,57.100,0.06323,4.047,0.001
21.71,57.200,0.06336,4.055,0.001
21.77,57.300,0.06348,4.066,0.001
21.80,57.400,0.06365,4.070,0.001
21.84,57.500,0.06377,4.079,0.001
21.88,57.600,0.06390,4.087,0.001
21.91,57.700,0.06406,4.092,0.001
21.98,57.800,0.06423,4.105,0.001
22.02,57.900,0.06435,4.112,0.001
22.07,58.000,0.06452,4.121,0.001
22.14,58.100,0.06464,4.135,0.001
22.16,58.200,0.06481,4.138,0.001
22.20,58.300,0.06498,4.145,0.001
22.25,58.400,0.06510,4.155,0.001
22.31,58.500,0.06527,4.166,0.001
22.35,58.600,0.06543,4.173,0.001
22.38,58.700,0.06556,4.178,0.001
22.43,58.800,0.06572,4.189,0.001
22.49,58.900,0.06589,4.199,0.001
22.51,59.000,0.06602,4.203,0.001
22.56,59.100,0.06618,4.213,0.001
22.62,59.200,0.06635,4.224,0.001
22.66,59.300,0.06651,4.231,0.001
22.70,59.400,0.06668,4.240,0.001
22.75,59.500,0.06685,4.249,0.001
22.80,59.600,0.06701,4.258,0.001
22.88,59.700,0.06718,4.272,0.001
22.91,59.800,0.06739,4.279,0.001
22.98,59.900,0.06755,4.292,0.001
23.06,60.000,0.06776,4.306,0.001
23.11,60.100,0.06797,4.315,0.001
23.18,60.200,0.06813,4.329,0.001
23.24,60.300,0.06834,4.341,0.001
23.28,60.400,0.06855,4.347,0.001
23.37,60.500,0.06876,4.364,0.001
23.44,60.600,0.06901,4.377,0.001
23.49,60.700,0.06922,4.387,0.001
23.57,60.800,0.06942,4.402,0.001
23.60,60.900,0.06959,4.407,0.001
23.67,61.000,0.06980,4.420,0.001
23.75,61.100,0.07000,4.435,0.001
23.81,61.200,0.07021,4.446,0.001
23.85,61.300,0.07042,4.454,0.001
23.92,61.400,0.07059,4.466,0.001
23.96,61.500,0.07075,4.474,0.001
24.03,61.600,0.07096,4.487,0.001
24.06,61.700,0.07113,4.492,0.001
24.11,61.800,0.07125,4.502,0.001
24.17,61.900,0.07142,4.513,0.001
24.20,62.000,0.07158,4.520,0.001
24.23,62.100,0.07171,4.525,0.001
24.29,62.200,0.07187,4.536,0.001
24.30,62.300,0.07200,4.538,0.001
24.38,62.400,0.07212,4.552,0.001
24.37,62.500,0.07229,4.552,0.001
24.45,62.600,0.07241,4.565,0.001
24.47,62.700,0.07254,4.570,0.001
24.53,62.800,0.07271,4.580,0.001
24.55,62.900,0.07283,4.585,0.001
24.61,63.000,0.07296,4.596,0.001
24.62,63.100,0.07312,4.597,0.001
24.70,63.200,0.07325,4.612,0.001
24.73,63.300,0.07337,4.618,0.001
24.77,63.400,0.07354,4.626,0.001
24.82,63.500,0.07366,4.635,0.001
24.87,63.600,0.07383,4.645,0.001
24.90,63.700,0.07399,4.649,0.001
24.97,63.800,0.07412,4.663,0.001
24.99,63.900,0.07424,4.666,0.001
25.06,64.000,0.07441,4.679,0.001
25.11,64.100,0.07458,4.689,0.001
25.16,64.200,0.07474,4.698,0.001
25.18,64.300,0.07487,4.703,0.001
25.25,64.400,0.07503,4.715,0.001
25.30,64.500,0.07520,4.724,0.001
25.33,64.600,0.07532,4.731,0.001
25.38,64.700,0.07549,4.740,0.001
25.45,64.800,0.07566,4.753,0.001
25.48,64.900,0.07582,4.759,0.001
25.54,65.000,0.07595,4.769,0.001
25.61,65.100,0.07611,4.782,0.001
25.67,65.200,0.07628,4.793,0.002
25.69,65.300,0.07649,4.797,0.002
25.78,65.400,0.07665,4.814,0.002
25.83,65.500,0.07682,4.824,0.002
25.89,65.600,0.07699,4.834,0.002
25.98,65.700,0.07719,4.851,0.002
26.03,65.800,0.07740,4.861,0.002
26.09,65.900,0.07757,4.871,0.002
26.18,66.000,0.07778,4.888,0.002
26.23,66.100,0.07798,4.898,0.002
26.31,66.200,0.07819,4.913,0.002
26.37,66.300,0.07840,4.925,0.002
26.44,66.400,0.07861,4.937,0.002
26.53,66.500,0.07886,4.954,0.002
26.58,66.600,0.07906,4.964,0.002
26.62,66.700,0.07923,4.972,0.002
26.72,66.800,0.07944,4.989,0.002
26.74,66.900,0.07965,4.994,0.002
26.82,67.000,0.07985,5.008,0.002
26.89,67.100,0.08002,5.021,0.002
26.92,67.200,0.08019,5.027,0.002
26.97,67.300,0.08035,5.036,0.002
27.01,67.400,0.08052,5.045,0.002
27.04,67.500,0.08068,5.050,0.002
27.10,67.600,0.08085,5.061,0.002
27.14,67.700,0.08102,5.068,0.002
27.19,67.800,0.08114,5.078,0.002
27.26,67.900,0.08131,5.090,0.002
27.27,68.000,0.08147,5.092,0.002
27.33,68.100,0.08160,5.104,0.002
27.36,68.200,0.08172,5.109,0.002
27.40,68.300,0.08189,5.116,0.002
27.46,68.400,0.08201,5.128,0.002
27.49,68.500,0.08214,5.134,0.002
27.52,68.600,0.08231,5.139,0.002
27.59,68.700,0.08243,5.151,0.002
27.62,68.800,0.08255,5.157,0.002
27.66,68.900,0.08272,5.165,0.002
27.73,69.000,0.08285,5.178,0.002
27.75,69.100,0.08297,5.182,0.002
27.80,69.200,0.08314,5.191,0.002
27.86,69.300,0.08326,5.203,0.002
27.89,69.400,0.08343,5.207,0.002
27.96,69.500,0.08355,5.220,0.002
27.98,69.600,0.08372,5.224,0.002
28.04,69.700,0.08384,5.236,0.002
28.07,69.800,0.08401,5.242,0.002
28.11,69.900,0.08418,5.250,0.002
28.18,70.000,0.08430,5.262,0.002
28.26,70.100,0.08447,5.276,0.002
28.29,70.200,0.08463,5.283,0.002
28.36,70.300,0.08476,5.296,0.002
28.39,70.400,0.08492,5.302,0.002
28.44,70.500,0.08509,5.311,0.002
28.49,70.600,0.08521,5.321,0.002
28.55,70.700,0.08538,5.332,0.002
28.61,70.800,0.08555,5.342,0.002
28.66,70.900,0.08571,5.353,0.002
28.72,71.000,0.08588,5.363,0.002
28.79,71.100,0.08605,5.377,0.002
28.85,71.200,0.08625,5.388,0.002
28.91,71.300,0.08642,5.398,0.002
28.98,71.400,0.08659,5.413,0.002
29.06,71.500,0.08679,5.426,0.002
29.12,71.600,0.08700,5.437,0.002
29.19,71.700,0.08721,5.452,0.002
29.28,71.800,0.08742,5.468,0.002
29.37,71.900,0.08762,5.484,0.002
29.42,72.000,0.08783,5.495,0.002
29.48,72.100,0.08808,5.505,0.002
29.58,72.200,0.08829,5.525,0.002
29.64,72.300,0.08850,5.535,0.002
29.70,72.400,0.08870,5.546,0.002
29.77,72.500,0.08891,5.559,0.002
29.83,72.600,0.08908,5.571,0.002
29.88,72.700,0.08929,5.581,0.002
29.95,72.800,0.08945,5.594,0.002
29.99,72.900,0.08966,5.600,0.002
30.05,73.000,0.08983,5.611,0.002
30.11,73.100,0.08999,5.622,0.002
30.14,73.200,0.09016,5.628,0.002
30.21,73.300,0.09033,5.641,0.002
30.26,73.400,0.09049,5.650,0.002
30.27,73.500,0.09062,5.653,0.002
30.35,73.600,0.09078,5.667,0.002
30.36,73.700,0.09091,5.669,0.002
30.41,73.800,0.09107,5.680,0.002
30.45,73.900,0.09120,5.685,0.002
30.50,74.000,0.09132,5.696,0.002
30.55,74.100,0.09149,5.705,0.002
30.59,74.200,0.09161,5.712,0.002
30.62,74.300,0.09174,5.718,0.002
30.68,74.400,0.09186,5.729,0.002
30.72,74.500,0.09203,5.737,0.002
30.77,74.600,0.09215,5.746,0.002
30.80,74.700,0.09228,5.752,0.002
30.87,74.800,0.09244,5.765,0.002
30.94,74.900,0.09261,5.778,0.002
31.00,75.000,0.09274,5.788,0.002
31.02,75.100,0.09290,5.793,0.002
31.10,75.200,0.09303,5.808,0.002
31.15,75.300,0.09319,5.818,0.002
31.20,75.400,0.09336,5.826,0.002
31.27,75.500,0.09348,5.839,0.002
31.31,75.600,0.09365,5.848,0.002
31.35,75.700,0.09382,5.855,0.002
31.43,75.800,0.09398,5.869,0.002
31.47,75.900,0.09411,5.877,0.002
31.54,76.000,0.09427,5.891,0.002
31.59,76.100,0.09444,5.899,0.002
31.64,76.200,0.09461,5.908,0.002
31.70,76.300,0.09477,5.920,0.002
31.76,76.400,0.09494,5.931,0.002
31.80,76.500,0.09506,5.938,0.002
31.89,76.600,0.09527,5.956,0.002
31.94,76.700,0.09544,5.965,0.002
32.02,76.800,0.09560,5.980,0.002
32.10,76.900,0.09581,5.995,0.002
32.13,77.000,0.09598,6.000,0.002
32.23,77.100,0.09618,6.018,0.002
32.30,77.200,0.09639,6.031,0.002
32.37,77.300,0.09660,6.044,0.002
32.47,77.400,0.09681,6.063,0.002
32.55,77.500,0.09706,6.078,0.002
32.59,77.600,0.09727,6.086,0.002
32.69,77.700,0.09747,6.105,0.002
32.73,77.800,0.09768,6.112,0.002
32.80,77.900,0.09793,6.125,0.002
32.85,78.000,0.09814,6.135,0.002
32.93,78.100,0.09835,6.150,0.002
32.99,78.200,0.09855,6.161,0.002
33.06,78.300,0.09876,6.173,0.002
33.11,78.400,0.09893,6.182,0.002
33.19,78.500,0.09914,6.197,0.002
33.21,78.600,0.09930,6.202,0.002
33.26,78.700,0.09947,6.211,0.002
33.32,78.800,0.09963,6.223,0.002
33.37,78.900,0.09980,6.232,0.002
33.42,79.000,0.09997,6.241,0.002
33.48,79.100,0.10013,6.252,0.002
33.50,79.200,0.10026,6.256,0.002
33.58,79.300,0.10042,6.271,0.002
33.61,79.400,0.10055,6.276,0.002
33.65,79.500,0.10071,6.284,0.002
33.72,79.600,0.10084,6.296,0.002
33.74,79.700,0.10096,6.300,0.002
33.77,79.800,0.10113,6.307,0.002
33.85,79.900,0.10125,6.320,0.002
33.86,80.000,0.10138,6.323,0.002
33.94,80.100,0.10155,6.337,0.002
33.97,80.200,0.10167,6.344,0.002
34.03,80.300,0.10184,6.355,0.002
34.12,80.400,0.10196,6.371,0.002
34.15,80.500,0.10213,6.378,0.002
34.18,80.600,0.10225,6.383,0.002
34.27,80.700,0.10242,6.399,0.002
34.31,80.800,0.10258,6.407,0.002
34.36,80.900,0.10271,6.416,0.002
34.39,81.000,0.10288,6.423,0.002
34.47,81.100,0.10304,6.437,0.002
34.51,81.200,0.10321,6.444,0.002
34.57,81.300,0.10333,6.456,0.002
34.60,81.400,0.10350,6.461,0.002
34.69,81.500,0.10366,6.478,0.002
34.72,81.600,0.10383,6.483,0.002
34.77,81.700,0.10400,6.492,0.002
34.83,81.800,0.10412,6.504,0.002
34.89,81.900,0.10429,6.515,0.002
34.92,82.000,0.10445,6.521,0.002
34.98,82.100,0.10462,6.532,0.002
35.04,82.200,0.10479,6.543,0.002
35.10,82.300,0.10495,6.554,0.002
35.15,82.400,0.10516,6.563,0.002
35.21,82.500,0.10533,6.575,0.002
35.29,82.600,0.10549,6.590,0.002
35.35,82.700,0.10570,6.601,0.002
35.44,82.800,0.10591,6.618,0.002
35.51,82.900,0.10612,6.631,0.002
35.57,83.000,0.10632,6.642,0.002
35.62,83.100,0.10653,6.652,0.002
35.71,83.200,0.10674,6.668,0.002
35.77,83.300,0.10695,6.679,0.002
35.86,83.400,0.10716,6.697,0.002
35.90,83.500,0.10736,6.704,0.002
35.96,83.600,0.10757,6.715,0.002
36.06,83.700,0.10778,6.733,0.002
36.10,83.800,0.10799,6.741,0.002
36.14,83.900,0.10815,6.748,0.002
36.23,84.000,0.10836,6.765,0.002
36.22,84.100,0.10857,6.765,0.002
36.30,84.200,0.10873,6.779,0.002
36.34,84.300,0.10890,6.786,0.002
36.36,84.400,0.10907,6.790,0.002
36.40,84.500,0.10919,6.796,0.002
36.43,84.600,0.10936,6.804,0.002
36.46,84.700,0.10952,6.808,0.002
36.50,84.800,0.10965,6.816,0.002
36.51,84.900,0.10982,6.817,0.002
36.54,85.000,0.10994,6.824,0.002
36.56,85.100,0.11011,6.827,0.002
36.57,85.200,0.11023,6.830,0.002
36.61,85.300,0.11036,6.836,0.002
36.61,85.400,0.11052,6.837,0.002
36.63,85.500,0.11065,6.840,0.002
36.67,85.600,0.11077,6.848,0.002
36.67,85.700,0.11094,6.847,0.002
36.70,85.800,0.11106,6.854,0.002
36.72,85.900,0.11119,6.857,0.002
36.73,86.000,0.11135,6.859,0.002
36.76,86.100,0.11148,6.865,0.002
36.78,86.200,0.11164,6.868,0.002
36.78,86.300,0.11177,6.868,0.002
36.81,86.400,0.11193,6.875,0.002
36.81,86.500,0.11210,6.873,0.002
36.83,86.600,0.11223,6.877,0.002
36.82,86.700,0.11239,6.875,0.002
36.80,86.800,0.11252,6.873,0.002
36.79,86.900,0.11268,6.871,0.002
36.80,87.000,0.11285,6.871,0.002
36.75,87.100,0.11297,6.862,0.002
36.76,87.200,0.11314,6.864,0.002
36.66,87.300,0.11331,6.845,0.002
36.62,87.400,0.11343,6.838,0.002
36.57,87.500,0.11360,6.829,0.002
36.53,87.600,0.11376,6.822,0.002
36.49,87.700,0.11393,6.814,0.002
36.46,87.800,0.11410,6.809,0.002
36.42,87.900,0.11426,6.802,0.002
36.41,88.000,0.11443,6.799,0.002
36.33,88.100,0.11464,6.784,0.002
36.29,88.200,0.11480,6.777,0.002
36.20,88.300,0.11501,6.760,0.002
36.09,88.400,0.11522,6.740,0.002
36.02,88.500,0.11543,6.725,0.002
35.97,88.600,0.11559,6.717,0.002
35.90,88.700,0.11584,6.704,0.002
35.85,88.800,0.11605,6.695,0.002
35.77,88.900,0.11626,6.680,0.002
35.67,89.000,0.11646,6.660,0.002
35.54,89.100,0.11667,6.637,0.002
35.38,89.200,0.11688,6.607,0.002
35.23,89.300,0.11709,6.579,0.002
35.10,89.400,0.11730,6.554,0.002
34.96,89.500,0.11750,6.528,0.002
34.82,89.600,0.11771,6.502,0.002
34.73,89.700,0.11788,6.486,0.002
34.58,89.800,0.11804,6.458,0.002
34.48,89.900,0.11821,6.438,0.002
34.37,90.000,0.11838,6.419,0.002
34.28,90.100,0.11854,6.401,0.002
34.17,90.200,0.11871,6.380,0.002
34.05,90.300,0.11883,6.358,0.002
33.90,90.400,0.11900,6.330,0.002
33.84,90.500,0.11912,6.319,0.002
33.71,90.600,0.11929,6.296,0.002
33.63,90.700,0.11941,6.280,0.002
33.54,90.800,0.11958,6.263,0.002
33.44,90.900,0.11971,6.245,0.002
33.36,91.000,0.11983,6.230,0.002
33.31,91.100,0.11995,6.221,0.002
33.21,91.200,0.12008,6.201,0.002
33.15,91.300,0.12025,6.191,0.002
33.08,91.400,0.12037,6.177,0.002
33.00,91.500,0.12050,6.163,0.002
32.93,91.600,0.12066,6.149,0.002
32.83,91.700,0.12079,6.131,0.002
32.70,91.800,0.12091,6.107,0.002
32.58,91.900,0.12108,6.084,0.002
32.24,92.000,0.12120,6.021,0.002
31.99,92.100,0.12137,5.974,0.002
31.70,92.200,0.12153,5.919,0.002
31.46,92.300,0.12166,5.874,0.002
31.28,92.400,0.12182,5.841,0.002
31.06,92.500,0.12199,5.800,0.002
30.86,92.600,0.12212,5.763,0.002
30.71,92.700,0.12228,5.734,0.002
30.51,92.800,0.12245,5.698,0.002
30.34,92.900,0.12257,5.667,0.002
30.14,93.000,0.12274,5.629,0.002
29.94,93.100,0.12291,5.591,0.002
29.55,93.200,0.12307,5.519,0.002
24.74,93.300,0.12320,4.621,0.002
24.36,93.400,0.12336,4.550,0.002
24.13,93.500,0.12353,4.506,0.002
23.96,93.600,0.12369,4.474,0.002
23.87,93.700,0.12386,4.457,0.002
23.79,93.800,0.12407,4.443,0.002
23.73,93.900,0.12424,4.432,0.002
23.71,94.000,0.12444,4.428,0.002
23.66,94.100,0.12465,4.419,0.002
23.63,94.200,0.12486,4.412,0.002
23.60,94.300,0.12507,4.408,0.002
23.58,94.400,0.12527,4.403,0.002
23.55,94.500,0.12548,4.398,0.002
23.55,94.600,0.12569,4.398,0.002
23.52,94.700,0.12590,4.393,0.002
23.50,94.800,0.12611,4.388,0.002
23.49,94.900,0.12631,4.386,0.002
23.45,95.000,0.12652,4.380,0.002
23.45,95.100,0.12673,4.380,0.002
23.42,95.200,0.12689,4.373,0.002
23.38,95.300,0.12710,4.367,0.003
23.37,95.400,0.12731,4.365,0.003
23.33,95.500,0.12748,4.357,0.003
23.32,95.600,0.12764,4.355,0.003
23.31,95.700,0.12781,4.353,0.003
23.30,95.800,0.12798,4.351,0.003
23.30,95.900,0.12814,4.351,0.003
23.29,96.000,0.12827,4.350,0.003
23.26,96.100,0.12843,4.343,0.003
23.26,96.200,0.12856,4.343,0.003
23.23,96.300,0.12872,4.339,0.003
23.19,96.400,0.12885,4.330,0.003
23.20,96.500,0.12901,4.332,0.003
23.18,96.600,0.12914,4.328,0.003
23.16,96.700,0.12926,4.325,0.003
23.16,96.800,0.12939,4.325,0.003
23.13,96.900,0.12955,4.320,0.003
23.13,97.000,0.12968,4.320,0.003
23.13,97.100,0.12980,4.320,0.003
23.11,97.200,0.12997,4.315,0.003
23.11,97.300,0.13009,4.315,0.003
23.10,97.400,0.13022,4.313,0.003
23.08,97.500,0.13039,4.309,0.003
23.10,97.600,0.13051,4.313,0.003
23.08,97.700,0.13068,4.311,0.003
23.10,97.800,0.13080,4.314,0.003
23.11,97.900,0.13097,4.315,0.003
23.09,98.000,0.13109,4.312,0.003
23.09,98.100,0.13126,4.312,0.003
23.10,98.200,0.13142,4.314,0.003
23.06,98.300,0.13155,4.306,0.003
23.07,98.400,0.13172,4.309,0.003
23.08,98.500,0.13184,4.311,0.003
23.06,98.600,0.13201,4.307,0.003
23.06,98.700,0.13217,4.305,0.003
23.05,98.800,0.13234,4.305,0.003
23.03,98.900,0.13246,4.301,0.003
23.02,99.000,0.13263,4.299,0.003
23.00,99.100,0.13280,4.294,0.003
22.98,99.200,0.13296,4.291,0.003
22.95,99.300,0.13313,4.286,0.003
22.92,99.400,0.13329,4.280,0.003
22.95,99.500,0.13346,4.285,0.003
22.92,99.600,0.13367,4.281,0.003
22.91,99.700,0.13383,4.278,0.003
22.93,99.800,0.13404,4.282,0.003
22.90,99.900,0.13421,4.277,0.003
22.90,100.000,0.13442,4.277,0.003
22.91,100.100,0.13462,4.278,0.003
22.90,100.200,0.13483,4.276,0.003
22.88,100.300,0.13504,4.272,0.003
22.88,100.400,0.13525,4.272,0.003
22.88,100.500,0.13546,4.272,0.003
22.85,100.600,0.13566,4.267,0.003
22.84,100.700,0.13587,4.265,0.003
22.81,100.800,0.13608,4.260,0.003
22.79,100.900,0.13624,4.256,0.003
22.75,101.000,0.13645,4.248,0.003
22.73,101.100,0.13662,4.244,0.003
22.68,101.200,0.13683,4.236,0.003
22.66,101.300,0.13699,4.232,0.003
22.64,101.400,0.13716,4.228,0.003
22.64,101.500,0.13733,4.227,0.003
22.63,101.600,0.13749,4.226,0.003
22.60,101.700,0.13762,4.220,0.003
22.59,101.800,0.13778,4.219,0.003
22.58,101.900,0.13795,4.216,0.003
22.57,102.000,0.13807,4.215,0.003
22.55,102.100,0.13824,4.212,0.003
22.54,102.200,0.13836,4.209,0.003
22.54,102.300,0.13849,4.209,0.003
22.53,102.400,0.13865,4.207,0.003
22.51,102.500,0.13878,4.203,0.003
22.50,102.600,0.13890,4.202,0.003
22.46,102.700,0.13907,4.194,0.003
22.47,102.800,0.13920,4.196,0.003
22.45,102.900,0.13932,4.193,0.003
22.44,103.000,0.13944,4.190,0.003
22.43,103.100,0.13961,4.189,0.003
22.41,103.200,0.13974,4.185,0.003
22.39,103.300,0.13986,4.180,0.003
22.38,103.400,0.14003,4.179,0.003
22.37,103.500,0.14015,4.176,0.003
22.36,103.600,0.14032,4.175,0.003
22.35,103.700,0.14044,4.174,0.003
22.33,103.800,0.14061,4.170,0.003
22.30,103.900,0.14077,4.164,0.003
22.29,104.000,0.14090,4.162,0.003
22.23,104.100,0.14107,4.151,0.003
22.20,104.200,0.14123,4.146,0.003
22.18,104.300,0.14136,4.143,0.003
22.14,104.400,0.14152,4.135,0.003
22.15,104.500,0.14169,4.136,0.003
22.13,104.600,0.14181,4.132,0.003
22.12,104.700,0.14198,4.130,0.003
22.11,104.800,0.14215,4.128,0.003
22.09,104.900,0.14231,4.125,0.003
22.07,105.000,0.14248,4.122,0.003
22.06,105.100,0.14264,4.120,0.003
22.06,105.200,0.14281,4.120,0.003
22.04,105.300,0.14298,4.116,0.003
22.02,105.400,0.14318,4.112,0.003
21.98,105.500,0.14335,4.104,0.003
21.96,105.600,0.14356,4.102,0.003
21.91,105.700,0.14377,4.092,0.003
21.89,105.800,0.14397,4.087,0.003
21.82,105.900,0.14418,4.075,0.003
21.76,106.000,0.14439,4.063,0.003
21.68,106.100,0.14460,4.048,0.003
21.64,106.200,0.14481,4.040,0.003
21.60,106.300,0.14501,4.033,0.003
21.54,106.400,0.14522,4.022,0.003
21.50,106.500,0.14543,4.014,0.003
21.47,106.600,0.14564,4.008,0.003
21.43,106.700,0.14584,4.001,0.003
21.35,106.800,0.14605,3.987,0.003
21.28,106.900,0.14622,3.974,0.003
21.21,107.000,0.14643,3.962,0.003
21.17,107.100,0.14659,3.954,0.003
21.13,107.200,0.14676,3.946,0.003
21.09,107.300,0.14692,3.938,0.003
21.05,107.400,0.14705,3.930,0.003
21.00,107.500,0.14722,3.921,0.003
20.97,107.600,0.14738,3.916,0.003
20.94,107.700,0.14751,3.910,0.003
20.90,107.800,0.14767,3.903,0.003
20.88,107.900,0.14780,3.899,0.003
20.83,108.000,0.14792,3.891,0.003
20.78,108.100,0.14809,3.880,0.003
20.75,108.200,0.14821,3.875,0.003
20.72,108.300,0.14834,3.869,0.003
20.68,108.400,0.14850,3.861,0.003
20.66,108.500,0.14863,3.857,0.003
20.61,108.600,0.14875,3.848,0.003
20.57,108.700,0.14892,3.841,0.003
20.52,108.800,0.14904,3.831,0.003
20.51,108.900,0.14921,3.829,0.003
20.45,109.000,0.14933,3.818,0.003
20.41,109.100,0.14950,3.811,0.003
20.38,109.200,0.14963,3.806,0.003
20.33,109.300,0.14979,3.796,0.003
20.19,109.400,0.14996,3.771,0.003
18.37,109.500,0.15008,3.431,0.003
17.73,109.600,0.15025,3.311,0.003
17.49,109.700,0.15042,3.267,0.003
17.36,109.800,0.15058,3.242,0.003
17.29,109.900,0.15075,3.228,0.003
17.19,110.000,0.15087,3.210,0.003
17.11,110.100,0.15104,3.196,0.003
17.03,110.200,0.15120,3.180,0.003
16.95,110.300,0.15137,3.166,0.003
16.81,110.400,0.15154,3.139,0.003
16.62,110.500,0.15170,3.104,0.003
16.07,110.600,0.15187,3.000,0.003
13.93,110.700,0.15204,2.602,0.003
13.11,110.800,0.15220,2.448,0.003
12.85,110.900,0.15237,2.399,0.003
12.70,111.000,0.15258,2.371,0.003
12.61,111.100,0.15278,2.356,0.003
12.55,111.200,0.15299,2.344,0.003
12.50,111.300,0.15320,2.334,0.003
12.45,111.400,0.15341,2.325,0.003
12.40,111.500,0.15362,2.316,0.003
12.37,111.600,0.15382,2.309,0.003
12.32,111.700,0.15403,2.300,0.003
12.27,111.800,0.15428,2.291,0.003
12.22,111.900,0.15449,2.283,0.003
12.16,112.000,0.15470,2.272,0.003
12.10,112.100,0.15490,2.260,0.003
12.07,112.200,0.15511,2.254,0.003
12.00,112.300,0.15532,2.241,0.003
11.94,112.400,0.15549,2.230,0.003
11.89,112.500,0.15569,2.220,0.003
11.82,112.600,0.15586,2.207,0.003
11.74,112.700,0.15607,2.192,0.003
11.69,112.800,0.15623,2.183,0.003
11.61,112.900,0.15636,2.169,0.003
11.56,113.000,0.15652,2.158,0.003
11.50,113.100,0.15669,2.147,0.003
11.44,113.200,0.15686,2.136,0.003
11.38,113.300,0.15698,2.126,0.003
11.30,113.400,0.15715,2.111,0.003
11.26,113.500,0.15727,2.103,0.003
11.21,113.600,0.15740,2.093,0.003
11.14,113.700,0.15756,2.080,0.003
11.08,113.800,0.15769,2.070,0.003
11.01,113.900,0.15781,2.057,0.003
10.99,114.000,0.15798,2.051,0.003
10.94,114.100,0.15810,2.043,0.003
10.88,114.200,0.15827,2.033,0.003
10.84,114.300,0.15839,2.024,0.003
10.80,114.400,0.15856,2.016,0.003
10.73,114.500,0.15868,2.004,0.003
10.67,114.600,0.15885,1.992,0.003
10.64,114.700,0.15898,1.987,0.003
10.59,114.800,0.15914,1.978,0.003
10.53,114.900,0.15931,1.967,0.003
10.47,114.980,0.15939,1.956,0.003