File: data-files/CWRU/0900-10-20A.txt
""
"Test Method","Will_Huddleston_Disks.msm"
"Sample I. D.","900-10-20A.mss"
"Specimen Number","1"

"Load (N)","Time (s)","Extension (mm)","Stress (MPa)","Strain (mm/mm)"

3.34,0.200,0.01240,0.622,0.000
3.34,0.300,0.01240,0.621,0.000
3.34,0.400,0.01240,0.621,0.000
3.33,0.500,0.01240,0.619,0.000
3.34,0.600,0.01240,0.621,0.000
3.33,0.700,0.01244,0.619,0.000
3.35,0.800,0.01244,0.623,0.000
3.34,0.900,0.01244,0.622,0.000
3.35,1.000,0.01244,0.622,0.000
3.33,1.100,0.01248,0.619,0.000
3.35,1.200,0.01248,0.622,0.000
3.32,1.300,0.01248,0.618,0.000
3.34,1.400,0.01252,0.622,0.000
3.32,1.500,0.01252,0.618,0.000
3.34,1.600,0.01252,0.620,0.000
3.33,1.700,0.01256,0.620,0.000
3.36,1.800,0.01260,0.625,0.000
3.38,1.900,0.01265,0.628,0.000
3.41,2.000,0.01273,0.634,0.000
3.46,2.100,0.01290,0.644,0.000
3.57,2.200,0.01306,0.664,0.000
3.61,2.300,0.01327,0.672,0.000
3.72,2.400,0.01348,0.691,0.000
3.76,2.500,0.01364,0.700,0.000
3.82,2.600,0.01385,0.711,0.000
3.89,2.700,0.01402,0.723,0.000
3.95,2.800,0.01423,0.735,0.000
4.01,2.900,0.01439,0.745,0.000
4.06,3.000,0.01456,0.755,0.000
4.10,3.100,0.01472,0.762,0.000
4.15,3.200,0.01489,0.772,0.000
4.21,3.300,0.01506,0.783,0.000
4.24,3.400,0.01518,0.789,0.000
4.26,3.500,0.01535,0.792,0.000
4.32,3.600,0.01547,0.803,0.000
4.34,3.700,0.01564,0.808,0.000
4.39,3.800,0.01576,0.817,0.000
4.42,3.900,0.01593,0.822,0.000
4.48,4.000,0.01605,0.834,0.000
4.51,4.100,0.01618,0.839,0.000
4.54,4.200,0.01630,0.843,0.000
4.57,4.300,0.01647,0.850,0.000
4.60,4.400,0.01659,0.856,0.000
4.64,4.500,0.01672,0.862,0.000
4.68,4.600,0.01684,0.870,0.000
4.72,4.700,0.01701,0.878,0.000
4.76,4.800,0.01713,0.886,0.000
4.79,4.900,0.01730,0.890,0.000
4.83,5.000,0.01743,0.898,0.000
4.86,5.100,0.01759,0.904,0.000
4.91,5.200,0.01772,0.913,0.000
4.95,5.300,0.01788,0.921,0.000
5.00,5.400,0.01801,0.929,0.000
5.04,5.500,0.01817,0.937,0.000
5.07,5.600,0.01834,0.943,0.000
5.13,5.700,0.01846,0.954,0.000
5.16,5.800,0.01863,0.960,0.000
5.20,5.900,0.01880,0.967,0.000
5.25,6.000,0.01892,0.976,0.000
5.28,6.100,0.01909,0.982,0.000
5.32,6.200,0.01925,0.989,0.000
5.36,6.300,0.01938,0.996,0.000
5.40,6.400,0.01954,1.004,0.000
5.44,6.500,0.01971,1.012,0.000
5.48,6.600,0.01988,1.018,0.000
5.51,6.700,0.02004,1.025,0.000
5.58,6.800,0.02021,1.037,0.000
5.62,6.900,0.02038,1.045,0.000
5.66,7.000,0.02058,1.052,0.000
5.72,7.100,0.02075,1.064,0.000
5.77,7.200,0.02096,1.074,0.000
5.80,7.300,0.02117,1.078,0.000
5.85,7.400,0.02137,1.088,0.000
5.92,7.500,0.02158,1.100,0.000
5.95,7.600,0.02179,1.107,0.000
6.02,7.700,0.02200,1.119,0.000
6.06,7.800,0.02220,1.127,0.000
6.12,7.900,0.02241,1.138,0.000
6.17,8.000,0.02262,1.147,0.000
6.22,8.100,0.02283,1.157,0.000
6.27,8.200,0.02304,1.166,0.000
6.31,8.300,0.02320,1.173,0.000
6.35,8.400,0.02341,1.181,0.000
6.40,8.500,0.02358,1.190,0.000
6.43,8.600,0.02378,1.196,0.000
6.48,8.700,0.02395,1.205,0.000
6.52,8.800,0.02412,1.212,0.000
6.57,8.900,0.02428,1.221,0.000
6.60,9.000,0.02445,1.227,0.000
6.64,9.100,0.02461,1.235,0.000
6.68,9.200,0.02478,1.242,0.000
6.71,9.300,0.02495,1.247,0.000
6.73,9.400,0.02507,1.252,0.000
6.78,9.500,0.02524,1.261,0.000
6.80,9.600,0.02536,1.264,0.000
6.82,9.700,0.02553,1.268,0.001
6.87,9.800,0.02565,1.277,0.001
6.89,9.900,0.02578,1.281,0.001
6.91,10.000,0.02594,1.285,0.001
6.94,10.100,0.02607,1.290,0.001
6.95,10.200,0.02619,1.292,0.001
7.00,10.300,0.02636,1.301,0.001
7.04,10.400,0.02648,1.308,0.001
7.06,10.500,0.02661,1.313,0.001
7.08,10.600,0.02678,1.317,0.001
7.12,10.700,0.02690,1.325,0.001
7.15,10.800,0.02707,1.329,0.001
7.18,10.900,0.02719,1.335,0.001
7.21,11.000,0.02736,1.340,0.001
7.24,11.100,0.02748,1.345,0.001
7.27,11.200,0.02765,1.352,0.001
7.29,11.300,0.02781,1.355,0.001
7.33,11.400,0.02794,1.363,0.001
7.36,11.500,0.02811,1.368,0.001
7.38,11.600,0.02827,1.372,0.001
7.41,11.700,0.02844,1.378,0.001
7.43,11.800,0.02856,1.382,0.001
7.46,11.900,0.02873,1.386,0.001
7.50,12.000,0.02889,1.394,0.001
7.50,12.100,0.02906,1.396,0.001
7.56,12.200,0.02923,1.405,0.001
7.59,12.300,0.02939,1.412,0.001
7.61,12.400,0.02956,1.416,0.001
7.66,12.500,0.02973,1.423,0.001
7.69,12.600,0.02989,1.430,0.001
7.73,12.700,0.03010,1.438,0.001
7.77,12.800,0.03027,1.445,0.001
7.81,12.900,0.03047,1.452,0.001
7.84,13.000,0.03068,1.458,0.001
7.90,13.100,0.03089,1.470,0.001
7.93,13.200,0.03110,1.474,0.001
7.96,13.300,0.03135,1.480,0.001
8.00,13.400,0.03155,1.487,0.001
8.03,13.500,0.03176,1.493,0.001
8.07,13.600,0.03197,1.501,0.001
8.11,13.700,0.03222,1.507,0.001
8.14,13.800,0.03243,1.514,0.001
8.16,13.900,0.03263,1.518,0.001
8.19,14.000,0.03284,1.522,0.001
8.21,14.100,0.03301,1.527,0.001
8.22,14.200,0.03322,1.529,0.001
8.25,14.300,0.03338,1.533,0.001
8.26,14.400,0.03355,1.536,0.001
8.27,14.500,0.03372,1.538,0.001
8.29,14.600,0.03388,1.542,0.001
8.31,14.700,0.03405,1.545,0.001
8.35,14.800,0.03421,1.552,0.001
8.36,14.900,0.03434,1.555,0.001
8.38,15.000,0.03450,1.558,0.001
8.40,15.100,0.03463,1.562,0.001
8.43,15.200,0.03480,1.568,0.001
8.44,15.300,0.03492,1.569,0.001
8.46,15.400,0.03505,1.573,0.001
8.47,15.500,0.03521,1.574,0.001
8.50,15.600,0.03534,1.580,0.001
8.51,15.700,0.03546,1.583,0.001
8.53,15.800,0.03559,1.587,0.001
8.55,15.900,0.03571,1.590,0.001
8.58,16.000,0.03588,1.596,0.001
8.58,16.100,0.03600,1.595,0.001
8.58,16.200,0.03617,1.596,0.001
8.63,16.300,0.03629,1.604,0.001
8.64,16.400,0.03646,1.607,0.001
8.66,16.500,0.03658,1.610,0.001
8.68,16.600,0.03675,1.614,0.001
8.70,16.700,0.03692,1.617,0.001
8.72,16.800,0.03704,1.621,0.001
8.73,16.900,0.03721,1.624,0.001
8.74,17.000,0.03737,1.625,0.001
8.79,17.100,0.03750,1.634,0.001
8.80,17.200,0.03766,1.635,0.001
8.82,17.300,0.03783,1.640,0.001
8.83,17.400,0.03800,1.642,0.001
8.85,17.500,0.03812,1.645,0.001
8.87,17.600,0.03829,1.649,0.001
8.91,17.700,0.03845,1.656,0.001
8.91,17.800,0.03858,1.658,0.001
8.96,17.900,0.03874,1.665,0.001
9.00,18.000,0.03891,1.673,0.001
9.01,18.100,0.03908,1.675,0.001
9.03,18.200,0.03928,1.680,0.001
9.07,18.300,0.03945,1.687,0.001
9.12,18.400,0.03962,1.695,0.001
9.14,18.500,0.03982,1.700,0.001
9.16,18.600,0.04003,1.703,0.001
9.21,18.700,0.04024,1.713,0.001
9.25,18.800,0.04045,1.720,0.001
9.28,18.900,0.04061,1.726,0.001
9.34,19.000,0.04082,1.736,0.001
9.38,19.100,0.04103,1.744,0.001
9.41,19.200,0.04128,1.750,0.001
9.46,19.300,0.04149,1.759,0.001
9.50,19.400,0.04169,1.767,0.001
9.53,19.500,0.04186,1.772,0.001
9.57,19.600,0.04207,1.779,0.001
9.61,19.700,0.04228,1.786,0.001
9.65,19.800,0.04248,1.795,0.001
9.68,19.900,0.04265,1.800,0.001
9.72,20.000,0.04286,1.807,0.001
9.73,20.100,0.04302,1.810,0.001
9.76,20.200,0.04319,1.816,0.001
9.80,20.300,0.04336,1.821,0.001
9.80,20.400,0.04352,1.823,0.001
9.83,20.500,0.04365,1.829,0.001
9.86,20.600,0.04381,1.833,0.001
9.88,20.700,0.04394,1.837,0.001
9.88,20.800,0.04410,1.836,0.001
9.92,20.900,0.04423,1.844,0.001
9.93,21.000,0.04440,1.846,0.001
9.96,21.100,0.04452,1.853,0.001
9.98,21.200,0.04464,1.856,0.001
10.02,21.300,0.04477,1.863,0.001
10.04,21.400,0.04494,1.868,0.001
10.08,21.500,0.04506,1.874,0.001
10.11,21.600,0.04518,1.879,0.001
10.15,21.700,0.04535,1.887,0.001
10.18,21.800,0.04548,1.892,0.001
10.18,21.900,0.04564,1.894,0.001
10.22,22.000,0.04577,1.899,0.001
10.26,22.100,0.04593,1.908,0.001
10.28,22.200,0.04606,1.912,0.001
10.32,22.300,0.04622,1.919,0.001
10.34,22.400,0.04635,1.923,0.001
10.37,22.500,0.04651,1.929,0.001
10.40,22.600,0.04668,1.934,0.001
10.44,22.700,0.04681,1.941,0.001
10.44,22.800,0.04697,1.942,0.001
10.49,22.900,0.04714,1.951,0.001
10.51,23.000,0.04726,1.954,0.001
10.55,23.100,0.04743,1.962,0.001
10.57,23.200,0.04759,1.965,0.001
10.62,23.300,0.04776,1.975,0.001
10.62,23.400,0.04793,1.975,0.001
10.66,23.500,0.04805,1.982,0.001
10.68,23.600,0.04822,1.987,0.001
10.74,23.700,0.04838,1.997,0.001
10.75,23.800,0.04855,1.999,0.001
10.79,23.900,0.04876,2.007,0.001
10.84,24.000,0.04892,2.015,0.001
10.88,24.100,0.04909,2.023,0.001
10.92,24.200,0.04930,2.030,0.001
10.96,24.300,0.04951,2.037,0.001
11.01,24.400,0.04967,2.047,0.001
11.05,24.500,0.04992,2.055,0.001
11.08,24.600,0.05013,2.060,0.001
11.13,24.700,0.05030,2.069,0.001
11.17,24.800,0.05055,2.077,0.001
11.19,24.900,0.05075,2.080,0.001
11.25,25.000,0.05096,2.091,0.001
11.28,25.100,0.05117,2.097,0.001
11.33,25.200,0.05133,2.107,0.001
11.34,25.300,0.05154,2.109,0.001
11.39,25.400,0.05175,2.119,0.001
11.42,25.500,0.05196,2.124,0.001
11.47,25.600,0.05212,2.132,0.001
11.48,25.700,0.05229,2.135,0.001
11.52,25.800,0.05246,2.143,0.001
11.54,25.900,0.05262,2.145,0.001
11.57,26.000,0.05279,2.151,0.001
11.58,26.100,0.05296,2.153,0.001
11.61,26.200,0.05312,2.159,0.001
11.63,26.300,0.05329,2.162,0.001
11.65,26.400,0.05341,2.166,0.001
11.65,26.500,0.05358,2.166,0.001
11.69,26.600,0.05370,2.173,0.001
11.67,26.700,0.05387,2.169,0.001
11.70,26.800,0.05399,2.175,0.001
11.71,26.900,0.05412,2.177,0.001
11.74,27.000,0.05424,2.182,0.001
11.75,27.100,0.05441,2.185,0.001
11.81,27.200,0.05453,2.197,0.001
11.83,27.300,0.05466,2.200,0.001
11.88,27.400,0.05483,2.209,0.001
11.90,27.500,0.05495,2.213,0.001
11.93,27.600,0.05507,2.218,0.001
11.95,27.700,0.05524,2.221,0.001
11.99,27.800,0.05537,2.229,0.001
11.99,27.900,0.05553,2.229,0.001
12.02,28.000,0.05566,2.236,0.001
12.06,28.100,0.05582,2.242,0.001
12.08,28.200,0.05595,2.246,0.001
12.12,28.300,0.05611,2.254,0.001
12.13,28.400,0.05624,2.256,0.001
12.17,28.500,0.05640,2.263,0.001
12.18,28.600,0.05657,2.265,0.001
12.22,28.700,0.05674,2.273,0.001
12.25,28.800,0.05686,2.277,0.001
12.27,28.900,0.05703,2.281,0.001
12.28,29.000,0.05715,2.283,0.001
12.33,29.100,0.05732,2.293,0.001
12.36,29.200,0.05749,2.298,0.001
12.38,29.300,0.05765,2.301,0.001
12.41,29.400,0.05782,2.307,0.001
12.44,29.500,0.05798,2.313,0.001
12.47,29.600,0.05815,2.319,0.001
12.51,29.700,0.05832,2.327,0.001
12.53,29.800,0.05852,2.330,0.001
12.58,29.900,0.05869,2.339,0.001
12.62,30.000,0.05890,2.346,0.001
12.66,30.100,0.05911,2.354,0.001
12.69,30.200,0.05931,2.360,0.001
12.74,30.300,0.05952,2.370,0.001
12.77,30.400,0.05977,2.374,0.001
12.81,30.500,0.05998,2.382,0.001
12.84,30.600,0.06019,2.388,0.001
12.88,30.700,0.06039,2.395,0.001
12.92,30.800,0.06060,2.402,0.001
12.93,30.900,0.06081,2.405,0.001
12.98,31.000,0.06102,2.414,0.001
13.02,31.100,0.06123,2.420,0.001
13.04,31.200,0.06139,2.425,0.001
13.08,31.300,0.06160,2.432,0.001
13.10,31.400,0.06177,2.436,0.001
13.12,31.500,0.06193,2.439,0.001
13.15,31.600,0.06210,2.444,0.001
13.15,31.700,0.06226,2.446,0.001
13.18,31.800,0.06243,2.451,0.001
13.21,31.900,0.06260,2.455,0.001
13.21,32.000,0.06272,2.457,0.001
13.25,32.100,0.06289,2.465,0.001
13.27,32.200,0.06301,2.468,0.001
13.30,32.300,0.06318,2.473,0.001
13.31,32.400,0.06330,2.476,0.001
13.36,32.500,0.06343,2.484,0.001
13.38,32.600,0.06359,2.489,0.001
13.41,32.700,0.06372,2.493,0.001
13.43,32.800,0.06384,2.497,0.001
13.44,32.900,0.06401,2.500,0.001
13.47,33.000,0.06413,2.505,0.001
13.49,33.100,0.06426,2.509,0.001
13.52,33.200,0.06443,2.515,0.001
13.55,33.300,0.06455,2.519,0.001
13.58,33.400,0.06467,2.525,0.001
13.61,33.500,0.06484,2.531,0.001
13.63,33.600,0.06501,2.534,0.001
13.66,33.700,0.06513,2.540,0.001
13.69,33.800,0.06530,2.545,0.001
13.69,33.900,0.06546,2.546,0.001
13.73,34.000,0.06559,2.554,0.001
13.77,34.100,0.06575,2.561,0.001
13.79,34.200,0.06592,2.565,0.001
13.83,34.300,0.06609,2.571,0.001
13.86,34.400,0.06625,2.577,0.001
13.90,34.500,0.06638,2.584,0.001
13.94,34.600,0.06654,2.591,0.001
13.95,34.700,0.06671,2.595,0.001
14.00,34.800,0.06688,2.603,0.001
14.03,34.900,0.06704,2.608,0.001
14.07,35.000,0.06721,2.617,0.001
14.11,35.100,0.06738,2.624,0.001
14.16,35.200,0.06758,2.633,0.001
14.20,35.300,0.06775,2.640,0.001
14.26,35.400,0.06796,2.651,0.001
14.30,35.500,0.06817,2.658,0.001
14.33,35.600,0.06837,2.665,0.001
14.36,35.700,0.06854,2.670,0.001
14.40,35.800,0.06875,2.678,0.001
14.44,35.900,0.06900,2.686,0.001
14.48,36.000,0.06920,2.693,0.001
14.52,36.100,0.06941,2.700,0.001
14.56,36.200,0.06962,2.708,0.001
14.61,36.300,0.06983,2.718,0.001
14.67,36.400,0.07004,2.728,0.001
14.70,36.500,0.07024,2.733,0.001
14.71,36.600,0.07045,2.736,0.001
14.46,36.700,0.07066,2.689,0.001
6.11,36.800,0.07087,1.136,0.001
6.38,36.900,0.07103,1.185,0.001
6.48,37.000,0.07124,1.204,0.001
6.57,37.100,0.07141,1.221,0.001
6.61,37.200,0.07157,1.230,0.001
6.67,37.300,0.07174,1.241,0.001
6.72,37.400,0.07191,1.249,0.001
6.76,37.500,0.07207,1.257,0.001
6.79,37.600,0.07220,1.262,0.001
6.84,37.700,0.07236,1.271,0.001
6.88,37.800,0.07253,1.279,0.001
6.90,37.900,0.07265,1.284,0.001
6.94,38.000,0.07282,1.291,0.001
6.98,38.100,0.07294,1.298,0.001
7.00,38.200,0.07307,1.302,0.001
7.06,38.300,0.07323,1.313,0.001
7.09,38.400,0.07336,1.319,0.001
7.13,38.500,0.07348,1.325,0.001
7.16,38.600,0.07361,1.331,0.001
7.21,38.700,0.07378,1.341,0.001
7.26,38.800,0.07390,1.350,0.001
7.26,38.900,0.07407,1.351,0.001
7.32,39.000,0.07419,1.361,0.001
7.36,39.100,0.07436,1.369,0.001
7.38,39.200,0.07452,1.373,0.001
7.41,39.300,0.07465,1.379,0.001
7.43,39.400,0.07481,1.382,0.001
7.47,39.500,0.07498,1.388,0.001
7.50,39.600,0.07510,1.394,0.001
7.53,39.700,0.07527,1.400,0.001
7.56,39.800,0.07544,1.405,0.001
7.59,39.900,0.07560,1.411,0.001
7.60,40.000,0.07577,1.413,0.001
7.65,40.100,0.07589,1.423,0.001
7.69,40.200,0.07606,1.430,0.001
7.73,40.300,0.07623,1.437,0.002
7.76,40.400,0.07639,1.442,0.002
7.77,40.500,0.07656,1.445,0.002
7.83,40.600,0.07673,1.455,0.002
7.83,40.700,0.07689,1.456,0.002
7.87,40.800,0.07706,1.464,0.002
7.91,40.900,0.07727,1.472,0.002
7.96,41.000,0.07743,1.480,0.002
7.98,41.100,0.07764,1.484,0.002
8.04,41.200,0.07781,1.496,0.002
8.07,41.300,0.07801,1.501,0.002
8.12,41.400,0.07822,1.511,0.002
8.14,41.500,0.07843,1.514,0.002
8.21,41.600,0.07864,1.526,0.002
8.24,41.700,0.07884,1.532,0.002
8.29,41.800,0.07905,1.541,0.002
8.30,41.900,0.07926,1.544,0.002
8.35,42.000,0.07947,1.552,0.002
8.38,42.100,0.07968,1.558,0.002
8.41,42.200,0.07988,1.563,0.002
8.45,42.300,0.08009,1.572,0.002
8.49,42.400,0.08026,1.578,0.002
8.51,42.500,0.08047,1.583,0.002
8.55,42.600,0.08067,1.589,0.002
8.56,42.700,0.08084,1.592,0.002
8.60,42.800,0.08101,1.600,0.002
8.61,42.900,0.08117,1.601,0.002
8.65,43.000,0.08134,1.609,0.002
8.66,43.100,0.08146,1.611,0.002
8.71,43.200,0.08163,1.619,0.002
8.73,43.300,0.08180,1.623,0.002
8.74,43.400,0.08192,1.626,0.002
8.75,43.500,0.08209,1.627,0.002
8.78,43.600,0.08221,1.632,0.002
8.79,43.700,0.08234,1.634,0.002
8.82,43.800,0.08250,1.639,0.002
8.84,43.900,0.08263,1.644,0.002
8.85,44.000,0.08275,1.645,0.002
8.88,44.100,0.08292,1.650,0.002
8.90,44.200,0.08304,1.654,0.002
8.93,44.300,0.08317,1.660,0.002
8.95,44.400,0.08333,1.665,0.002
8.96,44.500,0.08346,1.665,0.002
9.00,44.600,0.08362,1.673,0.002
9.02,44.700,0.08375,1.677,0.002
9.03,44.800,0.08391,1.679,0.002
9.06,44.900,0.08404,1.685,0.002
9.11,45.000,0.08421,1.694,0.002
9.12,45.100,0.08433,1.696,0.002
9.15,45.200,0.08450,1.701,0.002
9.18,45.300,0.08466,1.707,0.002
9.22,45.400,0.08479,1.715,0.002
9.25,45.500,0.08495,1.721,0.002
9.27,45.600,0.08512,1.724,0.002
9.31,45.700,0.08524,1.730,0.002
9.33,45.800,0.08541,1.735,0.002
9.35,45.900,0.08558,1.739,0.002
9.37,46.000,0.08574,1.742,0.002
9.41,46.100,0.08591,1.750,0.002
9.43,46.200,0.08608,1.754,0.002
9.46,46.300,0.08624,1.760,0.002
9.50,46.400,0.08641,1.766,0.002
9.53,46.500,0.08657,1.771,0.002
9.57,46.600,0.08674,1.780,0.002
9.59,46.700,0.08695,1.784,0.002
9.63,46.800,0.08711,1.791,0.002
9.67,46.900,0.08732,1.799,0.002
9.70,47.000,0.08753,1.804,0.002
9.73,47.100,0.08774,1.810,0.002
9.78,47.200,0.08795,1.818,0.002
9.83,47.300,0.08819,1.828,0.002
9.85,47.400,0.08840,1.831,0.002
9.89,47.500,0.08861,1.838,0.002
9.92,47.600,0.08882,1.845,0.002
9.94,47.700,0.08903,1.849,0.002
9.97,47.800,0.08923,1.854,0.002
10.02,47.900,0.08944,1.864,0.002
10.03,48.000,0.08965,1.865,0.002
10.08,48.100,0.08982,1.874,0.002
10.09,48.200,0.08998,1.876,0.002
10.11,48.300,0.09019,1.880,0.002
10.14,48.400,0.09036,1.885,0.002
10.16,48.500,0.09052,1.889,0.002
10.19,48.600,0.09069,1.895,0.002
10.21,48.700,0.09081,1.899,0.002
10.23,48.800,0.09098,1.902,0.002
10.27,48.900,0.09115,1.909,0.002
10.27,49.000,0.09127,1.910,0.002
10.31,49.100,0.09139,1.918,0.002
10.33,49.200,0.09156,1.921,0.002
10.36,49.300,0.09169,1.927,0.002
10.36,49.400,0.09181,1.927,0.002
10.37,49.500,0.09198,1.929,0.002
10.39,49.600,0.09210,1.932,0.002
10.42,49.700,0.09223,1.937,0.002
10.41,49.800,0.09235,1.936,0.002
10.47,49.900,0.09252,1.948,0.002
10.47,50.000,0.09264,1.947,0.002
10.51,50.100,0.09277,1.954,0.002
10.52,50.200,0.09293,1.957,0.002
10.58,50.300,0.09306,1.967,0.002
10.56,50.400,0.09322,1.964,0.002
10.63,50.500,0.09335,1.977,0.002
10.62,50.600,0.09351,1.975,0.002
10.66,50.700,0.09364,1.982,0.002
10.67,50.800,0.09380,1.983,0.002
10.72,50.900,0.09397,1.994,0.002
10.73,51.000,0.09414,1.994,0.002
10.77,51.100,0.09426,2.003,0.002
10.78,51.200,0.09443,2.004,0.002
10.83,51.300,0.09455,2.014,0.002
10.83,51.400,0.09472,2.014,0.002
10.87,51.500,0.09489,2.022,0.002
10.86,51.600,0.09505,2.020,0.002
10.92,51.700,0.09522,2.031,0.002
10.94,51.800,0.09534,2.034,0.002
10.98,51.900,0.09551,2.041,0.002
10.99,52.000,0.09568,2.044,0.002
11.04,52.100,0.09584,2.053,0.002
11.06,52.200,0.09605,2.056,0.002
11.11,52.300,0.09622,2.066,0.002
11.14,52.400,0.09642,2.071,0.002
11.19,52.500,0.09659,2.081,0.002
11.22,52.600,0.09680,2.086,0.002
11.26,52.700,0.09700,2.094,0.002
11.29,52.800,0.09721,2.099,0.002
11.33,52.900,0.09742,2.107,0.002
11.36,53.000,0.09763,2.113,0.002
11.40,53.100,0.09784,2.119,0.002
11.42,53.200,0.09804,2.124,0.002
11.45,53.300,0.09825,2.130,0.002
11.48,53.400,0.09846,2.135,0.002
11.52,53.500,0.09863,2.143,0.002
11.53,53.600,0.09883,2.144,0.002
11.56,53.700,0.09904,2.150,0.002
11.60,53.800,0.09925,2.156,0.002
11.62,53.900,0.09942,2.161,0.002
11.63,54.000,0.09962,2.163,0.002
11.66,54.100,0.09979,2.169,0.002
11.68,54.200,0.09991,2.172,0.002
11.72,54.300,0.10008,2.179,0.002
11.75,54.400,0.10025,2.185,0.002
11.77,54.500,0.10041,2.188,0.002
11.79,54.600,0.10054,2.192,0.002
11.82,54.700,0.10070,2.197,0.002
11.84,54.800,0.10087,2.202,0.002
11.86,54.900,0.10099,2.205,0.002
11.88,55.000,0.10112,2.209,0.002
11.92,55.100,0.10124,2.216,0.002
11.94,55.200,0.10141,2.220,0.002
11.95,55.300,0.10153,2.222,0.002
11.98,55.400,0.10166,2.227,0.002
12.01,55.500,0.10178,2.234,0.002
12.04,55.600,0.10195,2.239,0.002
12.06,55.700,0.10207,2.242,0.002
12.08,55.800,0.10220,2.246,0.002
12.09,55.900,0.10232,2.248,0.002
12.12,56.000,0.10249,2.254,0.002
12.13,56.100,0.10261,2.255,0.002
12.15,56.200,0.10278,2.260,0.002
12.16,56.300,0.10295,2.261,0.002
12.19,56.400,0.10307,2.266,0.002
12.19,56.500,0.10324,2.267,0.002
12.22,56.600,0.10340,2.273,0.002
12.23,56.700,0.10353,2.274,0.002
12.27,56.800,0.10370,2.281,0.002
12.28,56.900,0.10386,2.284,0.002
12.34,57.000,0.10399,2.295,0.002
12.36,57.100,0.10415,2.297,0.002
12.41,57.200,0.10432,2.307,0.002
12.44,57.300,0.10448,2.314,0.002
12.50,57.400,0.10461,2.324,0.002
12.52,57.500,0.10478,2.328,0.002
12.56,57.600,0.10494,2.335,0.002
12.57,57.700,0.10511,2.337,0.002
12.59,57.800,0.10527,2.342,0.002
12.63,57.900,0.10544,2.348,0.002
12.65,58.000,0.10561,2.351,0.002
12.69,58.100,0.10581,2.360,0.002
12.73,58.200,0.10598,2.367,0.002
12.75,58.300,0.10619,2.370,0.002
12.78,58.400,0.10640,2.376,0.002
12.81,58.500,0.10656,2.383,0.002
12.85,58.600,0.10677,2.390,0.002
12.88,58.700,0.10698,2.395,0.002
12.91,58.800,0.10719,2.401,0.002
12.94,58.900,0.10739,2.407,0.002
12.98,59.000,0.10760,2.413,0.002
13.01,59.100,0.10781,2.419,0.002
13.06,59.200,0.10802,2.429,0.002
13.10,59.300,0.10818,2.435,0.002
13.13,59.400,0.10839,2.441,0.002
13.16,59.500,0.10860,2.446,0.002
13.20,59.600,0.10877,2.454,0.002
13.22,59.700,0.10893,2.458,0.002
13.23,59.800,0.10914,2.460,0.002
13.27,59.900,0.10931,2.468,0.002
13.29,60.000,0.10947,2.471,0.002
13.32,60.100,0.10964,2.477,0.002
13.33,60.200,0.10976,2.479,0.002
13.35,60.300,0.10993,2.483,0.002
13.36,60.400,0.11009,2.485,0.002
13.38,60.500,0.11022,2.489,0.002
13.40,60.600,0.11039,2.492,0.002
13.42,60.700,0.11051,2.496,0.002
13.44,60.800,0.11068,2.498,0.002
13.44,60.900,0.11080,2.500,0.002
13.45,61.000,0.11093,2.502,0.002
13.48,61.100,0.11105,2.506,0.002
13.51,61.200,0.11122,2.511,0.002
13.52,61.300,0.11134,2.514,0.002
13.54,61.400,0.11147,2.518,0.002
13.57,61.500,0.11159,2.523,0.002
13.60,61.600,0.11176,2.529,0.002
13.62,61.700,0.11188,2.532,0.002
13.63,61.800,0.11205,2.535,0.002
13.66,61.900,0.11217,2.540,0.002
13.68,62.000,0.11234,2.544,0.002
13.69,62.100,0.11246,2.546,0.002
13.74,62.200,0.11263,2.555,0.002
13.78,62.300,0.11275,2.562,0.002
13.79,62.400,0.11292,2.564,0.002
13.82,62.500,0.11309,2.570,0.002
13.86,62.600,0.11321,2.577,0.002
13.88,62.700,0.11338,2.581,0.002
13.91,62.800,0.11350,2.586,0.002
13.93,62.900,0.11367,2.590,0.002
13.95,63.000,0.11383,2.594,0.002
13.97,63.100,0.11396,2.597,0.002
13.97,63.200,0.11413,2.599,0.002
14.00,63.300,0.11429,2.602,0.002
14.02,63.400,0.11446,2.607,0.002
14.06,63.500,0.11462,2.614,0.002
14.10,63.600,0.11479,2.621,0.002
14.11,63.700,0.11496,2.624,0.002
14.13,63.800,0.11512,2.627,0.002
14.14,63.900,0.11533,2.629,0.002
14.19,64.000,0.11554,2.639,0.002
14.24,64.100,0.11575,2.648,0.002
14.27,64.200,0.11595,2.653,0.002
14.29,64.300,0.11616,2.657,0.002
14.33,64.400,0.11637,2.664,0.002
14.35,64.500,0.11658,2.669,0.002
14.41,64.600,0.11679,2.679,0.002
14.43,64.700,0.11703,2.684,0.002
14.49,64.800,0.11724,2.694,0.002
14.53,64.900,0.11745,2.702,0.002
14.54,65.000,0.11766,2.704,0.002
14.56,65.100,0.11787,2.707,0.002
14.59,65.200,0.11807,2.713,0.002
14.61,65.300,0.11824,2.717,0.002
14.65,65.400,0.11845,2.724,0.002
14.66,65.500,0.11861,2.726,0.002
14.68,65.600,0.11878,2.730,0.002
14.69,65.700,0.11895,2.731,0.002
14.71,65.800,0.11911,2.735,0.002
14.74,65.900,0.11924,2.741,0.002
14.76,66.000,0.11940,2.745,0.002
14.76,66.100,0.11953,2.744,0.002
14.79,66.200,0.11969,2.749,0.002
14.81,66.300,0.11982,2.755,0.002
14.82,66.400,0.11999,2.756,0.002
14.85,66.500,0.12011,2.762,0.002
14.85,66.600,0.12023,2.762,0.002
14.89,66.700,0.12040,2.769,0.002
14.90,66.800,0.12053,2.770,0.002
14.91,66.900,0.12065,2.772,0.002
14.95,67.000,0.12082,2.780,0.002
14.97,67.100,0.12094,2.784,0.002
14.98,67.200,0.12107,2.785,0.002
15.01,67.300,0.12123,2.791,0.002
15.04,67.400,0.12136,2.796,0.002
15.08,67.500,0.12152,2.804,0.002
15.08,67.600,0.12165,2.805,0.002
15.12,67.700,0.12181,2.811,0.002
15.13,67.800,0.12198,2.813,0.002
15.16,67.900,0.12210,2.819,0.002
15.17,68.000,0.12227,2.821,0.002
15.21,68.100,0.12244,2.828,0.002
15.21,68.200,0.12256,2.828,0.002
15.25,68.300,0.12273,2.835,0.002
15.26,68.400,0.12289,2.838,0.002
15.30,68.500,0.12306,2.844,0.002
15.31,68.600,0.12323,2.846,0.002
15.34,68.700,0.12335,2.853,0.002
15.34,68.800,0.12352,2.852,0.002
15.36,68.900,0.12368,2.857,0.002
15.40,69.000,0.12385,2.863,0.002
15.42,69.100,0.12402,2.868,0.002
15.43,69.200,0.12418,2.869,0.002
15.45,69.300,0.12435,2.873,0.002
15.48,69.400,0.12456,2.879,0.002
15.53,69.500,0.12472,2.887,0.002
15.56,69.600,0.12493,2.893,0.002
15.59,69.700,0.12514,2.899,0.002
15.64,69.800,0.12535,2.908,0.002
15.66,69.900,0.12555,2.912,0.002
15.70,70.000,0.12576,2.919,0.002
15.74,70.100,0.12601,2.927,0.002
15.77,70.200,0.12622,2.932,0.002
15.79,70.300,0.12643,2.936,0.002
15.83,70.400,0.12663,2.943,0.002
15.88,70.500,0.12684,2.952,0.002
15.91,70.600,0.12705,2.958,0.003
15.94,70.700,0.12726,2.964,0.003
15.96,70.800,0.12747,2.967,0.003
15.99,70.900,0.12767,2.973,0.003
16.01,71.000,0.12788,2.978,0.003
16.03,71.100,0.12805,2.981,0.003
16.06,71.200,0.12821,2.986,0.003
16.10,71.300,0.12838,2.993,0.003
16.11,71.400,0.12855,2.995,0.003
16.13,71.500,0.12871,3.000,0.003
16.14,71.600,0.12884,3.002,0.003
16.16,71.700,0.12900,3.005,0.003
16.17,71.800,0.12913,3.007,0.003
16.18,71.900,0.12929,3.009,0.003
16.20,72.000,0.12942,3.012,0.003
16.22,72.100,0.12958,3.015,0.003
16.23,72.200,0.12971,3.017,0.003
16.25,72.300,0.12983,3.022,0.003
16.27,72.400,0.13000,3.025,0.003
16.29,72.500,0.13012,3.030,0.003
16.29,72.600,0.13025,3.030,0.003
16.34,72.700,0.13042,3.039,0.003
16.35,72.800,0.13054,3.041,0.003
16.38,72.900,0.13071,3.045,0.003
16.39,73.000,0.13083,3.048,0.003
16.44,73.100,0.13100,3.057,0.003
16.45,73.200,0.13112,3.059,0.003
16.50,73.300,0.13129,3.067,0.003
16.51,73.400,0.13141,3.070,0.003
16.55,73.500,0.13158,3.077,0.003
16.58,73.600,0.13175,3.083,0.003
16.60,73.700,0.13191,3.087,0.003
16.64,73.800,0.13204,3.094,0.003
12.74,73.900,0.13220,2.369,0.003
13.03,74.000,0.13237,2.422,0.003
13.09,74.100,0.13249,2.433,0.003
13.14,74.200,0.13266,2.443,0.003
13.17,74.300,0.13283,2.448,0.003
13.19,74.400,0.13299,2.454,0.003
13.25,74.500,0.13316,2.463,0.003
13.28,74.600,0.13332,2.470,0.003
13.33,74.700,0.13349,2.478,0.003
13.34,74.800,0.13366,2.481,0.003
13.38,74.900,0.13382,2.488,0.003
13.41,75.000,0.13399,2.494,0.003
13.47,75.100,0.13420,2.504,0.003
13.50,75.200,0.13441,2.510,0.003
13.55,75.300,0.13457,2.519,0.003
13.61,75.400,0.13478,2.531,0.003
13.62,75.500,0.13499,2.533,0.003
13.68,75.600,0.13519,2.544,0.003
13.71,75.700,0.13540,2.549,0.003
13.76,75.800,0.13561,2.558,0.003
13.79,75.900,0.13582,2.564,0.003
13.84,76.000,0.13603,2.573,0.003
13.88,76.100,0.13623,2.580,0.003
13.91,76.200,0.13644,2.587,0.003
13.94,76.300,0.13665,2.593,0.003
13.98,76.400,0.13686,2.600,0.003
14.00,76.500,0.13702,2.603,0.003
14.04,76.600,0.13723,2.611,0.003
14.06,76.700,0.13740,2.614,0.003
14.08,76.800,0.13756,2.618,0.003
14.11,76.900,0.13773,2.624,0.003
14.13,77.000,0.13790,2.628,0.003
14.17,77.100,0.13806,2.634,0.003
14.19,77.200,0.13823,2.639,0.003
14.22,77.300,0.13835,2.644,0.003
14.23,77.400,0.13852,2.646,0.003
14.27,77.500,0.13869,2.653,0.003
14.26,77.600,0.13881,2.652,0.003
14.28,77.700,0.13893,2.656,0.003
14.31,77.800,0.13910,2.661,0.003
14.34,77.900,0.13923,2.666,0.003
14.34,78.000,0.13935,2.666,0.003
14.35,78.100,0.13952,2.668,0.003
14.38,78.200,0.13964,2.674,0.003
12.87,78.300,0.13977,2.394,0.003
7.51,78.400,0.13989,1.396,0.003
7.42,78.500,0.14006,1.380,0.003
7.50,78.600,0.14018,1.395,0.003
7.54,78.700,0.14035,1.402,0.003
7.58,78.800,0.14047,1.409,0.003
7.62,78.900,0.14064,1.418,0.003
7.66,79.000,0.14076,1.425,0.003
7.70,79.100,0.14093,1.433,0.003
7.75,79.200,0.14105,1.440,0.003
7.80,79.300,0.14122,1.450,0.003
7.83,79.400,0.14134,1.457,0.003
7.87,79.500,0.14151,1.463,0.003
7.91,79.600,0.14164,1.471,0.003
7.94,79.700,0.14180,1.476,0.003
7.98,79.800,0.14197,1.484,0.003
8.02,79.900,0.14213,1.492,0.003
8.06,80.000,0.14230,1.498,0.003
8.10,80.100,0.14243,1.507,0.003
8.11,80.200,0.14259,1.509,0.003
8.15,80.300,0.14276,1.515,0.003
8.19,80.400,0.14292,1.523,0.003
8.23,80.500,0.14309,1.529,0.003
8.28,80.600,0.14326,1.540,0.003
8.30,80.700,0.14342,1.543,0.003
8.35,80.800,0.14363,1.552,0.003
8.39,80.900,0.14380,1.560,0.003
8.45,81.000,0.14400,1.570,0.003
8.48,81.100,0.14421,1.576,0.003
8.53,81.200,0.14442,1.585,0.003
8.58,81.300,0.14463,1.595,0.003
8.60,81.400,0.14484,1.599,0.003
8.65,81.500,0.14504,1.608,0.003
8.70,81.600,0.14525,1.617,0.003
8.73,81.700,0.14546,1.623,0.003
8.78,81.800,0.14567,1.632,0.003
8.79,81.900,0.14587,1.635,0.003
8.84,82.000,0.14608,1.644,0.003
8.86,82.100,0.14629,1.648,0.003
8.89,82.160,0.14637,1.654,0.003