File: data-files/CWRU/0900-05-00A.txt
""
"Test Method","Will_Huddleston_Disks.msm"
"Sample I. D.","900-5-0A.mss"
"Specimen Number","1"

"Load (N)","Time (s)","Extension (mm)","Stress (MPa)","Strain (mm/mm)"

1.44,0.200,-0.06649,0.194,-0.001
1.44,0.300,-0.06649,0.195,-0.001
1.44,0.400,-0.06649,0.195,-0.001
1.44,0.500,-0.06649,0.194,-0.001
1.43,0.600,-0.06645,0.193,-0.001
1.43,0.700,-0.06645,0.194,-0.001
1.43,0.800,-0.06645,0.193,-0.001
1.44,0.900,-0.06641,0.195,-0.001
1.44,1.000,-0.06641,0.195,-0.001
1.44,1.100,-0.06641,0.194,-0.001
1.43,1.200,-0.06637,0.194,-0.001
1.44,1.300,-0.06637,0.194,-0.001
1.43,1.400,-0.06637,0.193,-0.001
1.44,1.500,-0.06633,0.195,-0.001
1.44,1.600,-0.06633,0.194,-0.001
1.44,1.700,-0.06628,0.195,-0.001
1.44,1.800,-0.06628,0.195,-0.001
1.42,1.900,-0.06624,0.192,-0.001
1.43,2.000,-0.06624,0.193,-0.001
1.45,2.100,-0.06620,0.196,-0.001
1.49,2.200,-0.06616,0.201,-0.001
1.49,2.300,-0.06612,0.202,-0.001
1.55,2.400,-0.06599,0.209,-0.001
1.62,2.500,-0.06583,0.219,-0.001
1.73,2.600,-0.06562,0.234,-0.001
1.80,2.700,-0.06541,0.243,-0.001
1.87,2.800,-0.06525,0.252,-0.001
1.91,2.900,-0.06504,0.258,-0.001
1.92,3.000,-0.06483,0.260,-0.001
1.94,3.100,-0.06462,0.262,-0.001
1.97,3.200,-0.06446,0.266,-0.001
2.00,3.300,-0.06425,0.271,-0.001
2.04,3.400,-0.06404,0.275,-0.001
2.03,3.500,-0.06387,0.274,-0.001
2.07,3.600,-0.06367,0.279,-0.001
2.08,3.700,-0.06350,0.281,-0.001
2.13,3.800,-0.06329,0.287,-0.001
2.14,3.900,-0.06317,0.289,-0.001
2.15,4.000,-0.06300,0.291,-0.001
2.18,4.100,-0.06284,0.295,-0.001
2.21,4.200,-0.06267,0.299,-0.001
2.22,4.300,-0.06250,0.300,-0.001
2.25,4.400,-0.06238,0.303,-0.001
2.25,4.500,-0.06225,0.304,-0.001
2.28,4.600,-0.06209,0.308,-0.001
2.29,4.700,-0.06196,0.310,-0.001
2.32,4.800,-0.06184,0.313,-0.001
2.33,4.900,-0.06167,0.315,-0.001
2.33,5.000,-0.06155,0.315,-0.001
2.37,5.100,-0.06142,0.320,-0.001
2.39,5.200,-0.06130,0.323,-0.001
2.40,5.300,-0.06117,0.325,-0.001
2.44,5.400,-0.06105,0.329,-0.001
2.46,5.500,-0.06088,0.332,-0.001
2.48,5.600,-0.06076,0.335,-0.001
2.50,5.700,-0.06063,0.338,-0.001
2.52,5.800,-0.06051,0.341,-0.001
2.56,5.900,-0.06034,0.346,-0.001
2.58,6.000,-0.06022,0.348,-0.001
2.59,6.100,-0.06009,0.350,-0.001
2.63,6.200,-0.05993,0.355,-0.001
2.64,6.300,-0.05980,0.356,-0.001
2.66,6.400,-0.05964,0.360,-0.001
2.69,6.500,-0.05947,0.363,-0.001
2.71,6.600,-0.05934,0.367,-0.001
2.75,6.700,-0.05918,0.371,-0.001
2.75,6.800,-0.05905,0.372,-0.001
2.77,6.900,-0.05889,0.375,-0.001
2.80,7.000,-0.05872,0.379,-0.001
2.85,7.100,-0.05855,0.385,-0.001
2.86,7.200,-0.05839,0.386,-0.001
2.87,7.300,-0.05826,0.388,-0.001
2.90,7.400,-0.05810,0.392,-0.001
2.93,7.500,-0.05793,0.395,-0.001
2.95,7.600,-0.05777,0.398,-0.001
2.97,7.700,-0.05760,0.402,-0.001
3.00,7.800,-0.05743,0.405,-0.001
3.03,7.900,-0.05727,0.409,-0.001
3.03,8.000,-0.05706,0.410,-0.001
3.07,8.100,-0.05689,0.415,-0.001
3.12,8.200,-0.05668,0.421,-0.001
3.14,8.300,-0.05648,0.424,-0.001
3.18,8.400,-0.05631,0.430,-0.001
3.21,8.500,-0.05606,0.433,-0.001
3.23,8.600,-0.05585,0.437,-0.001
3.27,8.700,-0.05565,0.442,-0.001
3.32,8.800,-0.05540,0.448,-0.001
3.34,8.900,-0.05519,0.451,-0.001
3.36,9.000,-0.05498,0.455,-0.001
3.40,9.100,-0.05477,0.459,-0.001
3.42,9.200,-0.05457,0.462,-0.001
3.45,9.300,-0.05436,0.466,-0.001
3.48,9.400,-0.05415,0.470,-0.001
3.51,9.500,-0.05394,0.474,-0.001
3.52,9.600,-0.05378,0.476,-0.001
3.55,9.700,-0.05361,0.479,-0.001
3.57,9.800,-0.05344,0.483,-0.001
3.58,9.900,-0.05328,0.484,-0.001
3.62,10.000,-0.05311,0.490,-0.001
3.64,10.100,-0.05294,0.492,-0.001
3.67,10.200,-0.05278,0.496,-0.001
3.69,10.300,-0.05265,0.499,-0.001
3.71,10.400,-0.05249,0.501,-0.001
3.73,10.500,-0.05232,0.505,-0.001
3.75,10.600,-0.05220,0.507,-0.001
3.77,10.700,-0.05203,0.510,-0.001
3.77,10.800,-0.05191,0.510,-0.001
3.80,10.900,-0.05178,0.513,-0.001
3.82,11.000,-0.05166,0.516,-0.001
3.83,11.100,-0.05149,0.518,-0.001
3.84,11.200,-0.05137,0.519,-0.001
3.87,11.300,-0.05124,0.523,-0.001
3.87,11.400,-0.05107,0.523,-0.001
3.90,11.500,-0.05095,0.526,-0.001
3.92,11.600,-0.05078,0.530,-0.001
3.94,11.700,-0.05066,0.532,-0.001
3.95,11.800,-0.05049,0.534,-0.001
3.98,11.900,-0.05033,0.538,-0.001
4.00,12.000,-0.05020,0.541,-0.001
4.01,12.100,-0.05004,0.542,-0.001
4.05,12.200,-0.04987,0.547,-0.001
4.07,12.300,-0.04970,0.549,-0.001
4.10,12.400,-0.04958,0.554,-0.001
4.13,12.500,-0.04941,0.558,-0.001
4.16,12.600,-0.04925,0.563,-0.001
4.21,12.700,-0.04908,0.569,-0.001
4.23,12.800,-0.04891,0.572,-0.001
4.27,12.900,-0.04875,0.576,-0.001
4.30,13.000,-0.04862,0.582,-0.001
4.35,13.100,-0.04846,0.588,-0.001
4.37,13.200,-0.04829,0.591,-0.001
4.42,13.300,-0.04812,0.597,-0.001
4.43,13.400,-0.04796,0.599,-0.001
4.47,13.500,-0.04775,0.605,-0.001
4.52,13.600,-0.04758,0.611,-0.001
4.55,13.700,-0.04742,0.615,-0.001
4.60,13.800,-0.04721,0.622,-0.001
4.63,13.900,-0.04700,0.626,-0.001
4.68,14.000,-0.04679,0.633,-0.001
4.71,14.100,-0.04659,0.636,-0.001
4.74,14.200,-0.04638,0.641,-0.001
4.77,14.300,-0.04617,0.645,-0.001
4.80,14.400,-0.04596,0.649,-0.001
4.84,14.500,-0.04571,0.654,-0.001
4.86,14.600,-0.04555,0.657,-0.001
4.90,14.700,-0.04534,0.662,-0.001
4.92,14.800,-0.04513,0.664,-0.001
4.95,14.900,-0.04492,0.669,-0.001
4.98,15.000,-0.04472,0.673,-0.001
5.00,15.100,-0.04451,0.675,-0.001
5.03,15.200,-0.04434,0.680,-0.001
5.04,15.300,-0.04414,0.682,-0.001
5.06,15.400,-0.04397,0.684,-0.001
5.08,15.500,-0.04380,0.686,-0.001
5.10,15.600,-0.04364,0.689,-0.001
5.12,15.700,-0.04351,0.691,-0.001
5.14,15.800,-0.04335,0.694,-0.001
5.15,15.900,-0.04318,0.696,-0.001
5.17,16.000,-0.04305,0.699,-0.001
5.18,16.100,-0.04289,0.700,-0.001
5.19,16.200,-0.04276,0.702,-0.001
5.20,16.300,-0.04260,0.703,-0.001
5.23,16.400,-0.04247,0.707,-0.001
5.24,16.500,-0.04235,0.708,-0.001
5.24,16.600,-0.04218,0.709,-0.001
5.27,16.700,-0.04206,0.712,-0.001
5.29,16.800,-0.04193,0.715,-0.001
5.29,16.900,-0.04181,0.715,-0.001
5.31,17.000,-0.04164,0.717,-0.001
5.32,17.100,-0.04152,0.718,-0.001
5.34,17.200,-0.04139,0.722,-0.001
5.35,17.300,-0.04123,0.723,-0.001
5.37,17.400,-0.04110,0.725,-0.001
5.41,17.500,-0.04094,0.732,-0.001
5.43,17.600,-0.04081,0.733,-0.001
5.45,17.700,-0.04064,0.736,-0.001
5.49,17.800,-0.04052,0.742,-0.001
5.51,17.900,-0.04035,0.744,-0.001
5.53,18.000,-0.04019,0.747,-0.001
5.57,18.100,-0.04006,0.752,-0.001
5.59,18.200,-0.03990,0.756,-0.001
5.62,18.300,-0.03973,0.759,-0.001
5.64,18.400,-0.03956,0.763,-0.001
5.68,18.500,-0.03944,0.767,-0.001
5.70,18.600,-0.03927,0.770,-0.001
5.73,18.700,-0.03911,0.774,-0.001
5.76,18.800,-0.03894,0.779,-0.001
5.78,18.900,-0.03877,0.782,-0.001
5.82,19.000,-0.03861,0.787,-0.001
5.85,19.100,-0.03844,0.790,-0.001
5.88,19.200,-0.03828,0.794,-0.001
5.89,19.300,-0.03811,0.796,-0.001
5.95,19.400,-0.03794,0.804,-0.001
5.97,19.500,-0.03774,0.807,-0.001
6.00,19.600,-0.03753,0.811,-0.001
6.03,19.700,-0.03732,0.815,-0.001
6.05,19.800,-0.03711,0.818,-0.001
6.10,19.900,-0.03686,0.824,-0.001
6.12,20.000,-0.03665,0.828,-0.001
6.15,20.100,-0.03645,0.831,-0.001
6.18,20.200,-0.03624,0.836,-0.001
6.20,20.300,-0.03603,0.838,-0.001
6.22,20.400,-0.03582,0.840,-0.001
6.26,20.500,-0.03562,0.846,-0.001
6.27,20.600,-0.03541,0.848,-0.001
6.29,20.700,-0.03520,0.850,-0.001
6.32,20.800,-0.03503,0.855,-0.001
6.36,20.900,-0.03483,0.860,-0.001
6.37,21.000,-0.03466,0.861,-0.001
6.39,21.100,-0.03449,0.864,-0.001
6.37,21.200,-0.03433,0.861,-0.001
6.43,21.300,-0.03416,0.869,-0.001
6.44,21.400,-0.03400,0.870,-0.001
6.46,21.500,-0.03387,0.873,-0.001
6.48,21.600,-0.03370,0.876,-0.001
6.50,21.700,-0.03358,0.879,-0.001
6.55,21.800,-0.03341,0.885,-0.001
6.55,21.900,-0.03329,0.885,-0.001
6.57,22.000,-0.03316,0.887,-0.001
6.59,22.100,-0.03304,0.891,-0.001
6.62,22.200,-0.03287,0.894,-0.001
6.62,22.300,-0.03275,0.895,-0.001
6.63,22.400,-0.03262,0.896,-0.001
6.67,22.500,-0.03250,0.901,-0.001
6.69,22.600,-0.03233,0.905,-0.001
6.72,22.700,-0.03221,0.908,-0.001
6.73,22.800,-0.03208,0.909,-0.001
6.77,22.900,-0.03196,0.915,-0.001
6.79,23.000,-0.03179,0.918,-0.001
6.81,23.100,-0.03167,0.920,-0.001
6.83,23.200,-0.03150,0.923,-0.001
6.87,23.300,-0.03138,0.928,-0.001
6.88,23.400,-0.03121,0.930,-0.001
6.90,23.500,-0.03104,0.933,-0.001
6.94,23.600,-0.03092,0.937,-0.001
6.96,23.700,-0.03075,0.940,-0.001
6.97,23.800,-0.03059,0.942,-0.001
7.01,23.900,-0.03046,0.948,-0.001
7.02,24.000,-0.03030,0.949,-0.001
7.06,24.100,-0.03013,0.954,-0.001
7.08,24.200,-0.03001,0.956,-0.001
7.11,24.300,-0.02984,0.961,-0.001
7.13,24.400,-0.02967,0.963,-0.001
7.17,24.500,-0.02951,0.969,-0.001
7.18,24.600,-0.02934,0.971,-0.001
7.21,24.700,-0.02917,0.974,-0.001
7.24,24.800,-0.02901,0.978,-0.001
7.28,24.900,-0.02884,0.984,-0.001
7.29,25.000,-0.02863,0.986,-0.001
7.33,25.100,-0.02847,0.990,-0.001
7.37,25.200,-0.02826,0.995,-0.001
7.40,25.300,-0.02805,1.000,-0.001
7.44,25.400,-0.02789,1.006,-0.001
7.48,25.500,-0.02768,1.010,-0.001
7.51,25.600,-0.02743,1.014,-0.001
7.55,25.700,-0.02722,1.020,-0.001
7.57,25.800,-0.02701,1.023,-0.001
7.60,25.900,-0.02681,1.027,-0.001
7.64,26.000,-0.02656,1.032,-0.001
7.67,26.100,-0.02635,1.036,-0.001
7.71,26.200,-0.02618,1.042,-0.001
7.72,26.300,-0.02598,1.043,-0.001
7.78,26.400,-0.02577,1.052,-0.001
7.80,26.500,-0.02556,1.054,-0.001
7.81,26.600,-0.02539,1.056,0.000
7.84,26.700,-0.02523,1.059,0.000
7.87,26.800,-0.02506,1.063,0.000
7.89,26.900,-0.02489,1.066,0.000
7.91,27.000,-0.02473,1.068,0.000
7.92,27.100,-0.02456,1.070,0.000
7.96,27.200,-0.02444,1.075,0.000
7.96,27.300,-0.02427,1.076,0.000
8.01,27.400,-0.02415,1.083,0.000
7.99,27.500,-0.02398,1.080,0.000
8.04,27.600,-0.02386,1.087,0.000
8.08,27.700,-0.02369,1.091,0.000
8.09,27.800,-0.02356,1.093,0.000
8.11,27.900,-0.02344,1.096,0.000
8.13,28.000,-0.02332,1.098,0.000
8.13,28.100,-0.02315,1.099,0.000
8.18,28.200,-0.02302,1.106,0.000
8.19,28.300,-0.02290,1.106,0.000
8.23,28.400,-0.02273,1.112,0.000
8.25,28.500,-0.02261,1.115,0.000
8.27,28.600,-0.02248,1.118,0.000
8.30,28.700,-0.02232,1.121,0.000
8.33,28.800,-0.02219,1.125,0.000
8.35,28.900,-0.02203,1.128,0.000
8.40,29.000,-0.02190,1.135,0.000
8.40,29.100,-0.02174,1.136,0.000
8.44,29.200,-0.02161,1.140,0.000
8.46,29.300,-0.02145,1.143,0.000
8.49,29.400,-0.02128,1.147,0.000
8.51,29.500,-0.02115,1.151,0.000
8.55,29.600,-0.02099,1.155,0.000
8.56,29.700,-0.02082,1.157,0.000
8.61,29.800,-0.02066,1.163,0.000
8.62,29.900,-0.02053,1.164,0.000
8.67,30.000,-0.02037,1.172,0.000
8.70,30.100,-0.02020,1.176,0.000
8.74,30.200,-0.02003,1.181,0.000
8.75,30.300,-0.01987,1.183,0.000
8.79,30.400,-0.01970,1.188,0.000
8.82,30.500,-0.01953,1.192,0.000
8.86,30.600,-0.01937,1.197,0.000
8.89,30.700,-0.01920,1.202,0.000
8.93,30.800,-0.01899,1.206,0.000
8.96,30.900,-0.01883,1.211,0.000
9.02,31.000,-0.01862,1.219,0.000
9.06,31.100,-0.01841,1.225,0.000
9.11,31.200,-0.01820,1.231,0.000
9.14,31.300,-0.01800,1.235,0.000
9.19,31.400,-0.01779,1.243,0.000
9.24,31.500,-0.01758,1.249,0.000
9.29,31.600,-0.01737,1.256,0.000
9.34,31.700,-0.01712,1.262,0.000
9.37,31.800,-0.01696,1.266,0.000
9.41,31.900,-0.01671,1.272,0.000
9.45,32.000,-0.01654,1.277,0.000
9.50,32.100,-0.01633,1.284,0.000
9.53,32.200,-0.01617,1.288,0.000
9.57,32.300,-0.01596,1.294,0.000
9.59,32.400,-0.01579,1.296,0.000
9.63,32.500,-0.01563,1.301,0.000
9.65,32.600,-0.01546,1.304,0.000
9.68,32.700,-0.01530,1.309,0.000
9.71,32.800,-0.01513,1.312,0.000
9.74,32.900,-0.01500,1.316,0.000
9.77,33.000,-0.01484,1.320,0.000
9.79,33.100,-0.01471,1.323,0.000
9.83,33.200,-0.01455,1.329,0.000
9.85,33.300,-0.01442,1.331,0.000
9.88,33.400,-0.01430,1.335,0.000
9.91,33.500,-0.01413,1.340,0.000
9.94,33.600,-0.01401,1.344,0.000
9.96,33.700,-0.01388,1.346,0.000
9.99,33.800,-0.01376,1.350,0.000
10.02,33.900,-0.01363,1.355,0.000
10.04,34.000,-0.01347,1.357,0.000
10.08,34.100,-0.01334,1.362,0.000
10.10,34.200,-0.01322,1.365,0.000
10.14,34.300,-0.01305,1.371,0.000
10.16,34.400,-0.01293,1.374,0.000
10.21,34.500,-0.01280,1.380,0.000
10.25,34.600,-0.01264,1.385,0.000
10.30,34.700,-0.01251,1.392,0.000
10.32,34.800,-0.01234,1.395,0.000
10.36,34.900,-0.01222,1.399,0.000
10.41,35.000,-0.01205,1.406,0.000
10.44,35.100,-0.01193,1.410,0.000
10.48,35.200,-0.01176,1.416,0.000
10.52,35.300,-0.01160,1.422,0.000
10.55,35.400,-0.01143,1.426,0.000
10.59,35.500,-0.01131,1.431,0.000
10.64,35.600,-0.01114,1.438,0.000
10.67,35.700,-0.01097,1.442,0.000
10.70,35.800,-0.01081,1.446,0.000
10.75,35.900,-0.01068,1.453,0.000
10.78,36.000,-0.01052,1.456,0.000
10.86,36.100,-0.01035,1.467,0.000
10.88,36.200,-0.01014,1.470,0.000
10.95,36.300,-0.00998,1.479,0.000
10.97,36.400,-0.00981,1.483,0.000
11.04,36.500,-0.00960,1.492,0.000
11.08,36.600,-0.00944,1.497,0.000
11.15,36.700,-0.00923,1.507,0.000
11.20,36.800,-0.00902,1.513,0.000
11.27,36.900,-0.00881,1.523,0.000
11.33,37.000,-0.00856,1.530,0.000
11.40,37.100,-0.00836,1.540,0.000
11.45,37.200,-0.00815,1.547,0.000
11.49,37.300,-0.00794,1.553,0.000
11.55,37.400,-0.00769,1.561,0.000
11.60,37.500,-0.00748,1.567,0.000
11.64,37.600,-0.00727,1.573,0.000
11.72,37.700,-0.00707,1.584,0.000
11.78,37.800,-0.00686,1.592,0.000
11.83,37.900,-0.00669,1.599,0.000
11.87,38.000,-0.00649,1.604,0.000
11.91,38.100,-0.00632,1.610,0.000
11.95,38.200,-0.00611,1.614,0.000
11.98,38.300,-0.00599,1.618,0.000
12.00,38.400,-0.00582,1.621,0.000
12.06,38.500,-0.00565,1.630,0.000
12.10,38.600,-0.00549,1.635,0.000
12.13,38.700,-0.00536,1.639,0.000
12.14,38.800,-0.00520,1.640,0.000
12.20,38.900,-0.00507,1.649,0.000
12.25,39.000,-0.00491,1.656,0.000
12.29,39.100,-0.00478,1.661,0.000
12.31,39.200,-0.00466,1.663,0.000
12.34,39.300,-0.00449,1.668,0.000
12.38,39.400,-0.00437,1.673,0.000
12.41,39.500,-0.00424,1.677,0.000
12.42,39.600,-0.00408,1.679,0.000
12.48,39.700,-0.00395,1.686,0.000
12.54,39.800,-0.00383,1.694,0.000
12.56,39.900,-0.00370,1.698,0.000
12.60,40.000,-0.00353,1.703,0.000
12.64,40.100,-0.00341,1.708,0.000
12.69,40.200,-0.00324,1.715,0.000
12.73,40.300,-0.00312,1.720,0.000
12.77,40.400,-0.00295,1.726,0.000
12.82,40.500,-0.00279,1.733,0.000
12.87,40.600,-0.00266,1.739,0.000
12.89,40.700,-0.00250,1.742,0.000
12.95,40.800,-0.00233,1.750,0.000
13.00,40.900,-0.00221,1.757,0.000
13.07,41.000,-0.00204,1.766,0.000
13.08,41.100,-0.00187,1.767,0.000
13.15,41.200,-0.00171,1.777,0.000
13.19,41.300,-0.00154,1.783,0.000
13.23,41.400,-0.00142,1.788,0.000
13.29,41.500,-0.00125,1.796,0.000
13.33,41.600,-0.00108,1.801,0.000
13.39,41.700,-0.00092,1.809,0.000
13.43,41.800,-0.00075,1.815,0.000
13.49,41.900,-0.00058,1.823,0.000
13.55,42.000,-0.00038,1.831,0.000
13.60,42.100,-0.00021,1.838,0.000
13.66,42.200,0.00000,1.846,0.000
13.71,42.300,0.00016,1.853,0.000
13.77,42.400,0.00037,1.860,0.000
13.84,42.500,0.00058,1.870,0.000
13.90,42.600,0.00079,1.879,0.000
13.97,42.700,0.00099,1.888,0.000
14.06,42.800,0.00124,1.900,0.000
14.13,42.900,0.00145,1.909,0.000
14.18,43.000,0.00166,1.917,0.000
14.23,43.100,0.00187,1.924,0.000
14.32,43.200,0.00212,1.935,0.000
14.37,43.300,0.00232,1.942,0.000
14.44,43.400,0.00253,1.951,0.000
14.49,43.500,0.00274,1.958,0.000
14.54,43.600,0.00291,1.966,0.000
14.58,43.700,0.00311,1.970,0.000
14.64,43.800,0.00328,1.978,0.000
14.69,43.900,0.00345,1.985,0.000
14.75,44.000,0.00361,1.993,0.000
14.79,44.100,0.00378,1.998,0.000
14.85,44.200,0.00395,2.006,0.000
14.87,44.300,0.00411,2.009,0.000
14.92,44.400,0.00424,2.017,0.000
14.97,44.500,0.00440,2.023,0.000
15.02,44.600,0.00453,2.030,0.000
15.06,44.700,0.00469,2.035,0.000
15.10,44.800,0.00482,2.041,0.000
15.15,44.900,0.00494,2.048,0.000
15.20,45.000,0.00507,2.054,0.000
15.23,45.100,0.00523,2.058,0.000
15.27,45.200,0.00536,2.064,0.000
15.32,45.300,0.00548,2.070,0.000
15.36,45.400,0.00565,2.076,0.000
15.43,45.500,0.00577,2.085,0.000
15.48,45.600,0.00594,2.092,0.000
15.53,45.700,0.00606,2.098,0.000
15.58,45.800,0.00623,2.106,0.000
15.63,45.900,0.00636,2.113,0.000
15.67,46.000,0.00652,2.118,0.000
15.75,46.100,0.00669,2.128,0.000
15.79,46.200,0.00685,2.133,0.000
15.85,46.300,0.00698,2.142,0.000
15.88,46.400,0.00714,2.146,0.000
15.93,46.500,0.00731,2.152,0.000
16.00,46.600,0.00744,2.162,0.000
16.04,46.700,0.00760,2.167,0.000
16.11,46.800,0.00777,2.176,0.000
16.14,46.900,0.00793,2.182,0.000
16.22,47.000,0.00810,2.191,0.000
16.26,47.100,0.00823,2.197,0.000
16.31,47.200,0.00839,2.205,0.000
16.37,47.300,0.00856,2.212,0.000
16.45,47.400,0.00872,2.223,0.000
16.48,47.500,0.00893,2.228,0.000
16.56,47.600,0.00910,2.238,0.000
16.61,47.700,0.00926,2.245,0.000
16.70,47.800,0.00947,2.257,0.000
16.76,47.900,0.00968,2.265,0.000
16.82,48.000,0.00985,2.273,0.000
16.91,48.100,0.01005,2.285,0.000
16.99,48.200,0.01030,2.296,0.000
17.05,48.300,0.01051,2.304,0.000
17.13,48.400,0.01072,2.315,0.000
17.22,48.500,0.01093,2.327,0.000
17.31,48.600,0.01113,2.339,0.000
17.37,48.700,0.01138,2.348,0.000
17.46,48.800,0.01159,2.359,0.000
17.52,48.900,0.01176,2.368,0.000
17.60,49.000,0.01197,2.379,0.000
17.66,49.100,0.01217,2.386,0.000
17.72,49.200,0.01238,2.395,0.000
17.78,49.300,0.01255,2.403,0.000
17.84,49.400,0.01271,2.411,0.000
17.90,49.500,0.01288,2.418,0.000
17.95,49.600,0.01305,2.425,0.000
18.00,49.700,0.01321,2.432,0.000
18.05,49.800,0.01338,2.439,0.000
18.10,49.900,0.01350,2.446,0.000
18.15,50.000,0.01367,2.453,0.000
18.20,50.100,0.01384,2.459,0.000
18.25,50.200,0.01396,2.466,0.000
18.30,50.300,0.01408,2.473,0.000
18.35,50.400,0.01425,2.480,0.000
18.39,50.500,0.01438,2.486,0.000
18.44,50.600,0.01450,2.492,0.000
18.47,50.700,0.01467,2.496,0.000
18.55,50.800,0.01479,2.507,0.000
18.59,50.900,0.01492,2.512,0.000
18.64,51.000,0.01508,2.519,0.000
18.68,51.100,0.01521,2.525,0.000
18.75,51.200,0.01533,2.534,0.000
18.81,51.300,0.01550,2.542,0.000
18.85,51.400,0.01562,2.547,0.000
18.92,51.500,0.01579,2.557,0.000
18.97,51.600,0.01591,2.563,0.000
19.04,51.700,0.01608,2.573,0.000
19.08,51.800,0.01625,2.579,0.000
19.15,51.900,0.01637,2.588,0.000
19.21,52.000,0.01654,2.596,0.000
19.28,52.100,0.01670,2.606,0.000
19.33,52.200,0.01687,2.612,0.000
19.38,52.300,0.01699,2.619,0.000
19.44,52.400,0.01716,2.627,0.000
19.51,52.500,0.01733,2.637,0.000
19.57,52.600,0.01749,2.644,0.000
19.63,52.700,0.01762,2.653,0.000
19.70,52.800,0.01778,2.662,0.000
19.74,52.900,0.01795,2.667,0.000
19.80,53.000,0.01812,2.676,0.000
19.87,53.100,0.01828,2.685,0.000
19.95,53.200,0.01845,2.696,0.000
20.01,53.300,0.01861,2.704,0.000
20.09,53.400,0.01882,2.715,0.000
20.20,53.500,0.01899,2.729,0.000
20.28,53.600,0.01920,2.741,0.000
20.36,53.700,0.01940,2.751,0.000
20.45,53.800,0.01961,2.764,0.000
20.54,53.900,0.01982,2.775,0.000
20.63,54.000,0.02003,2.788,0.000
20.72,54.100,0.02028,2.800,0.000
20.82,54.200,0.02048,2.813,0.000
20.91,54.300,0.02069,2.826,0.000
20.99,54.400,0.02090,2.837,0.000
21.09,54.500,0.02111,2.850,0.000
21.16,54.600,0.02132,2.859,0.000
21.23,54.700,0.02152,2.868,0.000
21.30,54.800,0.02169,2.878,0.000
21.38,54.900,0.02190,2.889,0.000
21.44,55.000,0.02206,2.897,0.000
21.51,55.100,0.02223,2.907,0.000
21.56,55.200,0.02240,2.913,0.000
21.64,55.300,0.02256,2.924,0.000
21.67,55.400,0.02273,2.928,0.000
21.74,55.500,0.02285,2.937,0.000
21.81,55.600,0.02302,2.948,0.000
21.88,55.700,0.02314,2.956,0.000
21.91,55.800,0.02331,2.961,0.000
21.97,55.900,0.02343,2.969,0.000
22.02,56.000,0.02356,2.976,0.000
22.07,56.100,0.02368,2.983,0.000
22.12,56.200,0.02381,2.990,0.000
22.17,56.300,0.02398,2.996,0.000
22.26,56.400,0.02410,3.008,0.000
22.28,56.500,0.02422,3.011,0.000
22.33,56.600,0.02439,3.017,0.000
22.39,56.700,0.02452,3.025,0.000
22.46,56.800,0.02464,3.035,0.000
22.52,56.900,0.02481,3.044,0.000
22.59,57.000,0.02493,3.052,0.000
22.64,57.100,0.02506,3.060,0.000
22.70,57.200,0.02522,3.068,0.000
22.78,57.300,0.02539,3.078,0.000
22.85,57.400,0.02551,3.087,0.001
22.91,57.500,0.02568,3.096,0.001
22.98,57.600,0.02580,3.106,0.001
23.04,57.700,0.02597,3.113,0.001
23.12,57.800,0.02609,3.124,0.001
23.19,57.900,0.02626,3.134,0.001
23.25,58.000,0.02643,3.142,0.001
23.33,58.100,0.02659,3.152,0.001
23.38,58.200,0.02672,3.160,0.001
23.46,58.300,0.02688,3.170,0.001
23.54,58.400,0.02705,3.181,0.001
23.61,58.500,0.02722,3.190,0.001
23.68,58.600,0.02738,3.201,0.001
23.76,58.700,0.02755,3.211,0.001
23.84,58.800,0.02772,3.222,0.001
23.93,58.900,0.02788,3.233,0.001
24.01,59.000,0.02805,3.245,0.001
24.11,59.100,0.02826,3.258,0.001
24.20,59.200,0.02846,3.271,0.001
24.31,59.300,0.02863,3.284,0.001
24.41,59.400,0.02884,3.298,0.001
24.51,59.500,0.02904,3.312,0.001
24.61,59.600,0.02925,3.325,0.001
24.71,59.700,0.02950,3.339,0.001
24.83,59.800,0.02971,3.355,0.001
24.93,59.900,0.02992,3.369,0.001
25.03,60.000,0.03013,3.383,0.001
25.12,60.100,0.03033,3.395,0.001
25.20,60.200,0.03054,3.406,0.001
25.30,60.300,0.03075,3.419,0.001
25.38,60.400,0.03096,3.430,0.001
25.48,60.500,0.03116,3.443,0.001
25.55,60.600,0.03133,3.452,0.001
25.64,60.700,0.03150,3.464,0.001
25.71,60.800,0.03166,3.474,0.001
25.78,60.900,0.03183,3.484,0.001
25.84,61.000,0.03200,3.492,0.001
25.90,61.100,0.03216,3.500,0.001
25.97,61.200,0.03229,3.509,0.001
26.02,61.300,0.03245,3.516,0.001
26.09,61.400,0.03258,3.526,0.001
26.15,61.500,0.03274,3.533,0.001
26.21,61.600,0.03287,3.542,0.001
26.28,61.700,0.03299,3.552,0.001
26.35,61.800,0.03316,3.560,0.001
26.40,61.900,0.03328,3.567,0.001
26.45,62.000,0.03341,3.574,0.001
26.51,62.100,0.03353,3.582,0.001
26.57,62.200,0.03366,3.591,0.001
26.65,62.300,0.03378,3.601,0.001
26.69,62.400,0.03395,3.607,0.001
26.76,62.500,0.03407,3.616,0.001
26.83,62.600,0.03420,3.626,0.001
26.92,62.700,0.03436,3.638,0.001
26.98,62.800,0.03449,3.646,0.001
27.06,62.900,0.03465,3.657,0.001
27.15,63.000,0.03478,3.669,0.001
27.23,63.100,0.03495,3.679,0.001
27.32,63.200,0.03511,3.692,0.001
27.40,63.300,0.03524,3.702,0.001
27.47,63.400,0.03540,3.712,0.001
27.54,63.500,0.03557,3.722,0.001
27.61,63.600,0.03569,3.731,0.001
27.70,63.700,0.03586,3.744,0.001
27.78,63.800,0.03603,3.754,0.001
27.86,63.900,0.03615,3.765,0.001
27.93,64.000,0.03632,3.775,0.001
28.01,64.100,0.03648,3.786,0.001
28.09,64.200,0.03665,3.796,0.001
28.18,64.300,0.03682,3.808,0.001
28.26,64.400,0.03698,3.819,0.001
28.35,64.500,0.03715,3.832,0.001
28.43,64.600,0.03731,3.841,0.001
28.52,64.700,0.03748,3.855,0.001
28.61,64.800,0.03765,3.866,0.001
28.72,64.900,0.03785,3.881,0.001
28.82,65.000,0.03802,3.895,0.001
28.91,65.100,0.03823,3.907,0.001
29.03,65.200,0.03844,3.923,0.001
29.14,65.300,0.03864,3.937,0.001
29.25,65.400,0.03885,3.952,0.001
29.36,65.500,0.03906,3.968,0.001
29.46,65.600,0.03927,3.981,0.001
29.56,65.700,0.03948,3.995,0.001
29.66,65.800,0.03968,4.008,0.001
29.76,65.900,0.03989,4.022,0.001
29.86,66.000,0.04010,4.035,0.001
29.97,66.100,0.04026,4.050,0.001
30.07,66.200,0.04047,4.064,0.001
30.15,66.300,0.04064,4.075,0.001
30.25,66.400,0.04085,4.087,0.001
30.33,66.500,0.04101,4.098,0.001
30.40,66.600,0.04118,4.108,0.001
30.47,66.700,0.04135,4.118,0.001
30.55,66.800,0.04151,4.129,0.001
30.64,66.900,0.04168,4.140,0.001
30.70,67.000,0.04180,4.149,0.001
30.78,67.100,0.04197,4.159,0.001
30.85,67.200,0.04209,4.169,0.001
30.93,67.300,0.04226,4.180,0.001
31.01,67.400,0.04238,4.190,0.001
31.07,67.500,0.04255,4.199,0.001
31.15,67.600,0.04268,4.210,0.001
31.22,67.700,0.04280,4.218,0.001
31.28,67.800,0.04292,4.227,0.001
31.36,67.900,0.04309,4.237,0.001
31.41,68.000,0.04322,4.245,0.001
31.50,68.100,0.04334,4.256,0.001
31.57,68.200,0.04346,4.266,0.001
31.66,68.300,0.04363,4.278,0.001
31.72,68.400,0.04376,4.286,0.001
31.82,68.500,0.04388,4.299,0.001
31.90,68.600,0.04405,4.310,0.001
31.97,68.700,0.04417,4.320,0.001
32.04,68.800,0.04434,4.330,0.001
32.15,68.900,0.04446,4.345,0.001
32.22,69.000,0.04463,4.355,0.001
32.31,69.100,0.04479,4.367,0.001
32.39,69.200,0.04492,4.377,0.001
32.48,69.300,0.04509,4.390,0.001
32.57,69.400,0.04525,4.401,0.001
32.66,69.500,0.04538,4.413,0.001
32.74,69.600,0.04554,4.425,0.001
32.84,69.700,0.04571,4.437,0.001
32.92,69.800,0.04587,4.448,0.001
33.02,69.900,0.04600,4.462,0.001
33.09,70.000,0.04617,4.472,0.001
33.18,70.100,0.04633,4.484,0.001
33.28,70.200,0.04650,4.497,0.001
33.39,70.300,0.04666,4.512,0.001
33.48,70.400,0.04687,4.525,0.001
33.58,70.500,0.04704,4.538,0.001
33.69,70.600,0.04720,4.553,0.001
33.82,70.700,0.04741,4.570,0.001
33.94,70.800,0.04762,4.586,0.001
34.06,70.900,0.04783,4.603,0.001
34.19,71.000,0.04804,4.620,0.001
34.33,71.100,0.04824,4.639,0.001
34.46,71.200,0.04845,4.657,0.001
34.58,71.300,0.04870,4.674,0.001
34.70,71.400,0.04891,4.689,0.001
34.83,71.500,0.04912,4.707,0.001
34.95,71.600,0.04932,4.723,0.001
35.07,71.700,0.04953,4.740,0.001
35.17,71.800,0.04974,4.753,0.001
35.31,71.900,0.04995,4.772,0.001
35.41,72.000,0.05011,4.785,0.001
35.51,72.100,0.05032,4.799,0.001
35.61,72.200,0.05049,4.812,0.001
35.69,72.300,0.05065,4.823,0.001
35.79,72.400,0.05082,4.836,0.001
35.86,72.500,0.05099,4.847,0.001
35.96,72.600,0.05111,4.859,0.001
36.04,72.700,0.05128,4.870,0.001
36.12,72.800,0.05140,4.881,0.001
36.19,72.900,0.05157,4.890,0.001
36.28,73.000,0.05169,4.902,0.001
36.36,73.100,0.05186,4.913,0.001
36.44,73.200,0.05198,4.924,0.001
36.51,73.300,0.05211,4.934,0.001
36.60,73.400,0.05227,4.946,0.001
36.68,73.500,0.05240,4.957,0.001
36.75,73.600,0.05252,4.966,0.001
36.83,73.700,0.05265,4.977,0.001
36.91,73.800,0.05281,4.988,0.001
37.00,73.900,0.05294,5.001,0.001
37.10,74.000,0.05306,5.013,0.001
37.17,74.100,0.05323,5.023,0.001
37.28,74.200,0.05336,5.038,0.001
37.36,74.300,0.05352,5.049,0.001
37.47,74.400,0.05365,5.063,0.001
37.55,74.500,0.05381,5.074,0.001
37.66,74.600,0.05398,5.089,0.001
37.77,74.700,0.05410,5.103,0.001
37.85,74.800,0.05427,5.115,0.001
37.93,74.900,0.05444,5.125,0.001
38.03,75.000,0.05456,5.139,0.001
38.13,75.100,0.05473,5.152,0.001
38.22,75.200,0.05489,5.165,0.001
38.31,75.300,0.05506,5.177,0.001
38.41,75.400,0.05518,5.190,0.001
38.51,75.500,0.05535,5.204,0.001
38.60,75.600,0.05552,5.217,0.001
38.72,75.700,0.05568,5.232,0.001
38.81,75.800,0.05585,5.245,0.001
38.92,75.900,0.05601,5.260,0.001
39.05,76.000,0.05618,5.277,0.001
39.16,76.100,0.05639,5.292,0.001
39.31,76.200,0.05655,5.312,0.001
39.43,76.300,0.05672,5.328,0.001
39.55,76.400,0.05693,5.345,0.001
39.72,76.500,0.05714,5.367,0.001
39.88,76.600,0.05734,5.389,0.001
40.02,76.700,0.05759,5.408,0.001
40.16,76.800,0.05780,5.427,0.001
40.31,76.900,0.05801,5.448,0.001
40.45,77.000,0.05822,5.466,0.001
40.59,77.100,0.05847,5.486,0.001
40.76,77.200,0.05867,5.509,0.001
40.90,77.300,0.05888,5.527,0.001
41.03,77.400,0.05909,5.544,0.001
41.16,77.500,0.05930,5.562,0.001
41.26,77.600,0.05951,5.576,0.001
41.38,77.700,0.05967,5.591,0.001
41.48,77.800,0.05984,5.606,0.001
41.59,77.900,0.06005,5.620,0.001
41.69,78.000,0.06017,5.634,0.001
41.80,78.100,0.06034,5.648,0.001
41.87,78.200,0.06050,5.659,0.001
41.98,78.300,0.06067,5.673,0.001
42.08,78.400,0.06079,5.686,0.001
42.17,78.500,0.06096,5.698,0.001
42.26,78.600,0.06108,5.711,0.001
42.35,78.700,0.06125,5.723,0.001
42.42,78.800,0.06138,5.733,0.001
42.51,78.900,0.06154,5.745,0.001
42.59,79.000,0.06167,5.755,0.001
42.67,79.100,0.06179,5.766,0.001
42.78,79.200,0.06196,5.781,0.001
42.85,79.300,0.06208,5.790,0.001
42.92,79.400,0.06221,5.800,0.001
43.02,79.500,0.06233,5.814,0.001
43.11,79.600,0.06246,5.826,0.001
43.23,79.700,0.06262,5.842,0.001
43.32,79.800,0.06275,5.854,0.001
43.44,79.900,0.06291,5.870,0.001
43.53,80.000,0.06304,5.882,0.001
43.64,80.100,0.06320,5.898,0.001
43.73,80.200,0.06337,5.909,0.001
43.85,80.300,0.06349,5.926,0.001
43.97,80.400,0.06366,5.943,0.001
44.04,80.500,0.06383,5.952,0.001
44.15,80.600,0.06395,5.966,0.001
44.26,80.700,0.06412,5.980,0.001
44.38,80.800,0.06428,5.998,0.001
44.49,80.900,0.06441,6.013,0.001
44.57,81.000,0.06458,6.023,0.001
44.71,81.100,0.06474,6.042,0.001
44.81,81.200,0.06491,6.056,0.001
44.90,81.300,0.06507,6.067,0.001
45.00,81.400,0.06520,6.082,0.001
45.14,81.500,0.06536,6.100,0.001
45.27,81.600,0.06557,6.118,0.001
45.41,81.700,0.06574,6.137,0.001
45.52,81.800,0.06590,6.151,0.001
45.65,81.900,0.06607,6.168,0.001
45.80,82.000,0.06628,6.189,0.001
45.96,82.100,0.06645,6.210,0.001
46.10,82.200,0.06665,6.229,0.001
46.27,82.300,0.06686,6.252,0.001
46.43,82.400,0.06707,6.274,0.001
46.60,82.500,0.06732,6.297,0.001
46.75,82.600,0.06753,6.318,0.001
46.91,82.700,0.06773,6.339,0.001
47.07,82.800,0.06794,6.361,0.001
47.21,82.900,0.06815,6.380,0.001
47.37,83.000,0.06836,6.401,0.001
47.50,83.100,0.06856,6.419,0.001
47.62,83.200,0.06877,6.435,0.001
47.75,83.300,0.06894,6.453,0.001
47.87,83.400,0.06910,6.469,0.001
47.99,83.500,0.06931,6.485,0.001
48.10,83.600,0.06948,6.500,0.001
48.22,83.700,0.06964,6.516,0.001
48.31,83.800,0.06977,6.528,0.001
48.40,83.900,0.06994,6.541,0.001
48.51,84.000,0.07010,6.555,0.001
48.61,84.100,0.07023,6.570,0.001
48.71,84.200,0.07039,6.583,0.001
48.81,84.300,0.07052,6.596,0.001
48.92,84.400,0.07068,6.611,0.001
49.03,84.500,0.07081,6.626,0.001
49.12,84.600,0.07093,6.638,0.001
49.20,84.700,0.07110,6.649,0.001
49.30,84.800,0.07122,6.662,0.001
49.39,84.900,0.07135,6.674,0.001
49.48,85.000,0.07147,6.686,0.001
49.58,85.100,0.07164,6.700,0.001
49.67,85.200,0.07176,6.713,0.001
49.80,85.300,0.07189,6.730,0.001
49.89,85.400,0.07206,6.743,0.001
50.00,85.500,0.07218,6.757,0.001
50.11,85.600,0.07230,6.771,0.001
50.22,85.700,0.07247,6.787,0.001
31.07,85.800,0.07260,4.198,0.001
28.84,85.900,0.07276,3.898,0.001
28.88,86.000,0.07293,3.902,0.001
29.12,86.100,0.07305,3.936,0.001
29.38,86.200,0.07322,3.970,0.001
29.66,86.300,0.07338,4.008,0.001
29.91,86.400,0.07355,4.042,0.001
30.18,86.500,0.07368,4.078,0.001
30.43,86.600,0.07384,4.112,0.001
30.67,86.700,0.07401,4.145,0.001
30.89,86.800,0.07417,4.174,0.001
31.12,86.900,0.07434,4.206,0.001
31.34,87.000,0.07451,4.235,0.001
31.56,87.100,0.07467,4.265,0.001
31.75,87.200,0.07484,4.290,0.001
31.96,87.300,0.07501,4.319,0.001
32.14,87.400,0.07517,4.343,0.001
32.34,87.500,0.07538,4.371,0.001
32.55,87.600,0.07555,4.399,0.001
32.75,87.700,0.07575,4.426,0.001
32.96,87.800,0.07600,4.454,0.001
26.16,87.900,0.07621,3.536,0.002
11.76,88.000,0.07642,1.590,0.002
11.51,88.100,0.07663,1.555,0.002
11.73,88.200,0.07688,1.585,0.002
11.98,88.300,0.07708,1.619,0.002
12.22,88.400,0.07733,1.651,0.002
12.42,88.500,0.07754,1.678,0.002
12.64,88.600,0.07775,1.708,0.002
12.83,88.700,0.07796,1.734,0.002
12.98,88.800,0.07816,1.754,0.002
13.16,88.900,0.07837,1.778,0.002
13.28,89.000,0.07858,1.795,0.002
13.40,89.100,0.07875,1.810,0.002
13.52,89.200,0.07891,1.827,0.002
13.61,89.300,0.07912,1.839,0.002
13.72,89.400,0.07929,1.854,0.002
13.81,89.500,0.07945,1.866,0.002
13.91,89.600,0.07958,1.879,0.002
13.99,89.700,0.07974,1.890,0.002
14.08,89.800,0.07987,1.902,0.002
14.16,89.900,0.08003,1.914,0.002
14.23,90.000,0.08016,1.923,0.002
14.30,90.100,0.08032,1.932,0.002
14.37,90.200,0.08045,1.942,0.002
14.44,90.300,0.08057,1.951,0.002
14.53,90.400,0.08070,1.963,0.002
14.59,90.500,0.08082,1.971,0.002
14.66,90.600,0.08099,1.982,0.002
14.72,90.700,0.08111,1.990,0.002
14.82,90.800,0.08124,2.003,0.002
14.88,90.900,0.08141,2.011,0.002
14.97,91.000,0.08153,2.023,0.002
15.04,91.100,0.08165,2.032,0.002
15.13,91.200,0.08182,2.045,0.002
15.21,91.300,0.08199,2.055,0.002
15.30,91.400,0.08211,2.067,0.002
15.37,91.500,0.08224,2.077,0.002
15.46,91.600,0.08240,2.090,0.002
15.52,91.700,0.08257,2.098,0.002
15.63,91.800,0.08269,2.112,0.002
15.69,91.900,0.08286,2.121,0.002
15.73,91.930,0.08290,2.126,0.002