File: data-files/CWRU/0900-05-50C-2.txt
""
"Test Method","Will_Huddleston_Disks.msm"
"Sample I. D.","900-5-50C.mss"
"Specimen Number","2"

"Load (N)","Time (s)","Extension (mm)","Stress (MPa)","Strain (mm/mm)"

106.04,0.200,-0.00012,14.205,0.000
106.02,0.300,-0.00012,14.202,0.000
106.03,0.400,-0.00012,14.205,0.000
106.01,0.500,-0.00012,14.201,0.000
106.02,0.600,-0.00012,14.203,0.000
106.00,0.700,-0.00012,14.200,0.000
106.00,0.800,-0.00012,14.201,0.000
106.00,0.900,-0.00012,14.201,0.000
106.01,1.000,-0.00012,14.201,0.000
106.01,1.100,-0.00012,14.201,0.000
106.00,1.200,-0.00012,14.200,0.000
105.99,1.300,-0.00012,14.199,0.000
105.99,1.400,-0.00008,14.199,0.000
106.01,1.500,-0.00008,14.201,0.000
105.98,1.600,-0.00008,14.198,0.000
105.98,1.700,-0.00008,14.198,0.000
105.99,1.800,-0.00008,14.198,0.000
105.99,1.900,-0.00008,14.199,0.000
105.98,2.000,-0.00008,14.197,0.000
106.00,2.100,-0.00008,14.201,0.000
105.97,2.200,-0.00008,14.196,0.000
105.99,2.300,-0.00004,14.199,0.000
105.98,2.400,-0.00004,14.197,0.000
105.98,2.500,-0.00004,14.197,0.000
105.95,2.600,-0.00004,14.194,0.000
105.99,2.700,-0.00004,14.199,0.000
105.94,2.800,-0.00004,14.192,0.000
105.97,2.900,-0.00004,14.197,0.000
105.95,3.000,-0.00004,14.194,0.000
105.97,3.100,0.00000,14.197,0.000
105.95,3.200,0.00000,14.193,0.000
105.97,3.300,0.00000,14.197,0.000
105.95,3.400,0.00000,14.193,0.000
105.97,3.500,0.00000,14.196,0.000
105.94,3.600,0.00000,14.193,0.000
105.97,3.700,0.00000,14.196,0.000
105.93,3.800,0.00000,14.191,0.000
105.97,3.900,0.00004,14.197,0.000
105.94,4.000,0.00004,14.193,0.000
105.97,4.100,0.00004,14.196,0.000
105.94,4.200,0.00004,14.192,0.000
105.97,4.300,0.00004,14.196,0.000
105.94,4.400,0.00004,14.193,0.000
105.95,4.500,0.00008,14.194,0.000
105.94,4.600,0.00008,14.192,0.000
105.95,4.700,0.00008,14.194,0.000
105.94,4.800,0.00008,14.192,0.000
105.95,4.900,0.00008,14.193,0.000
105.95,5.000,0.00008,14.194,0.000
105.95,5.100,0.00008,14.194,0.000
105.95,5.200,0.00012,14.194,0.000
105.96,5.300,0.00012,14.196,0.000
105.96,5.400,0.00012,14.195,0.000
105.97,5.500,0.00012,14.196,0.000
105.99,5.600,0.00017,14.199,0.000
106.02,5.700,0.00017,14.203,0.000
106.17,5.800,0.00025,14.223,0.000
106.39,5.900,0.00033,14.253,0.000
106.77,6.000,0.00042,14.303,0.000
107.14,6.100,0.00054,14.353,0.000
107.46,6.200,0.00062,14.397,0.000
107.74,6.300,0.00071,14.433,0.000
108.01,6.400,0.00079,14.470,0.000
108.24,6.500,0.00087,14.501,0.000
108.48,6.600,0.00096,14.533,0.000
108.69,6.700,0.00100,14.561,0.000
108.94,6.800,0.00108,14.594,0.000
109.14,6.900,0.00116,14.621,0.000
109.36,7.000,0.00125,14.651,0.000
109.57,7.100,0.00133,14.679,0.000
109.78,7.200,0.00141,14.707,0.000
109.98,7.300,0.00150,14.733,0.000
110.20,7.400,0.00158,14.763,0.000
110.38,7.500,0.00166,14.787,0.000
110.56,7.600,0.00175,14.811,0.000
110.74,7.700,0.00183,14.836,0.000
110.91,7.800,0.00187,14.858,0.000
111.09,7.900,0.00195,14.882,0.000
111.25,8.000,0.00204,14.904,0.000
111.42,8.100,0.00212,14.926,0.000
111.58,8.200,0.00220,14.948,0.000
111.76,8.300,0.00233,14.972,0.000
111.89,8.400,0.00241,14.989,0.000
112.03,8.500,0.00245,15.009,0.000
112.15,8.600,0.00253,15.025,0.000
112.32,8.700,0.00262,15.047,0.000
112.44,8.800,0.00270,15.063,0.000
112.62,8.900,0.00283,15.087,0.000
112.75,9.000,0.00291,15.104,0.000
112.91,9.100,0.00299,15.126,0.000
113.03,9.200,0.00308,15.143,0.000
113.19,9.300,0.00316,15.163,0.000
113.30,9.400,0.00324,15.178,0.000
113.45,9.500,0.00332,15.198,0.000
113.57,9.600,0.00341,15.214,0.000
113.71,9.700,0.00353,15.234,0.000
113.83,9.800,0.00362,15.250,0.000
114.01,9.900,0.00370,15.274,0.000
114.13,10.000,0.00378,15.289,0.000
114.30,10.100,0.00391,15.312,0.000
114.42,10.200,0.00399,15.328,0.000
114.59,10.300,0.00411,15.351,0.000
114.72,10.400,0.00420,15.368,0.000
114.89,10.500,0.00432,15.392,0.000
115.05,10.600,0.00445,15.413,0.000
115.20,10.700,0.00453,15.433,0.000
115.34,10.800,0.00465,15.451,0.000
115.50,10.900,0.00478,15.473,0.000
115.65,11.000,0.00486,15.492,0.000
115.81,11.100,0.00499,15.514,0.000
115.95,11.200,0.00511,15.534,0.000
116.09,11.300,0.00519,15.552,0.000
116.21,11.400,0.00532,15.569,0.000
116.33,11.500,0.00540,15.585,0.000
116.46,11.600,0.00553,15.601,0.000
116.59,11.700,0.00565,15.619,0.000
116.73,11.800,0.00573,15.637,0.000
116.85,11.900,0.00586,15.653,0.000
117.00,12.000,0.00594,15.674,0.000
117.14,12.100,0.00607,15.692,0.000
117.27,12.200,0.00615,15.710,0.000
117.39,12.300,0.00627,15.727,0.000
117.55,12.400,0.00636,15.748,0.000
117.63,12.500,0.00644,15.758,0.000
117.75,12.600,0.00657,15.774,0.000
117.84,12.700,0.00665,15.787,0.000
117.97,12.800,0.00673,15.804,0.000
118.07,12.900,0.00686,15.817,0.000
118.22,13.000,0.00694,15.838,0.000
118.33,13.100,0.00702,15.852,0.000
118.43,13.200,0.00711,15.866,0.000
118.51,13.300,0.00719,15.876,0.000
118.59,13.400,0.00727,15.887,0.000
118.68,13.500,0.00736,15.899,0.000
118.79,13.600,0.00744,15.914,0.000
118.87,13.700,0.00752,15.924,0.000
118.97,13.800,0.00760,15.938,0.000
119.06,13.900,0.00769,15.950,0.000
119.18,14.000,0.00777,15.966,0.000
119.26,14.100,0.00785,15.976,0.000
119.36,14.200,0.00790,15.991,0.000
119.46,14.300,0.00798,16.003,0.000
119.58,14.400,0.00806,16.019,0.000
119.65,14.500,0.00814,16.029,0.000
119.75,14.600,0.00823,16.042,0.000
119.84,14.700,0.00831,16.055,0.000
119.94,14.800,0.00835,16.067,0.000
120.01,14.900,0.00844,16.077,0.000
120.12,15.000,0.00852,16.092,0.000
120.18,15.100,0.00856,16.100,0.000
120.28,15.200,0.00864,16.114,0.000
120.35,15.300,0.00873,16.123,0.000
120.43,15.400,0.00877,16.134,0.000
120.51,15.500,0.00885,16.145,0.000
120.59,15.600,0.00893,16.156,0.000
120.69,15.700,0.00898,16.168,0.000
120.76,15.800,0.00906,16.178,0.000
120.85,15.900,0.00910,16.189,0.000
120.91,16.000,0.00918,16.198,0.000
121.03,16.100,0.00923,16.213,0.000
121.08,16.200,0.00931,16.220,0.000
121.20,16.300,0.00939,16.237,0.000
121.27,16.400,0.00943,16.247,0.000
121.39,16.500,0.00952,16.263,0.000
121.47,16.600,0.00960,16.273,0.000
121.60,16.700,0.00964,16.290,0.000
121.68,16.800,0.00972,16.301,0.000
121.78,16.900,0.00981,16.314,0.000
121.88,17.000,0.00985,16.327,0.000
121.99,17.100,0.00993,16.343,0.000
122.07,17.200,0.01001,16.353,0.000
122.20,17.300,0.01010,16.371,0.000
122.28,17.400,0.01014,16.382,0.000
112.52,17.500,0.01022,15.074,0.000
9.92,17.560,0.01026,1.329,0.000