File: data-files/CWRU/0900-05-20B.txt
""
"Test Method","Will_Huddleston_Disks.msm"
"Sample I. D.","900-5-20B.mss"
"Specimen Number","1"

"Load (N)","Time (s)","Extension (mm)","Stress (MPa)","Strain (mm/mm)"

2.11,0.200,-0.16046,0.205,-0.003
2.10,0.400,-0.16042,0.205,-0.003
2.11,0.600,-0.16042,0.206,-0.003
2.11,0.800,-0.16037,0.206,-0.003
2.10,1.000,-0.16033,0.205,-0.003
2.11,1.200,-0.16029,0.205,-0.003
2.11,1.400,-0.16025,0.206,-0.003
2.13,1.600,-0.16021,0.208,-0.003
2.25,1.800,-0.16004,0.220,-0.003
2.45,2.000,-0.15975,0.239,-0.003
2.60,2.200,-0.15942,0.253,-0.003
2.66,2.400,-0.15913,0.259,-0.003
2.73,2.600,-0.15884,0.266,-0.003
2.79,2.800,-0.15859,0.272,-0.003
2.83,3.000,-0.15834,0.276,-0.003
2.88,3.200,-0.15805,0.281,-0.003
2.93,3.400,-0.15780,0.286,-0.003
2.98,3.600,-0.15755,0.291,-0.003
3.03,3.800,-0.15726,0.295,-0.003
3.07,4.000,-0.15697,0.299,-0.003
3.11,4.200,-0.15668,0.303,-0.003
3.16,4.400,-0.15643,0.308,-0.003
3.19,4.600,-0.15614,0.311,-0.003
3.23,4.800,-0.15585,0.314,-0.003
3.28,5.000,-0.15551,0.320,-0.003
3.31,5.200,-0.15522,0.323,-0.003
3.34,5.400,-0.15493,0.326,-0.003
3.38,5.600,-0.15460,0.330,-0.003
3.41,5.800,-0.15427,0.333,-0.003
3.46,6.000,-0.15389,0.337,-0.003
3.50,6.200,-0.15352,0.341,-0.003
3.54,6.400,-0.15310,0.345,-0.003
3.54,6.600,-0.15265,0.345,-0.003
3.56,6.800,-0.15223,0.347,-0.003
3.57,7.000,-0.15181,0.348,-0.003
3.60,7.200,-0.15140,0.351,-0.003
3.60,7.400,-0.15102,0.351,-0.003
3.63,7.600,-0.15065,0.354,-0.003
3.63,7.800,-0.15032,0.354,-0.003
3.68,8.000,-0.15003,0.359,-0.003
3.66,8.200,-0.14974,0.357,-0.003
3.68,8.400,-0.14945,0.359,-0.003
3.70,8.600,-0.14920,0.360,-0.003
3.72,8.800,-0.14891,0.363,-0.003
3.75,9.000,-0.14866,0.366,-0.003
3.81,9.200,-0.14837,0.371,-0.003
3.81,9.400,-0.14812,0.372,-0.003
3.87,9.600,-0.14783,0.377,-0.003
3.90,9.800,-0.14753,0.380,-0.003
3.94,10.000,-0.14724,0.384,-0.003
3.97,10.200,-0.14691,0.387,-0.003
4.05,10.400,-0.14662,0.395,-0.003
4.07,10.600,-0.14633,0.397,-0.003
4.15,10.800,-0.14600,0.405,-0.003
4.19,11.000,-0.14571,0.408,-0.003
4.26,11.200,-0.14537,0.415,-0.003
4.30,11.400,-0.14504,0.419,-0.003
4.37,11.600,-0.14467,0.426,-0.003
4.43,11.800,-0.14429,0.432,-0.003
4.49,12.000,-0.14388,0.437,-0.003
4.56,12.200,-0.14346,0.444,-0.003
4.64,12.400,-0.14305,0.452,-0.003
4.67,12.600,-0.14263,0.455,-0.003
4.74,12.800,-0.14221,0.462,-0.003
4.79,13.000,-0.14184,0.467,-0.003
4.82,13.200,-0.14147,0.470,-0.003
4.83,13.400,-0.14109,0.471,-0.003
4.88,13.600,-0.14076,0.475,-0.003
4.88,13.800,-0.14047,0.475,-0.003
4.90,14.000,-0.14018,0.478,-0.003
4.91,14.200,-0.13989,0.479,-0.003
4.90,14.400,-0.13960,0.477,-0.003
4.95,14.600,-0.13931,0.482,-0.003
4.96,14.800,-0.13906,0.483,-0.003
4.96,15.000,-0.13877,0.483,-0.003
4.99,15.200,-0.13852,0.486,-0.003
5.00,15.400,-0.13823,0.487,-0.003
5.01,15.600,-0.13793,0.488,-0.003
5.03,15.800,-0.13760,0.490,-0.003
5.03,16.000,-0.13731,0.490,-0.003
5.03,16.200,-0.13702,0.490,-0.003
5.07,16.400,-0.13669,0.494,-0.003
5.07,16.600,-0.13640,0.494,-0.003
5.08,16.800,-0.13606,0.495,-0.003
5.08,17.000,-0.13577,0.495,-0.003
5.09,17.200,-0.13544,0.496,-0.003
5.09,17.400,-0.13507,0.496,-0.003
5.12,17.600,-0.13469,0.499,-0.003
5.14,17.800,-0.13428,0.501,-0.003
5.15,18.000,-0.13390,0.502,-0.003
5.16,18.200,-0.13345,0.503,-0.003
5.19,18.400,-0.13307,0.506,-0.003
5.21,18.600,-0.13266,0.508,-0.003
5.25,18.800,-0.13228,0.511,-0.003
5.28,19.000,-0.13191,0.515,-0.003
5.32,19.200,-0.13154,0.519,-0.003
5.35,19.400,-0.13120,0.522,-0.003
5.39,19.600,-0.13091,0.526,-0.003
5.43,19.800,-0.13062,0.529,-0.003
5.48,20.000,-0.13033,0.534,-0.003
5.50,20.200,-0.13008,0.536,-0.003
5.54,20.400,-0.12979,0.540,-0.003
5.59,20.600,-0.12954,0.544,-0.003
5.63,20.800,-0.12925,0.548,-0.003
5.66,21.000,-0.12896,0.551,-0.003
5.69,21.200,-0.12867,0.555,-0.003
5.75,21.400,-0.12838,0.561,-0.003
5.79,21.600,-0.12809,0.564,-0.003
5.84,21.800,-0.12780,0.569,-0.003
5.88,22.000,-0.12750,0.573,-0.003
5.91,22.200,-0.12717,0.576,-0.003
5.98,22.400,-0.12688,0.582,-0.002
6.00,22.600,-0.12655,0.584,-0.002
6.06,22.800,-0.12626,0.590,-0.002
6.11,23.000,-0.12588,0.595,-0.002
6.16,23.200,-0.12555,0.600,-0.002
6.23,23.400,-0.12514,0.607,-0.002
6.29,23.600,-0.12476,0.613,-0.002
6.35,23.800,-0.12430,0.619,-0.002
6.40,24.000,-0.12389,0.624,-0.002
6.48,24.200,-0.12347,0.631,-0.002
6.52,24.400,-0.12306,0.635,-0.002
6.58,24.600,-0.12268,0.642,-0.002
6.63,24.800,-0.12231,0.646,-0.002
6.69,25.000,-0.12198,0.652,-0.002
6.71,25.200,-0.12169,0.654,-0.002
6.75,25.400,-0.12140,0.658,-0.002
6.80,25.600,-0.12110,0.663,-0.002
6.84,25.800,-0.12081,0.666,-0.002
6.87,26.000,-0.12056,0.670,-0.002
6.91,26.200,-0.12027,0.673,-0.002
6.96,26.400,-0.12002,0.679,-0.002
7.02,26.600,-0.11973,0.684,-0.002
7.05,26.800,-0.11944,0.687,-0.002
7.10,27.000,-0.11915,0.692,-0.002
7.15,27.200,-0.11886,0.697,-0.002
7.20,27.400,-0.11853,0.702,-0.002
7.26,27.600,-0.11824,0.707,-0.002
7.29,27.800,-0.11790,0.711,-0.002
7.36,28.000,-0.11761,0.717,-0.002
7.39,28.200,-0.11732,0.721,-0.002
7.47,28.400,-0.11699,0.728,-0.002
7.49,28.600,-0.11666,0.730,-0.002
7.57,28.800,-0.11628,0.738,-0.002
7.65,29.000,-0.11591,0.746,-0.002
7.73,29.200,-0.11549,0.753,-0.002
7.80,29.400,-0.11504,0.761,-0.002
7.91,29.600,-0.11462,0.771,-0.002
7.97,29.800,-0.11416,0.777,-0.002
8.07,30.000,-0.11375,0.787,-0.002
8.12,30.200,-0.11333,0.792,-0.002
8.20,30.400,-0.11296,0.799,-0.002
8.25,30.600,-0.11259,0.804,-0.002
8.33,30.800,-0.11229,0.812,-0.002
8.39,31.000,-0.11196,0.818,-0.002
8.44,31.200,-0.11167,0.823,-0.002
8.50,31.400,-0.11138,0.829,-0.002
8.53,31.600,-0.11113,0.832,-0.002
8.60,31.800,-0.11084,0.838,-0.002
8.66,32.000,-0.11055,0.844,-0.002
8.72,32.200,-0.11030,0.850,-0.002
8.77,32.400,-0.11001,0.855,-0.002
8.84,32.600,-0.10972,0.861,-0.002
8.90,32.800,-0.10943,0.868,-0.002
8.97,33.000,-0.10909,0.874,-0.002
9.04,33.200,-0.10880,0.881,-0.002
9.11,33.400,-0.10847,0.888,-0.002
9.16,33.600,-0.10818,0.893,-0.002
9.24,33.800,-0.10785,0.901,-0.002
9.31,34.000,-0.10752,0.907,-0.002
9.41,34.200,-0.10718,0.917,-0.002
9.45,34.400,-0.10685,0.921,-0.002
9.56,34.600,-0.10644,0.932,-0.002
9.64,34.800,-0.10606,0.940,-0.002
9.75,35.000,-0.10565,0.950,-0.002
9.86,35.200,-0.10519,0.961,-0.002
9.95,35.400,-0.10477,0.969,-0.002
10.06,35.600,-0.10436,0.981,-0.002
10.14,35.800,-0.10398,0.988,-0.002
10.21,36.000,-0.10361,0.995,-0.002
10.30,36.200,-0.10324,1.004,-0.002
10.38,36.400,-0.10290,1.012,-0.002
10.44,36.600,-0.10261,1.017,-0.002
10.52,36.800,-0.10228,1.025,-0.002
10.59,37.000,-0.10199,1.032,-0.002
10.65,37.200,-0.10174,1.037,-0.002
10.71,37.400,-0.10145,1.044,-0.002
10.78,37.600,-0.10120,1.050,-0.002
10.83,37.800,-0.10091,1.056,-0.002
10.92,38.000,-0.10062,1.064,-0.002
10.99,38.200,-0.10033,1.071,-0.002
11.06,38.400,-0.10004,1.078,-0.002
11.15,38.600,-0.09974,1.086,-0.002
11.24,38.800,-0.09945,1.095,-0.002
11.30,39.000,-0.09916,1.101,-0.002
11.39,39.200,-0.09883,1.110,-0.002
11.48,39.400,-0.09854,1.119,-0.002
11.55,39.600,-0.09821,1.126,-0.002
11.65,39.800,-0.09787,1.136,-0.002
11.74,40.000,-0.09754,1.144,-0.002
11.85,40.200,-0.09717,1.155,-0.002
11.96,40.400,-0.09679,1.166,-0.002
12.08,40.600,-0.09638,1.178,-0.002
12.19,40.800,-0.09596,1.188,-0.002
12.30,41.000,-0.09551,1.199,-0.002
12.43,41.200,-0.09509,1.212,-0.002
12.53,41.400,-0.09472,1.221,-0.002
12.63,41.600,-0.09430,1.231,-0.002
12.72,41.800,-0.09397,1.239,-0.002
12.81,42.000,-0.09359,1.248,-0.002
12.88,42.200,-0.09330,1.256,-0.002
12.96,42.400,-0.09301,1.264,-0.002
13.06,42.600,-0.09272,1.273,-0.002
13.12,42.800,-0.09243,1.278,-0.002
13.20,43.000,-0.09218,1.286,-0.002
13.27,43.200,-0.09189,1.293,-0.002
13.36,43.400,-0.09164,1.302,-0.002
13.45,43.600,-0.09135,1.311,-0.002
13.54,43.800,-0.09106,1.320,-0.002
13.63,44.000,-0.09077,1.329,-0.002
13.73,44.200,-0.09048,1.338,-0.002
13.83,44.400,-0.09019,1.348,-0.002
13.93,44.600,-0.08985,1.357,-0.002
14.03,44.800,-0.08956,1.367,-0.002
13.85,45.000,-0.08923,1.350,-0.002
13.97,45.200,-0.08894,1.361,-0.002
14.08,45.400,-0.08861,1.372,-0.002
14.20,45.600,-0.08828,1.384,-0.002
14.30,45.800,-0.08790,1.394,-0.002
14.45,46.000,-0.08753,1.409,-0.002
14.57,46.200,-0.08715,1.420,-0.002
14.73,46.400,-0.08674,1.436,-0.002
14.87,46.600,-0.08628,1.449,-0.002
15.00,46.800,-0.08587,1.461,-0.002
15.14,47.000,-0.08545,1.475,-0.002
15.28,47.200,-0.08503,1.489,-0.002
15.39,47.400,-0.08466,1.500,-0.002
15.49,47.600,-0.08429,1.509,-0.002
15.59,47.800,-0.08395,1.519,-0.002
15.68,48.000,-0.08366,1.528,-0.002
15.78,48.200,-0.08337,1.538,-0.002
15.88,48.400,-0.08308,1.548,-0.002
15.97,48.600,-0.08279,1.557,-0.002
16.06,48.800,-0.08254,1.566,-0.002
16.16,49.000,-0.08225,1.575,-0.002
16.26,49.200,-0.08200,1.584,-0.002
16.35,49.400,-0.08171,1.594,-0.002
16.46,49.600,-0.08142,1.604,-0.002
16.58,49.800,-0.08113,1.616,-0.002
16.67,50.000,-0.08084,1.625,-0.002
16.78,50.200,-0.08050,1.635,-0.002
16.90,50.400,-0.08021,1.647,-0.002
17.00,50.600,-0.07988,1.657,-0.002
17.12,50.800,-0.07959,1.669,-0.002
17.24,51.000,-0.07926,1.680,-0.002
17.35,51.200,-0.07893,1.691,-0.002
17.49,51.400,-0.07859,1.705,-0.002
17.61,51.600,-0.07822,1.716,-0.002
17.77,51.800,-0.07784,1.732,-0.002
17.92,52.000,-0.07743,1.746,-0.002
18.08,52.200,-0.07701,1.762,-0.002
18.24,52.400,-0.07660,1.778,-0.002
18.40,52.600,-0.07618,1.793,-0.001
18.56,52.800,-0.07577,1.809,-0.001
18.70,53.000,-0.07539,1.823,-0.001
18.82,53.200,-0.07506,1.835,-0.001
18.94,53.400,-0.07469,1.846,-0.001
19.07,53.600,-0.07440,1.858,-0.001
19.18,53.800,-0.07410,1.869,-0.001
19.29,54.000,-0.07377,1.880,-0.001
19.39,54.200,-0.07352,1.890,-0.001
19.48,54.400,-0.07323,1.899,-0.001
19.60,54.600,-0.07298,1.910,-0.001
19.68,54.800,-0.07269,1.918,-0.001
19.80,55.000,-0.07244,1.930,-0.001
19.91,55.200,-0.07215,1.941,-0.001
20.04,55.400,-0.07186,1.953,-0.001
20.16,55.600,-0.07157,1.965,-0.001
20.28,55.800,-0.07128,1.976,-0.001
20.41,56.000,-0.07095,1.989,-0.001
20.55,56.200,-0.07066,2.003,-0.001
20.67,56.400,-0.07032,2.014,-0.001
20.80,56.600,-0.07003,2.027,-0.001
20.93,56.800,-0.06970,2.040,-0.001
21.08,57.000,-0.06937,2.055,-0.001
21.23,57.200,-0.06904,2.069,-0.001
21.42,57.400,-0.06862,2.087,-0.001
21.61,57.600,-0.06825,2.106,-0.001
21.82,57.800,-0.06779,2.127,-0.001
22.00,58.000,-0.06737,2.144,-0.001
22.21,58.200,-0.06692,2.165,-0.001
22.40,58.400,-0.06650,2.183,-0.001
22.56,58.600,-0.06608,2.199,-0.001
22.72,58.800,-0.06575,2.214,-0.001
22.85,59.000,-0.06538,2.227,-0.001
22.98,59.200,-0.06509,2.240,-0.001
23.11,59.400,-0.06480,2.252,-0.001
23.24,59.600,-0.06451,2.265,-0.001
23.35,59.800,-0.06421,2.276,-0.001
23.47,60.000,-0.06392,2.287,-0.001
23.59,60.200,-0.06367,2.299,-0.001
23.70,60.400,-0.06338,2.310,-0.001
23.86,60.600,-0.06313,2.325,-0.001
23.98,60.800,-0.06284,2.337,-0.001
24.14,61.000,-0.06255,2.352,-0.001
24.29,61.200,-0.06226,2.367,-0.001
24.44,61.400,-0.06193,2.382,-0.001
24.58,61.600,-0.06164,2.395,-0.001
24.75,61.800,-0.06131,2.412,-0.001
24.92,62.000,-0.06101,2.429,-0.001
25.07,62.200,-0.06068,2.443,-0.001
25.24,62.400,-0.06035,2.459,-0.001
25.41,62.600,-0.06002,2.476,-0.001
25.61,62.800,-0.05964,2.496,-0.001
25.83,63.000,-0.05927,2.517,-0.001
26.03,63.200,-0.05885,2.537,-0.001
26.26,63.400,-0.05844,2.559,-0.001
26.51,63.600,-0.05798,2.583,-0.001
26.73,63.800,-0.05752,2.605,-0.001
26.97,64.000,-0.05711,2.628,-0.001
27.17,64.200,-0.05669,2.648,-0.001
27.36,64.400,-0.05632,2.666,-0.001
27.55,64.600,-0.05595,2.685,-0.001
27.70,64.800,-0.05561,2.700,-0.001
27.86,65.000,-0.05528,2.715,-0.001
28.01,65.200,-0.05499,2.730,-0.001
28.17,65.400,-0.05466,2.745,-0.001
28.31,65.600,-0.05441,2.759,-0.001
28.48,65.800,-0.05412,2.776,-0.001
28.61,66.000,-0.05383,2.789,-0.001
28.77,66.200,-0.05353,2.804,-0.001
28.94,66.400,-0.05324,2.820,-0.001
29.11,66.600,-0.05295,2.837,-0.001
29.29,66.800,-0.05266,2.855,-0.001
29.46,67.000,-0.05233,2.871,-0.001
29.66,67.200,-0.05204,2.890,-0.001
29.85,67.400,-0.05171,2.909,-0.001
30.03,67.600,-0.05142,2.926,-0.001
30.21,67.800,-0.05108,2.944,-0.001
30.42,68.000,-0.05075,2.964,-0.001
30.64,68.200,-0.05042,2.986,-0.001
30.85,68.400,-0.05004,3.006,-0.001
31.10,68.600,-0.04963,3.031,-0.001
31.35,68.800,-0.04925,3.056,-0.001
31.64,69.000,-0.04880,3.083,-0.001
31.86,69.200,-0.04838,3.105,-0.001
32.14,69.400,-0.04797,3.132,-0.001
32.39,69.600,-0.04755,3.156,-0.001
32.62,69.800,-0.04718,3.179,-0.001
32.85,70.000,-0.04680,3.202,-0.001
33.05,70.200,-0.04643,3.221,-0.001
33.27,70.400,-0.04610,3.242,-0.001
33.44,70.600,-0.04576,3.259,-0.001
33.65,70.800,-0.04547,3.279,-0.001
33.81,71.000,-0.04518,3.295,-0.001
33.98,71.200,-0.04489,3.312,-0.001
34.18,71.400,-0.04460,3.331,-0.001
34.35,71.600,-0.04435,3.347,-0.001
34.54,71.800,-0.04406,3.366,-0.001
34.74,72.000,-0.04377,3.386,-0.001
34.94,72.200,-0.04348,3.405,-0.001
35.14,72.400,-0.04319,3.425,-0.001
35.33,72.600,-0.04290,3.443,-0.001
35.54,72.800,-0.04256,3.464,-0.001
35.74,73.000,-0.04227,3.483,-0.001
35.98,73.200,-0.04194,3.506,-0.001
36.18,73.400,-0.04165,3.527,-0.001
36.41,73.600,-0.04132,3.548,-0.001
36.66,73.800,-0.04098,3.573,-0.001
36.92,74.000,-0.04061,3.598,-0.001
37.20,74.200,-0.04024,3.625,-0.001
37.50,74.400,-0.03986,3.655,-0.001
37.84,74.600,-0.03941,3.688,-0.001
38.16,74.800,-0.03899,3.719,-0.001
38.47,75.000,-0.03853,3.749,-0.001
38.78,75.200,-0.03812,3.780,-0.001
39.07,75.400,-0.03770,3.807,-0.001
39.36,75.600,-0.03733,3.836,-0.001
39.59,75.800,-0.03700,3.859,-0.001
39.82,76.000,-0.03666,3.880,-0.001
40.03,76.200,-0.03633,3.901,-0.001
40.24,76.400,-0.03604,3.922,-0.001
40.47,76.600,-0.03579,3.944,-0.001
40.62,76.800,-0.03550,3.959,-0.001
40.84,77.000,-0.03525,3.980,-0.001
41.04,77.200,-0.03496,4.000,-0.001
41.25,77.400,-0.03467,4.021,-0.001
41.47,77.600,-0.03442,4.042,-0.001
41.71,77.800,-0.03413,4.065,-0.001
41.95,78.000,-0.03380,4.088,-0.001
42.18,78.200,-0.03350,4.111,-0.001
42.40,78.400,-0.03321,4.132,-0.001
42.66,78.600,-0.03288,4.157,-0.001
42.89,78.800,-0.03259,4.180,-0.001
43.13,79.000,-0.03226,4.203,-0.001
43.37,79.200,-0.03193,4.227,-0.001
43.66,79.400,-0.03159,4.255,-0.001
43.94,79.600,-0.03126,4.282,-0.001
44.26,79.800,-0.03089,4.313,-0.001
44.59,80.000,-0.03051,4.346,-0.001
44.95,80.200,-0.03010,4.381,-0.001
45.31,80.400,-0.02964,4.416,-0.001
45.67,80.600,-0.02922,4.451,-0.001
46.04,80.800,-0.02881,4.487,-0.001
46.36,81.000,-0.02839,4.518,-0.001
46.72,81.200,-0.02798,4.553,-0.001
47.02,81.400,-0.02765,4.583,-0.001
47.30,81.600,-0.02727,4.610,-0.001
47.53,81.800,-0.02698,4.632,-0.001
47.78,82.000,-0.02669,4.657,-0.001
48.04,82.200,-0.02640,4.682,-0.001
48.27,82.400,-0.02611,4.704,-0.001
48.52,82.600,-0.02586,4.728,-0.001
48.77,82.800,-0.02557,4.753,-0.001
49.02,83.000,-0.02528,4.778,0.000
49.29,83.200,-0.02499,4.804,0.000
49.57,83.400,-0.02470,4.831,0.000
49.87,83.600,-0.02440,4.860,0.000
50.14,83.800,-0.02411,4.887,0.000
50.43,84.000,-0.02382,4.915,0.000
50.73,84.200,-0.02353,4.944,0.000
51.03,84.400,-0.02320,4.973,0.000
51.36,84.600,-0.02291,5.005,0.000
51.68,84.800,-0.02258,5.037,0.000
51.99,85.000,-0.02224,5.067,0.000
52.33,85.200,-0.02191,5.100,0.000
52.73,85.400,-0.02154,5.139,0.000
53.11,85.600,-0.02116,5.176,0.000
53.55,85.800,-0.02079,5.219,0.000
53.97,86.000,-0.02037,5.260,0.000
54.42,86.200,-0.01996,5.304,0.000
54.83,86.400,-0.01954,5.343,0.000
55.25,86.600,-0.01913,5.384,0.000
55.64,86.800,-0.01871,5.422,0.000
56.01,87.000,-0.01834,5.458,0.000
56.33,87.200,-0.01800,5.490,0.000
56.62,87.400,-0.01767,5.519,0.000
56.91,87.600,-0.01734,5.547,0.000
57.18,87.800,-0.01705,5.572,0.000
57.48,88.000,-0.01676,5.602,0.000
57.73,88.200,-0.01651,5.626,0.000
57.99,88.400,-0.01622,5.651,0.000
58.27,88.600,-0.01597,5.679,0.000
58.56,88.800,-0.01568,5.707,0.000
58.84,89.000,-0.01539,5.735,0.000
59.13,89.200,-0.01510,5.763,0.000
59.45,89.400,-0.01480,5.794,0.000
59.75,89.600,-0.01451,5.823,0.000
60.07,89.800,-0.01422,5.855,0.000
60.39,90.000,-0.01393,5.885,0.000
60.74,90.200,-0.01364,5.919,0.000
61.05,90.400,-0.01331,5.950,0.000
61.38,90.600,-0.01302,5.982,0.000
61.73,90.800,-0.01264,6.016,0.000
62.12,91.000,-0.01231,6.054,0.000
62.55,91.200,-0.01194,6.096,0.000
62.97,91.400,-0.01152,6.137,0.000
63.45,91.600,-0.01111,6.184,0.000
63.92,91.800,-0.01069,6.230,0.000
64.39,92.000,-0.01023,6.276,0.000
64.83,92.200,-0.00982,6.319,0.000
65.26,92.400,-0.00940,6.360,0.000
65.67,92.600,-0.00903,6.400,0.000
66.04,92.800,-0.00865,6.436,0.000
66.39,93.000,-0.00832,6.470,0.000
66.69,93.200,-0.00803,6.500,0.000
67.01,93.400,-0.00774,6.531,0.000
67.33,93.600,-0.00745,6.562,0.000
67.62,93.800,-0.00716,6.590,0.000
67.95,94.000,-0.00691,6.622,0.000
68.26,94.200,-0.00662,6.652,0.000
68.57,94.400,-0.00637,6.683,0.000
68.91,94.600,-0.00608,6.716,0.000
69.25,94.800,-0.00579,6.749,0.000
69.60,95.000,-0.00545,6.783,0.000
69.96,95.200,-0.00516,6.818,0.000
70.34,95.400,-0.00487,6.855,0.000
70.72,95.600,-0.00454,6.892,0.000
71.07,95.800,-0.00425,6.926,0.000
71.45,96.000,-0.00392,6.964,0.000
71.82,96.200,-0.00358,7.000,0.000
72.23,96.400,-0.00325,7.039,0.000
72.63,96.600,-0.00288,7.079,0.000
73.12,96.800,-0.00250,7.126,0.000
73.58,97.000,-0.00213,7.171,0.000
74.07,97.200,-0.00171,7.218,0.000
74.57,97.400,-0.00126,7.268,0.000
75.05,97.600,-0.00084,7.314,0.000
75.51,97.800,-0.00043,7.359,0.000
75.99,98.000,-0.00001,7.406,0.000
76.42,98.200,0.00040,7.448,0.000
76.81,98.400,0.00078,7.486,0.000
77.18,98.600,0.00111,7.522,0.000
77.50,98.800,0.00140,7.553,0.000
77.83,99.000,0.00173,7.585,0.000
78.19,99.200,0.00203,7.620,0.000
78.49,99.400,0.00227,7.650,0.000
78.82,99.600,0.00257,7.681,0.000
79.11,99.800,0.00286,7.710,0.000
79.46,100.000,0.00311,7.744,0.000
79.82,100.200,0.00340,7.779,0.000
80.16,100.400,0.00369,7.812,0.000
80.53,100.600,0.00402,7.848,0.000
80.88,100.800,0.00431,7.883,0.000
81.25,101.000,0.00460,7.918,0.000
81.60,101.200,0.00493,7.953,0.000
81.96,101.400,0.00523,7.988,0.000
82.32,101.600,0.00556,8.023,0.000
82.71,101.800,0.00589,8.061,0.000
83.10,102.000,0.00622,8.099,0.000
83.51,102.200,0.00655,8.139,0.000
83.96,102.400,0.00693,8.182,0.000
84.40,102.600,0.00730,8.225,0.000
84.88,102.800,0.00772,8.272,0.000
85.33,103.000,0.00813,8.316,0.000
85.77,103.200,0.00859,8.359,0.000
86.16,103.400,0.00901,8.397,0.000
86.45,103.600,0.00942,8.426,0.000
86.68,103.800,0.00980,8.447,0.000
86.93,104.000,0.01017,8.472,0.000
87.14,104.200,0.01050,8.492,0.000
87.37,104.400,0.01079,8.515,0.000
87.63,104.600,0.01108,8.540,0.000
87.92,104.800,0.01142,8.568,0.000
88.20,105.000,0.01167,8.596,0.000
88.49,105.200,0.01196,8.624,0.000
88.78,105.400,0.01225,8.652,0.000
89.07,105.600,0.01254,8.681,0.000
89.40,105.800,0.01279,8.712,0.000
89.72,106.000,0.01308,8.744,0.000
90.04,106.200,0.01337,8.775,0.000
90.41,106.400,0.01366,8.812,0.000
90.73,106.600,0.01399,8.843,0.000
91.10,106.800,0.01428,8.878,0.000
91.48,107.000,0.01458,8.916,0.000
91.83,107.200,0.01491,8.949,0.000
92.23,107.400,0.01520,8.988,0.000
92.62,107.600,0.01553,9.027,0.000
93.06,107.800,0.01586,9.069,0.000
93.55,108.000,0.01624,9.117,0.000
94.07,108.200,0.01661,9.168,0.000
94.61,108.400,0.01703,9.221,0.000
95.16,108.600,0.01748,9.274,0.000
95.72,108.800,0.01790,9.329,0.000
96.25,109.000,0.01832,9.380,0.000
96.76,109.200,0.01873,9.430,0.000
97.22,109.400,0.01915,9.475,0.000
97.65,109.600,0.01952,9.517,0.000
98.02,109.800,0.01985,9.553,0.000
98.37,110.000,0.02014,9.587,0.000
98.71,110.200,0.02043,9.620,0.000
99.05,110.400,0.02073,9.653,0.000
99.39,110.600,0.02102,9.686,0.000
99.68,110.800,0.02127,9.715,0.000
100.02,111.000,0.02152,9.748,0.000
100.37,111.200,0.02181,9.782,0.000
100.72,111.400,0.02210,9.816,0.000
101.08,111.600,0.02235,9.851,0.000
101.45,111.800,0.02264,9.887,0.000
101.84,112.000,0.02293,9.925,0.000
102.22,112.200,0.02322,9.962,0.000
102.61,112.400,0.02351,10.000,0.000
103.00,112.600,0.02384,10.039,0.000
103.38,112.800,0.02413,10.075,0.000
103.78,113.000,0.02442,10.114,0.000
104.17,113.200,0.02476,10.153,0.000
104.61,113.400,0.02509,10.195,0.000
105.06,113.600,0.02542,10.239,0.001
105.53,113.800,0.02575,10.285,0.001
106.05,114.000,0.02617,10.335,0.001
106.59,114.200,0.02658,10.388,0.001
107.14,114.400,0.02700,10.442,0.001
107.68,114.600,0.02742,10.495,0.001
108.19,114.800,0.02783,10.544,0.001
108.61,115.000,0.02825,10.585,0.001
109.08,115.200,0.02862,10.631,0.001
109.48,115.400,0.02900,10.670,0.001
109.81,115.600,0.02933,10.702,0.001
110.13,115.800,0.02962,10.733,0.001
110.43,116.000,0.02995,10.762,0.001
110.76,116.200,0.03024,10.794,0.001
111.06,116.400,0.03049,10.824,0.001
111.39,116.600,0.03078,10.856,0.001
111.74,116.800,0.03103,10.890,0.001
112.11,117.000,0.03132,10.926,0.001
112.49,117.200,0.03161,10.963,0.001
112.89,117.400,0.03186,11.002,0.001
113.30,117.600,0.03215,11.042,0.001
113.73,117.800,0.03249,11.084,0.001
114.16,118.000,0.03278,11.126,0.001
114.56,118.200,0.03307,11.165,0.001
115.01,118.400,0.03336,11.208,0.001
115.40,118.600,0.03369,11.247,0.001
115.84,118.800,0.03398,11.289,0.001
116.27,119.000,0.03431,11.332,0.001
116.76,119.200,0.03465,11.380,0.001
117.31,119.400,0.03498,11.433,0.001
117.86,119.600,0.03535,11.486,0.001
118.45,119.800,0.03577,11.544,0.001
119.02,120.000,0.03618,11.599,0.001
119.63,120.200,0.03660,11.659,0.001
120.15,120.400,0.03702,11.710,0.001
120.68,120.600,0.03743,11.761,0.001
121.20,120.800,0.03780,11.812,0.001
121.57,121.000,0.03818,11.848,0.001
122.01,121.200,0.03855,11.891,0.001
122.47,121.400,0.03889,11.936,0.001
122.87,121.600,0.03922,11.975,0.001
123.24,121.800,0.03951,12.011,0.001
123.61,122.000,0.03980,12.047,0.001
123.96,122.200,0.04009,12.081,0.001
124.33,122.400,0.04034,12.117,0.001
124.71,122.600,0.04063,12.154,0.001
125.11,122.800,0.04088,12.193,0.001
125.49,123.000,0.04117,12.231,0.001
125.90,123.200,0.04146,12.270,0.001
126.31,123.400,0.04175,12.310,0.001
126.71,123.600,0.04204,12.349,0.001
127.14,123.800,0.04233,12.391,0.001
127.57,124.000,0.04263,12.433,0.001
128.02,124.200,0.04292,12.477,0.001
128.41,124.400,0.04325,12.515,0.001
128.85,124.600,0.04354,12.557,0.001
129.23,124.800,0.04387,12.594,0.001
129.70,125.000,0.04420,12.640,0.001
130.14,125.200,0.04454,12.683,0.001
130.60,125.400,0.04491,12.728,0.001
131.02,125.600,0.04533,12.769,0.001
131.49,125.800,0.04574,12.815,0.001
131.97,126.000,0.04620,12.862,0.001
132.42,126.200,0.04661,12.906,0.001
132.82,126.400,0.04703,12.944,0.001
133.21,126.600,0.04740,12.983,0.001
133.56,126.800,0.04778,13.016,0.001
133.74,127.000,0.04815,13.034,0.001
133.80,127.200,0.04848,13.040,0.001
133.62,127.400,0.04878,13.022,0.001
133.50,127.600,0.04907,13.010,0.001
133.44,127.800,0.04932,13.005,0.001
133.38,128.000,0.04961,12.999,0.001
133.31,128.200,0.04986,12.992,0.001
133.26,128.400,0.05015,12.987,0.001
133.29,128.600,0.05044,12.990,0.001
133.42,128.800,0.05073,13.003,0.001
133.63,129.000,0.05098,13.023,0.001
133.84,129.200,0.05131,13.044,0.001
134.07,129.400,0.05160,13.066,0.001
134.27,129.600,0.05189,13.086,0.001
134.48,129.800,0.05222,13.107,0.001
134.72,130.000,0.05252,13.129,0.001
135.00,130.200,0.05285,13.157,0.001
135.30,130.400,0.05318,13.186,0.001
135.65,130.600,0.05351,13.221,0.001
136.01,130.800,0.05385,13.255,0.001
136.48,131.000,0.05426,13.301,0.001
136.93,131.200,0.05464,13.345,0.001
137.37,131.400,0.05509,13.388,0.001
137.63,131.600,0.05551,13.414,0.001
137.77,131.800,0.05596,13.427,0.001
137.80,132.000,0.05638,13.430,0.001
137.71,132.200,0.05680,13.421,0.001
137.37,132.400,0.05717,13.388,0.001
136.71,132.600,0.05750,13.323,0.001
135.65,132.800,0.05783,13.221,0.001
134.79,133.000,0.05817,13.136,0.001
134.24,133.200,0.05846,13.083,0.001
133.76,133.400,0.05875,13.036,0.001
133.38,133.600,0.05904,12.999,0.001
133.05,133.800,0.05929,12.967,0.001
132.67,134.000,0.05958,12.930,0.001
132.30,134.200,0.05983,12.893,0.001
132.09,134.400,0.06012,12.873,0.001
132.02,134.600,0.06041,12.867,0.001
132.04,134.800,0.06074,12.868,0.001
132.13,135.000,0.06103,12.877,0.001
132.25,135.200,0.06137,12.889,0.001
132.35,135.400,0.06166,12.898,0.001
132.44,135.600,0.06199,12.907,0.001
132.56,135.800,0.06228,12.919,0.001
132.75,136.000,0.06261,12.938,0.001
132.97,136.200,0.06295,12.959,0.001
133.24,136.400,0.06332,12.985,0.001
133.46,136.600,0.06365,13.007,0.001
133.56,136.800,0.06407,13.016,0.001
133.59,137.000,0.06448,13.019,0.001
133.60,137.200,0.06490,13.020,0.001
133.39,137.400,0.06536,13.000,0.001
133.05,137.600,0.06577,12.967,0.001
132.68,137.800,0.06619,12.931,0.001
132.43,138.000,0.06656,12.906,0.001
132.32,138.200,0.06694,12.895,0.001
131.82,138.400,0.06727,12.847,0.001
131.35,138.600,0.06756,12.801,0.001
131.23,138.800,0.06789,12.789,0.001
131.28,139.000,0.06818,12.794,0.001
131.37,139.200,0.06847,12.803,0.001
131.53,139.400,0.06872,12.819,0.001
131.71,139.600,0.06901,12.837,0.001
131.92,139.800,0.06926,12.856,0.001
132.11,140.000,0.06955,12.875,0.001
132.36,140.200,0.06984,12.900,0.001
132.59,140.400,0.07014,12.922,0.001
132.82,140.600,0.07043,12.945,0.001
133.11,140.800,0.07072,12.973,0.001
133.47,141.000,0.07105,13.008,0.001
133.84,141.200,0.07134,13.044,0.001
134.29,141.400,0.07163,13.087,0.001
134.76,141.600,0.07196,13.134,0.001
135.30,141.800,0.07230,13.186,0.001
135.81,142.000,0.07263,13.236,0.001
136.33,142.200,0.07296,13.286,0.001
136.94,142.400,0.07338,13.345,0.001
137.50,142.600,0.07379,13.400,0.001
138.10,142.800,0.07421,13.459,0.001
138.62,143.000,0.07462,13.510,0.001
139.13,143.200,0.07508,13.560,0.001
139.63,143.400,0.07550,13.608,0.001
140.12,143.600,0.07587,13.655,0.001
140.53,143.800,0.07624,13.696,0.002
140.95,144.000,0.07658,13.736,0.002
141.23,144.200,0.07691,13.764,0.002
141.44,144.400,0.07720,13.785,0.002
141.69,144.600,0.07749,13.809,0.002
142.02,144.800,0.07778,13.841,0.002
142.38,145.000,0.07803,13.876,0.002
142.78,145.200,0.07832,13.915,0.002
143.14,145.400,0.07857,13.950,0.002
143.56,145.600,0.07886,13.991,0.002
144.05,145.800,0.07915,14.039,0.002
144.56,146.000,0.07944,14.089,0.002
145.15,146.200,0.07973,14.146,0.002
145.73,146.400,0.08003,14.203,0.002
146.35,146.600,0.08036,14.263,0.002
147.00,146.800,0.08065,14.326,0.002
147.69,147.000,0.08094,14.394,0.002
148.37,147.200,0.08127,14.460,0.002
149.06,147.400,0.08160,14.527,0.002
149.81,147.600,0.08194,14.600,0.002
150.60,147.800,0.08227,14.677,0.002
151.43,148.000,0.08264,14.758,0.002
152.32,148.200,0.08306,14.845,0.002
153.26,148.400,0.08347,14.937,0.002
154.25,148.600,0.08389,15.033,0.002
155.18,148.800,0.08435,15.123,0.002
156.04,149.000,0.08476,15.207,0.002
156.86,149.200,0.08514,15.287,0.002
157.62,149.400,0.08555,15.361,0.002
158.37,149.600,0.08589,15.434,0.002
159.02,149.800,0.08622,15.498,0.002
159.61,150.000,0.08655,15.555,0.002
160.20,150.200,0.08684,15.612,0.002
160.79,150.400,0.08713,15.670,0.002
161.33,150.600,0.08742,15.723,0.002
161.82,150.800,0.08767,15.771,0.002
162.35,151.000,0.08796,15.822,0.002
162.86,151.200,0.08821,15.872,0.002
163.39,151.400,0.08850,15.924,0.002
163.97,151.600,0.08879,15.980,0.002
164.53,151.800,0.08908,16.035,0.002
165.09,152.000,0.08938,16.089,0.002
165.66,152.200,0.08971,16.145,0.002
166.19,152.400,0.09000,16.197,0.002
166.75,152.600,0.09029,16.251,0.002
167.30,152.800,0.09062,16.305,0.002
167.86,153.000,0.09091,16.360,0.002
168.44,153.200,0.09125,16.416,0.002
169.05,153.400,0.09158,16.475,0.002
169.71,153.600,0.09195,16.539,0.002
170.40,153.800,0.09233,16.607,0.002
171.16,154.000,0.09274,16.681,0.002
171.99,154.200,0.09316,16.762,0.002
172.79,154.400,0.09357,16.840,0.002
173.51,154.600,0.09399,16.910,0.002
174.23,154.800,0.09440,16.980,0.002
174.84,155.000,0.09478,17.039,0.002
175.42,155.200,0.09515,17.096,0.002
175.90,155.400,0.09548,17.143,0.002
176.36,155.600,0.09582,17.188,0.002
176.74,155.800,0.09611,17.225,0.002
177.14,156.000,0.09640,17.264,0.002
177.54,156.200,0.09669,17.302,0.002
177.92,156.400,0.09694,17.340,0.002
178.33,156.600,0.09723,17.379,0.002
178.74,156.800,0.09752,17.420,0.002
179.20,157.000,0.09777,17.465,0.002
179.67,157.200,0.09806,17.510,0.002
180.14,157.400,0.09835,17.556,0.002
180.59,157.600,0.09864,17.600,0.002
181.06,157.800,0.09893,17.646,0.002
181.51,158.000,0.09927,17.690,0.002
181.98,158.200,0.09956,17.735,0.002
182.41,158.400,0.09989,17.778,0.002
182.86,158.600,0.10018,17.822,0.002
183.29,158.800,0.10051,17.863,0.002
183.72,159.000,0.10080,17.905,0.002
184.25,159.200,0.10118,17.956,0.002
184.87,159.400,0.10155,18.017,0.002
185.48,159.600,0.10197,18.077,0.002
186.17,159.800,0.10238,18.144,0.002
186.80,160.000,0.10284,18.205,0.002
187.35,160.200,0.10326,18.259,0.002
187.80,160.400,0.10367,18.302,0.002
188.20,160.600,0.10409,18.342,0.002
188.54,160.800,0.10446,18.375,0.002
188.81,161.000,0.10479,18.401,0.002
189.04,161.200,0.10513,18.423,0.002
189.18,161.400,0.10542,18.437,0.002
189.29,161.600,0.10571,18.448,0.002
189.41,161.800,0.10600,18.460,0.002
189.51,162.000,0.10629,18.469,0.002
189.60,162.200,0.10654,18.478,0.002
189.61,162.400,0.10683,18.479,0.002
189.69,162.600,0.10708,18.487,0.002
189.77,162.800,0.10737,18.494,0.002
189.81,163.000,0.10766,18.499,0.002
189.81,163.200,0.10795,18.498,0.002
189.77,163.400,0.10828,18.495,0.002
189.63,163.600,0.10857,18.481,0.002
189.43,163.800,0.10887,18.461,0.002
189.07,164.000,0.10920,18.427,0.002
188.56,164.200,0.10953,18.377,0.002
187.94,164.400,0.10986,18.317,0.002
187.33,164.600,0.11020,18.257,0.002
186.67,164.800,0.11053,18.193,0.002
186.00,165.000,0.11090,18.128,0.002
185.41,165.200,0.11132,18.069,0.002
185.26,165.400,0.11173,18.055,0.002
185.30,165.600,0.11219,18.059,0.002
185.35,165.800,0.11261,18.064,0.002
185.38,166.000,0.11302,18.066,0.002
185.44,166.200,0.11344,18.073,0.002
185.47,166.400,0.11381,18.075,0.002
185.40,166.600,0.11418,18.069,0.002
185.30,166.800,0.11452,18.059,0.002
185.11,167.000,0.11485,18.041,0.002
184.81,167.200,0.11514,18.012,0.002
184.50,167.400,0.11547,17.981,0.002
184.07,167.600,0.11572,17.940,0.002
183.65,167.800,0.11601,17.898,0.002
183.14,168.000,0.11630,17.849,0.002
182.50,168.200,0.11655,17.786,0.002
181.12,168.400,0.11684,17.652,0.002
176.43,168.600,0.11714,17.194,0.002
171.66,168.800,0.11743,16.730,0.002
170.38,169.000,0.11776,16.605,0.002
170.01,169.200,0.11805,16.569,0.002
169.92,169.400,0.11838,16.560,0.002
169.88,169.600,0.11867,16.556,0.002
169.78,169.800,0.11901,16.547,0.002
169.59,170.000,0.11934,16.528,0.002
169.30,170.200,0.11967,16.500,0.002
168.98,170.400,0.12000,16.469,0.002
168.80,170.600,0.12038,16.451,0.002
168.71,170.800,0.12075,16.442,0.002
168.76,171.000,0.12117,16.447,0.002
168.89,171.200,0.12162,16.460,0.002
168.94,171.400,0.12204,16.464,0.002
168.97,171.600,0.12241,16.468,0.002
169.01,171.800,0.12283,16.471,0.002
169.07,172.000,0.12320,16.477,0.002
169.11,172.200,0.12358,16.481,0.002
169.14,172.400,0.12391,16.484,0.002
169.10,172.600,0.12424,16.480,0.002
169.06,172.800,0.12453,16.476,0.002
168.98,173.000,0.12482,16.468,0.002
168.91,173.200,0.12511,16.461,0.002
168.81,173.400,0.12540,16.452,0.002
168.84,173.600,0.12565,16.455,0.002
168.89,173.800,0.12594,16.460,0.002
168.97,174.000,0.12619,16.467,0.002
169.09,174.200,0.12649,16.479,0.002
169.22,174.400,0.12678,16.491,0.002
169.34,174.600,0.12707,16.504,0.003
169.50,174.800,0.12740,16.519,0.003
169.63,175.000,0.12769,16.532,0.003
169.68,175.200,0.12798,16.537,0.003
169.67,175.400,0.12831,16.536,0.003
169.67,175.600,0.12860,16.536,0.003
169.73,175.800,0.12894,16.541,0.003
169.81,176.000,0.12923,16.549,0.003
169.91,176.200,0.12960,16.559,0.003
170.11,176.400,0.12998,16.579,0.003
170.28,176.600,0.13035,16.595,0.003
170.49,176.800,0.13081,16.616,0.003
170.57,177.000,0.13122,16.624,0.003
170.46,177.200,0.13164,16.612,0.003
170.27,177.400,0.13205,16.594,0.003
169.93,177.600,0.13247,16.561,0.003
169.34,177.800,0.13284,16.504,0.003
168.50,178.000,0.13322,16.422,0.003
167.77,178.200,0.13351,16.351,0.003
167.00,178.400,0.13384,16.275,0.003
166.58,178.600,0.13409,16.234,0.003
166.38,178.800,0.13438,16.215,0.003
166.25,179.000,0.13463,16.203,0.003
166.24,179.200,0.13492,16.201,0.003
166.24,179.400,0.13517,16.201,0.003
166.32,179.600,0.13546,16.209,0.003
166.40,179.800,0.13575,16.217,0.003
166.51,180.000,0.13604,16.228,0.003
166.56,180.200,0.13633,16.233,0.003
166.60,180.400,0.13662,16.236,0.003
166.61,180.600,0.13696,16.238,0.003
166.56,180.800,0.13725,16.233,0.003
166.49,181.000,0.13758,16.226,0.003
166.36,181.200,0.13787,16.213,0.003
166.16,181.400,0.13820,16.194,0.003
165.99,181.600,0.13849,16.177,0.003
165.91,181.800,0.13887,16.169,0.003
165.89,182.000,0.13920,16.168,0.003
165.85,182.200,0.13958,16.164,0.003
165.93,182.400,0.13999,16.171,0.003
166.11,182.600,0.14045,16.189,0.003
166.23,182.800,0.14091,16.200,0.003
166.17,183.000,0.14132,16.195,0.003
165.95,183.200,0.14174,16.174,0.003
165.70,183.400,0.14211,16.149,0.003
165.42,183.600,0.14248,16.121,0.003
165.17,183.800,0.14282,16.097,0.003
165.08,184.000,0.14315,16.089,0.003
165.11,184.200,0.14344,16.091,0.003
165.17,184.400,0.14373,16.097,0.003
165.09,184.600,0.14402,16.090,0.003
165.05,184.800,0.14427,16.086,0.003
165.01,185.000,0.14456,16.081,0.003
164.94,185.200,0.14485,16.075,0.003
164.82,185.400,0.14510,16.063,0.003
164.66,185.600,0.14539,16.047,0.003
164.49,185.800,0.14568,16.031,0.003
164.37,186.000,0.14597,16.019,0.003
164.17,186.200,0.14631,15.999,0.003
163.80,186.400,0.14660,15.964,0.003
163.60,186.600,0.14693,15.944,0.003
163.60,186.800,0.14722,15.944,0.003
163.68,187.000,0.14755,15.952,0.003
163.75,187.200,0.14784,15.959,0.003
163.75,187.400,0.14818,15.958,0.003
163.62,187.600,0.14855,15.946,0.003
163.66,187.800,0.14893,15.950,0.003
163.90,188.000,0.14930,15.974,0.003
164.44,188.200,0.14976,16.026,0.003
165.14,188.400,0.15017,16.094,0.003
165.83,188.600,0.15059,16.161,0.003
166.60,188.800,0.15100,16.236,0.003
167.32,189.000,0.15142,16.306,0.003
168.01,189.200,0.15179,16.374,0.003
168.69,189.400,0.15213,16.440,0.003
169.30,189.600,0.15246,16.499,0.003
169.88,189.800,0.15275,16.556,0.003
170.45,190.000,0.15308,16.612,0.003
171.04,190.200,0.15333,16.670,0.003
171.60,190.400,0.15362,16.724,0.003
172.15,190.600,0.15391,16.777,0.003
172.70,190.800,0.15416,16.831,0.003
173.30,191.000,0.15445,16.890,0.003
173.96,191.200,0.15474,16.954,0.003
174.63,191.400,0.15503,17.019,0.003
175.27,191.600,0.15532,17.081,0.003
175.95,191.800,0.15562,17.148,0.003
176.63,192.000,0.15591,17.214,0.003
177.28,192.200,0.15624,17.278,0.003
177.93,192.400,0.15653,17.341,0.003
178.53,192.600,0.15682,17.400,0.003
179.18,192.800,0.15715,17.462,0.003
179.81,193.000,0.15749,17.524,0.003
180.54,193.200,0.15782,17.595,0.003
181.40,193.400,0.15819,17.679,0.003
182.24,193.600,0.15857,17.761,0.003
183.15,193.800,0.15898,17.850,0.003
184.11,194.000,0.15944,17.943,0.003
185.11,194.200,0.15985,18.040,0.003
186.10,194.400,0.16027,18.137,0.003
187.00,194.600,0.16069,18.225,0.003
187.88,194.800,0.16110,18.310,0.003
188.71,195.000,0.16143,18.391,0.003
189.55,195.200,0.16177,18.473,0.003
190.29,195.400,0.16210,18.545,0.003
191.00,195.600,0.16239,18.615,0.003
191.72,195.800,0.16268,18.684,0.003
192.48,196.000,0.16293,18.758,0.003
193.19,196.200,0.16322,18.828,0.003
193.90,196.400,0.16347,18.897,0.003
194.59,196.600,0.16376,18.964,0.003
195.40,196.800,0.16405,19.043,0.003
196.19,197.000,0.16434,19.120,0.003
197.06,197.200,0.16463,19.206,0.003
197.93,197.400,0.16492,19.290,0.003
198.83,197.600,0.16522,19.378,0.003
199.80,197.800,0.16555,19.472,0.003
200.70,198.000,0.16584,19.560,0.003
201.64,198.200,0.16617,19.651,0.003
202.55,198.400,0.16646,19.741,0.003
203.50,198.600,0.16679,19.833,0.003
204.52,198.800,0.16713,19.932,0.003
205.62,199.000,0.16750,20.040,0.003
206.76,199.200,0.16792,20.150,0.003
207.95,199.400,0.16829,20.266,0.003
209.21,199.600,0.16875,20.389,0.003
210.50,199.800,0.16920,20.515,0.003
211.74,200.000,0.16962,20.636,0.003
212.97,200.200,0.17004,20.755,0.003
214.18,200.400,0.17041,20.874,0.003
215.33,200.600,0.17078,20.986,0.003
216.39,200.800,0.17116,21.089,0.003
217.38,201.000,0.17149,21.186,0.003
218.32,201.200,0.17178,21.277,0.003
219.19,201.400,0.17207,21.362,0.003
220.06,201.600,0.17236,21.447,0.003
220.90,201.800,0.17265,21.529,0.003
221.74,202.000,0.17290,21.610,0.003
222.58,202.200,0.17319,21.692,0.003
223.46,202.400,0.17344,21.778,0.003
224.34,202.600,0.17373,21.864,0.003
225.28,202.800,0.17403,21.955,0.003
226.20,203.000,0.17436,22.045,0.003
227.20,203.200,0.17465,22.143,0.003
228.17,203.400,0.17498,22.237,0.003
229.13,203.600,0.17527,22.331,0.003
230.05,203.800,0.17560,22.421,0.003
50.53,204.000,0.17594,4.924,0.003
70.11,204.200,0.17627,6.833,0.003
71.74,204.400,0.17660,6.992,0.003
73.30,204.600,0.17698,7.144,0.003
74.82,204.800,0.17735,7.292,0.003
76.42,205.000,0.17777,7.448,0.003
78.09,205.200,0.17818,7.610,0.004
79.75,205.400,0.17864,7.772,0.004
81.33,205.600,0.17901,7.927,0.004
82.85,205.800,0.17943,8.075,0.004
84.31,206.000,0.17984,8.217,0.004
85.62,206.200,0.18022,8.345,0.004
86.77,206.400,0.18055,8.457,0.004
87.79,206.600,0.18088,8.556,0.004
88.67,206.800,0.18117,8.641,0.004
89.47,207.000,0.18146,8.720,0.004
90.25,207.200,0.18175,8.796,0.004
90.93,207.400,0.18205,8.862,0.004
91.61,207.600,0.18229,8.928,0.004
92.25,207.800,0.18259,8.991,0.004
92.85,208.000,0.18283,9.049,0.004
93.46,208.200,0.18313,9.108,0.004
94.00,208.400,0.18342,9.161,0.004
94.56,208.600,0.18371,9.216,0.004
95.12,208.800,0.18400,9.270,0.004
95.64,209.000,0.18429,9.321,0.004
96.16,209.200,0.18462,9.372,0.004
96.63,209.400,0.18491,9.417,0.004
97.08,209.600,0.18525,9.462,0.004
97.54,209.800,0.18554,9.506,0.004
97.92,210.000,0.18587,9.543,0.004
98.34,210.200,0.18624,9.584,0.004
98.76,210.400,0.18662,9.625,0.004
99.21,210.600,0.18699,9.669,0.004
99.58,210.800,0.18745,9.705,0.004
99.92,211.000,0.18786,9.738,0.004
100.22,211.200,0.18832,9.768,0.004
100.50,211.400,0.18874,9.795,0.004
100.67,211.600,0.18915,9.811,0.004
100.66,211.800,0.18953,9.811,0.004
100.51,212.000,0.18990,9.796,0.004
100.47,212.200,0.19019,9.791,0.004
100.58,212.400,0.19052,9.803,0.004
100.75,212.600,0.19081,9.819,0.004
100.90,212.800,0.19110,9.834,0.004
101.09,213.000,0.19135,9.852,0.004
101.32,213.200,0.19160,9.875,0.004
101.56,213.400,0.19189,9.898,0.004
101.81,213.600,0.19214,9.923,0.004
102.08,213.800,0.19243,9.949,0.004
102.38,214.000,0.19273,9.978,0.004
102.70,214.200,0.19302,10.009,0.004
103.01,214.400,0.19331,10.039,0.004
103.38,214.600,0.19360,10.075,0.004
103.71,214.800,0.19393,10.107,0.004
104.04,215.000,0.19426,10.139,0.004
104.43,215.200,0.19455,10.178,0.004
104.77,215.400,0.19489,10.211,0.004
105.11,215.600,0.19522,10.244,0.004
105.39,215.800,0.19555,10.271,0.004
105.63,216.000,0.19592,10.294,0.004
105.81,216.200,0.19630,10.313,0.004
105.98,216.400,0.19671,10.328,0.004
106.21,216.600,0.19717,10.351,0.004
106.45,216.800,0.19759,10.375,0.004
106.77,217.000,0.19800,10.405,0.004
107.08,217.200,0.19842,10.436,0.004
107.38,217.400,0.19883,10.465,0.004
107.72,217.600,0.19917,10.498,0.004
107.99,217.800,0.19954,10.524,0.004
108.24,218.000,0.19983,10.549,0.004
108.48,218.200,0.20012,10.572,0.004
108.71,218.400,0.20045,10.595,0.004
108.91,218.600,0.20070,10.614,0.004
109.09,218.800,0.20099,10.632,0.004
109.28,219.000,0.20124,10.651,0.004
109.52,219.200,0.20154,10.674,0.004
109.80,219.400,0.20178,10.701,0.004
110.10,219.600,0.20208,10.730,0.004
110.42,219.800,0.20237,10.761,0.004
110.77,220.000,0.20266,10.796,0.004
111.12,220.200,0.20295,10.829,0.004
111.18,220.230,0.20299,10.835,0.004