File: data-files/CWRU/0900-05-10D.txt
""
"Test Method","Will_Huddleston_Disks.msm"
"Sample I. D.","900-5-10D.mss"
"Specimen Number","1"

"Load (N)","Time (s)","Extension (mm)","Stress (MPa)","Strain (mm/mm)"

2.25,0.200,-0.06480,0.415,-0.001
2.28,0.300,-0.06476,0.419,-0.001
2.26,0.400,-0.06476,0.416,-0.001
2.27,0.500,-0.06476,0.418,-0.001
2.26,0.600,-0.06476,0.416,-0.001
2.27,0.700,-0.06472,0.418,-0.001
2.27,0.800,-0.06472,0.418,-0.001
2.27,0.900,-0.06467,0.419,-0.001
2.27,1.000,-0.06467,0.418,-0.001
2.28,1.100,-0.06467,0.419,-0.001
2.29,1.200,-0.06463,0.421,-0.001
2.29,1.300,-0.06463,0.422,-0.001
2.28,1.400,-0.06459,0.420,-0.001
2.28,1.500,-0.06459,0.419,-0.001
2.30,1.600,-0.06455,0.424,-0.001
2.32,1.700,-0.06451,0.428,-0.001
2.34,1.800,-0.06447,0.431,-0.001
2.37,1.900,-0.06438,0.436,-0.001
2.42,2.000,-0.06430,0.445,-0.001
2.47,2.100,-0.06422,0.454,-0.001
2.53,2.200,-0.06409,0.465,-0.001
2.59,2.300,-0.06393,0.477,-0.001
2.65,2.400,-0.06380,0.489,-0.001
2.70,2.500,-0.06368,0.497,-0.001
2.75,2.600,-0.06351,0.506,-0.001
2.78,2.700,-0.06339,0.512,-0.001
2.83,2.800,-0.06322,0.520,-0.001
2.87,2.900,-0.06310,0.529,-0.001
2.90,3.000,-0.06297,0.533,-0.001
2.94,3.100,-0.06280,0.542,-0.001
2.98,3.200,-0.06268,0.548,-0.001
3.02,3.300,-0.06251,0.556,-0.001
3.06,3.400,-0.06239,0.562,-0.001
3.09,3.500,-0.06222,0.568,-0.001
3.10,3.600,-0.06210,0.571,-0.001
3.12,3.700,-0.06193,0.575,-0.001
3.15,3.800,-0.06181,0.579,-0.001
3.17,3.900,-0.06164,0.584,-0.001
3.20,4.000,-0.06152,0.589,-0.001
3.22,4.100,-0.06135,0.593,-0.001
3.26,4.200,-0.06118,0.600,-0.001
3.27,4.300,-0.06106,0.602,-0.001
3.31,4.400,-0.06089,0.608,-0.001
3.33,4.500,-0.06073,0.612,-0.001
3.35,4.600,-0.06052,0.617,-0.001
3.37,4.700,-0.06035,0.621,-0.001
3.40,4.800,-0.06019,0.625,-0.001
3.42,4.900,-0.05998,0.630,-0.001
3.47,5.000,-0.05981,0.639,-0.001
3.48,5.100,-0.05960,0.641,-0.001
3.53,5.200,-0.05940,0.650,-0.001
3.54,5.300,-0.05919,0.652,-0.001
3.58,5.400,-0.05898,0.658,-0.001
3.61,5.500,-0.05877,0.665,-0.001
3.63,5.600,-0.05857,0.668,-0.001
3.66,5.700,-0.05836,0.674,-0.001
3.68,5.800,-0.05819,0.677,-0.001
3.72,5.900,-0.05798,0.684,-0.001
3.74,6.000,-0.05778,0.689,-0.001
3.75,6.100,-0.05761,0.690,-0.001
3.78,6.200,-0.05740,0.695,-0.001
3.81,6.300,-0.05724,0.701,-0.001
3.82,6.400,-0.05707,0.703,-0.001
3.84,6.500,-0.05690,0.707,-0.001
3.87,6.600,-0.05674,0.712,-0.001
3.87,6.700,-0.05657,0.712,-0.001
3.90,6.800,-0.05640,0.718,-0.001
3.92,6.900,-0.05628,0.722,-0.001
3.93,7.000,-0.05611,0.724,-0.001
3.95,7.100,-0.05599,0.728,-0.001
3.97,7.200,-0.05582,0.731,-0.001
3.98,7.300,-0.05570,0.732,-0.001
3.97,7.400,-0.05557,0.730,-0.001
4.00,7.500,-0.05541,0.736,-0.001
4.01,7.600,-0.05528,0.738,-0.001
4.03,7.700,-0.05516,0.743,-0.001
4.07,7.800,-0.05499,0.749,-0.001
4.06,7.900,-0.05487,0.748,-0.001
4.09,8.000,-0.05474,0.753,-0.001
4.10,8.100,-0.05462,0.755,-0.001
4.12,8.200,-0.05445,0.759,-0.001
4.13,8.300,-0.05433,0.761,-0.001
4.15,8.400,-0.05416,0.764,-0.001
4.16,8.500,-0.05404,0.765,-0.001
4.18,8.600,-0.05387,0.770,-0.001
4.19,8.700,-0.05375,0.772,-0.001
4.21,8.800,-0.05358,0.775,-0.001
4.25,8.900,-0.05345,0.782,-0.001
4.24,9.000,-0.05329,0.780,-0.001
4.27,9.100,-0.05316,0.786,-0.001
4.29,9.200,-0.05300,0.790,-0.001
4.30,9.300,-0.05283,0.792,-0.001
4.32,9.400,-0.05271,0.795,-0.001
4.34,9.500,-0.05254,0.798,-0.001
4.35,9.600,-0.05237,0.800,-0.001
4.37,9.700,-0.05225,0.805,-0.001
4.40,9.800,-0.05208,0.810,-0.001
4.41,9.900,-0.05192,0.812,-0.001
4.41,10.000,-0.05175,0.812,-0.001
4.44,10.100,-0.05158,0.817,-0.001
4.46,10.200,-0.05142,0.821,-0.001
4.47,10.300,-0.05125,0.823,-0.001
4.50,10.400,-0.05104,0.828,-0.001
4.52,10.500,-0.05088,0.832,-0.001
4.54,10.600,-0.05067,0.836,-0.001
4.56,10.700,-0.05046,0.840,-0.001
4.60,10.800,-0.05025,0.846,-0.001
4.61,10.900,-0.05005,0.848,-0.001
4.62,11.000,-0.04984,0.850,-0.001
4.65,11.100,-0.04959,0.856,-0.001
4.66,11.200,-0.04938,0.858,-0.001
4.66,11.300,-0.04917,0.859,-0.001
4.68,11.400,-0.04897,0.861,-0.001
4.70,11.500,-0.04876,0.866,-0.001
4.71,11.600,-0.04855,0.867,-0.001
4.72,11.700,-0.04834,0.870,-0.001
4.76,11.800,-0.04818,0.875,-0.001
4.76,11.900,-0.04797,0.876,-0.001
4.74,12.000,-0.04780,0.873,-0.001
4.77,12.100,-0.04764,0.878,-0.001
4.78,12.200,-0.04747,0.880,-0.001
4.79,12.300,-0.04730,0.882,-0.001
4.81,12.400,-0.04714,0.886,-0.001
4.81,12.500,-0.04697,0.886,-0.001
4.82,12.600,-0.04685,0.887,-0.001
4.84,12.700,-0.04668,0.891,-0.001
4.86,12.800,-0.04656,0.895,-0.001
4.86,12.900,-0.04639,0.895,-0.001
4.88,13.000,-0.04627,0.898,-0.001
4.89,13.100,-0.04614,0.901,-0.001
4.89,13.200,-0.04597,0.901,-0.001
4.91,13.300,-0.04585,0.903,-0.001
4.92,13.400,-0.04572,0.906,-0.001
4.94,13.500,-0.04560,0.909,-0.001
4.95,13.600,-0.04543,0.910,-0.001
4.97,13.700,-0.04531,0.914,-0.001
4.99,13.800,-0.04514,0.918,-0.001
4.99,13.900,-0.04502,0.918,-0.001
4.99,14.000,-0.04485,0.918,-0.001
5.02,14.100,-0.04473,0.924,-0.001
5.04,14.200,-0.04456,0.928,-0.001
5.04,14.300,-0.04444,0.928,-0.001
5.05,14.400,-0.04427,0.930,-0.001
5.06,14.500,-0.04410,0.932,-0.001
5.08,14.600,-0.04398,0.936,-0.001
5.10,14.700,-0.04381,0.938,-0.001
5.12,14.800,-0.04365,0.942,-0.001
5.13,14.900,-0.04348,0.944,-0.001
5.13,15.000,-0.04336,0.944,-0.001
5.15,15.100,-0.04319,0.949,-0.001
5.16,15.200,-0.04302,0.949,-0.001
5.17,15.300,-0.04286,0.952,-0.001
5.18,15.400,-0.04269,0.954,-0.001
5.20,15.500,-0.04253,0.957,-0.001
5.22,15.600,-0.04236,0.960,-0.001
5.21,15.700,-0.04219,0.959,-0.001
5.22,15.800,-0.04203,0.961,-0.001
5.20,15.900,-0.04186,0.957,-0.001
5.22,16.000,-0.04165,0.961,-0.001
5.24,16.100,-0.04144,0.965,-0.001
5.27,16.200,-0.04128,0.970,-0.001
5.28,16.300,-0.04107,0.972,-0.001
5.29,16.400,-0.04086,0.974,-0.001
5.28,16.500,-0.04066,0.972,-0.001
5.29,16.600,-0.04041,0.973,-0.001
5.30,16.700,-0.04020,0.976,-0.001
5.32,16.800,-0.03999,0.980,-0.001
5.33,16.900,-0.03978,0.982,-0.001
5.34,17.000,-0.03957,0.983,-0.001
5.35,17.100,-0.03937,0.984,-0.001
5.35,17.200,-0.03916,0.985,-0.001
5.37,17.300,-0.03895,0.988,-0.001
5.36,17.400,-0.03874,0.987,-0.001
5.39,17.500,-0.03854,0.991,-0.001
5.38,17.600,-0.03837,0.991,-0.001
5.38,17.700,-0.03820,0.990,-0.001
5.39,17.800,-0.03800,0.991,-0.001
5.41,17.900,-0.03783,0.996,-0.001
5.41,18.000,-0.03766,0.996,-0.001
5.42,18.100,-0.03754,0.997,-0.001
5.44,18.200,-0.03737,1.002,-0.001
5.42,18.300,-0.03721,0.998,-0.001
5.42,18.400,-0.03708,0.998,-0.001
5.43,18.500,-0.03692,1.000,-0.001
5.41,18.600,-0.03679,0.996,-0.001
5.42,18.700,-0.03662,0.998,-0.001
5.43,18.800,-0.03650,1.000,-0.001
5.43,18.900,-0.03633,1.000,-0.001
5.44,19.000,-0.03621,1.000,-0.001
5.44,19.100,-0.03608,1.001,-0.001
5.44,19.200,-0.03592,1.002,-0.001
5.46,19.300,-0.03579,1.006,-0.001
5.45,19.400,-0.03567,1.004,-0.001
5.48,19.500,-0.03550,1.009,-0.001
5.48,19.600,-0.03538,1.008,-0.001
5.49,19.700,-0.03521,1.010,-0.001
5.49,19.800,-0.03509,1.010,-0.001
5.50,19.900,-0.03492,1.013,-0.001
5.50,20.000,-0.03475,1.012,-0.001
5.51,20.100,-0.03463,1.015,-0.001
5.51,20.200,-0.03446,1.014,-0.001
5.51,20.300,-0.03430,1.014,-0.001
5.52,20.400,-0.03417,1.015,-0.001
5.55,20.500,-0.03401,1.022,-0.001
5.55,20.600,-0.03384,1.021,-0.001
5.55,20.700,-0.03367,1.022,-0.001
5.57,20.800,-0.03351,1.026,-0.001
5.57,20.900,-0.03334,1.026,-0.001
5.57,21.000,-0.03322,1.025,-0.001
5.57,21.100,-0.03305,1.026,-0.001
5.58,21.200,-0.03288,1.027,-0.001
5.57,21.300,-0.03272,1.026,-0.001
5.57,21.400,-0.03255,1.025,-0.001
5.58,21.500,-0.03234,1.027,-0.001
5.58,21.600,-0.03218,1.027,-0.001
5.59,21.700,-0.03197,1.029,-0.001
5.61,21.800,-0.03180,1.032,-0.001
5.61,21.900,-0.03160,1.032,-0.001
5.61,22.000,-0.03139,1.033,-0.001
5.63,22.100,-0.03118,1.037,-0.001
5.64,22.200,-0.03097,1.037,-0.001
5.65,22.300,-0.03076,1.040,-0.001
5.66,22.400,-0.03056,1.042,-0.001
5.67,22.500,-0.03035,1.044,-0.001
5.68,22.600,-0.03014,1.045,-0.001
5.70,22.700,-0.02993,1.049,-0.001
5.70,22.800,-0.02973,1.049,-0.001
5.72,22.900,-0.02952,1.053,-0.001
5.74,23.000,-0.02935,1.056,-0.001
5.75,23.100,-0.02914,1.058,-0.001
5.76,23.200,-0.02898,1.061,-0.001
5.77,23.300,-0.02877,1.062,-0.001
5.78,23.400,-0.02860,1.063,-0.001
5.78,23.500,-0.02844,1.064,-0.001
5.80,23.600,-0.02827,1.068,-0.001
5.82,23.700,-0.02811,1.071,-0.001
5.82,23.800,-0.02794,1.072,-0.001
5.85,23.900,-0.02781,1.076,-0.001
5.85,24.000,-0.02765,1.077,-0.001
5.88,24.100,-0.02748,1.083,-0.001
5.90,24.200,-0.02736,1.085,-0.001
5.91,24.300,-0.02719,1.088,-0.001
5.91,24.400,-0.02707,1.087,-0.001
5.92,24.500,-0.02694,1.089,-0.001
5.93,24.600,-0.02678,1.091,-0.001
5.95,24.700,-0.02665,1.094,-0.001
5.96,24.800,-0.02653,1.098,-0.001
5.98,24.900,-0.02636,1.100,-0.001
5.98,25.000,-0.02624,1.101,-0.001
6.01,25.100,-0.02611,1.106,-0.001
6.04,25.200,-0.02594,1.111,-0.001
6.03,25.300,-0.02582,1.111,-0.001
6.06,25.400,-0.02565,1.116,-0.001
6.09,25.500,-0.02553,1.121,-0.001
6.12,25.600,-0.02536,1.126,0.000
6.13,25.700,-0.02524,1.129,0.000
6.17,25.800,-0.02507,1.135,0.000
6.20,25.900,-0.02495,1.140,0.000
6.23,26.000,-0.02478,1.147,0.000
6.26,26.100,-0.02461,1.152,0.000
6.25,26.200,-0.02449,1.151,0.000
6.30,26.300,-0.02432,1.161,0.000
6.34,26.400,-0.02416,1.168,0.000
6.37,26.500,-0.02403,1.172,0.000
6.39,26.600,-0.02387,1.176,0.000
6.43,26.700,-0.02370,1.184,0.000
6.47,26.800,-0.02353,1.191,0.000
6.49,26.900,-0.02341,1.195,0.000
6.53,27.000,-0.02324,1.201,0.000
6.57,27.100,-0.02308,1.208,0.000
6.61,27.200,-0.02287,1.216,0.000
6.62,27.300,-0.02270,1.219,0.000
6.68,27.400,-0.02250,1.229,0.000
6.71,27.500,-0.02233,1.236,0.000
6.75,27.600,-0.02212,1.243,0.000
6.79,27.700,-0.02191,1.250,0.000
6.84,27.800,-0.02171,1.260,0.000
6.88,27.900,-0.02150,1.267,0.000
6.93,28.000,-0.02129,1.275,0.000
6.96,28.100,-0.02104,1.281,0.000
7.02,28.200,-0.02083,1.293,0.000
7.06,28.300,-0.02063,1.300,0.000
7.08,28.400,-0.02046,1.303,0.000
7.15,28.500,-0.02025,1.315,0.000
7.19,28.600,-0.02004,1.324,0.000
7.23,28.700,-0.01984,1.330,0.000
7.25,28.800,-0.01963,1.335,0.000
7.30,28.900,-0.01946,1.343,0.000
7.33,29.000,-0.01930,1.349,0.000
7.36,29.100,-0.01913,1.355,0.000
7.40,29.200,-0.01896,1.363,0.000
7.45,29.300,-0.01880,1.371,0.000
7.48,29.400,-0.01863,1.376,0.000
7.49,29.500,-0.01846,1.379,0.000
7.51,29.600,-0.01834,1.383,0.000
7.55,29.700,-0.01817,1.390,0.000
7.58,29.800,-0.01805,1.395,0.000
7.61,29.900,-0.01792,1.401,0.000
7.64,30.000,-0.01776,1.406,0.000
7.66,30.100,-0.01763,1.411,0.000
7.70,30.200,-0.01751,1.417,0.000
7.72,30.300,-0.01738,1.421,0.000
7.76,30.400,-0.01726,1.427,0.000
7.79,30.500,-0.01709,1.434,0.000
7.81,30.600,-0.01697,1.437,0.000
7.84,30.700,-0.01684,1.443,0.000
7.89,30.800,-0.01668,1.453,0.000
7.91,30.900,-0.01655,1.457,0.000
7.94,31.000,-0.01639,1.461,0.000
7.98,31.100,-0.01626,1.469,0.000
8.01,31.200,-0.01610,1.474,0.000
8.05,31.300,-0.01597,1.481,0.000
8.06,31.400,-0.01580,1.484,0.000
8.11,31.500,-0.01564,1.492,0.000
8.14,31.600,-0.01551,1.499,0.000
8.19,31.700,-0.01535,1.507,0.000
8.24,31.800,-0.01518,1.516,0.000
8.25,31.900,-0.01506,1.519,0.000
8.29,32.000,-0.01489,1.527,0.000
8.31,32.100,-0.01472,1.531,0.000
8.36,32.200,-0.01456,1.539,0.000
8.39,32.300,-0.01443,1.544,0.000
8.43,32.400,-0.01427,1.552,0.000
8.46,32.500,-0.01410,1.558,0.000
8.52,32.600,-0.01393,1.568,0.000
8.55,32.700,-0.01377,1.573,0.000
8.59,32.800,-0.01360,1.582,0.000
8.64,32.900,-0.01344,1.590,0.000
8.67,33.000,-0.01323,1.596,0.000
8.74,33.100,-0.01306,1.609,0.000
8.77,33.200,-0.01290,1.615,0.000
8.83,33.300,-0.01269,1.626,0.000
8.88,33.400,-0.01248,1.635,0.000
8.93,33.500,-0.01227,1.645,0.000
8.98,33.600,-0.01206,1.654,0.000
9.05,33.700,-0.01186,1.666,0.000
9.10,33.800,-0.01165,1.675,0.000
9.17,33.900,-0.01144,1.688,0.000
9.20,34.000,-0.01123,1.693,0.000
9.25,34.100,-0.01103,1.703,0.000
9.31,34.200,-0.01082,1.713,0.000
9.37,34.300,-0.01061,1.725,0.000
9.42,34.400,-0.01040,1.733,0.000
9.48,34.500,-0.01019,1.745,0.000
9.52,34.600,-0.01003,1.752,0.000
9.55,34.700,-0.00986,1.758,0.000
9.60,34.800,-0.00965,1.767,0.000
9.63,34.900,-0.00949,1.772,0.000
9.67,35.000,-0.00932,1.780,0.000
9.71,35.100,-0.00920,1.787,0.000
9.75,35.200,-0.00903,1.795,0.000
9.78,35.300,-0.00891,1.800,0.000
9.81,35.400,-0.00874,1.806,0.000
9.85,35.500,-0.00857,1.813,0.000
9.89,35.600,-0.00845,1.820,0.000
9.93,35.700,-0.00832,1.827,0.000
9.96,35.800,-0.00816,1.833,0.000
10.00,35.900,-0.00803,1.841,0.000
10.03,36.000,-0.00791,1.846,0.000
10.07,36.100,-0.00778,1.853,0.000
10.10,36.200,-0.00762,1.858,0.000
10.14,36.300,-0.00749,1.867,0.000
10.19,36.400,-0.00733,1.876,0.000
10.23,36.500,-0.00720,1.883,0.000
10.27,36.600,-0.00708,1.890,0.000
10.31,36.700,-0.00691,1.897,0.000
10.34,36.800,-0.00679,1.904,0.000
10.38,36.900,-0.00662,1.910,0.000
10.42,37.000,-0.00645,1.918,0.000
10.47,37.100,-0.00633,1.928,0.000
10.51,37.200,-0.00616,1.934,0.000
10.55,37.300,-0.00600,1.942,0.000
10.60,37.400,-0.00587,1.950,0.000
10.64,37.500,-0.00571,1.959,0.000
10.68,37.600,-0.00554,1.965,0.000
10.73,37.700,-0.00542,1.975,0.000
10.77,37.800,-0.00525,1.983,0.000
10.80,37.900,-0.00508,1.988,0.000
10.85,38.000,-0.00492,1.996,0.000
10.90,38.100,-0.00475,2.006,0.000
10.95,38.200,-0.00463,2.015,0.000
10.99,38.300,-0.00446,2.023,0.000
11.03,38.400,-0.00429,2.029,0.000
11.05,38.500,-0.00413,2.034,0.000
11.13,38.600,-0.00392,2.048,0.000
11.18,38.700,-0.00375,2.058,0.000
11.23,38.800,-0.00355,2.068,0.000
11.29,38.900,-0.00338,2.078,0.000
11.36,39.000,-0.00317,2.091,0.000
11.41,39.100,-0.00296,2.100,0.000
11.48,39.200,-0.00276,2.113,0.000
11.53,39.300,-0.00255,2.123,0.000
11.61,39.400,-0.00234,2.137,0.000
11.67,39.500,-0.00213,2.148,0.000
11.73,39.600,-0.00193,2.159,0.000
11.79,39.700,-0.00172,2.170,0.000
11.84,39.800,-0.00151,2.179,0.000
11.90,39.900,-0.00130,2.190,0.000
11.97,40.000,-0.00109,2.202,0.000
12.02,40.100,-0.00093,2.213,0.000
12.06,40.200,-0.00072,2.220,0.000
12.12,40.300,-0.00055,2.230,0.000
12.16,40.400,-0.00035,2.239,0.000
12.21,40.500,-0.00018,2.247,0.000
12.24,40.600,-0.00001,2.252,0.000
12.30,40.700,0.00015,2.264,0.000
12.34,40.800,0.00028,2.271,0.000
12.37,40.900,0.00044,2.276,0.000
12.42,41.000,0.00061,2.286,0.000
12.47,41.100,0.00073,2.296,0.000
12.51,41.200,0.00090,2.302,0.000
12.53,41.300,0.00103,2.306,0.000
12.57,41.400,0.00119,2.314,0.000
12.60,41.500,0.00132,2.320,0.000
12.65,41.600,0.00144,2.329,0.000
12.68,41.700,0.00157,2.335,0.000
12.72,41.800,0.00173,2.341,0.000
12.77,41.900,0.00186,2.351,0.000
12.83,42.000,0.00198,2.361,0.000
12.86,42.100,0.00215,2.367,0.000
12.90,42.200,0.00227,2.374,0.000
12.95,42.300,0.00240,2.383,0.000
13.00,42.400,0.00256,2.392,0.000
13.03,42.500,0.00269,2.398,0.000
13.08,42.600,0.00285,2.407,0.000
13.11,42.700,0.00298,2.414,0.000
13.15,42.800,0.00314,2.421,0.000
13.21,42.900,0.00327,2.432,0.000
13.26,43.000,0.00344,2.441,0.000
13.30,43.100,0.00356,2.447,0.000
13.34,43.200,0.00373,2.455,0.000
13.40,43.300,0.00389,2.467,0.000
13.45,43.400,0.00402,2.475,0.000
13.50,43.500,0.00418,2.486,0.000
13.55,43.600,0.00435,2.495,0.000
13.60,43.700,0.00452,2.502,0.000
13.64,43.800,0.00464,2.511,0.000
13.70,43.900,0.00481,2.522,0.000
13.76,44.000,0.00497,2.532,0.000
13.81,44.100,0.00514,2.541,0.000
13.85,44.200,0.00531,2.550,0.000
13.91,44.300,0.00547,2.561,0.000
13.98,44.400,0.00568,2.573,0.000
14.04,44.500,0.00585,2.585,0.000
14.11,44.600,0.00605,2.597,0.000
14.18,44.700,0.00626,2.609,0.000
14.25,44.800,0.00647,2.622,0.000
14.32,44.900,0.00668,2.636,0.000
14.38,45.000,0.00688,2.647,0.000
14.44,45.100,0.00709,2.658,0.000
14.53,45.200,0.00730,2.675,0.000
14.61,45.300,0.00751,2.689,0.000
14.67,45.400,0.00776,2.700,0.000
14.74,45.500,0.00797,2.714,0.000
14.81,45.600,0.00817,2.725,0.000
14.86,45.700,0.00834,2.736,0.000
14.93,45.800,0.00855,2.748,0.000
15.01,45.900,0.00875,2.763,0.000
15.06,46.000,0.00892,2.771,0.000
15.10,46.100,0.00913,2.780,0.000
15.18,46.200,0.00930,2.794,0.000
15.21,46.300,0.00946,2.800,0.000
15.25,46.400,0.00963,2.807,0.000
15.31,46.500,0.00979,2.818,0.000
15.34,46.600,0.00992,2.823,0.000
15.39,46.700,0.01008,2.832,0.000
15.43,46.800,0.01021,2.840,0.000
15.49,46.900,0.01038,2.850,0.000
15.53,47.000,0.01050,2.859,0.000
15.57,47.100,0.01062,2.866,0.000
15.61,47.200,0.01079,2.873,0.000
15.65,47.300,0.01092,2.881,0.000
15.69,47.400,0.01104,2.889,0.000
15.75,47.500,0.01117,2.898,0.000
15.79,47.600,0.01133,2.907,0.000
15.82,47.700,0.01146,2.912,0.000
15.88,47.800,0.01158,2.923,0.000
15.93,47.900,0.01175,2.932,0.000
15.99,48.000,0.01187,2.943,0.000
16.05,48.100,0.01204,2.954,0.000
16.10,48.200,0.01216,2.963,0.000
16.15,48.300,0.01233,2.972,0.000
16.21,48.400,0.01249,2.983,0.000
16.26,48.500,0.01262,2.993,0.000
16.31,48.600,0.01279,3.002,0.000
16.38,48.700,0.01295,3.015,0.000
16.43,48.800,0.01308,3.024,0.000
16.50,48.900,0.01324,3.037,0.000
16.54,49.000,0.01341,3.045,0.000
16.60,49.100,0.01358,3.056,0.000
16.65,49.200,0.01370,3.064,0.000
16.70,49.300,0.01387,3.074,0.000
16.77,49.400,0.01403,3.088,0.000
16.83,49.500,0.01420,3.099,0.000
16.90,49.600,0.01436,3.110,0.000
16.95,49.700,0.01453,3.121,0.000
17.03,49.800,0.01470,3.134,0.000
17.08,49.900,0.01486,3.144,0.000
17.15,50.000,0.01507,3.156,0.000
17.22,50.100,0.01524,3.169,0.000
17.29,50.200,0.01545,3.183,0.000
17.36,50.300,0.01565,3.196,0.000
17.44,50.400,0.01586,3.210,0.000
17.52,50.500,0.01607,3.225,0.000
17.58,50.600,0.01628,3.236,0.000
17.66,50.700,0.01648,3.252,0.000
17.75,50.800,0.01669,3.267,0.000
17.82,50.900,0.01690,3.280,0.000
17.89,51.000,0.01711,3.293,0.000
17.97,51.100,0.01732,3.307,0.000
18.04,51.200,0.01752,3.321,0.000
18.11,51.300,0.01773,3.333,0.000
18.18,51.400,0.01794,3.346,0.000
18.26,51.500,0.01815,3.360,0.000
18.32,51.600,0.01831,3.373,0.000
18.37,51.700,0.01852,3.382,0.000
18.46,51.800,0.01869,3.397,0.000
18.51,51.900,0.01885,3.407,0.000
18.55,52.000,0.01902,3.415,0.000
18.62,52.100,0.01919,3.428,0.000
18.68,52.200,0.01935,3.439,0.000
18.73,52.300,0.01952,3.447,0.000
18.79,52.400,0.01964,3.459,0.000
18.85,52.500,0.01981,3.469,0.000
18.89,52.600,0.01993,3.478,0.000
18.94,52.700,0.02010,3.486,0.000
19.00,52.800,0.02022,3.496,0.000
19.04,52.900,0.02035,3.504,0.000
19.09,53.000,0.02047,3.515,0.000
19.14,53.100,0.02064,3.523,0.000
19.18,53.200,0.02076,3.531,0.000
19.24,53.300,0.02089,3.542,0.000
19.31,53.400,0.02106,3.554,0.000
19.37,53.500,0.02118,3.564,0.000
19.42,53.600,0.02135,3.575,0.000
19.48,53.700,0.02147,3.585,0.000
19.54,53.800,0.02164,3.596,0.000
19.59,53.900,0.02180,3.606,0.000
19.65,54.000,0.02193,3.616,0.000
19.72,54.100,0.02209,3.630,0.000
19.77,54.200,0.02226,3.639,0.000
19.83,54.300,0.02239,3.649,0.000
19.90,54.400,0.02255,3.663,0.000
19.95,54.500,0.02272,3.673,0.000
20.01,54.600,0.02288,3.684,0.000
20.10,54.700,0.02301,3.700,0.000
20.14,54.800,0.02317,3.708,0.000
20.20,54.900,0.02334,3.719,0.000
20.26,55.000,0.02351,3.729,0.000
20.33,55.100,0.02367,3.742,0.000
20.37,55.200,0.02380,3.749,0.000
20.44,55.300,0.02396,3.763,0.000
20.52,55.400,0.02417,3.777,0.000
20.56,55.500,0.02434,3.785,0.000
20.64,55.600,0.02450,3.799,0.000
20.73,55.700,0.02467,3.815,0.000
20.79,55.800,0.02488,3.828,0.000
20.85,55.900,0.02509,3.839,0.000
20.95,56.000,0.02525,3.857,0.000
21.03,56.100,0.02546,3.871,0.001
21.11,56.200,0.02567,3.886,0.001
21.20,56.300,0.02588,3.903,0.001
21.27,56.400,0.02608,3.916,0.001
21.36,56.500,0.02629,3.932,0.001
21.44,56.600,0.02650,3.947,0.001
21.53,56.700,0.02671,3.962,0.001
21.61,56.800,0.02691,3.977,0.001
21.69,56.900,0.02712,3.992,0.001
21.77,57.000,0.02733,4.006,0.001
21.85,57.100,0.02754,4.022,0.001
21.92,57.200,0.02770,4.035,0.001
21.99,57.300,0.02791,4.048,0.001
22.04,57.400,0.02808,4.057,0.001
22.12,57.500,0.02824,4.072,0.001
22.18,57.600,0.02841,4.083,0.001
22.24,57.700,0.02858,4.093,0.001
22.29,57.800,0.02874,4.102,0.001
22.35,57.900,0.02887,4.114,0.001
22.41,58.000,0.02903,4.125,0.001
22.47,58.100,0.02916,4.136,0.001
22.53,58.200,0.02932,4.147,0.001
22.57,58.300,0.02945,4.154,0.001
22.62,58.400,0.02962,4.164,0.001
22.69,58.500,0.02974,4.177,0.001
22.73,58.600,0.02987,4.185,0.001
22.79,58.700,0.03003,4.194,0.001
22.82,58.800,0.03016,4.201,0.001
22.89,58.900,0.03028,4.213,0.001
22.92,59.000,0.03045,4.220,0.001
23.00,59.100,0.03057,4.234,0.001
23.06,59.200,0.03070,4.245,0.001
23.11,59.300,0.03086,4.253,0.001
23.17,59.400,0.03099,4.265,0.001
23.23,59.500,0.03115,4.276,0.001
23.27,59.600,0.03128,4.284,0.001
23.35,59.700,0.03144,4.298,0.001
23.39,59.800,0.03161,4.306,0.001
23.47,59.900,0.03174,4.320,0.001
23.52,60.000,0.03190,4.328,0.001
23.59,60.100,0.03203,4.342,0.001
23.65,60.200,0.03219,4.353,0.001
23.71,60.300,0.03236,4.364,0.001
23.77,60.400,0.03252,4.375,0.001
23.84,60.500,0.03265,4.388,0.001
23.88,60.600,0.03282,4.396,0.001
23.95,60.700,0.03298,4.409,0.001
24.03,60.800,0.03315,4.423,0.001
24.08,60.900,0.03327,4.433,0.001
24.16,61.000,0.03344,4.446,0.001
24.23,61.100,0.03361,4.460,0.001
24.30,61.200,0.03381,4.473,0.001
24.38,61.300,0.03398,4.488,0.001
24.47,61.400,0.03415,4.504,0.001
24.57,61.500,0.03435,4.522,0.001
24.65,61.600,0.03456,4.537,0.001
24.74,61.700,0.03477,4.553,0.001
24.84,61.800,0.03498,4.573,0.001
24.93,61.900,0.03518,4.589,0.001
25.03,62.000,0.03539,4.608,0.001
25.13,62.100,0.03560,4.625,0.001
25.22,62.200,0.03585,4.642,0.001
25.30,62.300,0.03606,4.656,0.001
25.39,62.400,0.03626,4.674,0.001
25.48,62.500,0.03647,4.690,0.001
25.56,62.600,0.03668,4.704,0.001
25.65,62.700,0.03689,4.722,0.001
25.74,62.800,0.03705,4.738,0.001
25.80,62.900,0.03726,4.748,0.001
25.86,63.000,0.03743,4.760,0.001
25.91,63.100,0.03759,4.769,0.001
25.99,63.200,0.03776,4.783,0.001
26.06,63.300,0.03793,4.796,0.001
26.11,63.400,0.03809,4.806,0.001
26.18,63.500,0.03822,4.819,0.001
26.23,63.600,0.03838,4.827,0.001
26.29,63.700,0.03851,4.838,0.001
26.35,63.800,0.03868,4.849,0.001
26.39,63.900,0.03880,4.857,0.001
26.45,64.000,0.03897,4.868,0.001
26.50,64.100,0.03909,4.878,0.001
26.55,64.200,0.03922,4.887,0.001
26.60,64.300,0.03934,4.897,0.001
26.68,64.400,0.03946,4.910,0.001
26.72,64.500,0.03963,4.918,0.001
26.76,64.600,0.03976,4.926,0.001
26.84,64.700,0.03988,4.940,0.001
26.89,64.800,0.04005,4.950,0.001
26.96,64.900,0.04017,4.962,0.001
27.02,65.000,0.04034,4.973,0.001
27.08,65.100,0.04046,4.985,0.001
27.12,65.200,0.04063,4.993,0.001
27.20,65.300,0.04075,5.007,0.001
27.28,65.400,0.04092,5.022,0.001
27.35,65.500,0.04109,5.035,0.001
27.41,65.600,0.04121,5.045,0.001
27.47,65.700,0.04138,5.056,0.001
27.53,65.800,0.04154,5.067,0.001
27.62,65.900,0.04167,5.083,0.001
27.69,66.000,0.04183,5.097,0.001
27.76,66.100,0.04200,5.109,0.001
27.82,66.200,0.04212,5.120,0.001
27.89,66.300,0.04229,5.134,0.001
27.96,66.400,0.04246,5.146,0.001
28.04,66.500,0.04262,5.161,0.001
28.11,66.600,0.04279,5.174,0.001
28.18,66.700,0.04296,5.186,0.001
28.25,66.800,0.04312,5.201,0.001
28.34,66.900,0.04329,5.217,0.001
28.42,67.000,0.04345,5.232,0.001
28.53,67.100,0.04366,5.251,0.001
28.62,67.200,0.04387,5.268,0.001
28.71,67.300,0.04404,5.284,0.001
28.81,67.400,0.04424,5.302,0.001
28.90,67.500,0.04445,5.319,0.001
29.01,67.600,0.04466,5.339,0.001
29.11,67.700,0.04491,5.359,0.001
29.20,67.800,0.04512,5.375,0.001
29.30,67.900,0.04532,5.394,0.001
29.39,68.000,0.04553,5.410,0.001
29.48,68.100,0.04574,5.426,0.001
29.57,68.200,0.04595,5.443,0.001
29.65,68.300,0.04611,5.458,0.001
29.74,68.400,0.04632,5.475,0.001
29.83,68.500,0.04653,5.491,0.001
29.92,68.600,0.04670,5.508,0.001
29.98,68.700,0.04690,5.519,0.001
30.05,68.800,0.04707,5.532,0.001
30.12,68.900,0.04724,5.544,0.001
30.19,69.000,0.04740,5.557,0.001
30.27,69.100,0.04753,5.571,0.001
30.32,69.200,0.04769,5.581,0.001
30.38,69.300,0.04786,5.592,0.001
30.46,69.400,0.04798,5.606,0.001
30.51,69.500,0.04815,5.616,0.001
30.58,69.600,0.04827,5.628,0.001
30.64,69.700,0.04844,5.640,0.001
30.70,69.800,0.04857,5.650,0.001
30.74,69.900,0.04869,5.657,0.001
30.82,70.000,0.04881,5.672,0.001
30.86,70.100,0.04898,5.681,0.001
30.92,70.200,0.04911,5.691,0.001
30.98,70.300,0.04923,5.702,0.001
31.04,70.400,0.04935,5.714,0.001
31.12,70.500,0.04952,5.729,0.001
31.20,70.600,0.04965,5.743,0.001
31.26,70.700,0.04981,5.755,0.001
31.33,70.800,0.04994,5.768,0.001
31.41,70.900,0.05010,5.781,0.001
31.48,71.000,0.05023,5.794,0.001
31.55,71.100,0.05039,5.808,0.001
31.62,71.200,0.05052,5.821,0.001
31.70,71.300,0.05068,5.835,0.001
31.77,71.400,0.05085,5.847,0.001
31.84,71.500,0.05098,5.860,0.001
31.92,71.600,0.05114,5.876,0.001
32.01,71.700,0.05131,5.892,0.001
32.06,71.800,0.05143,5.901,0.001
32.14,71.900,0.05160,5.917,0.001
32.22,72.000,0.05177,5.930,0.001
32.29,72.100,0.05189,5.944,0.001
32.38,72.200,0.05206,5.959,0.001
32.45,72.300,0.05222,5.973,0.001
32.54,72.400,0.05239,5.990,0.001
32.62,72.500,0.05255,6.004,0.001
32.72,72.600,0.05272,6.023,0.001
32.80,72.700,0.05293,6.038,0.001
32.92,72.800,0.05309,6.059,0.001
32.99,72.900,0.05330,6.073,0.001
33.11,73.000,0.05347,6.094,0.001
33.20,73.100,0.05368,6.111,0.001
33.30,73.200,0.05388,6.129,0.001
33.39,73.300,0.05409,6.147,0.001
33.51,73.400,0.05430,6.168,0.001
33.63,73.500,0.05451,6.190,0.001
33.72,73.600,0.05472,6.207,0.001
33.82,73.700,0.05492,6.226,0.001
33.94,73.800,0.05509,6.247,0.001
34.03,73.900,0.05530,6.263,0.001
34.13,74.000,0.05551,6.282,0.001
34.21,74.100,0.05571,6.298,0.001
34.32,74.200,0.05588,6.317,0.001
34.42,74.300,0.05609,6.336,0.001
34.50,74.400,0.05625,6.350,0.001
34.58,74.500,0.05646,6.365,0.001
34.66,74.600,0.05663,6.380,0.001
34.74,74.700,0.05679,6.394,0.001
34.81,74.800,0.05696,6.407,0.001
34.90,74.900,0.05708,6.425,0.001
34.96,75.000,0.05725,6.435,0.001
35.04,75.100,0.05742,6.450,0.001
35.11,75.200,0.05754,6.463,0.001
35.20,75.300,0.05771,6.479,0.001
35.26,75.400,0.05783,6.490,0.001
35.33,75.500,0.05796,6.503,0.001
35.40,75.600,0.05812,6.516,0.001
35.47,75.700,0.05825,6.529,0.001
35.53,75.800,0.05837,6.540,0.001
35.60,75.900,0.05850,6.552,0.001
35.68,76.000,0.05866,6.568,0.001
35.75,76.100,0.05879,6.581,0.001
35.83,76.200,0.05891,6.595,0.001
35.91,76.300,0.05908,6.610,0.001
35.98,76.400,0.05920,6.622,0.001
36.06,76.500,0.05933,6.638,0.001
36.15,76.600,0.05949,6.653,0.001
36.22,76.700,0.05966,6.668,0.001
36.31,76.800,0.05979,6.683,0.001
36.40,76.900,0.05995,6.700,0.001
36.47,77.000,0.06008,6.713,0.001
36.56,77.100,0.06024,6.729,0.001
36.65,77.200,0.06037,6.746,0.001
36.72,77.300,0.06053,6.759,0.001
36.80,77.400,0.06070,6.773,0.001
36.88,77.500,0.06082,6.789,0.001
36.96,77.600,0.06099,6.804,0.001
37.05,77.700,0.06116,6.819,0.001
37.12,77.800,0.06128,6.833,0.001
37.23,77.900,0.06145,6.852,0.001
37.29,78.000,0.06161,6.865,0.001
37.39,78.100,0.06178,6.882,0.001
37.48,78.200,0.06195,6.899,0.001
37.57,78.300,0.06211,6.915,0.001
37.67,78.400,0.06228,6.934,0.001
37.76,78.500,0.06244,6.950,0.001
37.90,78.600,0.06265,6.976,0.001
38.00,78.700,0.06282,6.994,0.001
38.13,78.800,0.06303,7.018,0.001
38.25,78.900,0.06323,7.041,0.001
38.37,79.000,0.06344,7.062,0.001
38.50,79.100,0.06369,7.086,0.001
38.61,79.200,0.06390,7.107,0.001
38.73,79.300,0.06411,7.129,0.001
38.85,79.400,0.06432,7.152,0.001
38.98,79.500,0.06452,7.175,0.001
39.10,79.600,0.06473,7.198,0.001
39.23,79.700,0.06494,7.220,0.001
39.33,79.800,0.06515,7.239,0.001
39.46,79.900,0.06535,7.264,0.001
39.54,80.000,0.06552,7.278,0.001
39.66,80.100,0.06573,7.300,0.001
39.74,80.200,0.06589,7.315,0.001
39.82,80.300,0.06606,7.329,0.001
39.90,80.400,0.06623,7.344,0.001
40.00,80.500,0.06639,7.363,0.001
40.06,80.600,0.06652,7.374,0.001
40.14,80.700,0.06668,7.389,0.001
40.23,80.800,0.06681,7.405,0.001
40.31,80.900,0.06697,7.419,0.001
40.38,81.000,0.06710,7.433,0.001
40.46,81.100,0.06727,7.447,0.001
40.55,81.200,0.06739,7.464,0.001
40.61,81.300,0.06751,7.474,0.001
40.69,81.400,0.06764,7.489,0.001
40.76,81.500,0.06776,7.503,0.001
40.84,81.600,0.06793,7.517,0.001
40.92,81.700,0.06806,7.531,0.001
41.01,81.800,0.06818,7.549,0.001
41.09,81.900,0.06835,7.564,0.001
41.18,82.000,0.06847,7.579,0.001
41.26,82.100,0.06864,7.595,0.001
41.35,82.200,0.06876,7.612,0.001
41.46,82.300,0.06893,7.631,0.001
41.54,82.400,0.06905,7.646,0.001
41.63,82.500,0.06922,7.663,0.001
41.71,82.600,0.06938,7.678,0.001
41.81,82.700,0.06951,7.696,0.001
41.89,82.800,0.06968,7.711,0.001
41.99,82.900,0.06984,7.730,0.001
42.09,83.000,0.06997,7.747,0.001
42.18,83.100,0.07013,7.763,0.001
42.27,83.200,0.07030,7.780,0.001
42.37,83.300,0.07047,7.798,0.001
42.46,83.400,0.07059,7.816,0.001
42.54,83.500,0.07076,7.831,0.001
42.65,83.600,0.07092,7.850,0.001
42.74,83.700,0.07109,7.866,0.001
42.86,83.800,0.07125,7.888,0.001
42.96,83.900,0.07142,7.907,0.001
43.06,84.000,0.07163,7.927,0.001
43.19,84.100,0.07180,7.950,0.001
43.32,84.200,0.07200,7.973,0.001
43.45,84.300,0.07217,7.997,0.001
43.58,84.400,0.07238,8.022,0.001
43.72,84.500,0.07258,8.047,0.001
43.85,84.600,0.07279,8.071,0.001
43.98,84.700,0.07300,8.095,0.001
44.13,84.800,0.07325,8.124,0.001
44.26,84.900,0.07346,8.146,0.001
44.40,85.000,0.07367,8.172,0.001
44.54,85.100,0.07387,8.198,0.001
44.67,85.200,0.07408,8.222,0.001
44.79,85.300,0.07429,8.245,0.001
44.92,85.400,0.07450,8.269,0.001
45.05,85.500,0.07470,8.292,0.001
45.17,85.600,0.07491,8.313,0.001
45.28,85.700,0.07508,8.334,0.001
45.40,85.800,0.07529,8.356,0.001
45.49,85.900,0.07545,8.374,0.001
45.60,86.000,0.07562,8.394,0.001
45.69,86.100,0.07578,8.409,0.001
45.79,86.200,0.07595,8.428,0.001
45.87,86.300,0.07608,8.444,0.001
45.95,86.400,0.07624,8.458,0.002
46.05,86.500,0.07641,8.477,0.002
46.13,86.600,0.07653,8.491,0.002
46.22,86.700,0.07670,8.508,0.002
46.30,86.800,0.07682,8.522,0.002
46.39,86.900,0.07695,8.539,0.002
46.47,87.000,0.07711,8.553,0.002
46.56,87.100,0.07724,8.570,0.002
46.65,87.200,0.07736,8.587,0.002
46.75,87.300,0.07753,8.604,0.002
46.82,87.400,0.07765,8.618,0.002
46.91,87.500,0.07782,8.635,0.002
47.02,87.600,0.07795,8.654,0.002
47.10,87.700,0.07811,8.669,0.002
47.21,87.800,0.07824,8.690,0.002
47.32,87.900,0.07840,8.710,0.002
47.42,88.000,0.07857,8.729,0.002
47.52,88.100,0.07869,8.747,0.002
47.62,88.200,0.07886,8.766,0.002
47.57,88.300,0.07903,8.756,0.002
8.02,88.400,0.07915,1.476,0.002
9.71,88.500,0.07932,1.788,0.002
10.08,88.600,0.07948,1.855,0.002
10.19,88.700,0.07965,1.876,0.002
10.27,88.800,0.07982,1.890,0.002
10.37,88.900,0.07994,1.909,0.002
10.43,89.000,0.08011,1.920,0.002
10.51,89.100,0.08027,1.935,0.002
10.60,89.200,0.08044,1.952,0.002
10.69,89.300,0.08060,1.967,0.002
10.76,89.400,0.08077,1.981,0.002
10.85,89.500,0.08094,1.997,0.002
10.93,89.600,0.08110,2.012,0.002
11.01,89.700,0.08131,2.027,0.002
11.11,89.800,0.08148,2.045,0.002
11.20,89.900,0.08169,2.061,0.002
11.28,90.000,0.08189,2.077,0.002
11.37,90.100,0.08206,2.093,0.002
11.47,90.200,0.08231,2.111,0.002
11.56,90.300,0.08252,2.127,0.002
11.63,90.400,0.08272,2.140,0.002
11.70,90.500,0.08293,2.154,0.002
11.79,90.600,0.08314,2.170,0.002
11.85,90.700,0.08335,2.182,0.002
11.86,90.720,0.08339,2.183,0.002