File: data-files/CWRU/0900-05-50D.txt
""
"Test Method","Will_Huddleston_Disks.msm"
"Sample I. D.","900-5-50D.mss"
"Specimen Number","1"

"Load (N)","Time (s)","Extension (mm)","Stress (MPa)","Strain (mm/mm)"

2.93,0.200,-0.22653,0.252,-0.004
2.93,0.500,-0.22653,0.253,-0.004
2.93,0.800,-0.22653,0.253,-0.004
2.92,1.100,-0.22653,0.252,-0.004
2.92,1.400,-0.22649,0.252,-0.004
2.92,1.700,-0.22649,0.252,-0.004
2.93,2.000,-0.22645,0.253,-0.004
2.93,2.300,-0.22645,0.253,-0.004
2.93,2.600,-0.22641,0.253,-0.004
2.92,2.900,-0.22641,0.252,-0.004
2.93,3.200,-0.22636,0.253,-0.004
2.93,3.500,-0.22632,0.253,-0.004
2.95,3.800,-0.22632,0.255,-0.004
2.97,4.100,-0.22628,0.256,-0.004
2.99,4.400,-0.22620,0.258,-0.004
3.06,4.700,-0.22612,0.264,-0.004
3.11,5.000,-0.22599,0.268,-0.004
3.22,5.300,-0.22582,0.277,-0.004
3.31,5.600,-0.22562,0.286,-0.004
3.41,5.900,-0.22537,0.294,-0.004
3.49,6.200,-0.22516,0.301,-0.004
3.57,6.500,-0.22491,0.308,-0.004
3.62,6.800,-0.22470,0.312,-0.004
3.69,7.100,-0.22445,0.318,-0.004
3.77,7.400,-0.22420,0.325,-0.004
3.82,7.700,-0.22395,0.329,-0.004
3.87,8.000,-0.22366,0.334,-0.004
3.94,8.300,-0.22337,0.340,-0.004
4.00,8.600,-0.22308,0.345,-0.004
4.06,8.900,-0.22275,0.350,-0.004
4.11,9.200,-0.22246,0.354,-0.004
4.16,9.500,-0.22217,0.359,-0.004
4.22,9.800,-0.22188,0.364,-0.004
4.27,10.100,-0.22159,0.369,-0.004
4.33,10.400,-0.22134,0.373,-0.004
4.36,10.700,-0.22105,0.377,-0.004
4.40,11.000,-0.22080,0.379,-0.004
4.42,11.300,-0.22055,0.382,-0.004
4.45,11.600,-0.22034,0.384,-0.004
4.47,11.900,-0.22013,0.385,-0.004
4.50,12.200,-0.21988,0.388,-0.004
4.53,12.500,-0.21967,0.391,-0.004
4.54,12.800,-0.21947,0.392,-0.004
4.58,13.100,-0.21930,0.395,-0.004
4.60,13.400,-0.21909,0.397,-0.004
4.62,13.700,-0.21888,0.398,-0.004
4.65,14.000,-0.21868,0.401,-0.004
4.69,14.300,-0.21847,0.404,-0.004
4.74,14.600,-0.21826,0.409,-0.004
4.78,14.900,-0.21805,0.412,-0.004
4.80,15.200,-0.21785,0.414,-0.004
4.83,15.500,-0.21764,0.417,-0.004
4.88,15.800,-0.21739,0.421,-0.004
4.91,16.100,-0.21718,0.423,-0.004
4.92,16.400,-0.21693,0.425,-0.004
4.96,16.700,-0.21672,0.428,-0.004
5.00,17.000,-0.21647,0.431,-0.004
5.03,17.300,-0.21623,0.434,-0.004
5.08,17.600,-0.21602,0.438,-0.004
5.12,17.900,-0.21577,0.442,-0.004
5.18,18.200,-0.21552,0.447,-0.004
5.21,18.500,-0.21527,0.449,-0.004
5.25,18.800,-0.21498,0.453,-0.004
5.31,19.100,-0.21469,0.458,-0.004
5.34,19.400,-0.21444,0.460,-0.004
5.42,19.700,-0.21411,0.467,-0.004
5.48,20.000,-0.21381,0.472,-0.004
5.51,20.300,-0.21348,0.475,-0.004
5.57,20.600,-0.21315,0.480,-0.004
5.62,20.900,-0.21286,0.485,-0.004
5.67,21.200,-0.21253,0.489,-0.004
5.71,21.500,-0.21224,0.493,-0.004
5.77,21.800,-0.21194,0.497,-0.004
5.79,22.100,-0.21165,0.500,-0.004
5.85,22.400,-0.21140,0.504,-0.004
5.87,22.700,-0.21116,0.506,-0.004
5.92,23.000,-0.21095,0.510,-0.004
5.94,23.300,-0.21074,0.512,-0.004
5.97,23.600,-0.21049,0.515,-0.004
6.00,23.900,-0.21028,0.517,-0.004
6.04,24.200,-0.21007,0.521,-0.004
6.07,24.500,-0.20987,0.524,-0.004
6.09,24.800,-0.20966,0.525,-0.004
6.12,25.100,-0.20945,0.528,-0.004
6.16,25.400,-0.20929,0.532,-0.004
6.18,25.700,-0.20908,0.534,-0.004
6.22,26.000,-0.20887,0.536,-0.004
6.23,26.300,-0.20866,0.538,-0.004
6.28,26.600,-0.20841,0.542,-0.004
6.32,26.900,-0.20820,0.546,-0.004
6.36,27.200,-0.20796,0.549,-0.004
6.38,27.500,-0.20775,0.550,-0.004
6.40,27.800,-0.20754,0.552,-0.004
6.44,28.100,-0.20729,0.556,-0.004
6.48,28.400,-0.20708,0.559,-0.004
6.51,28.700,-0.20683,0.561,-0.004
6.56,29.000,-0.20658,0.566,-0.004
6.58,29.300,-0.20633,0.568,-0.004
6.62,29.600,-0.20609,0.571,-0.004
6.65,29.900,-0.20584,0.574,-0.004
6.68,30.200,-0.20559,0.576,-0.004
6.74,30.500,-0.20534,0.581,-0.004
6.79,30.800,-0.20505,0.585,-0.004
6.83,31.100,-0.20476,0.589,-0.004
6.88,31.400,-0.20442,0.593,-0.004
6.93,31.700,-0.20413,0.598,-0.004
6.98,32.000,-0.20380,0.602,-0.004
7.01,32.300,-0.20351,0.605,-0.004
7.07,32.600,-0.20318,0.610,-0.004
7.12,32.900,-0.20289,0.614,-0.004
7.13,33.200,-0.20259,0.615,-0.004
7.19,33.500,-0.20230,0.620,-0.004
7.22,33.800,-0.20205,0.623,-0.004
7.26,34.100,-0.20181,0.626,-0.004
7.29,34.400,-0.20156,0.629,-0.004
7.31,34.700,-0.20135,0.630,-0.004
7.35,35.000,-0.20110,0.634,-0.004
7.39,35.300,-0.20089,0.637,-0.004
7.42,35.600,-0.20068,0.640,-0.004
7.44,35.900,-0.20048,0.642,-0.004
7.46,36.200,-0.20027,0.644,-0.004
7.50,36.500,-0.20006,0.647,-0.004
7.53,36.800,-0.19985,0.650,-0.004
7.56,37.100,-0.19964,0.652,-0.004
7.59,37.400,-0.19944,0.654,-0.004
7.63,37.700,-0.19923,0.658,-0.004
7.66,38.000,-0.19902,0.661,-0.004
7.69,38.300,-0.19881,0.663,-0.004
7.74,38.600,-0.19856,0.667,-0.004
7.79,38.900,-0.19836,0.672,-0.004
7.81,39.200,-0.19815,0.674,-0.004
7.84,39.500,-0.19790,0.677,-0.004
7.88,39.800,-0.19769,0.680,-0.004
7.95,40.100,-0.19744,0.686,-0.004
7.97,40.400,-0.19719,0.688,-0.004
8.00,40.700,-0.19698,0.691,-0.004
8.05,41.000,-0.19674,0.695,-0.004
8.08,41.300,-0.19649,0.697,-0.004
8.13,41.600,-0.19620,0.701,-0.004
8.18,41.900,-0.19595,0.706,-0.004
8.22,42.200,-0.19565,0.709,-0.004
8.26,42.500,-0.19536,0.712,-0.004
8.30,42.800,-0.19507,0.716,-0.004
8.35,43.100,-0.19474,0.721,-0.004
8.41,43.400,-0.19441,0.726,-0.004
8.44,43.700,-0.19408,0.728,-0.004
8.49,44.000,-0.19378,0.733,-0.004
8.52,44.300,-0.19349,0.735,-0.004
8.57,44.600,-0.19316,0.739,-0.004
8.61,44.900,-0.19287,0.743,-0.004
8.64,45.200,-0.19262,0.746,-0.004
8.68,45.500,-0.19237,0.748,-0.004
8.73,45.800,-0.19212,0.753,-0.004
8.74,46.100,-0.19187,0.754,-0.004
8.78,46.400,-0.19167,0.758,-0.004
8.80,46.700,-0.19146,0.759,-0.004
8.83,47.000,-0.19121,0.762,-0.004
8.89,47.300,-0.19100,0.767,-0.004
8.89,47.600,-0.19083,0.767,-0.004
8.93,47.900,-0.19063,0.771,-0.004
8.96,48.200,-0.19042,0.773,-0.004
8.99,48.500,-0.19021,0.775,-0.004
9.04,48.800,-0.19000,0.780,-0.004
9.07,49.100,-0.18980,0.782,-0.004
9.09,49.400,-0.18959,0.784,-0.004
9.13,49.700,-0.18938,0.788,-0.004
9.16,50.000,-0.18913,0.790,-0.004
9.20,50.300,-0.18888,0.794,-0.004
9.23,50.600,-0.18867,0.797,-0.004
9.28,50.900,-0.18842,0.801,-0.004
9.31,51.200,-0.18817,0.803,-0.004
9.34,51.500,-0.18793,0.806,-0.004
9.38,51.800,-0.18768,0.810,-0.004
9.44,52.100,-0.18743,0.814,-0.004
9.48,52.400,-0.18718,0.818,-0.004
9.53,52.700,-0.18693,0.822,-0.004
9.57,53.000,-0.18668,0.826,-0.004
9.61,53.300,-0.18639,0.829,-0.004
9.66,53.600,-0.18610,0.834,-0.004
9.72,53.900,-0.18576,0.838,-0.004
9.78,54.200,-0.18547,0.844,-0.004
9.84,54.500,-0.18514,0.849,-0.004
9.87,54.800,-0.18485,0.851,-0.004
9.92,55.100,-0.18452,0.856,-0.004
9.97,55.400,-0.18419,0.860,-0.004
10.02,55.700,-0.18389,0.865,-0.004
10.06,56.000,-0.18360,0.868,-0.004
10.11,56.300,-0.18331,0.872,-0.004
10.15,56.600,-0.18306,0.876,-0.004
10.18,56.900,-0.18277,0.878,-0.004
10.20,57.200,-0.18256,0.880,-0.004
10.25,57.500,-0.18232,0.884,-0.004
10.29,57.800,-0.18207,0.888,-0.004
10.32,58.100,-0.18186,0.890,-0.004
10.34,58.400,-0.18165,0.892,-0.004
10.38,58.700,-0.18144,0.896,-0.004
10.41,59.000,-0.18124,0.898,-0.004
10.44,59.300,-0.18103,0.901,-0.004
10.48,59.600,-0.18082,0.904,-0.004
10.53,59.900,-0.18061,0.908,-0.004
10.59,60.200,-0.18040,0.913,-0.004
10.62,60.500,-0.18020,0.916,-0.004
10.66,60.800,-0.17995,0.920,-0.004
10.71,61.100,-0.17974,0.924,-0.004
10.76,61.400,-0.17949,0.928,-0.004
10.80,61.700,-0.17928,0.932,-0.004
10.85,62.000,-0.17903,0.936,-0.004
10.88,62.300,-0.17878,0.939,-0.004
10.91,62.600,-0.17858,0.941,-0.004
10.95,62.900,-0.17833,0.944,-0.004
11.01,63.200,-0.17808,0.950,-0.004
11.04,63.500,-0.17783,0.953,-0.004
11.10,63.800,-0.17758,0.958,-0.003
11.13,64.100,-0.17733,0.960,-0.003
11.21,64.400,-0.17704,0.967,-0.003
11.26,64.700,-0.17675,0.971,-0.003
11.32,65.000,-0.17646,0.977,-0.003
11.39,65.300,-0.17617,0.982,-0.003
11.44,65.600,-0.17583,0.987,-0.003
11.49,65.900,-0.17550,0.992,-0.003
11.56,66.200,-0.17517,0.997,-0.003
11.63,66.500,-0.17484,1.003,-0.003
11.68,66.800,-0.17454,1.007,-0.003
11.74,67.100,-0.17425,1.013,-0.003
11.76,67.400,-0.17396,1.014,-0.003
11.82,67.700,-0.17367,1.019,-0.003
11.85,68.000,-0.17342,1.023,-0.003
11.89,68.300,-0.17317,1.026,-0.003
11.93,68.600,-0.17297,1.029,-0.003
11.96,68.900,-0.17272,1.032,-0.003
12.01,69.200,-0.17251,1.036,-0.003
12.03,69.500,-0.17230,1.038,-0.003
12.07,69.800,-0.17209,1.041,-0.003
12.10,70.100,-0.17188,1.044,-0.003
12.13,70.400,-0.17168,1.047,-0.003
12.17,70.700,-0.17147,1.050,-0.003
12.22,71.000,-0.17126,1.054,-0.003
12.25,71.300,-0.17105,1.057,-0.003
12.32,71.600,-0.17085,1.063,-0.003
12.34,71.900,-0.17064,1.065,-0.003
12.40,72.200,-0.17043,1.070,-0.003
12.44,72.500,-0.17018,1.073,-0.003
12.48,72.800,-0.16997,1.077,-0.003
12.51,73.100,-0.16972,1.079,-0.003
12.57,73.400,-0.16952,1.084,-0.003
12.63,73.700,-0.16927,1.090,-0.003
12.66,74.000,-0.16902,1.092,-0.003
12.72,74.300,-0.16881,1.097,-0.003
12.76,74.600,-0.16856,1.101,-0.003
12.80,74.900,-0.16831,1.104,-0.003
12.88,75.200,-0.16806,1.111,-0.003
12.95,75.500,-0.16777,1.117,-0.003
13.01,75.800,-0.16752,1.122,-0.003
13.07,76.100,-0.16723,1.127,-0.003
13.13,76.400,-0.16694,1.133,-0.003
13.21,76.700,-0.16661,1.140,-0.003
13.29,77.000,-0.16627,1.147,-0.003
13.36,77.300,-0.16594,1.152,-0.003
13.43,77.600,-0.16565,1.159,-0.003
13.50,77.900,-0.16532,1.164,-0.003
13.55,78.200,-0.16503,1.169,-0.003
13.61,78.500,-0.16474,1.174,-0.003
13.68,78.800,-0.16445,1.180,-0.003
13.72,79.100,-0.16420,1.183,-0.003
13.75,79.400,-0.16395,1.186,-0.003
13.80,79.700,-0.16370,1.190,-0.003
13.85,80.000,-0.16349,1.195,-0.003
13.88,80.300,-0.16328,1.197,-0.003
13.93,80.600,-0.16303,1.201,-0.003
13.96,80.900,-0.16283,1.205,-0.003
14.01,81.200,-0.16262,1.209,-0.003
14.03,81.500,-0.16245,1.211,-0.003
14.08,81.800,-0.16224,1.215,-0.003
14.13,82.100,-0.16204,1.219,-0.003
14.18,82.400,-0.16183,1.223,-0.003
14.23,82.700,-0.16162,1.228,-0.003
14.28,83.000,-0.16141,1.232,-0.003
14.33,83.300,-0.16121,1.236,-0.003
14.39,83.600,-0.16096,1.241,-0.003
14.44,83.900,-0.16075,1.245,-0.003
14.49,84.200,-0.16050,1.250,-0.003
14.55,84.500,-0.16029,1.256,-0.003
14.61,84.800,-0.16004,1.261,-0.003
14.66,85.100,-0.15983,1.264,-0.003
14.73,85.400,-0.15958,1.271,-0.003
14.79,85.700,-0.15934,1.276,-0.003
14.84,86.000,-0.15909,1.280,-0.003
14.90,86.300,-0.15884,1.286,-0.003
14.97,86.600,-0.15859,1.291,-0.003
15.04,86.900,-0.15834,1.298,-0.003
15.12,87.200,-0.15805,1.304,-0.003
15.20,87.500,-0.15776,1.311,-0.003
15.27,87.800,-0.15747,1.317,-0.003
15.35,88.100,-0.15713,1.324,-0.003
15.44,88.400,-0.15680,1.332,-0.003
15.52,88.700,-0.15647,1.339,-0.003
15.59,89.000,-0.15614,1.345,-0.003
15.67,89.300,-0.15584,1.351,-0.003
15.74,89.600,-0.15555,1.358,-0.003
15.80,89.900,-0.15526,1.363,-0.003
15.87,90.200,-0.15497,1.369,-0.003
15.91,90.500,-0.15472,1.373,-0.003
15.96,90.800,-0.15447,1.377,-0.003
16.02,91.100,-0.15422,1.382,-0.003
16.07,91.400,-0.15397,1.386,-0.003
16.14,91.700,-0.15377,1.392,-0.003
16.18,92.000,-0.15356,1.395,-0.003
16.24,92.300,-0.15335,1.401,-0.003
16.29,92.600,-0.15310,1.405,-0.003
16.35,92.900,-0.15294,1.410,-0.003
16.37,93.200,-0.15273,1.412,-0.003
16.45,93.500,-0.15252,1.419,-0.003
16.48,93.800,-0.15231,1.422,-0.003
16.53,94.100,-0.15210,1.426,-0.003
16.61,94.400,-0.15190,1.433,-0.003
16.66,94.700,-0.15165,1.438,-0.003
16.75,95.000,-0.15144,1.445,-0.003
16.81,95.300,-0.15119,1.450,-0.003
16.87,95.600,-0.15098,1.455,-0.003
16.93,95.900,-0.15073,1.461,-0.003
17.00,96.200,-0.15053,1.467,-0.003
17.06,96.500,-0.15028,1.471,-0.003
17.14,96.800,-0.15003,1.479,-0.003
17.21,97.100,-0.14982,1.485,-0.003
17.28,97.400,-0.14957,1.490,-0.003
17.35,97.700,-0.14932,1.497,-0.003
17.42,98.000,-0.14907,1.503,-0.003
17.50,98.300,-0.14878,1.510,-0.003
17.60,98.600,-0.14853,1.518,-0.003
17.67,98.900,-0.14824,1.525,-0.003
17.77,99.200,-0.14795,1.533,-0.003
17.87,99.500,-0.14762,1.541,-0.003
17.98,99.800,-0.14733,1.551,-0.003
18.07,100.100,-0.14699,1.559,-0.003
18.16,100.400,-0.14670,1.567,-0.003
18.24,100.700,-0.14641,1.573,-0.003
18.34,101.000,-0.14608,1.582,-0.003
18.41,101.300,-0.14579,1.588,-0.003
18.48,101.600,-0.14554,1.595,-0.003
18.57,101.900,-0.14525,1.602,-0.003
18.62,102.200,-0.14500,1.606,-0.003
18.67,102.500,-0.14475,1.610,-0.003
18.75,102.800,-0.14454,1.617,-0.003
18.81,103.100,-0.14429,1.623,-0.003
18.86,103.400,-0.14408,1.627,-0.003
18.93,103.700,-0.14388,1.633,-0.003
18.98,104.000,-0.14367,1.638,-0.003
19.04,104.300,-0.14346,1.643,-0.003
19.11,104.600,-0.14329,1.649,-0.003
19.18,104.900,-0.14309,1.654,-0.003
19.25,105.200,-0.14288,1.660,-0.003
19.32,105.500,-0.14267,1.667,-0.003
19.39,105.800,-0.14246,1.672,-0.003
19.46,106.100,-0.14226,1.679,-0.003
19.55,106.400,-0.14205,1.686,-0.003
19.63,106.700,-0.14180,1.693,-0.003
19.71,107.000,-0.14159,1.700,-0.003
19.77,107.300,-0.14138,1.706,-0.003
19.85,107.600,-0.14113,1.712,-0.003
19.92,107.900,-0.14088,1.719,-0.003
20.01,108.200,-0.14068,1.726,-0.003
20.10,108.500,-0.14043,1.734,-0.003
20.17,108.800,-0.14018,1.740,-0.003
20.26,109.100,-0.13997,1.748,-0.003
20.34,109.400,-0.13972,1.755,-0.003
20.44,109.700,-0.13943,1.763,-0.003
20.55,110.000,-0.13918,1.773,-0.003
20.65,110.300,-0.13889,1.781,-0.003
20.76,110.600,-0.13860,1.791,-0.003
20.88,110.900,-0.13827,1.801,-0.003
21.00,111.200,-0.13793,1.812,-0.003
21.13,111.500,-0.13760,1.822,-0.003
21.24,111.800,-0.13731,1.832,-0.003
21.35,112.100,-0.13698,1.842,-0.003
21.48,112.400,-0.13669,1.853,-0.003
21.56,112.700,-0.13635,1.860,-0.003
21.67,113.000,-0.13606,1.870,-0.003
21.74,113.300,-0.13581,1.876,-0.003
21.83,113.600,-0.13557,1.883,-0.003
21.93,113.900,-0.13532,1.892,-0.003
21.98,114.200,-0.13507,1.897,-0.003
22.08,114.500,-0.13486,1.904,-0.003
22.12,114.800,-0.13465,1.908,-0.003
22.22,115.100,-0.13444,1.917,-0.003
22.31,115.400,-0.13424,1.925,-0.003
22.37,115.700,-0.13403,1.929,-0.003
22.44,116.000,-0.13382,1.936,-0.003
22.53,116.300,-0.13361,1.944,-0.003
22.63,116.600,-0.13340,1.952,-0.003
22.72,116.900,-0.13320,1.960,-0.003
22.78,117.200,-0.13299,1.965,-0.003
22.87,117.500,-0.13278,1.973,-0.003
22.96,117.800,-0.13253,1.981,-0.003
23.05,118.100,-0.13232,1.989,-0.003
23.14,118.400,-0.13212,1.997,-0.003
23.25,118.700,-0.13187,2.006,-0.003
23.31,119.000,-0.13162,2.011,-0.003
23.43,119.300,-0.13141,2.021,-0.003
23.51,119.600,-0.13116,2.028,-0.003
23.61,119.900,-0.13091,2.036,-0.003
23.72,120.200,-0.13070,2.046,-0.003
23.82,120.500,-0.13045,2.055,-0.003
23.94,120.800,-0.13016,2.065,-0.003
24.05,121.100,-0.12991,2.075,-0.003
24.18,121.400,-0.12962,2.086,-0.003
24.31,121.700,-0.12933,2.097,-0.003
24.46,122.000,-0.12904,2.110,-0.003
24.59,122.300,-0.12871,2.122,-0.003
24.74,122.600,-0.12838,2.134,-0.003
24.90,122.900,-0.12800,2.148,-0.003
25.02,123.200,-0.12767,2.159,-0.003
25.14,123.500,-0.12738,2.169,-0.003
25.27,123.800,-0.12709,2.180,-0.003
25.40,124.100,-0.12680,2.192,-0.002
25.50,124.400,-0.12651,2.200,-0.002
25.62,124.700,-0.12626,2.210,-0.002
25.69,125.000,-0.12601,2.216,-0.002
25.79,125.300,-0.12576,2.225,-0.002
25.89,125.600,-0.12551,2.233,-0.002
25.98,125.900,-0.12530,2.241,-0.002
26.05,126.200,-0.12509,2.247,-0.002
26.14,126.500,-0.12489,2.255,-0.002
26.20,126.800,-0.12468,2.261,-0.002
26.30,127.100,-0.12447,2.269,-0.002
26.39,127.400,-0.12426,2.276,-0.002
26.48,127.700,-0.12405,2.284,-0.002
26.59,128.000,-0.12385,2.294,-0.002
26.67,128.300,-0.12364,2.300,-0.002
26.79,128.600,-0.12343,2.311,-0.002
26.88,128.900,-0.12318,2.319,-0.002
26.99,129.200,-0.12297,2.328,-0.002
27.09,129.500,-0.12272,2.337,-0.002
27.21,129.800,-0.12252,2.347,-0.002
27.31,130.100,-0.12227,2.356,-0.002
27.42,130.400,-0.12202,2.366,-0.002
27.54,130.700,-0.12177,2.376,-0.002
27.66,131.000,-0.12152,2.387,-0.002
27.77,131.300,-0.12127,2.396,-0.002
27.89,131.600,-0.12102,2.406,-0.002
28.01,131.900,-0.12077,2.417,-0.002
28.14,132.200,-0.12048,2.428,-0.002
28.29,132.500,-0.12023,2.440,-0.002
28.43,132.800,-0.11994,2.453,-0.002
28.57,133.100,-0.11965,2.465,-0.002
28.74,133.400,-0.11932,2.480,-0.002
28.89,133.700,-0.11898,2.492,-0.002
29.04,134.000,-0.11865,2.505,-0.002
29.20,134.300,-0.11832,2.519,-0.002
29.32,134.600,-0.11803,2.529,-0.002
29.48,134.900,-0.11774,2.543,-0.002
29.60,135.200,-0.11745,2.553,-0.002
29.74,135.500,-0.11716,2.565,-0.002
29.87,135.800,-0.11687,2.577,-0.002
29.96,136.100,-0.11662,2.585,-0.002
30.05,136.400,-0.11637,2.592,-0.002
30.15,136.700,-0.11616,2.601,-0.002
30.27,137.000,-0.11591,2.612,-0.002
30.35,137.300,-0.11570,2.619,-0.002
30.45,137.600,-0.11549,2.626,-0.002
30.53,137.900,-0.11529,2.634,-0.002
30.64,138.200,-0.11508,2.643,-0.002
30.71,138.500,-0.11487,2.649,-0.002
30.82,138.800,-0.11466,2.659,-0.002
30.92,139.100,-0.11445,2.668,-0.002
31.02,139.400,-0.11425,2.676,-0.002
31.13,139.700,-0.11404,2.686,-0.002
31.26,140.000,-0.11383,2.697,-0.002
31.37,140.300,-0.11362,2.706,-0.002
31.49,140.600,-0.11337,2.716,-0.002
31.61,140.900,-0.11317,2.727,-0.002
31.73,141.200,-0.11292,2.737,-0.002
31.85,141.500,-0.11271,2.747,-0.002
31.98,141.800,-0.11246,2.759,-0.002
32.12,142.100,-0.11221,2.771,-0.002
32.24,142.400,-0.11196,2.781,-0.002
32.34,142.700,-0.11171,2.790,-0.002
32.48,143.000,-0.11150,2.802,-0.002
32.63,143.300,-0.11125,2.815,-0.002
32.77,143.600,-0.11096,2.827,-0.002
32.94,143.900,-0.11071,2.841,-0.002
33.12,144.200,-0.11038,2.857,-0.002
33.27,144.500,-0.11009,2.870,-0.002
33.46,144.800,-0.10976,2.886,-0.002
33.65,145.100,-0.10943,2.903,-0.002
33.78,145.400,-0.10914,2.915,-0.002
33.95,145.700,-0.10880,2.929,-0.002
34.10,146.000,-0.10851,2.942,-0.002
34.25,146.300,-0.10822,2.955,-0.002
34.41,146.600,-0.10789,2.969,-0.002
34.54,146.900,-0.10764,2.979,-0.002
34.66,147.200,-0.10735,2.990,-0.002
34.78,147.500,-0.10714,3.001,-0.002
34.88,147.800,-0.10689,3.009,-0.002
35.00,148.100,-0.10668,3.020,-0.002
35.12,148.400,-0.10643,3.030,-0.002
35.22,148.700,-0.10623,3.038,-0.002
35.33,149.000,-0.10602,3.048,-0.002
35.44,149.300,-0.10581,3.057,-0.002
35.52,149.600,-0.10560,3.064,-0.002
35.62,149.900,-0.10544,3.073,-0.002
35.72,150.200,-0.10523,3.082,-0.002
35.86,150.500,-0.10502,3.094,-0.002
35.97,150.800,-0.10481,3.103,-0.002
36.11,151.100,-0.10461,3.115,-0.002
36.23,151.400,-0.10440,3.126,-0.002
36.37,151.700,-0.10415,3.138,-0.002
36.49,152.000,-0.10394,3.148,-0.002
36.62,152.300,-0.10373,3.159,-0.002
36.76,152.600,-0.10348,3.171,-0.002
36.88,152.900,-0.10323,3.182,-0.002
37.05,153.200,-0.10299,3.196,-0.002
37.17,153.500,-0.10278,3.206,-0.002
37.33,153.800,-0.10253,3.220,-0.002
37.44,154.100,-0.10228,3.230,-0.002
37.58,154.400,-0.10203,3.242,-0.002
37.72,154.700,-0.10178,3.254,-0.002
37.88,155.000,-0.10153,3.268,-0.002
38.08,155.300,-0.10124,3.285,-0.002
38.22,155.600,-0.10095,3.297,-0.002
38.46,155.900,-0.10066,3.318,-0.002
38.63,156.200,-0.10033,3.333,-0.002
38.85,156.500,-0.09999,3.351,-0.002
38.99,156.800,-0.09966,3.363,-0.002
39.20,157.100,-0.09937,3.381,-0.002
39.33,157.400,-0.09904,3.393,-0.002
39.52,157.700,-0.09875,3.409,-0.002
39.68,158.000,-0.09846,3.424,-0.002
39.83,158.300,-0.09816,3.436,-0.002
39.97,158.600,-0.09792,3.448,-0.002
40.11,158.900,-0.09767,3.460,-0.002
40.23,159.200,-0.09742,3.470,-0.002
40.35,159.500,-0.09717,3.481,-0.002
40.49,159.800,-0.09696,3.493,-0.002
40.56,160.100,-0.09675,3.499,-0.002
40.72,160.400,-0.09654,3.513,-0.002
40.82,160.700,-0.09634,3.522,-0.002
40.94,161.000,-0.09613,3.532,-0.002
41.07,161.300,-0.09596,3.543,-0.002
41.18,161.600,-0.09575,3.552,-0.002
41.32,161.900,-0.09555,3.565,-0.002
41.44,162.200,-0.09534,3.575,-0.002
41.59,162.500,-0.09513,3.588,-0.002
41.72,162.800,-0.09488,3.599,-0.002
41.88,163.100,-0.09467,3.613,-0.002
42.00,163.400,-0.09447,3.624,-0.002
42.15,163.700,-0.09422,3.636,-0.002
42.31,164.000,-0.09401,3.650,-0.002
42.44,164.300,-0.09376,3.661,-0.002
42.60,164.600,-0.09355,3.675,-0.002
42.74,164.900,-0.09330,3.687,-0.002
42.89,165.200,-0.09305,3.700,-0.002
43.04,165.500,-0.09280,3.713,-0.002
43.21,165.800,-0.09255,3.728,-0.002
43.37,166.100,-0.09231,3.742,-0.002
43.55,166.400,-0.09206,3.757,-0.002
43.76,166.700,-0.09177,3.775,-0.002
43.92,167.000,-0.09147,3.789,-0.002
44.13,167.300,-0.09118,3.807,-0.002
44.35,167.600,-0.09089,3.826,-0.002
44.57,167.900,-0.09056,3.845,-0.002
44.77,168.200,-0.09027,3.862,-0.002
44.98,168.500,-0.08994,3.880,-0.002
45.16,168.800,-0.08965,3.896,-0.002
45.37,169.100,-0.08936,3.914,-0.002
45.55,169.400,-0.08906,3.929,-0.002
45.71,169.700,-0.08877,3.944,-0.002
45.87,170.000,-0.08852,3.957,-0.002
46.01,170.300,-0.08827,3.969,-0.002
46.16,170.600,-0.08807,3.982,-0.002
46.30,170.900,-0.08782,3.995,-0.002
46.43,171.200,-0.08761,4.006,-0.002
46.55,171.500,-0.08740,4.016,-0.002
46.67,171.800,-0.08719,4.026,-0.002
46.78,172.100,-0.08699,4.036,-0.002
46.90,172.400,-0.08678,4.046,-0.002
47.04,172.700,-0.08657,4.058,-0.002
47.15,173.000,-0.08640,4.068,-0.002
47.29,173.300,-0.08620,4.079,-0.002
47.44,173.600,-0.08599,4.092,-0.002
47.56,173.900,-0.08578,4.103,-0.002
47.69,174.200,-0.08557,4.114,-0.002
47.86,174.500,-0.08532,4.129,-0.002
47.96,174.800,-0.08512,4.138,-0.002
48.13,175.100,-0.08491,4.152,-0.002
48.20,175.400,-0.08466,4.158,-0.002
48.16,175.700,-0.08445,4.155,-0.002
48.27,176.000,-0.08420,4.164,-0.002
48.46,176.300,-0.08395,4.180,-0.002
48.61,176.600,-0.08375,4.194,-0.002
48.76,176.900,-0.08350,4.207,-0.002
48.94,177.200,-0.08325,4.222,-0.002
49.10,177.500,-0.08300,4.236,-0.002
49.24,177.800,-0.08275,4.248,-0.002
49.42,178.100,-0.08246,4.264,-0.002
49.61,178.400,-0.08217,4.280,-0.002
49.78,178.700,-0.08187,4.295,-0.002
50.03,179.000,-0.08154,4.316,-0.002
50.25,179.300,-0.08121,4.335,-0.002
50.49,179.600,-0.08088,4.356,-0.002
50.68,179.900,-0.08059,4.372,-0.002
50.92,180.200,-0.08025,4.392,-0.002
51.14,180.500,-0.07992,4.412,-0.002
51.30,180.800,-0.07963,4.426,-0.002
51.46,181.100,-0.07938,4.440,-0.002
51.60,181.400,-0.07909,4.451,-0.002
51.76,181.700,-0.07884,4.466,-0.002
51.87,182.000,-0.07863,4.475,-0.002
52.01,182.300,-0.07838,4.487,-0.002
52.08,182.600,-0.07818,4.493,-0.002
52.28,182.900,-0.07797,4.510,-0.002
52.39,183.200,-0.07776,4.519,-0.002
52.53,183.500,-0.07755,4.532,-0.002
52.64,183.800,-0.07735,4.541,-0.002
52.77,184.100,-0.07714,4.553,-0.002
52.90,184.400,-0.07693,4.564,-0.002
53.05,184.700,-0.07676,4.577,-0.002
53.19,185.000,-0.07656,4.588,-0.002
53.29,185.300,-0.07635,4.598,-0.002
53.45,185.600,-0.07610,4.611,-0.001
53.54,185.900,-0.07589,4.619,-0.001
53.74,186.200,-0.07564,4.636,-0.001
53.88,186.500,-0.07543,4.648,-0.001
54.04,186.800,-0.07523,4.662,-0.001
54.20,187.100,-0.07498,4.676,-0.001
54.39,187.400,-0.07473,4.693,-0.001
54.54,187.700,-0.07448,4.705,-0.001
54.71,188.000,-0.07427,4.720,-0.001
54.89,188.300,-0.07402,4.735,-0.001
55.08,188.600,-0.07377,4.752,-0.001
55.28,188.900,-0.07348,4.769,-0.001
55.49,189.200,-0.07323,4.787,-0.001
55.73,189.500,-0.07294,4.808,-0.001
55.96,189.800,-0.07265,4.828,-0.001
56.23,190.100,-0.07236,4.851,-0.001
56.50,190.400,-0.07203,4.874,-0.001
56.76,190.700,-0.07174,4.896,-0.001
57.02,191.000,-0.07140,4.919,-0.001
57.24,191.300,-0.07107,4.938,-0.001
57.51,191.600,-0.07074,4.962,-0.001
57.73,191.900,-0.07045,4.980,-0.001
57.96,192.200,-0.07016,5.000,-0.001
58.15,192.500,-0.06987,5.017,-0.001
58.34,192.800,-0.06962,5.033,-0.001
58.51,193.100,-0.06937,5.048,-0.001
58.72,193.400,-0.06912,5.066,-0.001
58.86,193.700,-0.06887,5.078,-0.001
59.04,194.000,-0.06866,5.093,-0.001
59.19,194.300,-0.06841,5.106,-0.001
59.32,194.600,-0.06820,5.118,-0.001
59.50,194.900,-0.06800,5.133,-0.001
59.64,195.200,-0.06779,5.145,-0.001
59.81,195.500,-0.06758,5.160,-0.001
59.94,195.800,-0.06737,5.171,-0.001
60.11,196.100,-0.06716,5.186,-0.001
60.29,196.400,-0.06696,5.201,-0.001
60.46,196.700,-0.06675,5.216,-0.001
60.63,197.000,-0.06650,5.230,-0.001
60.76,197.300,-0.06629,5.242,-0.001
60.93,197.600,-0.06604,5.256,-0.001
61.07,197.900,-0.06579,5.268,-0.001
61.18,198.200,-0.06559,5.278,-0.001
61.30,198.500,-0.06534,5.288,-0.001
61.39,198.800,-0.06509,5.296,-0.001
61.45,199.100,-0.06484,5.302,-0.001
61.57,199.400,-0.06459,5.311,-0.001
61.68,199.700,-0.06434,5.321,-0.001
61.77,200.000,-0.06409,5.329,-0.001
61.91,200.300,-0.06384,5.341,-0.001
62.02,200.600,-0.06355,5.351,-0.001
62.14,200.900,-0.06326,5.360,-0.001
62.11,201.200,-0.06297,5.358,-0.001
61.95,201.500,-0.06263,5.344,-0.001
61.85,201.800,-0.06234,5.336,-0.001
61.94,202.100,-0.06201,5.343,-0.001
62.07,202.400,-0.06168,5.354,-0.001
62.14,202.700,-0.06135,5.360,-0.001
62.20,203.000,-0.06106,5.365,-0.001
62.23,203.300,-0.06076,5.368,-0.001
62.33,203.600,-0.06047,5.377,-0.001
62.43,203.900,-0.06018,5.386,-0.001
62.52,204.200,-0.05993,5.393,-0.001
62.59,204.500,-0.05968,5.400,-0.001
62.67,204.800,-0.05948,5.406,-0.001
62.81,205.100,-0.05923,5.418,-0.001
62.93,205.400,-0.05902,5.429,-0.001
63.05,205.700,-0.05881,5.440,-0.001
63.22,206.000,-0.05860,5.453,-0.001
63.37,206.300,-0.05840,5.467,-0.001
63.53,206.600,-0.05819,5.481,-0.001
63.72,206.900,-0.05798,5.497,-0.001
63.90,207.200,-0.05777,5.512,-0.001
64.06,207.500,-0.05756,5.526,-0.001
64.26,207.800,-0.05736,5.544,-0.001
64.45,208.100,-0.05715,5.560,-0.001
64.66,208.400,-0.05694,5.578,-0.001
64.87,208.700,-0.05669,5.596,-0.001
65.08,209.000,-0.05648,5.614,-0.001
65.29,209.300,-0.05624,5.633,-0.001
65.51,209.600,-0.05603,5.652,-0.001
65.76,209.900,-0.05578,5.673,-0.001
65.98,210.200,-0.05553,5.692,-0.001
66.23,210.500,-0.05532,5.714,-0.001
66.47,210.800,-0.05507,5.734,-0.001
66.73,211.100,-0.05482,5.756,-0.001
66.98,211.400,-0.05457,5.778,-0.001
67.23,211.700,-0.05428,5.800,-0.001
67.52,212.000,-0.05403,5.825,-0.001
67.86,212.300,-0.05374,5.854,-0.001
68.16,212.600,-0.05341,5.880,-0.001
68.47,212.900,-0.05312,5.907,-0.001
68.82,213.200,-0.05279,5.937,-0.001
69.13,213.500,-0.05245,5.964,-0.001
69.44,213.800,-0.05212,5.991,-0.001
69.75,214.100,-0.05183,6.018,-0.001
70.03,214.400,-0.05150,6.042,-0.001
70.32,214.700,-0.05121,6.066,-0.001
70.57,215.000,-0.05092,6.088,-0.001
70.78,215.300,-0.05067,6.106,-0.001
71.02,215.600,-0.05042,6.127,-0.001
71.24,215.900,-0.05017,6.146,-0.001
71.44,216.200,-0.04992,6.163,-0.001
71.63,216.500,-0.04971,6.179,-0.001
71.84,216.800,-0.04950,6.197,-0.001
72.02,217.100,-0.04930,6.213,-0.001
72.20,217.400,-0.04909,6.229,-0.001
72.40,217.700,-0.04888,6.246,-0.001
72.60,218.000,-0.04867,6.263,-0.001
72.77,218.300,-0.04851,6.277,-0.001
72.96,218.600,-0.04830,6.294,-0.001
73.17,218.900,-0.04809,6.312,-0.001
73.38,219.200,-0.04784,6.331,-0.001
73.59,219.500,-0.04763,6.349,-0.001
73.82,219.800,-0.04743,6.368,-0.001
74.02,220.100,-0.04718,6.386,-0.001
74.22,220.400,-0.04697,6.402,-0.001
74.44,220.700,-0.04672,6.421,-0.001
74.64,221.000,-0.04651,6.439,-0.001
74.86,221.300,-0.04626,6.458,-0.001
75.08,221.600,-0.04601,6.477,-0.001
75.31,221.900,-0.04576,6.496,-0.001
75.53,222.200,-0.04556,6.515,-0.001
75.75,222.500,-0.04531,6.535,-0.001
75.99,222.800,-0.04506,6.555,-0.001
76.28,223.100,-0.04477,6.580,-0.001
76.52,223.400,-0.04452,6.601,-0.001
76.77,223.700,-0.04423,6.623,-0.001
77.08,224.000,-0.04389,6.650,-0.001
77.36,224.300,-0.04360,6.674,-0.001
77.63,224.600,-0.04327,6.697,-0.001
77.92,224.900,-0.04298,6.722,-0.001
78.24,225.200,-0.04265,6.750,-0.001
78.53,225.500,-0.04231,6.775,-0.001
78.78,225.800,-0.04202,6.796,-0.001
79.05,226.100,-0.04173,6.819,-0.001
79.31,226.400,-0.04144,6.841,-0.001
79.53,226.700,-0.04119,6.861,-0.001
79.74,227.000,-0.04094,6.879,-0.001
79.93,227.300,-0.04069,6.895,-0.001
80.11,227.600,-0.04044,6.911,-0.001
80.34,227.900,-0.04024,6.931,-0.001
80.51,228.200,-0.04003,6.946,-0.001
80.68,228.500,-0.03982,6.960,-0.001
80.88,228.800,-0.03961,6.978,-0.001
81.03,229.100,-0.03940,6.990,-0.001
81.20,229.400,-0.03920,7.005,-0.001
81.31,229.700,-0.03899,7.015,-0.001
81.51,230.000,-0.03878,7.031,-0.001
81.66,230.300,-0.03857,7.045,-0.001
81.86,230.600,-0.03837,7.062,-0.001
82.04,230.900,-0.03816,7.077,-0.001
82.29,231.200,-0.03791,7.099,-0.001
82.48,231.500,-0.03770,7.115,-0.001
82.70,231.800,-0.03745,7.134,-0.001
82.93,232.100,-0.03724,7.154,-0.001
83.13,232.400,-0.03699,7.172,-0.001
83.34,232.700,-0.03679,7.189,-0.001
83.53,233.000,-0.03654,7.206,-0.001
83.74,233.300,-0.03629,7.224,-0.001
83.95,233.600,-0.03608,7.242,-0.001
84.17,233.900,-0.03583,7.261,-0.001
84.38,234.200,-0.03558,7.279,-0.001
84.66,234.500,-0.03533,7.304,-0.001
84.94,234.800,-0.03504,7.327,-0.001
85.24,235.100,-0.03475,7.353,-0.001
85.52,235.400,-0.03446,7.378,-0.001
85.84,235.700,-0.03413,7.405,-0.001
86.17,236.000,-0.03384,7.434,-0.001
86.46,236.300,-0.03350,7.459,-0.001
86.77,236.600,-0.03321,7.485,-0.001
87.02,236.900,-0.03288,7.507,-0.001
87.30,237.200,-0.03259,7.531,-0.001
87.51,237.500,-0.03234,7.549,-0.001
87.73,237.800,-0.03205,7.568,-0.001
87.96,238.100,-0.03176,7.588,-0.001
88.19,238.400,-0.03151,7.608,-0.001
88.37,238.700,-0.03130,7.624,-0.001
88.55,239.000,-0.03105,7.639,-0.001
88.77,239.300,-0.03084,7.658,-0.001
88.96,239.600,-0.03060,7.674,-0.001
89.15,239.900,-0.03039,7.691,-0.001
89.32,240.200,-0.03018,7.705,-0.001
89.48,240.500,-0.02997,7.719,-0.001
89.63,240.800,-0.02976,7.732,-0.001
89.79,241.100,-0.02956,7.746,-0.001
89.97,241.400,-0.02939,7.762,-0.001
90.14,241.700,-0.02914,7.776,-0.001
90.31,242.000,-0.02893,7.791,-0.001
90.52,242.300,-0.02873,7.809,-0.001
90.72,242.600,-0.02852,7.826,-0.001
90.93,242.900,-0.02831,7.844,-0.001
91.15,243.200,-0.02806,7.863,-0.001
91.37,243.500,-0.02785,7.883,-0.001
91.62,243.800,-0.02760,7.904,-0.001
91.85,244.100,-0.02740,7.923,-0.001
92.10,244.400,-0.02715,7.945,-0.001
92.37,244.700,-0.02694,7.968,-0.001
92.58,245.000,-0.02669,7.987,-0.001
92.86,245.300,-0.02644,8.011,-0.001
93.12,245.600,-0.02619,8.034,-0.001
93.40,245.900,-0.02594,8.058,-0.001
93.73,246.200,-0.02565,8.086,-0.001
94.05,246.500,-0.02536,8.114,0.000
94.40,246.800,-0.02507,8.144,0.000
94.74,247.100,-0.02478,8.173,0.000
95.08,247.400,-0.02444,8.202,0.000
95.46,247.700,-0.02415,8.235,0.000
95.78,248.000,-0.02382,8.263,0.000
96.09,248.300,-0.02349,8.289,0.000
96.39,248.600,-0.02320,8.315,0.000
96.65,248.900,-0.02291,8.338,0.000
96.91,249.200,-0.02262,8.361,0.000
97.12,249.500,-0.02237,8.378,0.000
97.33,249.800,-0.02212,8.396,0.000
97.58,250.100,-0.02187,8.418,0.000
97.75,250.400,-0.02166,8.432,0.000
97.97,250.700,-0.02141,8.451,0.000
98.14,251.000,-0.02120,8.466,0.000
98.33,251.300,-0.02100,8.483,0.000
98.52,251.600,-0.02079,8.499,0.000
98.71,251.900,-0.02058,8.516,0.000
98.91,252.200,-0.02037,8.533,0.000
99.11,252.500,-0.02021,8.550,0.000
99.33,252.800,-0.02000,8.569,0.000
99.56,253.100,-0.01979,8.589,0.000
99.81,253.400,-0.01954,8.610,0.000
100.04,253.700,-0.01933,8.630,0.000
100.26,254.000,-0.01913,8.649,0.000
100.53,254.300,-0.01888,8.672,0.000
100.78,254.600,-0.01867,8.694,0.000
101.02,254.900,-0.01842,8.715,0.000
101.30,255.200,-0.01817,8.739,0.000
101.52,255.500,-0.01796,8.758,0.000
101.76,255.800,-0.01771,8.779,0.000
101.99,256.100,-0.01746,8.798,0.000
102.22,256.400,-0.01721,8.818,0.000
102.43,256.700,-0.01696,8.836,0.000
102.67,257.000,-0.01672,8.857,0.000
102.94,257.300,-0.01642,8.881,0.000
103.23,257.600,-0.01618,8.906,0.000
103.53,257.900,-0.01584,8.931,0.000
103.79,258.200,-0.01555,8.954,0.000
104.09,258.500,-0.01526,8.980,0.000
104.44,258.800,-0.01493,9.009,0.000
104.74,259.100,-0.01460,9.036,0.000
105.02,259.400,-0.01426,9.060,0.000
105.30,259.700,-0.01397,9.084,0.000
105.62,260.000,-0.01364,9.112,0.000
105.89,260.300,-0.01335,9.135,0.000
106.22,260.600,-0.01306,9.163,0.000
106.46,260.900,-0.01281,9.184,0.000
106.76,261.200,-0.01256,9.210,0.000
107.00,261.500,-0.01231,9.231,0.000
107.28,261.800,-0.01206,9.255,0.000
107.51,262.100,-0.01181,9.275,0.000
107.76,262.400,-0.01160,9.296,0.000
108.01,262.700,-0.01140,9.318,0.000
108.27,263.000,-0.01119,9.340,0.000
108.52,263.300,-0.01098,9.362,0.000
108.76,263.600,-0.01077,9.382,0.000
109.00,263.900,-0.01057,9.403,0.000
109.25,264.200,-0.01036,9.424,0.000
109.52,264.500,-0.01015,9.448,0.000
109.80,264.800,-0.00990,9.473,0.000
110.07,265.100,-0.00969,9.495,0.000
110.31,265.400,-0.00948,9.516,0.000
110.59,265.700,-0.00924,9.540,0.000
110.83,266.000,-0.00899,9.561,0.000
111.09,266.300,-0.00878,9.584,0.000
111.33,266.600,-0.00853,9.604,0.000
111.55,266.900,-0.00828,9.623,0.000
111.78,267.200,-0.00807,9.643,0.000
111.99,267.500,-0.00782,9.661,0.000
112.22,267.800,-0.00757,9.681,0.000
112.47,268.100,-0.00728,9.702,0.000
112.70,268.400,-0.00703,9.722,0.000
112.95,268.700,-0.00678,9.744,0.000
113.18,269.000,-0.00649,9.764,0.000
113.36,269.300,-0.00620,9.779,0.000
113.51,269.600,-0.00587,9.792,0.000
113.53,269.900,-0.00558,9.794,0.000
113.43,270.200,-0.00525,9.786,0.000
113.27,270.500,-0.00491,9.772,0.000
113.01,270.800,-0.00458,9.749,0.000
112.79,271.100,-0.00429,9.731,0.000
112.59,271.400,-0.00400,9.713,0.000
112.55,271.700,-0.00371,9.710,0.000
112.61,272.000,-0.00346,9.715,0.000
112.77,272.300,-0.00321,9.729,0.000
112.97,272.600,-0.00296,9.746,0.000
113.17,272.900,-0.00271,9.763,0.000
113.40,273.200,-0.00250,9.783,0.000
113.60,273.500,-0.00225,9.800,0.000
113.79,273.800,-0.00205,9.816,0.000
113.91,274.100,-0.00184,9.827,0.000
114.02,274.400,-0.00163,9.836,0.000
114.08,274.700,-0.00142,9.842,0.000
114.06,275.000,-0.00122,9.839,0.000
113.91,275.300,-0.00101,9.827,0.000
113.86,275.600,-0.00080,9.823,0.000
113.98,275.900,-0.00059,9.833,0.000
114.09,276.200,-0.00038,9.842,0.000
114.23,276.500,-0.00018,9.855,0.000
114.35,276.800,0.00007,9.865,0.000
114.41,277.100,0.00028,9.869,0.000
114.50,277.400,0.00049,9.877,0.000
114.68,277.700,0.00074,9.894,0.000
114.95,278.000,0.00095,9.916,0.000
115.26,278.300,0.00120,9.943,0.000
115.62,278.600,0.00144,9.974,0.000
115.96,278.900,0.00169,10.004,0.000
116.33,279.200,0.00190,10.035,0.000
116.71,279.500,0.00215,10.068,0.000
117.15,279.800,0.00244,10.107,0.000
117.63,280.100,0.00273,10.147,0.000
118.15,280.400,0.00302,10.193,0.000
118.67,280.700,0.00331,10.237,0.000
119.24,281.000,0.00365,10.287,0.000
119.83,281.300,0.00398,10.337,0.000
120.32,281.600,0.00427,10.380,0.000
120.86,281.900,0.00460,10.426,0.000
121.30,282.200,0.00489,10.464,0.000
121.79,282.500,0.00523,10.507,0.000
122.17,282.800,0.00552,10.540,0.000
122.52,283.100,0.00581,10.569,0.000
122.83,283.400,0.00606,10.596,0.000
123.16,283.700,0.00631,10.625,0.000
123.44,284.000,0.00651,10.649,0.000
123.71,284.300,0.00676,10.672,0.000
124.01,284.600,0.00697,10.698,0.000
124.28,284.900,0.00718,10.721,0.000
124.56,285.200,0.00739,10.746,0.000
124.82,285.500,0.00759,10.768,0.000
125.07,285.800,0.00780,10.790,0.000
125.32,286.100,0.00801,10.811,0.000
125.58,286.400,0.00818,10.834,0.000
125.89,286.700,0.00838,10.861,0.000
126.18,287.000,0.00859,10.885,0.000
126.46,287.300,0.00880,10.909,0.000
126.75,287.600,0.00905,10.935,0.000
127.04,287.900,0.00926,10.960,0.000
127.32,288.200,0.00946,10.984,0.000
127.61,288.500,0.00971,11.009,0.000
127.85,288.800,0.00992,11.029,0.000
128.10,289.100,0.01013,11.051,0.000
128.36,289.400,0.01038,11.074,0.000
128.66,289.700,0.01063,11.099,0.000
128.93,290.000,0.01084,11.122,0.000
129.19,290.300,0.01109,11.145,0.000
129.40,290.600,0.01133,11.163,0.000
129.62,290.900,0.01158,11.182,0.000
129.88,291.200,0.01188,11.204,0.000
130.14,291.500,0.01212,11.227,0.000
130.32,291.800,0.01242,11.243,0.000
130.55,292.100,0.01271,11.262,0.000
130.83,292.400,0.01304,11.287,0.000
131.13,292.700,0.01337,11.312,0.000
131.37,293.000,0.01366,11.333,0.000
131.56,293.300,0.01399,11.349,0.000
131.74,293.600,0.01433,11.365,0.000
131.85,293.900,0.01462,11.374,0.000
131.96,294.200,0.01491,11.384,0.000
132.05,294.500,0.01520,11.392,0.000
132.07,294.800,0.01545,11.394,0.000
132.08,295.100,0.01570,11.394,0.000
132.07,295.400,0.01595,11.393,0.000
132.03,295.700,0.01616,11.390,0.000
131.99,296.000,0.01640,11.387,0.000
131.95,296.300,0.01661,11.383,0.000
131.84,296.600,0.01682,11.374,0.000
131.74,296.900,0.01703,11.365,0.000
131.62,297.200,0.01724,11.355,0.000
131.49,297.500,0.01744,11.343,0.000
131.35,297.800,0.01765,11.331,0.000
131.17,298.100,0.01786,11.316,0.000
131.02,298.400,0.01803,11.303,0.000
130.84,298.700,0.01823,11.287,0.000
130.63,299.000,0.01848,11.269,0.000
130.38,299.300,0.01869,11.248,0.000
130.04,299.600,0.01890,11.218,0.000
129.56,299.900,0.01915,11.177,0.000
129.01,300.200,0.01936,11.129,0.000
128.33,300.500,0.01960,11.071,0.000
127.41,300.800,0.01985,10.991,0.000
126.27,301.100,0.02006,10.893,0.000
125.30,301.400,0.02031,10.809,0.000
124.69,301.700,0.02056,10.756,0.000
124.24,302.000,0.02081,10.718,0.000
123.87,302.300,0.02106,10.686,0.000
123.66,302.600,0.02131,10.668,0.000
123.49,302.900,0.02160,10.653,0.000
123.34,303.200,0.02185,10.640,0.000
123.18,303.500,0.02214,10.627,0.000
123.00,303.800,0.02247,10.611,0.000
122.83,304.100,0.02276,10.596,0.000
122.65,304.400,0.02310,10.581,0.000
122.35,304.700,0.02343,10.555,0.000
122.08,305.000,0.02372,10.531,0.000
121.61,305.300,0.02401,10.491,0.000
120.63,305.600,0.02434,10.406,0.000
118.98,305.900,0.02459,10.265,0.000
117.72,306.200,0.02488,10.156,0.000
116.82,306.500,0.02513,10.078,0.000
116.12,306.800,0.02538,10.018,0.000
115.54,307.100,0.02563,9.967,0.001
115.06,307.400,0.02584,9.926,0.001
114.76,307.700,0.02609,9.901,0.001
114.53,308.000,0.02629,9.880,0.001
114.25,308.300,0.02650,9.856,0.001
114.04,308.600,0.02667,9.838,0.001
113.86,308.900,0.02688,9.823,0.001
113.80,309.200,0.02708,9.817,0.001
113.76,309.500,0.02729,9.814,0.001
113.72,309.800,0.02750,9.811,0.001
113.72,310.100,0.02771,9.810,0.001
113.72,310.400,0.02792,9.810,0.001
113.74,310.700,0.02812,9.812,0.001
113.80,311.000,0.02833,9.818,0.001
113.88,311.300,0.02858,9.824,0.001
113.97,311.600,0.02879,9.832,0.001
114.12,311.900,0.02904,9.845,0.001
114.26,312.200,0.02929,9.857,0.001
114.38,312.500,0.02949,9.867,0.001
114.50,312.800,0.02974,9.878,0.001
114.71,313.100,0.02999,9.896,0.001
114.90,313.400,0.03020,9.912,0.001
115.11,313.700,0.03045,9.930,0.001
115.36,314.000,0.03074,9.952,0.001
115.58,314.300,0.03099,9.971,0.001
115.87,314.600,0.03128,9.996,0.001
116.18,314.900,0.03157,10.023,0.001
116.49,315.200,0.03186,10.049,0.001
116.83,315.500,0.03220,10.078,0.001
117.11,315.800,0.03249,10.103,0.001
117.42,316.100,0.03282,10.129,0.001
117.71,316.400,0.03315,10.155,0.001
118.03,316.700,0.03344,10.182,0.001
118.36,317.000,0.03373,10.210,0.001
118.65,317.300,0.03402,10.236,0.001
118.94,317.600,0.03432,10.261,0.001
119.18,317.900,0.03456,10.282,0.001
119.42,318.200,0.03481,10.302,0.001
119.70,318.500,0.03506,10.327,0.001
119.93,318.800,0.03527,10.346,0.001
120.18,319.100,0.03548,10.368,0.001
120.43,319.400,0.03569,10.389,0.001
120.68,319.700,0.03589,10.411,0.001
120.87,320.000,0.03610,10.427,0.001
121.11,320.300,0.03631,10.448,0.001
121.37,320.600,0.03652,10.471,0.001
121.65,320.900,0.03673,10.495,0.001
121.90,321.200,0.03693,10.516,0.001
122.18,321.500,0.03714,10.540,0.001
122.50,321.800,0.03735,10.567,0.001
122.80,322.100,0.03756,10.594,0.001
123.11,322.400,0.03781,10.621,0.001
123.40,322.700,0.03801,10.645,0.001
123.68,323.000,0.03826,10.670,0.001
123.99,323.300,0.03851,10.696,0.001
124.26,323.600,0.03876,10.719,0.001
124.52,323.900,0.03897,10.742,0.001
124.81,324.200,0.03922,10.767,0.001
125.13,324.500,0.03947,10.795,0.001
125.44,324.800,0.03972,10.822,0.001
125.76,325.100,0.03997,10.849,0.001
126.07,325.400,0.04026,10.876,0.001
126.47,325.700,0.04055,10.910,0.001
126.87,326.000,0.04084,10.945,0.001
127.23,326.300,0.04113,10.975,0.001
127.66,326.600,0.04146,11.013,0.001
128.12,326.900,0.04180,11.052,0.001
128.55,327.200,0.04213,11.090,0.001
128.95,327.500,0.04250,11.124,0.001
129.32,327.800,0.04283,11.156,0.001
129.71,328.100,0.04313,11.190,0.001
130.06,328.400,0.04342,11.220,0.001
130.46,328.700,0.04371,11.255,0.001
130.82,329.000,0.04396,11.286,0.001
131.19,329.300,0.04425,11.317,0.001
131.47,329.600,0.04445,11.341,0.001
131.75,329.900,0.04470,11.365,0.001
132.05,330.200,0.04491,11.391,0.001
132.26,330.500,0.04516,11.410,0.001
132.44,330.800,0.04537,11.425,0.001
132.62,331.100,0.04558,11.441,0.001
132.79,331.400,0.04578,11.456,0.001
132.94,331.700,0.04599,11.468,0.001
133.09,332.000,0.04620,11.481,0.001
133.22,332.300,0.04641,11.493,0.001
133.40,332.600,0.04662,11.508,0.001
133.53,332.900,0.04682,11.519,0.001
133.64,333.200,0.04707,11.529,0.001
133.69,333.500,0.04728,11.534,0.001
133.64,333.800,0.04753,11.529,0.001
133.57,334.100,0.04778,11.523,0.001
133.60,334.400,0.04799,11.526,0.001
133.77,334.700,0.04824,11.540,0.001
134.05,335.000,0.04849,11.564,0.001
134.37,335.300,0.04874,11.592,0.001
134.72,335.600,0.04894,11.622,0.001
135.16,335.900,0.04919,11.660,0.001
135.60,336.200,0.04948,11.698,0.001
136.13,336.500,0.04973,11.744,0.001
136.60,336.800,0.05002,11.784,0.001
137.20,337.100,0.05027,11.836,0.001
137.83,337.400,0.05061,11.890,0.001
138.51,337.700,0.05090,11.949,0.001
139.22,338.000,0.05123,12.011,0.001
139.91,338.300,0.05156,12.070,0.001
140.59,338.600,0.05189,12.129,0.001
141.21,338.900,0.05218,12.182,0.001
141.77,339.200,0.05252,12.230,0.001
142.30,339.500,0.05281,12.276,0.001
142.81,339.800,0.05310,12.320,0.001
143.24,340.100,0.05335,12.357,0.001
143.66,340.400,0.05360,12.394,0.001
144.07,340.700,0.05385,12.429,0.001
144.45,341.000,0.05410,12.461,0.001
144.86,341.300,0.05430,12.497,0.001
145.25,341.600,0.05455,12.530,0.001
145.64,341.900,0.05476,12.564,0.001
146.02,342.200,0.05497,12.597,0.001
146.35,342.500,0.05518,12.625,0.001
146.72,342.800,0.05538,12.657,0.001
147.10,343.100,0.05559,12.690,0.001
147.49,343.400,0.05580,12.723,0.001
147.87,343.700,0.05601,12.756,0.001
148.23,344.000,0.05622,12.787,0.001
148.63,344.300,0.05642,12.822,0.001
149.00,344.600,0.05663,12.854,0.001
149.46,344.900,0.05688,12.893,0.001
149.87,345.200,0.05709,12.929,0.001
150.29,345.500,0.05734,12.965,0.001
150.68,345.800,0.05759,12.999,0.001
151.07,346.100,0.05779,13.032,0.001
151.42,346.400,0.05804,13.062,0.001
151.84,346.700,0.05829,13.099,0.001
152.20,347.000,0.05854,13.130,0.001
152.56,347.300,0.05879,13.161,0.001
152.99,347.600,0.05904,13.198,0.001
153.43,347.900,0.05933,13.236,0.001
153.98,348.200,0.05958,13.284,0.001
154.52,348.500,0.05991,13.330,0.001
155.08,348.800,0.06020,13.378,0.001
155.58,349.100,0.06054,13.421,0.001
156.10,349.400,0.06083,13.467,0.001
156.57,349.700,0.06116,13.507,0.001
156.83,350.000,0.06149,13.529,0.001
157.10,350.300,0.06178,13.553,0.001
157.38,350.600,0.06207,13.577,0.001
157.70,350.900,0.06241,13.604,0.001
158.02,351.200,0.06266,13.632,0.001
158.34,351.500,0.06291,13.659,0.001
158.73,351.800,0.06315,13.693,0.001
159.05,352.100,0.06340,13.721,0.001
159.41,352.400,0.06361,13.752,0.001
159.74,352.700,0.06382,13.780,0.001
160.11,353.000,0.06403,13.812,0.001
160.51,353.300,0.06424,13.847,0.001
160.89,353.600,0.06444,13.879,0.001
161.29,353.900,0.06465,13.914,0.001
161.72,354.200,0.06486,13.951,0.001
162.20,354.500,0.06507,13.993,0.001
162.66,354.800,0.06523,14.032,0.001
163.17,355.100,0.06548,14.076,0.001
163.66,355.400,0.06569,14.119,0.001
164.20,355.700,0.06590,14.165,0.001
164.71,356.000,0.06611,14.209,0.001
165.21,356.300,0.06635,14.253,0.001
165.75,356.600,0.06656,14.299,0.001
166.25,356.900,0.06681,14.342,0.001
166.76,357.200,0.06706,14.386,0.001
167.29,357.500,0.06727,14.432,0.001
167.76,357.800,0.06752,14.472,0.001
168.26,358.100,0.06777,14.516,0.001
168.76,358.400,0.06802,14.559,0.001
169.33,358.700,0.06827,14.608,0.001
169.85,359.000,0.06852,14.652,0.001
170.47,359.300,0.06881,14.706,0.001
171.08,359.600,0.06906,14.759,0.001
171.70,359.900,0.06935,14.812,0.001
172.38,360.200,0.06968,14.871,0.001
173.09,360.500,0.06997,14.932,0.001
173.75,360.800,0.07030,14.989,0.001
174.47,361.100,0.07063,15.051,0.001
175.15,361.400,0.07097,15.110,0.001
175.70,361.700,0.07126,15.158,0.001
176.33,362.000,0.07159,15.212,0.001
176.88,362.300,0.07188,15.259,0.001
177.41,362.600,0.07213,15.305,0.001
177.92,362.900,0.07238,15.349,0.001
178.43,363.200,0.07263,15.393,0.001
178.85,363.500,0.07288,15.429,0.001
179.29,363.800,0.07309,15.467,0.001
179.74,364.100,0.07334,15.506,0.001
180.18,364.400,0.07354,15.544,0.001
180.56,364.700,0.07375,15.576,0.001
180.92,365.000,0.07396,15.607,0.001
181.31,365.300,0.07417,15.641,0.001
181.72,365.600,0.07438,15.676,0.001
182.15,365.900,0.07458,15.713,0.001
182.56,366.200,0.07475,15.749,0.001
183.02,366.500,0.07500,15.789,0.001
183.50,366.800,0.07521,15.830,0.001
183.99,367.100,0.07541,15.873,0.001
184.48,367.400,0.07566,15.915,0.001
185.00,367.700,0.07587,15.960,0.001
185.49,368.000,0.07608,16.002,0.001
186.03,368.300,0.07633,16.048,0.002
186.55,368.600,0.07654,16.094,0.002
187.11,368.900,0.07679,16.141,0.002
187.67,369.200,0.07703,16.190,0.002
188.23,369.500,0.07728,16.238,0.002
188.82,369.800,0.07749,16.290,0.002
189.41,370.100,0.07774,16.340,0.002
190.02,370.400,0.07803,16.393,0.002
190.71,370.700,0.07828,16.452,0.002
191.41,371.000,0.07857,16.512,0.002
192.12,371.300,0.07886,16.573,0.002
192.94,371.600,0.07915,16.644,0.002
193.75,371.900,0.07949,16.714,0.002
194.55,372.200,0.07982,16.784,0.002
195.34,372.500,0.08015,16.852,0.002
196.09,372.800,0.08044,16.916,0.002
196.80,373.100,0.08073,16.978,0.002
197.51,373.400,0.08107,17.038,0.002
198.17,373.700,0.08131,17.095,0.002
198.77,374.000,0.08161,17.147,0.002
199.36,374.300,0.08186,17.199,0.002
199.87,374.600,0.08210,17.242,0.002
200.41,374.900,0.08231,17.289,0.002
200.88,375.200,0.08256,17.329,0.002
201.36,375.500,0.08277,17.371,0.002
201.81,375.800,0.08298,17.410,0.002
202.28,376.100,0.08318,17.450,0.002
202.73,376.400,0.08339,17.489,0.002
203.15,376.700,0.08360,17.525,0.002
203.59,377.000,0.08381,17.563,0.002
204.02,377.300,0.08397,17.600,0.002
204.49,377.600,0.08418,17.641,0.002
204.95,377.900,0.08439,17.681,0.002
205.44,378.200,0.08460,17.723,0.002
205.95,378.500,0.08485,17.767,0.002
206.41,378.800,0.08505,17.806,0.002
206.89,379.100,0.08526,17.848,0.002
207.37,379.400,0.08547,17.889,0.002
207.88,379.700,0.08572,17.933,0.002
208.36,380.000,0.08593,17.975,0.002
208.82,380.300,0.08618,18.015,0.002
209.29,380.600,0.08643,18.055,0.002
209.69,380.900,0.08668,18.090,0.002
210.12,381.200,0.08688,18.126,0.002
210.51,381.500,0.08713,18.160,0.002
211.01,381.800,0.08742,18.204,0.002
211.56,382.100,0.08767,18.251,0.002
212.19,382.400,0.08796,18.305,0.002
212.84,382.700,0.08825,18.361,0.002
213.55,383.000,0.08859,18.423,0.002
214.30,383.300,0.08892,18.488,0.002
215.09,383.600,0.08925,18.555,0.002
215.81,383.900,0.08958,18.617,0.002
216.49,384.200,0.08988,18.676,0.002
217.11,384.500,0.09021,18.730,0.002
217.76,384.800,0.09050,18.786,0.002
218.33,385.100,0.09079,18.835,0.002
218.83,385.400,0.09108,18.878,0.002
219.24,385.700,0.09133,18.914,0.002
219.64,386.000,0.09154,18.948,0.002
220.03,386.300,0.09179,18.982,0.002
220.49,386.600,0.09199,19.021,0.002
220.91,386.900,0.09220,19.057,0.002
221.33,387.200,0.09241,19.093,0.002
221.76,387.500,0.09266,19.130,0.002
222.20,387.800,0.09287,19.169,0.002
222.59,388.100,0.09303,19.203,0.002
222.99,388.400,0.09324,19.237,0.002
223.40,388.700,0.09345,19.272,0.002
223.91,389.000,0.09366,19.317,0.002
224.40,389.300,0.09386,19.358,0.002
224.91,389.600,0.09407,19.402,0.002
225.42,389.900,0.09432,19.446,0.002
225.95,390.200,0.09453,19.493,0.002
226.52,390.500,0.09474,19.541,0.002
227.10,390.800,0.09499,19.591,0.002
227.71,391.100,0.09524,19.644,0.002
228.30,391.400,0.09544,19.695,0.002
228.93,391.700,0.09569,19.749,0.002
229.55,392.000,0.09594,19.803,0.002
230.08,392.300,0.09619,19.849,0.002
230.55,392.600,0.09644,19.889,0.002
231.07,392.900,0.09669,19.934,0.002
231.48,393.200,0.09694,19.970,0.002
232.33,393.500,0.09723,20.043,0.002
233.18,393.800,0.09752,20.116,0.002
233.96,394.100,0.09781,20.184,0.002
234.84,394.400,0.09814,20.259,0.002
235.85,394.700,0.09848,20.346,0.002
236.75,395.000,0.09877,20.424,0.002
237.55,395.300,0.09910,20.493,0.002
238.46,395.600,0.09943,20.572,0.002
239.10,395.900,0.09972,20.627,0.002
239.91,396.200,0.10006,20.696,0.002
240.64,396.500,0.10031,20.759,0.002
241.31,396.800,0.10060,20.817,0.002
241.95,397.100,0.10085,20.873,0.002
242.52,397.400,0.10110,20.922,0.002
242.89,397.700,0.10130,20.953,0.002
243.47,398.000,0.10155,21.004,0.002
244.04,398.300,0.10176,21.053,0.002
244.62,398.600,0.10197,21.103,0.002
245.07,398.900,0.10218,21.141,0.002
245.59,399.200,0.10238,21.186,0.002
246.11,399.500,0.10259,21.231,0.002
246.72,399.800,0.10280,21.284,0.002
247.14,400.100,0.10301,21.320,0.002
247.74,400.400,0.10321,21.372,0.002
248.34,400.700,0.10342,21.424,0.002
248.83,401.000,0.10363,21.466,0.002
249.40,401.300,0.10388,21.515,0.002
249.77,401.600,0.10409,21.547,0.002
250.33,401.900,0.10434,21.595,0.002
250.97,402.200,0.10459,21.651,0.002
251.54,402.500,0.10479,21.700,0.002
252.20,402.800,0.10504,21.757,0.002
252.86,403.100,0.10529,21.813,0.002
253.49,403.400,0.10554,21.868,0.002
254.17,403.700,0.10579,21.927,0.002
254.85,404.000,0.10604,21.985,0.002
255.55,404.300,0.10629,22.046,0.002
256.29,404.600,0.10658,22.110,0.002
256.98,404.900,0.10687,22.169,0.002
257.78,405.200,0.10716,22.238,0.002
258.56,405.500,0.10745,22.305,0.002
259.33,405.800,0.10774,22.372,0.002
260.17,406.100,0.10808,22.445,0.002
261.02,406.400,0.10841,22.518,0.002
261.79,406.700,0.10874,22.584,0.002
262.51,407.000,0.10903,22.647,0.002
10.47,407.080,0.10912,0.903,0.002