File: data-files/CWRU/0900-05-50C-1.txt
""
"Test Method","Will_Huddleston_Disks.msm"
"Sample I. D.","900-5-50C.mss"
"Specimen Number","1"

"Load (N)","Time (s)","Extension (mm)","Stress (MPa)","Strain (mm/mm)"

3.61,0.200,-0.06404,0.484,-0.001
3.61,0.500,-0.06404,0.483,-0.001
3.62,0.800,-0.06400,0.485,-0.001
3.61,1.100,-0.06400,0.484,-0.001
3.61,1.400,-0.06400,0.484,-0.001
3.61,1.700,-0.06396,0.483,-0.001
3.61,2.000,-0.06396,0.484,-0.001
3.61,2.300,-0.06391,0.483,-0.001
3.60,2.600,-0.06387,0.482,-0.001
3.59,2.900,-0.06383,0.482,-0.001
3.61,3.200,-0.06375,0.484,-0.001
3.64,3.500,-0.06367,0.487,-0.001
3.71,3.800,-0.06354,0.497,-0.001
3.85,4.100,-0.06337,0.516,-0.001
3.96,4.400,-0.06317,0.530,-0.001
4.08,4.700,-0.06296,0.546,-0.001
4.14,5.000,-0.06275,0.555,-0.001
4.22,5.300,-0.06254,0.566,-0.001
4.28,5.600,-0.06234,0.573,-0.001
4.35,5.900,-0.06213,0.583,-0.001
4.39,6.200,-0.06192,0.589,-0.001
4.45,6.500,-0.06167,0.596,-0.001
4.51,6.800,-0.06146,0.604,-0.001
4.55,7.100,-0.06126,0.610,-0.001
4.62,7.400,-0.06101,0.619,-0.001
4.66,7.700,-0.06076,0.624,-0.001
4.72,8.000,-0.06051,0.633,-0.001
4.77,8.300,-0.06022,0.639,-0.001
4.84,8.600,-0.05993,0.649,-0.001
4.90,8.900,-0.05963,0.656,-0.001
4.96,9.200,-0.05930,0.665,-0.001
5.03,9.500,-0.05901,0.674,-0.001
5.07,9.800,-0.05872,0.679,-0.001
5.12,10.100,-0.05843,0.685,-0.001
5.19,10.400,-0.05814,0.695,-0.001
5.24,10.700,-0.05785,0.702,-0.001
5.30,11.000,-0.05756,0.710,-0.001
5.34,11.300,-0.05731,0.716,-0.001
5.38,11.600,-0.05706,0.721,-0.001
5.41,11.900,-0.05685,0.724,-0.001
5.45,12.200,-0.05660,0.731,-0.001
5.50,12.500,-0.05639,0.736,-0.001
5.51,12.800,-0.05619,0.738,-0.001
5.56,13.100,-0.05598,0.744,-0.001
5.57,13.400,-0.05577,0.747,-0.001
5.63,13.700,-0.05556,0.754,-0.001
5.65,14.000,-0.05540,0.756,-0.001
5.69,14.300,-0.05519,0.763,-0.001
5.73,14.600,-0.05498,0.768,-0.001
5.78,14.900,-0.05477,0.774,-0.001
5.80,15.200,-0.05456,0.778,-0.001
5.86,15.500,-0.05436,0.785,-0.001
5.89,15.800,-0.05415,0.789,-0.001
5.94,16.100,-0.05390,0.796,-0.001
5.97,16.400,-0.05369,0.800,-0.001
6.02,16.700,-0.05348,0.807,-0.001
6.07,17.000,-0.05323,0.813,-0.001
6.11,17.300,-0.05303,0.818,-0.001
6.15,17.600,-0.05278,0.824,-0.001
6.21,17.900,-0.05257,0.832,-0.001
6.23,18.200,-0.05232,0.835,-0.001
6.28,18.500,-0.05211,0.842,-0.001
6.33,18.800,-0.05186,0.848,-0.001
6.38,19.100,-0.05161,0.855,-0.001
6.43,19.400,-0.05136,0.862,-0.001
6.49,19.700,-0.05107,0.870,-0.001
6.56,20.000,-0.05078,0.879,-0.001
6.61,20.300,-0.05049,0.886,-0.001
6.67,20.600,-0.05020,0.893,-0.001
6.72,20.900,-0.04987,0.901,-0.001
6.78,21.200,-0.04954,0.908,-0.001
6.82,21.500,-0.04925,0.914,-0.001
6.88,21.800,-0.04891,0.922,-0.001
6.94,22.100,-0.04862,0.930,-0.001
7.00,22.400,-0.04833,0.937,-0.001
7.02,22.700,-0.04804,0.941,-0.001
7.09,23.000,-0.04779,0.950,-0.001
7.12,23.300,-0.04754,0.954,-0.001
7.17,23.600,-0.04729,0.960,-0.001
7.21,23.900,-0.04708,0.965,-0.001
7.25,24.200,-0.04688,0.971,-0.001
7.28,24.500,-0.04663,0.976,-0.001
7.31,24.800,-0.04642,0.979,-0.001
7.36,25.100,-0.04621,0.986,-0.001
7.39,25.400,-0.04600,0.991,-0.001
7.42,25.700,-0.04584,0.995,-0.001
7.46,26.000,-0.04563,0.999,-0.001
7.51,26.300,-0.04542,1.006,-0.001
7.54,26.600,-0.04521,1.011,-0.001
7.58,26.900,-0.04501,1.016,-0.001
7.64,27.200,-0.04476,1.024,-0.001
7.67,27.500,-0.04455,1.028,-0.001
7.75,27.800,-0.04434,1.038,-0.001
7.78,28.100,-0.04409,1.043,-0.001
7.82,28.400,-0.04388,1.048,-0.001
7.86,28.700,-0.04364,1.053,-0.001
7.92,29.000,-0.04343,1.060,-0.001
7.96,29.300,-0.04318,1.066,-0.001
8.00,29.600,-0.04297,1.071,-0.001
8.08,29.900,-0.04272,1.082,-0.001
8.10,30.200,-0.04247,1.085,-0.001
8.15,30.500,-0.04218,1.092,-0.001
8.21,30.800,-0.04193,1.099,-0.001
8.26,31.100,-0.04164,1.107,-0.001
8.32,31.400,-0.04139,1.115,-0.001
8.37,31.700,-0.04110,1.121,-0.001
8.44,32.000,-0.04077,1.130,-0.001
8.48,32.300,-0.04048,1.136,-0.001
8.54,32.600,-0.04014,1.144,-0.001
8.59,32.900,-0.03985,1.150,-0.001
8.65,33.200,-0.03956,1.159,-0.001
8.71,33.500,-0.03923,1.167,-0.001
8.75,33.800,-0.03894,1.173,-0.001
8.82,34.100,-0.03869,1.181,-0.001
8.88,34.400,-0.03840,1.189,-0.001
8.91,34.700,-0.03815,1.194,-0.001
8.96,35.000,-0.03790,1.200,-0.001
9.01,35.300,-0.03769,1.207,-0.001
9.06,35.600,-0.03744,1.214,-0.001
9.10,35.900,-0.03724,1.219,-0.001
9.13,36.200,-0.03703,1.224,-0.001
9.17,36.500,-0.03682,1.229,-0.001
9.19,36.800,-0.03661,1.231,-0.001
9.24,37.100,-0.03640,1.238,-0.001
9.27,37.400,-0.03620,1.241,-0.001
9.32,37.700,-0.03599,1.248,-0.001
9.35,38.000,-0.03582,1.253,-0.001
9.40,38.300,-0.03557,1.259,-0.001
9.43,38.600,-0.03537,1.264,-0.001
9.49,38.900,-0.03516,1.271,-0.001
9.54,39.200,-0.03495,1.278,-0.001
9.59,39.500,-0.03474,1.284,-0.001
9.64,39.800,-0.03453,1.291,-0.001
9.68,40.100,-0.03429,1.297,-0.001
9.72,40.400,-0.03408,1.302,-0.001
9.76,40.700,-0.03383,1.308,-0.001
9.81,41.000,-0.03358,1.314,-0.001
9.84,41.300,-0.03337,1.318,-0.001
9.91,41.600,-0.03312,1.328,-0.001
9.96,41.900,-0.03291,1.335,-0.001
10.01,42.200,-0.03262,1.342,-0.001
10.08,42.500,-0.03237,1.350,-0.001
10.13,42.800,-0.03212,1.357,-0.001
10.20,43.100,-0.03179,1.367,-0.001
10.26,43.400,-0.03150,1.375,-0.001
10.31,43.700,-0.03121,1.381,-0.001
10.39,44.000,-0.03088,1.392,-0.001
10.47,44.300,-0.03055,1.403,-0.001
10.52,44.600,-0.03025,1.409,-0.001
10.60,44.900,-0.02992,1.420,-0.001
10.65,45.200,-0.02963,1.427,-0.001
10.70,45.500,-0.02934,1.433,-0.001
10.77,45.800,-0.02905,1.443,-0.001
10.83,46.100,-0.02880,1.450,-0.001
10.87,46.400,-0.02855,1.457,-0.001
10.90,46.700,-0.02830,1.461,-0.001
10.97,47.000,-0.02809,1.470,-0.001
11.01,47.300,-0.02789,1.474,-0.001
11.06,47.600,-0.02768,1.482,-0.001
11.10,47.900,-0.02747,1.487,-0.001
11.13,48.200,-0.02726,1.491,-0.001
11.18,48.500,-0.02705,1.497,-0.001
11.22,48.800,-0.02685,1.503,-0.001
11.24,49.100,-0.02668,1.506,-0.001
11.30,49.400,-0.02647,1.513,-0.001
11.35,49.700,-0.02627,1.520,-0.001
11.40,50.000,-0.02606,1.528,-0.001
11.45,50.300,-0.02581,1.534,-0.001
11.49,50.600,-0.02560,1.539,-0.001
11.53,50.900,-0.02539,1.545,0.000
11.58,51.200,-0.02514,1.552,0.000
11.64,51.500,-0.02494,1.559,0.000
11.68,51.800,-0.02469,1.565,0.000
11.75,52.100,-0.02448,1.573,0.000
11.79,52.400,-0.02423,1.580,0.000
11.84,52.700,-0.02398,1.586,0.000
11.89,53.000,-0.02373,1.593,0.000
11.94,53.300,-0.02348,1.599,0.000
12.00,53.600,-0.02323,1.608,0.000
12.08,53.900,-0.02298,1.618,0.000
12.13,54.200,-0.02269,1.625,0.000
12.20,54.500,-0.02240,1.634,0.000
12.27,54.800,-0.02211,1.644,0.000
12.36,55.100,-0.02178,1.655,0.000
12.43,55.400,-0.02144,1.666,0.000
12.50,55.700,-0.02115,1.675,0.000
12.58,56.000,-0.02082,1.686,0.000
12.65,56.300,-0.02049,1.694,0.000
12.70,56.600,-0.02020,1.702,0.000
12.76,56.900,-0.01991,1.709,0.000
12.83,57.200,-0.01962,1.718,0.000
12.87,57.500,-0.01937,1.725,0.000
12.94,57.800,-0.01912,1.733,0.000
12.96,58.100,-0.01887,1.736,0.000
13.02,58.400,-0.01866,1.744,0.000
13.07,58.700,-0.01841,1.751,0.000
13.10,59.000,-0.01820,1.756,0.000
13.16,59.300,-0.01800,1.763,0.000
13.19,59.600,-0.01779,1.767,0.000
13.25,59.900,-0.01762,1.775,0.000
13.30,60.200,-0.01741,1.782,0.000
13.35,60.500,-0.01721,1.788,0.000
13.40,60.800,-0.01700,1.795,0.000
13.45,61.100,-0.01679,1.802,0.000
13.49,61.400,-0.01658,1.808,0.000
13.55,61.700,-0.01637,1.816,0.000
13.60,62.000,-0.01613,1.822,0.000
13.66,62.300,-0.01592,1.830,0.000
13.72,62.600,-0.01567,1.838,0.000
13.75,62.900,-0.01546,1.842,0.000
13.82,63.200,-0.01521,1.851,0.000
13.87,63.500,-0.01500,1.858,0.000
13.94,63.800,-0.01475,1.868,0.000
13.98,64.100,-0.01450,1.873,0.000
14.06,64.400,-0.01426,1.883,0.000
14.11,64.700,-0.01405,1.890,0.000
14.17,65.000,-0.01380,1.899,0.000
14.26,65.300,-0.01351,1.911,0.000
14.34,65.600,-0.01322,1.921,0.000
14.41,65.900,-0.01297,1.931,0.000
14.48,66.200,-0.01263,1.940,0.000
14.57,66.500,-0.01234,1.952,0.000
14.66,66.800,-0.01201,1.963,0.000
14.74,67.100,-0.01168,1.975,0.000
14.82,67.400,-0.01135,1.985,0.000
14.88,67.700,-0.01106,1.993,0.000
14.95,68.000,-0.01076,2.003,0.000
15.03,68.300,-0.01047,2.014,0.000
15.08,68.600,-0.01018,2.021,0.000
15.15,68.900,-0.00993,2.030,0.000
15.21,69.200,-0.00968,2.037,0.000
15.26,69.500,-0.00943,2.044,0.000
15.30,69.800,-0.00919,2.050,0.000
15.36,70.100,-0.00898,2.057,0.000
15.42,70.400,-0.00877,2.066,0.000
15.47,70.700,-0.00856,2.072,0.000
15.53,71.000,-0.00835,2.081,0.000
15.57,71.300,-0.00815,2.086,0.000
15.61,71.600,-0.00794,2.091,0.000
15.68,71.900,-0.00773,2.101,0.000
15.72,72.200,-0.00752,2.106,0.000
15.78,72.500,-0.00732,2.114,0.000
15.84,72.800,-0.00711,2.122,0.000
15.89,73.100,-0.00690,2.129,0.000
15.97,73.400,-0.00665,2.139,0.000
16.02,73.700,-0.00644,2.146,0.000
16.08,74.000,-0.00624,2.154,0.000
16.15,74.300,-0.00599,2.164,0.000
16.20,74.600,-0.00578,2.170,0.000
16.29,74.900,-0.00553,2.182,0.000
16.35,75.200,-0.00528,2.190,0.000
16.41,75.500,-0.00507,2.198,0.000
16.46,75.800,-0.00482,2.205,0.000
16.53,76.100,-0.00457,2.215,0.000
16.63,76.400,-0.00432,2.227,0.000
16.68,76.700,-0.00407,2.234,0.000
16.77,77.000,-0.00378,2.247,0.000
16.84,77.300,-0.00349,2.256,0.000
16.95,77.600,-0.00320,2.270,0.000
17.04,77.900,-0.00287,2.283,0.000
17.14,78.200,-0.00254,2.296,0.000
17.21,78.500,-0.00220,2.305,0.000
17.30,78.800,-0.00191,2.318,0.000
17.38,79.100,-0.00158,2.329,0.000
17.46,79.400,-0.00125,2.339,0.000
17.52,79.700,-0.00096,2.348,0.000
17.62,80.000,-0.00067,2.361,0.000
17.67,80.300,-0.00042,2.367,0.000
17.74,80.600,-0.00017,2.377,0.000
17.80,80.900,0.00004,2.385,0.000
17.85,81.200,0.00029,2.391,0.000
17.94,81.500,0.00050,2.403,0.000
17.97,81.800,0.00070,2.408,0.000
18.04,82.100,0.00091,2.417,0.000
18.08,82.400,0.00112,2.422,0.000
18.16,82.700,0.00133,2.432,0.000
18.20,83.000,0.00154,2.438,0.000
18.26,83.300,0.00174,2.447,0.000
18.32,83.600,0.00191,2.454,0.000
18.41,83.900,0.00216,2.466,0.000
18.48,84.200,0.00237,2.475,0.000
18.55,84.500,0.00257,2.485,0.000
18.61,84.800,0.00282,2.493,0.000
18.66,85.100,0.00303,2.500,0.000
18.74,85.400,0.00324,2.510,0.000
18.84,85.700,0.00349,2.523,0.000
18.91,86.000,0.00370,2.533,0.000
18.97,86.300,0.00395,2.541,0.000
19.07,86.600,0.00420,2.554,0.000
19.13,86.900,0.00444,2.563,0.000
19.22,87.200,0.00469,2.575,0.000
19.28,87.500,0.00494,2.583,0.000
19.37,87.800,0.00519,2.595,0.000
19.45,88.100,0.00548,2.606,0.000
19.55,88.400,0.00573,2.618,0.000
19.65,88.700,0.00607,2.633,0.000
19.75,89.000,0.00636,2.646,0.000
19.85,89.300,0.00669,2.660,0.000
19.97,89.600,0.00702,2.675,0.000
20.07,89.900,0.00735,2.688,0.000
20.14,90.200,0.00764,2.698,0.000
20.25,90.500,0.00798,2.713,0.000
20.33,90.800,0.00827,2.723,0.000
20.43,91.100,0.00856,2.737,0.000
20.51,91.400,0.00885,2.747,0.000
20.59,91.700,0.00910,2.759,0.000
20.65,92.000,0.00935,2.766,0.000
20.72,92.300,0.00960,2.776,0.000
20.80,92.600,0.00981,2.786,0.000
20.86,92.900,0.01001,2.794,0.000
20.93,93.200,0.01026,2.804,0.000
21.00,93.500,0.01047,2.814,0.000
21.07,93.800,0.01064,2.822,0.000
21.14,94.100,0.01084,2.832,0.000
21.19,94.400,0.01105,2.839,0.000
21.26,94.700,0.01126,2.849,0.000
21.33,95.000,0.01147,2.858,0.000
21.42,95.300,0.01168,2.869,0.000
21.51,95.600,0.01192,2.882,0.000
21.57,95.900,0.01213,2.890,0.000
21.66,96.200,0.01238,2.901,0.000
21.74,96.500,0.01259,2.912,0.000
21.81,96.800,0.01284,2.922,0.000
21.90,97.100,0.01309,2.934,0.000
21.96,97.400,0.01330,2.942,0.000
22.07,97.700,0.01355,2.957,0.000
22.13,98.000,0.01379,2.965,0.000
22.21,98.300,0.01404,2.975,0.000
22.31,98.600,0.01429,2.989,0.000
22.40,98.900,0.01454,3.001,0.000
22.50,99.200,0.01479,3.014,0.000
22.61,99.500,0.01508,3.029,0.000
22.70,99.800,0.01537,3.041,0.000
22.82,100.100,0.01566,3.057,0.000
22.93,100.400,0.01600,3.072,0.000
23.07,100.700,0.01633,3.090,0.000
23.16,101.000,0.01662,3.103,0.000
23.28,101.300,0.01695,3.119,0.000
23.39,101.600,0.01724,3.133,0.000
23.50,101.900,0.01758,3.148,0.000
23.60,102.200,0.01787,3.161,0.000
23.69,102.500,0.01816,3.174,0.000
23.79,102.800,0.01841,3.187,0.000
23.86,103.100,0.01866,3.197,0.000
23.95,103.400,0.01891,3.209,0.000
24.02,103.700,0.01911,3.217,0.000
24.09,104.000,0.01936,3.227,0.000
24.19,104.300,0.01957,3.241,0.000
24.25,104.600,0.01978,3.249,0.000
24.33,104.900,0.01999,3.260,0.000
24.40,105.200,0.02019,3.268,0.000
24.48,105.500,0.02040,3.279,0.000
24.55,105.800,0.02061,3.289,0.000
24.63,106.100,0.02082,3.299,0.000
24.71,106.400,0.02103,3.310,0.000
24.78,106.700,0.02123,3.320,0.000
24.86,107.000,0.02144,3.331,0.000
24.97,107.300,0.02169,3.345,0.000
25.06,107.600,0.02190,3.357,0.000
25.14,107.900,0.02215,3.369,0.000
25.23,108.200,0.02236,3.380,0.000
25.30,108.500,0.02260,3.389,0.000
25.39,108.800,0.02281,3.402,0.000
25.49,109.100,0.02306,3.415,0.000
25.60,109.400,0.02327,3.430,0.000
25.69,109.700,0.02352,3.442,0.000
25.80,110.000,0.02377,3.456,0.000
25.89,110.300,0.02402,3.468,0.000
26.01,110.600,0.02427,3.484,0.000
26.13,110.900,0.02456,3.500,0.000
26.26,111.200,0.02485,3.518,0.000
26.39,111.500,0.02514,3.535,0.000
26.53,111.800,0.02547,3.555,0.001
26.69,112.100,0.02580,3.575,0.001
26.80,112.400,0.02614,3.590,0.001
26.95,112.700,0.02647,3.610,0.001
27.06,113.000,0.02676,3.625,0.001
27.18,113.300,0.02709,3.641,0.001
27.30,113.600,0.02738,3.658,0.001
27.37,113.900,0.02763,3.667,0.001
27.48,114.200,0.02788,3.681,0.001
27.56,114.500,0.02813,3.692,0.001
27.66,114.800,0.02838,3.706,0.001
27.73,115.100,0.02859,3.715,0.001
27.83,115.400,0.02880,3.728,0.001
27.92,115.700,0.02905,3.740,0.001
27.99,116.000,0.02921,3.749,0.001
28.05,116.300,0.02942,3.758,0.001
28.15,116.600,0.02963,3.771,0.001
28.21,116.900,0.02984,3.780,0.001
28.32,117.200,0.03004,3.794,0.001
28.40,117.500,0.03025,3.804,0.001
28.50,117.800,0.03046,3.818,0.001
28.59,118.100,0.03067,3.830,0.001
28.68,118.400,0.03087,3.843,0.001
28.81,118.700,0.03112,3.859,0.001
28.89,119.000,0.03133,3.871,0.001
29.00,119.300,0.03158,3.885,0.001
29.08,119.600,0.03179,3.896,0.001
29.19,119.900,0.03204,3.910,0.001
29.31,120.200,0.03225,3.927,0.001
29.41,120.500,0.03249,3.939,0.001
29.51,120.800,0.03274,3.954,0.001
29.63,121.100,0.03299,3.969,0.001
29.75,121.400,0.03320,3.986,0.001
29.87,121.700,0.03349,4.001,0.001
30.00,122.000,0.03374,4.019,0.001
30.14,122.300,0.03403,4.038,0.001
30.29,122.600,0.03432,4.058,0.001
30.43,122.900,0.03461,4.077,0.001
30.60,123.200,0.03495,4.099,0.001
30.76,123.500,0.03528,4.121,0.001
30.92,123.800,0.03561,4.142,0.001
31.05,124.100,0.03594,4.160,0.001
31.18,124.400,0.03623,4.177,0.001
31.31,124.700,0.03653,4.194,0.001
31.43,125.000,0.03682,4.211,0.001
31.57,125.300,0.03711,4.230,0.001
31.67,125.600,0.03736,4.242,0.001
31.78,125.900,0.03761,4.257,0.001
31.87,126.200,0.03786,4.269,0.001
31.96,126.500,0.03806,4.282,0.001
32.05,126.800,0.03831,4.294,0.001
32.16,127.100,0.03852,4.308,0.001
32.25,127.400,0.03873,4.321,0.001
32.34,127.700,0.03894,4.332,0.001
32.44,128.000,0.03914,4.345,0.001
32.53,128.300,0.03935,4.358,0.001
32.62,128.600,0.03956,4.370,0.001
32.71,128.900,0.03977,4.383,0.001
32.83,129.200,0.03997,4.398,0.001
32.95,129.500,0.04018,4.415,0.001
33.05,129.800,0.04039,4.428,0.001
33.16,130.100,0.04064,4.442,0.001
33.30,130.400,0.04085,4.461,0.001
33.40,130.700,0.04110,4.475,0.001
33.53,131.000,0.04130,4.492,0.001
33.65,131.300,0.04155,4.508,0.001
33.77,131.600,0.04176,4.525,0.001
33.88,131.900,0.04201,4.539,0.001
34.02,132.200,0.04226,4.557,0.001
34.13,132.500,0.04251,4.572,0.001
34.27,132.800,0.04272,4.591,0.001
34.40,133.100,0.04301,4.609,0.001
34.55,133.400,0.04326,4.629,0.001
34.71,133.700,0.04355,4.650,0.001
34.84,134.000,0.04384,4.667,0.001
35.02,134.300,0.04413,4.692,0.001
35.18,134.600,0.04446,4.713,0.001
35.36,134.900,0.04475,4.737,0.001
35.55,135.200,0.04513,4.762,0.001
35.68,135.500,0.04542,4.780,0.001
35.84,135.800,0.04575,4.802,0.001
35.97,136.100,0.04604,4.819,0.001
36.14,136.400,0.04633,4.841,0.001
36.26,136.700,0.04658,4.858,0.001
36.43,137.000,0.04687,4.880,0.001
36.51,137.300,0.04712,4.891,0.001
36.64,137.600,0.04737,4.909,0.001
36.74,137.900,0.04758,4.922,0.001
36.88,138.200,0.04783,4.941,0.001
36.97,138.500,0.04804,4.953,0.001
37.10,138.800,0.04824,4.970,0.001
37.20,139.100,0.04845,4.984,0.001
37.29,139.400,0.04866,4.996,0.001
37.42,139.700,0.04887,5.013,0.001
37.52,140.000,0.04908,5.026,0.001
37.63,140.300,0.04928,5.042,0.001
37.75,140.600,0.04949,5.057,0.001
37.89,140.900,0.04970,5.075,0.001
38.00,141.200,0.04995,5.091,0.001
38.14,141.500,0.05016,5.110,0.001
38.28,141.800,0.05036,5.129,0.001
38.41,142.100,0.05061,5.146,0.001
38.53,142.400,0.05086,5.161,0.001
38.67,142.700,0.05107,5.180,0.001
38.79,143.000,0.05132,5.196,0.001
38.90,143.300,0.05157,5.211,0.001
39.03,143.600,0.05178,5.229,0.001
39.17,143.900,0.05203,5.247,0.001
39.32,144.200,0.05228,5.267,0.001
39.46,144.500,0.05252,5.286,0.001
39.63,144.800,0.05282,5.308,0.001
39.78,145.100,0.05311,5.329,0.001
39.96,145.400,0.05340,5.353,0.001
40.14,145.700,0.05373,5.377,0.001
40.33,146.000,0.05406,5.403,0.001
40.52,146.300,0.05439,5.428,0.001
40.69,146.600,0.05473,5.452,0.001
40.86,146.900,0.05502,5.474,0.001
41.03,147.200,0.05535,5.496,0.001
41.18,147.500,0.05564,5.517,0.001
41.32,147.800,0.05593,5.536,0.001
41.47,148.100,0.05622,5.556,0.001
41.57,148.400,0.05647,5.569,0.001
41.70,148.700,0.05672,5.586,0.001
41.80,149.000,0.05693,5.600,0.001
41.93,149.300,0.05718,5.617,0.001
42.02,149.600,0.05739,5.630,0.001
42.12,149.900,0.05759,5.643,0.001
42.25,150.200,0.05780,5.660,0.001
42.34,150.500,0.05801,5.672,0.001
42.46,150.800,0.05822,5.688,0.001
42.57,151.100,0.05843,5.703,0.001
42.70,151.400,0.05863,5.720,0.001
42.80,151.700,0.05884,5.734,0.001
42.93,152.000,0.05905,5.751,0.001
43.05,152.300,0.05926,5.767,0.001
43.17,152.600,0.05951,5.783,0.001
43.30,152.900,0.05971,5.800,0.001
43.42,153.200,0.05996,5.816,0.001
43.53,153.500,0.06017,5.832,0.001
43.68,153.800,0.06042,5.851,0.001
43.78,154.100,0.06067,5.864,0.001
43.92,154.400,0.06088,5.884,0.001
44.05,154.700,0.06113,5.901,0.001
44.18,155.000,0.06138,5.918,0.001
44.31,155.300,0.06158,5.936,0.001
44.47,155.600,0.06187,5.958,0.001
44.59,155.900,0.06212,5.974,0.001
44.77,156.200,0.06242,5.998,0.001
44.93,156.500,0.06271,6.020,0.001
45.09,156.800,0.06300,6.041,0.001
45.26,157.100,0.06333,6.063,0.001
45.43,157.400,0.06366,6.086,0.001
45.59,157.700,0.06399,6.108,0.001
45.73,158.000,0.06433,6.126,0.001
45.88,158.300,0.06462,6.147,0.001
46.03,158.600,0.06495,6.167,0.001
46.21,158.900,0.06524,6.191,0.001
46.36,159.200,0.06553,6.211,0.001
46.51,159.500,0.06578,6.230,0.001
46.63,159.800,0.06603,6.247,0.001
46.75,160.100,0.06628,6.264,0.001
46.87,160.400,0.06649,6.279,0.001
46.98,160.700,0.06674,6.294,0.001
47.10,161.000,0.06694,6.310,0.001
47.22,161.300,0.06715,6.326,0.001
47.34,161.600,0.06736,6.341,0.001
47.46,161.900,0.06757,6.358,0.001
47.58,162.200,0.06778,6.374,0.001
47.70,162.500,0.06798,6.390,0.001
47.82,162.800,0.06819,6.407,0.001
47.95,163.100,0.06844,6.423,0.001
48.09,163.400,0.06865,6.442,0.001
48.23,163.700,0.06886,6.461,0.001
48.37,164.000,0.06911,6.479,0.001
48.48,164.300,0.06931,6.495,0.001
48.63,164.600,0.06956,6.515,0.001
48.78,164.900,0.06981,6.535,0.001
48.92,165.200,0.07002,6.554,0.001
49.07,165.500,0.07027,6.574,0.001
49.18,165.800,0.07052,6.589,0.001
49.34,166.100,0.07077,6.609,0.001
49.50,166.400,0.07102,6.631,0.001
49.65,166.700,0.07127,6.651,0.001
49.82,167.000,0.07152,6.674,0.001
50.01,167.300,0.07181,6.699,0.001
50.21,167.600,0.07210,6.727,0.001
50.43,167.900,0.07239,6.756,0.001
50.63,168.200,0.07272,6.783,0.001
50.86,168.500,0.07305,6.814,0.001
51.06,168.800,0.07339,6.840,0.001
51.24,169.100,0.07372,6.864,0.001
51.42,169.400,0.07401,6.888,0.001
51.60,169.700,0.07434,6.913,0.001
51.75,170.000,0.07463,6.933,0.001
51.91,170.300,0.07492,6.955,0.001
52.04,170.600,0.07517,6.972,0.001
52.19,170.900,0.07542,6.992,0.001
52.30,171.200,0.07567,7.007,0.001
52.43,171.500,0.07592,7.024,0.001
52.55,171.800,0.07613,7.040,0.001
52.66,172.100,0.07634,7.054,0.002
52.79,172.400,0.07654,7.071,0.002
52.90,172.700,0.07679,7.087,0.002
53.02,173.000,0.07700,7.103,0.002
53.11,173.300,0.07717,7.115,0.002
53.25,173.600,0.07738,7.134,0.002
53.37,173.900,0.07758,7.150,0.002
53.50,174.200,0.07779,7.167,0.002
53.66,174.500,0.07804,7.189,0.002
53.80,174.800,0.07825,7.207,0.002
53.94,175.100,0.07846,7.226,0.002
54.08,175.400,0.07866,7.245,0.002
54.21,175.700,0.07891,7.262,0.002
54.38,176.000,0.07912,7.285,0.002
54.51,176.300,0.07937,7.302,0.002
54.67,176.600,0.07958,7.324,0.002
54.81,176.900,0.07983,7.343,0.002
54.96,177.200,0.08003,7.363,0.002
55.12,177.500,0.08028,7.384,0.002
55.27,177.800,0.08053,7.404,0.002
55.42,178.100,0.08078,7.424,0.002
55.59,178.400,0.08103,7.447,0.002
55.75,178.700,0.08128,7.469,0.002
55.97,179.000,0.08157,7.498,0.002
56.16,179.300,0.08186,7.523,0.002
56.38,179.600,0.08220,7.553,0.002
56.59,179.900,0.08249,7.581,0.002
56.78,180.200,0.08282,7.606,0.002
56.99,180.500,0.08315,7.634,0.002
57.17,180.800,0.08344,7.658,0.002
57.35,181.100,0.08377,7.683,0.002
57.52,181.400,0.08407,7.706,0.002
57.69,181.700,0.08436,7.729,0.002
57.82,182.000,0.08461,7.747,0.002
57.97,182.300,0.08486,7.766,0.002
58.08,182.600,0.08510,7.780,0.002
58.23,182.900,0.08531,7.800,0.002
58.33,183.200,0.08552,7.815,0.002
58.46,183.500,0.08573,7.832,0.002
58.59,183.800,0.08598,7.849,0.002
58.69,184.100,0.08614,7.862,0.002
58.81,184.400,0.08635,7.879,0.002
58.89,184.700,0.08656,7.890,0.002
59.05,185.000,0.08677,7.910,0.002
59.17,185.300,0.08697,7.926,0.002
59.31,185.600,0.08718,7.946,0.002
59.43,185.900,0.08739,7.962,0.002
59.58,186.200,0.08760,7.981,0.002
59.71,186.500,0.08781,7.999,0.002
59.85,186.800,0.08801,8.018,0.002
60.01,187.100,0.08822,8.039,0.002
60.13,187.400,0.08847,8.055,0.002
60.32,187.700,0.08868,8.081,0.002
60.43,188.000,0.08893,8.096,0.002
60.61,188.300,0.08914,8.119,0.002
60.72,188.600,0.08938,8.134,0.002
60.88,188.900,0.08963,8.156,0.002
61.01,189.200,0.08984,8.173,0.002
61.18,189.500,0.09009,8.196,0.002
61.36,189.800,0.09034,8.221,0.002
61.51,190.100,0.09063,8.240,0.002
61.70,190.400,0.09088,8.266,0.002
61.88,190.700,0.09117,8.290,0.002
62.12,191.000,0.09146,8.321,0.002
62.30,191.300,0.09175,8.346,0.002
62.51,191.600,0.09209,8.375,0.002
62.70,191.900,0.09242,8.399,0.002
62.85,192.200,0.09271,8.419,0.002
63.01,192.500,0.09300,8.441,0.002
63.18,192.800,0.09329,8.464,0.002
63.33,193.100,0.09358,8.484,0.002
63.49,193.400,0.09383,8.505,0.002
63.63,193.700,0.09412,8.524,0.002
63.77,194.000,0.09437,8.542,0.002
63.91,194.300,0.09458,8.562,0.002
64.03,194.600,0.09483,8.578,0.002
64.15,194.900,0.09504,8.594,0.002
64.27,195.200,0.09524,8.610,0.002
64.40,195.500,0.09545,8.627,0.002
64.52,195.800,0.09566,8.643,0.002
64.64,196.100,0.09583,8.660,0.002
64.78,196.400,0.09603,8.678,0.002
64.90,196.700,0.09624,8.695,0.002
65.05,197.000,0.09645,8.715,0.002
65.21,197.300,0.09666,8.736,0.002
65.35,197.600,0.09686,8.755,0.002
65.50,197.900,0.09707,8.774,0.002
65.67,198.200,0.09728,8.798,0.002
65.84,198.500,0.09753,8.820,0.002
66.00,198.800,0.09774,8.842,0.002
66.18,199.100,0.09795,8.866,0.002
66.33,199.400,0.09819,8.886,0.002
66.52,199.700,0.09844,8.911,0.002
66.67,200.000,0.09869,8.932,0.002
66.84,200.300,0.09890,8.954,0.002
67.00,200.600,0.09915,8.976,0.002
67.19,200.900,0.09940,9.001,0.002
67.35,201.200,0.09965,9.023,0.002
67.53,201.500,0.09990,9.047,0.002
67.71,201.800,0.10019,9.071,0.002
67.91,202.100,0.10044,9.098,0.002
68.15,202.400,0.10073,9.130,0.002
68.39,202.700,0.10102,9.162,0.002
68.60,203.000,0.10135,9.190,0.002
68.84,203.300,0.10169,9.223,0.002
69.06,203.600,0.10198,9.252,0.002
69.25,203.900,0.10227,9.278,0.002
69.47,204.200,0.10260,9.307,0.002
69.67,204.500,0.10289,9.334,0.002
69.84,204.800,0.10314,9.356,0.002
69.98,205.100,0.10343,9.375,0.002
70.15,205.400,0.10368,9.398,0.002
70.30,205.700,0.10393,9.417,0.002
70.45,206.000,0.10414,9.438,0.002
70.59,206.300,0.10439,9.456,0.002
70.72,206.600,0.10459,9.474,0.002
70.85,206.900,0.10480,9.492,0.002
71.00,207.200,0.10501,9.512,0.002
71.14,207.500,0.10522,9.530,0.002
71.26,207.800,0.10538,9.546,0.002
71.39,208.100,0.10559,9.564,0.002
71.51,208.400,0.10580,9.580,0.002
71.66,208.700,0.10601,9.601,0.002
71.81,209.000,0.10621,9.620,0.002
71.98,209.300,0.10642,9.643,0.002
72.13,209.600,0.10663,9.663,0.002
72.29,209.900,0.10688,9.684,0.002
72.44,210.200,0.10709,9.705,0.002
72.62,210.500,0.10730,9.729,0.002
72.74,210.800,0.10754,9.744,0.002
72.89,211.100,0.10775,9.765,0.002
73.03,211.400,0.10800,9.783,0.002
73.20,211.700,0.10821,9.807,0.002
73.36,212.000,0.10846,9.828,0.002
73.51,212.300,0.10871,9.848,0.002
73.71,212.600,0.10896,9.874,0.002
73.90,212.900,0.10921,9.900,0.002
74.11,213.200,0.10946,9.928,0.002
74.33,213.500,0.10975,9.958,0.002
74.55,213.800,0.11004,9.987,0.002
74.80,214.100,0.11037,10.020,0.002
75.04,214.400,0.11070,10.053,0.002
75.29,214.700,0.11104,10.086,0.002
75.50,215.000,0.11133,10.115,0.002
75.69,215.300,0.11166,10.140,0.002
75.87,215.600,0.11199,10.165,0.002
76.06,215.900,0.11228,10.189,0.002
76.20,216.200,0.11257,10.208,0.002
76.36,216.500,0.11282,10.229,0.002
76.49,216.800,0.11307,10.246,0.002
76.62,217.100,0.11332,10.264,0.002
76.71,217.400,0.11353,10.276,0.002
76.82,217.700,0.11378,10.291,0.002
76.96,218.000,0.11399,10.310,0.002
77.08,218.300,0.11419,10.326,0.002
77.21,218.600,0.11440,10.344,0.002
77.32,218.900,0.11461,10.359,0.002
77.46,219.200,0.11482,10.377,0.002
77.56,219.500,0.11498,10.391,0.002
77.71,219.800,0.11519,10.410,0.002
77.85,220.100,0.11540,10.429,0.002
78.00,220.400,0.11561,10.449,0.002
78.13,220.700,0.11586,10.467,0.002
78.32,221.000,0.11606,10.492,0.002
78.48,221.300,0.11627,10.514,0.002
78.64,221.600,0.11652,10.536,0.002
78.81,221.900,0.11673,10.558,0.002
78.96,222.200,0.11698,10.578,0.002
79.13,222.500,0.11723,10.600,0.002
79.29,222.800,0.11744,10.622,0.002
79.47,223.100,0.11768,10.647,0.002
79.64,223.400,0.11793,10.669,0.002
79.81,223.700,0.11818,10.692,0.002
80.01,224.000,0.11843,10.718,0.002
80.20,224.300,0.11872,10.744,0.002
80.43,224.600,0.11897,10.774,0.002
80.66,224.900,0.11926,10.806,0.002
80.90,225.200,0.11960,10.838,0.002
81.11,225.500,0.11989,10.866,0.002
81.37,225.800,0.12022,10.901,0.002
81.57,226.100,0.12055,10.928,0.002
81.79,226.400,0.12088,10.958,0.002
81.98,226.700,0.12118,10.983,0.002
82.17,227.000,0.12151,11.008,0.002
82.34,227.300,0.12180,11.031,0.002
82.51,227.600,0.12209,11.054,0.002
82.68,227.900,0.12234,11.077,0.002
82.84,228.200,0.12263,11.098,0.002
82.98,228.500,0.12284,11.117,0.002
83.14,228.800,0.12309,11.137,0.002
83.28,229.100,0.12329,11.157,0.002
83.41,229.400,0.12354,11.174,0.002
83.56,229.700,0.12375,11.195,0.002
83.69,230.000,0.12396,11.212,0.002
83.83,230.300,0.12417,11.231,0.002
83.95,230.600,0.12437,11.247,0.002
84.11,230.900,0.12454,11.268,0.002
84.25,231.200,0.12475,11.287,0.002
84.44,231.500,0.12500,11.312,0.002
84.60,231.800,0.12521,11.334,0.002
84.78,232.100,0.12541,11.358,0.002
84.95,232.400,0.12566,11.381,0.002
85.15,232.700,0.12587,11.407,0.002
85.31,233.000,0.12612,11.429,0.002
85.48,233.300,0.12633,11.452,0.002
85.66,233.600,0.12658,11.475,0.002
85.79,233.900,0.12683,11.492,0.002
85.97,234.200,0.12708,11.517,0.003
86.14,234.500,0.12728,11.539,0.003
86.32,234.800,0.12753,11.564,0.003
86.47,235.100,0.12778,11.584,0.003
86.66,235.400,0.12807,11.610,0.003
86.86,235.700,0.12832,11.637,0.003
87.05,236.000,0.12861,11.662,0.003
87.24,236.300,0.12890,11.687,0.003
87.42,236.600,0.12920,11.712,0.003
87.60,236.900,0.12953,11.735,0.003
87.79,237.200,0.12986,11.760,0.003
87.96,237.500,0.13015,11.784,0.003
88.12,237.800,0.13048,11.805,0.003
88.24,238.100,0.13077,11.821,0.003
88.37,238.400,0.13107,11.838,0.003
88.50,238.700,0.13136,11.856,0.003
88.65,239.000,0.13165,11.876,0.003
88.72,239.300,0.13190,11.886,0.003
88.83,239.600,0.13215,11.900,0.003
88.86,239.900,0.13240,11.904,0.003
88.97,240.200,0.13260,11.918,0.003
89.03,240.500,0.13285,11.927,0.003
89.13,240.800,0.13306,11.941,0.003
89.18,241.100,0.13327,11.947,0.003
89.25,241.400,0.13348,11.956,0.003
89.32,241.700,0.13368,11.966,0.003
89.40,242.000,0.13389,11.977,0.003
89.45,242.300,0.13406,11.983,0.003
89.52,242.600,0.13427,11.992,0.003
89.61,242.900,0.13447,12.005,0.003
89.68,243.200,0.13472,12.014,0.003
89.76,243.500,0.13493,12.025,0.003
89.83,243.800,0.13514,12.034,0.003
89.91,244.100,0.13535,12.044,0.003
89.98,244.400,0.13559,12.055,0.003
90.03,244.700,0.13580,12.062,0.003
90.09,245.000,0.13605,12.069,0.003
90.10,245.300,0.13626,12.070,0.003
90.07,245.600,0.13651,12.066,0.003
89.95,245.900,0.13676,12.050,0.003
89.49,246.200,0.13697,11.989,0.003
86.42,246.500,0.13722,11.577,0.003
85.55,246.800,0.13746,11.461,0.003
85.43,247.100,0.13776,11.445,0.003
85.55,247.400,0.13801,11.461,0.003
85.68,247.700,0.13830,11.478,0.003
85.83,248.000,0.13859,11.499,0.003
85.92,248.300,0.13892,11.511,0.003
86.04,248.600,0.13921,11.527,0.003
86.06,248.900,0.13954,11.529,0.003
86.04,249.200,0.13988,11.526,0.003
86.11,249.500,0.14017,11.535,0.003
86.15,249.800,0.14046,11.541,0.003
86.18,250.100,0.14075,11.545,0.003
86.15,250.400,0.14100,11.542,0.003
86.19,250.700,0.14125,11.547,0.003
86.20,251.000,0.14150,11.548,0.003
86.19,251.300,0.14175,11.547,0.003
86.19,251.600,0.14195,11.547,0.003
86.19,251.900,0.14220,11.547,0.003
86.22,252.200,0.14241,11.551,0.003
86.24,252.500,0.14262,11.553,0.003
86.28,252.800,0.14283,11.559,0.003
86.33,253.100,0.14303,11.566,0.003
86.43,253.400,0.14320,11.579,0.003
86.51,253.700,0.14341,11.589,0.003
86.59,254.000,0.14362,11.600,0.003
86.66,254.300,0.14382,11.609,0.003
86.76,254.600,0.14403,11.623,0.003
86.83,254.900,0.14424,11.632,0.003
86.86,255.200,0.14449,11.637,0.003
86.89,255.500,0.14470,11.640,0.003
86.89,255.800,0.14490,11.641,0.003
86.89,256.100,0.14515,11.640,0.003
86.86,256.400,0.14536,11.637,0.003
86.86,256.700,0.14561,11.636,0.003
86.84,257.000,0.14586,11.633,0.003
86.85,257.300,0.14611,11.635,0.003
86.88,257.600,0.14632,11.640,0.003
86.94,257.900,0.14657,11.647,0.003
87.01,258.200,0.14682,11.656,0.003
87.09,258.500,0.14706,11.667,0.003
87.20,258.800,0.14736,11.681,0.003
87.31,259.100,0.14765,11.697,0.003
87.49,259.400,0.14794,11.721,0.003
87.67,259.700,0.14823,11.745,0.003
87.93,260.000,0.14856,11.779,0.003
88.13,260.300,0.14889,11.806,0.003
88.39,260.600,0.14923,11.841,0.003
88.63,260.900,0.14956,11.873,0.003
88.86,261.200,0.14989,11.904,0.003
89.09,261.500,0.15018,11.935,0.003
89.30,261.800,0.15047,11.963,0.003
89.47,262.100,0.15076,11.986,0.003
89.66,262.400,0.15101,12.012,0.003
89.83,262.700,0.15122,12.035,0.003
89.99,263.000,0.15147,12.055,0.003
90.15,263.300,0.15168,12.076,0.003
90.32,263.600,0.15193,12.100,0.003
90.49,263.900,0.15213,12.122,0.003
90.60,264.200,0.15234,12.138,0.003
90.78,264.500,0.15255,12.161,0.003
90.90,264.800,0.15272,12.177,0.003
91.09,265.100,0.15292,12.203,0.003
91.24,265.400,0.15313,12.222,0.003
91.41,265.700,0.15334,12.246,0.003
91.55,266.000,0.15355,12.265,0.003
91.75,266.300,0.15380,12.291,0.003
91.91,266.600,0.15400,12.313,0.003
92.07,266.900,0.15425,12.334,0.003
92.28,267.200,0.15446,12.362,0.003
92.42,267.500,0.15471,12.381,0.003
92.59,267.800,0.15492,12.403,0.003
92.72,268.100,0.15517,12.421,0.003
92.93,268.400,0.15542,12.450,0.003
93.04,268.700,0.15562,12.464,0.003
93.26,269.000,0.15587,12.493,0.003
93.36,269.300,0.15612,12.507,0.003
93.46,269.600,0.15637,12.520,0.003
93.54,269.900,0.15666,12.531,0.003
93.51,270.200,0.15691,12.528,0.003
93.37,270.500,0.15720,12.508,0.003
93.12,270.800,0.15749,12.474,0.003
93.04,271.100,0.15779,12.465,0.003
93.07,271.400,0.15812,12.468,0.003
93.15,271.700,0.15845,12.478,0.003
93.06,272.000,0.15878,12.467,0.003
92.84,272.300,0.15907,12.438,0.003
92.42,272.600,0.15936,12.381,0.003
92.21,272.900,0.15966,12.353,0.003
92.13,273.200,0.15995,12.342,0.003
92.08,273.500,0.16020,12.335,0.003
92.04,273.800,0.16045,12.330,0.003
92.00,274.100,0.16069,12.324,0.003
92.01,274.400,0.16094,12.327,0.003
92.02,274.700,0.16115,12.328,0.003
92.12,275.000,0.16136,12.341,0.003
92.19,275.300,0.16157,12.350,0.003
92.31,275.600,0.16178,12.366,0.003
92.36,275.900,0.16198,12.373,0.003
92.44,276.200,0.16219,12.383,0.003
92.51,276.500,0.16240,12.393,0.003
92.56,276.800,0.16261,12.400,0.003
92.62,277.100,0.16281,12.407,0.003
92.66,277.400,0.16302,12.413,0.003
92.70,277.700,0.16323,12.419,0.003
92.72,278.000,0.16344,12.421,0.003
92.74,278.300,0.16365,12.423,0.003
92.79,278.600,0.16389,12.431,0.003
92.91,278.900,0.16410,12.446,0.003
93.08,279.200,0.16435,12.470,0.003
93.26,279.500,0.16456,12.493,0.003
93.47,279.800,0.16481,12.521,0.003
93.61,280.100,0.16502,12.540,0.003
93.76,280.400,0.16527,12.560,0.003
93.93,280.700,0.16552,12.584,0.003
94.08,281.000,0.16576,12.604,0.003
94.26,281.300,0.16601,12.627,0.003
94.45,281.600,0.16630,12.653,0.003
94.69,281.900,0.16660,12.685,0.003
94.95,282.200,0.16689,12.720,0.003
95.22,282.500,0.16718,12.757,0.003
95.46,282.800,0.16751,12.788,0.003
95.61,283.100,0.16784,12.809,0.003
95.71,283.400,0.16817,12.822,0.003
95.86,283.700,0.16847,12.842,0.003
96.08,284.000,0.16876,12.872,0.003
96.30,284.300,0.16905,12.901,0.003
96.51,284.600,0.16934,12.929,0.003
96.70,284.900,0.16963,12.955,0.003
96.87,285.200,0.16988,12.977,0.003
97.04,285.500,0.17009,13.001,0.003
97.20,285.800,0.17034,13.021,0.003
97.37,286.100,0.17054,13.044,0.003
97.53,286.400,0.17075,13.066,0.003
97.69,286.700,0.17096,13.087,0.003
97.86,287.000,0.17121,13.110,0.003
98.00,287.300,0.17137,13.129,0.003
98.14,287.600,0.17158,13.148,0.003
98.30,287.900,0.17179,13.169,0.003
98.42,288.200,0.17200,13.185,0.003
98.62,288.500,0.17221,13.212,0.003
98.75,288.800,0.17241,13.230,0.003
98.88,289.100,0.17266,13.247,0.003
99.00,289.400,0.17287,13.263,0.003
99.14,289.700,0.17308,13.281,0.003
99.27,290.000,0.17333,13.299,0.003
99.41,290.300,0.17358,13.317,0.003
99.58,290.600,0.17378,13.341,0.003
99.75,290.900,0.17403,13.364,0.003
99.86,291.200,0.17428,13.378,0.003
100.00,291.500,0.17453,13.397,0.003
100.13,291.800,0.17478,13.414,0.003
100.21,292.100,0.17503,13.425,0.003
100.29,292.400,0.17528,13.435,0.003
100.42,292.700,0.17557,13.453,0.003
100.56,293.000,0.17586,13.472,0.003
100.75,293.300,0.17615,13.497,0.003
100.92,293.600,0.17644,13.520,0.003
101.12,293.900,0.17678,13.547,0.003
101.25,294.200,0.17711,13.563,0.003
101.32,294.500,0.17744,13.573,0.003
101.36,294.800,0.17777,13.579,0.003
101.38,295.100,0.17807,13.582,0.004
101.40,295.400,0.17836,13.584,0.004
101.40,295.700,0.17869,13.584,0.004
101.28,296.000,0.17894,13.568,0.004
101.18,296.300,0.17923,13.554,0.004
101.08,296.600,0.17948,13.541,0.004
100.99,296.900,0.17973,13.530,0.004
100.89,297.200,0.17994,13.516,0.004
100.80,297.500,0.18018,13.503,0.004
100.73,297.800,0.18039,13.494,0.004
100.61,298.100,0.18060,13.478,0.004
100.49,298.400,0.18081,13.462,0.004
100.38,298.700,0.18102,13.448,0.004
100.36,299.000,0.18122,13.445,0.004
100.36,299.300,0.18143,13.445,0.004
100.36,299.600,0.18164,13.445,0.004
100.31,299.900,0.18185,13.439,0.004
100.28,300.200,0.18210,13.434,0.004
100.14,300.500,0.18230,13.416,0.004
100.02,300.800,0.18251,13.400,0.004
99.97,301.100,0.18276,13.392,0.004
99.86,301.400,0.18301,13.378,0.004
99.74,301.700,0.18322,13.362,0.004
99.60,302.000,0.18347,13.343,0.004
99.52,302.300,0.18372,13.332,0.004
99.43,302.600,0.18397,13.320,0.004
99.42,302.900,0.18422,13.319,0.004
99.43,303.200,0.18446,13.321,0.004
99.52,303.500,0.18471,13.332,0.004
99.59,303.800,0.18500,13.342,0.004
99.69,304.100,0.18525,13.354,0.004
99.76,304.400,0.18555,13.365,0.004
99.86,304.700,0.18584,13.378,0.004
99.97,305.000,0.18617,13.393,0.004
100.06,305.300,0.18650,13.404,0.004
100.12,305.600,0.18679,13.413,0.004
100.15,305.900,0.18712,13.417,0.004
100.14,306.200,0.18746,13.416,0.004
100.08,306.500,0.18775,13.408,0.004
100.04,306.800,0.18804,13.402,0.004
99.96,307.100,0.18829,13.392,0.004
99.81,307.400,0.18858,13.371,0.004
99.54,307.700,0.18883,13.334,0.004
99.11,308.000,0.18904,13.277,0.004
98.70,308.300,0.18929,13.223,0.004
98.39,308.600,0.18949,13.180,0.004
98.15,308.900,0.18974,13.149,0.004
97.92,309.200,0.18995,13.118,0.004
97.77,309.500,0.19016,13.098,0.004
97.69,309.800,0.19032,13.087,0.004
97.63,310.100,0.19053,13.079,0.004
97.66,310.400,0.19074,13.083,0.004
97.63,310.700,0.19095,13.079,0.004
97.66,311.000,0.19116,13.083,0.004
97.67,311.300,0.19136,13.084,0.004
97.70,311.600,0.19157,13.089,0.004
97.76,311.900,0.19182,13.096,0.004
97.79,312.200,0.19203,13.100,0.004
97.84,312.500,0.19224,13.107,0.004
97.84,312.800,0.19248,13.108,0.004
97.84,313.100,0.19273,13.108,0.004
97.77,313.400,0.19294,13.097,0.004
97.76,313.700,0.19319,13.096,0.004
97.70,314.000,0.19340,13.088,0.004
97.67,314.300,0.19365,13.085,0.004
97.63,314.600,0.19390,13.079,0.004
97.61,314.900,0.19415,13.076,0.004
97.63,315.200,0.19444,13.079,0.004
97.68,315.500,0.19469,13.086,0.004
97.74,315.800,0.19498,13.094,0.004
97.78,316.100,0.19527,13.099,0.004
97.92,316.400,0.19560,13.118,0.004
98.03,316.700,0.19593,13.133,0.004
98.14,317.000,0.19627,13.148,0.004
98.23,317.300,0.19660,13.159,0.004
98.32,317.600,0.19693,13.172,0.004
98.38,317.900,0.19722,13.179,0.004
98.39,318.200,0.19751,13.181,0.004
98.36,318.500,0.19780,13.177,0.004
98.25,318.800,0.19805,13.163,0.004
98.10,319.100,0.19830,13.142,0.004
97.91,319.400,0.19851,13.116,0.004
97.73,319.700,0.19876,13.092,0.004
97.44,320.000,0.19897,13.054,0.004
97.24,320.300,0.19918,13.027,0.004
97.02,320.600,0.19938,12.998,0.004
96.85,320.900,0.19959,12.974,0.004
96.66,321.200,0.19980,12.949,0.004
96.52,321.500,0.20001,12.930,0.004
96.35,321.800,0.20021,12.908,0.004
96.19,322.100,0.20042,12.886,0.004
96.03,322.400,0.20059,12.865,0.004
95.89,322.700,0.20080,12.846,0.004
95.75,323.000,0.20105,12.828,0.004
95.47,323.300,0.20125,12.790,0.004
95.11,323.600,0.20146,12.742,0.004
94.67,323.900,0.20171,12.683,0.004
94.17,324.200,0.20192,12.616,0.004
93.84,324.500,0.20217,12.571,0.004
93.57,324.800,0.20238,12.535,0.004
93.35,325.100,0.20262,12.506,0.004
93.20,325.400,0.20287,12.485,0.004
93.03,325.700,0.20308,12.462,0.004
92.75,326.000,0.20333,12.426,0.004
92.39,326.300,0.20358,12.377,0.004
92.11,326.600,0.20383,12.339,0.004
91.95,326.900,0.20412,12.319,0.004
91.84,327.200,0.20441,12.304,0.004
91.71,327.500,0.20466,12.287,0.004
91.58,327.800,0.20499,12.269,0.004
91.42,328.100,0.20533,12.247,0.004
91.21,328.400,0.20566,12.219,0.004
90.94,328.700,0.20595,12.182,0.004
90.71,329.000,0.20628,12.152,0.004
90.49,329.300,0.20657,12.123,0.004
90.21,329.600,0.20686,12.085,0.004
89.90,329.900,0.20715,12.044,0.004
89.30,330.200,0.20740,11.963,0.004
88.37,330.500,0.20765,11.839,0.004
87.90,330.800,0.20790,11.776,0.004
87.64,331.100,0.20815,11.741,0.004
87.44,331.400,0.20836,11.714,0.004
87.24,331.700,0.20857,11.687,0.004
87.08,332.000,0.20877,11.665,0.004
86.99,332.300,0.20898,11.654,0.004
86.85,332.600,0.20919,11.635,0.004
86.83,332.900,0.20940,11.632,0.004
86.85,333.200,0.20961,11.635,0.004
86.96,333.500,0.20981,11.650,0.004
87.11,333.800,0.21002,11.670,0.004
87.27,334.100,0.21023,11.691,0.004
87.40,334.400,0.21044,11.709,0.004
87.59,334.700,0.21064,11.734,0.004
87.75,335.000,0.21085,11.755,0.004
87.96,335.300,0.21110,11.784,0.004
88.14,335.600,0.21131,11.807,0.004
88.34,335.900,0.21156,11.834,0.004
88.55,336.200,0.21177,11.862,0.004
88.76,336.500,0.21202,11.890,0.004
88.98,336.800,0.21227,11.920,0.004
89.25,337.100,0.21251,11.956,0.004
89.52,337.400,0.21276,11.992,0.004
89.79,337.700,0.21301,12.029,0.004
90.11,338.000,0.21326,12.072,0.004
90.46,338.300,0.21351,12.119,0.004
90.82,338.600,0.21380,12.167,0.004
91.16,338.900,0.21409,12.212,0.004
91.53,339.200,0.21438,12.263,0.004
91.87,339.500,0.21468,12.308,0.004
92.29,339.800,0.21501,12.363,0.004
92.64,340.100,0.21534,12.411,0.004
92.96,340.400,0.21563,12.454,0.004
93.28,340.700,0.21596,12.496,0.004
93.55,341.000,0.21625,12.532,0.004
93.78,341.300,0.21650,12.563,0.004
93.98,341.600,0.21680,12.590,0.004
94.16,341.900,0.21704,12.614,0.004
94.37,342.200,0.21729,12.642,0.004
94.54,342.500,0.21754,12.665,0.004
94.75,342.800,0.21775,12.693,0.004
94.95,343.100,0.21796,12.720,0.004
95.16,343.400,0.21821,12.748,0.004
95.35,343.700,0.21842,12.773,0.004
95.54,344.000,0.21858,12.799,0.004
95.71,344.300,0.21879,12.822,0.004
95.87,344.600,0.21900,12.843,0.004
95.99,344.900,0.21921,12.860,0.004
96.15,345.200,0.21937,12.881,0.004
96.29,345.500,0.21958,12.900,0.004
96.43,345.800,0.21983,12.919,0.004
96.56,346.100,0.22004,12.936,0.004
96.64,346.400,0.22024,12.946,0.004
96.57,346.700,0.22045,12.937,0.004
96.49,347.000,0.22070,12.926,0.004
96.32,347.300,0.22091,12.904,0.004
96.16,347.600,0.22116,12.882,0.004
96.15,347.900,0.22137,12.881,0.004
96.29,348.200,0.22162,12.899,0.004
96.43,348.500,0.22186,12.918,0.004
96.67,348.800,0.22211,12.950,0.004
96.89,349.100,0.22236,12.979,0.004
97.14,349.400,0.22261,13.013,0.004
97.44,349.700,0.22286,13.053,0.004
97.71,350.000,0.22315,13.090,0.004
97.99,350.300,0.22344,13.128,0.004
98.27,350.600,0.22373,13.165,0.004
98.51,350.900,0.22407,13.197,0.004
98.71,351.200,0.22440,13.224,0.004
98.86,351.500,0.22469,13.243,0.004
98.92,351.800,0.22502,13.251,0.004
98.97,352.100,0.22531,13.258,0.004
98.93,352.400,0.22565,13.254,0.004
98.87,352.700,0.22594,13.245,0.004
98.79,353.000,0.22619,13.234,0.004
98.67,353.300,0.22648,13.218,0.004
98.67,353.600,0.22673,13.219,0.004
98.71,353.900,0.22693,13.224,0.004
98.80,354.200,0.22718,13.236,0.004
98.94,354.500,0.22739,13.255,0.004
99.13,354.800,0.22760,13.281,0.004
99.27,355.100,0.22781,13.298,0.004
99.48,355.400,0.22802,13.327,0.004
99.63,355.700,0.22822,13.348,0.004
99.84,356.000,0.22843,13.375,0.004
100.03,356.300,0.22864,13.400,0.005
100.23,356.600,0.22885,13.427,0.005
100.41,356.900,0.22905,13.451,0.005
100.63,357.200,0.22926,13.481,0.005
100.86,357.500,0.22947,13.512,0.005
101.09,357.800,0.22972,13.542,0.005
101.35,358.100,0.22993,13.577,0.005
101.55,358.400,0.23018,13.604,0.005
101.78,358.700,0.23043,13.635,0.005
102.00,359.000,0.23063,13.665,0.005
102.19,359.300,0.23088,13.690,0.005
102.36,359.600,0.23113,13.713,0.005
102.57,359.900,0.23138,13.741,0.005
102.76,360.200,0.23163,13.767,0.005
102.97,360.500,0.23188,13.795,0.005
103.19,360.800,0.23213,13.823,0.005
103.42,361.100,0.23242,13.855,0.005
103.72,361.400,0.23271,13.895,0.005
103.97,361.700,0.23300,13.928,0.005
104.28,362.000,0.23329,13.969,0.005
104.57,362.300,0.23363,14.009,0.005
104.86,362.600,0.23396,14.048,0.005
105.09,362.900,0.23429,14.078,0.005
105.34,363.200,0.23462,14.112,0.005
105.60,363.500,0.23491,14.147,0.005
105.89,363.800,0.23520,14.185,0.005
106.20,364.100,0.23550,14.228,0.005
106.46,364.400,0.23579,14.261,0.005
106.71,364.700,0.23604,14.296,0.005
106.98,365.000,0.23628,14.331,0.005
107.21,365.300,0.23649,14.362,0.005
107.47,365.600,0.23674,14.397,0.005
107.72,365.900,0.23695,14.431,0.005
107.95,366.200,0.23716,14.461,0.005
108.18,366.500,0.23737,14.492,0.005
108.37,366.800,0.23757,14.518,0.005
108.58,367.100,0.23778,14.546,0.005
108.80,367.400,0.23799,14.575,0.005
109.03,367.680,0.23815,14.606,0.005