File: data-files/CWRU/0900-10-35A.txt
""
"Test Method","Will_Huddleston_Disks.msm"
"Sample I. D.","900-10-35A.mss"
"Specimen Number","1"

"Load (N)","Time (s)","Extension (mm)","Stress (MPa)","Strain (mm/mm)"

5.27,0.200,-0.03587,0.984,-0.001
5.26,0.300,-0.03587,0.981,-0.001
5.28,0.400,-0.03583,0.986,-0.001
5.26,0.500,-0.03583,0.981,-0.001
5.27,0.600,-0.03583,0.982,-0.001
5.25,0.700,-0.03583,0.980,-0.001
5.26,0.800,-0.03579,0.982,-0.001
5.27,0.900,-0.03579,0.984,-0.001
5.28,1.000,-0.03579,0.985,-0.001
5.26,1.100,-0.03575,0.981,-0.001
5.26,1.200,-0.03575,0.981,-0.001
5.27,1.300,-0.03575,0.983,-0.001
5.28,1.400,-0.03570,0.986,-0.001
5.27,1.500,-0.03570,0.983,-0.001
5.28,1.600,-0.03566,0.984,-0.001
5.27,1.700,-0.03566,0.983,-0.001
5.28,1.800,-0.03562,0.986,-0.001
5.29,1.900,-0.03562,0.986,-0.001
5.30,2.000,-0.03558,0.988,-0.001
5.33,2.100,-0.03554,0.993,-0.001
5.34,2.200,-0.03546,0.996,-0.001
5.40,2.300,-0.03537,1.008,-0.001
5.45,2.400,-0.03525,1.016,-0.001
5.57,2.500,-0.03508,1.039,-0.001
5.71,2.600,-0.03487,1.066,-0.001
5.82,2.700,-0.03462,1.085,-0.001
5.91,2.800,-0.03442,1.103,-0.001
5.97,2.900,-0.03425,1.113,-0.001
6.04,3.000,-0.03404,1.126,-0.001
6.09,3.100,-0.03383,1.135,-0.001
6.16,3.200,-0.03363,1.148,-0.001
6.19,3.300,-0.03346,1.154,-0.001
6.22,3.400,-0.03325,1.160,-0.001
6.25,3.500,-0.03305,1.166,-0.001
6.31,3.600,-0.03288,1.176,-0.001
6.34,3.700,-0.03267,1.183,-0.001
6.38,3.800,-0.03246,1.191,-0.001
6.41,3.900,-0.03230,1.195,-0.001
6.44,4.000,-0.03213,1.201,-0.001
6.47,4.100,-0.03196,1.207,-0.001
6.49,4.200,-0.03176,1.211,-0.001
6.53,4.300,-0.03163,1.217,-0.001
6.55,4.400,-0.03147,1.222,-0.001
6.58,4.500,-0.03130,1.226,-0.001
6.59,4.600,-0.03118,1.230,-0.001
6.63,4.700,-0.03101,1.237,-0.001
6.64,4.800,-0.03088,1.239,-0.001
6.68,4.900,-0.03072,1.246,-0.001
6.71,5.000,-0.03059,1.251,-0.001
6.73,5.100,-0.03047,1.255,-0.001
6.74,5.200,-0.03030,1.258,-0.001
6.78,5.300,-0.03018,1.265,-0.001
6.80,5.400,-0.03005,1.269,-0.001
6.84,5.500,-0.02993,1.275,-0.001
6.85,5.600,-0.02976,1.277,-0.001
6.86,5.700,-0.02964,1.280,-0.001
6.89,5.800,-0.02951,1.286,-0.001
6.91,5.900,-0.02935,1.290,-0.001
6.96,6.000,-0.02922,1.298,-0.001
6.97,6.100,-0.02906,1.300,-0.001
7.02,6.200,-0.02893,1.309,-0.001
7.03,6.300,-0.02876,1.312,-0.001
7.07,6.400,-0.02860,1.319,-0.001
7.11,6.500,-0.02847,1.326,-0.001
7.13,6.600,-0.02831,1.330,-0.001
7.15,6.700,-0.02814,1.334,-0.001
7.18,6.800,-0.02802,1.338,-0.001
7.21,6.900,-0.02785,1.345,-0.001
7.23,7.000,-0.02768,1.349,-0.001
7.27,7.100,-0.02752,1.356,-0.001
7.30,7.200,-0.02739,1.362,-0.001
7.33,7.300,-0.02723,1.368,-0.001
7.37,7.400,-0.02706,1.375,-0.001
7.39,7.500,-0.02689,1.378,-0.001
7.41,7.600,-0.02673,1.382,-0.001
7.45,7.700,-0.02656,1.389,-0.001
7.48,7.800,-0.02640,1.395,-0.001
7.51,7.900,-0.02623,1.401,-0.001
7.56,8.000,-0.02606,1.409,-0.001
7.60,8.100,-0.02590,1.418,-0.001
7.62,8.200,-0.02569,1.421,-0.001
7.66,8.300,-0.02552,1.429,-0.001
7.70,8.400,-0.02532,1.436,0.000
7.75,8.500,-0.02511,1.445,0.000
7.77,8.600,-0.02490,1.450,0.000
7.84,8.700,-0.02469,1.463,0.000
7.88,8.800,-0.02448,1.469,0.000
7.92,8.900,-0.02428,1.478,0.000
7.96,9.000,-0.02407,1.485,0.000
7.99,9.100,-0.02386,1.491,0.000
8.02,9.200,-0.02365,1.496,0.000
8.06,9.300,-0.02345,1.504,0.000
8.10,9.400,-0.02328,1.510,0.000
8.15,9.500,-0.02307,1.520,0.000
8.17,9.600,-0.02286,1.525,0.000
8.20,9.700,-0.02270,1.530,0.000
8.24,9.800,-0.02253,1.537,0.000
8.26,9.900,-0.02237,1.542,0.000
8.30,10.000,-0.02220,1.549,0.000
8.33,10.100,-0.02203,1.554,0.000
8.36,10.200,-0.02187,1.559,0.000
8.39,10.300,-0.02174,1.564,0.000
8.42,10.400,-0.02158,1.570,0.000
8.44,10.500,-0.02141,1.575,0.000
8.47,10.600,-0.02128,1.580,0.000
8.49,10.700,-0.02116,1.583,0.000
8.52,10.800,-0.02099,1.589,0.000
8.54,10.900,-0.02087,1.593,0.000
8.58,11.000,-0.02074,1.600,0.000
8.62,11.100,-0.02058,1.608,0.000
8.63,11.200,-0.02045,1.609,0.000
8.65,11.300,-0.02033,1.613,0.000
8.66,11.400,-0.02016,1.616,0.000
8.72,11.500,-0.02004,1.626,0.000
8.74,11.600,-0.01991,1.630,0.000
8.76,11.700,-0.01975,1.635,0.000
8.79,11.800,-0.01962,1.640,0.000
8.82,11.900,-0.01946,1.646,0.000
8.85,12.000,-0.01933,1.650,0.000
8.88,12.100,-0.01917,1.656,0.000
8.93,12.200,-0.01904,1.666,0.000
8.96,12.300,-0.01887,1.671,0.000
8.99,12.400,-0.01875,1.676,0.000
9.02,12.500,-0.01858,1.682,0.000
9.04,12.600,-0.01842,1.686,0.000
9.08,12.700,-0.01825,1.694,0.000
9.09,12.800,-0.01813,1.696,0.000
9.14,12.900,-0.01796,1.704,0.000
9.16,13.000,-0.01779,1.709,0.000
9.21,13.100,-0.01767,1.717,0.000
9.24,13.200,-0.01750,1.723,0.000
9.26,13.300,-0.01734,1.728,0.000
9.31,13.400,-0.01717,1.737,0.000
9.33,13.500,-0.01700,1.740,0.000
9.37,13.600,-0.01684,1.747,0.000
9.40,13.700,-0.01667,1.754,0.000
9.45,13.800,-0.01646,1.762,0.000
9.48,13.900,-0.01630,1.769,0.000
9.53,14.000,-0.01609,1.777,0.000
9.58,14.100,-0.01588,1.787,0.000
9.63,14.200,-0.01567,1.795,0.000
9.67,14.300,-0.01543,1.804,0.000
9.73,14.400,-0.01522,1.815,0.000
9.78,14.500,-0.01501,1.824,0.000
9.83,14.600,-0.01476,1.834,0.000
9.87,14.700,-0.01455,1.842,0.000
9.92,14.800,-0.01434,1.850,0.000
9.98,14.900,-0.01414,1.861,0.000
10.01,15.000,-0.01393,1.868,0.000
10.05,15.100,-0.01372,1.874,0.000
10.10,15.200,-0.01351,1.883,0.000
10.14,15.300,-0.01335,1.891,0.000
10.17,15.400,-0.01318,1.898,0.000
10.21,15.500,-0.01302,1.905,0.000
10.24,15.600,-0.01285,1.910,0.000
10.27,15.700,-0.01268,1.916,0.000
10.31,15.800,-0.01252,1.922,0.000
10.35,15.900,-0.01239,1.930,0.000
10.38,16.000,-0.01223,1.936,0.000
10.42,16.100,-0.01210,1.944,0.000
10.44,16.200,-0.01193,1.947,0.000
10.46,16.300,-0.01181,1.952,0.000
10.50,16.400,-0.01164,1.959,0.000
10.53,16.500,-0.01152,1.964,0.000
10.55,16.600,-0.01139,1.968,0.000
10.57,16.700,-0.01127,1.973,0.000
10.61,16.800,-0.01115,1.980,0.000
10.63,16.900,-0.01098,1.982,0.000
10.68,17.000,-0.01085,1.992,0.000
10.70,17.100,-0.01073,1.995,0.000
10.72,17.200,-0.01056,2.000,0.000
10.77,17.300,-0.01044,2.008,0.000
10.79,17.400,-0.01027,2.012,0.000
10.83,17.500,-0.01015,2.020,0.000
10.86,17.600,-0.00998,2.026,0.000
10.91,17.700,-0.00986,2.035,0.000
10.92,17.800,-0.00969,2.037,0.000
10.96,17.900,-0.00957,2.044,0.000
10.99,18.000,-0.00940,2.050,0.000
11.02,18.100,-0.00928,2.056,0.000
11.06,18.200,-0.00911,2.064,0.000
11.10,18.300,-0.00894,2.070,0.000
11.15,18.400,-0.00882,2.079,0.000
11.17,18.500,-0.00865,2.084,0.000
11.22,18.600,-0.00849,2.093,0.000
11.26,18.700,-0.00832,2.100,0.000
11.29,18.800,-0.00819,2.106,0.000
11.32,18.900,-0.00803,2.112,0.000
11.36,19.000,-0.00786,2.118,0.000
11.41,19.100,-0.00770,2.128,0.000
11.45,19.200,-0.00753,2.135,0.000
11.47,19.300,-0.00736,2.139,0.000
11.53,19.400,-0.00720,2.151,0.000
11.58,19.500,-0.00699,2.160,0.000
11.63,19.600,-0.00678,2.169,0.000
11.68,19.700,-0.00662,2.178,0.000
11.73,19.800,-0.00641,2.188,0.000
11.77,19.900,-0.00620,2.195,0.000
11.83,20.000,-0.00599,2.206,0.000
11.86,20.100,-0.00578,2.213,0.000
11.92,20.200,-0.00554,2.224,0.000
11.96,20.300,-0.00533,2.231,0.000
12.03,20.400,-0.00512,2.244,0.000
12.06,20.500,-0.00491,2.249,0.000
12.11,20.600,-0.00470,2.260,0.000
12.17,20.700,-0.00450,2.270,0.000
12.19,20.800,-0.00429,2.274,0.000
12.23,20.900,-0.00412,2.281,0.000
12.30,21.000,-0.00391,2.293,0.000
12.32,21.100,-0.00375,2.298,0.000
12.35,21.200,-0.00358,2.305,0.000
12.39,21.300,-0.00337,2.311,0.000
12.43,21.400,-0.00325,2.318,0.000
12.46,21.500,-0.00308,2.325,0.000
12.50,21.600,-0.00292,2.331,0.000
12.51,21.700,-0.00279,2.334,0.000
12.55,21.800,-0.00263,2.341,0.000
12.58,21.900,-0.00246,2.347,0.000
12.61,22.000,-0.00234,2.353,0.000
12.63,22.100,-0.00221,2.356,0.000
12.66,22.200,-0.00209,2.361,0.000
12.68,22.300,-0.00192,2.366,0.000
12.72,22.400,-0.00180,2.373,0.000
12.75,22.500,-0.00167,2.378,0.000
12.79,22.600,-0.00150,2.385,0.000
12.81,22.700,-0.00138,2.390,0.000
12.85,22.800,-0.00125,2.397,0.000
12.87,22.900,-0.00113,2.401,0.000
12.91,23.000,-0.00096,2.408,0.000
12.96,23.100,-0.00084,2.418,0.000
12.98,23.200,-0.00067,2.422,0.000
13.02,23.300,-0.00055,2.429,0.000
13.07,23.400,-0.00038,2.438,0.000
13.09,23.500,-0.00026,2.442,0.000
13.14,23.600,-0.00009,2.451,0.000
13.18,23.700,0.00007,2.459,0.000
13.22,23.800,0.00020,2.466,0.000
13.25,23.900,0.00037,2.472,0.000
13.30,24.000,0.00053,2.481,0.000
13.34,24.100,0.00066,2.488,0.000
13.38,24.200,0.00082,2.495,0.000
13.42,24.300,0.00099,2.503,0.000
13.45,24.400,0.00111,2.509,0.000
13.49,24.500,0.00128,2.516,0.000
13.54,24.600,0.00145,2.526,0.000
13.58,24.700,0.00161,2.533,0.000
13.62,24.800,0.00178,2.541,0.000
13.64,24.900,0.00190,2.545,0.000
13.69,25.000,0.00211,2.554,0.000
13.75,25.100,0.00228,2.564,0.000
13.79,25.200,0.00244,2.571,0.000
13.83,25.300,0.00261,2.580,0.000
13.90,25.400,0.00282,2.592,0.000
13.96,25.500,0.00303,2.604,0.000
14.01,25.600,0.00323,2.613,0.000
14.05,25.700,0.00340,2.621,0.000
14.11,25.800,0.00361,2.631,0.000
14.16,25.900,0.00386,2.641,0.000
14.23,26.000,0.00406,2.654,0.000
14.28,26.100,0.00427,2.664,0.000
14.32,26.200,0.00448,2.672,0.000
14.37,26.300,0.00465,2.681,0.000
14.42,26.400,0.00485,2.690,0.000
14.46,26.500,0.00506,2.697,0.000
14.52,26.600,0.00523,2.708,0.000
14.57,26.700,0.00544,2.717,0.000
14.61,26.800,0.00560,2.725,0.000
14.64,26.900,0.00577,2.731,0.000
14.68,27.000,0.00593,2.739,0.000
14.73,27.100,0.00610,2.748,0.000
14.75,27.200,0.00627,2.752,0.000
14.79,27.300,0.00643,2.759,0.000
14.82,27.400,0.00656,2.765,0.000
14.87,27.500,0.00672,2.774,0.000
14.91,27.600,0.00685,2.781,0.000
14.94,27.700,0.00701,2.786,0.000
14.99,27.800,0.00714,2.795,0.000
15.01,27.900,0.00731,2.800,0.000
15.04,28.000,0.00743,2.805,0.000
15.09,28.100,0.00756,2.815,0.000
15.11,28.200,0.00768,2.818,0.000
15.14,28.300,0.00785,2.824,0.000
15.18,28.400,0.00797,2.831,0.000
15.20,28.500,0.00810,2.836,0.000
15.25,28.600,0.00822,2.845,0.000
15.28,28.700,0.00834,2.850,0.000
15.32,28.800,0.00851,2.857,0.000
15.36,28.900,0.00864,2.864,0.000
15.41,29.000,0.00880,2.874,0.000
15.44,29.100,0.00893,2.879,0.000
15.47,29.200,0.00909,2.886,0.000
15.52,29.300,0.00922,2.896,0.000
15.58,29.400,0.00938,2.906,0.000
15.61,29.500,0.00951,2.911,0.000
15.65,29.600,0.00967,2.919,0.000
15.69,29.700,0.00980,2.927,0.000
15.73,29.800,0.00997,2.934,0.000
15.77,29.900,0.01013,2.941,0.000
15.82,30.000,0.01026,2.951,0.000
15.86,30.100,0.01042,2.958,0.000
15.90,30.200,0.01059,2.966,0.000
15.94,30.300,0.01075,2.974,0.000
15.98,30.400,0.01088,2.981,0.000
16.04,30.500,0.01105,2.992,0.000
16.07,30.600,0.01121,2.998,0.000
16.12,30.700,0.01138,3.007,0.000
16.17,30.800,0.01154,3.017,0.000
16.22,30.900,0.01171,3.025,0.000
16.27,31.000,0.01192,3.035,0.000
16.35,31.100,0.01208,3.049,0.000
16.41,31.200,0.01229,3.060,0.000
16.47,31.300,0.01250,3.072,0.000
16.52,31.400,0.01271,3.081,0.000
16.59,31.500,0.01292,3.094,0.000
16.67,31.600,0.01312,3.109,0.000
16.71,31.700,0.01333,3.116,0.000
16.76,31.800,0.01358,3.127,0.000
16.82,31.900,0.01379,3.138,0.000
16.88,32.000,0.01400,3.149,0.000
16.94,32.100,0.01420,3.160,0.000
17.00,32.200,0.01441,3.171,0.000
17.06,32.300,0.01462,3.183,0.000
17.11,32.400,0.01479,3.192,0.000
17.16,32.500,0.01499,3.200,0.000
17.21,32.600,0.01516,3.210,0.000
17.26,32.700,0.01537,3.219,0.000
17.32,32.800,0.01553,3.231,0.000
17.33,32.900,0.01566,3.233,0.000
17.39,33.000,0.01582,3.243,0.000
17.43,33.100,0.01599,3.251,0.000
17.46,33.200,0.01612,3.256,0.000
17.50,33.300,0.01628,3.265,0.000
17.55,33.400,0.01641,3.273,0.000
17.60,33.500,0.01653,3.282,0.000
17.62,33.600,0.01670,3.287,0.000
17.64,33.700,0.01682,3.291,0.000
17.71,33.800,0.01695,3.303,0.000
17.75,33.900,0.01707,3.310,0.000
17.77,34.000,0.01724,3.314,0.000
17.82,34.100,0.01736,3.324,0.000
17.87,34.200,0.01749,3.334,0.000
17.90,34.300,0.01765,3.340,0.000
17.96,34.400,0.01778,3.350,0.000
17.99,34.500,0.01790,3.355,0.000
18.03,34.600,0.01807,3.363,0.000
18.08,34.700,0.01819,3.372,0.000
18.13,34.800,0.01836,3.382,0.000
18.17,34.900,0.01853,3.389,0.000
18.22,35.000,0.01865,3.398,0.000
18.26,35.100,0.01882,3.407,0.000
18.29,35.200,0.01894,3.411,0.000
18.35,35.300,0.01911,3.423,0.000
18.38,35.400,0.01927,3.429,0.000
18.44,35.500,0.01944,3.440,0.000
18.48,35.600,0.01956,3.448,0.000
18.53,35.700,0.01973,3.457,0.000
18.57,35.800,0.01990,3.465,0.000
18.64,35.900,0.02006,3.477,0.000
18.67,36.000,0.02019,3.483,0.000
18.73,36.100,0.02035,3.493,0.000
18.79,36.200,0.02052,3.505,0.000
18.83,36.300,0.02069,3.512,0.000
18.88,36.400,0.02085,3.522,0.000
18.94,36.500,0.02106,3.533,0.000
18.99,36.600,0.02123,3.543,0.000
19.06,36.700,0.02139,3.556,0.000
19.14,36.800,0.02160,3.570,0.000
19.20,36.900,0.02181,3.582,0.000
19.25,37.000,0.02202,3.591,0.000
19.33,37.100,0.02222,3.606,0.000
19.42,37.200,0.02243,3.622,0.000
19.48,37.300,0.02264,3.634,0.000
19.55,37.400,0.02285,3.646,0.000
19.63,37.500,0.02310,3.662,0.000
19.71,37.600,0.02330,3.676,0.000
19.74,37.700,0.02351,3.683,0.000
19.83,37.800,0.02372,3.699,0.000
19.90,37.900,0.02393,3.713,0.000
19.94,38.000,0.02414,3.720,0.000
20.00,38.100,0.02434,3.731,0.000
20.07,38.200,0.02451,3.743,0.000
20.12,38.300,0.02468,3.753,0.000
20.15,38.400,0.02484,3.758,0.000
20.21,38.500,0.02501,3.770,0.000
20.26,38.600,0.02517,3.778,0.000
20.30,38.700,0.02534,3.787,0.000
20.35,38.800,0.02551,3.795,0.001
20.39,38.900,0.02563,3.803,0.001
20.45,39.000,0.02580,3.814,0.001
20.48,39.100,0.02592,3.821,0.001
20.53,39.200,0.02609,3.829,0.001
20.57,39.300,0.02621,3.837,0.001
20.60,39.400,0.02634,3.843,0.001
20.66,39.500,0.02650,3.853,0.001
20.70,39.600,0.02663,3.861,0.001
20.75,39.700,0.02675,3.871,0.001
20.78,39.800,0.02692,3.877,0.001
20.83,39.900,0.02704,3.886,0.001
20.88,40.000,0.02717,3.894,0.001
20.91,40.100,0.02734,3.901,0.001
20.97,40.200,0.02746,3.911,0.001
21.01,40.300,0.02763,3.919,0.001
21.07,40.400,0.02775,3.929,0.001
21.12,40.500,0.02792,3.939,0.001
21.16,40.600,0.02808,3.947,0.001
21.22,40.700,0.02821,3.957,0.001
21.28,40.800,0.02837,3.969,0.001
21.32,40.900,0.02854,3.977,0.001
21.39,41.000,0.02871,3.989,0.001
21.43,41.100,0.02883,3.997,0.001
21.48,41.200,0.02900,4.006,0.001
21.53,41.300,0.02916,4.017,0.001
21.59,41.400,0.02933,4.028,0.001
21.63,41.500,0.02950,4.035,0.001
21.70,41.600,0.02962,4.048,0.001
21.74,41.700,0.02979,4.056,0.001
21.80,41.800,0.02995,4.067,0.001
21.86,41.900,0.03012,4.077,0.001
21.91,42.000,0.03029,4.087,0.001
21.98,42.100,0.03045,4.100,0.001
22.05,42.200,0.03066,4.112,0.001
22.11,42.300,0.03083,4.124,0.001
22.18,42.400,0.03103,4.138,0.001
22.25,42.500,0.03120,4.150,0.001
22.32,42.600,0.03141,4.163,0.001
22.39,42.700,0.03162,4.177,0.001
22.46,42.800,0.03182,4.190,0.001
22.55,42.900,0.03207,4.206,0.001
22.64,43.000,0.03228,4.224,0.001
22.72,43.100,0.03249,4.237,0.001
22.78,43.200,0.03270,4.250,0.001
22.85,43.300,0.03290,4.262,0.001
22.93,43.400,0.03311,4.277,0.001
23.00,43.500,0.03332,4.290,0.001
23.05,43.600,0.03353,4.300,0.001
23.11,43.700,0.03374,4.311,0.001
23.17,43.800,0.03390,4.322,0.001
23.23,43.900,0.03411,4.333,0.001
23.29,44.000,0.03428,4.344,0.001
23.33,44.100,0.03444,4.351,0.001
23.38,44.200,0.03461,4.362,0.001
23.44,44.300,0.03477,4.372,0.001
23.49,44.400,0.03490,4.382,0.001
23.53,44.500,0.03507,4.390,0.001
23.57,44.600,0.03523,4.397,0.001
23.63,44.700,0.03536,4.408,0.001
23.67,44.800,0.03548,4.416,0.001
23.72,44.900,0.03565,4.424,0.001
23.76,45.000,0.03577,4.433,0.001
23.80,45.100,0.03590,4.439,0.001
23.85,45.200,0.03606,4.449,0.001
23.89,45.300,0.03619,4.456,0.001
23.95,45.400,0.03631,4.467,0.001
23.99,45.500,0.03648,4.474,0.001
24.03,45.600,0.03660,4.482,0.001
24.09,45.700,0.03673,4.493,0.001
24.13,45.800,0.03685,4.502,0.001
24.19,45.900,0.03702,4.512,0.001
24.25,46.000,0.03714,4.523,0.001
24.30,46.100,0.03731,4.532,0.001
24.36,46.200,0.03743,4.543,0.001
24.41,46.300,0.03760,4.554,0.001
24.46,46.400,0.03772,4.563,0.001
24.51,46.500,0.03789,4.573,0.001
24.57,46.600,0.03806,4.584,0.001
24.63,46.700,0.03818,4.594,0.001
24.69,46.800,0.03835,4.606,0.001
24.75,46.900,0.03851,4.617,0.001
24.81,47.000,0.03864,4.627,0.001
24.86,47.100,0.03881,4.638,0.001
24.92,47.200,0.03897,4.648,0.001
24.99,47.300,0.03914,4.661,0.001
25.03,47.400,0.03930,4.669,0.001
25.10,47.500,0.03947,4.683,0.001
25.16,47.600,0.03964,4.692,0.001
25.22,47.700,0.03980,4.705,0.001
25.29,47.800,0.03997,4.717,0.001
25.35,47.900,0.04013,4.729,0.001
25.42,48.000,0.04034,4.741,0.001
25.51,48.100,0.04051,4.758,0.001
25.58,48.200,0.04072,4.772,0.001
25.67,48.300,0.04092,4.788,0.001
25.75,48.400,0.04113,4.804,0.001
25.83,48.500,0.04134,4.818,0.001
25.91,48.600,0.04155,4.834,0.001
25.99,48.700,0.04176,4.848,0.001
26.06,48.800,0.04200,4.861,0.001
26.14,48.900,0.04221,4.876,0.001
26.22,49.000,0.04242,4.891,0.001
26.29,49.100,0.04263,4.904,0.001
26.39,49.200,0.04284,4.922,0.001
26.43,49.300,0.04300,4.930,0.001
26.50,49.400,0.04321,4.944,0.001
26.56,49.500,0.04338,4.955,0.001
26.62,49.600,0.04358,4.965,0.001
26.69,49.700,0.04375,4.978,0.001
26.74,49.800,0.04392,4.988,0.001
26.79,49.900,0.04408,4.998,0.001
26.84,50.000,0.04421,5.007,0.001
26.89,50.100,0.04437,5.016,0.001
26.95,50.200,0.04454,5.027,0.001
27.00,50.300,0.04466,5.037,0.001
27.05,50.400,0.04479,5.045,0.001
27.10,50.500,0.04496,5.055,0.001
27.15,50.600,0.04508,5.064,0.001
27.20,50.700,0.04520,5.073,0.001
27.24,50.800,0.04537,5.081,0.001
27.29,50.900,0.04550,5.090,0.001
27.34,51.000,0.04562,5.099,0.001
27.37,51.100,0.04574,5.106,0.001
27.44,51.200,0.04591,5.118,0.001
27.49,51.300,0.04604,5.128,0.001
27.55,51.400,0.04616,5.139,0.001
27.61,51.500,0.04633,5.151,0.001
27.67,51.600,0.04645,5.161,0.001
27.73,51.700,0.04662,5.173,0.001
27.79,51.800,0.04674,5.184,0.001
27.85,51.900,0.04691,5.195,0.001
27.90,52.000,0.04707,5.205,0.001
27.96,52.100,0.04720,5.216,0.001
28.03,52.200,0.04737,5.228,0.001
28.07,52.300,0.04749,5.236,0.001
28.14,52.400,0.04766,5.249,0.001
28.20,52.500,0.04782,5.261,0.001
28.27,52.600,0.04799,5.272,0.001
28.32,52.700,0.04811,5.282,0.001
28.39,52.800,0.04828,5.296,0.001
28.45,52.900,0.04845,5.306,0.001
28.53,53.000,0.04861,5.321,0.001
28.59,53.100,0.04878,5.333,0.001
28.65,53.200,0.04894,5.344,0.001
28.71,53.300,0.04911,5.355,0.001
28.79,53.400,0.04928,5.370,0.001
28.85,53.500,0.04944,5.382,0.001
28.92,53.600,0.04961,5.395,0.001
29.01,53.700,0.04982,5.412,0.001
29.08,53.800,0.05003,5.425,0.001
29.18,53.900,0.05019,5.443,0.001
29.26,54.000,0.05040,5.457,0.001
29.34,54.100,0.05061,5.474,0.001
29.43,54.200,0.05081,5.489,0.001
29.51,54.300,0.05102,5.504,0.001
29.62,54.400,0.05123,5.525,0.001
29.69,54.500,0.05148,5.539,0.001
29.79,54.600,0.05169,5.557,0.001
29.85,54.700,0.05190,5.568,0.001
29.93,54.800,0.05210,5.582,0.001
30.03,54.900,0.05231,5.602,0.001
30.11,55.000,0.05252,5.616,0.001
30.16,55.100,0.05268,5.627,0.001
30.25,55.200,0.05289,5.642,0.001
30.31,55.300,0.05306,5.654,0.001
30.38,55.400,0.05322,5.667,0.001
30.44,55.500,0.05339,5.677,0.001
30.49,55.600,0.05356,5.687,0.001
30.57,55.700,0.05372,5.702,0.001
30.62,55.800,0.05385,5.712,0.001
30.66,55.900,0.05401,5.720,0.001
30.72,56.000,0.05414,5.731,0.001
30.78,56.100,0.05431,5.741,0.001
30.82,56.200,0.05443,5.749,0.001
30.87,56.300,0.05460,5.759,0.001
30.93,56.400,0.05472,5.770,0.001
31.00,56.500,0.05485,5.782,0.001
31.05,56.600,0.05497,5.792,0.001
31.10,56.700,0.05509,5.801,0.001
31.16,56.800,0.05526,5.812,0.001
31.22,56.900,0.05539,5.823,0.001
31.27,57.000,0.05551,5.833,0.001
31.33,57.100,0.05568,5.844,0.001
31.40,57.200,0.05580,5.857,0.001
31.46,57.300,0.05597,5.868,0.001
31.53,57.400,0.05609,5.881,0.001
31.60,57.500,0.05626,5.894,0.001
31.66,57.600,0.05638,5.905,0.001
31.71,57.700,0.05655,5.915,0.001
31.78,57.800,0.05667,5.928,0.001
31.86,57.900,0.05684,5.944,0.001
31.93,58.000,0.05701,5.956,0.001
31.98,58.100,0.05717,5.966,0.001
32.06,58.200,0.05730,5.980,0.001
32.12,58.300,0.05746,5.992,0.001
32.18,58.400,0.05763,6.002,0.001
32.24,58.500,0.05780,6.014,0.001
32.32,58.600,0.05792,6.028,0.001
32.40,58.700,0.05809,6.044,0.001
32.45,58.800,0.05825,6.053,0.001
32.53,58.900,0.05842,6.069,0.001
32.59,59.000,0.05859,6.078,0.001
32.68,59.100,0.05875,6.095,0.001
32.75,59.200,0.05892,6.109,0.001
32.81,59.300,0.05908,6.121,0.001
32.88,59.400,0.05929,6.134,0.001
32.99,59.500,0.05946,6.154,0.001
33.05,59.600,0.05967,6.166,0.001
33.16,59.700,0.05983,6.185,0.001
33.25,59.800,0.06004,6.203,0.001
33.38,59.900,0.06025,6.226,0.001
33.47,60.000,0.06050,6.243,0.001
33.56,60.100,0.06070,6.260,0.001
33.66,60.200,0.06091,6.279,0.001
33.77,60.300,0.06112,6.299,0.001
33.86,60.400,0.06133,6.316,0.001
33.94,60.500,0.06154,6.330,0.001
34.02,60.600,0.06174,6.346,0.001
34.10,60.700,0.06191,6.361,0.001
34.20,60.800,0.06212,6.379,0.001
34.27,60.900,0.06228,6.393,0.001
34.35,61.000,0.06249,6.407,0.001
34.43,61.100,0.06266,6.421,0.001
34.49,61.200,0.06282,6.434,0.001
34.56,61.300,0.06295,6.447,0.001
34.62,61.400,0.06312,6.458,0.001
34.69,61.500,0.06328,6.470,0.001
34.75,61.600,0.06341,6.481,0.001
34.82,61.700,0.06357,6.495,0.001
34.89,61.800,0.06370,6.507,0.001
34.95,61.900,0.06382,6.519,0.001
34.99,62.000,0.06399,6.526,0.001
35.05,62.100,0.06411,6.538,0.001
35.12,62.200,0.06424,6.550,0.001
35.17,62.300,0.06436,6.560,0.001
35.22,62.400,0.06449,6.570,0.001
35.30,62.500,0.06465,6.584,0.001
35.34,62.600,0.06478,6.593,0.001
35.42,62.700,0.06490,6.608,0.001
35.49,62.800,0.06503,6.620,0.001
35.55,62.900,0.06519,6.630,0.001
35.63,63.000,0.06532,6.646,0.001
35.68,63.100,0.06548,6.656,0.001
35.76,63.200,0.06561,6.670,0.001
35.83,63.300,0.06573,6.684,0.001
35.88,63.400,0.06590,6.693,0.001
35.95,63.500,0.06607,6.707,0.001
36.03,63.600,0.06619,6.720,0.001
36.10,63.700,0.06636,6.733,0.001
36.18,63.800,0.06648,6.749,0.001
36.24,63.900,0.06665,6.759,0.001
36.31,64.000,0.06681,6.773,0.001
36.38,64.100,0.06694,6.787,0.001
36.47,64.200,0.06710,6.803,0.001
36.55,64.300,0.06723,6.817,0.001
36.64,64.400,0.06740,6.834,0.001
36.70,64.500,0.06756,6.847,0.001
36.78,64.600,0.06773,6.861,0.001
36.87,64.700,0.06789,6.877,0.001
36.95,64.800,0.06802,6.892,0.001
37.01,64.900,0.06819,6.904,0.001
37.12,65.000,0.06835,6.923,0.001
37.19,65.100,0.06856,6.937,0.001
37.31,65.200,0.06873,6.959,0.001
37.41,65.300,0.06893,6.978,0.001
37.52,65.400,0.06914,6.999,0.001
37.64,65.500,0.06935,7.020,0.001
37.75,65.600,0.06956,7.042,0.001
37.87,65.700,0.06976,7.063,0.001
37.99,65.800,0.06997,7.087,0.001
38.09,65.900,0.07018,7.105,0.001
38.23,66.000,0.07043,7.131,0.001
38.31,66.100,0.07064,7.146,0.001
38.43,66.200,0.07084,7.169,0.001
38.55,66.300,0.07105,7.191,0.001
38.66,66.400,0.07126,7.212,0.001
38.77,66.500,0.07143,7.231,0.001
38.83,66.600,0.07163,7.244,0.001
38.94,66.700,0.07180,7.263,0.001
39.03,66.800,0.07201,7.281,0.001
39.11,66.900,0.07217,7.296,0.001
39.19,67.000,0.07230,7.310,0.001
39.25,67.100,0.07247,7.321,0.001
39.33,67.200,0.07263,7.336,0.001
39.41,67.300,0.07276,7.351,0.001
39.46,67.400,0.07292,7.361,0.001
39.54,67.500,0.07305,7.375,0.001
39.61,67.600,0.07317,7.388,0.001
39.67,67.700,0.07334,7.400,0.001
39.76,67.800,0.07346,7.416,0.001
39.82,67.900,0.07363,7.427,0.001
39.90,68.000,0.07375,7.443,0.001
39.95,68.100,0.07388,7.451,0.001
40.04,68.200,0.07400,7.468,0.001
40.09,68.300,0.07413,7.479,0.001
40.16,68.400,0.07429,7.491,0.001
40.26,68.500,0.07442,7.510,0.001
40.32,68.600,0.07458,7.521,0.001
40.40,68.700,0.07471,7.536,0.001
40.48,68.800,0.07483,7.551,0.001
40.55,68.900,0.07500,7.564,0.001
40.65,69.000,0.07512,7.582,0.001
40.72,69.100,0.07529,7.595,0.001
40.80,69.200,0.07546,7.611,0.001
40.89,69.300,0.07558,7.628,0.001
41.00,69.400,0.07575,7.648,0.001
41.07,69.500,0.07591,7.661,0.001
41.17,69.600,0.07608,7.680,0.001
41.25,69.700,0.07621,7.694,0.002
41.34,69.800,0.07637,7.712,0.002
41.45,69.900,0.07654,7.731,0.002
41.53,70.000,0.07670,7.747,0.002
41.61,70.100,0.07687,7.761,0.002
41.73,70.200,0.07704,7.783,0.002
41.83,70.300,0.07720,7.802,0.002
41.91,70.400,0.07737,7.817,0.002
42.02,70.500,0.07754,7.839,0.002
42.11,70.600,0.07770,7.854,0.002
42.20,70.700,0.07787,7.872,0.002
42.32,70.800,0.07808,7.894,0.002
42.45,70.900,0.07828,7.919,0.002
42.57,71.000,0.07849,7.940,0.002
42.71,71.100,0.07870,7.967,0.002
42.82,71.200,0.07891,7.988,0.002
42.93,71.300,0.07911,8.008,0.002
43.08,71.400,0.07936,8.035,0.002
43.22,71.500,0.07957,8.061,0.002
43.34,71.600,0.07978,8.084,0.002
43.46,71.700,0.07999,8.107,0.002
43.58,71.800,0.08019,8.129,0.002
43.68,71.900,0.08040,8.148,0.002
43.79,72.000,0.08061,8.168,0.002
43.88,72.100,0.08082,8.185,0.002
43.99,72.200,0.08098,8.206,0.002
44.09,72.300,0.08119,8.224,0.002
44.17,72.400,0.08136,8.239,0.002
44.26,72.500,0.08152,8.257,0.002
44.36,72.600,0.08169,8.274,0.002
44.46,72.700,0.08186,8.293,0.002
44.54,72.800,0.08202,8.308,0.002
44.62,72.900,0.08215,8.323,0.002
44.71,73.000,0.08231,8.340,0.002
44.79,73.100,0.08248,8.355,0.002
44.87,73.200,0.08260,8.370,0.002
44.93,73.300,0.08277,8.382,0.002
45.02,73.400,0.08290,8.397,0.002
45.09,73.500,0.08302,8.410,0.002
45.15,73.600,0.08319,8.422,0.002
14.20,73.700,0.08331,2.649,0.002
16.83,73.800,0.08344,3.139,0.002
17.11,73.900,0.08360,3.192,0.002
17.23,74.000,0.08373,3.214,0.002
17.35,74.100,0.08389,3.236,0.002
17.51,74.200,0.08402,3.267,0.002
17.66,74.300,0.08418,3.295,0.002
17.81,74.400,0.08431,3.323,0.002
17.94,74.500,0.08447,3.347,0.002
18.07,74.600,0.08460,3.371,0.002
18.21,74.700,0.08477,3.397,0.002
18.36,74.800,0.08493,3.425,0.002
18.47,74.900,0.08510,3.446,0.002
18.59,75.000,0.08522,3.468,0.002
18.70,75.100,0.08539,3.489,0.002
18.81,75.200,0.08556,3.509,0.002
18.94,75.300,0.08572,3.533,0.002
19.07,75.400,0.08589,3.556,0.002
19.18,75.500,0.08605,3.577,0.002
19.28,75.600,0.08618,3.597,0.002
19.40,75.700,0.08634,3.619,0.002
19.49,75.800,0.08651,3.636,0.002
19.59,75.900,0.08668,3.654,0.002
19.74,76.000,0.08684,3.681,0.002
19.85,76.100,0.08701,3.702,0.002
19.93,76.200,0.08718,3.718,0.002
20.05,76.300,0.08738,3.739,0.002
20.17,76.400,0.08759,3.762,0.002
20.30,76.500,0.08776,3.786,0.002
20.38,76.600,0.08797,3.801,0.002
20.52,76.700,0.08817,3.828,0.002
20.64,76.800,0.08838,3.850,0.002
20.74,76.900,0.08859,3.869,0.002
20.87,77.000,0.08880,3.894,0.002
21.02,77.100,0.08900,3.920,0.002
21.12,77.200,0.08925,3.940,0.002
21.24,77.300,0.08946,3.962,0.002
21.35,77.400,0.08967,3.982,0.002
21.46,77.500,0.08988,4.003,0.002
21.57,77.600,0.09004,4.023,0.002
21.66,77.700,0.09025,4.041,0.002
21.76,77.800,0.09046,4.060,0.002
21.86,77.900,0.09063,4.078,0.002
21.95,78.000,0.09083,4.095,0.002
22.03,78.100,0.09100,4.110,0.002
22.11,78.200,0.09117,4.124,0.002
22.20,78.300,0.09133,4.142,0.002
22.29,78.400,0.09150,4.157,0.002
22.35,78.500,0.09166,4.169,0.002
22.41,78.600,0.09179,4.181,0.002
22.50,78.700,0.09195,4.196,0.002
22.55,78.800,0.09212,4.207,0.002
22.65,78.900,0.09225,4.225,0.002
22.70,79.000,0.09237,4.234,0.002
22.77,79.100,0.09254,4.247,0.002
22.84,79.200,0.09266,4.260,0.002
22.88,79.300,0.09279,4.268,0.002
22.97,79.400,0.09295,4.285,0.002
23.03,79.500,0.09308,4.296,0.002
23.10,79.600,0.09320,4.309,0.002
23.17,79.700,0.09337,4.321,0.002
23.23,79.800,0.09349,4.334,0.002
23.30,79.900,0.09362,4.347,0.002
23.35,80.000,0.09378,4.356,0.002
23.43,80.100,0.09391,4.371,0.002
23.51,80.200,0.09407,4.385,0.002
23.56,80.300,0.09420,4.395,0.002
23.63,80.400,0.09437,4.409,0.002
23.69,80.500,0.09449,4.419,0.002
23.77,80.600,0.09466,4.433,0.002
23.85,80.700,0.09482,4.448,0.002
23.91,80.800,0.09495,4.461,0.002
23.98,80.900,0.09511,4.473,0.002
24.07,81.000,0.09528,4.490,0.002
24.13,81.100,0.09545,4.501,0.002
24.20,81.200,0.09557,4.513,0.002
24.27,81.300,0.09574,4.526,0.002
24.33,81.400,0.09590,4.539,0.002
24.41,81.500,0.09607,4.554,0.002
24.47,81.600,0.09624,4.565,0.002
24.54,81.700,0.09636,4.577,0.002
24.61,81.800,0.09653,4.591,0.002
24.67,81.900,0.09669,4.601,0.002
24.77,82.000,0.09690,4.621,0.002
24.84,82.100,0.09707,4.634,0.002
24.95,82.200,0.09727,4.653,0.002
25.02,82.300,0.09748,4.667,0.002
25.11,82.400,0.09769,4.683,0.002
12.31,82.500,0.09790,2.296,0.002
9.96,82.600,0.09811,1.857,0.002
9.91,82.700,0.09831,1.849,0.002
10.01,82.800,0.09856,1.867,0.002
10.13,82.900,0.09877,1.890,0.002
10.25,83.000,0.09898,1.911,0.002
10.36,83.100,0.09919,1.933,0.002
10.48,83.200,0.09939,1.954,0.002
10.56,83.300,0.09960,1.970,0.002
10.64,83.400,0.09981,1.984,0.002
10.74,83.500,0.09998,2.004,0.002
10.81,83.600,0.10018,2.015,0.002
10.86,83.700,0.10035,2.026,0.002
10.93,83.800,0.10052,2.040,0.002
10.99,83.900,0.10068,2.049,0.002
11.05,84.000,0.10085,2.060,0.002
11.12,84.100,0.10097,2.075,0.002
11.17,84.200,0.10114,2.083,0.002
11.23,84.300,0.10126,2.095,0.002
11.26,84.400,0.10143,2.101,0.002
11.32,84.500,0.10155,2.112,0.002
11.35,84.600,0.10168,2.117,0.002
11.40,84.700,0.10185,2.126,0.002
11.45,84.800,0.10197,2.135,0.002
11.47,84.900,0.10209,2.140,0.002
11.53,85.000,0.10222,2.152,0.002
11.57,85.100,0.10234,2.158,0.002
11.62,85.200,0.10251,2.168,0.002
11.65,85.300,0.10263,2.173,0.002
11.71,85.400,0.10276,2.185,0.002
11.76,85.500,0.10288,2.193,0.002
11.79,85.600,0.10305,2.199,0.002
11.83,85.700,0.10318,2.207,0.002
11.87,85.800,0.10334,2.215,0.002
11.94,85.900,0.10347,2.227,0.002
11.99,86.000,0.10363,2.236,0.002
12.02,86.100,0.10376,2.242,0.002
12.08,86.200,0.10392,2.253,0.002
12.11,86.300,0.10405,2.259,0.002
12.16,86.400,0.10421,2.269,0.002
12.20,86.500,0.10438,2.276,0.002
12.25,86.600,0.10450,2.285,0.002
12.29,86.700,0.10467,2.293,0.002
12.33,86.800,0.10484,2.300,0.002
12.37,86.900,0.10500,2.308,0.002
12.41,87.000,0.10513,2.315,0.002
12.46,87.100,0.10529,2.324,0.002
12.50,87.200,0.10546,2.331,0.002
12.55,87.300,0.10563,2.341,0.002
12.60,87.400,0.10579,2.350,0.002
12.63,87.500,0.10596,2.357,0.002
12.70,87.600,0.10613,2.368,0.002
12.73,87.700,0.10633,2.374,0.002
12.79,87.800,0.10650,2.385,0.002
12.84,87.900,0.10671,2.396,0.002
12.90,88.000,0.10687,2.406,0.002
12.93,88.100,0.10708,2.412,0.002
13.00,88.200,0.10729,2.424,0.002
13.05,88.300,0.10750,2.433,0.002
13.10,88.400,0.10770,2.443,0.002
13.15,88.500,0.10795,2.453,0.002
13.24,88.600,0.10816,2.469,0.002
13.28,88.700,0.10837,2.477,0.002
13.32,88.800,0.10858,2.485,0.002
13.38,88.900,0.10879,2.496,0.002
13.44,89.000,0.10899,2.506,0.002
13.46,89.100,0.10920,2.512,0.002
13.51,89.200,0.10937,2.519,0.002
13.56,89.300,0.10957,2.530,0.002
13.58,89.400,0.10974,2.533,0.002
13.61,89.500,0.10991,2.538,0.002
13.65,89.600,0.11007,2.546,0.002
13.67,89.700,0.11024,2.550,0.002
13.71,89.800,0.11041,2.557,0.002
13.74,89.900,0.11053,2.563,0.002
13.77,90.000,0.11070,2.568,0.002
13.79,90.100,0.11082,2.572,0.002
13.81,90.200,0.11099,2.576,0.002
13.85,90.300,0.11111,2.584,0.002
13.87,90.400,0.11124,2.587,0.002
13.90,90.500,0.11140,2.593,0.002
13.94,90.600,0.11153,2.599,0.002
13.95,90.700,0.11165,2.602,0.002
13.98,90.800,0.11178,2.608,0.002
14.02,90.900,0.11194,2.615,0.002
14.06,91.000,0.11207,2.623,0.002
14.10,91.100,0.11219,2.629,0.002
14.11,91.200,0.11236,2.632,0.002
14.15,91.300,0.11248,2.640,0.002
14.20,91.400,0.11265,2.648,0.002
14.22,91.500,0.11277,2.653,0.002
14.26,91.600,0.11294,2.660,0.002
14.29,91.700,0.11307,2.666,0.002
14.32,91.800,0.11323,2.671,0.002
14.33,91.900,0.11336,2.673,0.002
14.36,92.000,0.11352,2.679,0.002
14.40,92.050,0.11361,2.685,0.002