File: data-files/CWRU/0900-05-05B.txt
""
"Test Method","Will_Huddleston_Disks.msm"
"Sample I. D.","900-5-5B.mss"
"Specimen Number","1"

"Load (N)","Time (s)","Extension (mm)","Stress (MPa)","Strain (mm/mm)"

1.93,0.200,-0.05961,0.248,-0.001
1.94,0.300,-0.05961,0.249,-0.001
1.94,0.400,-0.05957,0.248,-0.001
1.93,0.500,-0.05957,0.247,-0.001
1.94,0.600,-0.05957,0.249,-0.001
1.93,0.700,-0.05953,0.248,-0.001
1.92,0.800,-0.05953,0.246,-0.001
1.94,0.900,-0.05953,0.248,-0.001
1.93,1.000,-0.05949,0.247,-0.001
1.93,1.100,-0.05949,0.248,-0.001
1.95,1.200,-0.05945,0.249,-0.001
1.94,1.300,-0.05945,0.248,-0.001
1.94,1.400,-0.05945,0.248,-0.001
1.95,1.500,-0.05940,0.250,-0.001
1.96,1.600,-0.05940,0.251,-0.001
1.98,1.700,-0.05936,0.254,-0.001
2.01,1.800,-0.05932,0.257,-0.001
2.05,1.900,-0.05924,0.263,-0.001
2.13,2.000,-0.05916,0.273,-0.001
2.22,2.100,-0.05903,0.284,-0.001
2.32,2.200,-0.05886,0.298,-0.001
2.38,2.300,-0.05870,0.305,-0.001
2.47,2.400,-0.05857,0.316,-0.001
2.50,2.500,-0.05841,0.321,-0.001
2.55,2.600,-0.05828,0.327,-0.001
2.58,2.700,-0.05816,0.330,-0.001
2.62,2.800,-0.05799,0.335,-0.001
2.67,2.900,-0.05787,0.342,-0.001
2.69,3.000,-0.05774,0.345,-0.001
2.73,3.100,-0.05762,0.349,-0.001
2.75,3.200,-0.05745,0.352,-0.001
2.77,3.300,-0.05733,0.355,-0.001
2.81,3.400,-0.05720,0.360,-0.001
2.83,3.500,-0.05708,0.363,-0.001
2.87,3.600,-0.05695,0.367,-0.001
2.90,3.700,-0.05683,0.372,-0.001
2.92,3.800,-0.05666,0.374,-0.001
2.96,3.900,-0.05654,0.379,-0.001
2.97,4.000,-0.05637,0.381,-0.001
3.01,4.100,-0.05625,0.386,-0.001
3.02,4.200,-0.05608,0.386,-0.001
3.05,4.300,-0.05596,0.391,-0.001
3.08,4.400,-0.05579,0.394,-0.001
3.11,4.500,-0.05566,0.398,-0.001
3.14,4.600,-0.05550,0.402,-0.001
3.15,4.700,-0.05533,0.403,-0.001
3.17,4.800,-0.05521,0.406,-0.001
3.19,4.900,-0.05504,0.408,-0.001
3.22,5.000,-0.05488,0.413,-0.001
3.25,5.100,-0.05475,0.416,-0.001
3.28,5.200,-0.05458,0.420,-0.001
3.31,5.300,-0.05442,0.425,-0.001
3.33,5.400,-0.05425,0.427,-0.001
3.36,5.500,-0.05413,0.431,-0.001
3.40,5.600,-0.05396,0.436,-0.001
3.43,5.700,-0.05375,0.439,-0.001
3.46,5.800,-0.05359,0.444,-0.001
3.48,5.900,-0.05342,0.446,-0.001
3.52,6.000,-0.05325,0.451,-0.001
3.57,6.100,-0.05305,0.457,-0.001
3.58,6.200,-0.05284,0.458,-0.001
3.63,6.300,-0.05267,0.464,-0.001
3.66,6.400,-0.05246,0.469,-0.001
3.69,6.500,-0.05222,0.472,-0.001
3.71,6.600,-0.05201,0.476,-0.001
3.76,6.700,-0.05180,0.482,-0.001
3.80,6.800,-0.05159,0.487,-0.001
3.84,6.900,-0.05138,0.492,-0.001
3.88,7.000,-0.05118,0.497,-0.001
3.91,7.100,-0.05097,0.500,-0.001
3.94,7.200,-0.05076,0.504,-0.001
3.97,7.300,-0.05055,0.509,-0.001
4.01,7.400,-0.05035,0.513,-0.001
4.03,7.500,-0.05018,0.516,-0.001
4.04,7.600,-0.04997,0.517,-0.001
4.07,7.700,-0.04981,0.522,-0.001
4.10,7.800,-0.04964,0.525,-0.001
4.12,7.900,-0.04947,0.528,-0.001
4.16,8.000,-0.04931,0.533,-0.001
4.18,8.100,-0.04918,0.536,-0.001
4.19,8.200,-0.04902,0.536,-0.001
4.22,8.300,-0.04889,0.541,-0.001
4.25,8.400,-0.04872,0.544,-0.001
4.26,8.500,-0.04856,0.546,-0.001
4.28,8.600,-0.04843,0.548,-0.001
4.32,8.700,-0.04831,0.553,-0.001
4.33,8.800,-0.04814,0.555,-0.001
4.36,8.900,-0.04802,0.558,-0.001
4.38,9.000,-0.04789,0.561,-0.001
4.40,9.100,-0.04773,0.563,-0.001
4.42,9.200,-0.04760,0.566,-0.001
4.46,9.300,-0.04748,0.571,-0.001
4.47,9.400,-0.04731,0.572,-0.001
4.50,9.500,-0.04719,0.576,-0.001
4.50,9.600,-0.04706,0.577,-0.001
4.53,9.700,-0.04690,0.580,-0.001
4.55,9.800,-0.04677,0.582,-0.001
4.57,9.900,-0.04661,0.585,-0.001
4.58,10.000,-0.04644,0.586,-0.001
4.60,10.100,-0.04631,0.589,-0.001
4.61,10.200,-0.04615,0.590,-0.001
4.63,10.300,-0.04598,0.593,-0.001
4.65,10.400,-0.04586,0.595,-0.001
4.65,10.500,-0.04569,0.595,-0.001
4.68,10.600,-0.04553,0.599,-0.001
4.69,10.700,-0.04536,0.601,-0.001
4.70,10.800,-0.04519,0.603,-0.001
4.71,10.900,-0.04503,0.603,-0.001
4.74,11.000,-0.04490,0.607,-0.001
4.77,11.100,-0.04474,0.611,-0.001
4.78,11.200,-0.04457,0.612,-0.001
4.80,11.300,-0.04440,0.615,-0.001
4.84,11.400,-0.04424,0.620,-0.001
4.84,11.500,-0.04403,0.620,-0.001
4.88,11.600,-0.04386,0.625,-0.001
4.90,11.700,-0.04370,0.628,-0.001
4.93,11.800,-0.04349,0.631,-0.001
4.99,11.900,-0.04332,0.639,-0.001
5.01,12.000,-0.04311,0.642,-0.001
5.06,12.100,-0.04291,0.648,-0.001
5.09,12.200,-0.04270,0.652,-0.001
5.12,12.300,-0.04249,0.656,-0.001
5.17,12.400,-0.04228,0.663,-0.001
5.19,12.500,-0.04208,0.665,-0.001
5.24,12.600,-0.04187,0.671,-0.001
5.29,12.700,-0.04166,0.677,-0.001
5.31,12.800,-0.04145,0.680,-0.001
5.34,12.900,-0.04124,0.684,-0.001
5.40,13.000,-0.04104,0.691,-0.001
5.44,13.100,-0.04087,0.697,-0.001
5.46,13.200,-0.04066,0.699,-0.001
5.48,13.300,-0.04050,0.702,-0.001
5.51,13.400,-0.04033,0.706,-0.001
5.53,13.500,-0.04012,0.708,-0.001
5.56,13.600,-0.04000,0.712,-0.001
5.59,13.700,-0.03983,0.716,-0.001
5.62,13.800,-0.03967,0.719,-0.001
5.62,13.900,-0.03950,0.720,-0.001
5.65,14.000,-0.03937,0.724,-0.001
5.67,14.100,-0.03921,0.727,-0.001
5.69,14.200,-0.03908,0.729,-0.001
5.72,14.300,-0.03892,0.733,-0.001
5.73,14.400,-0.03879,0.735,-0.001
5.76,14.500,-0.03867,0.738,-0.001
5.77,14.600,-0.03850,0.740,-0.001
5.80,14.700,-0.03838,0.742,-0.001
5.82,14.800,-0.03825,0.745,-0.001
5.84,14.900,-0.03813,0.748,-0.001
5.85,15.000,-0.03800,0.750,-0.001
5.88,15.100,-0.03784,0.753,-0.001
5.90,15.200,-0.03771,0.755,-0.001
5.92,15.300,-0.03759,0.758,-0.001
5.95,15.400,-0.03742,0.762,-0.001
5.96,15.500,-0.03730,0.763,-0.001
5.98,15.600,-0.03713,0.766,-0.001
6.00,15.700,-0.03696,0.769,-0.001
6.00,15.800,-0.03684,0.769,-0.001
6.03,15.900,-0.03667,0.772,-0.001
6.05,16.000,-0.03655,0.774,-0.001
6.06,16.100,-0.03638,0.777,-0.001
6.09,16.200,-0.03622,0.780,-0.001
6.10,16.300,-0.03609,0.781,-0.001
6.11,16.400,-0.03593,0.782,-0.001
6.14,16.500,-0.03576,0.786,-0.001
6.14,16.600,-0.03559,0.786,-0.001
6.15,16.700,-0.03543,0.788,-0.001
6.18,16.800,-0.03530,0.791,-0.001
6.21,16.900,-0.03514,0.795,-0.001
6.21,17.000,-0.03497,0.795,-0.001
6.22,17.100,-0.03480,0.797,-0.001
6.25,17.200,-0.03464,0.800,-0.001
6.27,17.300,-0.03447,0.803,-0.001
6.29,17.400,-0.03426,0.805,-0.001
6.31,17.500,-0.03410,0.809,-0.001
6.33,17.600,-0.03389,0.811,-0.001
6.34,17.700,-0.03368,0.812,-0.001
6.36,17.800,-0.03347,0.815,-0.001
6.39,17.900,-0.03327,0.818,-0.001
6.39,18.000,-0.03306,0.818,-0.001
6.42,18.100,-0.03281,0.823,-0.001
6.46,18.200,-0.03260,0.828,-0.001
6.47,18.300,-0.03239,0.828,-0.001
6.51,18.400,-0.03219,0.833,-0.001
6.52,18.500,-0.03198,0.835,-0.001
6.54,18.600,-0.03177,0.837,-0.001
6.55,18.700,-0.03156,0.838,-0.001
6.59,18.800,-0.03135,0.844,-0.001
6.62,18.900,-0.03119,0.847,-0.001
6.64,19.000,-0.03098,0.850,-0.001
6.63,19.100,-0.03081,0.850,-0.001
6.66,19.200,-0.03065,0.853,-0.001
6.68,19.300,-0.03048,0.856,-0.001
6.70,19.400,-0.03032,0.858,-0.001
6.71,19.500,-0.03019,0.859,-0.001
6.74,19.600,-0.03002,0.864,-0.001
6.76,19.700,-0.02990,0.865,-0.001
6.79,19.800,-0.02973,0.870,-0.001
6.82,19.900,-0.02961,0.873,-0.001
6.82,20.000,-0.02948,0.874,-0.001
6.85,20.100,-0.02932,0.877,-0.001
6.87,20.200,-0.02919,0.880,-0.001
6.90,20.300,-0.02907,0.884,-0.001
6.92,20.400,-0.02894,0.886,-0.001
6.94,20.500,-0.02878,0.889,-0.001
6.98,20.600,-0.02865,0.894,-0.001
6.98,20.700,-0.02853,0.894,-0.001
7.02,20.800,-0.02836,0.899,-0.001
7.04,20.900,-0.02824,0.902,-0.001
7.07,21.000,-0.02807,0.905,-0.001
7.09,21.100,-0.02795,0.908,-0.001
7.13,21.200,-0.02778,0.913,-0.001
7.15,21.300,-0.02766,0.916,-0.001
7.16,21.400,-0.02749,0.917,-0.001
7.19,21.500,-0.02732,0.921,-0.001
7.21,21.600,-0.02720,0.924,-0.001
7.25,21.700,-0.02703,0.929,-0.001
7.25,21.800,-0.02687,0.928,-0.001
7.29,21.900,-0.02674,0.933,-0.001
7.30,22.000,-0.02658,0.936,-0.001
7.33,22.100,-0.02641,0.939,-0.001
7.36,22.200,-0.02628,0.942,-0.001
7.39,22.300,-0.02612,0.946,-0.001
7.40,22.400,-0.02595,0.948,-0.001
7.43,22.500,-0.02579,0.952,-0.001
7.45,22.600,-0.02562,0.955,-0.001
7.47,22.700,-0.02545,0.957,-0.001
7.50,22.800,-0.02529,0.961,0.000
7.54,22.900,-0.02512,0.966,0.000
7.56,23.000,-0.02495,0.968,0.000
7.62,23.100,-0.02475,0.976,0.000
7.63,23.200,-0.02458,0.977,0.000
7.66,23.300,-0.02437,0.981,0.000
7.68,23.400,-0.02417,0.984,0.000
7.73,23.500,-0.02396,0.990,0.000
7.76,23.600,-0.02375,0.993,0.000
7.79,23.700,-0.02350,0.998,0.000
7.83,23.800,-0.02329,1.003,0.000
7.86,23.900,-0.02308,1.007,0.000
7.88,24.000,-0.02288,1.010,0.000
7.92,24.100,-0.02267,1.014,0.000
7.94,24.200,-0.02246,1.017,0.000
7.97,24.300,-0.02225,1.021,0.000
7.98,24.400,-0.02205,1.023,0.000
8.03,24.500,-0.02184,1.028,0.000
8.06,24.600,-0.02167,1.033,0.000
8.08,24.700,-0.02146,1.035,0.000
8.10,24.800,-0.02130,1.037,0.000
8.14,24.900,-0.02113,1.042,0.000
8.13,25.000,-0.02097,1.042,0.000
8.16,25.100,-0.02080,1.045,0.000
8.17,25.200,-0.02067,1.047,0.000
8.21,25.300,-0.02051,1.052,0.000
8.22,25.400,-0.02038,1.052,0.000
8.25,25.500,-0.02022,1.057,0.000
8.27,25.600,-0.02009,1.059,0.000
8.29,25.700,-0.01993,1.062,0.000
8.30,25.800,-0.01980,1.063,0.000
8.33,25.900,-0.01968,1.066,0.000
8.33,26.000,-0.01955,1.067,0.000
8.37,26.100,-0.01939,1.072,0.000
8.39,26.200,-0.01926,1.075,0.000
8.41,26.300,-0.01914,1.077,0.000
8.43,26.400,-0.01897,1.079,0.000
8.46,26.500,-0.01885,1.083,0.000
8.49,26.600,-0.01868,1.087,0.000
8.52,26.700,-0.01856,1.091,0.000
8.54,26.800,-0.01839,1.094,0.000
8.57,26.900,-0.01826,1.098,0.000
8.59,27.000,-0.01810,1.100,0.000
8.61,27.100,-0.01797,1.102,0.000
8.64,27.200,-0.01781,1.107,0.000
8.67,27.300,-0.01764,1.110,0.000
8.69,27.400,-0.01747,1.113,0.000
8.73,27.500,-0.01735,1.118,0.000
8.75,27.600,-0.01718,1.121,0.000
8.78,27.700,-0.01702,1.124,0.000
8.81,27.800,-0.01685,1.128,0.000
8.83,27.900,-0.01673,1.131,0.000
8.86,28.000,-0.01656,1.135,0.000
8.88,28.100,-0.01639,1.138,0.000
8.92,28.200,-0.01623,1.142,0.000
8.94,28.300,-0.01606,1.145,0.000
8.98,28.400,-0.01590,1.150,0.000
9.02,28.500,-0.01573,1.155,0.000
9.03,28.600,-0.01556,1.157,0.000
9.07,28.700,-0.01540,1.162,0.000
9.10,28.800,-0.01519,1.166,0.000
9.16,28.900,-0.01502,1.174,0.000
9.19,29.000,-0.01482,1.177,0.000
9.24,29.100,-0.01465,1.183,0.000
9.27,29.200,-0.01440,1.188,0.000
9.33,29.300,-0.01419,1.194,0.000
9.38,29.400,-0.01398,1.202,0.000
9.42,29.500,-0.01378,1.206,0.000
9.47,29.600,-0.01357,1.213,0.000
9.51,29.700,-0.01336,1.218,0.000
9.52,29.800,-0.01315,1.219,0.000
9.59,29.900,-0.01295,1.228,0.000
9.64,30.000,-0.01274,1.234,0.000
9.68,30.100,-0.01253,1.240,0.000
9.71,30.200,-0.01236,1.244,0.000
9.74,30.300,-0.01216,1.248,0.000
9.78,30.400,-0.01199,1.253,0.000
9.82,30.500,-0.01182,1.257,0.000
9.84,30.600,-0.01166,1.261,0.000
9.89,30.700,-0.01149,1.266,0.000
9.91,30.800,-0.01137,1.269,0.000
9.94,30.900,-0.01120,1.273,0.000
9.95,31.000,-0.01108,1.275,0.000
9.99,31.100,-0.01091,1.280,0.000
10.05,31.200,-0.01078,1.287,0.000
10.06,31.300,-0.01062,1.289,0.000
10.09,31.400,-0.01049,1.292,0.000
10.11,31.500,-0.01033,1.295,0.000
10.13,31.600,-0.01020,1.298,0.000
10.17,31.700,-0.01008,1.303,0.000
10.20,31.800,-0.00995,1.306,0.000
10.23,31.900,-0.00983,1.310,0.000
10.26,32.000,-0.00966,1.315,0.000
10.29,32.100,-0.00954,1.318,0.000
10.33,32.200,-0.00941,1.324,0.000
10.34,32.300,-0.00925,1.324,0.000
10.40,32.400,-0.00912,1.331,0.000
10.43,32.500,-0.00900,1.336,0.000
10.47,32.600,-0.00883,1.341,0.000
10.50,32.700,-0.00871,1.345,0.000
10.54,32.800,-0.00854,1.350,0.000
10.57,32.900,-0.00842,1.354,0.000
10.61,33.000,-0.00825,1.359,0.000
10.64,33.100,-0.00808,1.363,0.000
10.67,33.200,-0.00796,1.367,0.000
10.71,33.300,-0.00779,1.372,0.000
10.76,33.400,-0.00767,1.378,0.000
10.79,33.500,-0.00750,1.382,0.000
10.83,33.600,-0.00734,1.387,0.000
10.88,33.700,-0.00721,1.393,0.000
10.91,33.800,-0.00704,1.397,0.000
10.96,33.900,-0.00688,1.404,0.000
11.00,34.000,-0.00671,1.408,0.000
11.04,34.100,-0.00655,1.414,0.000
11.08,34.200,-0.00638,1.419,0.000
11.13,34.300,-0.00621,1.425,0.000
11.18,34.400,-0.00605,1.431,0.000
11.20,34.500,-0.00588,1.434,0.000
11.27,34.600,-0.00567,1.443,0.000
11.32,34.700,-0.00547,1.450,0.000
11.37,34.800,-0.00530,1.457,0.000
11.42,34.900,-0.00505,1.462,0.000
11.49,35.000,-0.00484,1.472,0.000
11.53,35.100,-0.00463,1.477,0.000
11.60,35.200,-0.00443,1.486,0.000
11.66,35.300,-0.00418,1.494,0.000
11.70,35.400,-0.00397,1.498,0.000
11.74,35.500,-0.00376,1.504,0.000
11.83,35.600,-0.00355,1.515,0.000
11.87,35.700,-0.00335,1.520,0.000
11.92,35.800,-0.00314,1.527,0.000
11.96,35.900,-0.00297,1.532,0.000
12.01,36.000,-0.00276,1.538,0.000
12.05,36.100,-0.00260,1.543,0.000
12.09,36.200,-0.00243,1.549,0.000
12.13,36.300,-0.00227,1.553,0.000
12.16,36.400,-0.00210,1.557,0.000
12.19,36.500,-0.00193,1.561,0.000
12.23,36.600,-0.00177,1.567,0.000
12.27,36.700,-0.00164,1.571,0.000
12.30,36.800,-0.00152,1.575,0.000
12.32,36.900,-0.00135,1.578,0.000
12.37,37.000,-0.00123,1.585,0.000
12.38,37.100,-0.00106,1.586,0.000
12.44,37.200,-0.00094,1.593,0.000
12.46,37.300,-0.00081,1.596,0.000
12.50,37.400,-0.00069,1.601,0.000
12.54,37.500,-0.00052,1.606,0.000
12.58,37.600,-0.00040,1.611,0.000
12.61,37.700,-0.00027,1.616,0.000
12.66,37.800,-0.00015,1.621,0.000
12.70,37.900,0.00002,1.627,0.000
12.76,38.000,0.00014,1.634,0.000
12.78,38.100,0.00031,1.637,0.000
12.83,38.200,0.00044,1.644,0.000
12.88,38.300,0.00060,1.650,0.000
12.92,38.400,0.00073,1.655,0.000
12.97,38.500,0.00089,1.661,0.000
13.00,38.600,0.00102,1.665,0.000
13.05,38.700,0.00118,1.672,0.000
13.09,38.800,0.00135,1.677,0.000
13.13,38.900,0.00147,1.682,0.000
13.18,39.000,0.00164,1.688,0.000
13.22,39.100,0.00181,1.693,0.000
13.27,39.200,0.00197,1.699,0.000
13.31,39.300,0.00214,1.705,0.000
13.35,39.400,0.00226,1.709,0.000
13.40,39.500,0.00243,1.717,0.000
13.45,39.600,0.00260,1.723,0.000
13.50,39.700,0.00276,1.729,0.000
13.54,39.800,0.00293,1.735,0.000
13.60,39.900,0.00310,1.742,0.000
13.66,40.000,0.00330,1.749,0.000
13.70,40.100,0.00347,1.755,0.000
13.77,40.200,0.00368,1.764,0.000
13.83,40.300,0.00384,1.771,0.000
13.88,40.400,0.00405,1.778,0.000
13.96,40.500,0.00426,1.787,0.000
14.04,40.600,0.00447,1.798,0.000
14.10,40.700,0.00472,1.806,0.000
14.17,40.800,0.00492,1.814,0.000
14.23,40.900,0.00517,1.823,0.000
14.29,41.000,0.00538,1.830,0.000
14.36,41.100,0.00559,1.839,0.000
14.41,41.200,0.00580,1.846,0.000
14.47,41.300,0.00600,1.854,0.000
14.54,41.400,0.00621,1.862,0.000
14.61,41.500,0.00642,1.871,0.000
14.65,41.600,0.00663,1.876,0.000
14.69,41.700,0.00679,1.881,0.000
14.74,41.800,0.00696,1.888,0.000
14.79,41.900,0.00713,1.894,0.000
14.84,42.000,0.00729,1.901,0.000
14.90,42.100,0.00746,1.908,0.000
14.95,42.200,0.00762,1.915,0.000
14.99,42.300,0.00779,1.920,0.000
15.03,42.400,0.00792,1.924,0.000
15.08,42.500,0.00808,1.931,0.000
15.13,42.600,0.00821,1.937,0.000
15.17,42.700,0.00837,1.943,0.000
15.20,42.800,0.00850,1.947,0.000
15.25,42.900,0.00862,1.953,0.000
15.28,43.000,0.00879,1.957,0.000
15.33,43.100,0.00891,1.963,0.000
15.36,43.200,0.00904,1.967,0.000
15.43,43.300,0.00920,1.977,0.000
15.46,43.400,0.00933,1.980,0.000
15.51,43.500,0.00945,1.987,0.000
15.54,43.600,0.00962,1.991,0.000
15.60,43.700,0.00974,1.998,0.000
15.64,43.800,0.00991,2.003,0.000
15.70,43.900,0.01008,2.011,0.000
15.73,44.000,0.01020,2.015,0.000
15.82,44.100,0.01037,2.026,0.000
15.85,44.200,0.01049,2.030,0.000
15.91,44.300,0.01066,2.038,0.000
15.93,44.400,0.01082,2.041,0.000
16.00,44.500,0.01095,2.049,0.000
16.03,44.600,0.01112,2.053,0.000
16.09,44.700,0.01128,2.061,0.000
16.14,44.800,0.01145,2.067,0.000
16.20,44.900,0.01157,2.075,0.000
16.23,45.000,0.01174,2.079,0.000
16.31,45.100,0.01191,2.089,0.000
16.35,45.200,0.01207,2.094,0.000
16.43,45.300,0.01224,2.104,0.000
16.47,45.400,0.01240,2.109,0.000
16.55,45.500,0.01257,2.120,0.000
16.60,45.600,0.01278,2.126,0.000
16.67,45.700,0.01294,2.136,0.000
16.75,45.800,0.01315,2.145,0.000
16.80,45.900,0.01332,2.152,0.000
16.86,46.000,0.01353,2.159,0.000
16.94,46.100,0.01373,2.170,0.000
17.03,46.200,0.01394,2.181,0.000
17.09,46.300,0.01415,2.189,0.000
17.17,46.400,0.01436,2.199,0.000
17.26,46.500,0.01456,2.210,0.000
17.32,46.600,0.01481,2.218,0.000
17.40,46.700,0.01502,2.228,0.000
17.46,46.800,0.01523,2.236,0.000
17.55,46.900,0.01544,2.247,0.000
17.60,47.000,0.01565,2.255,0.000
17.68,47.100,0.01581,2.264,0.000
17.74,47.200,0.01602,2.272,0.000
17.80,47.300,0.01619,2.280,0.000
17.84,47.400,0.01639,2.285,0.000
17.91,47.500,0.01656,2.294,0.000
17.97,47.600,0.01673,2.302,0.000
18.01,47.700,0.01689,2.307,0.000
18.07,47.800,0.01702,2.314,0.000
18.13,47.900,0.01718,2.322,0.000
18.18,48.000,0.01735,2.328,0.000
18.23,48.100,0.01747,2.334,0.000
18.26,48.200,0.01764,2.339,0.000
18.30,48.300,0.01776,2.343,0.000
18.36,48.400,0.01793,2.351,0.000
18.41,48.500,0.01806,2.357,0.000
18.45,48.600,0.01818,2.363,0.000
18.49,48.700,0.01830,2.369,0.000
18.55,48.800,0.01847,2.376,0.000
18.59,48.900,0.01860,2.380,0.000
18.64,49.000,0.01872,2.387,0.000
18.69,49.100,0.01889,2.394,0.000
18.75,49.200,0.01901,2.402,0.000
18.79,49.300,0.01914,2.406,0.000
18.84,49.400,0.01930,2.414,0.000
18.91,49.500,0.01943,2.422,0.000
18.98,49.600,0.01959,2.431,0.000
19.01,49.700,0.01972,2.435,0.000
19.09,49.800,0.01988,2.445,0.000
19.14,49.900,0.02001,2.451,0.000
19.19,50.000,0.02017,2.458,0.000
19.23,50.100,0.02030,2.462,0.000
19.30,50.200,0.02047,2.472,0.000
19.37,50.300,0.02063,2.481,0.000
19.42,50.400,0.02080,2.487,0.000
19.46,50.500,0.02092,2.493,0.000
19.54,50.600,0.02109,2.503,0.000
19.60,50.700,0.02126,2.510,0.000
19.66,50.800,0.02142,2.518,0.000
19.71,50.900,0.02155,2.524,0.000
19.79,51.000,0.02171,2.535,0.000
19.83,51.100,0.02188,2.540,0.000
19.91,51.200,0.02204,2.550,0.000
19.98,51.300,0.02225,2.559,0.000
20.06,51.400,0.02242,2.569,0.000
20.13,51.500,0.02263,2.578,0.000
20.23,51.600,0.02279,2.591,0.000
20.30,51.700,0.02300,2.600,0.000
20.40,51.800,0.02325,2.612,0.000
20.47,51.900,0.02346,2.622,0.000
20.59,52.000,0.02367,2.638,0.000
20.68,52.100,0.02391,2.649,0.000
20.77,52.200,0.02412,2.660,0.000
20.84,52.300,0.02433,2.670,0.000
20.94,52.400,0.02454,2.682,0.000
21.01,52.500,0.02475,2.691,0.000
21.10,52.600,0.02495,2.703,0.000
21.19,52.700,0.02516,2.714,0.000
21.26,52.800,0.02537,2.723,0.000
21.32,52.900,0.02554,2.731,0.001
21.39,53.000,0.02574,2.740,0.001
21.45,53.100,0.02591,2.747,0.001
21.52,53.200,0.02608,2.757,0.001
21.57,53.300,0.02624,2.763,0.001
21.64,53.400,0.02641,2.771,0.001
21.68,53.500,0.02653,2.777,0.001
21.74,53.600,0.02670,2.784,0.001
21.79,53.700,0.02682,2.791,0.001
21.83,53.800,0.02699,2.796,0.001
21.90,53.900,0.02711,2.804,0.001
21.95,54.000,0.02724,2.811,0.001
22.00,54.100,0.02736,2.817,0.001
22.03,54.200,0.02753,2.822,0.001
22.09,54.300,0.02765,2.830,0.001
22.14,54.400,0.02778,2.836,0.001
22.20,54.500,0.02790,2.843,0.001
22.24,54.600,0.02803,2.849,0.001
22.32,54.700,0.02819,2.858,0.001
22.36,54.800,0.02832,2.864,0.001
22.43,54.900,0.02849,2.873,0.001
22.50,55.000,0.02861,2.882,0.001
22.56,55.100,0.02874,2.889,0.001
22.60,55.200,0.02890,2.895,0.001
22.70,55.300,0.02903,2.907,0.001
22.75,55.400,0.02919,2.914,0.001
22.82,55.500,0.02932,2.923,0.001
22.87,55.600,0.02948,2.929,0.001
22.95,55.700,0.02965,2.939,0.001
23.00,55.800,0.02977,2.945,0.001
23.07,55.900,0.02994,2.955,0.001
23.12,56.000,0.03006,2.961,0.001
23.21,56.100,0.03023,2.972,0.001
23.26,56.200,0.03040,2.979,0.001
23.33,56.300,0.03052,2.988,0.001
23.40,56.400,0.03069,2.997,0.001
23.48,56.500,0.03085,3.007,0.001
23.53,56.600,0.03102,3.014,0.001
23.62,56.700,0.03119,3.025,0.001
23.68,56.800,0.03135,3.033,0.001
23.79,56.900,0.03152,3.047,0.001
23.83,57.000,0.03169,3.052,0.001
23.95,57.100,0.03189,3.067,0.001
24.04,57.200,0.03206,3.079,0.001
24.12,57.300,0.03227,3.089,0.001
24.22,57.400,0.03248,3.102,0.001
24.34,57.500,0.03268,3.117,0.001
24.43,57.600,0.03289,3.129,0.001
24.55,57.700,0.03310,3.144,0.001
24.65,57.800,0.03335,3.157,0.001
24.75,57.900,0.03356,3.169,0.001
24.83,58.000,0.03376,3.181,0.001
24.94,58.100,0.03397,3.194,0.001
25.01,58.200,0.03418,3.203,0.001
25.11,58.300,0.03439,3.216,0.001
25.20,58.400,0.03459,3.227,0.001
25.28,58.500,0.03476,3.238,0.001
25.35,58.600,0.03497,3.247,0.001
25.43,58.700,0.03513,3.257,0.001
25.50,58.800,0.03530,3.266,0.001
25.56,58.900,0.03547,3.274,0.001
25.63,59.000,0.03563,3.283,0.001
25.68,59.100,0.03580,3.289,0.001
25.75,59.200,0.03592,3.297,0.001
25.82,59.300,0.03609,3.307,0.001
25.88,59.400,0.03626,3.314,0.001
25.93,59.500,0.03638,3.321,0.001
26.00,59.600,0.03655,3.329,0.001
26.06,59.700,0.03667,3.338,0.001
26.12,59.800,0.03680,3.345,0.001
26.18,59.900,0.03696,3.353,0.001
26.24,60.000,0.03709,3.361,0.001
26.30,60.100,0.03721,3.368,0.001
26.37,60.200,0.03734,3.378,0.001
26.43,60.300,0.03750,3.385,0.001
26.49,60.400,0.03763,3.393,0.001
26.57,60.500,0.03775,3.403,0.001
26.63,60.600,0.03792,3.411,0.001
26.69,60.700,0.03804,3.418,0.001
26.76,60.800,0.03817,3.428,0.001
26.85,60.900,0.03833,3.438,0.001
26.93,61.000,0.03850,3.449,0.001
26.99,61.100,0.03863,3.457,0.001
27.09,61.200,0.03879,3.469,0.001
27.14,61.300,0.03896,3.476,0.001
27.23,61.400,0.03908,3.488,0.001
27.29,61.500,0.03925,3.495,0.001
27.37,61.600,0.03942,3.506,0.001
27.44,61.700,0.03954,3.514,0.001
27.54,61.800,0.03971,3.527,0.001
27.61,61.900,0.03983,3.536,0.001
27.70,62.000,0.04000,3.548,0.001
27.78,62.100,0.04016,3.557,0.001
27.84,62.200,0.04033,3.566,0.001
27.95,62.300,0.04050,3.579,0.001
28.01,62.400,0.04066,3.588,0.001
28.09,62.500,0.04083,3.598,0.001
28.19,62.600,0.04099,3.610,0.001
28.28,62.700,0.04116,3.622,0.001
28.38,62.800,0.04133,3.634,0.001
28.46,62.900,0.04153,3.645,0.001
28.56,63.000,0.04170,3.658,0.001
28.66,63.100,0.04191,3.671,0.001
28.77,63.200,0.04212,3.685,0.001
28.89,63.300,0.04232,3.700,0.001
29.00,63.400,0.04253,3.714,0.001
29.11,63.500,0.04274,3.728,0.001
29.23,63.600,0.04295,3.743,0.001
29.33,63.700,0.04316,3.757,0.001
29.42,63.800,0.04336,3.768,0.001
29.52,63.900,0.04357,3.780,0.001
29.62,64.000,0.04378,3.794,0.001
29.73,64.100,0.04399,3.808,0.001
29.83,64.200,0.04419,3.821,0.001
29.93,64.300,0.04436,3.833,0.001
30.01,64.400,0.04457,3.844,0.001
30.09,64.500,0.04473,3.853,0.001
30.17,64.600,0.04490,3.864,0.001
30.27,64.700,0.04507,3.877,0.001
30.34,64.800,0.04523,3.886,0.001
30.41,64.900,0.04540,3.895,0.001
30.50,65.000,0.04552,3.906,0.001
30.58,65.100,0.04569,3.917,0.001
30.65,65.200,0.04581,3.925,0.001
30.73,65.300,0.04598,3.936,0.001
30.80,65.400,0.04615,3.945,0.001
30.86,65.500,0.04627,3.952,0.001
30.93,65.600,0.04640,3.961,0.001
31.01,65.700,0.04652,3.972,0.001
31.06,65.800,0.04665,3.979,0.001
31.16,65.900,0.04681,3.991,0.001
31.23,66.000,0.04694,4.000,0.001
31.31,66.100,0.04706,4.010,0.001
31.36,66.200,0.04723,4.017,0.001
31.46,66.300,0.04735,4.030,0.001
31.53,66.400,0.04748,4.038,0.001
31.61,66.500,0.04764,4.049,0.001
31.68,66.600,0.04777,4.057,0.001
31.77,66.700,0.04793,4.069,0.001
31.85,66.800,0.04806,4.079,0.001
31.94,66.900,0.04822,4.090,0.001
32.02,67.000,0.04835,4.101,0.001
32.11,67.100,0.04852,4.113,0.001
32.18,67.200,0.04868,4.121,0.001
32.28,67.300,0.04881,4.135,0.001
32.36,67.400,0.04897,4.145,0.001
32.44,67.500,0.04910,4.155,0.001
32.51,67.600,0.04926,4.163,0.001
32.61,67.700,0.04943,4.176,0.001
32.69,67.800,0.04960,4.187,0.001
32.79,67.900,0.04972,4.199,0.001
32.87,68.000,0.04989,4.209,0.001
32.96,68.100,0.05005,4.222,0.001
33.05,68.200,0.05022,4.233,0.001
33.16,68.300,0.05039,4.247,0.001
33.24,68.400,0.05055,4.257,0.001
33.34,68.500,0.05072,4.270,0.001
33.45,68.600,0.05093,4.284,0.001
33.58,68.700,0.05109,4.301,0.001
33.69,68.800,0.05130,4.315,0.001
33.81,68.900,0.05151,4.330,0.001
33.93,69.000,0.05172,4.346,0.001
34.06,69.100,0.05192,4.362,0.001
34.19,69.200,0.05217,4.379,0.001
34.32,69.300,0.05238,4.395,0.001
34.42,69.400,0.05259,4.408,0.001
34.55,69.500,0.05280,4.424,0.001
34.67,69.600,0.05300,4.440,0.001
34.79,69.700,0.05321,4.456,0.001
34.92,69.800,0.05342,4.472,0.001
35.02,69.900,0.05363,4.486,0.001
35.14,70.000,0.05383,4.501,0.001
35.24,70.100,0.05400,4.513,0.001
35.34,70.200,0.05417,4.526,0.001
35.40,70.300,0.05433,4.534,0.001
35.51,70.400,0.05450,4.548,0.001
35.59,70.500,0.05467,4.559,0.001
35.68,70.600,0.05483,4.569,0.001
35.77,70.700,0.05500,4.582,0.001
35.85,70.800,0.05512,4.591,0.001
35.92,70.900,0.05529,4.601,0.001
36.01,71.000,0.05541,4.612,0.001
36.08,71.100,0.05558,4.622,0.001
36.16,71.200,0.05570,4.631,0.001
36.24,71.300,0.05583,4.641,0.001
36.32,71.400,0.05595,4.651,0.001
36.40,71.500,0.05612,4.662,0.001
36.48,71.600,0.05625,4.672,0.001
36.56,71.700,0.05637,4.683,0.001
36.63,71.800,0.05649,4.691,0.001
36.72,71.900,0.05666,4.703,0.001
36.82,72.000,0.05679,4.716,0.001
36.91,72.100,0.05695,4.727,0.001
37.00,72.200,0.05708,4.739,0.001
37.09,72.300,0.05724,4.750,0.001
37.19,72.400,0.05737,4.764,0.001
37.26,72.500,0.05753,4.772,0.001
37.35,72.600,0.05766,4.783,0.001
37.46,72.700,0.05782,4.797,0.001
37.54,72.800,0.05799,4.808,0.001
37.64,72.900,0.05812,4.821,0.001
37.72,73.000,0.05828,4.831,0.001
37.81,73.100,0.05845,4.842,0.001
37.89,73.200,0.05857,4.853,0.001
37.98,73.300,0.05874,4.864,0.001
38.11,73.400,0.05890,4.881,0.001
38.18,73.500,0.05907,4.890,0.001
38.28,73.600,0.05924,4.903,0.001
38.38,73.700,0.05940,4.916,0.001
38.52,73.800,0.05957,4.933,0.001
38.62,73.900,0.05974,4.947,0.001
38.73,74.000,0.05990,4.961,0.001
38.84,74.100,0.06007,4.975,0.001
38.96,74.200,0.06023,4.990,0.001
39.10,74.300,0.06044,5.008,0.001
39.23,74.400,0.06065,5.024,0.001
39.36,74.500,0.06082,5.041,0.001
39.50,74.600,0.06102,5.059,0.001
39.62,74.700,0.06123,5.075,0.001
39.80,74.800,0.06148,5.097,0.001
39.94,74.900,0.06169,5.115,0.001
40.11,75.000,0.06190,5.137,0.001
40.25,75.100,0.06215,5.155,0.001
40.39,75.200,0.06235,5.173,0.001
40.54,75.300,0.06256,5.193,0.001
40.66,75.400,0.06277,5.208,0.001
40.79,75.500,0.06298,5.224,0.001
40.91,75.600,0.06314,5.240,0.001
41.02,75.700,0.06335,5.254,0.001
41.15,75.800,0.06356,5.271,0.001
41.27,75.900,0.06373,5.286,0.001
41.39,76.000,0.06389,5.301,0.001
41.48,76.100,0.06406,5.312,0.001
41.56,76.200,0.06422,5.323,0.001
41.64,76.300,0.06439,5.333,0.001
41.73,76.400,0.06451,5.345,0.001
41.83,76.500,0.06468,5.357,0.001
41.93,76.600,0.06481,5.370,0.001
42.02,76.700,0.06497,5.382,0.001
42.11,76.800,0.06510,5.393,0.001
42.20,76.900,0.06526,5.405,0.001
42.29,77.000,0.06539,5.417,0.001
42.36,77.100,0.06551,5.425,0.001
42.45,77.200,0.06564,5.437,0.001
42.55,77.300,0.06576,5.449,0.001
42.63,77.400,0.06593,5.460,0.001
42.73,77.500,0.06605,5.473,0.001
42.85,77.600,0.06622,5.488,0.001
42.94,77.700,0.06634,5.499,0.001
43.02,77.800,0.06647,5.510,0.001
43.16,77.900,0.06663,5.527,0.001
43.26,78.000,0.06680,5.540,0.001
43.36,78.100,0.06693,5.553,0.001
43.47,78.200,0.06709,5.567,0.001
43.60,78.300,0.06726,5.584,0.001
43.70,78.400,0.06738,5.597,0.001
43.81,78.500,0.06755,5.611,0.001
43.90,78.600,0.06771,5.623,0.001
44.02,78.700,0.06784,5.638,0.001
44.14,78.800,0.06801,5.653,0.001
44.25,78.900,0.06817,5.667,0.001
44.37,79.000,0.06834,5.682,0.001
44.47,79.100,0.06846,5.695,0.001
44.59,79.200,0.06863,5.710,0.001
44.70,79.300,0.06880,5.725,0.001
44.81,79.400,0.06896,5.739,0.001
44.94,79.500,0.06913,5.755,0.001
15.79,79.600,0.06929,2.023,0.001
13.06,79.700,0.06946,1.673,0.001
12.99,79.800,0.06963,1.664,0.001
13.17,79.900,0.06983,1.686,0.001
13.39,80.000,0.07000,1.715,0.001
13.61,80.100,0.07021,1.743,0.001
13.85,80.200,0.07042,1.774,0.001
14.12,80.300,0.07062,1.809,0.001
14.34,80.400,0.07083,1.837,0.001
14.56,80.500,0.07108,1.864,0.001
14.77,80.600,0.07129,1.892,0.001
14.99,80.700,0.07150,1.920,0.001
15.18,80.800,0.07170,1.944,0.001
15.34,80.900,0.07191,1.964,0.001
15.50,81.000,0.07212,1.985,0.001
15.62,81.100,0.07233,2.001,0.001
15.76,81.200,0.07249,2.019,0.001
15.88,81.300,0.07270,2.034,0.001
16.00,81.400,0.07287,2.049,0.001
16.08,81.500,0.07308,2.060,0.001
16.19,81.600,0.07324,2.073,0.001
16.27,81.700,0.07341,2.084,0.001
16.37,81.800,0.07357,2.097,0.001
16.45,81.900,0.07374,2.107,0.001
16.53,82.000,0.07386,2.118,0.001
16.61,82.100,0.07403,2.127,0.001
16.71,82.200,0.07420,2.140,0.001
16.76,82.300,0.07432,2.146,0.001
16.82,82.400,0.07449,2.155,0.001
16.88,82.500,0.07461,2.162,0.001
16.96,82.600,0.07474,2.172,0.001
17.00,82.700,0.07490,2.178,0.001
17.09,82.800,0.07503,2.189,0.001
17.14,82.900,0.07515,2.196,0.001
17.21,83.000,0.07528,2.204,0.001
17.28,83.100,0.07544,2.213,0.001
17.34,83.200,0.07557,2.221,0.001
17.43,83.300,0.07569,2.232,0.001
17.49,83.400,0.07586,2.240,0.001
17.54,83.500,0.07598,2.247,0.001
17.62,83.600,0.07615,2.257,0.001
17.69,83.700,0.07628,2.266,0.002
17.77,83.800,0.07644,2.276,0.002
17.83,83.900,0.07657,2.284,0.002
17.91,84.000,0.07673,2.294,0.002
17.96,84.100,0.07686,2.300,0.002
18.04,84.200,0.07702,2.310,0.002
18.11,84.300,0.07719,2.320,0.002
18.19,84.400,0.07731,2.329,0.002
18.25,84.500,0.07748,2.337,0.002
18.33,84.600,0.07765,2.348,0.002
18.40,84.700,0.07781,2.357,0.002
18.47,84.800,0.07798,2.366,0.002
18.56,84.900,0.07810,2.378,0.002
18.64,85.000,0.07827,2.387,0.002
18.69,85.100,0.07844,2.394,0.002
18.77,85.200,0.07860,2.403,0.002
18.84,85.300,0.07877,2.413,0.002
18.92,85.400,0.07893,2.423,0.002
19.01,85.500,0.07910,2.435,0.002
19.10,85.600,0.07931,2.446,0.002
19.21,85.700,0.07952,2.460,0.002
19.30,85.800,0.07972,2.472,0.002
19.40,85.900,0.07993,2.485,0.002
19.50,86.000,0.08014,2.497,0.002
19.60,86.100,0.08035,2.510,0.002
19.70,86.200,0.08060,2.523,0.002
19.78,86.300,0.08080,2.534,0.002
19.87,86.400,0.08101,2.545,0.002
19.96,86.500,0.08122,2.556,0.002
20.06,86.600,0.08143,2.569,0.002
20.15,86.700,0.08164,2.580,0.002
20.22,86.800,0.08184,2.590,0.002
20.30,86.900,0.08205,2.601,0.002
20.37,87.000,0.08222,2.609,0.002
20.46,87.100,0.08238,2.620,0.002
20.51,87.200,0.08259,2.627,0.002
20.59,87.300,0.08276,2.638,0.002
20.65,87.400,0.08292,2.645,0.002
20.73,87.500,0.08309,2.655,0.002
20.79,87.600,0.08321,2.663,0.002
20.86,87.700,0.08338,2.672,0.002
20.90,87.800,0.08351,2.677,0.002
20.97,87.900,0.08367,2.686,0.002
21.04,88.000,0.08380,2.695,0.002
21.09,88.100,0.08396,2.702,0.002
21.16,88.200,0.08409,2.710,0.002
21.22,88.300,0.08421,2.717,0.002
21.28,88.400,0.08434,2.725,0.002
21.33,88.500,0.08450,2.732,0.002
21.39,88.600,0.08463,2.739,0.002
21.46,88.700,0.08475,2.748,0.002
21.52,88.800,0.08488,2.756,0.002
21.61,88.900,0.08504,2.767,0.002
21.65,89.000,0.08517,2.773,0.002
21.73,89.100,0.08529,2.783,0.002
21.78,89.200,0.08546,2.790,0.002
21.86,89.300,0.08558,2.800,0.002
21.93,89.400,0.08575,2.809,0.002
22.02,89.500,0.08587,2.820,0.002
22.08,89.600,0.08604,2.827,0.002
22.14,89.700,0.08621,2.836,0.002
22.23,89.800,0.08633,2.847,0.002
22.30,89.900,0.08650,2.856,0.002
22.36,90.000,0.08662,2.864,0.002
22.43,90.100,0.08679,2.872,0.002
22.51,90.200,0.08695,2.883,0.002
22.59,90.300,0.08712,2.893,0.002
22.66,90.400,0.08725,2.902,0.002
22.73,90.500,0.08741,2.911,0.002
22.79,90.600,0.08758,2.919,0.002
22.87,90.700,0.08774,2.929,0.002
22.96,90.800,0.08791,2.940,0.002
23.05,90.900,0.08808,2.952,0.002
23.13,91.000,0.08824,2.963,0.002
23.20,91.100,0.08841,2.971,0.002
23.30,91.200,0.08858,2.984,0.002
23.38,91.300,0.08878,2.995,0.002
23.49,91.400,0.08895,3.008,0.002
23.60,91.500,0.08916,3.023,0.002
23.69,91.600,0.08937,3.034,0.002
23.79,91.700,0.08957,3.046,0.002
23.90,91.800,0.08978,3.060,0.002
24.01,91.900,0.08999,3.075,0.002
24.12,92.000,0.09020,3.089,0.002
24.23,92.100,0.09040,3.103,0.002
24.34,92.200,0.09065,3.118,0.002
24.45,92.300,0.09086,3.132,0.002
24.55,92.400,0.09107,3.145,0.002
24.66,92.500,0.09124,3.159,0.002
24.76,92.600,0.09144,3.172,0.002
24.84,92.700,0.09165,3.182,0.002
24.96,92.800,0.09182,3.197,0.002
25.05,92.900,0.09202,3.208,0.002
25.15,93.000,0.09219,3.221,0.002
25.22,93.100,0.09236,3.231,0.002
25.32,93.200,0.09252,3.243,0.002
25.38,93.300,0.09269,3.251,0.002
25.46,93.400,0.09281,3.261,0.002
25.54,93.500,0.09298,3.272,0.002
25.64,93.600,0.09311,3.284,0.002
25.71,93.700,0.09327,3.292,0.002
25.79,93.800,0.09340,3.304,0.002
25.84,93.900,0.09352,3.310,0.002
25.93,94.000,0.09369,3.322,0.002
25.98,94.100,0.09381,3.328,0.002
26.05,94.200,0.09394,3.337,0.002
26.14,94.300,0.09406,3.348,0.002
26.21,94.400,0.09419,3.357,0.002
26.28,94.500,0.09435,3.366,0.002
26.35,94.600,0.09448,3.375,0.002
26.43,94.700,0.09460,3.385,0.002
26.52,94.800,0.09477,3.397,0.002
26.59,94.900,0.09489,3.406,0.002
26.69,95.000,0.09502,3.418,0.002
26.76,95.100,0.09518,3.428,0.002
26.87,95.200,0.09535,3.441,0.002
26.94,95.300,0.09547,3.450,0.002
27.04,95.400,0.09564,3.463,0.002
27.13,95.500,0.09581,3.474,0.002
27.21,95.600,0.09593,3.485,0.002
27.29,95.700,0.09610,3.496,0.002
27.38,95.800,0.09626,3.507,0.002
27.48,95.900,0.09639,3.520,0.002
27.57,96.000,0.09655,3.530,0.002
27.67,96.100,0.09672,3.544,0.002
27.73,96.200,0.09689,3.551,0.002
27.83,96.300,0.09701,3.564,0.002
27.92,96.400,0.09718,3.576,0.002
28.03,96.500,0.09734,3.590,0.002
28.11,96.600,0.09751,3.600,0.002
28.21,96.700,0.09768,3.614,0.002
28.31,96.800,0.09788,3.625,0.002
28.42,96.900,0.09805,3.640,0.002
28.54,97.000,0.09826,3.655,0.002
28.65,97.100,0.09842,3.669,0.002
28.75,97.200,0.09863,3.682,0.002
28.90,97.300,0.09884,3.701,0.002
29.03,97.400,0.09905,3.718,0.002
29.14,97.500,0.09926,3.732,0.002
29.27,97.600,0.09946,3.749,0.002
29.40,97.700,0.09967,3.766,0.002
29.54,97.800,0.09988,3.783,0.002
29.68,97.900,0.10009,3.802,0.002
29.81,98.000,0.10029,3.818,0.002
29.94,98.100,0.10050,3.835,0.002
30.06,98.200,0.10071,3.850,0.002
30.15,98.300,0.10088,3.862,0.002
30.28,98.400,0.10108,3.878,0.002
30.40,98.500,0.10125,3.894,0.002
30.48,98.600,0.10146,3.904,0.002
30.59,98.700,0.10162,3.918,0.002
30.70,98.800,0.10179,3.932,0.002
30.79,98.900,0.10196,3.943,0.002
30.88,99.000,0.10208,3.955,0.002
30.98,99.100,0.10225,3.968,0.002
31.05,99.200,0.10237,3.977,0.002
31.15,99.300,0.10254,3.990,0.002
31.26,99.400,0.10270,4.003,0.002
31.34,99.500,0.10283,4.014,0.002
31.42,99.600,0.10295,4.025,0.002
31.51,99.700,0.10312,4.036,0.002
31.58,99.800,0.10324,4.045,0.002
31.66,99.900,0.10337,4.055,0.002
31.76,100.000,0.10349,4.068,0.002
31.85,100.100,0.10366,4.079,0.002
31.92,100.200,0.10379,4.088,0.002
32.02,100.300,0.10391,4.101,0.002
32.11,100.400,0.10403,4.113,0.002
32.19,100.500,0.10420,4.123,0.002
32.29,100.600,0.10433,4.135,0.002
32.38,100.700,0.10449,4.147,0.002
32.47,100.800,0.10462,4.159,0.002
32.58,100.900,0.10478,4.172,0.002
32.68,101.000,0.10491,4.185,0.002
32.78,101.100,0.10507,4.198,0.002
32.87,101.200,0.10524,4.210,0.002
32.98,101.300,0.10541,4.224,0.002
33.08,101.400,0.10553,4.237,0.002
33.19,101.500,0.10570,4.251,0.002
33.30,101.600,0.10586,4.265,0.002
33.41,101.700,0.10603,4.279,0.002
33.51,101.800,0.10620,4.292,0.002
33.62,101.900,0.10636,4.307,0.002
33.73,102.000,0.10649,4.320,0.002
33.84,102.100,0.10665,4.334,0.002
33.96,102.200,0.10682,4.349,0.002
34.06,102.300,0.10698,4.363,0.002
34.18,102.400,0.10715,4.378,0.002
34.28,102.500,0.10736,4.390,0.002
34.42,102.600,0.10753,4.408,0.002
34.58,102.700,0.10773,4.428,0.002
34.72,102.800,0.10794,4.447,0.002
34.89,102.900,0.10815,4.468,0.002
35.04,103.000,0.10836,4.488,0.002
35.19,103.100,0.10861,4.507,0.002
35.35,103.200,0.10881,4.528,0.002
35.52,103.300,0.10902,4.550,0.002
35.68,103.400,0.10927,4.570,0.002
35.83,103.500,0.10948,4.589,0.002
35.99,103.600,0.10969,4.609,0.002
36.13,103.700,0.10989,4.627,0.002
36.25,103.800,0.11010,4.643,0.002
36.39,103.900,0.11031,4.660,0.002
36.51,104.000,0.11052,4.676,0.002
36.64,104.100,0.11068,4.693,0.002
36.74,104.200,0.11089,4.706,0.002
36.89,104.300,0.11106,4.724,0.002
36.99,104.400,0.11122,4.737,0.002
37.07,104.500,0.11139,4.748,0.002
37.17,104.600,0.11151,4.761,0.002
37.27,104.700,0.11168,4.773,0.002
37.36,104.800,0.11181,4.786,0.002
37.47,104.900,0.11197,4.799,0.002
37.56,105.000,0.11210,4.811,0.002
37.65,105.100,0.11226,4.822,0.002
37.74,105.200,0.11239,4.833,0.002
37.83,105.300,0.11251,4.845,0.002
37.92,105.400,0.11264,4.857,0.002
38.02,105.500,0.11280,4.870,0.002
38.12,105.600,0.11293,4.882,0.002
38.20,105.700,0.11305,4.892,0.002
38.30,105.800,0.11322,4.906,0.002
38.41,105.900,0.11334,4.919,0.002
38.50,106.000,0.11347,4.931,0.002
38.60,106.100,0.11363,4.943,0.002
38.71,106.200,0.11376,4.958,0.002
38.80,106.300,0.11392,4.969,0.002
38.92,106.400,0.11405,4.984,0.002
39.01,106.500,0.11422,4.997,0.002
39.13,106.600,0.11438,5.011,0.002
39.22,106.700,0.11451,5.023,0.002
39.33,106.800,0.11467,5.038,0.002
39.44,106.900,0.11484,5.052,0.002
39.56,107.000,0.11501,5.067,0.002
39.66,107.100,0.11513,5.079,0.002
39.78,107.200,0.11530,5.095,0.002
39.90,107.300,0.11546,5.110,0.002
40.02,107.400,0.11563,5.125,0.002
40.13,107.500,0.11579,5.140,0.002
40.25,107.600,0.11592,5.155,0.002
40.38,107.700,0.11609,5.171,0.002
40.48,107.800,0.11625,5.185,0.002
40.60,107.900,0.11642,5.200,0.002
40.74,108.000,0.11658,5.217,0.002
40.85,108.100,0.11679,5.232,0.002
40.99,108.200,0.11696,5.250,0.002
41.14,108.300,0.11717,5.269,0.002
41.28,108.400,0.11733,5.286,0.002
41.43,108.500,0.11754,5.307,0.002
41.58,108.600,0.11775,5.326,0.002
41.74,108.700,0.11796,5.345,0.002
41.90,108.800,0.11820,5.366,0.002
42.06,108.900,0.11841,5.387,0.002
42.22,109.000,0.11862,5.407,0.002
42.37,109.100,0.11887,5.427,0.002
42.52,109.200,0.11908,5.445,0.002
42.65,109.300,0.11929,5.463,0.002
42.78,109.400,0.11949,5.480,0.002
42.93,109.500,0.11970,5.499,0.002
43.06,109.600,0.11991,5.515,0.002
43.16,109.700,0.12007,5.528,0.002
43.28,109.800,0.12028,5.543,0.002
43.38,109.900,0.12045,5.556,0.002
43.48,110.000,0.12062,5.569,0.002
43.59,110.100,0.12078,5.583,0.002
43.69,110.200,0.12095,5.596,0.002
43.79,110.300,0.12111,5.609,0.002
43.90,110.400,0.12124,5.622,0.002
43.97,110.500,0.12140,5.632,0.002
44.05,110.600,0.12153,5.642,0.002
44.14,110.700,0.12170,5.654,0.002
44.24,110.800,0.12182,5.666,0.002
44.32,110.900,0.12194,5.676,0.002
44.42,111.000,0.12211,5.689,0.002
44.51,111.100,0.12224,5.701,0.002
44.60,111.200,0.12236,5.712,0.002
44.70,111.300,0.12253,5.725,0.002
44.78,111.400,0.12265,5.735,0.002
44.89,111.500,0.12278,5.749,0.002
44.98,111.600,0.12294,5.761,0.002
45.07,111.700,0.12307,5.772,0.002
45.18,111.800,0.12323,5.787,0.002
45.27,111.900,0.12336,5.798,0.002
45.38,112.000,0.12352,5.812,0.002
45.50,112.100,0.12365,5.827,0.002
45.59,112.200,0.12381,5.839,0.002
45.71,112.300,0.12398,5.855,0.002
8.26,112.400,0.12411,1.058,0.002
11.78,112.500,0.12427,1.509,0.002
12.29,112.600,0.12444,1.574,0.002
12.50,112.700,0.12460,1.601,0.002
12.70,112.800,0.12473,1.626,0.002
12.89,112.900,0.12490,1.651,0.002
13.09,113.000,0.12506,1.677,0.002
13.30,113.100,0.12523,1.704,0.002
13.46,113.200,0.12539,1.724,0.002
13.64,113.300,0.12556,1.746,0.002
13.82,113.400,0.12573,1.770,0.002
14.00,113.500,0.12589,1.793,0.002
14.14,113.600,0.12606,1.811,0.002
14.31,113.700,0.12623,1.832,0.002
14.46,113.800,0.12643,1.852,0.002
14.59,113.900,0.12660,1.868,0.002
14.72,114.000,0.12681,1.885,0.002
14.88,114.100,0.12697,1.905,0.002
15.01,114.200,0.12718,1.923,0.003
15.14,114.300,0.12743,1.939,0.003
15.27,114.400,0.12764,1.956,0.003
15.38,114.500,0.12785,1.969,0.003
15.50,114.600,0.12805,1.986,0.003
15.61,114.700,0.12830,1.999,0.003
15.70,114.800,0.12851,2.011,0.003
15.80,114.900,0.12872,2.023,0.003
15.89,115.000,0.12888,2.035,0.003
15.98,115.100,0.12909,2.046,0.003
16.06,115.200,0.12930,2.057,0.003
16.15,115.300,0.12951,2.068,0.003
16.20,115.400,0.12967,2.075,0.003
16.28,115.500,0.12988,2.086,0.003
16.37,115.600,0.13005,2.096,0.003
16.41,115.700,0.13021,2.102,0.003
16.49,115.800,0.13038,2.111,0.003
16.54,115.900,0.13055,2.119,0.003
16.61,116.000,0.13067,2.127,0.003
16.66,116.100,0.13084,2.134,0.003
16.71,116.200,0.13100,2.141,0.003
16.78,116.300,0.13113,2.149,0.003
16.81,116.400,0.13130,2.153,0.003
16.87,116.500,0.13142,2.160,0.003
16.92,116.600,0.13154,2.167,0.003
16.98,116.700,0.13171,2.175,0.003
17.01,116.800,0.13184,2.178,0.003
17.06,116.900,0.13196,2.186,0.003
17.12,117.000,0.13213,2.193,0.003
17.17,117.100,0.13225,2.199,0.003
17.22,117.200,0.13238,2.206,0.003
17.28,117.300,0.13254,2.213,0.003
17.34,117.400,0.13267,2.221,0.003
17.38,117.500,0.13283,2.226,0.003
17.44,117.600,0.13296,2.234,0.003
17.50,117.700,0.13312,2.241,0.003
17.55,117.800,0.13325,2.248,0.003
17.60,117.900,0.13341,2.255,0.003
17.67,118.000,0.13354,2.263,0.003
17.70,118.100,0.13371,2.267,0.003
17.76,118.200,0.13387,2.275,0.003
17.81,118.300,0.13404,2.281,0.003
17.87,118.400,0.13416,2.288,0.003
17.92,118.500,0.13433,2.295,0.003
17.98,118.600,0.13449,2.303,0.003
18.04,118.700,0.13466,2.311,0.003
18.08,118.800,0.13479,2.316,0.003
18.14,118.900,0.13495,2.323,0.003
18.19,119.000,0.13512,2.330,0.003
18.26,119.100,0.13528,2.338,0.003
18.31,119.200,0.13545,2.345,0.003
18.37,119.300,0.13562,2.352,0.003
18.41,119.400,0.13578,2.358,0.003
18.48,119.500,0.13599,2.367,0.003
18.55,119.600,0.13616,2.376,0.003
18.62,119.700,0.13636,2.385,0.003
18.66,119.800,0.13657,2.390,0.003
18.75,119.900,0.13678,2.401,0.003
18.81,120.000,0.13699,2.409,0.003
18.89,120.100,0.13720,2.419,0.003
18.94,120.200,0.13740,2.426,0.003
18.97,120.300,0.13765,2.430,0.003
19.07,120.400,0.13786,2.443,0.003
19.11,120.500,0.13807,2.447,0.003
19.17,120.600,0.13828,2.455,0.003
19.22,120.700,0.13848,2.462,0.003
19.26,120.800,0.13869,2.467,0.003
19.31,120.900,0.13886,2.474,0.003
19.37,121.000,0.13907,2.481,0.003
19.41,121.100,0.13923,2.486,0.003
19.42,121.200,0.13940,2.487,0.003
19.46,121.300,0.13956,2.492,0.003
19.50,121.400,0.13973,2.498,0.003
19.55,121.500,0.13990,2.503,0.003
19.56,121.600,0.14006,2.505,0.003
19.61,121.700,0.14019,2.512,0.003
19.61,121.800,0.14035,2.511,0.003
19.66,121.900,0.14048,2.517,0.003
19.67,122.000,0.14060,2.520,0.003
19.71,122.100,0.14077,2.524,0.003
19.72,122.200,0.14089,2.525,0.003
19.76,122.300,0.14102,2.531,0.003
19.77,122.400,0.14114,2.532,0.003
19.80,122.500,0.14131,2.536,0.003
19.83,122.600,0.14143,2.540,0.003
19.92,122.700,0.14156,2.551,0.003
19.90,122.800,0.14168,2.549,0.003
19.97,122.900,0.14185,2.557,0.003
19.97,123.000,0.14197,2.558,0.003
20.03,123.100,0.14214,2.566,0.003
20.04,123.200,0.14227,2.566,0.003
20.08,123.300,0.14243,2.572,0.003
20.11,123.400,0.14256,2.575,0.003
20.15,123.500,0.14272,2.581,0.003
20.18,123.600,0.14289,2.584,0.003
20.22,123.700,0.14301,2.590,0.003
20.23,123.800,0.14318,2.591,0.003
20.29,123.900,0.14330,2.598,0.003
20.30,124.000,0.14347,2.600,0.003
20.35,124.100,0.14364,2.607,0.003
20.35,124.200,0.14380,2.607,0.003
20.41,124.300,0.14393,2.614,0.003
20.42,124.400,0.14409,2.615,0.003
20.46,124.500,0.14426,2.620,0.003
20.48,124.600,0.14439,2.623,0.003
20.52,124.700,0.14455,2.628,0.003
20.54,124.800,0.14472,2.631,0.003
20.59,124.900,0.14488,2.637,0.003
20.62,125.000,0.14505,2.641,0.003
20.66,125.100,0.14526,2.646,0.003
20.69,125.200,0.14542,2.649,0.003
20.75,125.300,0.14563,2.657,0.003
20.78,125.400,0.14580,2.661,0.003
20.82,125.500,0.14601,2.667,0.003
20.86,125.600,0.14621,2.672,0.003
20.89,125.700,0.14642,2.676,0.003
20.95,125.800,0.14663,2.683,0.003
20.98,125.900,0.14684,2.687,0.003
21.00,126.000,0.14709,2.689,0.003
21.02,126.100,0.14729,2.692,0.003
21.06,126.200,0.14750,2.697,0.003
21.09,126.300,0.14771,2.701,0.003
21.11,126.400,0.14792,2.703,0.003
21.13,126.500,0.14813,2.706,0.003
21.16,126.600,0.14829,2.711,0.003
21.16,126.700,0.14850,2.710,0.003
21.19,126.800,0.14867,2.714,0.003
21.19,126.900,0.14887,2.714,0.003
21.20,127.000,0.14904,2.715,0.003
21.20,127.100,0.14921,2.716,0.003
21.22,127.200,0.14933,2.718,0.003
21.22,127.300,0.14950,2.718,0.003
21.23,127.400,0.14966,2.719,0.003
21.26,127.500,0.14979,2.723,0.003
21.26,127.600,0.14995,2.723,0.003
21.26,127.700,0.15008,2.722,0.003
21.28,127.800,0.15020,2.725,0.003
21.26,127.900,0.15037,2.723,0.003
21.28,128.000,0.15049,2.726,0.003
21.27,128.100,0.15062,2.724,0.003
21.29,128.200,0.15078,2.727,0.003
21.29,128.300,0.15091,2.727,0.003
21.31,128.400,0.15103,2.730,0.003
21.34,128.500,0.15116,2.733,0.003
21.37,128.600,0.15132,2.737,0.003
21.37,128.700,0.15145,2.737,0.003
21.38,128.800,0.15162,2.738,0.003
21.41,128.900,0.15174,2.742,0.003
21.44,129.000,0.15191,2.746,0.003
21.46,129.100,0.15203,2.748,0.003
21.49,129.200,0.15220,2.752,0.003
21.49,129.300,0.15232,2.752,0.003
21.53,129.400,0.15249,2.757,0.003
21.53,129.500,0.15265,2.758,0.003
21.57,129.600,0.15282,2.762,0.003
21.56,129.700,0.15295,2.762,0.003
21.61,129.800,0.15311,2.768,0.003
21.60,129.900,0.15328,2.767,0.003
21.63,130.000,0.15344,2.770,0.003
21.62,130.100,0.15357,2.769,0.003
21.67,130.200,0.15374,2.775,0.003
21.68,130.300,0.15390,2.776,0.003
21.70,130.400,0.15407,2.779,0.003
21.69,130.500,0.15423,2.778,0.003
21.72,130.600,0.15440,2.782,0.003
21.72,130.700,0.15457,2.781,0.003
21.74,130.800,0.15477,2.784,0.003
21.78,130.900,0.15494,2.789,0.003
21.81,131.000,0.15515,2.793,0.003
21.81,131.100,0.15531,2.793,0.003
21.84,131.200,0.15552,2.797,0.003
21.85,131.300,0.15573,2.798,0.003
21.87,131.400,0.15594,2.800,0.003
21.87,131.500,0.15619,2.801,0.003
21.90,131.600,0.15639,2.805,0.003
21.91,131.700,0.15660,2.806,0.003
21.93,131.800,0.15685,2.809,0.003
21.91,131.900,0.15702,2.807,0.003
21.93,132.000,0.15723,2.809,0.003
21.93,132.100,0.15743,2.809,0.003
21.96,132.200,0.15764,2.812,0.003
21.96,132.300,0.15785,2.812,0.003
21.96,132.400,0.15802,2.812,0.003
21.94,132.500,0.15818,2.811,0.003
21.98,132.600,0.15839,2.815,0.003
21.96,132.700,0.15851,2.813,0.003
21.95,132.800,0.15868,2.811,0.003
21.96,132.900,0.15885,2.813,0.003
21.95,133.000,0.15901,2.811,0.003
21.94,133.100,0.15914,2.810,0.003
21.95,133.200,0.15930,2.811,0.003
21.95,133.300,0.15943,2.811,0.003
21.95,133.400,0.15959,2.812,0.003
21.96,133.500,0.15972,2.813,0.003
21.96,133.600,0.15989,2.813,0.003
21.97,133.700,0.16001,2.814,0.003
21.97,133.800,0.16013,2.814,0.003
21.99,133.900,0.16030,2.816,0.003
21.95,134.000,0.16043,2.812,0.003
22.00,134.100,0.16055,2.817,0.003
22.00,134.200,0.16068,2.817,0.003
22.01,134.300,0.16084,2.819,0.003
22.00,134.400,0.16097,2.818,0.003
22.03,134.500,0.16113,2.822,0.003
22.02,134.600,0.16126,2.820,0.003
22.04,134.700,0.16142,2.823,0.003
22.02,134.800,0.16155,2.821,0.003
22.07,134.900,0.16171,2.826,0.003
22.05,135.000,0.16184,2.824,0.003
22.09,135.100,0.16200,2.829,0.003
22.08,135.200,0.16217,2.828,0.003
22.10,135.300,0.16230,2.831,0.003
22.11,135.400,0.16246,2.832,0.003
22.14,135.500,0.16263,2.835,0.003
22.12,135.600,0.16275,2.834,0.003
22.15,135.700,0.16292,2.837,0.003
22.13,135.800,0.16309,2.835,0.003
22.18,135.900,0.16325,2.840,0.003
22.15,136.000,0.16338,2.836,0.003
22.18,136.100,0.16354,2.841,0.003
22.18,136.200,0.16371,2.840,0.003
22.21,136.300,0.16387,2.844,0.003
22.19,136.400,0.16408,2.842,0.003
22.23,136.500,0.16425,2.847,0.003
22.23,136.600,0.16446,2.847,0.003
22.25,136.700,0.16462,2.849,0.003
22.25,136.800,0.16483,2.850,0.003
22.29,136.900,0.16504,2.855,0.003
22.28,137.000,0.16525,2.853,0.003
22.31,137.100,0.16545,2.858,0.003
22.31,137.200,0.16570,2.857,0.003
22.34,137.300,0.16591,2.861,0.003
22.33,137.400,0.16612,2.860,0.003
22.35,137.500,0.16637,2.863,0.003
22.34,137.600,0.16658,2.862,0.003
22.35,137.700,0.16678,2.862,0.003
22.31,137.800,0.16699,2.858,0.003
22.33,137.900,0.16720,2.860,0.003
22.32,138.000,0.16737,2.859,0.003
22.33,138.100,0.16757,2.860,0.003
22.30,138.200,0.16774,2.856,0.003
22.29,138.300,0.16791,2.854,0.003
22.27,138.400,0.16807,2.853,0.003
22.26,138.500,0.16824,2.851,0.003
22.24,138.600,0.16840,2.849,0.003
22.26,138.700,0.16857,2.851,0.003
22.23,138.800,0.16870,2.847,0.003
22.23,138.900,0.16886,2.848,0.003
22.22,139.000,0.16899,2.846,0.003
22.25,139.100,0.16915,2.849,0.003
22.21,139.200,0.16928,2.845,0.003
22.22,139.300,0.16940,2.846,0.003
22.23,139.400,0.16953,2.847,0.003
22.21,139.500,0.16969,2.844,0.003
22.23,139.600,0.16982,2.847,0.003
22.23,139.700,0.16994,2.847,0.003
22.25,139.800,0.17011,2.850,0.003
22.25,139.900,0.17023,2.850,0.003
22.26,140.000,0.17040,2.850,0.003
22.26,140.100,0.17052,2.852,0.003
22.26,140.200,0.17069,2.851,0.003
22.27,140.300,0.17081,2.852,0.003
22.29,140.400,0.17098,2.854,0.003
22.29,140.500,0.17115,2.855,0.003
22.29,140.600,0.17127,2.854,0.003
22.29,140.700,0.17144,2.855,0.003
22.31,140.800,0.17160,2.857,0.003
22.30,140.900,0.17177,2.856,0.003
22.31,141.000,0.17190,2.857,0.003
22.30,141.100,0.17206,2.856,0.003
22.32,141.200,0.17223,2.858,0.003
22.33,141.300,0.17239,2.860,0.003
22.33,141.400,0.17252,2.861,0.003
22.34,141.500,0.17268,2.861,0.003
22.36,141.600,0.17285,2.863,0.003
22.36,141.700,0.17302,2.864,0.003
22.38,141.800,0.17318,2.867,0.003
22.38,141.900,0.17335,2.866,0.003
22.40,142.000,0.17356,2.869,0.003
22.41,142.100,0.17372,2.870,0.003
22.44,142.200,0.17393,2.874,0.003
22.45,142.300,0.17410,2.875,0.003
22.47,142.400,0.17431,2.877,0.003
22.46,142.500,0.17451,2.877,0.003
22.49,142.600,0.17472,2.880,0.003
22.48,142.700,0.17493,2.880,0.003
22.48,142.800,0.17514,2.880,0.003
22.48,142.900,0.17539,2.880,0.003
22.50,143.000,0.17559,2.882,0.003
22.51,143.100,0.17580,2.883,0.003
22.51,143.200,0.17601,2.883,0.003
22.51,143.300,0.17622,2.882,0.003
22.51,143.400,0.17642,2.883,0.003
22.50,143.500,0.17663,2.882,0.003
22.52,143.600,0.17684,2.884,0.003
22.49,143.700,0.17701,2.880,0.003
22.52,143.800,0.17717,2.884,0.003
22.46,143.900,0.17738,2.877,0.003
22.49,144.000,0.17755,2.880,0.003
22.48,144.100,0.17771,2.880,0.003
22.49,144.200,0.17784,2.880,0.004
22.48,144.300,0.17800,2.879,0.004
22.47,144.400,0.17817,2.878,0.004
22.45,144.500,0.17829,2.875,0.004
22.46,144.600,0.17846,2.877,0.004
22.46,144.700,0.17859,2.877,0.004
22.45,144.800,0.17875,2.875,0.004
22.46,144.900,0.17888,2.876,0.004
22.44,145.000,0.17900,2.874,0.004
22.46,145.100,0.17917,2.877,0.004
22.43,145.200,0.17929,2.873,0.004
22.46,145.300,0.17942,2.876,0.004
22.44,145.400,0.17958,2.874,0.004
22.47,145.500,0.17971,2.878,0.004
22.46,145.600,0.17987,2.876,0.004
22.48,145.700,0.18000,2.880,0.004
22.47,145.800,0.18016,2.877,0.004
22.49,145.900,0.18029,2.881,0.004
22.46,146.000,0.18046,2.877,0.004
22.52,146.100,0.18058,2.884,0.004
22.48,146.200,0.18075,2.879,0.004
22.52,146.300,0.18091,2.884,0.004
22.48,146.400,0.18108,2.879,0.004
22.52,146.500,0.18120,2.885,0.004
22.47,146.600,0.18137,2.878,0.004
22.53,146.700,0.18154,2.886,0.004
22.50,146.800,0.18166,2.882,0.004
22.54,146.900,0.18183,2.887,0.004
22.52,147.000,0.18199,2.885,0.004
22.55,147.100,0.18216,2.888,0.004
22.52,147.200,0.18233,2.884,0.004
22.57,147.300,0.18249,2.891,0.004
22.56,147.400,0.18266,2.889,0.004
22.59,147.500,0.18282,2.893,0.004
22.58,147.600,0.18299,2.892,0.004
22.62,147.700,0.18316,2.897,0.004
22.60,147.800,0.18336,2.895,0.004
22.61,147.810,0.18336,2.896,0.004