File: data-files/CWRU/0900-10-24B.txt
""
"Test Method","Will_Huddleston_Disks.msm"
"Sample I. D.","900-10-24B.mss"
"Specimen Number","1"

"Load (N)","Time (s)","Extension (mm)","Stress (MPa)","Strain (mm/mm)"

3.22,0.200,-0.04658,0.597,-0.001
3.22,0.300,-0.04658,0.598,-0.001
3.22,0.400,-0.04658,0.597,-0.001
3.21,0.500,-0.04658,0.596,-0.001
3.23,0.600,-0.04654,0.600,-0.001
3.23,0.700,-0.04654,0.599,-0.001
3.23,0.800,-0.04654,0.599,-0.001
3.20,0.900,-0.04650,0.595,-0.001
3.21,1.000,-0.04650,0.595,-0.001
3.22,1.100,-0.04646,0.598,-0.001
3.24,1.200,-0.04646,0.601,-0.001
3.22,1.300,-0.04646,0.598,-0.001
3.24,1.400,-0.04642,0.600,-0.001
3.22,1.500,-0.04642,0.597,-0.001
3.22,1.600,-0.04637,0.598,-0.001
3.23,1.700,-0.04637,0.599,-0.001
3.22,1.800,-0.04633,0.598,-0.001
3.23,1.900,-0.04633,0.600,-0.001
3.26,2.000,-0.04629,0.604,-0.001
3.26,2.100,-0.04625,0.605,-0.001
3.28,2.200,-0.04617,0.609,-0.001
3.31,2.300,-0.04612,0.613,-0.001
3.36,2.400,-0.04600,0.624,-0.001
3.44,2.500,-0.04583,0.638,-0.001
3.56,2.600,-0.04563,0.660,-0.001
3.61,2.700,-0.04538,0.671,-0.001
3.70,2.800,-0.04517,0.686,-0.001
3.75,2.900,-0.04500,0.695,-0.001
3.80,3.000,-0.04479,0.704,-0.001
3.82,3.100,-0.04459,0.709,-0.001
3.83,3.200,-0.04438,0.711,-0.001
3.85,3.300,-0.04417,0.714,-0.001
3.86,3.400,-0.04401,0.716,-0.001
3.86,3.500,-0.04380,0.716,-0.001
3.85,3.600,-0.04363,0.715,-0.001
3.86,3.700,-0.04342,0.716,-0.001
3.85,3.800,-0.04326,0.715,-0.001
3.88,3.900,-0.04309,0.719,-0.001
3.91,4.000,-0.04292,0.726,-0.001
3.91,4.100,-0.04276,0.725,-0.001
3.91,4.200,-0.04259,0.725,-0.001
3.92,4.300,-0.04243,0.727,-0.001
3.91,4.400,-0.04226,0.726,-0.001
3.92,4.500,-0.04214,0.727,-0.001
3.91,4.600,-0.04197,0.726,-0.001
3.92,4.700,-0.04184,0.728,-0.001
3.91,4.800,-0.04172,0.725,-0.001
3.93,4.900,-0.04155,0.730,-0.001
3.93,5.000,-0.04143,0.729,-0.001
3.94,5.100,-0.04130,0.731,-0.001
3.93,5.200,-0.04118,0.730,-0.001
3.95,5.300,-0.04105,0.733,-0.001
3.95,5.400,-0.04089,0.732,-0.001
3.97,5.500,-0.04076,0.737,-0.001
3.95,5.600,-0.04064,0.733,-0.001
3.97,5.700,-0.04051,0.736,-0.001
4.00,5.800,-0.04039,0.741,-0.001
3.98,5.900,-0.04027,0.738,-0.001
4.01,6.000,-0.04010,0.745,-0.001
4.02,6.100,-0.03997,0.746,-0.001
4.03,6.200,-0.03981,0.748,-0.001
4.04,6.300,-0.03968,0.749,-0.001
4.01,6.400,-0.03952,0.745,-0.001
4.02,6.500,-0.03939,0.747,-0.001
4.03,6.600,-0.03923,0.749,-0.001
4.06,6.700,-0.03910,0.753,-0.001
4.07,6.800,-0.03894,0.754,-0.001
4.07,6.900,-0.03877,0.755,-0.001
4.08,7.000,-0.03864,0.758,-0.001
4.09,7.100,-0.03848,0.759,-0.001
4.08,7.200,-0.03831,0.756,-0.001
4.10,7.300,-0.03819,0.761,-0.001
4.09,7.400,-0.03802,0.759,-0.001
4.11,7.500,-0.03785,0.764,-0.001
4.14,7.600,-0.03769,0.768,-0.001
4.16,7.700,-0.03752,0.771,-0.001
4.15,7.800,-0.03736,0.771,-0.001
4.17,7.900,-0.03719,0.774,-0.001
4.17,8.000,-0.03702,0.773,-0.001
4.19,8.100,-0.03686,0.777,-0.001
4.21,8.200,-0.03665,0.782,-0.001
4.23,8.300,-0.03648,0.784,-0.001
4.25,8.400,-0.03628,0.788,-0.001
4.25,8.500,-0.03607,0.789,-0.001
4.26,8.600,-0.03586,0.791,-0.001
4.27,8.700,-0.03565,0.792,-0.001
4.27,8.800,-0.03544,0.793,-0.001
4.28,8.900,-0.03520,0.793,-0.001
4.29,9.000,-0.03499,0.797,-0.001
4.30,9.100,-0.03478,0.797,-0.001
4.32,9.200,-0.03457,0.801,-0.001
4.31,9.300,-0.03436,0.799,-0.001
4.35,9.400,-0.03416,0.806,-0.001
4.35,9.500,-0.03399,0.807,-0.001
4.35,9.600,-0.03378,0.808,-0.001
4.35,9.700,-0.03357,0.807,-0.001
4.36,9.800,-0.03341,0.809,-0.001
4.37,9.900,-0.03324,0.811,-0.001
4.36,10.000,-0.03308,0.810,-0.001
4.41,10.100,-0.03291,0.818,-0.001
4.41,10.200,-0.03274,0.819,-0.001
4.42,10.300,-0.03262,0.821,-0.001
4.44,10.400,-0.03245,0.823,-0.001
4.45,10.500,-0.03229,0.826,-0.001
4.47,10.600,-0.03216,0.829,-0.001
4.48,10.700,-0.03204,0.831,-0.001
4.48,10.800,-0.03187,0.831,-0.001
4.48,10.900,-0.03175,0.832,-0.001
4.51,11.000,-0.03162,0.838,-0.001
4.52,11.100,-0.03146,0.839,-0.001
4.53,11.200,-0.03133,0.840,-0.001
4.55,11.300,-0.03121,0.845,-0.001
4.57,11.400,-0.03108,0.847,-0.001
4.58,11.500,-0.03091,0.849,-0.001
4.60,11.600,-0.03079,0.855,-0.001
4.58,11.700,-0.03067,0.851,-0.001
4.61,11.800,-0.03050,0.856,-0.001
4.62,11.900,-0.03037,0.857,-0.001
4.64,12.000,-0.03021,0.861,-0.001
4.64,12.100,-0.03004,0.862,-0.001
4.66,12.200,-0.02992,0.865,-0.001
4.67,12.300,-0.02975,0.867,-0.001
4.69,12.400,-0.02963,0.870,-0.001
4.70,12.500,-0.02946,0.872,-0.001
4.70,12.600,-0.02929,0.873,-0.001
4.73,12.700,-0.02913,0.878,-0.001
4.74,12.800,-0.02900,0.881,-0.001
4.75,12.900,-0.02884,0.882,-0.001
4.76,13.000,-0.02867,0.883,-0.001
4.77,13.100,-0.02850,0.886,-0.001
4.78,13.200,-0.02838,0.888,-0.001
4.82,13.300,-0.02821,0.894,-0.001
4.81,13.400,-0.02805,0.892,-0.001
4.81,13.500,-0.02788,0.894,-0.001
4.84,13.600,-0.02772,0.898,-0.001
4.86,13.700,-0.02755,0.902,-0.001
4.87,13.800,-0.02738,0.903,-0.001
4.87,13.900,-0.02722,0.903,-0.001
4.89,14.000,-0.02701,0.908,-0.001
4.93,14.100,-0.02684,0.915,-0.001
4.96,14.200,-0.02663,0.921,-0.001
4.97,14.300,-0.02643,0.922,-0.001
4.98,14.400,-0.02622,0.925,-0.001
5.00,14.500,-0.02601,0.929,-0.001
5.02,14.600,-0.02580,0.932,-0.001
5.05,14.700,-0.02555,0.936,-0.001
5.07,14.800,-0.02535,0.940,0.000
5.05,14.900,-0.02514,0.937,0.000
5.08,15.000,-0.02493,0.942,0.000
5.09,15.100,-0.02476,0.944,0.000
5.11,15.200,-0.02456,0.949,0.000
5.13,15.300,-0.02435,0.952,0.000
5.15,15.400,-0.02418,0.955,0.000
5.17,15.500,-0.02402,0.960,0.000
5.16,15.600,-0.02381,0.958,0.000
5.17,15.700,-0.02368,0.960,0.000
5.18,15.800,-0.02352,0.962,0.000
5.21,15.900,-0.02335,0.967,0.000
5.21,16.000,-0.02319,0.967,0.000
5.21,16.100,-0.02306,0.967,0.000
5.23,16.200,-0.02289,0.971,0.000
5.23,16.300,-0.02277,0.970,0.000
5.25,16.400,-0.02260,0.975,0.000
5.25,16.500,-0.02248,0.975,0.000
5.25,16.600,-0.02235,0.974,0.000
5.26,16.700,-0.02219,0.977,0.000
5.26,16.800,-0.02206,0.977,0.000
5.29,16.900,-0.02194,0.982,0.000
5.28,17.000,-0.02181,0.980,0.000
5.30,17.100,-0.02165,0.983,0.000
5.32,17.200,-0.02152,0.988,0.000
5.33,17.300,-0.02140,0.989,0.000
5.33,17.400,-0.02123,0.988,0.000
5.32,17.500,-0.02111,0.988,0.000
5.33,17.600,-0.02098,0.990,0.000
5.36,17.700,-0.02082,0.994,0.000
5.39,17.800,-0.02069,1.000,0.000
5.37,17.900,-0.02053,0.997,0.000
5.41,18.000,-0.02040,1.004,0.000
5.43,18.100,-0.02024,1.008,0.000
5.44,18.200,-0.02007,1.009,0.000
5.46,18.300,-0.01994,1.013,0.000
5.47,18.400,-0.01978,1.015,0.000
5.48,18.500,-0.01961,1.017,0.000
5.50,18.600,-0.01945,1.020,0.000
5.51,18.700,-0.01932,1.022,0.000
5.53,18.800,-0.01915,1.026,0.000
5.54,18.900,-0.01899,1.028,0.000
5.56,19.000,-0.01882,1.033,0.000
5.57,19.100,-0.01866,1.034,0.000
5.60,19.200,-0.01849,1.040,0.000
5.60,19.300,-0.01837,1.040,0.000
5.60,19.400,-0.01816,1.040,0.000
5.64,19.500,-0.01799,1.047,0.000
5.64,19.600,-0.01782,1.047,0.000
5.67,19.700,-0.01762,1.052,0.000
5.70,19.800,-0.01741,1.058,0.000
5.72,19.900,-0.01720,1.062,0.000
5.74,20.000,-0.01699,1.066,0.000
5.77,20.100,-0.01679,1.071,0.000
5.78,20.200,-0.01654,1.074,0.000
5.80,20.300,-0.01633,1.077,0.000
5.84,20.400,-0.01612,1.084,0.000
5.86,20.500,-0.01591,1.088,0.000
5.86,20.600,-0.01571,1.088,0.000
5.89,20.700,-0.01546,1.094,0.000
5.93,20.800,-0.01525,1.100,0.000
5.93,20.900,-0.01508,1.100,0.000
5.93,21.000,-0.01487,1.101,0.000
5.94,21.100,-0.01471,1.103,0.000
5.95,21.200,-0.01454,1.105,0.000
5.97,21.300,-0.01438,1.107,0.000
5.97,21.400,-0.01421,1.108,0.000
5.99,21.500,-0.01404,1.111,0.000
6.00,21.600,-0.01392,1.113,0.000
6.01,21.700,-0.01375,1.114,0.000
6.03,21.800,-0.01363,1.119,0.000
6.04,21.900,-0.01346,1.122,0.000
6.03,22.000,-0.01334,1.120,0.000
6.08,22.100,-0.01317,1.128,0.000
6.08,22.200,-0.01305,1.129,0.000
6.07,22.300,-0.01292,1.126,0.000
6.08,22.400,-0.01280,1.129,0.000
6.08,22.500,-0.01263,1.129,0.000
6.11,22.600,-0.01251,1.134,0.000
6.13,22.700,-0.01238,1.138,0.000
6.13,22.800,-0.01226,1.137,0.000
6.16,22.900,-0.01209,1.142,0.000
6.16,23.000,-0.01197,1.143,0.000
6.19,23.100,-0.01180,1.149,0.000
6.19,23.200,-0.01167,1.149,0.000
6.20,23.300,-0.01151,1.151,0.000
6.21,23.400,-0.01138,1.152,0.000
6.24,23.500,-0.01122,1.157,0.000
6.28,23.600,-0.01109,1.166,0.000
6.29,23.700,-0.01093,1.167,0.000
6.27,23.800,-0.01080,1.164,0.000
6.29,23.900,-0.01064,1.168,0.000
6.31,24.000,-0.01047,1.171,0.000
6.33,24.100,-0.01030,1.175,0.000
6.34,24.200,-0.01018,1.176,0.000
6.36,24.300,-0.01001,1.180,0.000
6.38,24.400,-0.00985,1.184,0.000
6.40,24.500,-0.00968,1.188,0.000
6.42,24.600,-0.00956,1.191,0.000
6.43,24.700,-0.00939,1.193,0.000
6.45,24.800,-0.00922,1.197,0.000
6.47,24.900,-0.00906,1.201,0.000
6.49,25.000,-0.00889,1.204,0.000
6.49,25.100,-0.00872,1.205,0.000
6.52,25.200,-0.00852,1.211,0.000
6.54,25.300,-0.00835,1.213,0.000
6.57,25.400,-0.00814,1.220,0.000
6.59,25.500,-0.00793,1.223,0.000
6.62,25.600,-0.00773,1.228,0.000
6.65,25.700,-0.00752,1.234,0.000
6.65,25.800,-0.00731,1.234,0.000
6.69,25.900,-0.00710,1.241,0.000
6.70,26.000,-0.00685,1.244,0.000
6.73,26.100,-0.00665,1.250,0.000
6.76,26.200,-0.00644,1.254,0.000
6.76,26.300,-0.00623,1.255,0.000
6.79,26.400,-0.00602,1.259,0.000
6.79,26.500,-0.00582,1.261,0.000
6.80,26.600,-0.00561,1.262,0.000
6.80,26.700,-0.00544,1.262,0.000
6.81,26.800,-0.00528,1.263,0.000
6.83,26.900,-0.00507,1.267,0.000
6.83,27.000,-0.00490,1.268,0.000
6.84,27.100,-0.00473,1.270,0.000
6.84,27.200,-0.00457,1.270,0.000
6.81,27.300,-0.00444,1.264,0.000
6.85,27.400,-0.00428,1.271,0.000
6.84,27.500,-0.00411,1.269,0.000
6.83,27.600,-0.00399,1.268,0.000
6.83,27.700,-0.00382,1.268,0.000
6.85,27.800,-0.00370,1.272,0.000
6.84,27.900,-0.00353,1.270,0.000
6.86,28.000,-0.00341,1.272,0.000
6.84,28.100,-0.00328,1.269,0.000
6.85,28.200,-0.00316,1.272,0.000
6.86,28.300,-0.00299,1.273,0.000
6.89,28.400,-0.00286,1.278,0.000
6.87,28.500,-0.00274,1.275,0.000
6.87,28.600,-0.00257,1.275,0.000
6.87,28.700,-0.00245,1.275,0.000
6.91,28.800,-0.00228,1.282,0.000
6.90,28.900,-0.00216,1.281,0.000
6.90,29.000,-0.00199,1.281,0.000
6.93,29.100,-0.00183,1.285,0.000
6.94,29.200,-0.00170,1.288,0.000
6.96,29.300,-0.00153,1.293,0.000
6.98,29.400,-0.00137,1.295,0.000
6.98,29.500,-0.00124,1.296,0.000
7.02,29.600,-0.00108,1.302,0.000
7.03,29.700,-0.00091,1.305,0.000
7.06,29.800,-0.00075,1.311,0.000
7.05,29.900,-0.00058,1.308,0.000
7.07,30.000,-0.00041,1.312,0.000
7.07,30.100,-0.00025,1.312,0.000
7.11,30.200,-0.00012,1.320,0.000
7.12,30.300,0.00004,1.322,0.000
7.13,30.400,0.00021,1.324,0.000
7.16,30.500,0.00042,1.329,0.000
7.18,30.600,0.00058,1.332,0.000
7.20,30.700,0.00075,1.335,0.000
7.21,30.800,0.00092,1.337,0.000
7.20,30.900,0.00112,1.336,0.000
7.22,31.000,0.00129,1.341,0.000
7.23,31.100,0.00150,1.341,0.000
7.27,31.200,0.00171,1.348,0.000
7.25,31.300,0.00191,1.346,0.000
7.29,31.400,0.00216,1.352,0.000
7.31,31.500,0.00237,1.357,0.000
7.32,31.600,0.00258,1.359,0.000
6.85,31.700,0.00279,1.271,0.000
5.14,31.800,0.00299,0.954,0.000
5.14,31.900,0.00320,0.955,0.000
5.17,32.000,0.00341,0.960,0.000
5.23,32.100,0.00362,0.970,0.000
5.26,32.200,0.00378,0.977,0.000
5.29,32.300,0.00399,0.982,0.000
5.37,32.400,0.00416,0.996,0.000
5.40,32.500,0.00437,1.002,0.000
5.41,32.600,0.00453,1.004,0.000
5.44,32.700,0.00470,1.009,0.000
5.47,32.800,0.00486,1.015,0.000
5.50,32.900,0.00503,1.020,0.000
5.52,33.000,0.00516,1.025,0.000
5.54,33.100,0.00532,1.029,0.000
5.56,33.200,0.00549,1.033,0.000
5.59,33.300,0.00561,1.037,0.000
5.60,33.400,0.00578,1.040,0.000
5.63,33.500,0.00590,1.045,0.000
5.64,33.600,0.00607,1.046,0.000
5.68,33.700,0.00619,1.053,0.000
5.70,33.800,0.00632,1.057,0.000
5.71,33.900,0.00644,1.059,0.000
5.74,34.000,0.00661,1.065,0.000
5.76,34.100,0.00673,1.069,0.000
5.78,34.200,0.00686,1.072,0.000
5.82,34.300,0.00703,1.080,0.000
5.83,34.400,0.00715,1.081,0.000
5.83,34.500,0.00732,1.082,0.000
5.88,34.600,0.00744,1.091,0.000
5.88,34.700,0.00761,1.092,0.000
5.93,34.800,0.00773,1.100,0.000
5.93,34.900,0.00790,1.101,0.000
5.96,35.000,0.00806,1.105,0.000
5.97,35.100,0.00819,1.109,0.000
6.01,35.200,0.00836,1.116,0.000
6.03,35.300,0.00852,1.120,0.000
6.04,35.400,0.00869,1.121,0.000
6.06,35.500,0.00881,1.125,0.000
6.10,35.600,0.00898,1.131,0.000
6.11,35.700,0.00914,1.134,0.000
6.14,35.800,0.00931,1.139,0.000
6.16,35.900,0.00948,1.142,0.000
6.19,36.000,0.00960,1.148,0.000
6.20,36.100,0.00977,1.151,0.000
6.23,36.200,0.00993,1.157,0.000
6.27,36.300,0.01010,1.163,0.000
6.27,36.400,0.01031,1.164,0.000
6.32,36.500,0.01047,1.173,0.000
6.34,36.600,0.01068,1.176,0.000
6.38,36.700,0.01089,1.184,0.000
6.39,36.800,0.01110,1.185,0.000
6.43,36.900,0.01126,1.193,0.000
6.44,37.000,0.01151,1.196,0.000
6.49,37.100,0.01172,1.205,0.000
6.52,37.200,0.01193,1.211,0.000
6.54,37.300,0.01214,1.214,0.000
6.58,37.400,0.01239,1.222,0.000
6.62,37.500,0.01259,1.228,0.000
6.63,37.600,0.01280,1.231,0.000
6.66,37.700,0.01301,1.236,0.000
6.68,37.800,0.01322,1.240,0.000
6.71,37.900,0.01343,1.246,0.000
6.72,38.000,0.01359,1.248,0.000
6.75,38.100,0.01380,1.253,0.000
6.76,38.200,0.01397,1.255,0.000
6.77,38.300,0.01413,1.257,0.000
6.81,38.400,0.01430,1.264,0.000
6.80,38.500,0.01446,1.263,0.000
6.83,38.600,0.01459,1.268,0.000
6.83,38.700,0.01475,1.267,0.000
6.85,38.800,0.01488,1.272,0.000
6.87,38.900,0.01505,1.275,0.000
6.89,39.000,0.01517,1.279,0.000
6.92,39.100,0.01534,1.284,0.000
6.92,39.200,0.01546,1.284,0.000
6.95,39.300,0.01559,1.289,0.000
6.96,39.400,0.01571,1.292,0.000
6.96,39.500,0.01584,1.292,0.000
6.99,39.600,0.01600,1.297,0.000
7.01,39.700,0.01613,1.300,0.000
7.04,39.800,0.01625,1.306,0.000
7.05,39.900,0.01642,1.308,0.000
7.05,40.000,0.01654,1.308,0.000
7.08,40.100,0.01671,1.314,0.000
7.08,40.200,0.01683,1.314,0.000
7.10,40.300,0.01700,1.317,0.000
7.11,40.400,0.01712,1.320,0.000
7.12,40.500,0.01729,1.321,0.000
7.14,40.600,0.01741,1.325,0.000
7.15,40.700,0.01758,1.328,0.000
7.17,40.800,0.01775,1.331,0.000
7.19,40.900,0.01787,1.334,0.000
7.20,41.000,0.01804,1.336,0.000
7.23,41.100,0.01820,1.341,0.000
7.25,41.200,0.01833,1.345,0.000
7.27,41.300,0.01849,1.349,0.000
7.28,41.400,0.01866,1.350,0.000
7.30,41.500,0.01883,1.355,0.000
7.33,41.600,0.01899,1.360,0.000
7.35,41.700,0.01916,1.365,0.000
7.37,41.800,0.01933,1.367,0.000
7.38,41.900,0.01949,1.370,0.000
7.40,42.000,0.01966,1.374,0.000
7.43,42.100,0.01982,1.379,0.000
7.44,42.200,0.01999,1.381,0.000
7.48,42.300,0.02020,1.388,0.000
7.50,42.400,0.02041,1.392,0.000
7.52,42.500,0.02057,1.396,0.000
7.55,42.600,0.02082,1.401,0.000
7.58,42.700,0.02103,1.407,0.000
7.62,42.800,0.02124,1.413,0.000
7.64,42.900,0.02145,1.418,0.000
7.67,43.000,0.02165,1.423,0.000
7.67,43.100,0.02186,1.424,0.000
7.73,43.200,0.02207,1.434,0.000
7.74,43.300,0.02228,1.437,0.000
7.75,43.400,0.02248,1.439,0.000
7.77,43.500,0.02269,1.442,0.000
7.79,43.600,0.02290,1.446,0.000
7.80,43.700,0.02307,1.447,0.000
7.82,43.800,0.02323,1.452,0.000
7.84,43.900,0.02344,1.455,0.000
7.86,44.000,0.02361,1.460,0.000
7.87,44.100,0.02373,1.461,0.000
7.88,44.200,0.02390,1.463,0.000
7.88,44.300,0.02406,1.462,0.000
7.91,44.400,0.02419,1.467,0.000
7.93,44.500,0.02435,1.472,0.000
7.94,44.600,0.02448,1.473,0.000
7.96,44.700,0.02465,1.478,0.000
7.96,44.800,0.02477,1.478,0.000
7.97,44.900,0.02489,1.480,0.000
7.99,45.000,0.02506,1.483,0.000
8.01,45.100,0.02519,1.487,0.000
8.01,45.200,0.02531,1.487,0.000
8.02,45.300,0.02543,1.489,0.001
8.05,45.400,0.02556,1.493,0.001
8.08,45.500,0.02573,1.500,0.001
8.11,45.600,0.02585,1.506,0.001
8.12,45.700,0.02602,1.506,0.001
8.14,45.800,0.02614,1.511,0.001
8.15,45.900,0.02627,1.513,0.001
8.17,46.000,0.02643,1.517,0.001
8.19,46.100,0.02656,1.520,0.001
8.21,46.200,0.02672,1.524,0.001
8.22,46.300,0.02689,1.526,0.001
8.24,46.400,0.02701,1.529,0.001
8.25,46.500,0.02718,1.531,0.001
8.28,46.600,0.02730,1.536,0.001
8.29,46.700,0.02747,1.539,0.001
8.32,46.800,0.02760,1.543,0.001
8.32,46.900,0.02776,1.545,0.001
8.36,47.000,0.02789,1.551,0.001
8.38,47.100,0.02805,1.555,0.001
8.41,47.200,0.02822,1.560,0.001
8.41,47.300,0.02834,1.561,0.001
8.45,47.400,0.02851,1.568,0.001
8.47,47.500,0.02868,1.571,0.001
8.47,47.600,0.02884,1.573,0.001
8.50,47.700,0.02901,1.578,0.001
8.52,47.800,0.02917,1.581,0.001
8.57,47.900,0.02934,1.590,0.001
8.59,48.000,0.02955,1.595,0.001
8.62,48.100,0.02972,1.599,0.001
8.64,48.200,0.02992,1.604,0.001
8.68,48.300,0.03009,1.611,0.001
8.70,48.400,0.03030,1.614,0.001
8.73,48.500,0.03050,1.619,0.001
8.76,48.600,0.03071,1.626,0.001
8.79,48.700,0.03092,1.632,0.001
8.82,48.800,0.03113,1.636,0.001
8.84,48.900,0.03134,1.641,0.001
8.85,49.000,0.03154,1.643,0.001
8.90,49.100,0.03175,1.652,0.001
8.92,49.200,0.03196,1.656,0.001
8.95,49.300,0.03213,1.660,0.001
8.96,49.400,0.03233,1.663,0.001
8.98,49.500,0.03250,1.666,0.001
9.00,49.600,0.03267,1.670,0.001
9.01,49.700,0.03283,1.672,0.001
9.04,49.800,0.03300,1.677,0.001
9.06,49.900,0.03316,1.681,0.001
9.08,50.000,0.03333,1.685,0.001
9.09,50.100,0.03350,1.686,0.001
9.10,50.200,0.03362,1.689,0.001
9.12,50.300,0.03379,1.693,0.001
9.14,50.400,0.03391,1.697,0.001
9.15,50.500,0.03408,1.699,0.001
9.18,50.600,0.03420,1.703,0.001
9.19,50.700,0.03433,1.706,0.001
9.21,50.800,0.03449,1.709,0.001
9.22,50.900,0.03462,1.711,0.001
9.24,51.000,0.03474,1.715,0.001
9.24,51.100,0.03487,1.715,0.001
9.27,51.200,0.03503,1.720,0.001
9.29,51.300,0.03516,1.723,0.001
9.32,51.400,0.03528,1.729,0.001
9.34,51.500,0.03541,1.734,0.001
9.35,51.600,0.03557,1.735,0.001
9.38,51.700,0.03570,1.740,0.001
9.39,51.800,0.03587,1.742,0.001
9.41,51.900,0.03599,1.746,0.001
9.44,52.000,0.03616,1.751,0.001
9.47,52.100,0.03628,1.757,0.001
9.48,52.200,0.03645,1.759,0.001
9.50,52.300,0.03657,1.764,0.001
9.53,52.400,0.03674,1.769,0.001
9.55,52.500,0.03690,1.773,0.001
9.58,52.600,0.03703,1.777,0.001
9.59,52.700,0.03720,1.780,0.001
9.61,52.800,0.03736,1.784,0.001
9.64,52.900,0.03753,1.790,0.001
9.68,53.000,0.03769,1.796,0.001
9.68,53.100,0.03782,1.797,0.001
9.72,53.200,0.03798,1.804,0.001
9.76,53.300,0.03815,1.811,0.001
9.79,53.400,0.03832,1.816,0.001
9.81,53.500,0.03848,1.821,0.001
9.85,53.600,0.03869,1.829,0.001
9.90,53.700,0.03886,1.838,0.001
9.92,53.800,0.03907,1.842,0.001
9.93,53.900,0.03923,1.844,0.001
9.98,54.000,0.03944,1.852,0.001
10.02,54.100,0.03965,1.859,0.001
10.05,54.200,0.03990,1.865,0.001
10.08,54.300,0.04010,1.871,0.001
10.13,54.400,0.04031,1.879,0.001
10.14,54.500,0.04052,1.883,0.001
10.19,54.600,0.04073,1.891,0.001
10.20,54.700,0.04094,1.893,0.001
10.24,54.800,0.04114,1.901,0.001
10.25,54.900,0.04135,1.903,0.001
10.31,55.000,0.04156,1.912,0.001
10.32,55.100,0.04177,1.916,0.001
10.36,55.200,0.04197,1.923,0.001
10.37,55.300,0.04214,1.925,0.001
10.39,55.400,0.04231,1.928,0.001
10.41,55.500,0.04247,1.933,0.001
10.44,55.600,0.04264,1.938,0.001
10.46,55.700,0.04281,1.941,0.001
10.47,55.800,0.04297,1.944,0.001
10.49,55.900,0.04310,1.947,0.001
10.51,56.000,0.04326,1.950,0.001
10.52,56.100,0.04339,1.952,0.001
10.56,56.200,0.04351,1.960,0.001
10.57,56.300,0.04368,1.961,0.001
10.59,56.400,0.04380,1.965,0.001
10.60,56.500,0.04393,1.967,0.001
10.61,56.600,0.04409,1.970,0.001
10.64,56.700,0.04422,1.975,0.001
10.67,56.800,0.04434,1.980,0.001
10.66,56.900,0.04447,1.978,0.001
10.70,57.000,0.04459,1.985,0.001
10.73,57.100,0.04476,1.991,0.001
10.76,57.200,0.04488,1.998,0.001
10.78,57.300,0.04505,2.000,0.001
10.81,57.400,0.04517,2.007,0.001
10.84,57.500,0.04534,2.011,0.001
10.85,57.600,0.04546,2.014,0.001
10.89,57.700,0.04563,2.022,0.001
10.91,57.800,0.04576,2.024,0.001
10.94,57.900,0.04592,2.030,0.001
10.97,58.000,0.04609,2.035,0.001
10.99,58.100,0.04621,2.039,0.001
11.01,58.200,0.04638,2.043,0.001
11.05,58.300,0.04655,2.051,0.001
11.08,58.400,0.04671,2.056,0.001
11.09,58.500,0.04688,2.058,0.001
11.14,58.600,0.04704,2.067,0.001
11.15,58.700,0.04721,2.069,0.001
11.19,58.800,0.04738,2.076,0.001
11.22,58.900,0.04754,2.082,0.001
11.23,59.000,0.04771,2.084,0.001
11.28,59.100,0.04787,2.093,0.001
11.31,59.200,0.04804,2.099,0.001
11.33,59.300,0.04825,2.102,0.001
11.38,59.400,0.04842,2.112,0.001
11.41,59.500,0.04862,2.117,0.001
11.46,59.600,0.04883,2.127,0.001
11.49,59.700,0.04900,2.133,0.001
11.52,59.800,0.04925,2.138,0.001
11.55,59.900,0.04945,2.143,0.001
11.59,60.000,0.04966,2.151,0.001
11.64,60.100,0.04987,2.160,0.001
11.66,60.200,0.05008,2.165,0.001
11.70,60.300,0.05029,2.172,0.001
11.73,60.400,0.05049,2.176,0.001
11.77,60.500,0.05070,2.184,0.001
11.79,60.600,0.05091,2.189,0.001
11.82,60.700,0.05112,2.193,0.001
11.83,60.800,0.05132,2.196,0.001
11.86,60.900,0.05149,2.201,0.001
11.91,61.000,0.05170,2.211,0.001
11.95,61.100,0.05186,2.217,0.001
11.96,61.200,0.05203,2.220,0.001
11.99,61.300,0.05220,2.226,0.001
12.02,61.400,0.05232,2.230,0.001
12.04,61.500,0.05249,2.235,0.001
12.07,61.600,0.05265,2.241,0.001
12.10,61.700,0.05278,2.245,0.001
12.12,61.800,0.05294,2.250,0.001
12.13,61.900,0.05307,2.252,0.001
12.18,62.000,0.05324,2.260,0.001
12.20,62.100,0.05336,2.263,0.001
12.20,62.200,0.05348,2.264,0.001
12.22,62.300,0.05365,2.268,0.001
12.23,62.400,0.05378,2.270,0.001
12.28,62.500,0.05390,2.278,0.001
12.31,62.600,0.05407,2.284,0.001
12.33,62.700,0.05419,2.287,0.001
12.36,62.800,0.05432,2.295,0.001
12.39,62.900,0.05448,2.300,0.001
12.42,63.000,0.05465,2.306,0.001
12.45,63.100,0.05477,2.311,0.001
12.47,63.200,0.05494,2.314,0.001
12.49,63.300,0.05506,2.319,0.001
12.53,63.400,0.05523,2.325,0.001
12.56,63.500,0.05540,2.331,0.001
12.59,63.600,0.05552,2.336,0.001
12.60,63.700,0.05569,2.339,0.001
12.65,63.800,0.05585,2.347,0.001
12.68,63.900,0.05602,2.353,0.001
12.68,64.000,0.05619,2.353,0.001
12.72,64.100,0.05631,2.361,0.001
12.76,64.200,0.05648,2.368,0.001
12.77,64.300,0.05664,2.371,0.001
12.83,64.400,0.05681,2.381,0.001
12.84,64.500,0.05698,2.382,0.001
12.85,64.600,0.05714,2.385,0.001
12.91,64.700,0.05731,2.396,0.001
12.94,64.800,0.05747,2.402,0.001
12.99,64.900,0.05768,2.410,0.001
13.00,65.000,0.05785,2.413,0.001
13.07,65.100,0.05806,2.426,0.001
13.11,65.200,0.05822,2.433,0.001
13.16,65.300,0.05843,2.442,0.001
13.20,65.400,0.05864,2.449,0.001
13.24,65.500,0.05885,2.458,0.001
13.29,65.600,0.05909,2.467,0.001
13.34,65.700,0.05930,2.475,0.001
13.37,65.800,0.05951,2.482,0.001
13.41,65.900,0.05972,2.489,0.001
13.45,66.000,0.05993,2.495,0.001
13.49,66.100,0.06013,2.503,0.001
13.52,66.200,0.06034,2.509,0.001
13.55,66.300,0.06055,2.514,0.001
13.61,66.400,0.06072,2.526,0.001
13.62,66.500,0.06088,2.528,0.001
13.64,66.600,0.06109,2.532,0.001
13.69,66.700,0.06126,2.542,0.001
13.70,66.800,0.06142,2.543,0.001
13.73,66.900,0.06159,2.548,0.001
13.75,67.000,0.06171,2.551,0.001
13.76,67.100,0.06188,2.554,0.001
13.81,67.200,0.06205,2.563,0.001
13.83,67.300,0.06217,2.566,0.001
13.86,67.400,0.06234,2.573,0.001
13.87,67.500,0.06246,2.574,0.001
13.90,67.600,0.06259,2.580,0.001
13.94,67.700,0.06275,2.587,0.001
13.95,67.800,0.06288,2.588,0.001
13.98,67.900,0.06300,2.594,0.001
14.00,68.000,0.06313,2.599,0.001
14.03,68.100,0.06329,2.604,0.001
14.04,68.200,0.06342,2.605,0.001
14.07,68.300,0.06354,2.612,0.001
14.11,68.400,0.06367,2.619,0.001
14.15,68.500,0.06383,2.625,0.001
14.16,68.600,0.06396,2.629,0.001
14.20,68.700,0.06412,2.635,0.001
14.23,68.800,0.06425,2.640,0.001
14.25,68.900,0.06441,2.645,0.001
14.28,69.000,0.06454,2.650,0.001
14.31,69.100,0.06471,2.656,0.001
14.34,69.200,0.06487,2.661,0.001
14.38,69.300,0.06500,2.669,0.001
14.40,69.400,0.06516,2.673,0.001
14.43,69.500,0.06533,2.678,0.001
14.46,69.600,0.06545,2.683,0.001
14.50,69.700,0.06562,2.691,0.001
14.52,69.800,0.06579,2.694,0.001
14.56,69.900,0.06591,2.702,0.001
14.58,70.000,0.06608,2.706,0.001
14.63,70.100,0.06624,2.715,0.001
14.68,70.200,0.06641,2.725,0.001
14.70,70.300,0.06658,2.727,0.001
14.73,70.400,0.06674,2.734,0.001
14.75,70.500,0.06691,2.737,0.001
14.80,70.600,0.06707,2.747,0.001
14.86,70.700,0.06728,2.758,0.001
14.90,70.800,0.06745,2.765,0.001
14.95,70.900,0.06766,2.775,0.001
15.00,71.000,0.06786,2.784,0.001
15.04,71.100,0.06807,2.791,0.001
15.10,71.200,0.06828,2.801,0.001
15.15,71.300,0.06853,2.811,0.001
15.22,71.400,0.06874,2.824,0.001
15.24,71.500,0.06894,2.829,0.001
15.30,71.600,0.06919,2.839,0.001
15.34,71.700,0.06940,2.847,0.001
15.38,71.800,0.06961,2.855,0.001
15.43,71.900,0.06982,2.864,0.001
15.47,72.000,0.06998,2.871,0.001
15.41,72.100,0.07019,2.861,0.001
15.46,72.200,0.07040,2.869,0.001
15.50,72.300,0.07056,2.877,0.001
15.53,72.400,0.07073,2.882,0.001
15.57,72.500,0.07090,2.890,0.001
15.59,72.600,0.07106,2.894,0.001
15.61,72.700,0.07119,2.898,0.001
15.64,72.800,0.07135,2.902,0.001
15.69,72.900,0.07148,2.911,0.001
15.71,73.000,0.07164,2.915,0.001
15.70,73.100,0.07177,2.914,0.001
15.75,73.200,0.07189,2.922,0.001
15.78,73.300,0.07206,2.928,0.001
15.81,73.400,0.07219,2.934,0.001
15.83,73.500,0.07231,2.938,0.001
15.87,73.600,0.07243,2.944,0.001
15.88,73.700,0.07256,2.947,0.001
15.91,73.800,0.07273,2.952,0.001
15.93,73.900,0.07285,2.956,0.001
15.97,74.000,0.07297,2.964,0.001
16.03,74.100,0.07310,2.974,0.001
16.06,74.200,0.07327,2.981,0.001
16.10,74.300,0.07339,2.988,0.001
16.12,74.400,0.07356,2.991,0.001
16.13,74.500,0.07368,2.993,0.001
16.18,74.600,0.07385,3.003,0.001
16.21,74.700,0.07397,3.008,0.001
16.25,74.800,0.07414,3.015,0.001
16.27,74.900,0.07426,3.020,0.001
16.30,75.000,0.07443,3.026,0.001
16.35,75.100,0.07460,3.035,0.001
16.38,75.200,0.07472,3.040,0.001
16.41,75.300,0.07489,3.045,0.001
16.45,75.400,0.07505,3.053,0.001
16.49,75.500,0.07518,3.061,0.001
16.52,75.600,0.07534,3.066,0.001
16.56,75.700,0.07551,3.073,0.001
16.59,75.800,0.07568,3.079,0.001
16.63,75.900,0.07584,3.086,0.001
16.65,76.000,0.07601,3.090,0.001
16.68,76.100,0.07617,3.096,0.001
16.73,76.200,0.07634,3.104,0.002
16.78,76.300,0.07651,3.115,0.002
16.84,76.400,0.07671,3.124,0.002
16.89,76.500,0.07688,3.135,0.002
16.94,76.600,0.07709,3.143,0.002
16.99,76.700,0.07730,3.153,0.002
17.05,76.800,0.07750,3.163,0.002
17.09,76.900,0.07771,3.173,0.002
17.12,77.000,0.07792,3.178,0.002
17.18,77.100,0.07817,3.188,0.002
17.21,77.200,0.07838,3.194,0.002
17.26,77.300,0.07858,3.203,0.002
17.31,77.400,0.07879,3.212,0.002
17.35,77.500,0.07900,3.221,0.002
17.39,77.600,0.07921,3.228,0.002
17.43,77.700,0.07937,3.235,0.002
17.46,77.800,0.07958,3.240,0.002
17.50,77.900,0.07979,3.248,0.002
17.52,78.000,0.07996,3.252,0.002
17.55,78.100,0.08012,3.257,0.002
17.60,78.200,0.08029,3.266,0.002
17.62,78.300,0.08045,3.270,0.002
17.66,78.400,0.08062,3.277,0.002
17.67,78.500,0.08075,3.279,0.002
17.71,78.600,0.08091,3.287,0.002
17.74,78.700,0.08104,3.292,0.002
17.76,78.800,0.08120,3.296,0.002
17.80,78.900,0.08133,3.303,0.002
17.82,79.000,0.08149,3.308,0.002
17.86,79.100,0.08162,3.315,0.002
17.87,79.200,0.08174,3.316,0.002
17.89,79.300,0.08187,3.320,0.002
17.94,79.400,0.08203,3.329,0.002
17.96,79.500,0.08216,3.334,0.002
17.98,79.600,0.08228,3.338,0.002
18.01,79.700,0.08241,3.342,0.002
18.05,79.800,0.08257,3.349,0.002
18.09,79.900,0.08270,3.358,0.002
18.11,80.000,0.08286,3.362,0.002
18.14,80.100,0.08299,3.367,0.002
18.18,80.200,0.08316,3.374,0.002
18.24,80.300,0.08328,3.385,0.002
18.26,80.400,0.08345,3.390,0.002
18.30,80.500,0.08357,3.396,0.002
18.32,80.600,0.08374,3.399,0.002
18.36,80.700,0.08390,3.408,0.002
18.39,80.800,0.08403,3.413,0.002
18.45,80.900,0.08419,3.424,0.002
18.47,81.000,0.08436,3.428,0.002
18.49,81.100,0.08453,3.431,0.002
18.54,81.200,0.08465,3.441,0.002
18.56,81.300,0.08482,3.445,0.002
18.61,81.400,0.08498,3.454,0.002
18.66,81.500,0.08515,3.464,0.002
18.70,81.600,0.08532,3.470,0.002
18.74,81.700,0.08548,3.477,0.002
18.77,81.800,0.08565,3.484,0.002
18.80,81.900,0.08582,3.489,0.002
18.84,82.000,0.08598,3.496,0.002
18.91,82.100,0.08619,3.509,0.002
18.94,82.200,0.08636,3.515,0.002
18.99,82.300,0.08656,3.525,0.002
19.02,82.400,0.08677,3.530,0.002
19.07,82.500,0.08698,3.539,0.002
19.14,82.600,0.08719,3.553,0.002
19.19,82.700,0.08739,3.561,0.002
19.23,82.800,0.08760,3.569,0.002
19.27,82.900,0.08781,3.576,0.002
19.32,83.000,0.08802,3.586,0.002
19.37,83.100,0.08823,3.595,0.002
19.40,83.200,0.08843,3.601,0.002
19.44,83.300,0.08864,3.607,0.002
19.48,83.400,0.08881,3.615,0.002
19.53,83.500,0.08902,3.624,0.002
19.56,83.600,0.08918,3.630,0.002
19.58,83.700,0.08935,3.633,0.002
19.61,83.800,0.08951,3.640,0.002
19.65,83.900,0.08972,3.646,0.002
19.67,84.000,0.08985,3.651,0.002
19.68,84.100,0.09001,3.653,0.002
19.71,84.200,0.09018,3.658,0.002
19.75,84.300,0.09030,3.666,0.002
19.77,84.400,0.09047,3.670,0.002
19.79,84.500,0.09059,3.672,0.002
17.50,84.600,0.09076,3.248,0.002
12.65,84.700,0.09089,2.348,0.002
12.57,84.800,0.09101,2.333,0.002
12.61,84.900,0.09118,2.340,0.002
12.69,85.000,0.09130,2.354,0.002
12.74,85.100,0.09143,2.365,0.002
12.81,85.200,0.09155,2.377,0.002
12.87,85.300,0.09172,2.388,0.002
12.94,85.400,0.09184,2.401,0.002
13.01,85.500,0.09197,2.414,0.002
13.04,85.600,0.09213,2.420,0.002
13.10,85.700,0.09226,2.431,0.002
13.16,85.800,0.09238,2.443,0.002
13.24,85.900,0.09255,2.457,0.002
13.30,86.000,0.09267,2.468,0.002
13.33,86.100,0.09284,2.474,0.002
13.40,86.200,0.09296,2.486,0.002
13.45,86.300,0.09313,2.496,0.002
13.50,86.400,0.09330,2.505,0.002
13.54,86.500,0.09342,2.513,0.002
13.59,86.600,0.09359,2.522,0.002
13.65,86.700,0.09375,2.533,0.002
13.67,86.800,0.09388,2.536,0.002
13.73,86.900,0.09404,2.548,0.002
13.77,87.000,0.09421,2.556,0.002
13.82,87.100,0.09438,2.565,0.002
13.86,87.200,0.09454,2.573,0.002
13.90,87.300,0.09467,2.580,0.002
13.95,87.400,0.09483,2.589,0.002
14.00,87.500,0.09500,2.598,0.002
14.04,87.600,0.09517,2.606,0.002
14.12,87.700,0.09537,2.621,0.002
14.13,87.800,0.09554,2.623,0.002
14.18,87.900,0.09571,2.632,0.002
14.25,88.000,0.09591,2.644,0.002
14.29,88.100,0.09612,2.652,0.002
14.35,88.200,0.09633,2.663,0.002
14.39,88.300,0.09654,2.670,0.002
14.45,88.400,0.09674,2.682,0.002
14.52,88.500,0.09699,2.696,0.002
14.55,88.600,0.09720,2.699,0.002
14.62,88.700,0.09741,2.714,0.002
14.66,88.800,0.09762,2.721,0.002
14.71,88.900,0.09783,2.730,0.002
14.76,89.000,0.09803,2.739,0.002
14.80,89.100,0.09824,2.746,0.002
14.84,89.200,0.09845,2.753,0.002
14.88,89.300,0.09866,2.762,0.002
14.92,89.400,0.09882,2.769,0.002
14.95,89.500,0.09899,2.774,0.002
14.98,89.600,0.09915,2.779,0.002
15.00,89.700,0.09932,2.785,0.002
15.04,89.800,0.09949,2.792,0.002
15.07,89.900,0.09965,2.797,0.002
15.12,90.000,0.09978,2.806,0.002
15.12,90.100,0.09990,2.805,0.002
15.15,90.200,0.10007,2.812,0.002
15.19,90.300,0.10024,2.819,0.002
15.22,90.400,0.10036,2.824,0.002
15.23,90.500,0.10048,2.827,0.002
15.26,90.600,0.10065,2.832,0.002
15.28,90.700,0.10078,2.837,0.002
15.32,90.800,0.10090,2.844,0.002
15.36,90.900,0.10102,2.851,0.002
15.37,91.000,0.10119,2.852,0.002
15.39,91.100,0.10132,2.857,0.002
15.43,91.200,0.10144,2.864,0.002
15.47,91.300,0.10161,2.871,0.002
15.49,91.400,0.10173,2.875,0.002
15.53,91.500,0.10190,2.883,0.002
15.58,91.600,0.10202,2.891,0.002
15.60,91.700,0.10219,2.894,0.002
15.61,91.800,0.10235,2.897,0.002
15.67,91.900,0.10248,2.907,0.002
15.69,92.000,0.10265,2.913,0.002
15.72,92.100,0.10281,2.916,0.002
15.74,92.200,0.10298,2.922,0.002
15.77,92.300,0.10310,2.926,0.002
15.84,92.400,0.10327,2.939,0.002
15.84,92.500,0.10344,2.940,0.002
15.87,92.600,0.10360,2.946,0.002
15.89,92.700,0.10377,2.950,0.002
15.94,92.800,0.10393,2.958,0.002
15.95,92.900,0.10410,2.960,0.002
15.99,93.000,0.10427,2.968,0.002
16.04,93.100,0.10443,2.976,0.002
16.07,93.200,0.10460,2.982,0.002
16.10,93.300,0.10476,2.988,0.002
16.14,93.400,0.10493,2.995,0.002
16.17,93.500,0.10514,3.001,0.002
16.22,93.600,0.10531,3.010,0.002
16.26,93.700,0.10551,3.018,0.002
16.31,93.800,0.10572,3.026,0.002
16.34,93.900,0.10597,3.033,0.002
16.39,94.000,0.10618,3.041,0.002
16.43,94.100,0.10639,3.050,0.002
16.46,94.200,0.10659,3.055,0.002
16.52,94.300,0.10684,3.065,0.002
16.55,94.400,0.10705,3.072,0.002
16.60,94.500,0.10726,3.081,0.002
16.63,94.600,0.10751,3.086,0.002
16.66,94.700,0.10772,3.091,0.002
16.70,94.800,0.10788,3.098,0.002
16.72,94.900,0.10809,3.102,0.002
16.74,95.000,0.10830,3.107,0.002
16.77,95.100,0.10846,3.112,0.002
16.79,95.200,0.10863,3.116,0.002
16.81,95.300,0.10880,3.120,0.002
16.82,95.400,0.10896,3.121,0.002
16.84,95.500,0.10909,3.126,0.002
16.87,95.600,0.10925,3.131,0.002
16.89,95.700,0.10942,3.135,0.002
16.92,95.800,0.10954,3.140,0.002
16.93,95.900,0.10971,3.142,0.002
16.94,96.000,0.10983,3.144,0.002
16.97,96.100,0.10996,3.150,0.002
16.99,96.200,0.11013,3.153,0.002
17.01,96.300,0.11025,3.157,0.002
17.02,96.400,0.11037,3.159,0.002
17.05,96.500,0.11050,3.164,0.002
17.07,96.600,0.11067,3.167,0.002
17.08,96.700,0.11079,3.170,0.002
17.13,96.800,0.11092,3.178,0.002
17.12,96.900,0.11108,3.177,0.002
17.16,97.000,0.11121,3.184,0.002
17.17,97.100,0.11137,3.187,0.002
17.22,97.200,0.11154,3.197,0.002
17.24,97.300,0.11166,3.200,0.002
17.28,97.400,0.11183,3.206,0.002
17.29,97.500,0.11200,3.208,0.002
17.33,97.600,0.11216,3.216,0.002
17.33,97.700,0.11229,3.216,0.002
17.36,97.800,0.11245,3.222,0.002
17.40,97.900,0.11262,3.230,0.002
17.40,98.000,0.11279,3.230,0.002
17.46,98.100,0.11295,3.240,0.002
17.44,98.200,0.11308,3.237,0.002
17.46,98.300,0.11324,3.241,0.002
17.50,98.400,0.11341,3.248,0.002
17.53,98.500,0.11357,3.253,0.002
17.55,98.600,0.11374,3.257,0.002
17.57,98.700,0.11391,3.261,0.002
17.61,98.800,0.11407,3.268,0.002
17.64,98.900,0.11428,3.273,0.002
17.68,99.000,0.11445,3.281,0.002
17.71,99.100,0.11466,3.287,0.002
17.73,99.200,0.11486,3.290,0.002
17.77,99.300,0.11503,3.299,0.002
17.81,99.400,0.11528,3.305,0.002
17.85,99.500,0.11549,3.312,0.002
17.88,99.600,0.11569,3.317,0.002
17.92,99.700,0.11590,3.325,0.002
17.94,99.800,0.11615,3.330,0.002
17.99,99.900,0.11636,3.339,0.002
18.00,100.000,0.11657,3.340,0.002
18.03,100.100,0.11677,3.345,0.002
18.04,100.200,0.11698,3.348,0.002
18.07,100.300,0.11715,3.354,0.002
18.09,100.400,0.11736,3.358,0.002
18.09,100.500,0.11752,3.358,0.002
18.12,100.600,0.11773,3.363,0.002
2.16,100.700,0.11790,0.402,0.002
1.93,100.710,0.11794,0.359,0.002