File: data-files/CWRU/0900-05-28w.txt
""
"Test Method","Will_Huddleston_Disks.msm"
"Sample I. D.","28w.mss"
"Specimen Number","1"

"Load (N)","Time (s)","Extension (mm)","Stress (MPa)","Strain (mm/mm)"

3.46,0.200,-0.03547,0.465,-0.001
3.44,0.300,-0.03547,0.463,-0.001
3.46,0.400,-0.03547,0.465,-0.001
3.44,0.500,-0.03547,0.463,-0.001
3.47,0.600,-0.03547,0.467,-0.001
3.45,0.700,-0.03547,0.465,-0.001
3.48,0.800,-0.03547,0.468,-0.001
3.44,0.900,-0.03547,0.463,-0.001
3.47,1.000,-0.03547,0.466,-0.001
3.45,1.100,-0.03543,0.465,-0.001
3.47,1.200,-0.03543,0.467,-0.001
3.46,1.300,-0.03543,0.466,-0.001
3.48,1.400,-0.03543,0.468,-0.001
3.46,1.500,-0.03543,0.465,-0.001
3.47,1.600,-0.03543,0.467,-0.001
3.44,1.700,-0.03543,0.463,-0.001
3.46,1.800,-0.03539,0.465,-0.001
3.44,1.900,-0.03539,0.463,-0.001
3.46,2.000,-0.03539,0.466,-0.001
3.43,2.100,-0.03539,0.462,-0.001
3.45,2.200,-0.03539,0.465,-0.001
3.46,2.300,-0.03535,0.465,-0.001
3.47,2.400,-0.03535,0.466,-0.001
3.44,2.500,-0.03535,0.463,-0.001
3.45,2.600,-0.03535,0.465,-0.001
3.45,2.700,-0.03535,0.465,-0.001
3.45,2.800,-0.03535,0.465,-0.001
3.47,2.900,-0.03531,0.467,-0.001
3.45,3.000,-0.03531,0.464,-0.001
3.47,3.100,-0.03531,0.467,-0.001
3.47,3.200,-0.03531,0.467,-0.001
3.46,3.300,-0.03531,0.466,-0.001
3.45,3.400,-0.03527,0.465,-0.001
3.46,3.500,-0.03527,0.465,-0.001
3.46,3.600,-0.03527,0.466,-0.001
3.47,3.700,-0.03522,0.467,-0.001
3.46,3.800,-0.03522,0.466,-0.001
3.48,3.900,-0.03522,0.468,-0.001
3.48,4.000,-0.03522,0.468,-0.001
3.48,4.100,-0.03518,0.468,-0.001
3.48,4.200,-0.03518,0.468,-0.001
3.51,4.300,-0.03514,0.473,-0.001
3.49,4.400,-0.03514,0.469,-0.001
3.54,4.500,-0.03510,0.476,-0.001
3.52,4.600,-0.03506,0.474,-0.001
3.56,4.700,-0.03506,0.478,-0.001
3.55,4.800,-0.03502,0.478,-0.001
3.59,4.900,-0.03497,0.483,-0.001
3.61,5.000,-0.03493,0.486,-0.001
3.64,5.100,-0.03489,0.490,-0.001
3.67,5.200,-0.03481,0.493,-0.001
3.73,5.300,-0.03473,0.502,-0.001
3.75,5.400,-0.03464,0.505,-0.001
3.82,5.500,-0.03456,0.513,-0.001
3.84,5.600,-0.03452,0.516,-0.001
3.88,5.700,-0.03443,0.522,-0.001
3.91,5.800,-0.03435,0.526,-0.001
3.95,5.900,-0.03427,0.532,-0.001
3.95,6.000,-0.03419,0.532,-0.001
4.01,6.100,-0.03410,0.539,-0.001
4.01,6.200,-0.03402,0.540,-0.001
4.06,6.300,-0.03394,0.547,-0.001
4.07,6.400,-0.03385,0.547,-0.001
4.10,6.500,-0.03377,0.551,-0.001
4.12,6.600,-0.03369,0.554,-0.001
4.14,6.700,-0.03360,0.557,-0.001
4.16,6.800,-0.03348,0.559,-0.001
4.19,6.900,-0.03340,0.563,-0.001
4.21,7.000,-0.03331,0.566,-0.001
4.23,7.100,-0.03323,0.569,-0.001
4.25,7.200,-0.03315,0.572,-0.001
4.28,7.300,-0.03302,0.576,-0.001
4.29,7.400,-0.03294,0.578,-0.001
4.32,7.500,-0.03281,0.582,-0.001
4.35,7.600,-0.03273,0.585,-0.001
4.38,7.700,-0.03265,0.590,-0.001
4.39,7.800,-0.03252,0.591,-0.001
4.41,7.900,-0.03244,0.593,-0.001
4.43,8.000,-0.03232,0.596,-0.001
4.46,8.100,-0.03223,0.600,-0.001
4.47,8.200,-0.03211,0.602,-0.001
4.51,8.300,-0.03202,0.606,-0.001
4.51,8.400,-0.03194,0.607,-0.001
4.54,8.500,-0.03182,0.611,-0.001
4.56,8.600,-0.03173,0.613,-0.001
4.57,8.700,-0.03165,0.614,-0.001
4.60,8.800,-0.03153,0.619,-0.001
4.62,8.900,-0.03144,0.621,-0.001
4.63,9.000,-0.03136,0.624,-0.001
4.65,9.100,-0.03123,0.626,-0.001
4.68,9.200,-0.03115,0.629,-0.001
4.69,9.300,-0.03107,0.632,-0.001
4.71,9.400,-0.03099,0.633,-0.001
4.73,9.500,-0.03086,0.637,-0.001
4.75,9.600,-0.03078,0.639,-0.001
4.76,9.700,-0.03069,0.640,-0.001
4.78,9.800,-0.03061,0.643,-0.001
4.78,9.900,-0.03053,0.643,-0.001
4.81,10.000,-0.03045,0.648,-0.001
4.84,10.100,-0.03036,0.651,-0.001
4.84,10.200,-0.03028,0.650,-0.001
4.86,10.300,-0.03020,0.653,-0.001
4.87,10.400,-0.03011,0.656,-0.001
4.86,10.500,-0.03003,0.654,-0.001
4.89,10.600,-0.02995,0.657,-0.001
4.90,10.700,-0.02986,0.660,-0.001
4.93,10.800,-0.02978,0.663,-0.001
4.94,10.900,-0.02974,0.664,-0.001
4.96,11.000,-0.02966,0.667,-0.001
4.97,11.100,-0.02957,0.668,-0.001
4.98,11.200,-0.02949,0.670,-0.001
4.99,11.300,-0.02941,0.671,-0.001
5.00,11.400,-0.02936,0.672,-0.001
5.01,11.500,-0.02928,0.674,-0.001
5.03,11.600,-0.02920,0.676,-0.001
5.06,11.700,-0.02916,0.681,-0.001
5.07,11.800,-0.02907,0.682,-0.001
5.08,11.900,-0.02899,0.684,-0.001
5.09,12.000,-0.02895,0.684,-0.001
5.10,12.100,-0.02887,0.686,-0.001
5.11,12.200,-0.02878,0.687,-0.001
5.13,12.300,-0.02874,0.690,-0.001
5.14,12.400,-0.02866,0.691,-0.001
5.15,12.500,-0.02862,0.693,-0.001
5.16,12.600,-0.02853,0.695,-0.001
5.17,12.700,-0.02845,0.696,-0.001
5.21,12.800,-0.02841,0.701,-0.001
5.21,12.900,-0.02833,0.700,-0.001
5.21,13.000,-0.02828,0.701,-0.001
5.22,13.100,-0.02820,0.702,-0.001
5.25,13.200,-0.02812,0.706,-0.001
5.25,13.300,-0.02808,0.706,-0.001
5.28,13.400,-0.02799,0.710,-0.001
5.29,13.500,-0.02791,0.712,-0.001
5.31,13.600,-0.02787,0.714,-0.001
5.32,13.700,-0.02779,0.716,-0.001
5.32,13.800,-0.02770,0.716,-0.001
5.33,13.900,-0.02766,0.717,-0.001
5.35,14.000,-0.02758,0.720,-0.001
5.35,14.100,-0.02749,0.720,-0.001
5.38,14.200,-0.02741,0.724,-0.001
5.39,14.300,-0.02737,0.725,-0.001
5.40,14.400,-0.02729,0.727,-0.001
5.43,14.500,-0.02720,0.730,-0.001
5.43,14.600,-0.02712,0.731,-0.001
5.45,14.700,-0.02708,0.733,-0.001
5.47,14.800,-0.02700,0.736,-0.001
5.47,14.900,-0.02691,0.735,-0.001
5.50,15.000,-0.02683,0.740,-0.001
5.51,15.100,-0.02675,0.741,-0.001
5.54,15.200,-0.02671,0.745,-0.001
5.53,15.300,-0.02662,0.744,-0.001
5.55,15.400,-0.02654,0.747,-0.001
5.57,15.500,-0.02646,0.749,-0.001
5.58,15.600,-0.02637,0.751,-0.001
5.60,15.700,-0.02629,0.753,-0.001
5.62,15.800,-0.02621,0.755,-0.001
5.63,15.900,-0.02616,0.757,-0.001
5.65,16.000,-0.02608,0.760,-0.001
5.66,16.100,-0.02600,0.762,-0.001
5.68,16.200,-0.02592,0.765,-0.001
5.70,16.300,-0.02583,0.767,-0.001
5.72,16.400,-0.02575,0.769,-0.001
5.73,16.500,-0.02567,0.771,-0.001
5.73,16.600,-0.02558,0.771,-0.001
5.75,16.700,-0.02554,0.774,-0.001
5.76,16.800,-0.02546,0.775,-0.001
5.79,16.900,-0.02538,0.779,0.000
5.80,17.000,-0.02529,0.780,0.000
5.82,17.100,-0.02521,0.783,0.000
5.84,17.200,-0.02513,0.785,0.000
5.86,17.300,-0.02504,0.789,0.000
5.87,17.400,-0.02496,0.789,0.000
5.88,17.500,-0.02488,0.792,0.000
5.90,17.600,-0.02479,0.794,0.000
5.92,17.700,-0.02471,0.797,0.000
5.92,17.800,-0.02463,0.796,0.000
5.95,17.900,-0.02454,0.801,0.000
5.98,18.000,-0.02442,0.804,0.000
6.00,18.100,-0.02434,0.807,0.000
6.01,18.200,-0.02421,0.809,0.000
6.04,18.300,-0.02413,0.813,0.000
6.07,18.400,-0.02405,0.817,0.000
6.08,18.500,-0.02392,0.819,0.000
6.09,18.600,-0.02384,0.820,0.000
6.11,18.700,-0.02371,0.822,0.000
6.14,18.800,-0.02363,0.826,0.000
6.17,18.900,-0.02351,0.830,0.000
6.18,19.000,-0.02342,0.832,0.000
6.20,19.100,-0.02330,0.834,0.000
6.23,19.200,-0.02317,0.838,0.000
6.26,19.300,-0.02305,0.843,0.000
6.27,19.400,-0.02297,0.844,0.000
6.32,19.500,-0.02284,0.850,0.000
6.33,19.600,-0.02272,0.852,0.000
6.34,19.700,-0.02263,0.853,0.000
6.35,19.800,-0.02251,0.854,0.000
6.40,19.900,-0.02238,0.861,0.000
6.41,20.000,-0.02230,0.862,0.000
6.44,20.100,-0.02218,0.866,0.000
6.45,20.200,-0.02209,0.868,0.000
6.45,20.300,-0.02197,0.868,0.000
6.48,20.400,-0.02188,0.872,0.000
6.50,20.500,-0.02176,0.874,0.000
6.53,20.600,-0.02168,0.879,0.000
6.55,20.700,-0.02155,0.882,0.000
6.57,20.800,-0.02147,0.883,0.000
6.58,20.900,-0.02139,0.885,0.000
6.59,21.000,-0.02130,0.887,0.000
6.62,21.100,-0.02118,0.890,0.000
6.63,21.200,-0.02110,0.892,0.000
6.64,21.300,-0.02101,0.893,0.000
6.67,21.400,-0.02093,0.897,0.000
6.67,21.500,-0.02085,0.898,0.000
6.72,21.600,-0.02076,0.904,0.000
6.71,21.700,-0.02072,0.903,0.000
6.73,21.800,-0.02064,0.905,0.000
6.74,21.900,-0.02055,0.907,0.000
6.76,22.000,-0.02047,0.909,0.000
6.77,22.100,-0.02039,0.910,0.000
6.78,22.200,-0.02031,0.912,0.000
6.79,22.300,-0.02022,0.913,0.000
6.82,22.400,-0.02018,0.917,0.000
6.82,22.500,-0.02010,0.918,0.000
6.84,22.600,-0.02001,0.920,0.000
6.85,22.700,-0.01997,0.921,0.000
6.86,22.800,-0.01989,0.923,0.000
6.86,22.900,-0.01981,0.923,0.000
6.89,23.000,-0.01977,0.927,0.000
6.89,23.100,-0.01968,0.927,0.000
6.92,23.200,-0.01960,0.931,0.000
6.93,23.300,-0.01956,0.932,0.000
6.95,23.400,-0.01947,0.935,0.000
6.95,23.500,-0.01939,0.935,0.000
6.97,23.600,-0.01935,0.937,0.000
6.96,23.700,-0.01927,0.936,0.000
7.00,23.800,-0.01923,0.942,0.000
6.99,23.900,-0.01914,0.941,0.000
7.03,24.000,-0.01910,0.946,0.000
7.03,24.100,-0.01902,0.946,0.000
7.06,24.200,-0.01893,0.950,0.000
7.07,24.300,-0.01889,0.951,0.000
7.09,24.400,-0.01881,0.954,0.000
7.08,24.500,-0.01873,0.953,0.000
7.10,24.600,-0.01868,0.955,0.000
7.10,24.700,-0.01860,0.955,0.000
7.16,24.800,-0.01852,0.963,0.000
7.14,24.900,-0.01848,0.960,0.000
7.18,25.000,-0.01839,0.966,0.000
7.16,25.100,-0.01831,0.963,0.000
7.20,25.200,-0.01827,0.969,0.000
7.21,25.300,-0.01819,0.970,0.000
7.23,25.400,-0.01810,0.972,0.000
7.23,25.500,-0.01806,0.973,0.000
7.26,25.600,-0.01798,0.976,0.000
7.26,25.700,-0.01790,0.977,0.000
7.30,25.800,-0.01781,0.983,0.000
7.29,25.900,-0.01773,0.981,0.000
7.32,26.000,-0.01769,0.985,0.000
7.33,26.100,-0.01760,0.986,0.000
7.36,26.200,-0.01752,0.990,0.000
7.36,26.300,-0.01744,0.990,0.000
7.38,26.400,-0.01736,0.994,0.000
7.39,26.500,-0.01727,0.994,0.000
7.42,26.600,-0.01719,0.998,0.000
7.43,26.700,-0.01711,1.000,0.000
7.45,26.800,-0.01706,1.002,0.000
7.45,26.900,-0.01698,1.003,0.000
7.48,27.000,-0.01690,1.006,0.000
7.50,27.100,-0.01681,1.009,0.000
7.51,27.200,-0.01673,1.010,0.000
7.52,27.300,-0.01665,1.011,0.000
7.53,27.400,-0.01661,1.014,0.000
7.56,27.500,-0.01652,1.017,0.000
7.57,27.600,-0.01644,1.019,0.000
7.58,27.700,-0.01636,1.020,0.000
7.61,27.800,-0.01627,1.024,0.000
7.62,27.900,-0.01619,1.026,0.000
7.63,28.000,-0.01611,1.027,0.000
7.66,28.100,-0.01603,1.031,0.000
7.67,28.200,-0.01594,1.032,0.000
7.71,28.300,-0.01586,1.037,0.000
7.71,28.400,-0.01578,1.038,0.000
7.73,28.500,-0.01569,1.040,0.000
7.74,28.600,-0.01561,1.042,0.000
7.76,28.700,-0.01553,1.044,0.000
7.78,28.800,-0.01544,1.046,0.000
7.79,28.900,-0.01536,1.048,0.000
7.82,29.000,-0.01528,1.053,0.000
7.83,29.100,-0.01519,1.054,0.000
7.85,29.200,-0.01507,1.056,0.000
7.87,29.300,-0.01499,1.059,0.000
7.89,29.400,-0.01490,1.062,0.000
7.93,29.500,-0.01478,1.067,0.000
7.93,29.600,-0.01470,1.067,0.000
7.97,29.700,-0.01461,1.072,0.000
8.00,29.800,-0.01449,1.077,0.000
8.03,29.900,-0.01440,1.080,0.000
8.04,30.000,-0.01428,1.081,0.000
8.07,30.100,-0.01420,1.086,0.000
8.09,30.200,-0.01407,1.089,0.000
8.12,30.300,-0.01395,1.092,0.000
8.15,30.400,-0.01386,1.097,0.000
8.19,30.500,-0.01374,1.102,0.000
8.20,30.600,-0.01362,1.103,0.000
8.22,30.700,-0.01353,1.106,0.000
8.25,30.800,-0.01341,1.109,0.000
8.27,30.900,-0.01328,1.113,0.000
8.30,31.000,-0.01320,1.116,0.000
8.33,31.100,-0.01307,1.121,0.000
8.34,31.200,-0.01295,1.123,0.000
8.37,31.300,-0.01283,1.125,0.000
8.39,31.400,-0.01274,1.129,0.000
8.41,31.500,-0.01262,1.132,0.000
8.42,31.600,-0.01253,1.133,0.000
8.44,31.700,-0.01241,1.136,0.000
8.46,31.800,-0.01233,1.138,0.000
8.50,31.900,-0.01220,1.143,0.000
8.51,32.000,-0.01212,1.145,0.000
8.51,32.100,-0.01204,1.145,0.000
8.55,32.200,-0.01191,1.151,0.000
8.57,32.300,-0.01183,1.153,0.000
8.60,32.400,-0.01175,1.157,0.000
8.60,32.500,-0.01162,1.157,0.000
8.63,32.600,-0.01154,1.161,0.000
8.64,32.700,-0.01145,1.162,0.000
8.67,32.800,-0.01137,1.166,0.000
8.68,32.900,-0.01129,1.168,0.000
8.70,33.000,-0.01120,1.171,0.000
8.71,33.100,-0.01112,1.172,0.000
8.73,33.200,-0.01104,1.174,0.000
8.73,33.300,-0.01100,1.174,0.000
8.75,33.400,-0.01091,1.177,0.000
8.76,33.500,-0.01083,1.179,0.000
8.79,33.600,-0.01075,1.182,0.000
8.81,33.700,-0.01066,1.185,0.000
8.83,33.800,-0.01058,1.188,0.000
8.84,33.900,-0.01054,1.189,0.000
8.86,34.000,-0.01046,1.192,0.000
8.87,34.100,-0.01037,1.193,0.000
8.88,34.200,-0.01029,1.195,0.000
8.88,34.300,-0.01025,1.195,0.000
8.92,34.400,-0.01017,1.200,0.000
8.91,34.500,-0.01008,1.199,0.000
8.94,34.600,-0.01004,1.203,0.000
8.95,34.700,-0.00996,1.204,0.000
8.97,34.800,-0.00988,1.206,0.000
8.96,34.900,-0.00983,1.205,0.000
8.99,35.000,-0.00975,1.210,0.000
8.99,35.100,-0.00971,1.210,0.000
9.01,35.200,-0.00963,1.212,0.000
9.04,35.300,-0.00954,1.216,0.000
9.05,35.400,-0.00950,1.218,0.000
9.06,35.500,-0.00942,1.219,0.000
9.08,35.600,-0.00933,1.222,0.000
9.10,35.700,-0.00929,1.224,0.000
9.13,35.800,-0.00921,1.228,0.000
9.12,35.900,-0.00913,1.227,0.000
9.15,36.000,-0.00904,1.230,0.000
9.16,36.100,-0.00900,1.232,0.000
9.19,36.200,-0.00892,1.237,0.000
9.19,36.300,-0.00884,1.237,0.000
9.23,36.400,-0.00875,1.241,0.000
9.23,36.500,-0.00871,1.242,0.000
9.25,36.600,-0.00863,1.244,0.000
9.25,36.700,-0.00855,1.244,0.000
9.27,36.800,-0.00846,1.247,0.000
9.28,36.900,-0.00842,1.249,0.000
9.31,37.000,-0.00834,1.253,0.000
9.34,37.100,-0.00825,1.257,0.000
9.37,37.200,-0.00817,1.260,0.000
9.37,37.300,-0.00809,1.261,0.000
9.39,37.400,-0.00801,1.264,0.000
9.42,37.500,-0.00792,1.267,0.000
9.43,37.600,-0.00784,1.269,0.000
9.45,37.700,-0.00780,1.272,0.000
9.46,37.800,-0.00771,1.273,0.000
9.48,37.900,-0.00763,1.276,0.000
9.49,38.000,-0.00755,1.277,0.000
9.52,38.100,-0.00746,1.281,0.000
9.55,38.200,-0.00742,1.284,0.000
9.55,38.300,-0.00734,1.285,0.000
9.57,38.400,-0.00726,1.287,0.000
9.59,38.500,-0.00717,1.290,0.000
9.62,38.600,-0.00709,1.294,0.000
9.63,38.700,-0.00701,1.295,0.000
9.66,38.800,-0.00692,1.300,0.000
9.68,38.900,-0.00684,1.302,0.000
9.68,39.000,-0.00676,1.303,0.000
9.71,39.100,-0.00668,1.307,0.000
9.73,39.200,-0.00663,1.309,0.000
9.75,39.300,-0.00655,1.311,0.000
9.77,39.400,-0.00647,1.314,0.000
9.78,39.500,-0.00638,1.316,0.000
9.80,39.600,-0.00630,1.319,0.000
9.82,39.700,-0.00622,1.321,0.000
9.86,39.800,-0.00614,1.326,0.000
9.88,39.900,-0.00605,1.330,0.000
9.90,40.000,-0.00597,1.332,0.000
9.91,40.100,-0.00589,1.334,0.000
9.93,40.200,-0.00576,1.336,0.000
9.96,40.300,-0.00568,1.340,0.000
9.99,40.400,-0.00559,1.344,0.000
10.01,40.500,-0.00551,1.346,0.000
10.04,40.600,-0.00543,1.351,0.000
10.07,40.700,-0.00530,1.354,0.000
10.07,40.800,-0.00522,1.355,0.000
10.10,40.900,-0.00514,1.359,0.000
10.13,41.000,-0.00501,1.363,0.000
10.14,41.100,-0.00493,1.364,0.000
10.18,41.200,-0.00485,1.369,0.000
10.22,41.300,-0.00472,1.375,0.000
10.23,41.400,-0.00460,1.377,0.000
10.27,41.500,-0.00451,1.382,0.000
10.30,41.600,-0.00439,1.385,0.000
10.34,41.700,-0.00431,1.391,0.000
10.36,41.800,-0.00418,1.394,0.000
10.38,41.900,-0.00406,1.396,0.000
10.40,42.000,-0.00397,1.399,0.000
10.44,42.100,-0.00385,1.405,0.000
10.44,42.200,-0.00372,1.405,0.000
10.49,42.300,-0.00364,1.411,0.000
10.50,42.400,-0.00352,1.412,0.000
10.55,42.500,-0.00343,1.420,0.000
10.55,42.600,-0.00331,1.420,0.000
10.58,42.700,-0.00323,1.424,0.000
10.60,42.800,-0.00310,1.426,0.000
10.63,42.900,-0.00302,1.431,0.000
10.63,43.000,-0.00294,1.430,0.000
10.68,43.100,-0.00281,1.437,0.000
10.69,43.200,-0.00273,1.438,0.000
10.73,43.300,-0.00264,1.444,0.000
10.73,43.400,-0.00256,1.444,0.000
10.76,43.500,-0.00244,1.447,0.000
10.75,43.600,-0.00235,1.447,0.000
10.80,43.700,-0.00227,1.454,0.000
10.79,43.800,-0.00219,1.452,0.000
10.83,43.900,-0.00210,1.457,0.000
10.84,44.000,-0.00202,1.458,0.000
10.88,44.100,-0.00194,1.463,0.000
10.89,44.200,-0.00185,1.465,0.000
10.91,44.300,-0.00177,1.467,0.000
10.91,44.400,-0.00169,1.468,0.000
10.95,44.500,-0.00161,1.474,0.000
10.97,44.600,-0.00152,1.475,0.000
10.99,44.700,-0.00148,1.478,0.000
10.99,44.800,-0.00140,1.479,0.000
11.04,44.900,-0.00131,1.485,0.000
11.04,45.000,-0.00123,1.485,0.000
11.07,45.100,-0.00115,1.489,0.000
11.07,45.200,-0.00111,1.490,0.000
11.10,45.300,-0.00102,1.493,0.000
11.12,45.400,-0.00094,1.496,0.000
11.11,45.500,-0.00086,1.495,0.000
11.12,45.600,-0.00082,1.497,0.000
11.15,45.700,-0.00073,1.500,0.000
11.16,45.800,-0.00065,1.501,0.000
11.19,45.900,-0.00061,1.505,0.000
11.19,46.000,-0.00053,1.505,0.000
11.23,46.100,-0.00048,1.510,0.000
11.22,46.200,-0.00040,1.510,0.000
11.24,46.300,-0.00032,1.513,0.000
11.25,46.400,-0.00028,1.513,0.000
11.27,46.500,-0.00019,1.517,0.000
11.29,46.600,-0.00015,1.519,0.000
11.30,46.700,-0.00007,1.521,0.000
11.30,46.800,-0.00003,1.521,0.000
11.33,46.900,0.00006,1.524,0.000
11.35,47.000,0.00014,1.527,0.000
11.36,47.100,0.00018,1.529,0.000
11.37,47.200,0.00026,1.530,0.000
11.40,47.300,0.00035,1.533,0.000
11.39,47.400,0.00039,1.533,0.000
11.44,47.500,0.00047,1.539,0.000
11.44,47.600,0.00056,1.539,0.000
11.47,47.700,0.00060,1.543,0.000
11.49,47.800,0.00068,1.546,0.000
11.53,47.900,0.00076,1.551,0.000
11.52,48.000,0.00080,1.549,0.000
11.55,48.100,0.00089,1.554,0.000
11.56,48.200,0.00097,1.555,0.000
11.59,48.300,0.00101,1.560,0.000
11.59,48.400,0.00110,1.559,0.000
11.63,48.500,0.00118,1.564,0.000
11.64,48.600,0.00122,1.566,0.000
11.67,48.700,0.00130,1.570,0.000
11.68,48.800,0.00139,1.571,0.000
11.72,48.900,0.00147,1.577,0.000
11.72,49.000,0.00155,1.577,0.000
11.75,49.100,0.00159,1.581,0.000
11.76,49.200,0.00168,1.582,0.000
11.80,49.300,0.00176,1.587,0.000
11.79,49.400,0.00184,1.587,0.000
11.84,49.500,0.00189,1.593,0.000
11.84,49.600,0.00197,1.592,0.000
11.87,49.700,0.00205,1.598,0.000
11.87,49.800,0.00213,1.597,0.000
11.91,49.900,0.00222,1.602,0.000
11.93,50.000,0.00226,1.605,0.000
11.97,50.100,0.00234,1.610,0.000
11.97,50.200,0.00243,1.610,0.000
12.00,50.300,0.00251,1.614,0.000
12.00,50.400,0.00259,1.615,0.000
12.04,50.500,0.00267,1.620,0.000
12.05,50.600,0.00276,1.621,0.000
12.10,50.700,0.00284,1.628,0.000
12.09,50.800,0.00292,1.627,0.000
12.13,50.900,0.00297,1.632,0.000
12.12,51.000,0.00305,1.631,0.000
12.17,51.100,0.00313,1.638,0.000
12.18,51.200,0.00321,1.639,0.000
12.21,51.300,0.00330,1.642,0.000
12.23,51.400,0.00338,1.646,0.000
12.27,51.500,0.00346,1.650,0.000
12.28,51.600,0.00355,1.653,0.000
12.29,51.700,0.00363,1.654,0.000
12.31,51.800,0.00371,1.656,0.000
12.34,51.900,0.00380,1.661,0.000
12.36,52.000,0.00388,1.664,0.000
12.40,52.100,0.00400,1.669,0.000
12.43,52.200,0.00409,1.672,0.000
12.46,52.300,0.00417,1.676,0.000
12.47,52.400,0.00425,1.678,0.000
12.50,52.500,0.00438,1.682,0.000
12.53,52.600,0.00446,1.686,0.000
12.56,52.700,0.00454,1.690,0.000
12.58,52.800,0.00467,1.693,0.000
12.62,52.900,0.00475,1.697,0.000
12.65,53.000,0.00488,1.701,0.000
12.69,53.100,0.00500,1.708,0.000
12.72,53.200,0.00509,1.712,0.000
12.76,53.300,0.00521,1.716,0.000
12.77,53.400,0.00533,1.719,0.000
12.81,53.500,0.00542,1.724,0.000
12.82,53.600,0.00554,1.725,0.000
12.85,53.700,0.00563,1.728,0.000
12.88,53.800,0.00571,1.732,0.000
12.91,53.900,0.00583,1.737,0.000
12.94,54.000,0.00592,1.741,0.000
12.98,54.100,0.00604,1.746,0.000
13.01,54.200,0.00612,1.750,0.000
13.04,54.300,0.00625,1.754,0.000
13.06,54.400,0.00633,1.757,0.000
13.08,54.500,0.00646,1.760,0.000
13.11,54.600,0.00654,1.763,0.000
13.13,54.700,0.00666,1.767,0.000
13.15,54.800,0.00675,1.769,0.000
13.17,54.900,0.00683,1.772,0.000
13.22,55.000,0.00691,1.778,0.000
13.23,55.100,0.00704,1.780,0.000
13.26,55.200,0.00712,1.785,0.000
13.28,55.300,0.00720,1.786,0.000
13.29,55.400,0.00729,1.788,0.000
13.30,55.500,0.00737,1.789,0.000
13.34,55.600,0.00745,1.795,0.000
13.35,55.700,0.00754,1.796,0.000
13.38,55.800,0.00762,1.801,0.000
13.39,55.900,0.00770,1.802,0.000
13.42,56.000,0.00779,1.806,0.000
13.43,56.100,0.00787,1.807,0.000
13.47,56.200,0.00791,1.812,0.000
13.47,56.300,0.00799,1.812,0.000
13.51,56.400,0.00808,1.817,0.000
13.50,56.500,0.00816,1.817,0.000
13.53,56.600,0.00824,1.820,0.000
13.54,56.700,0.00828,1.822,0.000
13.58,56.800,0.00837,1.826,0.000
13.57,56.900,0.00845,1.826,0.000
13.63,57.000,0.00849,1.833,0.000
13.63,57.100,0.00858,1.834,0.000
13.67,57.200,0.00866,1.839,0.000
13.66,57.300,0.00870,1.838,0.000
13.69,57.400,0.00878,1.842,0.000
13.71,57.500,0.00887,1.845,0.000
13.73,57.600,0.00891,1.847,0.000
13.73,57.700,0.00899,1.847,0.000
13.76,57.800,0.00903,1.851,0.000
13.76,57.900,0.00912,1.852,0.000
13.80,58.000,0.00920,1.857,0.000
13.80,58.100,0.00924,1.857,0.000
13.83,58.200,0.00932,1.860,0.000
13.83,58.300,0.00937,1.861,0.000
13.86,58.400,0.00945,1.864,0.000
13.87,58.500,0.00949,1.866,0.000
13.89,58.600,0.00957,1.868,0.000
13.90,58.700,0.00961,1.870,0.000
13.96,58.800,0.00970,1.878,0.000
13.95,58.900,0.00978,1.876,0.000
13.98,59.000,0.00982,1.881,0.000
14.00,59.100,0.00991,1.883,0.000
14.01,59.200,0.00995,1.885,0.000
14.02,59.300,0.01003,1.886,0.000
14.06,59.400,0.01011,1.892,0.000
14.06,59.500,0.01015,1.892,0.000
14.09,59.600,0.01024,1.896,0.000
14.10,59.700,0.01032,1.898,0.000
14.14,59.800,0.01036,1.902,0.000
14.16,59.900,0.01045,1.905,0.000
14.18,60.000,0.01053,1.908,0.000
14.20,60.100,0.01061,1.911,0.000
14.21,60.200,0.01065,1.911,0.000
14.24,60.300,0.01074,1.916,0.000
14.27,60.400,0.01082,1.920,0.000
14.28,60.500,0.01090,1.921,0.000
14.31,60.600,0.01099,1.925,0.000
14.34,60.700,0.01103,1.929,0.000
14.35,60.800,0.01111,1.931,0.000
14.37,60.900,0.01119,1.933,0.000
14.39,61.000,0.01128,1.937,0.000
14.41,61.100,0.01136,1.939,0.000
14.41,61.200,0.01144,1.938,0.000
14.46,61.300,0.01148,1.945,0.000
14.47,61.400,0.01157,1.947,0.000
14.49,61.500,0.01165,1.950,0.000
14.51,61.600,0.01173,1.952,0.000
14.54,61.700,0.01182,1.956,0.000
14.55,61.800,0.01186,1.957,0.000
14.57,61.900,0.01194,1.961,0.000
14.59,62.000,0.01202,1.963,0.000
14.62,62.100,0.01211,1.967,0.000
14.63,62.200,0.01219,1.968,0.000
14.66,62.300,0.01227,1.972,0.000
14.67,62.400,0.01236,1.973,0.000
14.70,62.500,0.01244,1.978,0.000
14.71,62.600,0.01252,1.979,0.000
14.75,62.700,0.01261,1.984,0.000
14.74,62.800,0.01269,1.983,0.000
14.80,62.900,0.01277,1.991,0.000
14.79,63.000,0.01286,1.990,0.000
14.82,63.100,0.01294,1.994,0.000
14.82,63.200,0.01302,1.994,0.000
14.87,63.300,0.01311,2.000,0.000
14.87,63.400,0.01319,2.001,0.000
14.90,63.500,0.01327,2.005,0.000
14.92,63.600,0.01335,2.007,0.000
14.95,63.700,0.01344,2.012,0.000
14.96,63.800,0.01352,2.013,0.000
14.99,63.900,0.01365,2.017,0.000
14.98,64.000,0.01373,2.016,0.000
15.02,64.100,0.01381,2.021,0.000
15.03,64.200,0.01394,2.022,0.000
15.06,64.300,0.01402,2.026,0.000
15.05,64.400,0.01410,2.025,0.000
15.08,64.500,0.01423,2.029,0.000
15.06,64.600,0.01435,2.026,0.000
15.08,64.700,0.01444,2.028,0.000
15.06,64.800,0.01456,2.026,0.000
15.07,64.900,0.01464,2.027,0.000
15.02,65.000,0.01477,2.021,0.000
14.95,65.100,0.01485,2.011,0.000
14.62,65.200,0.01498,1.966,0.000
14.28,65.300,0.01506,1.921,0.000
13.65,65.400,0.01518,1.836,0.000
11.69,65.500,0.01527,1.573,0.000
8.69,65.600,0.01539,1.169,0.000
8.55,65.700,0.01552,1.151,0.000
8.54,65.800,0.01560,1.149,0.000
8.57,65.900,0.01572,1.152,0.000
8.59,66.000,0.01581,1.156,0.000
8.62,66.100,0.01593,1.160,0.000
8.63,66.200,0.01601,1.161,0.000
8.69,66.300,0.01610,1.169,0.000
8.70,66.400,0.01618,1.171,0.000
8.74,66.500,0.01631,1.175,0.000
8.76,66.600,0.01639,1.179,0.000
8.81,66.700,0.01647,1.185,0.000
8.83,66.800,0.01660,1.188,0.000
8.87,66.900,0.01668,1.193,0.000
8.91,67.000,0.01676,1.199,0.000
8.95,67.100,0.01685,1.204,0.000
8.94,67.200,0.01693,1.203,0.000
9.00,67.300,0.01701,1.211,0.000
9.02,67.400,0.01709,1.214,0.000
9.04,67.500,0.01718,1.217,0.000
9.03,67.600,0.01726,1.215,0.000
9.08,67.700,0.01734,1.221,0.000
9.09,67.800,0.01743,1.223,0.000
9.13,67.900,0.01751,1.228,0.000
9.13,68.000,0.01755,1.228,0.000
9.18,68.100,0.01763,1.234,0.000
9.19,68.200,0.01772,1.236,0.000
9.24,68.300,0.01780,1.243,0.000
9.22,68.400,0.01788,1.240,0.000
9.28,68.500,0.01793,1.248,0.000
9.28,68.600,0.01801,1.248,0.000
9.31,68.700,0.01809,1.253,0.000
9.33,68.800,0.01818,1.255,0.000
9.37,68.900,0.01822,1.260,0.000
9.37,69.000,0.01830,1.261,0.000
9.42,69.100,0.01838,1.267,0.000
9.44,69.200,0.01842,1.270,0.000
9.46,69.300,0.01851,1.273,0.000
9.49,69.400,0.01855,1.277,0.000
9.51,69.500,0.01863,1.279,0.000
9.54,69.600,0.01872,1.284,0.000
9.57,69.700,0.01876,1.288,0.000
9.60,69.800,0.01884,1.292,0.000
9.62,69.900,0.01888,1.295,0.000
9.67,70.000,0.01896,1.300,0.000
9.67,70.100,0.01905,1.301,0.000
9.72,70.200,0.01909,1.308,0.000
9.71,70.300,0.01917,1.307,0.000
9.77,70.400,0.01921,1.315,0.000
9.77,70.500,0.01930,1.315,0.000
9.83,70.600,0.01938,1.323,0.000
9.83,70.700,0.01942,1.322,0.000
9.88,70.800,0.01950,1.329,0.000
9.87,70.900,0.01959,1.327,0.000
9.91,71.000,0.01963,1.334,0.000
9.91,71.100,0.01971,1.333,0.000
9.97,71.200,0.01980,1.341,0.000
9.97,71.300,0.01988,1.341,0.000
10.04,71.400,0.01996,1.350,0.000
10.04,71.500,0.02000,1.350,0.000
10.10,71.600,0.02009,1.359,0.000
10.09,71.700,0.02017,1.358,0.000
10.14,71.800,0.02025,1.364,0.000
10.14,71.900,0.02029,1.364,0.000
10.21,72.000,0.02038,1.373,0.000
10.21,72.100,0.02046,1.374,0.000
10.28,72.200,0.02054,1.382,0.000
10.26,72.300,0.02063,1.381,0.000
10.32,72.400,0.02067,1.389,0.000
10.31,72.500,0.02075,1.387,0.000
10.38,72.600,0.02083,1.397,0.000
10.37,72.700,0.02092,1.395,0.000
10.43,72.800,0.02100,1.404,0.000
10.45,72.900,0.02108,1.405,0.000
10.50,73.000,0.02113,1.413,0.000
10.51,73.100,0.02121,1.415,0.000
10.58,73.200,0.02129,1.423,0.000
10.57,73.300,0.02137,1.423,0.000
10.63,73.400,0.02146,1.430,0.000
10.61,73.500,0.02154,1.428,0.000
10.68,73.600,0.02162,1.438,0.000
10.68,73.700,0.02167,1.437,0.000
10.72,73.800,0.02175,1.442,0.000
10.75,73.900,0.02183,1.446,0.000
10.82,74.000,0.02192,1.456,0.000
10.82,74.100,0.02200,1.455,0.000
10.87,74.200,0.02208,1.463,0.000
10.88,74.300,0.02216,1.463,0.000
10.95,74.400,0.02225,1.474,0.000
10.95,74.500,0.02233,1.473,0.000
11.01,74.600,0.02241,1.482,0.000
11.05,74.700,0.02250,1.486,0.000
11.10,74.800,0.02258,1.494,0.000
11.11,74.900,0.02270,1.495,0.000
11.18,75.000,0.02279,1.505,0.000
11.19,75.100,0.02287,1.505,0.000
11.24,75.200,0.02295,1.512,0.000
11.27,75.300,0.02304,1.516,0.000
11.32,75.400,0.02312,1.523,0.000
11.34,75.500,0.02324,1.526,0.000
11.42,75.600,0.02333,1.537,0.000
11.46,75.700,0.02345,1.541,0.000
11.52,75.800,0.02354,1.549,0.000
11.55,75.900,0.02362,1.554,0.000
11.61,76.000,0.02374,1.562,0.000
11.62,76.100,0.02383,1.563,0.000
11.72,76.200,0.02395,1.577,0.000
11.75,76.300,0.02403,1.581,0.000
11.81,76.400,0.02416,1.590,0.000
11.87,76.500,0.02428,1.597,0.000
11.92,76.600,0.02437,1.604,0.000
11.97,76.700,0.02449,1.611,0.000
12.02,76.800,0.02457,1.617,0.000
12.07,76.900,0.02470,1.624,0.000
12.14,77.000,0.02478,1.633,0.000
12.18,77.100,0.02491,1.638,0.000
12.24,77.200,0.02499,1.647,0.000
12.29,77.300,0.02511,1.654,0.000
12.33,77.400,0.02520,1.659,0.000
12.37,77.500,0.02528,1.664,0.000
12.42,77.600,0.02541,1.671,0.001
12.48,77.700,0.02549,1.679,0.001
12.54,77.800,0.02557,1.687,0.001
12.58,77.900,0.02566,1.693,0.001
12.63,78.000,0.02578,1.699,0.001
12.67,78.100,0.02586,1.705,0.001
12.72,78.200,0.02595,1.711,0.001
12.78,78.300,0.02603,1.719,0.001
12.83,78.400,0.02611,1.726,0.001
12.87,78.500,0.02620,1.731,0.001
12.90,78.600,0.02628,1.735,0.001
12.93,78.700,0.02636,1.739,0.001
12.95,78.800,0.02644,1.743,0.001
12.99,78.900,0.02653,1.747,0.001
13.04,79.000,0.02661,1.755,0.001
13.07,79.100,0.02669,1.759,0.001
13.12,79.200,0.02678,1.765,0.001
13.15,79.300,0.02686,1.769,0.001
13.18,79.400,0.02694,1.773,0.001
13.22,79.500,0.02698,1.778,0.001
13.24,79.600,0.02707,1.781,0.001
13.29,79.700,0.02715,1.789,0.001
13.32,79.800,0.02723,1.792,0.001
13.37,79.900,0.02728,1.799,0.001
13.39,80.000,0.02736,1.802,0.001
13.44,80.100,0.02744,1.808,0.001
13.46,80.200,0.02753,1.811,0.001
13.52,80.300,0.02757,1.819,0.001
13.53,80.400,0.02765,1.821,0.001
13.58,80.500,0.02773,1.828,0.001
13.62,80.600,0.02777,1.833,0.001
13.65,80.700,0.02786,1.836,0.001
13.69,80.800,0.02790,1.842,0.001
13.73,80.900,0.02798,1.847,0.001
13.76,81.000,0.02807,1.851,0.001
13.78,81.100,0.02811,1.855,0.001
13.83,81.200,0.02819,1.860,0.001
13.86,81.300,0.02827,1.865,0.001
13.89,81.400,0.02831,1.869,0.001
13.94,81.500,0.02840,1.876,0.001
13.96,81.600,0.02848,1.878,0.001
14.00,81.700,0.02852,1.884,0.001
14.02,81.800,0.02861,1.887,0.001
14.07,81.900,0.02865,1.893,0.001
14.10,82.000,0.02873,1.897,0.001
14.16,82.100,0.02881,1.905,0.001
14.17,82.200,0.02885,1.906,0.001
14.23,82.300,0.02894,1.914,0.001
14.24,82.400,0.02902,1.916,0.001
14.30,82.500,0.02906,1.924,0.001
14.32,82.600,0.02915,1.927,0.001
14.38,82.700,0.02923,1.934,0.001
14.40,82.800,0.02931,1.937,0.001
14.43,82.900,0.02935,1.941,0.001
14.48,83.000,0.02944,1.947,0.001
14.51,83.100,0.02952,1.952,0.001
14.54,83.200,0.02960,1.957,0.001
14.58,83.300,0.02964,1.961,0.001
14.62,83.400,0.02973,1.967,0.001
14.67,83.500,0.02981,1.974,0.001
14.70,83.600,0.02989,1.977,0.001
14.74,83.700,0.02998,1.983,0.001
14.77,83.800,0.03006,1.987,0.001
14.81,83.900,0.03010,1.992,0.001
14.84,84.000,0.03018,1.996,0.001
14.87,84.100,0.03027,2.001,0.001
14.91,84.200,0.03035,2.006,0.001
14.97,84.300,0.03043,2.014,0.001
15.00,84.400,0.03052,2.018,0.001
15.03,84.500,0.03056,2.022,0.001
15.06,84.600,0.03064,2.026,0.001
15.10,84.700,0.03072,2.031,0.001
15.10,84.800,0.03081,2.031,0.001
15.14,84.900,0.03089,2.037,0.001
15.17,85.000,0.03097,2.041,0.001
15.22,85.100,0.03102,2.047,0.001
15.26,85.200,0.03110,2.053,0.001
15.28,85.300,0.03118,2.056,0.001
15.32,85.400,0.03127,2.061,0.001
15.34,85.500,0.03135,2.064,0.001
15.40,85.600,0.03143,2.072,0.001
15.41,85.700,0.03151,2.073,0.001
15.45,85.800,0.03160,2.079,0.001
15.49,85.900,0.03168,2.084,0.001
15.54,86.000,0.03176,2.090,0.001
15.56,86.100,0.03185,2.094,0.001
15.61,86.200,0.03193,2.100,0.001
15.64,86.300,0.03201,2.104,0.001
15.69,86.400,0.03210,2.111,0.001
15.72,86.500,0.03218,2.115,0.001
15.77,86.600,0.03226,2.121,0.001
15.78,86.700,0.03235,2.123,0.001
15.83,86.800,0.03243,2.130,0.001
15.88,86.900,0.03255,2.137,0.001
15.94,87.000,0.03264,2.145,0.001
15.97,87.100,0.03276,2.149,0.001
16.03,87.200,0.03284,2.157,0.001
16.07,87.300,0.03293,2.162,0.001
16.11,87.400,0.03305,2.167,0.001
16.15,87.500,0.03314,2.173,0.001
16.20,87.600,0.03326,2.180,0.001
16.24,87.700,0.03338,2.185,0.001
16.32,87.800,0.03347,2.196,0.001
16.35,87.900,0.03359,2.199,0.001
16.41,88.000,0.03372,2.208,0.001
16.45,88.100,0.03380,2.214,0.001
16.50,88.200,0.03392,2.219,0.001
16.53,88.300,0.03401,2.224,0.001
16.59,88.400,0.03413,2.232,0.001
16.62,88.500,0.03426,2.236,0.001
16.69,88.600,0.03434,2.246,0.001
16.70,88.700,0.03446,2.247,0.001
16.77,88.800,0.03455,2.257,0.001
16.81,88.900,0.03463,2.262,0.001
16.85,89.000,0.03476,2.267,0.001
16.88,89.100,0.03484,2.271,0.001
16.93,89.200,0.03492,2.278,0.001
16.96,89.300,0.03505,2.282,0.001
17.02,89.400,0.03513,2.289,0.001
17.03,89.500,0.03525,2.291,0.001
17.08,89.600,0.03534,2.298,0.001
17.12,89.700,0.03542,2.304,0.001
17.18,89.800,0.03550,2.311,0.001
17.18,89.900,0.03559,2.312,0.001
17.24,90.000,0.03567,2.319,0.001
17.26,90.100,0.03575,2.322,0.001
17.30,90.200,0.03584,2.328,0.001
17.31,90.300,0.03592,2.329,0.001
17.36,90.400,0.03600,2.336,0.001
17.37,90.500,0.03609,2.337,0.001
17.42,90.600,0.03617,2.344,0.001
17.43,90.700,0.03625,2.345,0.001
17.47,90.800,0.03629,2.351,0.001
17.49,90.900,0.03638,2.353,0.001
17.53,91.000,0.03646,2.359,0.001
17.54,91.100,0.03654,2.360,0.001
17.58,91.200,0.03658,2.366,0.001
17.60,91.300,0.03667,2.368,0.001
17.65,91.400,0.03675,2.375,0.001
17.66,91.500,0.03683,2.376,0.001
17.70,91.600,0.03688,2.382,0.001
17.73,91.700,0.03696,2.385,0.001
17.78,91.800,0.03704,2.392,0.001
17.79,91.900,0.03712,2.393,0.001
17.80,92.000,0.03717,2.395,0.001
17.81,92.100,0.03725,2.396,0.001
17.86,92.200,0.03729,2.402,0.001
17.88,92.300,0.03737,2.406,0.001
17.91,92.400,0.03742,2.410,0.001
17.94,92.500,0.03750,2.413,0.001
17.98,92.600,0.03758,2.418,0.001
17.99,92.700,0.03762,2.421,0.001
18.02,92.800,0.03771,2.424,0.001
18.06,92.900,0.03775,2.429,0.001
18.09,93.000,0.03783,2.433,0.001
18.10,93.100,0.03791,2.436,0.001
18.13,93.200,0.03796,2.439,0.001
18.17,93.300,0.03804,2.445,0.001
18.20,93.400,0.03812,2.448,0.001
18.22,93.500,0.03816,2.451,0.001
18.26,93.600,0.03825,2.456,0.001
18.29,93.700,0.03833,2.461,0.001
18.33,93.800,0.03837,2.466,0.001
18.34,93.900,0.03845,2.468,0.001
18.37,94.000,0.03854,2.471,0.001
18.41,94.100,0.03858,2.477,0.001
18.43,94.200,0.03866,2.479,0.001
18.48,94.300,0.03875,2.487,0.001
18.49,94.400,0.03883,2.488,0.001
18.55,94.500,0.03891,2.495,0.001
18.55,94.600,0.03895,2.496,0.001
18.56,94.700,0.03904,2.496,0.001
18.55,94.800,0.03912,2.496,0.001
18.52,94.900,0.03920,2.492,0.001
18.47,95.000,0.03929,2.484,0.001
18.51,95.100,0.03937,2.490,0.001
18.52,95.200,0.03945,2.492,0.001
18.56,95.300,0.03949,2.497,0.001
18.60,95.400,0.03958,2.503,0.001
18.65,95.500,0.03966,2.509,0.001
18.70,95.600,0.03974,2.515,0.001
18.74,95.700,0.03983,2.522,0.001
18.77,95.800,0.03991,2.526,0.001
18.81,95.900,0.03999,2.531,0.001
18.86,96.000,0.04008,2.537,0.001
18.91,96.100,0.04016,2.544,0.001
18.93,96.200,0.04024,2.547,0.001
18.98,96.300,0.04032,2.553,0.001
19.01,96.400,0.04041,2.558,0.001
19.06,96.500,0.04045,2.564,0.001
19.08,96.600,0.04053,2.567,0.001
19.13,96.700,0.04062,2.573,0.001
19.16,96.800,0.04070,2.578,0.001
19.21,96.900,0.04078,2.584,0.001
19.24,97.000,0.04086,2.589,0.001
19.29,97.100,0.04095,2.595,0.001
19.32,97.200,0.04103,2.599,0.001
19.35,97.300,0.04111,2.604,0.001
19.37,97.400,0.04120,2.606,0.001
19.42,97.500,0.04132,2.613,0.001
19.46,97.600,0.04140,2.618,0.001
19.51,97.700,0.04149,2.624,0.001
19.52,97.800,0.04157,2.626,0.001
19.57,97.900,0.04165,2.633,0.001
19.63,98.000,0.04174,2.640,0.001
19.67,98.100,0.04186,2.647,0.001
19.72,98.200,0.04195,2.653,0.001
19.74,98.300,0.04207,2.656,0.001
19.75,98.400,0.04215,2.657,0.001
19.79,98.500,0.04224,2.663,0.001
19.82,98.600,0.04236,2.666,0.001
19.87,98.700,0.04244,2.674,0.001
19.92,98.800,0.04257,2.680,0.001
19.98,98.900,0.04265,2.688,0.001
20.02,99.000,0.04278,2.693,0.001
20.07,99.100,0.04286,2.700,0.001
20.12,99.200,0.04298,2.707,0.001
20.16,99.300,0.04311,2.713,0.001
20.22,99.400,0.04319,2.720,0.001
20.27,99.500,0.04332,2.727,0.001
20.32,99.600,0.04344,2.733,0.001
20.38,99.700,0.04352,2.741,0.001
20.41,99.800,0.04365,2.746,0.001
20.46,99.900,0.04373,2.753,0.001
20.50,100.000,0.04386,2.758,0.001
20.55,100.100,0.04398,2.765,0.001
20.60,100.200,0.04406,2.772,0.001
20.64,100.300,0.04419,2.777,0.001
20.68,100.400,0.04427,2.782,0.001
20.72,100.500,0.04436,2.788,0.001
20.76,100.600,0.04448,2.793,0.001
20.82,100.700,0.04456,2.801,0.001
20.85,100.800,0.04469,2.806,0.001
20.89,100.900,0.04477,2.810,0.001
20.94,101.000,0.04485,2.817,0.001
20.98,101.100,0.04494,2.822,0.001
21.01,101.200,0.04502,2.827,0.001
21.05,101.300,0.04510,2.832,0.001
21.07,101.400,0.04519,2.835,0.001
21.10,101.500,0.04531,2.839,0.001
21.12,101.600,0.04535,2.842,0.001
21.16,101.700,0.04544,2.847,0.001
21.20,101.800,0.04552,2.853,0.001
21.23,101.900,0.04560,2.856,0.001
21.26,102.000,0.04569,2.861,0.001
21.30,102.100,0.04577,2.866,0.001
21.33,102.200,0.04585,2.869,0.001
21.36,102.300,0.04593,2.874,0.001
21.39,102.400,0.04602,2.878,0.001
21.42,102.500,0.04610,2.882,0.001
21.45,102.600,0.04614,2.886,0.001
21.48,102.700,0.04623,2.889,0.001
21.54,102.800,0.04631,2.898,0.001
21.56,102.900,0.04639,2.900,0.001
21.58,103.000,0.04643,2.903,0.001
21.59,103.100,0.04652,2.905,0.001
21.63,103.200,0.04660,2.910,0.001
21.65,103.300,0.04668,2.912,0.001
21.69,103.400,0.04672,2.918,0.001
21.70,103.500,0.04681,2.920,0.001
21.76,103.600,0.04689,2.927,0.001
21.77,103.700,0.04693,2.928,0.001
21.81,103.800,0.04701,2.934,0.001
21.80,103.900,0.04706,2.934,0.001
21.85,104.000,0.04714,2.940,0.001
21.87,104.100,0.04722,2.942,0.001
21.91,104.200,0.04726,2.948,0.001
21.93,104.300,0.04735,2.951,0.001
21.98,104.400,0.04743,2.957,0.001
22.01,104.500,0.04747,2.961,0.001
22.04,104.600,0.04756,2.965,0.001
22.06,104.700,0.04764,2.968,0.001
22.10,104.800,0.04768,2.973,0.001
22.12,104.900,0.04776,2.976,0.001
22.14,105.000,0.04785,2.979,0.001
22.16,105.100,0.04789,2.982,0.001
22.22,105.200,0.04797,2.989,0.001
22.25,105.300,0.04805,2.994,0.001
22.29,105.400,0.04814,2.999,0.001
22.33,105.500,0.04822,3.004,0.001
22.38,105.600,0.04826,3.011,0.001
22.41,105.700,0.04834,3.014,0.001
22.45,105.800,0.04843,3.020,0.001
22.46,105.900,0.04851,3.022,0.001
22.51,106.000,0.04859,3.029,0.001
22.53,106.100,0.04868,3.032,0.001
22.57,106.200,0.04876,3.037,0.001
22.60,106.300,0.04880,3.040,0.001
22.66,106.400,0.04888,3.048,0.001
22.67,106.500,0.04897,3.050,0.001
22.72,106.600,0.04905,3.057,0.001
22.73,106.700,0.04913,3.057,0.001
22.79,106.800,0.04922,3.066,0.001
22.81,106.900,0.04930,3.069,0.001
22.86,107.000,0.04938,3.076,0.001
22.88,107.100,0.04947,3.078,0.001
22.92,107.200,0.04955,3.083,0.001
22.95,107.300,0.04963,3.088,0.001
23.00,107.400,0.04972,3.095,0.001
23.02,107.500,0.04980,3.098,0.001
23.07,107.600,0.04984,3.103,0.001
23.10,107.700,0.04992,3.108,0.001
23.15,107.800,0.05005,3.115,0.001
23.18,107.900,0.05009,3.119,0.001
23.23,108.000,0.05021,3.125,0.001
23.25,108.100,0.05026,3.127,0.001
23.29,108.200,0.05034,3.134,0.001
23.34,108.300,0.05042,3.140,0.001
23.36,108.400,0.05051,3.143,0.001
23.40,108.500,0.05059,3.148,0.001
23.45,108.600,0.05071,3.155,0.001
23.48,108.700,0.05080,3.159,0.001
23.52,108.800,0.05088,3.164,0.001
23.55,108.900,0.05096,3.168,0.001
23.60,109.000,0.05105,3.174,0.001
23.65,109.100,0.05113,3.181,0.001
23.68,109.200,0.05121,3.186,0.001
23.72,109.300,0.05130,3.191,0.001
23.77,109.400,0.05142,3.198,0.001
23.81,109.500,0.05150,3.203,0.001
23.84,109.600,0.05159,3.208,0.001
23.89,109.700,0.05171,3.214,0.001
23.93,109.800,0.05179,3.220,0.001
23.99,109.900,0.05188,3.228,0.001
24.01,110.000,0.05200,3.231,0.001
24.08,110.100,0.05208,3.239,0.001
24.14,110.200,0.05221,3.247,0.001
24.20,110.300,0.05229,3.256,0.001
24.21,110.400,0.05242,3.258,0.001
24.28,110.500,0.05250,3.266,0.001
24.31,110.600,0.05262,3.270,0.001
24.37,110.700,0.05275,3.278,0.001
24.40,110.800,0.05283,3.283,0.001
24.47,110.900,0.05296,3.292,0.001
24.46,111.000,0.05304,3.291,0.001
24.49,111.100,0.05317,3.295,0.001
24.50,111.200,0.05325,3.297,0.001
24.57,111.300,0.05333,3.306,0.001
24.59,111.400,0.05346,3.308,0.001
24.65,111.500,0.05354,3.316,0.001
24.69,111.600,0.05366,3.322,0.001
24.74,111.700,0.05375,3.329,0.001
24.76,111.800,0.05383,3.332,0.001
24.82,111.900,0.05395,3.339,0.001
24.85,112.000,0.05404,3.344,0.001
24.91,112.100,0.05412,3.352,0.001
24.92,112.200,0.05425,3.353,0.001
24.98,112.300,0.05433,3.360,0.001
25.01,112.400,0.05441,3.364,0.001
25.05,112.500,0.05449,3.370,0.001
25.06,112.600,0.05458,3.371,0.001
25.12,112.700,0.05466,3.380,0.001
25.14,112.800,0.05474,3.382,0.001
25.16,112.900,0.05483,3.386,0.001
25.20,113.000,0.05491,3.390,0.001
25.25,113.100,0.05499,3.397,0.001
25.28,113.200,0.05508,3.401,0.001
25.32,113.300,0.05516,3.407,0.001
25.33,113.400,0.05524,3.408,0.001
25.39,113.500,0.05533,3.415,0.001
25.41,113.600,0.05537,3.418,0.001
25.41,113.700,0.05545,3.419,0.001
25.46,113.800,0.05553,3.425,0.001
25.50,113.900,0.05562,3.431,0.001
25.53,114.000,0.05570,3.435,0.001
25.57,114.100,0.05578,3.440,0.001
25.57,114.200,0.05582,3.441,0.001
25.62,114.300,0.05591,3.447,0.001
25.65,114.400,0.05599,3.451,0.001
25.68,114.500,0.05603,3.455,0.001
25.70,114.600,0.05612,3.458,0.001
25.72,114.700,0.05620,3.461,0.001
25.74,114.800,0.05624,3.463,0.001
25.78,114.900,0.05632,3.468,0.001
25.80,115.000,0.05641,3.472,0.001
25.85,115.100,0.05645,3.477,0.001
25.88,115.200,0.05653,3.481,0.001
7.00,115.300,0.05657,0.942,0.001
8.69,115.400,0.05666,1.169,0.001
8.90,115.500,0.05674,1.197,0.001
8.97,115.600,0.05678,1.207,0.001
9.06,115.700,0.05686,1.218,0.001
9.12,115.800,0.05695,1.227,0.001
9.20,115.900,0.05699,1.238,0.001
9.25,116.000,0.05707,1.245,0.001
9.33,116.100,0.05711,1.255,0.001
9.38,116.200,0.05720,1.261,0.001
9.46,116.300,0.05728,1.272,0.001
9.52,116.400,0.05736,1.281,0.001
9.58,116.500,0.05740,1.288,0.001
9.63,116.600,0.05749,1.295,0.001
9.69,116.700,0.05757,1.304,0.001
9.74,116.800,0.05761,1.310,0.001
9.80,116.900,0.05769,1.318,0.001
9.85,117.000,0.05778,1.325,0.001
9.89,117.100,0.05782,1.331,0.001
9.95,117.200,0.05790,1.338,0.001
9.99,117.300,0.05799,1.344,0.001
10.05,117.400,0.05807,1.352,0.001
10.09,117.500,0.05815,1.357,0.001
10.12,117.600,0.05823,1.361,0.001
10.17,117.700,0.05828,1.368,0.001
10.20,117.800,0.05836,1.372,0.001
10.24,117.900,0.05844,1.378,0.001
10.27,118.000,0.05853,1.382,0.001
10.31,118.100,0.05861,1.387,0.001
10.35,118.200,0.05869,1.392,0.001
10.39,118.300,0.05878,1.398,0.001
10.40,118.310,0.05878,1.399,0.001