File: data-files/CWRU/0900-05-40C.txt
""
"Test Method","Will_Huddleston_Disks.msm"
"Sample I. D.","900-5-40C.mss"
"Specimen Number","1"

"Load (N)","Time (s)","Extension (mm)","Stress (MPa)","Strain (mm/mm)"

5.65,0.200,-0.04783,1.129,-0.001
5.67,0.300,-0.04779,1.133,-0.001
5.64,0.400,-0.04779,1.128,-0.001
5.66,0.500,-0.04779,1.132,-0.001
5.65,0.600,-0.04775,1.130,-0.001
5.66,0.700,-0.04775,1.131,-0.001
5.67,0.800,-0.04775,1.132,-0.001
5.65,0.900,-0.04771,1.130,-0.001
5.65,1.000,-0.04771,1.130,-0.001
5.67,1.100,-0.04767,1.134,-0.001
5.65,1.200,-0.04767,1.130,-0.001
5.66,1.300,-0.04767,1.131,-0.001
5.64,1.400,-0.04763,1.128,-0.001
5.64,1.500,-0.04763,1.127,-0.001
5.65,1.600,-0.04758,1.129,-0.001
5.66,1.700,-0.04754,1.132,-0.001
5.67,1.800,-0.04754,1.134,-0.001
5.66,1.900,-0.04750,1.131,-0.001
5.71,2.000,-0.04742,1.141,-0.001
5.80,2.100,-0.04729,1.159,-0.001
5.91,2.200,-0.04713,1.182,-0.001
6.09,2.300,-0.04692,1.216,-0.001
6.27,2.400,-0.04671,1.253,-0.001
6.44,2.500,-0.04650,1.287,-0.001
6.55,2.600,-0.04630,1.310,-0.001
6.68,2.700,-0.04609,1.336,-0.001
6.76,2.800,-0.04592,1.351,-0.001
6.86,2.900,-0.04571,1.371,-0.001
6.93,3.000,-0.04551,1.384,-0.001
6.97,3.100,-0.04530,1.394,-0.001
7.05,3.200,-0.04513,1.409,-0.001
7.10,3.300,-0.04493,1.419,-0.001
7.15,3.400,-0.04476,1.430,-0.001
7.18,3.500,-0.04459,1.435,-0.001
7.22,3.600,-0.04443,1.443,-0.001
7.26,3.700,-0.04426,1.452,-0.001
7.30,3.800,-0.04409,1.460,-0.001
7.34,3.900,-0.04393,1.467,-0.001
7.37,4.000,-0.04380,1.473,-0.001
7.39,4.100,-0.04364,1.478,-0.001
7.44,4.200,-0.04351,1.488,-0.001
7.46,4.300,-0.04335,1.491,-0.001
7.50,4.400,-0.04322,1.499,-0.001
7.52,4.500,-0.04310,1.503,-0.001
7.53,4.600,-0.04293,1.506,-0.001
7.56,4.700,-0.04281,1.511,-0.001
7.60,4.800,-0.04268,1.519,-0.001
7.63,4.900,-0.04256,1.525,-0.001
7.64,5.000,-0.04239,1.528,-0.001
7.67,5.100,-0.04227,1.534,-0.001
7.70,5.200,-0.04214,1.540,-0.001
7.72,5.300,-0.04202,1.543,-0.001
7.76,5.400,-0.04185,1.551,-0.001
7.78,5.500,-0.04173,1.555,-0.001
7.81,5.600,-0.04160,1.561,-0.001
7.85,5.700,-0.04143,1.569,-0.001
7.88,5.800,-0.04131,1.575,-0.001
7.91,5.900,-0.04119,1.581,-0.001
7.93,6.000,-0.04102,1.585,-0.001
7.98,6.100,-0.04089,1.594,-0.001
7.98,6.200,-0.04073,1.596,-0.001
8.02,6.300,-0.04056,1.602,-0.001
8.04,6.400,-0.04044,1.607,-0.001
8.09,6.500,-0.04027,1.617,-0.001
8.10,6.600,-0.04015,1.619,-0.001
8.13,6.700,-0.03998,1.625,-0.001
8.15,6.800,-0.03986,1.629,-0.001
8.19,6.900,-0.03969,1.637,-0.001
8.21,7.000,-0.03952,1.641,-0.001
8.26,7.100,-0.03940,1.652,-0.001
8.28,7.200,-0.03923,1.655,-0.001
8.30,7.300,-0.03907,1.658,-0.001
8.35,7.400,-0.03890,1.669,-0.001
8.39,7.500,-0.03873,1.677,-0.001
8.41,7.600,-0.03857,1.682,-0.001
8.44,7.700,-0.03836,1.688,-0.001
8.49,7.800,-0.03819,1.697,-0.001
8.52,7.900,-0.03799,1.704,-0.001
8.53,8.000,-0.03778,1.706,-0.001
8.59,8.100,-0.03757,1.717,-0.001
8.63,8.200,-0.03736,1.725,-0.001
8.67,8.300,-0.03715,1.734,-0.001
8.71,8.400,-0.03695,1.741,-0.001
8.74,8.500,-0.03674,1.747,-0.001
8.80,8.600,-0.03653,1.758,-0.001
8.84,8.700,-0.03628,1.767,-0.001
8.84,8.800,-0.03607,1.768,-0.001
8.88,8.900,-0.03587,1.776,-0.001
8.92,9.000,-0.03570,1.784,-0.001
8.97,9.100,-0.03549,1.793,-0.001
8.98,9.200,-0.03533,1.796,-0.001
9.03,9.300,-0.03512,1.804,-0.001
9.04,9.400,-0.03495,1.806,-0.001
9.08,9.500,-0.03479,1.816,-0.001
9.11,9.600,-0.03462,1.821,-0.001
9.12,9.700,-0.03449,1.822,-0.001
9.15,9.800,-0.03433,1.829,-0.001
9.18,9.900,-0.03416,1.834,-0.001
9.19,10.000,-0.03404,1.838,-0.001
9.21,10.100,-0.03391,1.841,-0.001
9.22,10.200,-0.03375,1.843,-0.001
9.26,10.300,-0.03362,1.851,-0.001
9.26,10.400,-0.03350,1.851,-0.001
9.30,10.500,-0.03333,1.859,-0.001
9.31,10.600,-0.03321,1.861,-0.001
9.34,10.700,-0.03308,1.867,-0.001
9.36,10.800,-0.03296,1.871,-0.001
9.39,10.900,-0.03279,1.878,-0.001
9.41,11.000,-0.03267,1.882,-0.001
9.44,11.100,-0.03254,1.887,-0.001
9.46,11.200,-0.03238,1.892,-0.001
9.51,11.300,-0.03225,1.901,-0.001
9.53,11.400,-0.03213,1.905,-0.001
9.57,11.500,-0.03196,1.914,-0.001
9.59,11.600,-0.03179,1.918,-0.001
9.62,11.700,-0.03167,1.924,-0.001
9.65,11.800,-0.03150,1.929,-0.001
9.68,11.900,-0.03138,1.936,-0.001
9.71,12.000,-0.03121,1.942,-0.001
9.73,12.100,-0.03105,1.945,-0.001
9.76,12.200,-0.03092,1.950,-0.001
9.79,12.300,-0.03075,1.957,-0.001
9.83,12.400,-0.03059,1.965,-0.001
9.85,12.500,-0.03046,1.970,-0.001
9.88,12.600,-0.03030,1.975,-0.001
9.92,12.700,-0.03013,1.984,-0.001
9.93,12.800,-0.02997,1.985,-0.001
9.95,12.900,-0.02980,1.990,-0.001
10.01,13.000,-0.02963,2.001,-0.001
10.02,13.100,-0.02947,2.004,-0.001
10.08,13.200,-0.02930,2.015,-0.001
10.10,13.300,-0.02913,2.018,-0.001
10.14,13.400,-0.02897,2.027,-0.001
10.17,13.500,-0.02880,2.033,-0.001
10.20,13.600,-0.02859,2.039,-0.001
10.25,13.700,-0.02839,2.049,-0.001
10.29,13.800,-0.02818,2.057,-0.001
10.33,13.900,-0.02801,2.066,-0.001
10.36,14.000,-0.02780,2.070,-0.001
10.40,14.100,-0.02755,2.079,-0.001
10.46,14.200,-0.02735,2.090,-0.001
10.50,14.300,-0.02714,2.099,-0.001
10.54,14.400,-0.02693,2.106,-0.001
10.56,14.500,-0.02672,2.112,-0.001
10.62,14.600,-0.02656,2.122,-0.001
10.66,14.700,-0.02635,2.130,-0.001
10.69,14.800,-0.02614,2.138,-0.001
10.73,14.900,-0.02593,2.145,-0.001
10.77,15.000,-0.02577,2.154,-0.001
10.80,15.100,-0.02556,2.160,-0.001
10.83,15.200,-0.02539,2.164,0.000
10.85,15.300,-0.02523,2.168,0.000
10.88,15.400,-0.02506,2.176,0.000
10.92,15.500,-0.02494,2.183,0.000
10.93,15.600,-0.02477,2.186,0.000
10.97,15.700,-0.02460,2.194,0.000
10.99,15.800,-0.02448,2.197,0.000
11.00,15.900,-0.02431,2.200,0.000
11.05,16.000,-0.02419,2.210,0.000
11.08,16.100,-0.02406,2.214,0.000
11.11,16.200,-0.02394,2.221,0.000
11.12,16.300,-0.02377,2.223,0.000
11.16,16.400,-0.02365,2.231,0.000
11.18,16.500,-0.02352,2.234,0.000
11.22,16.600,-0.02340,2.243,0.000
11.25,16.700,-0.02323,2.248,0.000
11.26,16.800,-0.02311,2.250,0.000
11.33,16.900,-0.02298,2.264,0.000
11.35,17.000,-0.02282,2.269,0.000
11.37,17.100,-0.02269,2.273,0.000
11.41,17.200,-0.02253,2.281,0.000
11.43,17.300,-0.02240,2.286,0.000
11.47,17.400,-0.02224,2.293,0.000
11.48,17.500,-0.02211,2.296,0.000
11.52,17.600,-0.02194,2.302,0.000
11.55,17.700,-0.02178,2.309,0.000
11.58,17.800,-0.02165,2.316,0.000
11.62,17.900,-0.02149,2.323,0.000
11.65,18.000,-0.02132,2.329,0.000
11.68,18.100,-0.02120,2.334,0.000
11.70,18.200,-0.02103,2.339,0.000
11.75,18.300,-0.02086,2.349,0.000
11.80,18.400,-0.02070,2.358,0.000
11.82,18.500,-0.02057,2.363,0.000
11.86,18.600,-0.02041,2.370,0.000
11.90,18.700,-0.02024,2.379,0.000
11.94,18.800,-0.02007,2.386,0.000
11.97,18.900,-0.01991,2.392,0.000
12.01,19.000,-0.01974,2.400,0.000
12.05,19.100,-0.01958,2.409,0.000
12.07,19.200,-0.01937,2.413,0.000
12.13,19.300,-0.01920,2.424,0.000
12.18,19.400,-0.01899,2.434,0.000
12.21,19.500,-0.01879,2.442,0.000
12.27,19.600,-0.01858,2.452,0.000
12.33,19.700,-0.01837,2.465,0.000
12.37,19.800,-0.01816,2.472,0.000
12.41,19.900,-0.01796,2.482,0.000
12.46,20.000,-0.01775,2.491,0.000
12.51,20.100,-0.01754,2.501,0.000
12.56,20.200,-0.01733,2.512,0.000
12.61,20.300,-0.01712,2.521,0.000
12.65,20.400,-0.01692,2.529,0.000
12.68,20.500,-0.01671,2.535,0.000
12.71,20.600,-0.01654,2.541,0.000
12.76,20.700,-0.01633,2.551,0.000
12.79,20.800,-0.01617,2.556,0.000
12.83,20.900,-0.01600,2.565,0.000
12.85,21.000,-0.01584,2.568,0.000
12.90,21.100,-0.01567,2.579,0.000
12.92,21.200,-0.01550,2.582,0.000
12.95,21.300,-0.01534,2.590,0.000
12.98,21.400,-0.01521,2.595,0.000
13.02,21.500,-0.01505,2.603,0.000
13.04,21.600,-0.01492,2.606,0.000
13.08,21.700,-0.01476,2.615,0.000
13.12,21.800,-0.01463,2.623,0.000
13.13,21.900,-0.01451,2.624,0.000
13.16,22.000,-0.01438,2.631,0.000
13.21,22.100,-0.01422,2.641,0.000
13.24,22.200,-0.01409,2.646,0.000
13.26,22.300,-0.01397,2.650,0.000
13.29,22.400,-0.01384,2.656,0.000
13.33,22.500,-0.01368,2.664,0.000
13.35,22.600,-0.01355,2.669,0.000
13.39,22.700,-0.01343,2.676,0.000
13.42,22.800,-0.01326,2.682,0.000
13.47,22.900,-0.01314,2.692,0.000
13.50,23.000,-0.01297,2.700,0.000
13.54,23.100,-0.01284,2.708,0.000
13.56,23.200,-0.01268,2.710,0.000
13.61,23.300,-0.01255,2.720,0.000
13.64,23.400,-0.01239,2.727,0.000
13.67,23.500,-0.01226,2.734,0.000
13.70,23.600,-0.01210,2.739,0.000
13.74,23.700,-0.01197,2.746,0.000
13.77,23.800,-0.01181,2.753,0.000
13.82,23.900,-0.01164,2.762,0.000
13.85,24.000,-0.01151,2.769,0.000
13.88,24.100,-0.01135,2.775,0.000
13.92,24.200,-0.01122,2.782,0.000
13.95,24.300,-0.01106,2.789,0.000
13.99,24.400,-0.01089,2.796,0.000
14.04,24.500,-0.01072,2.807,0.000
14.08,24.600,-0.01056,2.814,0.000
14.12,24.700,-0.01039,2.822,0.000
14.16,24.800,-0.01023,2.831,0.000
14.21,24.900,-0.01006,2.841,0.000
14.27,25.000,-0.00985,2.853,0.000
14.32,25.100,-0.00964,2.862,0.000
14.38,25.200,-0.00944,2.874,0.000
14.44,25.300,-0.00923,2.887,0.000
14.49,25.400,-0.00902,2.896,0.000
14.55,25.500,-0.00877,2.910,0.000
14.60,25.600,-0.00856,2.919,0.000
14.66,25.700,-0.00836,2.931,0.000
14.72,25.800,-0.00811,2.943,0.000
14.78,25.900,-0.00790,2.954,0.000
14.83,26.000,-0.00769,2.965,0.000
14.87,26.100,-0.00748,2.973,0.000
14.92,26.200,-0.00728,2.983,0.000
14.98,26.300,-0.00707,2.995,0.000
15.02,26.400,-0.00690,3.003,0.000
15.04,26.500,-0.00674,3.006,0.000
15.09,26.600,-0.00657,3.016,0.000
15.13,26.700,-0.00640,3.024,0.000
15.17,26.800,-0.00624,3.032,0.000
15.20,26.900,-0.00607,3.038,0.000
15.22,27.000,-0.00595,3.042,0.000
15.26,27.100,-0.00578,3.050,0.000
15.30,27.200,-0.00565,3.059,0.000
15.32,27.300,-0.00549,3.063,0.000
15.36,27.400,-0.00536,3.071,0.000
15.38,27.500,-0.00524,3.074,0.000
15.42,27.600,-0.00511,3.082,0.000
15.46,27.700,-0.00495,3.091,0.000
15.48,27.800,-0.00482,3.095,0.000
15.50,27.900,-0.00470,3.099,0.000
15.56,28.000,-0.00457,3.110,0.000
15.58,28.100,-0.00441,3.115,0.000
15.63,28.200,-0.00428,3.124,0.000
15.66,28.300,-0.00412,3.130,0.000
15.67,28.400,-0.00399,3.132,0.000
15.71,28.500,-0.00387,3.141,0.000
15.77,28.600,-0.00370,3.153,0.000
15.80,28.700,-0.00358,3.158,0.000
15.84,28.800,-0.00341,3.167,0.000
15.90,28.900,-0.00324,3.179,0.000
15.95,29.000,-0.00312,3.189,0.000
15.98,29.100,-0.00295,3.194,0.000
16.00,29.200,-0.00283,3.199,0.000
16.06,29.300,-0.00266,3.210,0.000
16.11,29.400,-0.00250,3.220,0.000
16.14,29.500,-0.00233,3.226,0.000
16.19,29.600,-0.00216,3.236,0.000
16.22,29.700,-0.00204,3.243,0.000
16.27,29.800,-0.00187,3.253,0.000
16.32,29.900,-0.00171,3.262,0.000
16.36,30.000,-0.00154,3.270,0.000
16.40,30.100,-0.00137,3.277,0.000
16.44,30.200,-0.00121,3.287,0.000
16.50,30.300,-0.00104,3.298,0.000
16.55,30.400,-0.00088,3.307,0.000
16.60,30.500,-0.00067,3.319,0.000
16.67,30.600,-0.00050,3.332,0.000
16.71,30.700,-0.00029,3.341,0.000
16.77,30.800,-0.00009,3.352,0.000
16.84,30.900,0.00012,3.366,0.000
16.90,31.000,0.00033,3.378,0.000
16.97,31.100,0.00054,3.393,0.000
17.03,31.200,0.00079,3.405,0.000
17.11,31.300,0.00099,3.420,0.000
17.14,31.400,0.00120,3.427,0.000
17.19,31.500,0.00141,3.436,0.000
17.27,31.600,0.00162,3.451,0.000
17.33,31.700,0.00183,3.464,0.000
17.35,31.800,0.00203,3.468,0.000
17.41,31.900,0.00224,3.481,0.000
17.45,32.000,0.00241,3.489,0.000
17.52,32.100,0.00261,3.502,0.000
17.56,32.200,0.00278,3.511,0.000
17.60,32.300,0.00295,3.518,0.000
17.62,32.400,0.00311,3.522,0.000
17.67,32.500,0.00328,3.532,0.000
17.70,32.600,0.00345,3.539,0.000
17.75,32.700,0.00361,3.548,0.000
17.79,32.800,0.00374,3.555,0.000
17.81,32.900,0.00390,3.561,0.000
17.86,33.000,0.00403,3.570,0.000
17.89,33.100,0.00419,3.576,0.000
17.93,33.200,0.00432,3.584,0.000
17.95,33.300,0.00444,3.587,0.000
17.99,33.400,0.00461,3.597,0.000
18.03,33.500,0.00473,3.605,0.000
18.07,33.600,0.00486,3.613,0.000
18.11,33.700,0.00498,3.620,0.000
18.13,33.800,0.00515,3.624,0.000
18.21,33.900,0.00527,3.641,0.000
18.23,34.000,0.00544,3.645,0.000
18.27,34.100,0.00557,3.653,0.000
18.32,34.200,0.00573,3.663,0.000
18.36,34.300,0.00586,3.670,0.000
18.44,34.400,0.00602,3.685,0.000
18.47,34.500,0.00615,3.692,0.000
18.49,34.600,0.00631,3.696,0.000
18.56,34.700,0.00644,3.711,0.000
18.60,34.800,0.00660,3.718,0.000
18.64,34.900,0.00677,3.725,0.000
18.68,35.000,0.00689,3.735,0.000
18.73,35.100,0.00706,3.745,0.000
18.80,35.200,0.00723,3.758,0.000
18.84,35.300,0.00739,3.767,0.000
18.89,35.400,0.00756,3.776,0.000
18.95,35.500,0.00768,3.788,0.000
19.00,35.600,0.00785,3.798,0.000
19.05,35.700,0.00802,3.808,0.000
19.09,35.800,0.00818,3.817,0.000
19.14,35.900,0.00835,3.826,0.000
19.19,36.000,0.00852,3.837,0.000
19.27,36.100,0.00872,3.852,0.000
19.32,36.200,0.00889,3.863,0.000
19.39,36.300,0.00910,3.875,0.000
19.46,36.400,0.00926,3.891,0.000
19.51,36.500,0.00947,3.899,0.000
19.56,36.600,0.00968,3.910,0.000
19.65,36.700,0.00989,3.928,0.000
19.71,36.800,0.01009,3.940,0.000
19.78,36.900,0.01030,3.955,0.000
19.84,37.000,0.01051,3.966,0.000
19.92,37.100,0.01072,3.983,0.000
19.97,37.200,0.01093,3.993,0.000
20.04,37.300,0.01113,4.005,0.000
20.08,37.400,0.01134,4.015,0.000
20.15,37.500,0.01155,4.028,0.000
20.20,37.600,0.01172,4.038,0.000
20.28,37.700,0.01192,4.055,0.000
20.32,37.800,0.01209,4.062,0.000
20.36,37.900,0.01230,4.071,0.000
20.41,38.000,0.01246,4.080,0.000
20.48,38.100,0.01263,4.094,0.000
20.51,38.200,0.01275,4.099,0.000
20.57,38.300,0.01292,4.113,0.000
20.59,38.400,0.01309,4.116,0.000
20.68,38.500,0.01321,4.134,0.000
20.71,38.600,0.01338,4.140,0.000
20.77,38.700,0.01354,4.151,0.000
20.78,38.800,0.01367,4.153,0.000
20.84,38.900,0.01379,4.165,0.000
20.88,39.000,0.01396,4.174,0.000
20.93,39.100,0.01408,4.184,0.000
20.96,39.200,0.01421,4.191,0.000
21.01,39.300,0.01437,4.201,0.000
21.05,39.400,0.01450,4.208,0.000
21.12,39.500,0.01462,4.222,0.000
21.15,39.600,0.01479,4.228,0.000
21.20,39.700,0.01492,4.239,0.000
21.26,39.800,0.01508,4.249,0.000
21.31,39.900,0.01521,4.260,0.000
21.36,40.000,0.01537,4.269,0.000
21.39,40.100,0.01550,4.276,0.000
21.46,40.200,0.01566,4.290,0.000
21.53,40.300,0.01579,4.304,0.000
21.57,40.400,0.01595,4.312,0.000
21.62,40.500,0.01612,4.321,0.000
21.69,40.600,0.01624,4.335,0.000
21.75,40.700,0.01641,4.347,0.000
21.79,40.800,0.01658,4.356,0.000
21.85,40.900,0.01674,4.368,0.000
21.90,41.000,0.01687,4.379,0.000
21.96,41.100,0.01703,4.389,0.000
22.01,41.200,0.01720,4.399,0.000
22.09,41.300,0.01737,4.415,0.000
22.14,41.400,0.01753,4.425,0.000
22.20,41.500,0.01770,4.437,0.000
22.23,41.600,0.01787,4.444,0.000
22.31,41.700,0.01803,4.459,0.000
22.37,41.800,0.01820,4.471,0.000
22.45,41.900,0.01841,4.488,0.000
22.51,42.000,0.01857,4.500,0.000
22.60,42.100,0.01878,4.517,0.000
22.66,42.200,0.01899,4.529,0.000
22.73,42.300,0.01920,4.545,0.000
22.83,42.400,0.01940,4.563,0.000
22.91,42.500,0.01965,4.580,0.000
23.00,42.600,0.01986,4.597,0.000
23.08,42.700,0.02007,4.613,0.000
23.14,42.800,0.02028,4.625,0.000
23.23,42.900,0.02048,4.643,0.000
23.30,43.000,0.02069,4.658,0.000
23.38,43.100,0.02090,4.673,0.000
23.44,43.200,0.02111,4.685,0.000
23.50,43.300,0.02131,4.698,0.000
23.59,43.400,0.02148,4.716,0.000
23.64,43.500,0.02169,4.725,0.000
23.69,43.600,0.02185,4.736,0.000
23.75,43.700,0.02202,4.747,0.000
23.80,43.800,0.02219,4.759,0.000
23.85,43.900,0.02235,4.768,0.000
23.90,44.000,0.02248,4.778,0.000
23.96,44.100,0.02260,4.790,0.000
23.99,44.200,0.02277,4.795,0.000
24.05,44.300,0.02294,4.808,0.000
24.10,44.400,0.02306,4.817,0.000
24.17,44.500,0.02318,4.831,0.000
24.20,44.600,0.02331,4.838,0.000
24.25,44.700,0.02348,4.848,0.000
24.31,44.800,0.02360,4.859,0.000
24.35,44.900,0.02373,4.867,0.000
24.38,45.000,0.02385,4.875,0.000
24.46,45.100,0.02402,4.890,0.000
24.51,45.200,0.02414,4.900,0.000
24.59,45.300,0.02431,4.915,0.000
24.64,45.400,0.02443,4.926,0.000
24.71,45.500,0.02460,4.940,0.000
24.74,45.600,0.02472,4.946,0.000
24.80,45.700,0.02489,4.958,0.000
24.87,45.800,0.02501,4.971,0.000
24.95,45.900,0.02518,4.987,0.000
24.99,46.000,0.02535,4.996,0.000
25.06,46.100,0.02547,5.010,0.001
25.11,46.200,0.02564,5.020,0.001
25.17,46.300,0.02580,5.031,0.001
25.22,46.400,0.02593,5.042,0.001
25.28,46.500,0.02609,5.054,0.001
25.34,46.600,0.02626,5.066,0.001
25.42,46.700,0.02643,5.082,0.001
25.47,46.800,0.02655,5.091,0.001
25.54,46.900,0.02672,5.105,0.001
25.59,47.000,0.02688,5.116,0.001
25.67,47.100,0.02705,5.131,0.001
25.73,47.200,0.02722,5.144,0.001
25.82,47.300,0.02738,5.162,0.001
25.87,47.400,0.02755,5.171,0.001
25.96,47.500,0.02776,5.190,0.001
26.03,47.600,0.02792,5.204,0.001
26.13,47.700,0.02813,5.224,0.001
26.23,47.800,0.02834,5.243,0.001
26.31,47.900,0.02855,5.259,0.001
26.39,48.000,0.02875,5.276,0.001
26.51,48.100,0.02896,5.299,0.001
26.60,48.200,0.02921,5.318,0.001
26.68,48.300,0.02942,5.333,0.001
26.77,48.400,0.02963,5.351,0.001
26.86,48.500,0.02988,5.370,0.001
26.95,48.600,0.03008,5.387,0.001
27.03,48.700,0.03029,5.404,0.001
27.12,48.800,0.03050,5.421,0.001
27.22,48.900,0.03066,5.441,0.001
27.28,49.000,0.03087,5.453,0.001
27.33,49.100,0.03108,5.464,0.001
27.39,49.200,0.03125,5.475,0.001
27.46,49.300,0.03141,5.490,0.001
27.55,49.400,0.03158,5.506,0.001
27.60,49.500,0.03175,5.518,0.001
27.65,49.600,0.03187,5.528,0.001
27.71,49.700,0.03204,5.539,0.001
27.75,49.800,0.03220,5.546,0.001
27.81,49.900,0.03233,5.560,0.001
27.86,50.000,0.03249,5.570,0.001
27.92,50.100,0.03262,5.581,0.001
27.97,50.200,0.03274,5.592,0.001
28.03,50.300,0.03287,5.603,0.001
28.07,50.400,0.03303,5.611,0.001
28.13,50.500,0.03316,5.624,0.001
28.19,50.600,0.03328,5.635,0.001
28.25,50.700,0.03345,5.648,0.001
28.30,50.800,0.03357,5.657,0.001
28.36,50.900,0.03370,5.669,0.001
28.42,51.000,0.03386,5.682,0.001
28.50,51.100,0.03399,5.698,0.001
28.57,51.200,0.03416,5.711,0.001
28.62,51.300,0.03428,5.722,0.001
28.69,51.400,0.03445,5.736,0.001
28.78,51.500,0.03461,5.754,0.001
28.83,51.600,0.03474,5.762,0.001
28.89,51.700,0.03490,5.775,0.001
28.95,51.800,0.03507,5.788,0.001
29.03,51.900,0.03519,5.803,0.001
29.09,52.000,0.03536,5.815,0.001
29.17,52.100,0.03553,5.830,0.001
29.22,52.200,0.03565,5.841,0.001
29.28,52.300,0.03582,5.853,0.001
29.33,52.400,0.03598,5.862,0.001
29.41,52.500,0.03611,5.879,0.001
29.48,52.600,0.03627,5.893,0.001
29.55,52.700,0.03644,5.907,0.001
29.62,52.800,0.03661,5.922,0.001
29.69,52.900,0.03677,5.936,0.001
29.79,53.000,0.03694,5.955,0.001
29.88,53.100,0.03711,5.973,0.001
29.93,53.200,0.03731,5.984,0.001
30.04,53.300,0.03748,6.005,0.001
30.13,53.400,0.03769,6.024,0.001
30.22,53.500,0.03790,6.040,0.001
30.31,53.600,0.03806,6.059,0.001
30.43,53.700,0.03831,6.083,0.001
30.52,53.800,0.03852,6.101,0.001
30.62,53.900,0.03873,6.120,0.001
30.71,54.000,0.03893,6.140,0.001
30.81,54.100,0.03914,6.159,0.001
30.89,54.200,0.03935,6.176,0.001
30.97,54.300,0.03956,6.192,0.001
31.09,54.400,0.03977,6.214,0.001
31.15,54.500,0.03997,6.228,0.001
31.23,54.600,0.04014,6.244,0.001
31.32,54.700,0.04035,6.261,0.001
31.39,54.800,0.04051,6.276,0.001
31.47,54.900,0.04068,6.290,0.001
31.52,55.000,0.04085,6.301,0.001
31.56,55.100,0.04101,6.309,0.001
31.65,55.200,0.04118,6.327,0.001
31.71,55.300,0.04134,6.339,0.001
31.75,55.400,0.04147,6.348,0.001
31.82,55.500,0.04164,6.361,0.001
31.88,55.600,0.04176,6.373,0.001
31.94,55.700,0.04193,6.385,0.001
32.02,55.800,0.04205,6.401,0.001
32.06,55.900,0.04222,6.408,0.001
32.11,56.000,0.04234,6.420,0.001
32.17,56.100,0.04247,6.432,0.001
32.25,56.200,0.04259,6.448,0.001
32.28,56.300,0.04276,6.454,0.001
32.35,56.400,0.04288,6.467,0.001
32.41,56.500,0.04301,6.478,0.001
32.48,56.600,0.04313,6.492,0.001
32.54,56.700,0.04330,6.504,0.001
32.61,56.800,0.04342,6.519,0.001
32.69,56.900,0.04355,6.535,0.001
32.74,57.000,0.04371,6.545,0.001
32.82,57.100,0.04384,6.560,0.001
32.87,57.200,0.04400,6.570,0.001
32.97,57.300,0.04413,6.590,0.001
33.02,57.400,0.04430,6.601,0.001
33.08,57.500,0.04442,6.612,0.001
33.17,57.600,0.04459,6.631,0.001
33.22,57.700,0.04471,6.641,0.001
33.30,57.800,0.04488,6.657,0.001
33.38,57.900,0.04504,6.673,0.001
33.46,58.000,0.04517,6.688,0.001
33.52,58.100,0.04533,6.701,0.001
33.61,58.200,0.04550,6.718,0.001
33.68,58.300,0.04562,6.732,0.001
33.76,58.400,0.04579,6.749,0.001
33.83,58.500,0.04596,6.763,0.001
33.91,58.600,0.04612,6.779,0.001
34.00,58.700,0.04629,6.797,0.001
34.08,58.800,0.04646,6.814,0.001
34.16,58.900,0.04662,6.830,0.001
34.28,59.000,0.04679,6.853,0.001
34.36,59.100,0.04700,6.869,0.001
34.47,59.200,0.04720,6.891,0.001
34.58,59.300,0.04741,6.912,0.001
34.67,59.400,0.04762,6.931,0.001
34.77,59.500,0.04783,6.951,0.001
34.90,59.600,0.04804,6.976,0.001
34.97,59.700,0.04824,6.991,0.001
35.08,59.800,0.04845,7.013,0.001
35.19,59.900,0.04866,7.035,0.001
35.30,60.000,0.04887,7.056,0.001
35.39,60.100,0.04907,7.075,0.001
35.51,60.200,0.04928,7.098,0.001
35.58,60.300,0.04949,7.113,0.001
35.67,60.400,0.04966,7.130,0.001
35.74,60.500,0.04986,7.145,0.001
35.83,60.600,0.05003,7.162,0.001
35.90,60.700,0.05020,7.177,0.001
35.98,60.800,0.05036,7.193,0.001
36.04,60.900,0.05053,7.204,0.001
36.12,61.000,0.05069,7.221,0.001
36.17,61.100,0.05086,7.230,0.001
36.24,61.200,0.05099,7.244,0.001
36.29,61.300,0.05115,7.254,0.001
36.37,61.400,0.05128,7.271,0.001
36.44,61.500,0.05144,7.285,0.001
36.50,61.600,0.05157,7.297,0.001
36.57,61.700,0.05169,7.311,0.001
36.64,61.800,0.05182,7.324,0.001
36.68,61.900,0.05198,7.332,0.001
36.73,62.000,0.05211,7.343,0.001
36.81,62.100,0.05223,7.358,0.001
36.87,62.200,0.05236,7.370,0.001
36.97,62.300,0.05252,7.390,0.001
37.03,62.400,0.05265,7.402,0.001
37.10,62.500,0.05277,7.417,0.001
37.17,62.600,0.05294,7.431,0.001
37.24,62.700,0.05306,7.445,0.001
37.34,62.800,0.05323,7.464,0.001
37.42,62.900,0.05335,7.480,0.001
37.49,63.000,0.05352,7.495,0.001
37.57,63.100,0.05369,7.511,0.001
37.65,63.200,0.05381,7.526,0.001
37.75,63.300,0.05398,7.546,0.001
37.80,63.400,0.05414,7.557,0.001
37.90,63.500,0.05431,7.577,0.001
37.98,63.600,0.05448,7.592,0.001
38.07,63.700,0.05460,7.611,0.001
38.14,63.800,0.05477,7.624,0.001
38.25,63.900,0.05493,7.646,0.001
38.30,64.000,0.05510,7.656,0.001
38.42,64.100,0.05527,7.680,0.001
38.48,64.200,0.05543,7.692,0.001
38.58,64.300,0.05560,7.712,0.001
38.64,64.400,0.05576,7.725,0.001
38.77,64.500,0.05597,7.751,0.001
38.85,64.600,0.05614,7.767,0.001
38.96,64.700,0.05630,7.789,0.001
39.07,64.800,0.05651,7.810,0.001
39.18,64.900,0.05672,7.831,0.001
39.26,65.000,0.05693,7.848,0.001
39.41,65.100,0.05714,7.878,0.001
39.52,65.200,0.05734,7.900,0.001
39.65,65.300,0.05759,7.927,0.001
39.75,65.400,0.05780,7.947,0.001
39.88,65.500,0.05801,7.972,0.001
39.97,65.600,0.05826,7.990,0.001
40.09,65.700,0.05847,8.014,0.001
40.18,65.800,0.05867,8.031,0.001
40.29,65.900,0.05884,8.053,0.001
40.38,66.000,0.05905,8.071,0.001
40.50,66.100,0.05926,8.096,0.001
40.57,66.200,0.05942,8.111,0.001
40.65,66.300,0.05963,8.126,0.001
40.74,66.400,0.05980,8.144,0.001
40.83,66.500,0.05996,8.162,0.001
40.88,66.600,0.06013,8.173,0.001
40.95,66.700,0.06025,8.186,0.001
41.04,66.800,0.06042,8.204,0.001
41.11,66.900,0.06054,8.219,0.001
41.18,67.000,0.06071,8.232,0.001
41.24,67.100,0.06083,8.244,0.001
41.33,67.200,0.06100,8.262,0.001
41.38,67.300,0.06113,8.273,0.001
41.47,67.400,0.06125,8.290,0.001
41.53,67.500,0.06142,8.302,0.001
41.62,67.600,0.06154,8.320,0.001
41.66,67.700,0.06167,8.328,0.001
41.75,67.800,0.06183,8.346,0.001
41.83,67.900,0.06196,8.361,0.001
41.91,68.000,0.06208,8.378,0.001
42.00,68.100,0.06225,8.395,0.001
42.08,68.200,0.06237,8.411,0.001
42.15,68.300,0.06254,8.425,0.001
42.24,68.400,0.06270,8.444,0.001
42.34,68.500,0.06283,8.463,0.001
42.42,68.600,0.06300,8.480,0.001
42.49,68.700,0.06316,8.494,0.001
42.61,68.800,0.06329,8.517,0.001
42.68,68.900,0.06345,8.532,0.001
42.78,69.000,0.06362,8.552,0.001
42.85,69.100,0.06378,8.567,0.001
42.94,69.200,0.06391,8.584,0.001
43.01,69.300,0.06408,8.598,0.001
43.13,69.400,0.06424,8.621,0.001
43.21,69.500,0.06441,8.637,0.001
43.29,69.600,0.06457,8.654,0.001
43.39,69.700,0.06474,8.674,0.001
43.49,69.800,0.06491,8.694,0.001
43.58,69.900,0.06507,8.711,0.001
43.67,70.000,0.06524,8.730,0.001
43.77,70.100,0.06541,8.751,0.001
43.90,70.200,0.06561,8.776,0.001
44.00,70.300,0.06578,8.796,0.001
44.10,70.400,0.06599,8.817,0.001
44.24,70.500,0.06615,8.844,0.001
44.36,70.600,0.06636,8.868,0.001
44.46,70.700,0.06657,8.889,0.001
44.60,70.800,0.06682,8.916,0.001
44.70,70.900,0.06703,8.936,0.001
44.86,71.000,0.06723,8.968,0.001
44.94,71.100,0.06744,8.984,0.001
45.09,71.200,0.06765,9.013,0.001
45.18,71.300,0.06786,9.031,0.001
45.31,71.400,0.06807,9.057,0.001
45.40,71.500,0.06827,9.076,0.001
45.50,71.600,0.06848,9.095,0.001
45.60,71.700,0.06865,9.115,0.001
45.69,71.800,0.06885,9.134,0.001
45.77,71.900,0.06902,9.150,0.001
45.85,72.000,0.06919,9.165,0.001
45.91,72.100,0.06935,9.177,0.001
46.01,72.200,0.06952,9.197,0.001
46.07,72.300,0.06969,9.210,0.001
46.14,72.400,0.06981,9.223,0.001
46.21,72.500,0.06998,9.238,0.001
46.29,72.600,0.07014,9.254,0.001
46.36,72.700,0.07027,9.268,0.001
46.43,72.800,0.07043,9.281,0.001
46.49,72.900,0.07056,9.295,0.001
46.55,73.000,0.07068,9.306,0.001
46.63,73.100,0.07085,9.323,0.001
46.69,73.200,0.07097,9.334,0.001
46.75,73.300,0.07110,9.346,0.001
46.84,73.400,0.07122,9.363,0.001
46.90,73.500,0.07139,9.376,0.001
46.98,73.600,0.07151,9.391,0.001
47.05,73.700,0.07164,9.405,0.001
47.13,73.800,0.07181,9.421,0.001
47.21,73.900,0.07193,9.438,0.001
47.29,74.000,0.07210,9.453,0.001
47.37,74.100,0.07222,9.470,0.001
47.44,74.200,0.07235,9.483,0.001
47.54,74.300,0.07251,9.504,0.001
47.60,74.400,0.07268,9.516,0.001
47.71,74.500,0.07280,9.537,0.001
47.78,74.600,0.07297,9.551,0.001
47.89,74.700,0.07309,9.573,0.001
47.96,74.800,0.07326,9.587,0.001
48.05,74.900,0.07343,9.606,0.001
48.13,75.000,0.07355,9.622,0.001
48.24,75.100,0.07372,9.643,0.001
48.32,75.200,0.07388,9.660,0.001
48.43,75.300,0.07405,9.681,0.001
48.53,75.400,0.07417,9.701,0.001
48.62,75.500,0.07434,9.718,0.001
48.72,75.600,0.07451,9.739,0.001
48.84,75.700,0.07467,9.764,0.001
48.91,75.800,0.07484,9.778,0.001
49.04,75.900,0.07505,9.802,0.001
49.16,76.000,0.07521,9.828,0.001
49.30,76.100,0.07542,9.855,0.001
49.42,76.200,0.07563,9.879,0.001
49.55,76.300,0.07584,9.905,0.001
49.69,76.400,0.07604,9.932,0.001
49.84,76.500,0.07625,9.963,0.002
49.98,76.600,0.07650,9.990,0.002
50.12,76.700,0.07671,10.019,0.002
50.23,76.800,0.07692,10.041,0.002
50.34,76.900,0.07712,10.064,0.002
50.46,77.000,0.07733,10.087,0.002
50.60,77.100,0.07754,10.116,0.002
50.70,77.200,0.07775,10.136,0.002
50.81,77.300,0.07796,10.157,0.002
50.91,77.400,0.07812,10.177,0.002
50.98,77.500,0.07833,10.192,0.002
51.06,77.600,0.07850,10.208,0.002
51.16,77.700,0.07866,10.228,0.002
51.22,77.800,0.07883,10.239,0.002
51.28,77.900,0.07895,10.250,0.002
51.37,78.000,0.07912,10.269,0.002
51.41,78.100,0.07924,10.276,0.002
51.49,78.200,0.07941,10.293,0.002
51.55,78.300,0.07953,10.305,0.002
51.62,78.400,0.07970,10.319,0.002
51.68,78.500,0.07983,10.330,0.002
51.78,78.600,0.07995,10.350,0.002
51.83,78.700,0.08012,10.362,0.002
51.91,78.800,0.08024,10.377,0.002
51.97,78.900,0.08037,10.389,0.002
52.05,79.000,0.08049,10.405,0.002
52.12,79.100,0.08061,10.419,0.002
52.22,79.200,0.08078,10.438,0.002
52.27,79.300,0.08091,10.449,0.002
52.37,79.400,0.08103,10.468,0.002
52.42,79.500,0.08120,10.480,0.002
52.56,79.600,0.08132,10.506,0.002
52.62,79.700,0.08149,10.519,0.002
52.72,79.800,0.08161,10.540,0.002
52.81,79.900,0.08178,10.557,0.002
52.91,80.000,0.08190,10.577,0.002
53.00,80.100,0.08207,10.594,0.002
53.08,80.200,0.08219,10.611,0.002
53.18,80.300,0.08236,10.631,0.002
53.29,80.400,0.08253,10.653,0.002
53.36,80.500,0.08265,10.666,0.002
53.47,80.600,0.08282,10.689,0.002
53.55,80.700,0.08298,10.706,0.002
53.68,80.800,0.08311,10.731,0.002
53.77,80.900,0.08327,10.748,0.002
53.86,81.000,0.08344,10.767,0.002
53.96,81.100,0.08361,10.787,0.002
54.07,81.200,0.08377,10.809,0.002
54.16,81.300,0.08394,10.828,0.002
54.30,81.400,0.08411,10.854,0.002
54.38,81.500,0.08427,10.870,0.002
54.51,81.600,0.08444,10.897,0.002
54.64,81.700,0.08465,10.923,0.002
54.78,81.800,0.08485,10.952,0.002
54.92,81.900,0.08506,10.978,0.002
55.06,82.000,0.08527,11.006,0.002
55.20,82.100,0.08548,11.035,0.002
55.35,82.200,0.08568,11.065,0.002
55.51,82.300,0.08589,11.096,0.002
55.63,82.400,0.08614,11.120,0.002
55.77,82.500,0.08635,11.149,0.002
55.90,82.600,0.08656,11.176,0.002
56.02,82.700,0.08677,11.199,0.002
56.12,82.800,0.08697,11.219,0.002
56.21,82.900,0.08718,11.236,0.002
56.32,83.000,0.08735,11.260,0.002
56.42,83.100,0.08755,11.279,0.002
56.53,83.200,0.08772,11.301,0.002
56.61,83.300,0.08789,11.317,0.002
56.69,83.400,0.08810,11.332,0.002
56.80,83.500,0.08822,11.354,0.002
56.85,83.600,0.08839,11.365,0.002
56.94,83.700,0.08855,11.382,0.002
57.00,83.800,0.08872,11.394,0.002
57.09,83.900,0.08884,11.412,0.002
57.15,84.000,0.08901,11.424,0.002
57.22,84.100,0.08913,11.439,0.002
57.28,84.200,0.08926,11.451,0.002
57.35,84.300,0.08942,11.464,0.002
57.41,84.400,0.08955,11.477,0.002
57.48,84.500,0.08967,11.490,0.002
57.55,84.600,0.08984,11.504,0.002
57.62,84.700,0.08997,11.519,0.002
57.70,84.800,0.09009,11.535,0.002
57.77,84.900,0.09021,11.549,0.002
57.85,85.000,0.09038,11.565,0.002
57.93,85.100,0.09051,11.580,0.002
57.99,85.200,0.09063,11.593,0.002
58.10,85.300,0.09080,11.615,0.002
58.18,85.400,0.09092,11.631,0.002
58.28,85.500,0.09109,11.651,0.002
58.37,85.600,0.09121,11.669,0.002
58.47,85.700,0.09138,11.689,0.002
58.55,85.800,0.09150,11.704,0.002
58.65,85.900,0.09167,11.725,0.002
58.74,86.000,0.09179,11.742,0.002
58.85,86.100,0.09196,11.765,0.002
58.94,86.200,0.09213,11.783,0.002
59.06,86.300,0.09225,11.807,0.002
59.13,86.400,0.09242,11.821,0.002
59.27,86.500,0.09258,11.849,0.002
59.32,86.600,0.09275,11.858,0.002
59.45,86.700,0.09292,11.885,0.002
59.53,86.800,0.09304,11.900,0.002
59.66,86.900,0.09321,11.926,0.002
59.76,87.000,0.09337,11.946,0.002
59.88,87.100,0.09354,11.971,0.002
59.98,87.200,0.09371,11.990,0.002
60.09,87.300,0.09391,12.013,0.002
60.21,87.400,0.09408,12.037,0.002
60.34,87.500,0.09425,12.062,0.002
60.46,87.600,0.09445,12.086,0.002
60.59,87.700,0.09466,12.111,0.002
60.72,87.800,0.09487,12.138,0.002
60.88,87.900,0.09508,12.169,0.002
60.99,88.000,0.09528,12.193,0.002
61.16,88.100,0.09549,12.226,0.002
61.26,88.200,0.09570,12.246,0.002
61.42,88.300,0.09591,12.278,0.002
61.53,88.400,0.09612,12.300,0.002
61.67,88.500,0.09632,12.328,0.002
61.77,88.600,0.09653,12.349,0.002
61.90,88.700,0.09670,12.374,0.002
62.03,88.800,0.09690,12.399,0.002
62.15,88.900,0.09711,12.424,0.002
62.25,89.000,0.09728,12.443,0.002
62.35,89.100,0.09745,12.464,0.002
62.43,89.200,0.09761,12.481,0.002
62.52,89.300,0.09778,12.499,0.002
62.59,89.400,0.09794,12.513,0.002
62.65,89.500,0.09811,12.524,0.002
62.73,89.600,0.09823,12.539,0.002
62.83,89.700,0.09840,12.560,0.002
62.91,89.800,0.09853,12.576,0.002
62.98,89.900,0.09869,12.590,0.002
63.05,90.000,0.09882,12.603,0.002
63.12,90.100,0.09894,12.619,0.002
63.19,90.200,0.09911,12.632,0.002
63.27,90.300,0.09923,12.649,0.002
63.36,90.400,0.09936,12.665,0.002
63.44,90.500,0.09948,12.682,0.002
63.53,90.600,0.09965,12.700,0.002
63.61,90.700,0.09977,12.716,0.002
63.69,90.800,0.09990,12.732,0.002
63.79,90.900,0.10002,12.752,0.002
63.86,91.000,0.10019,12.766,0.002
63.95,91.100,0.10031,12.785,0.002
64.04,91.200,0.10048,12.802,0.002
64.13,91.300,0.10060,12.820,0.002
64.22,91.400,0.10077,12.838,0.002
64.32,91.500,0.10089,12.857,0.002
64.42,91.600,0.10106,12.878,0.002
64.51,91.700,0.10119,12.895,0.002
64.64,91.800,0.10135,12.922,0.002
64.72,91.900,0.10152,12.938,0.002
64.82,92.000,0.10164,12.957,0.002
64.93,92.100,0.10181,12.979,0.002
65.04,92.200,0.10197,13.002,0.002
65.13,92.300,0.10214,13.020,0.002
65.24,92.400,0.10227,13.042,0.002
65.35,92.500,0.10243,13.063,0.002
65.45,92.600,0.10260,13.084,0.002
65.55,92.700,0.10276,13.104,0.002
65.64,92.800,0.10293,13.122,0.002
65.77,92.900,0.10310,13.147,0.002
65.88,93.000,0.10326,13.170,0.002
66.02,93.100,0.10347,13.198,0.002
66.15,93.200,0.10364,13.224,0.002
66.30,93.300,0.10384,13.253,0.002
66.44,93.400,0.10405,13.282,0.002
66.62,93.500,0.10426,13.317,0.002
66.75,93.600,0.10447,13.344,0.002
66.92,93.700,0.10468,13.377,0.002
67.03,93.800,0.10488,13.401,0.002
67.21,93.900,0.10509,13.435,0.002
67.32,94.000,0.10530,13.458,0.002
67.46,94.100,0.10555,13.486,0.002
67.59,94.200,0.10576,13.512,0.002
67.71,94.300,0.10592,13.535,0.002
67.82,94.400,0.10613,13.557,0.002
67.94,94.500,0.10634,13.582,0.002
68.05,94.600,0.10655,13.603,0.002
68.16,94.700,0.10671,13.625,0.002
68.24,94.800,0.10688,13.642,0.002
68.34,94.900,0.10704,13.662,0.002
68.45,95.000,0.10721,13.683,0.002
68.54,95.100,0.10738,13.701,0.002
68.60,95.200,0.10754,13.714,0.002
68.66,95.300,0.10767,13.726,0.002
68.75,95.400,0.10783,13.743,0.002
68.83,95.500,0.10796,13.759,0.002
68.92,95.600,0.10808,13.778,0.002
69.00,95.700,0.10825,13.794,0.002
69.08,95.800,0.10837,13.809,0.002
69.15,95.900,0.10850,13.823,0.002
69.24,96.000,0.10867,13.841,0.002
69.31,96.100,0.10879,13.856,0.002
69.41,96.200,0.10891,13.875,0.002
69.51,96.300,0.10904,13.895,0.002
69.61,96.400,0.10921,13.915,0.002
69.71,96.500,0.10933,13.935,0.002
69.81,96.600,0.10950,13.956,0.002
69.91,96.700,0.10962,13.974,0.002
70.02,96.800,0.10979,13.998,0.002
70.13,96.900,0.10991,14.020,0.002
70.20,97.000,0.11008,14.034,0.002
70.31,97.100,0.11020,14.056,0.002
70.45,97.200,0.11037,14.083,0.002
70.52,97.300,0.11054,14.098,0.002
70.64,97.400,0.11066,14.121,0.002
70.73,97.500,0.11083,14.139,0.002
70.83,97.600,0.11099,14.158,0.002
70.95,97.700,0.11116,14.184,0.002
71.04,97.800,0.11128,14.202,0.002
71.15,97.900,0.11145,14.223,0.002
71.25,98.000,0.11162,14.242,0.002
71.35,98.100,0.11178,14.264,0.002
71.49,98.200,0.11195,14.292,0.002
71.59,98.300,0.11211,14.312,0.002
71.72,98.400,0.11228,14.337,0.002
71.83,98.500,0.11245,14.359,0.002
71.97,98.600,0.11261,14.387,0.002
72.10,98.700,0.11282,14.413,0.002
72.26,98.800,0.11299,14.446,0.002
72.39,98.900,0.11319,14.471,0.002
72.56,99.000,0.11340,14.504,0.002
72.70,99.100,0.11361,14.533,0.002
72.85,99.200,0.11382,14.563,0.002
73.04,99.300,0.11403,14.600,0.002
73.18,99.400,0.11428,14.629,0.002
73.34,99.500,0.11448,14.660,0.002
73.50,99.600,0.11473,14.694,0.002
73.66,99.700,0.11494,14.725,0.002
73.79,99.800,0.11515,14.750,0.002
73.90,99.900,0.11536,14.773,0.002
74.04,100.000,0.11556,14.801,0.002
74.17,100.100,0.11577,14.827,0.002
74.28,100.200,0.11598,14.848,0.002
74.35,100.300,0.11615,14.863,0.002
74.46,100.400,0.11635,14.886,0.002
74.55,100.500,0.11652,14.903,0.002
74.65,100.600,0.11669,14.923,0.002
74.70,100.700,0.11685,14.933,0.002
74.78,100.800,0.11698,14.948,0.002
74.85,100.900,0.11714,14.962,0.002
74.94,101.000,0.11731,14.981,0.002
75.00,101.100,0.11743,14.993,0.002
75.09,101.200,0.11760,15.011,0.002
75.16,101.300,0.11772,15.024,0.002
75.24,101.400,0.11785,15.041,0.002
75.32,101.500,0.11802,15.056,0.002
75.40,101.600,0.11814,15.072,0.002
75.45,101.700,0.11826,15.084,0.002
75.54,101.800,0.11843,15.101,0.002
75.62,101.900,0.11856,15.116,0.002
75.70,102.000,0.11868,15.133,0.002
75.76,102.100,0.11885,15.146,0.002
75.87,102.200,0.11897,15.166,0.002
75.91,102.300,0.11914,15.175,0.002
76.04,102.400,0.11926,15.201,0.002
76.12,102.500,0.11943,15.216,0.002
76.21,102.600,0.11959,15.235,0.002
76.29,102.700,0.11972,15.251,0.002
76.40,102.800,0.11989,15.273,0.002
76.46,102.900,0.12005,15.284,0.002
76.58,103.000,0.12018,15.309,0.002
76.66,103.100,0.12034,15.325,0.002
76.79,103.200,0.12051,15.350,0.002
76.85,103.300,0.12067,15.364,0.002
76.98,103.400,0.12080,15.388,0.002
77.04,103.500,0.12097,15.401,0.002
77.17,103.600,0.12113,15.427,0.002
77.23,103.700,0.12130,15.438,0.002
77.37,103.800,0.12146,15.467,0.002
77.45,103.900,0.12163,15.482,0.002
77.59,104.000,0.12180,15.510,0.002
77.66,104.100,0.12196,15.524,0.002
77.79,104.200,0.12213,15.550,0.002
77.89,104.300,0.12234,15.571,0.002
78.06,104.400,0.12250,15.604,0.002
78.17,104.500,0.12271,15.626,0.002
78.34,104.600,0.12292,15.661,0.002
78.47,104.700,0.12313,15.686,0.002
78.62,104.800,0.12333,15.717,0.002
78.76,104.900,0.12354,15.744,0.002
78.92,105.000,0.12375,15.777,0.002
79.06,105.100,0.12396,15.804,0.002
79.23,105.200,0.12421,15.838,0.002
79.35,105.300,0.12441,15.862,0.002
79.48,105.400,0.12462,15.888,0.002
79.60,105.500,0.12483,15.912,0.002
79.74,105.600,0.12500,15.941,0.002
79.85,105.700,0.12520,15.962,0.002
79.96,105.800,0.12537,15.984,0.002
80.05,105.900,0.12558,16.003,0.002
80.00,106.000,0.12574,15.993,0.002
61.31,106.100,0.12591,12.256,0.002
62.11,106.200,0.12612,12.416,0.002
62.29,106.300,0.12624,12.452,0.002
62.40,106.400,0.12641,12.475,0.002
62.51,106.500,0.12658,12.495,0.002
62.59,106.600,0.12670,12.511,0.002
62.67,106.700,0.12687,12.529,0.002
62.77,106.800,0.12699,12.548,0.002
62.83,106.900,0.12716,12.561,0.003
62.92,107.000,0.12728,12.578,0.003
62.98,107.100,0.12741,12.590,0.003
63.04,107.200,0.12757,12.603,0.003
63.12,107.300,0.12770,12.618,0.003
63.18,107.400,0.12782,12.630,0.003
63.27,107.500,0.12795,12.648,0.003
63.32,107.600,0.12807,12.657,0.003
63.37,107.700,0.12824,12.668,0.003
63.45,107.800,0.12836,12.684,0.003
63.51,107.900,0.12849,12.697,0.003
63.58,108.000,0.12865,12.710,0.003
57.77,108.100,0.12878,11.549,0.003
33.40,108.200,0.12894,6.676,0.003
33.07,108.300,0.12907,6.612,0.003
33.28,108.400,0.12924,6.653,0.003
33.50,108.500,0.12936,6.697,0.003
33.70,108.600,0.12953,6.737,0.003
33.91,108.700,0.12969,6.779,0.003
34.11,108.800,0.12982,6.818,0.003
34.27,108.900,0.12998,6.852,0.003
34.44,109.000,0.13015,6.884,0.003
34.63,109.100,0.13032,6.922,0.003
34.79,109.200,0.13044,6.955,0.003
34.95,109.300,0.13061,6.987,0.003
35.06,109.400,0.13077,7.008,0.003
35.17,109.500,0.13094,7.030,0.003
35.30,109.600,0.13111,7.057,0.003
35.43,109.700,0.13127,7.083,0.003
35.55,109.800,0.13144,7.107,0.003
35.66,109.900,0.13160,7.129,0.003
35.76,110.000,0.13177,7.148,0.003
35.89,110.100,0.13198,7.174,0.003
36.01,110.200,0.13214,7.199,0.003
36.14,110.300,0.13235,7.224,0.003
36.25,110.400,0.13256,7.247,0.003
36.38,110.500,0.13277,7.273,0.003
36.49,110.600,0.13298,7.295,0.003
36.60,110.700,0.13318,7.317,0.003
36.70,110.800,0.13339,7.337,0.003
36.82,110.900,0.13364,7.360,0.003
36.90,111.000,0.13385,7.377,0.003
37.00,111.100,0.13401,7.397,0.003
37.07,111.200,0.13422,7.411,0.003
37.15,111.300,0.13443,7.427,0.003
37.24,111.400,0.13460,7.445,0.003
37.31,111.500,0.13480,7.458,0.003
37.36,111.600,0.13497,7.469,0.003
37.42,111.700,0.13514,7.481,0.003
37.46,111.800,0.13530,7.489,0.003
37.53,111.900,0.13547,7.502,0.003
30.21,112.000,0.13563,6.039,0.003
7.43,112.050,0.13572,1.485,0.003