File: data-files/CWRU/0900-05-50B.txt
""
"Test Method","Will_Huddleston_Disks.msm"
"Sample I. D.","600-5-50B.mss"
"Specimen Number","1"

"Load (N)","Time (s)","Extension (mm)","Stress (MPa)","Strain (mm/mm)"

2.88,0.200,-0.26216,0.283,-0.005
2.88,0.400,-0.26216,0.283,-0.005
2.88,0.600,-0.26212,0.282,-0.005
2.86,0.800,-0.26212,0.281,-0.005
2.86,1.000,-0.26208,0.281,-0.005
2.87,1.200,-0.26204,0.281,-0.005
2.85,1.400,-0.26204,0.280,-0.005
2.84,1.600,-0.26200,0.279,-0.005
2.87,1.800,-0.26196,0.282,-0.005
2.88,2.000,-0.26191,0.282,-0.005
2.90,2.200,-0.26183,0.284,-0.005
3.04,2.400,-0.26158,0.299,-0.005
3.24,2.600,-0.26129,0.317,-0.005
3.34,2.800,-0.26100,0.328,-0.005
3.43,3.000,-0.26071,0.336,-0.005
3.53,3.200,-0.26042,0.346,-0.005
3.60,3.400,-0.26013,0.353,-0.005
3.65,3.600,-0.25984,0.358,-0.005
3.75,3.800,-0.25950,0.368,-0.005
3.80,4.000,-0.25913,0.373,-0.005
3.91,4.200,-0.25880,0.383,-0.005
3.98,4.400,-0.25838,0.391,-0.005
4.08,4.600,-0.25797,0.400,-0.005
4.17,4.800,-0.25755,0.409,-0.005
4.25,5.000,-0.25713,0.417,-0.005
4.29,5.200,-0.25676,0.421,-0.005
4.38,5.400,-0.25639,0.429,-0.005
4.44,5.600,-0.25601,0.435,-0.005
4.48,5.800,-0.25568,0.440,-0.005
4.54,6.000,-0.25535,0.446,-0.005
4.60,6.200,-0.25506,0.451,-0.005
4.62,6.400,-0.25477,0.453,-0.005
4.67,6.600,-0.25448,0.458,-0.005
4.70,6.800,-0.25418,0.461,-0.005
4.76,7.000,-0.25394,0.467,-0.005
4.80,7.200,-0.25364,0.470,-0.005
4.82,7.400,-0.25339,0.473,-0.005
4.88,7.600,-0.25310,0.479,-0.005
4.94,7.800,-0.25281,0.484,-0.005
4.97,8.000,-0.25252,0.487,-0.005
4.99,8.200,-0.25223,0.489,-0.005
5.01,8.400,-0.25194,0.492,-0.005
5.07,8.600,-0.25165,0.497,-0.005
5.09,8.800,-0.25136,0.499,-0.005
5.11,9.000,-0.25103,0.502,-0.005
5.14,9.200,-0.25074,0.504,-0.005
5.17,9.400,-0.25040,0.507,-0.005
5.20,9.600,-0.25007,0.510,-0.005
5.23,9.800,-0.24970,0.513,-0.005
5.30,10.000,-0.24928,0.520,-0.005
5.35,10.200,-0.24887,0.524,-0.005
5.36,10.400,-0.24845,0.526,-0.005
5.42,10.600,-0.24799,0.532,-0.005
5.47,10.800,-0.24758,0.537,-0.005
5.51,11.000,-0.24716,0.540,-0.005
5.57,11.200,-0.24675,0.546,-0.005
5.60,11.400,-0.24641,0.550,-0.005
5.62,11.600,-0.24604,0.551,-0.005
5.68,11.800,-0.24575,0.557,-0.005
5.71,12.000,-0.24542,0.560,-0.005
5.74,12.200,-0.24517,0.563,-0.005
5.78,12.400,-0.24488,0.567,-0.005
5.82,12.600,-0.24459,0.571,-0.005
5.85,12.800,-0.24434,0.574,-0.005
5.89,13.000,-0.24404,0.577,-0.005
5.93,13.200,-0.24380,0.581,-0.005
5.97,13.400,-0.24350,0.585,-0.005
6.00,13.600,-0.24317,0.588,-0.005
6.03,13.800,-0.24288,0.591,-0.005
6.08,14.000,-0.24259,0.596,-0.005
6.10,14.200,-0.24230,0.598,-0.005
6.13,14.400,-0.24197,0.602,-0.005
6.16,14.600,-0.24163,0.604,-0.005
6.20,14.800,-0.24134,0.608,-0.005
6.22,15.000,-0.24101,0.610,-0.005
6.27,15.200,-0.24064,0.615,-0.005
6.30,15.400,-0.24030,0.618,-0.005
6.34,15.600,-0.23993,0.621,-0.005
6.38,15.800,-0.23952,0.626,-0.005
6.44,16.000,-0.23906,0.632,-0.005
6.50,16.200,-0.23864,0.637,-0.005
6.55,16.400,-0.23823,0.642,-0.005
6.62,16.600,-0.23781,0.649,-0.005
6.66,16.800,-0.23740,0.653,-0.005
6.71,17.000,-0.23702,0.658,-0.005
6.73,17.200,-0.23669,0.660,-0.005
6.77,17.400,-0.23636,0.664,-0.005
6.83,17.600,-0.23607,0.670,-0.005
6.85,17.800,-0.23573,0.671,-0.005
6.90,18.000,-0.23544,0.676,-0.005
6.90,18.200,-0.23519,0.677,-0.005
6.95,18.400,-0.23490,0.682,-0.005
6.99,18.600,-0.23461,0.685,-0.005
7.04,18.800,-0.23432,0.690,-0.005
7.06,19.000,-0.23407,0.692,-0.005
7.12,19.200,-0.23374,0.698,-0.005
7.15,19.400,-0.23345,0.701,-0.005
7.18,19.600,-0.23312,0.704,-0.005
7.22,19.800,-0.23282,0.708,-0.005
7.27,20.000,-0.23249,0.713,-0.005
7.29,20.200,-0.23220,0.715,-0.005
7.32,20.400,-0.23187,0.718,-0.005
7.37,20.600,-0.23158,0.723,-0.005
7.41,20.800,-0.23120,0.727,-0.005
7.46,21.000,-0.23087,0.731,-0.005
7.50,21.200,-0.23046,0.736,-0.005
7.58,21.400,-0.23008,0.743,-0.005
7.63,21.600,-0.22967,0.748,-0.005
7.69,21.800,-0.22921,0.754,-0.005
7.74,22.000,-0.22879,0.759,-0.005
7.80,22.200,-0.22838,0.765,-0.004
7.85,22.400,-0.22800,0.769,-0.004
7.90,22.600,-0.22763,0.774,-0.004
7.94,22.800,-0.22726,0.778,-0.004
7.98,23.000,-0.22692,0.783,-0.004
8.02,23.200,-0.22663,0.786,-0.004
8.04,23.400,-0.22634,0.788,-0.004
8.08,23.600,-0.22605,0.792,-0.004
8.12,23.800,-0.22576,0.797,-0.004
8.16,24.000,-0.22551,0.800,-0.004
8.18,24.200,-0.22522,0.802,-0.004
8.23,24.400,-0.22497,0.807,-0.004
8.26,24.600,-0.22468,0.810,-0.004
8.30,24.800,-0.22439,0.814,-0.004
8.34,25.000,-0.22410,0.818,-0.004
8.40,25.200,-0.22377,0.824,-0.004
8.44,25.400,-0.22347,0.828,-0.004
8.48,25.600,-0.22314,0.832,-0.004
8.53,25.800,-0.22285,0.837,-0.004
8.57,26.000,-0.22252,0.841,-0.004
8.63,26.200,-0.22223,0.846,-0.004
8.67,26.400,-0.22190,0.850,-0.004
8.72,26.600,-0.22156,0.855,-0.004
8.79,26.800,-0.22119,0.862,-0.004
8.86,27.000,-0.22077,0.869,-0.004
8.92,27.200,-0.22036,0.875,-0.004
8.99,27.400,-0.21990,0.882,-0.004
9.06,27.600,-0.21949,0.889,-0.004
9.11,27.800,-0.21907,0.894,-0.004
9.20,28.000,-0.21865,0.902,-0.004
9.24,28.200,-0.21828,0.906,-0.004
9.26,28.400,-0.21795,0.908,-0.004
9.32,28.600,-0.21762,0.914,-0.004
9.35,28.800,-0.21732,0.917,-0.004
9.39,29.000,-0.21703,0.921,-0.004
9.44,29.200,-0.21674,0.926,-0.004
9.49,29.400,-0.21645,0.931,-0.004
9.50,29.600,-0.21620,0.931,-0.004
9.56,29.800,-0.21595,0.937,-0.004
9.59,30.000,-0.21566,0.941,-0.004
9.63,30.200,-0.21537,0.944,-0.004
9.71,30.400,-0.21512,0.952,-0.004
9.74,30.600,-0.21483,0.955,-0.004
9.80,30.800,-0.21450,0.961,-0.004
9.85,31.000,-0.21421,0.966,-0.004
9.91,31.200,-0.21392,0.972,-0.004
9.96,31.400,-0.21363,0.977,-0.004
10.01,31.600,-0.21329,0.981,-0.004
10.06,31.800,-0.21296,0.987,-0.004
10.13,32.000,-0.21267,0.993,-0.004
10.19,32.200,-0.21234,0.999,-0.004
10.23,32.400,-0.21196,1.003,-0.004
10.32,32.600,-0.21159,1.012,-0.004
10.40,32.800,-0.21117,1.020,-0.004
10.47,33.000,-0.21076,1.027,-0.004
10.58,33.200,-0.21030,1.038,-0.004
10.64,33.400,-0.20989,1.044,-0.004
10.70,33.600,-0.20947,1.050,-0.004
10.78,33.800,-0.20905,1.057,-0.004
10.82,34.000,-0.20868,1.062,-0.004
10.88,34.200,-0.20835,1.067,-0.004
10.92,34.400,-0.20802,1.071,-0.004
10.98,34.600,-0.20773,1.077,-0.004
11.01,34.800,-0.20743,1.080,-0.004
11.07,35.000,-0.20714,1.086,-0.004
11.12,35.200,-0.20685,1.090,-0.004
11.17,35.400,-0.20660,1.095,-0.004
11.23,35.600,-0.20631,1.101,-0.004
11.27,35.800,-0.20606,1.106,-0.004
11.33,36.000,-0.20577,1.111,-0.004
11.39,36.200,-0.20548,1.117,-0.004
11.45,36.400,-0.20519,1.123,-0.004
11.51,36.600,-0.20490,1.129,-0.004
11.58,36.800,-0.20461,1.136,-0.004
11.66,37.000,-0.20428,1.143,-0.004
11.70,37.200,-0.20398,1.147,-0.004
11.76,37.400,-0.20365,1.153,-0.004
11.84,37.600,-0.20336,1.161,-0.004
11.90,37.800,-0.20303,1.167,-0.004
11.97,38.000,-0.20266,1.173,-0.004
12.07,38.200,-0.20232,1.183,-0.004
12.14,38.400,-0.20195,1.190,-0.004
12.21,38.600,-0.20153,1.197,-0.004
12.32,38.800,-0.20112,1.208,-0.004
12.40,39.000,-0.20070,1.216,-0.004
12.48,39.200,-0.20029,1.224,-0.004
12.56,39.400,-0.19987,1.231,-0.004
12.64,39.600,-0.19950,1.240,-0.004
12.69,39.800,-0.19912,1.245,-0.004
12.75,40.000,-0.19879,1.251,-0.004
12.81,40.200,-0.19846,1.256,-0.004
12.86,40.400,-0.19817,1.262,-0.004
12.94,40.600,-0.19788,1.269,-0.004
12.99,40.800,-0.19759,1.274,-0.004
13.05,41.000,-0.19734,1.280,-0.004
13.08,41.200,-0.19705,1.283,-0.004
13.14,41.400,-0.19680,1.289,-0.004
13.22,41.600,-0.19650,1.296,-0.004
13.28,41.800,-0.19626,1.302,-0.004
13.34,42.000,-0.19592,1.309,-0.004
13.40,42.200,-0.19567,1.314,-0.004
13.48,42.400,-0.19538,1.322,-0.004
13.54,42.600,-0.19505,1.328,-0.004
13.63,42.800,-0.19476,1.336,-0.004
13.69,43.000,-0.19443,1.342,-0.004
13.77,43.200,-0.19414,1.350,-0.004
13.84,43.400,-0.19380,1.357,-0.004
13.91,43.600,-0.19347,1.364,-0.004
14.00,43.800,-0.19314,1.373,-0.004
14.09,44.000,-0.19276,1.382,-0.004
14.19,44.200,-0.19239,1.392,-0.004
14.28,44.400,-0.19198,1.400,-0.004
14.36,44.600,-0.19152,1.408,-0.004
14.47,44.800,-0.19110,1.419,-0.004
14.57,45.000,-0.19069,1.429,-0.004
14.65,45.200,-0.19027,1.437,-0.004
14.73,45.400,-0.18990,1.445,-0.004
14.79,45.600,-0.18952,1.451,-0.004
14.87,45.800,-0.18919,1.459,-0.004
14.93,46.000,-0.18890,1.464,-0.004
14.99,46.200,-0.18861,1.471,-0.004
15.06,46.400,-0.18832,1.477,-0.004
15.12,46.600,-0.18807,1.483,-0.004
15.17,46.800,-0.18778,1.488,-0.004
15.23,47.000,-0.18753,1.493,-0.004
15.30,47.200,-0.18724,1.501,-0.004
15.39,47.400,-0.18695,1.509,-0.004
15.46,47.600,-0.18666,1.517,-0.004
15.54,47.800,-0.18637,1.524,-0.004
15.60,48.000,-0.18607,1.530,-0.004
15.68,48.200,-0.18578,1.538,-0.004
15.76,48.400,-0.18545,1.545,-0.004
15.85,48.600,-0.18512,1.554,-0.004
15.91,48.800,-0.18483,1.560,-0.004
16.00,49.000,-0.18450,1.569,-0.004
16.08,49.200,-0.18416,1.577,-0.004
16.18,49.400,-0.18379,1.586,-0.004
16.31,49.600,-0.18341,1.599,-0.004
16.41,49.800,-0.18304,1.610,-0.004
16.53,50.000,-0.18263,1.621,-0.004
16.65,50.200,-0.18217,1.633,-0.004
16.77,50.400,-0.18171,1.645,-0.004
16.89,50.600,-0.18130,1.656,-0.004
17.00,50.800,-0.18088,1.667,-0.004
17.08,51.000,-0.18051,1.675,-0.004
17.18,51.200,-0.18013,1.684,-0.004
17.25,51.400,-0.17976,1.692,-0.004
17.34,51.600,-0.17947,1.700,-0.004
17.40,51.800,-0.17913,1.706,-0.004
17.49,52.000,-0.17884,1.715,-0.004
17.56,52.200,-0.17859,1.722,-0.004
17.65,52.400,-0.17830,1.731,-0.004
17.70,52.600,-0.17801,1.735,-0.004
17.78,52.800,-0.17776,1.744,-0.003
17.85,53.000,-0.17747,1.750,-0.003
17.95,53.200,-0.17718,1.761,-0.003
18.02,53.400,-0.17689,1.768,-0.003
18.13,53.600,-0.17656,1.778,-0.003
18.21,53.800,-0.17627,1.786,-0.003
18.30,54.000,-0.17593,1.795,-0.003
18.39,54.200,-0.17564,1.803,-0.003
18.48,54.400,-0.17531,1.812,-0.003
18.58,54.600,-0.17498,1.822,-0.003
18.67,54.800,-0.17465,1.831,-0.003
18.79,55.000,-0.17431,1.843,-0.003
18.90,55.200,-0.17394,1.854,-0.003
19.05,55.400,-0.17357,1.868,-0.003
19.18,55.600,-0.17311,1.881,-0.003
19.32,55.800,-0.17269,1.895,-0.003
19.44,56.000,-0.17224,1.906,-0.003
19.57,56.200,-0.17182,1.919,-0.003
19.68,56.400,-0.17145,1.930,-0.003
19.78,56.600,-0.17103,1.940,-0.003
19.89,56.800,-0.17070,1.950,-0.003
19.96,57.000,-0.17037,1.958,-0.003
20.07,57.200,-0.17003,1.968,-0.003
20.13,57.400,-0.16974,1.974,-0.003
20.21,57.600,-0.16945,1.982,-0.003
20.30,57.800,-0.16916,1.991,-0.003
20.35,58.000,-0.16887,1.996,-0.003
20.43,58.200,-0.16862,2.004,-0.003
20.52,58.400,-0.16833,2.012,-0.003
20.61,58.600,-0.16808,2.021,-0.003
20.69,58.800,-0.16779,2.029,-0.003
20.81,59.000,-0.16750,2.040,-0.003
20.90,59.200,-0.16721,2.049,-0.003
21.03,59.400,-0.16692,2.062,-0.003
21.11,59.600,-0.16658,2.070,-0.003
21.21,59.800,-0.16629,2.080,-0.003
21.34,60.000,-0.16596,2.093,-0.003
21.43,60.200,-0.16567,2.101,-0.003
21.53,60.400,-0.16534,2.112,-0.003
21.64,60.600,-0.16501,2.122,-0.003
21.76,60.800,-0.16467,2.134,-0.003
21.90,61.000,-0.16426,2.148,-0.003
22.08,61.200,-0.16388,2.165,-0.003
22.20,61.400,-0.16343,2.177,-0.003
22.36,61.600,-0.16301,2.193,-0.003
22.51,61.800,-0.16255,2.207,-0.003
22.62,62.000,-0.16218,2.218,-0.003
22.77,62.200,-0.16176,2.233,-0.003
22.86,62.400,-0.16139,2.242,-0.003
22.97,62.600,-0.16106,2.253,-0.003
23.08,62.800,-0.16073,2.263,-0.003
23.18,63.000,-0.16043,2.273,-0.003
23.24,63.200,-0.16014,2.279,-0.003
23.35,63.400,-0.15985,2.290,-0.003
23.41,63.600,-0.15960,2.296,-0.003
23.50,63.800,-0.15931,2.305,-0.003
23.58,64.000,-0.15906,2.312,-0.003
23.67,64.200,-0.15877,2.321,-0.003
23.78,64.400,-0.15852,2.332,-0.003
23.89,64.600,-0.15823,2.343,-0.003
24.00,64.800,-0.15794,2.353,-0.003
24.09,65.000,-0.15761,2.362,-0.003
24.22,65.200,-0.15732,2.375,-0.003
24.33,65.400,-0.15703,2.386,-0.003
24.46,65.600,-0.15669,2.398,-0.003
24.58,65.800,-0.15636,2.410,-0.003
24.68,66.000,-0.15607,2.421,-0.003
24.82,66.200,-0.15574,2.434,-0.003
24.94,66.400,-0.15536,2.446,-0.003
25.10,66.600,-0.15499,2.461,-0.003
25.27,66.800,-0.15462,2.478,-0.003
25.43,67.000,-0.15420,2.494,-0.003
25.62,67.200,-0.15374,2.512,-0.003
25.79,67.400,-0.15329,2.530,-0.003
25.93,67.600,-0.15287,2.543,-0.003
26.09,67.800,-0.15246,2.558,-0.003
26.22,68.000,-0.15208,2.571,-0.003
26.38,68.200,-0.15171,2.587,-0.003
26.50,68.400,-0.15138,2.599,-0.003
26.62,68.600,-0.15104,2.610,-0.003
26.73,68.800,-0.15075,2.622,-0.003
26.82,69.000,-0.15046,2.630,-0.003
26.94,69.200,-0.15017,2.642,-0.003
27.04,69.400,-0.14992,2.652,-0.003
27.16,69.600,-0.14963,2.663,-0.003
27.25,69.800,-0.14938,2.672,-0.003
27.39,70.000,-0.14909,2.686,-0.003
27.53,70.200,-0.14880,2.700,-0.003
27.64,70.400,-0.14851,2.710,-0.003
27.78,70.600,-0.14822,2.724,-0.003
27.88,70.800,-0.14788,2.734,-0.003
28.00,71.000,-0.14759,2.746,-0.003
28.14,71.200,-0.14730,2.759,-0.003
28.26,71.400,-0.14697,2.772,-0.003
28.39,71.600,-0.14668,2.784,-0.003
28.53,71.800,-0.14635,2.798,-0.003
28.71,72.000,-0.14601,2.815,-0.003
28.83,72.200,-0.14564,2.827,-0.003
29.01,72.400,-0.14527,2.845,-0.003
29.21,72.600,-0.14485,2.864,-0.003
29.41,72.800,-0.14444,2.885,-0.003
29.62,73.000,-0.14398,2.904,-0.003
29.78,73.200,-0.14356,2.921,-0.003
29.96,73.400,-0.14315,2.938,-0.003
30.11,73.600,-0.14277,2.953,-0.003
30.29,73.800,-0.14240,2.970,-0.003
30.41,74.000,-0.14207,2.982,-0.003
30.54,74.200,-0.14173,2.995,-0.003
30.65,74.400,-0.14144,3.006,-0.003
30.79,74.600,-0.14115,3.020,-0.003
30.89,74.800,-0.14086,3.030,-0.003
31.01,75.000,-0.14061,3.041,-0.003
31.12,75.200,-0.14032,3.052,-0.003
31.26,75.400,-0.14007,3.065,-0.003
31.37,75.600,-0.13978,3.076,-0.003
31.50,75.800,-0.13949,3.089,-0.003
31.63,76.000,-0.13924,3.102,-0.003
31.75,76.200,-0.13895,3.114,-0.003
31.92,76.400,-0.13862,3.130,-0.003
32.06,76.600,-0.13833,3.144,-0.003
32.20,76.800,-0.13799,3.158,-0.003
32.33,77.000,-0.13770,3.170,-0.003
32.49,77.200,-0.13737,3.186,-0.003
32.62,77.400,-0.13704,3.199,-0.003
32.80,77.600,-0.13671,3.217,-0.003
32.98,77.800,-0.13637,3.234,-0.003
33.18,78.000,-0.13596,3.254,-0.003
33.38,78.200,-0.13558,3.274,-0.003
33.62,78.400,-0.13513,3.297,-0.003
33.83,78.600,-0.13471,3.318,-0.003
34.06,78.800,-0.13425,3.340,-0.003
34.25,79.000,-0.13384,3.359,-0.003
34.42,79.200,-0.13346,3.376,-0.003
34.58,79.400,-0.13305,3.391,-0.003
34.73,79.600,-0.13272,3.406,-0.003
34.87,79.800,-0.13243,3.420,-0.003
34.99,80.000,-0.13209,3.432,-0.003
35.14,80.200,-0.13180,3.446,-0.003
35.24,80.400,-0.13155,3.455,-0.003
35.38,80.600,-0.13126,3.470,-0.003
35.50,80.800,-0.13101,3.481,-0.003
35.65,81.000,-0.13072,3.496,-0.003
35.79,81.200,-0.13043,3.510,-0.003
35.93,81.400,-0.13018,3.523,-0.003
36.10,81.600,-0.12989,3.540,-0.003
36.24,81.800,-0.12956,3.554,-0.003
36.41,82.000,-0.12927,3.570,-0.003
36.57,82.200,-0.12894,3.587,-0.003
36.75,82.400,-0.12864,3.604,-0.003
36.91,82.600,-0.12831,3.620,-0.003
37.10,82.800,-0.12798,3.638,-0.003
37.26,83.000,-0.12769,3.654,-0.003
37.43,83.200,-0.12731,3.670,-0.003
37.64,83.400,-0.12698,3.692,-0.002
37.87,83.600,-0.12661,3.714,-0.002
38.11,83.800,-0.12619,3.737,-0.002
38.36,84.000,-0.12574,3.762,-0.002
38.63,84.200,-0.12528,3.788,-0.002
38.86,84.400,-0.12486,3.811,-0.002
39.09,84.600,-0.12445,3.833,-0.002
39.29,84.800,-0.12403,3.853,-0.002
39.49,85.000,-0.12366,3.872,-0.002
39.66,85.200,-0.12328,3.890,-0.002
39.83,85.400,-0.12295,3.906,-0.002
39.99,85.600,-0.12266,3.922,-0.002
40.15,85.800,-0.12237,3.937,-0.002
40.32,86.000,-0.12204,3.954,-0.002
40.44,86.200,-0.12179,3.965,-0.002
40.58,86.400,-0.12150,3.980,-0.002
40.75,86.600,-0.12121,3.997,-0.002
40.91,86.800,-0.12096,4.012,-0.002
41.07,87.000,-0.12067,4.028,-0.002
41.27,87.200,-0.12037,4.048,-0.002
41.44,87.400,-0.12008,4.064,-0.002
41.65,87.600,-0.11975,4.085,-0.002
41.84,87.800,-0.11946,4.103,-0.002
42.03,88.000,-0.11913,4.121,-0.002
42.23,88.200,-0.11884,4.141,-0.002
42.42,88.400,-0.11850,4.160,-0.002
42.64,88.600,-0.11817,4.181,-0.002
42.82,88.800,-0.11784,4.199,-0.002
43.05,89.000,-0.11747,4.222,-0.002
43.30,89.200,-0.11709,4.246,-0.002
43.53,89.400,-0.11672,4.269,-0.002
43.81,89.600,-0.11630,4.296,-0.002
44.11,89.800,-0.11585,4.326,-0.002
44.38,90.000,-0.11543,4.352,-0.002
44.65,90.200,-0.11501,4.379,-0.002
44.87,90.400,-0.11464,4.401,-0.002
45.11,90.600,-0.11422,4.424,-0.002
45.33,90.800,-0.11389,4.446,-0.002
45.51,91.000,-0.11352,4.463,-0.002
45.71,91.200,-0.11323,4.483,-0.002
45.89,91.400,-0.11294,4.500,-0.002
46.09,91.600,-0.11265,4.520,-0.002
46.24,91.800,-0.11235,4.535,-0.002
46.40,92.000,-0.11210,4.551,-0.002
46.60,92.200,-0.11181,4.570,-0.002
46.81,92.400,-0.11152,4.590,-0.002
46.99,92.600,-0.11127,4.608,-0.002
47.19,92.800,-0.11098,4.628,-0.002
47.41,93.000,-0.11069,4.649,-0.002
47.63,93.200,-0.11040,4.670,-0.002
47.83,93.400,-0.11007,4.691,-0.002
48.05,93.600,-0.10978,4.712,-0.002
48.28,93.800,-0.10945,4.734,-0.002
48.48,94.000,-0.10915,4.754,-0.002
48.69,94.200,-0.10882,4.775,-0.002
48.92,94.400,-0.10849,4.797,-0.002
49.18,94.600,-0.10816,4.822,-0.002
49.43,94.800,-0.10782,4.847,-0.002
49.72,95.000,-0.10741,4.876,-0.002
50.07,95.200,-0.10699,4.910,-0.002
50.40,95.400,-0.10654,4.942,-0.002
50.73,95.600,-0.10612,4.975,-0.002
51.03,95.800,-0.10571,5.005,-0.002
51.34,96.000,-0.10529,5.035,-0.002
51.60,96.200,-0.10487,5.060,-0.002
51.84,96.400,-0.10450,5.084,-0.002
52.07,96.600,-0.10417,5.106,-0.002
52.25,96.800,-0.10388,5.124,-0.002
52.45,97.000,-0.10354,5.144,-0.002
52.64,97.200,-0.10330,5.162,-0.002
52.84,97.400,-0.10300,5.182,-0.002
53.00,97.600,-0.10271,5.198,-0.002
53.19,97.800,-0.10246,5.216,-0.002
53.40,98.000,-0.10221,5.237,-0.002
53.61,98.200,-0.10192,5.257,-0.002
53.84,98.400,-0.10163,5.280,-0.002
54.07,98.600,-0.10134,5.303,-0.002
54.28,98.800,-0.10101,5.324,-0.002
54.48,99.000,-0.10072,5.342,-0.002
54.70,99.200,-0.10043,5.365,-0.002
54.94,99.400,-0.10010,5.388,-0.002
55.16,99.600,-0.09980,5.410,-0.002
55.38,99.800,-0.09947,5.431,-0.002
55.62,100.000,-0.09918,5.455,-0.002
55.88,100.200,-0.09881,5.480,-0.002
56.16,100.400,-0.09847,5.507,-0.002
56.46,100.600,-0.09810,5.537,-0.002
56.77,100.800,-0.09769,5.567,-0.002
57.11,101.000,-0.09723,5.601,-0.002
57.43,101.200,-0.09681,5.632,-0.002
57.75,101.400,-0.09640,5.663,-0.002
58.04,101.600,-0.09594,5.691,-0.002
58.33,101.800,-0.09557,5.720,-0.002
58.59,102.000,-0.09519,5.746,-0.002
58.79,102.200,-0.09482,5.765,-0.002
59.00,102.400,-0.09453,5.786,-0.002
59.18,102.600,-0.09424,5.804,-0.002
59.39,102.800,-0.09390,5.825,-0.002
59.57,103.000,-0.09365,5.842,-0.002
59.75,103.200,-0.09336,5.860,-0.002
59.94,103.400,-0.09311,5.879,-0.002
60.14,103.600,-0.09282,5.898,-0.002
60.34,103.800,-0.09257,5.918,-0.002
60.57,104.000,-0.09228,5.940,-0.002
60.78,104.200,-0.09199,5.961,-0.002
61.00,104.400,-0.09170,5.982,-0.002
61.24,104.600,-0.09141,6.006,-0.002
61.47,104.800,-0.09108,6.028,-0.002
61.72,105.000,-0.09079,6.052,-0.002
61.95,105.200,-0.09050,6.076,-0.002
62.16,105.400,-0.09016,6.096,-0.002
62.42,105.600,-0.08983,6.122,-0.002
62.67,105.800,-0.08950,6.146,-0.002
62.96,106.000,-0.08917,6.174,-0.002
63.25,106.200,-0.08883,6.203,-0.002
63.57,106.400,-0.08842,6.234,-0.002
63.91,106.600,-0.08800,6.268,-0.002
64.26,106.800,-0.08759,6.302,-0.002
64.59,107.000,-0.08717,6.334,-0.002
64.89,107.200,-0.08676,6.363,-0.002
65.15,107.400,-0.08638,6.389,-0.002
65.43,107.600,-0.08601,6.416,-0.002
65.66,107.800,-0.08563,6.439,-0.002
65.89,108.000,-0.08530,6.461,-0.002
66.11,108.200,-0.08501,6.483,-0.002
66.32,108.400,-0.08472,6.504,-0.002
66.52,108.600,-0.08443,6.523,-0.002
66.71,108.800,-0.08414,6.542,-0.002
66.90,109.000,-0.08385,6.560,-0.002
67.08,109.200,-0.08360,6.579,-0.002
67.29,109.400,-0.08331,6.599,-0.002
67.49,109.600,-0.08306,6.618,-0.002
67.71,109.800,-0.08277,6.640,-0.002
67.93,110.000,-0.08248,6.662,-0.002
68.15,110.200,-0.08218,6.683,-0.002
68.35,110.400,-0.08189,6.703,-0.002
68.59,110.600,-0.08160,6.726,-0.002
68.79,110.800,-0.08131,6.746,-0.002
69.00,111.000,-0.08098,6.767,-0.002
69.24,111.200,-0.08069,6.790,-0.002
69.44,111.400,-0.08040,6.810,-0.002
69.71,111.600,-0.08007,6.836,-0.002
69.97,111.800,-0.07969,6.862,-0.002
70.27,112.000,-0.07932,6.891,-0.002
70.59,112.200,-0.07894,6.922,-0.002
70.92,112.400,-0.07853,6.955,-0.002
71.26,112.600,-0.07807,6.988,-0.002
71.55,112.800,-0.07766,7.017,-0.002
71.84,113.000,-0.07724,7.045,-0.002
72.09,113.200,-0.07682,7.070,-0.002
72.36,113.400,-0.07645,7.096,-0.002
72.54,113.600,-0.07608,7.114,-0.001
72.72,113.800,-0.07574,7.131,-0.001
72.90,114.000,-0.07545,7.149,-0.001
73.07,114.200,-0.07516,7.166,-0.001
73.28,114.400,-0.07487,7.186,-0.001
73.49,114.600,-0.07458,7.207,-0.001
73.67,114.800,-0.07429,7.225,-0.001
73.84,115.000,-0.07404,7.241,-0.001
74.02,115.200,-0.07379,7.259,-0.001
74.23,115.400,-0.07350,7.280,-0.001
74.42,115.600,-0.07321,7.298,-0.001
74.61,115.800,-0.07292,7.317,-0.001
74.83,116.000,-0.07263,7.339,-0.001
75.06,116.200,-0.07234,7.361,-0.001
75.33,116.400,-0.07200,7.387,-0.001
75.55,116.600,-0.07171,7.409,-0.001
75.78,116.800,-0.07138,7.431,-0.001
75.99,117.000,-0.07109,7.452,-0.001
76.25,117.200,-0.07076,7.478,-0.001
76.52,117.400,-0.07038,7.504,-0.001
76.80,117.600,-0.07005,7.531,-0.001
77.13,117.800,-0.06963,7.564,-0.001
77.42,118.000,-0.06926,7.593,-0.001
77.77,118.200,-0.06880,7.627,-0.001
78.11,118.400,-0.06835,7.660,-0.001
78.45,118.600,-0.06793,7.693,-0.001
78.73,118.800,-0.06752,7.721,-0.001
79.08,119.000,-0.06710,7.755,-0.001
79.36,119.200,-0.06673,7.783,-0.001
79.63,119.400,-0.06639,7.809,-0.001
79.85,119.600,-0.06606,7.831,-0.001
80.09,119.800,-0.06577,7.855,-0.001
80.34,120.000,-0.06548,7.879,-0.001
80.55,120.200,-0.06519,7.899,-0.001
80.78,120.400,-0.06490,7.922,-0.001
81.01,120.600,-0.06465,7.944,-0.001
81.25,120.800,-0.06436,7.968,-0.001
81.49,121.000,-0.06407,7.992,-0.001
81.75,121.200,-0.06378,8.017,-0.001
81.97,121.400,-0.06348,8.039,-0.001
82.20,121.600,-0.06319,8.062,-0.001
82.43,121.800,-0.06286,8.084,-0.001
82.66,122.000,-0.06257,8.106,-0.001
82.93,122.200,-0.06224,8.132,-0.001
83.21,122.400,-0.06191,8.160,-0.001
83.53,122.600,-0.06157,8.192,-0.001
83.84,122.800,-0.06124,8.222,-0.001
84.20,123.000,-0.06091,8.257,-0.001
84.56,123.200,-0.06053,8.293,-0.001
84.94,123.400,-0.06016,8.329,-0.001
85.30,123.600,-0.05974,8.365,-0.001
85.75,123.800,-0.05933,8.409,-0.001
86.07,124.000,-0.05887,8.441,-0.001
86.40,124.200,-0.05846,8.473,-0.001
86.76,124.400,-0.05804,8.508,-0.001
87.05,124.600,-0.05767,8.537,-0.001
87.36,124.800,-0.05729,8.567,-0.001
87.61,125.000,-0.05696,8.592,-0.001
87.84,125.200,-0.05663,8.614,-0.001
88.08,125.400,-0.05634,8.638,-0.001
88.30,125.600,-0.05605,8.660,-0.001
88.56,125.800,-0.05576,8.685,-0.001
88.82,126.000,-0.05546,8.710,-0.001
89.07,126.200,-0.05522,8.735,-0.001
89.36,126.400,-0.05492,8.763,-0.001
89.62,126.600,-0.05463,8.789,-0.001
89.93,126.800,-0.05434,8.819,-0.001
90.20,127.000,-0.05405,8.846,-0.001
90.51,127.200,-0.05376,8.876,-0.001
90.77,127.400,-0.05347,8.902,-0.001
91.09,127.600,-0.05318,8.933,-0.001
91.36,127.800,-0.05285,8.959,-0.001
91.62,128.000,-0.05256,8.985,-0.001
91.96,128.200,-0.05222,9.018,-0.001
92.25,128.400,-0.05193,9.046,-0.001
92.56,128.600,-0.05160,9.077,-0.001
92.88,128.800,-0.05123,9.108,-0.001
93.30,129.000,-0.05085,9.150,-0.001
93.64,129.200,-0.05044,9.183,-0.001
94.00,129.400,-0.05002,9.219,-0.001
94.30,129.600,-0.04960,9.247,-0.001
94.55,129.800,-0.04915,9.272,-0.001
94.71,130.000,-0.04873,9.288,-0.001
94.79,130.200,-0.04836,9.296,-0.001
94.89,130.400,-0.04798,9.305,-0.001
94.96,130.600,-0.04765,9.313,-0.001
94.97,130.800,-0.04732,9.313,-0.001
94.80,131.000,-0.04703,9.297,-0.001
94.39,131.200,-0.04674,9.257,-0.001
94.06,131.400,-0.04645,9.224,-0.001
93.86,131.600,-0.04620,9.205,-0.001
93.74,131.800,-0.04591,9.193,-0.001
93.67,132.000,-0.04566,9.186,-0.001
93.56,132.200,-0.04537,9.175,-0.001
93.51,132.400,-0.04512,9.170,-0.001
93.56,132.600,-0.04483,9.175,-0.001
93.66,132.800,-0.04454,9.185,-0.001
93.82,133.000,-0.04420,9.200,-0.001
93.96,133.200,-0.04391,9.214,-0.001
94.17,133.400,-0.04362,9.235,-0.001
94.40,133.600,-0.04329,9.258,-0.001
94.60,133.800,-0.04300,9.277,-0.001
94.87,134.000,-0.04267,9.304,-0.001
95.13,134.200,-0.04233,9.329,-0.001
95.40,134.400,-0.04200,9.356,-0.001
95.61,134.600,-0.04167,9.376,-0.001
95.72,134.800,-0.04125,9.387,-0.001
95.92,135.000,-0.04084,9.406,-0.001
96.18,135.200,-0.04042,9.432,-0.001
96.46,135.400,-0.04001,9.459,-0.001
96.66,135.600,-0.03959,9.480,-0.001
96.85,135.800,-0.03917,9.498,-0.001
97.09,136.000,-0.03880,9.522,-0.001
97.36,136.200,-0.03843,9.548,-0.001
97.58,136.400,-0.03809,9.569,-0.001
97.76,136.600,-0.03776,9.587,-0.001
97.82,136.800,-0.03747,9.593,-0.001
97.78,137.000,-0.03718,9.589,-0.001
97.76,137.200,-0.03689,9.587,-0.001
97.76,137.400,-0.03664,9.587,-0.001
97.78,137.600,-0.03635,9.589,-0.001
97.66,137.800,-0.03610,9.577,-0.001
97.59,138.000,-0.03581,9.571,-0.001
97.68,138.200,-0.03552,9.579,-0.001
97.82,138.400,-0.03523,9.592,-0.001
98.00,138.600,-0.03498,9.610,-0.001
98.21,138.800,-0.03464,9.632,-0.001
98.42,139.000,-0.03435,9.652,-0.001
98.55,139.200,-0.03402,9.665,-0.001
98.58,139.400,-0.03373,9.668,-0.001
98.41,139.600,-0.03340,9.651,-0.001
98.13,139.800,-0.03307,9.624,-0.001
98.09,140.000,-0.03273,9.620,-0.001
98.23,140.200,-0.03240,9.633,-0.001
98.52,140.400,-0.03203,9.662,-0.001
98.86,140.600,-0.03165,9.695,-0.001
99.21,140.800,-0.03124,9.729,-0.001
99.50,141.000,-0.03082,9.758,-0.001
99.69,141.200,-0.03036,9.777,-0.001
99.86,141.400,-0.02995,9.793,-0.001
100.05,141.600,-0.02958,9.812,-0.001
100.27,141.800,-0.02920,9.833,-0.001
100.51,142.000,-0.02883,9.857,-0.001
100.73,142.200,-0.02849,9.878,-0.001
101.00,142.400,-0.02820,9.905,-0.001
101.22,142.600,-0.02787,9.926,-0.001
101.43,142.800,-0.02758,9.947,-0.001
101.59,143.000,-0.02733,9.962,-0.001
101.74,143.200,-0.02708,9.978,-0.001
101.89,143.400,-0.02679,9.992,-0.001
102.05,143.600,-0.02654,10.008,-0.001
102.17,143.800,-0.02625,10.020,-0.001
102.30,144.000,-0.02596,10.032,-0.001
102.44,144.200,-0.02567,10.046,-0.001
102.70,144.400,-0.02538,10.071,0.000
102.97,144.600,-0.02509,10.098,0.000
103.31,144.800,-0.02480,10.132,0.000
103.61,145.000,-0.02446,10.160,0.000
103.94,145.200,-0.02417,10.193,0.000
104.30,145.400,-0.02384,10.228,0.000
104.71,145.600,-0.02355,10.268,0.000
105.21,145.800,-0.02322,10.317,0.000
105.71,146.000,-0.02284,10.366,0.000
106.33,146.200,-0.02247,10.427,0.000
106.91,146.400,-0.02205,10.484,0.000
107.52,146.600,-0.02164,10.544,0.000
108.13,146.800,-0.02118,10.604,0.000
108.73,147.000,-0.02077,10.663,0.000
109.34,147.200,-0.02035,10.723,0.000
109.96,147.400,-0.01993,10.784,0.000
110.53,147.600,-0.01956,10.839,0.000
111.03,147.800,-0.01923,10.888,0.000
111.57,148.000,-0.01890,10.941,0.000
112.00,148.200,-0.01860,10.983,0.000
112.47,148.400,-0.01831,11.029,0.000
112.87,148.600,-0.01802,11.069,0.000
113.32,148.800,-0.01777,11.113,0.000
113.73,149.000,-0.01748,11.153,0.000
114.12,149.200,-0.01723,11.191,0.000
114.55,149.400,-0.01694,11.233,0.000
114.96,149.600,-0.01665,11.274,0.000
115.35,149.800,-0.01636,11.312,0.000
115.76,150.000,-0.01607,11.352,0.000
116.18,150.200,-0.01578,11.394,0.000
116.54,150.400,-0.01549,11.428,0.000
116.93,150.600,-0.01516,11.467,0.000
117.27,150.800,-0.01482,11.501,0.000
117.59,151.000,-0.01453,11.531,0.000
117.91,151.200,-0.01420,11.563,0.000
118.17,151.400,-0.01387,11.588,0.000
118.46,151.600,-0.01349,11.617,0.000
118.68,151.800,-0.01312,11.639,0.000
118.83,152.000,-0.01270,11.654,0.000
118.78,152.200,-0.01225,11.648,0.000
118.54,152.400,-0.01179,11.625,0.000
118.07,152.600,-0.01137,11.579,0.000
117.33,152.800,-0.01092,11.506,0.000
116.46,153.000,-0.01050,11.420,0.000
115.67,153.200,-0.01013,11.343,0.000
115.17,153.400,-0.00979,11.294,0.000
114.78,153.600,-0.00946,11.256,0.000
114.46,153.800,-0.00913,11.225,0.000
114.27,154.000,-0.00884,11.206,0.000
114.07,154.200,-0.00855,11.186,0.000
113.96,154.400,-0.00826,11.176,0.000
113.80,154.600,-0.00801,11.160,0.000
113.72,154.800,-0.00772,11.152,0.000
113.64,155.000,-0.00743,11.145,0.000
113.57,155.200,-0.00713,11.138,0.000
113.56,155.400,-0.00684,11.136,0.000
113.50,155.600,-0.00655,11.130,0.000
113.42,155.800,-0.00622,11.123,0.000
113.29,156.000,-0.00593,11.110,0.000
113.22,156.200,-0.00560,11.103,0.000
113.21,156.400,-0.00531,11.103,0.000
113.25,156.600,-0.00497,11.106,0.000
113.25,156.800,-0.00464,11.107,0.000
113.30,157.000,-0.00431,11.111,0.000
113.36,157.200,-0.00394,11.117,0.000
113.32,157.400,-0.00356,11.113,0.000
113.21,157.600,-0.00319,11.102,0.000
112.99,157.800,-0.00273,11.081,0.000
112.34,158.000,-0.00231,11.017,0.000
111.20,158.200,-0.00186,10.905,0.000
109.37,158.400,-0.00144,10.726,0.000
107.66,158.600,-0.00107,10.558,0.000
106.97,158.800,-0.00069,10.490,0.000
106.60,159.000,-0.00036,10.454,0.000
106.40,159.200,-0.00003,10.435,0.000
106.23,159.400,0.00026,10.418,0.000
106.08,159.600,0.00059,10.403,0.000
105.94,159.800,0.00089,10.389,0.000
105.81,160.000,0.00113,10.376,0.000
105.75,160.200,0.00143,10.371,0.000
105.78,160.400,0.00167,10.374,0.000
105.85,160.600,0.00197,10.381,0.000
105.99,160.800,0.00226,10.395,0.000
106.15,161.000,0.00255,10.410,0.000
106.34,161.200,0.00284,10.428,0.000
106.55,161.400,0.00313,10.449,0.000
106.74,161.600,0.00346,10.467,0.000
106.97,161.800,0.00375,10.490,0.000
107.17,162.000,0.00409,10.510,0.000
107.44,162.200,0.00442,10.536,0.000
107.71,162.400,0.00471,10.563,0.000
107.96,162.600,0.00504,10.587,0.000
108.24,162.800,0.00541,10.614,0.000
108.61,163.000,0.00579,10.652,0.000
108.99,163.200,0.00620,10.688,0.000
109.37,163.400,0.00666,10.725,0.000
109.78,163.600,0.00708,10.766,0.000
110.19,163.800,0.00753,10.806,0.000
110.50,164.000,0.00795,10.836,0.000
110.81,164.200,0.00837,10.867,0.000
111.14,164.400,0.00874,10.899,0.000
111.40,164.600,0.00907,10.924,0.000
111.66,164.800,0.00940,10.950,0.000
111.89,165.000,0.00974,10.973,0.000
112.15,165.200,0.01003,10.998,0.000
112.44,165.400,0.01032,11.026,0.000
112.70,165.600,0.01057,11.053,0.000
112.99,165.800,0.01086,11.080,0.000
113.32,166.000,0.01111,11.113,0.000
113.67,166.200,0.01140,11.148,0.000
114.07,166.400,0.01165,11.186,0.000
114.44,166.600,0.01194,11.223,0.000
114.83,166.800,0.01223,11.261,0.000
115.26,167.000,0.01256,11.303,0.000
115.65,167.200,0.01285,11.341,0.000
116.00,167.400,0.01314,11.376,0.000
116.38,167.600,0.01348,11.413,0.000
116.74,167.800,0.01377,11.448,0.000
117.12,168.000,0.01410,11.486,0.000
117.47,168.200,0.01443,11.520,0.000
117.93,168.400,0.01477,11.565,0.000
118.42,168.600,0.01514,11.613,0.000
118.90,168.800,0.01551,11.660,0.000
119.38,169.000,0.01589,11.707,0.000
119.91,169.200,0.01634,11.759,0.000
120.43,169.400,0.01676,11.810,0.000
120.95,169.600,0.01718,11.861,0.000
121.39,169.800,0.01759,11.904,0.000
121.84,170.000,0.01801,11.948,0.000
122.32,170.200,0.01834,11.995,0.000
122.79,170.400,0.01871,12.042,0.000
123.19,170.600,0.01905,12.081,0.000
123.56,170.800,0.01934,12.117,0.000
123.92,171.000,0.01963,12.152,0.000
124.25,171.200,0.01992,12.184,0.000
124.53,171.400,0.02017,12.212,0.000
124.78,171.600,0.02046,12.237,0.000
125.08,171.800,0.02071,12.266,0.000
125.40,172.000,0.02100,12.298,0.000
125.76,172.200,0.02129,12.333,0.000
126.15,172.400,0.02158,12.371,0.000
126.55,172.600,0.02187,12.411,0.000
126.97,172.800,0.02220,12.452,0.000
127.41,173.000,0.02249,12.494,0.000
127.82,173.200,0.02279,12.535,0.000
128.27,173.400,0.02312,12.579,0.000
128.69,173.600,0.02341,12.620,0.000
129.11,173.800,0.02374,12.662,0.000
129.58,174.000,0.02407,12.708,0.000
130.10,174.200,0.02441,12.759,0.000
130.66,174.400,0.02478,12.814,0.000
131.23,174.600,0.02515,12.870,0.000
131.83,174.800,0.02557,12.928,0.001
132.44,175.000,0.02599,12.988,0.001
133.06,175.200,0.02640,13.049,0.001
133.62,175.400,0.02682,13.104,0.001
134.12,175.600,0.02723,13.153,0.001
134.61,175.800,0.02756,13.201,0.001
135.08,176.000,0.02794,13.247,0.001
135.44,176.200,0.02827,13.282,0.001
135.76,176.400,0.02856,13.314,0.001
136.10,176.600,0.02885,13.346,0.001
136.39,176.800,0.02914,13.376,0.001
136.67,177.000,0.02943,13.403,0.001
136.96,177.200,0.02968,13.431,0.001
137.25,177.400,0.02997,13.460,0.001
137.59,177.600,0.03022,13.493,0.001
137.94,177.800,0.03051,13.528,0.001
138.31,178.000,0.03076,13.564,0.001
138.74,178.200,0.03105,13.606,0.001
139.20,178.400,0.03139,13.651,0.001
139.68,178.600,0.03168,13.698,0.001
140.16,178.800,0.03197,13.746,0.001
140.65,179.000,0.03226,13.793,0.001
141.14,179.200,0.03259,13.841,0.001
141.65,179.400,0.03288,13.891,0.001
142.18,179.600,0.03322,13.943,0.001
142.69,179.800,0.03355,13.993,0.001
143.27,180.000,0.03388,14.050,0.001
143.85,180.200,0.03430,14.107,0.001
144.45,180.400,0.03467,14.166,0.001
144.99,180.600,0.03513,14.219,0.001
145.48,180.800,0.03554,14.266,0.001
145.91,181.000,0.03600,14.309,0.001
146.38,181.200,0.03642,14.355,0.001
146.89,181.400,0.03679,14.405,0.001
147.30,181.600,0.03716,14.446,0.001
147.67,181.800,0.03750,14.482,0.001
148.08,182.000,0.03783,14.522,0.001
148.38,182.200,0.03812,14.551,0.001
148.67,182.400,0.03841,14.580,0.001
149.00,182.600,0.03866,14.612,0.001
149.28,182.800,0.03895,14.640,0.001
149.62,183.000,0.03920,14.672,0.001
149.97,183.200,0.03949,14.707,0.001
150.35,183.400,0.03974,14.745,0.001
150.70,183.600,0.04003,14.779,0.001
151.02,183.800,0.04032,14.810,0.001
151.34,184.000,0.04061,14.842,0.001
151.70,184.200,0.04095,14.877,0.001
152.03,184.400,0.04124,14.910,0.001
152.40,184.600,0.04153,14.945,0.001
152.77,184.800,0.04186,14.982,0.001
153.15,185.000,0.04219,15.019,0.001
153.46,185.200,0.04252,15.049,0.001
153.84,185.400,0.04286,15.086,0.001
154.32,185.600,0.04319,15.134,0.001
154.85,185.800,0.04356,15.186,0.001
155.42,186.000,0.04398,15.242,0.001
156.05,186.200,0.04439,15.304,0.001
156.75,186.400,0.04485,15.372,0.001
157.40,186.600,0.04531,15.436,0.001
157.96,186.800,0.04572,15.491,0.001
158.52,187.000,0.04614,15.546,0.001
158.93,187.200,0.04651,15.586,0.001
159.26,187.400,0.04689,15.619,0.001
159.57,187.600,0.04722,15.648,0.001
159.91,187.800,0.04751,15.681,0.001
160.27,188.000,0.04784,15.717,0.001
160.65,188.200,0.04813,15.754,0.001
161.04,188.400,0.04838,15.792,0.001
161.40,188.600,0.04867,15.828,0.001
161.77,188.800,0.04897,15.865,0.001
162.11,189.000,0.04921,15.898,0.001
162.52,189.200,0.04951,15.938,0.001
162.91,189.400,0.04980,15.976,0.001
163.27,189.600,0.05013,16.011,0.001
163.63,189.800,0.05042,16.046,0.001
163.96,190.000,0.05071,16.079,0.001
164.27,190.200,0.05104,16.109,0.001
164.55,190.400,0.05138,16.136,0.001
164.84,190.600,0.05167,16.165,0.001
165.12,190.800,0.05200,16.193,0.001
165.39,191.000,0.05233,16.219,0.001
165.69,191.200,0.05271,16.249,0.001
165.99,191.400,0.05308,16.278,0.001
166.23,191.600,0.05350,16.301,0.001
166.35,191.800,0.05391,16.313,0.001
166.44,192.000,0.05433,16.322,0.001
166.54,192.200,0.05478,16.332,0.001
166.76,192.400,0.05520,16.353,0.001
167.09,192.600,0.05557,16.386,0.001
167.48,192.800,0.05595,16.424,0.001
167.88,193.000,0.05632,16.464,0.001
168.27,193.200,0.05665,16.502,0.001
168.66,193.400,0.05699,16.540,0.001
169.02,193.600,0.05728,16.575,0.001
169.32,193.800,0.05757,16.605,0.001
169.55,194.000,0.05786,16.628,0.001
169.78,194.200,0.05815,16.650,0.001
169.85,194.400,0.05840,16.657,0.001
169.91,194.600,0.05869,16.662,0.001
170.03,194.800,0.05894,16.674,0.001
170.19,195.000,0.05923,16.691,0.001
170.37,195.200,0.05952,16.707,0.001
170.57,195.400,0.05985,16.727,0.001
170.86,195.600,0.06014,16.755,0.001
171.07,195.800,0.06043,16.777,0.001
171.33,196.000,0.06077,16.802,0.001
171.54,196.200,0.06106,16.822,0.001
171.70,196.400,0.06139,16.839,0.001
171.80,196.600,0.06172,16.848,0.001
171.81,196.800,0.06206,16.849,0.001
171.89,197.000,0.06243,16.857,0.001
171.99,197.200,0.06280,16.867,0.001
171.84,197.400,0.06322,16.852,0.001
171.42,197.600,0.06368,16.810,0.001
170.40,197.800,0.06413,16.710,0.001
169.27,198.000,0.06455,16.600,0.001
168.52,198.200,0.06496,16.526,0.001
166.96,198.400,0.06534,16.373,0.001
166.47,198.600,0.06571,16.325,0.001
166.58,198.800,0.06604,16.336,0.001
166.83,199.000,0.06634,16.361,0.001
167.11,199.200,0.06663,16.388,0.001
167.41,199.400,0.06692,16.417,0.001
167.70,199.600,0.06721,16.445,0.001
167.99,199.800,0.06746,16.474,0.001
168.33,200.000,0.06771,16.508,0.001
168.71,200.200,0.06800,16.545,0.001
169.16,200.400,0.06825,16.589,0.001
169.58,200.600,0.06854,16.630,0.001
170.08,200.800,0.06883,16.679,0.001
170.59,201.000,0.06912,16.729,0.001
171.06,201.200,0.06945,16.775,0.001
171.54,201.400,0.06974,16.823,0.001
172.05,201.600,0.07003,16.872,0.001
172.56,201.800,0.07037,16.923,0.001
173.10,202.000,0.07070,16.975,0.001
173.65,202.200,0.07103,17.029,0.001
174.21,202.400,0.07136,17.085,0.001
174.81,202.600,0.07170,17.143,0.001
175.44,202.800,0.07207,17.204,0.001
176.10,203.000,0.07249,17.270,0.001
176.79,203.200,0.07290,17.337,0.001
177.52,203.400,0.07336,17.409,0.001
178.27,203.600,0.07377,17.483,0.001
178.90,203.800,0.07419,17.545,0.001
179.53,204.000,0.07461,17.606,0.001
180.21,204.200,0.07498,17.673,0.001
180.86,204.400,0.07531,17.737,0.001
181.47,204.600,0.07564,17.796,0.001
182.06,204.800,0.07594,17.854,0.001
182.66,205.000,0.07623,17.913,0.002
183.25,205.200,0.07652,17.971,0.002
183.83,205.400,0.07677,18.028,0.002
184.40,205.600,0.07706,18.084,0.002
184.97,205.800,0.07731,18.140,0.002
185.61,206.000,0.07760,18.202,0.002
186.26,206.200,0.07789,18.266,0.002
186.91,206.400,0.07818,18.330,0.002
187.63,206.600,0.07847,18.400,0.002
188.33,206.800,0.07876,18.469,0.002
189.04,207.000,0.07905,18.538,0.002
189.80,207.200,0.07938,18.613,0.002
190.57,207.400,0.07968,18.688,0.002
191.31,207.600,0.08001,18.762,0.002
192.10,207.800,0.08030,18.839,0.002
192.95,208.000,0.08063,18.922,0.002
193.82,208.200,0.08101,19.007,0.002
194.72,208.400,0.08134,19.096,0.002
195.75,208.600,0.08171,19.197,0.002
196.83,208.800,0.08213,19.303,0.002
197.94,209.000,0.08258,19.412,0.002
199.15,209.200,0.08300,19.530,0.002
200.22,209.400,0.08342,19.635,0.002
201.22,209.600,0.08383,19.733,0.002
202.14,209.800,0.08420,19.823,0.002
203.10,210.000,0.08458,19.917,0.002
203.93,210.200,0.08491,19.998,0.002
204.67,210.400,0.08520,20.071,0.002
205.40,210.600,0.08549,20.143,0.002
206.15,210.800,0.08578,20.216,0.002
206.86,211.000,0.08607,20.286,0.002
207.48,211.200,0.08637,20.347,0.002
208.14,211.400,0.08662,20.412,0.002
208.84,211.600,0.08691,20.480,0.002
209.53,211.800,0.08716,20.548,0.002
210.24,212.000,0.08745,20.617,0.002
210.98,212.200,0.08774,20.690,0.002
211.74,212.400,0.08803,20.765,0.002
212.52,212.600,0.08832,20.841,0.002
213.19,212.800,0.08861,20.907,0.002
213.99,213.000,0.08894,20.985,0.002
214.79,213.200,0.08923,21.064,0.002
215.54,213.400,0.08957,21.138,0.002
216.32,213.600,0.08990,21.214,0.002
217.10,213.800,0.09023,21.290,0.002
217.90,214.000,0.09056,21.369,0.002
218.80,214.200,0.09094,21.457,0.002
219.61,214.400,0.09135,21.537,0.002
101.14,214.600,0.09181,9.918,0.002
104.12,214.800,0.09223,10.210,0.002
106.01,215.000,0.09268,10.396,0.002
107.73,215.200,0.09310,10.564,0.002
109.23,215.400,0.09347,10.712,0.002
110.53,215.600,0.09389,10.839,0.002
111.56,215.800,0.09422,10.941,0.002
112.47,216.000,0.09455,11.029,0.002
113.19,216.200,0.09484,11.100,0.002
113.72,216.400,0.09513,11.153,0.002
114.25,216.600,0.09538,11.204,0.002
114.72,216.800,0.09567,11.250,0.002
115.12,217.000,0.09597,11.289,0.002
115.48,217.200,0.09621,11.325,0.002
115.81,217.400,0.09651,11.357,0.002
116.16,217.600,0.09675,11.391,0.002
116.47,217.800,0.09705,11.422,0.002
116.78,218.000,0.09738,11.452,0.002
117.05,218.200,0.09767,11.479,0.002
117.29,218.400,0.09796,11.503,0.002
117.55,218.600,0.09829,11.528,0.002
117.83,218.800,0.09862,11.555,0.002
118.06,219.000,0.09896,11.577,0.002
118.30,219.200,0.09929,11.602,0.002
118.55,219.400,0.09962,11.626,0.002
118.85,219.600,0.09995,11.655,0.002
119.15,219.800,0.10037,11.684,0.002
119.43,220.000,0.10074,11.712,0.002
119.76,220.200,0.10116,11.745,0.002
120.01,220.400,0.10162,11.769,0.002
120.14,220.600,0.10207,11.782,0.002
120.23,220.800,0.10249,11.791,0.002
120.27,221.000,0.10290,11.794,0.002
120.35,221.200,0.10328,11.802,0.002
120.48,221.400,0.10365,11.815,0.002
120.63,221.600,0.10399,11.829,0.002
120.83,221.800,0.10432,11.849,0.002
121.02,222.000,0.10461,11.868,0.002
121.26,222.200,0.10490,11.892,0.002
121.44,222.400,0.10519,11.909,0.002
121.63,222.600,0.10548,11.928,0.002
121.82,222.800,0.10573,11.947,0.002
122.01,223.000,0.10602,11.966,0.002
122.22,223.200,0.10631,11.986,0.002
122.48,223.400,0.10660,12.012,0.002
122.74,223.600,0.10689,12.036,0.002
122.96,223.800,0.10719,12.058,0.002
123.14,224.000,0.10752,12.076,0.002
123.22,224.200,0.10785,12.084,0.002
123.13,224.400,0.10814,12.075,0.002
122.95,224.600,0.10847,12.057,0.002
122.68,224.800,0.10881,12.031,0.002
122.11,225.000,0.10914,11.975,0.002
121.68,225.200,0.10947,11.933,0.002
121.55,225.400,0.10984,11.920,0.002
121.64,225.600,0.11026,11.928,0.002
121.83,225.800,0.11068,11.948,0.002
122.12,226.000,0.11113,11.975,0.002
122.36,226.200,0.11155,12.000,0.002
122.61,226.400,0.11196,12.024,0.002
122.94,226.600,0.11238,12.056,0.002
123.29,226.800,0.11275,12.091,0.002
123.67,227.000,0.11309,12.128,0.002
124.04,227.200,0.11342,12.164,0.002
124.41,227.400,0.11375,12.201,0.002
124.77,227.600,0.11404,12.236,0.002
125.13,227.800,0.11433,12.271,0.002
125.45,228.000,0.11462,12.302,0.002
125.78,228.200,0.11487,12.335,0.002
126.11,228.400,0.11516,12.368,0.002
126.48,228.600,0.11545,12.403,0.002
126.86,228.800,0.11575,12.441,0.002
127.27,229.000,0.11600,12.481,0.002
127.73,229.200,0.11629,12.526,0.002
128.18,229.400,0.11662,12.570,0.002
128.63,229.600,0.11691,12.614,0.002
129.17,229.800,0.11720,12.667,0.002
129.69,230.000,0.11753,12.718,0.002
130.18,230.200,0.11782,12.766,0.002
130.74,230.400,0.11816,12.822,0.002
131.30,230.600,0.11849,12.877,0.002
131.92,230.800,0.11882,12.937,0.002
132.59,231.000,0.11919,13.003,0.002
133.36,231.200,0.11961,13.078,0.002
134.21,231.400,0.12003,13.161,0.002
135.09,231.600,0.12048,13.248,0.002
135.88,231.800,0.12094,13.326,0.002
136.67,232.000,0.12136,13.403,0.002
137.37,232.200,0.12173,13.472,0.002
138.13,232.400,0.12215,13.546,0.002
138.78,232.600,0.12248,13.610,0.002
139.37,232.800,0.12281,13.667,0.002
139.90,233.000,0.12314,13.720,0.002
140.43,233.200,0.12343,13.771,0.002
140.97,233.400,0.12368,13.825,0.002
141.50,233.600,0.12397,13.876,0.002
142.02,233.800,0.12426,13.927,0.002
142.56,234.000,0.12451,13.981,0.002
143.13,234.200,0.12480,14.036,0.002
143.73,234.400,0.12505,14.095,0.002
144.37,234.600,0.12535,14.158,0.002
144.99,234.800,0.12564,14.219,0.002
145.66,235.000,0.12597,14.284,0.002
146.28,235.200,0.12626,14.345,0.002
146.96,235.400,0.12655,14.412,0.002
147.65,235.600,0.12684,14.479,0.002
148.34,235.800,0.12717,14.547,0.003
149.08,236.000,0.12751,14.620,0.003
149.80,236.200,0.12780,14.691,0.003
150.55,236.400,0.12813,14.764,0.003
151.41,236.600,0.12850,14.848,0.003
152.30,236.800,0.12888,14.936,0.003
153.27,237.000,0.12929,15.031,0.003
154.24,237.200,0.12971,15.126,0.003
155.28,237.400,0.13017,15.228,0.003
156.21,237.600,0.13058,15.319,0.003
157.12,237.800,0.13100,15.409,0.003
157.95,238.000,0.13141,15.490,0.003
158.73,238.200,0.13179,15.566,0.003
159.43,238.400,0.13212,15.635,0.003
160.10,238.600,0.13245,15.701,0.003
160.73,238.800,0.13274,15.762,0.003
161.33,239.000,0.13303,15.822,0.003
161.93,239.200,0.13332,15.880,0.003
162.50,239.400,0.13361,15.936,0.003
163.08,239.600,0.13386,15.993,0.003
163.68,239.800,0.13415,16.052,0.003
164.29,240.000,0.13440,16.112,0.003
164.96,240.200,0.13470,16.177,0.003
165.68,240.400,0.13499,16.248,0.003
166.41,240.600,0.13528,16.319,0.003
167.18,240.800,0.13557,16.395,0.003
167.92,241.000,0.13590,16.467,0.003
168.69,241.200,0.13619,16.543,0.003
169.50,241.400,0.13648,16.622,0.003
170.27,241.600,0.13681,16.698,0.003
171.09,241.800,0.13715,16.778,0.003
171.91,242.000,0.13744,16.859,0.003
172.80,242.200,0.13781,16.946,0.003
173.74,242.400,0.13814,17.038,0.003
174.76,242.600,0.13856,17.139,0.003
175.79,242.800,0.13898,17.239,0.003
176.88,243.000,0.13939,17.346,0.003
177.92,243.200,0.13981,17.448,0.003
178.94,243.400,0.14022,17.548,0.003
179.91,243.600,0.14060,17.644,0.003
180.85,243.800,0.14097,17.735,0.003
181.78,244.000,0.14134,17.826,0.003
182.58,244.200,0.14168,17.905,0.003
183.34,244.400,0.14197,17.980,0.003
184.11,244.600,0.14230,18.055,0.003
184.84,244.800,0.14259,18.127,0.003
185.54,245.000,0.14284,18.195,0.003
186.21,245.200,0.14313,18.261,0.003
186.91,245.400,0.14338,18.330,0.003
187.59,245.600,0.14367,18.396,0.003
188.31,245.800,0.14392,18.467,0.003
189.05,246.000,0.14421,18.539,0.003
189.81,246.200,0.14450,18.615,0.003
190.56,246.400,0.14479,18.688,0.003
191.36,246.600,0.14508,18.766,0.003
192.13,246.800,0.14542,18.841,0.003
192.87,247.000,0.14571,18.914,0.003
193.65,247.200,0.14600,18.991,0.003
194.40,247.400,0.14633,19.065,0.003
195.18,247.600,0.14662,19.140,0.003
196.04,247.800,0.14695,19.225,0.003
196.88,248.000,0.14729,19.308,0.003
197.84,248.200,0.14770,19.402,0.003
198.87,248.400,0.14808,19.503,0.003
199.99,248.600,0.14849,19.612,0.003
201.20,248.800,0.14891,19.732,0.003
202.34,249.000,0.14936,19.843,0.003
203.46,249.200,0.14978,19.952,0.003
204.56,249.400,0.15020,20.061,0.003
205.57,249.600,0.15057,20.159,0.003
206.48,249.800,0.15094,20.249,0.003
207.37,250.000,0.15128,20.336,0.003
208.19,250.200,0.15157,20.416,0.003
208.89,250.400,0.15186,20.485,0.003
209.60,250.600,0.15215,20.554,0.003
210.35,250.800,0.15244,20.628,0.003
211.05,251.000,0.15269,20.697,0.003
211.75,251.200,0.15298,20.766,0.003
212.50,251.400,0.15323,20.840,0.003
213.26,251.600,0.15352,20.914,0.003
214.06,251.800,0.15381,20.993,0.003
208.58,252.000,0.15410,20.455,0.003
1.66,252.060,0.15423,0.163,0.003