File: data-files/CWRU/0900-05-28D.txt
""
"Test Method","Will_Huddleston_Disks.msm"
"Sample I. D.","900-5-28D.mss"
"Specimen Number","1"

"Load (N)","Time (s)","Extension (mm)","Stress (MPa)","Strain (mm/mm)"

4.01,0.200,-0.04609,0.410,-0.001
4.01,0.400,-0.04609,0.409,-0.001
4.02,0.600,-0.04605,0.410,-0.001
4.01,0.800,-0.04605,0.410,-0.001
4.01,1.000,-0.04601,0.409,-0.001
4.03,1.200,-0.04596,0.411,-0.001
4.03,1.400,-0.04592,0.411,-0.001
4.05,1.600,-0.04588,0.413,-0.001
4.11,1.800,-0.04576,0.419,-0.001
4.27,2.000,-0.04555,0.435,-0.001
4.48,2.200,-0.04517,0.457,-0.001
4.65,2.400,-0.04484,0.475,-0.001
4.71,2.600,-0.04451,0.481,-0.001
4.76,2.800,-0.04422,0.486,-0.001
4.78,3.000,-0.04393,0.487,-0.001
4.80,3.200,-0.04364,0.490,-0.001
4.81,3.400,-0.04339,0.491,-0.001
4.81,3.600,-0.04314,0.491,-0.001
4.82,3.800,-0.04289,0.492,-0.001
4.85,4.000,-0.04260,0.495,-0.001
4.86,4.200,-0.04235,0.496,-0.001
4.86,4.400,-0.04206,0.496,-0.001
4.86,4.600,-0.04177,0.496,-0.001
4.90,4.800,-0.04148,0.500,-0.001
4.93,5.000,-0.04119,0.503,-0.001
4.94,5.200,-0.04094,0.504,-0.001
4.98,5.400,-0.04060,0.508,-0.001
4.99,5.600,-0.04031,0.509,-0.001
5.04,5.800,-0.04002,0.514,-0.001
5.07,6.000,-0.03969,0.517,-0.001
5.13,6.200,-0.03940,0.523,-0.001
5.14,6.400,-0.03902,0.524,-0.001
5.19,6.600,-0.03869,0.529,-0.001
5.24,6.800,-0.03832,0.535,-0.001
5.31,7.000,-0.03790,0.542,-0.001
5.38,7.200,-0.03749,0.549,-0.001
5.46,7.400,-0.03707,0.557,-0.001
5.54,7.600,-0.03666,0.565,-0.001
5.61,7.800,-0.03628,0.573,-0.001
5.71,8.000,-0.03587,0.582,-0.001
5.76,8.200,-0.03549,0.587,-0.001
5.80,8.400,-0.03516,0.592,-0.001
5.86,8.600,-0.03487,0.598,-0.001
5.90,8.800,-0.03458,0.602,-0.001
5.95,9.000,-0.03429,0.607,-0.001
6.00,9.200,-0.03400,0.612,-0.001
6.03,9.400,-0.03371,0.616,-0.001
6.06,9.600,-0.03346,0.619,-0.001
6.08,9.800,-0.03317,0.621,-0.001
6.14,10.000,-0.03292,0.627,-0.001
6.18,10.200,-0.03262,0.631,-0.001
6.23,10.400,-0.03233,0.636,-0.001
6.28,10.600,-0.03204,0.640,-0.001
6.31,10.800,-0.03175,0.644,-0.001
6.37,11.000,-0.03146,0.650,-0.001
6.42,11.200,-0.03113,0.655,-0.001
6.47,11.400,-0.03084,0.660,-0.001
6.53,11.600,-0.03051,0.666,-0.001
6.59,11.800,-0.03021,0.673,-0.001
6.66,12.000,-0.02988,0.679,-0.001
6.73,12.200,-0.02951,0.686,-0.001
6.80,12.400,-0.02913,0.694,-0.001
6.87,12.600,-0.02872,0.701,-0.001
6.98,12.800,-0.02830,0.712,-0.001
7.06,13.000,-0.02785,0.721,-0.001
7.17,13.200,-0.02743,0.731,-0.001
7.25,13.400,-0.02697,0.740,-0.001
7.35,13.600,-0.02660,0.750,-0.001
7.42,13.800,-0.02618,0.757,-0.001
7.49,14.000,-0.02585,0.764,-0.001
7.54,14.200,-0.02552,0.769,-0.001
7.61,14.400,-0.02523,0.777,0.000
7.68,14.600,-0.02494,0.783,0.000
7.74,14.800,-0.02465,0.790,0.000
7.80,15.000,-0.02440,0.795,0.000
7.86,15.200,-0.02411,0.802,0.000
7.90,15.400,-0.02386,0.806,0.000
7.96,15.600,-0.02357,0.813,0.000
8.04,15.800,-0.02327,0.820,0.000
8.11,16.000,-0.02298,0.827,0.000
8.18,16.200,-0.02269,0.835,0.000
8.23,16.400,-0.02240,0.840,0.000
8.30,16.600,-0.02211,0.847,0.000
8.39,16.800,-0.02178,0.856,0.000
8.47,17.000,-0.02149,0.864,0.000
8.54,17.200,-0.02116,0.871,0.000
8.61,17.400,-0.02082,0.879,0.000
8.69,17.600,-0.02049,0.887,0.000
8.80,17.800,-0.02016,0.898,0.000
8.89,18.000,-0.01978,0.907,0.000
8.98,18.200,-0.01937,0.916,0.000
9.10,18.400,-0.01895,0.928,0.000
9.20,18.600,-0.01850,0.939,0.000
9.33,18.800,-0.01808,0.952,0.000
9.43,19.000,-0.01766,0.962,0.000
9.53,19.200,-0.01725,0.973,0.000
9.62,19.400,-0.01683,0.982,0.000
9.70,19.600,-0.01650,0.990,0.000
9.78,19.800,-0.01613,0.998,0.000
9.85,20.000,-0.01584,1.005,0.000
9.93,20.200,-0.01550,1.013,0.000
10.01,20.400,-0.01521,1.021,0.000
10.07,20.600,-0.01492,1.027,0.000
10.15,20.800,-0.01467,1.035,0.000
10.21,21.000,-0.01438,1.042,0.000
10.29,21.200,-0.01409,1.050,0.000
10.36,21.400,-0.01380,1.057,0.000
10.46,21.600,-0.01351,1.067,0.000
10.54,21.800,-0.01318,1.076,0.000
10.62,22.000,-0.01289,1.083,0.000
10.71,22.200,-0.01255,1.093,0.000
10.80,22.400,-0.01226,1.102,0.000
10.89,22.600,-0.01193,1.111,0.000
10.97,22.800,-0.01160,1.119,0.000
11.07,23.000,-0.01127,1.130,0.000
11.17,23.200,-0.01093,1.140,0.000
11.25,23.400,-0.01060,1.148,0.000
11.38,23.600,-0.01023,1.161,0.000
11.50,23.800,-0.00981,1.173,0.000
11.61,24.000,-0.00940,1.185,0.000
11.73,24.200,-0.00898,1.197,0.000
11.87,24.400,-0.00856,1.211,0.000
11.97,24.600,-0.00815,1.221,0.000
12.09,24.800,-0.00773,1.234,0.000
12.21,25.000,-0.00736,1.245,0.000
12.31,25.200,-0.00699,1.256,0.000
12.40,25.400,-0.00665,1.266,0.000
12.49,25.600,-0.00632,1.274,0.000
12.56,25.800,-0.00603,1.282,0.000
12.66,26.000,-0.00574,1.292,0.000
12.74,26.200,-0.00545,1.300,0.000
12.82,26.400,-0.00516,1.308,0.000
12.90,26.600,-0.00491,1.317,0.000
12.99,26.800,-0.00462,1.326,0.000
13.09,27.000,-0.00433,1.336,0.000
13.17,27.200,-0.00403,1.344,0.000
13.26,27.400,-0.00374,1.353,0.000
13.36,27.600,-0.00345,1.364,0.000
13.46,27.800,-0.00316,1.374,0.000
13.58,28.000,-0.00283,1.386,0.000
13.65,28.200,-0.00254,1.393,0.000
13.75,28.400,-0.00221,1.403,0.000
13.85,28.600,-0.00187,1.414,0.000
13.96,28.800,-0.00154,1.425,0.000
14.06,29.000,-0.00121,1.435,0.000
14.20,29.200,-0.00083,1.449,0.000
14.33,29.400,-0.00046,1.462,0.000
14.48,29.600,-0.00005,1.478,0.000
14.60,29.800,0.00041,1.490,0.000
14.75,30.000,0.00083,1.506,0.000
14.91,30.200,0.00128,1.521,0.000
15.03,30.400,0.00170,1.533,0.000
15.16,30.600,0.00207,1.547,0.000
15.26,30.800,0.00245,1.558,0.000
15.36,31.000,0.00278,1.568,0.000
15.48,31.200,0.00311,1.580,0.000
15.56,31.400,0.00340,1.588,0.000
15.65,31.600,0.00369,1.597,0.000
15.73,31.800,0.00394,1.605,0.000
15.84,32.000,0.00424,1.616,0.000
15.92,32.200,0.00448,1.625,0.000
16.03,32.400,0.00478,1.636,0.000
16.10,32.600,0.00507,1.643,0.000
16.21,32.800,0.00536,1.654,0.000
16.32,33.000,0.00565,1.665,0.000
16.44,33.200,0.00594,1.677,0.000
16.53,33.400,0.00623,1.687,0.000
16.63,33.600,0.00656,1.697,0.000
16.75,33.800,0.00685,1.710,0.000
16.85,34.000,0.00719,1.720,0.000
16.99,34.200,0.00748,1.733,0.000
17.09,34.400,0.00781,1.744,0.000
17.21,34.600,0.00814,1.756,0.000
17.36,34.800,0.00852,1.771,0.000
17.51,35.000,0.00889,1.786,0.000
17.64,35.200,0.00926,1.800,0.000
17.82,35.400,0.00972,1.819,0.000
17.99,35.600,0.01014,1.835,0.000
18.16,35.800,0.01059,1.853,0.000
18.31,36.000,0.01101,1.868,0.000
18.45,36.200,0.01142,1.883,0.000
18.58,36.400,0.01180,1.896,0.000
18.69,36.600,0.01213,1.907,0.000
18.81,36.800,0.01242,1.919,0.000
18.91,37.000,0.01275,1.930,0.000
19.02,37.200,0.01304,1.941,0.000
19.13,37.400,0.01334,1.952,0.000
19.23,37.600,0.01359,1.963,0.000
19.34,37.800,0.01388,1.973,0.000
19.46,38.000,0.01413,1.986,0.000
19.55,38.200,0.01442,1.995,0.000
19.69,38.400,0.01471,2.009,0.000
19.77,38.600,0.01500,2.017,0.000
19.92,38.800,0.01529,2.033,0.000
20.04,39.000,0.01562,2.045,0.000
20.15,39.200,0.01591,2.057,0.000
20.29,39.400,0.01620,2.070,0.000
20.41,39.600,0.01654,2.082,0.000
20.54,39.800,0.01683,2.096,0.000
20.67,40.000,0.01716,2.109,0.000
20.82,40.200,0.01749,2.124,0.000
20.96,40.400,0.01787,2.139,0.000
21.12,40.600,0.01820,2.155,0.000
21.31,40.800,0.01861,2.174,0.000
21.48,41.000,0.01903,2.192,0.000
21.67,41.200,0.01944,2.212,0.000
21.85,41.400,0.01986,2.230,0.000
22.04,41.600,0.02028,2.249,0.000
22.19,41.800,0.02069,2.264,0.000
22.37,42.000,0.02107,2.282,0.000
22.47,42.200,0.02140,2.293,0.000
22.63,42.400,0.02173,2.309,0.000
22.73,42.600,0.02206,2.320,0.000
22.84,42.800,0.02235,2.331,0.000
22.97,43.000,0.02264,2.344,0.000
23.07,43.200,0.02294,2.355,0.000
23.19,43.400,0.02318,2.366,0.000
23.31,43.600,0.02348,2.379,0.000
23.43,43.800,0.02372,2.391,0.000
23.56,44.000,0.02402,2.404,0.000
23.68,44.200,0.02431,2.417,0.000
23.81,44.400,0.02460,2.430,0.000
23.96,44.600,0.02489,2.445,0.000
24.09,44.800,0.02522,2.458,0.000
24.22,45.000,0.02551,2.471,0.001
24.36,45.200,0.02580,2.486,0.001
24.52,45.400,0.02613,2.502,0.001
24.67,45.600,0.02643,2.517,0.001
24.83,45.800,0.02676,2.533,0.001
24.99,46.000,0.02709,2.550,0.001
25.18,46.200,0.02746,2.570,0.001
25.37,46.400,0.02784,2.589,0.001
25.56,46.600,0.02825,2.608,0.001
25.78,46.800,0.02867,2.631,0.001
25.99,47.000,0.02909,2.652,0.001
26.20,47.200,0.02954,2.674,0.001
26.37,47.400,0.02996,2.691,0.001
26.58,47.600,0.03037,2.712,0.001
26.73,47.800,0.03075,2.727,0.001
26.88,48.000,0.03108,2.743,0.001
27.04,48.200,0.03141,2.760,0.001
27.17,48.400,0.03170,2.772,0.001
27.29,48.600,0.03199,2.785,0.001
27.45,48.800,0.03229,2.801,0.001
27.56,49.000,0.03253,2.813,0.001
27.69,49.200,0.03283,2.826,0.001
27.85,49.400,0.03307,2.842,0.001
27.99,49.600,0.03337,2.856,0.001
28.12,49.800,0.03366,2.869,0.001
28.31,50.000,0.03395,2.888,0.001
28.44,50.200,0.03424,2.902,0.001
28.61,50.400,0.03457,2.919,0.001
28.77,50.600,0.03486,2.935,0.001
28.95,50.800,0.03519,2.954,0.001
29.10,51.000,0.03549,2.969,0.001
29.28,51.200,0.03582,2.987,0.001
29.46,51.400,0.03615,3.006,0.001
29.65,51.600,0.03652,3.025,0.001
29.85,51.800,0.03686,3.046,0.001
30.06,52.000,0.03727,3.068,0.001
30.28,52.200,0.03765,3.090,0.001
30.52,52.400,0.03810,3.114,0.001
30.75,52.600,0.03852,3.138,0.001
30.99,52.800,0.03898,3.162,0.001
31.22,53.000,0.03939,3.186,0.001
31.41,53.200,0.03977,3.205,0.001
31.63,53.400,0.04018,3.228,0.001
31.81,53.600,0.04051,3.246,0.001
31.95,53.800,0.04085,3.260,0.001
32.12,54.000,0.04114,3.277,0.001
32.28,54.200,0.04147,3.294,0.001
32.43,54.400,0.04172,3.309,0.001
32.57,54.600,0.04201,3.324,0.001
32.75,54.800,0.04230,3.342,0.001
32.89,55.000,0.04255,3.356,0.001
33.06,55.200,0.04284,3.373,0.001
33.24,55.400,0.04313,3.392,0.001
33.41,55.600,0.04342,3.409,0.001
33.57,55.800,0.04375,3.426,0.001
33.76,56.000,0.04405,3.445,0.001
33.92,56.200,0.04434,3.461,0.001
34.10,56.400,0.04467,3.480,0.001
34.29,56.600,0.04496,3.499,0.001
34.48,56.800,0.04529,3.518,0.001
34.66,57.000,0.04562,3.537,0.001
34.88,57.200,0.04596,3.559,0.001
35.12,57.400,0.04633,3.583,0.001
35.34,57.600,0.04671,3.606,0.001
35.60,57.800,0.04712,3.632,0.001
35.86,58.000,0.04754,3.659,0.001
36.13,58.200,0.04795,3.687,0.001
36.40,58.400,0.04837,3.714,0.001
36.66,58.600,0.04878,3.740,0.001
36.89,58.800,0.04920,3.765,0.001
37.12,59.000,0.04957,3.788,0.001
37.33,59.200,0.04995,3.809,0.001
37.50,59.400,0.05024,3.826,0.001
37.68,59.600,0.05053,3.845,0.001
37.86,59.800,0.05086,3.863,0.001
38.04,60.000,0.05111,3.882,0.001
38.21,60.200,0.05140,3.899,0.001
38.38,60.400,0.05169,3.917,0.001
38.55,60.600,0.05194,3.934,0.001
38.72,60.800,0.05223,3.951,0.001
38.92,61.000,0.05252,3.972,0.001
39.11,61.200,0.05281,3.991,0.001
39.30,61.400,0.05310,4.010,0.001
39.48,61.600,0.05340,4.028,0.001
39.68,61.800,0.05369,4.049,0.001
39.89,62.000,0.05398,4.071,0.001
40.11,62.200,0.05431,4.093,0.001
40.31,62.400,0.05460,4.114,0.001
40.53,62.600,0.05493,4.136,0.001
40.78,62.800,0.05527,4.161,0.001
41.01,63.000,0.05564,4.184,0.001
41.31,63.200,0.05601,4.215,0.001
41.57,63.400,0.05639,4.242,0.001
41.89,63.600,0.05680,4.275,0.001
42.18,63.800,0.05726,4.305,0.001
42.50,64.000,0.05772,4.337,0.001
42.78,64.200,0.05813,4.366,0.001
43.07,64.400,0.05855,4.395,0.001
43.31,64.600,0.05892,4.420,0.001
43.55,64.800,0.05926,4.444,0.001
43.73,65.000,0.05959,4.463,0.001
43.93,65.200,0.05988,4.482,0.001
44.12,65.400,0.06017,4.502,0.001
44.31,65.600,0.06046,4.522,0.001
44.50,65.800,0.06071,4.541,0.001
44.68,66.000,0.06100,4.559,0.001
44.86,66.200,0.06125,4.577,0.001
45.04,66.400,0.06154,4.596,0.001
45.24,66.600,0.06183,4.616,0.001
45.48,66.800,0.06208,4.640,0.001
45.66,67.000,0.06237,4.660,0.001
45.88,67.200,0.06266,4.682,0.001
46.10,67.400,0.06300,4.704,0.001
46.34,67.600,0.06329,4.728,0.001
46.55,67.800,0.06358,4.750,0.001
46.79,68.000,0.06391,4.775,0.001
47.02,68.200,0.06420,4.798,0.001
47.27,68.400,0.06453,4.823,0.001
47.52,68.600,0.06487,4.849,0.001
47.81,68.800,0.06520,4.879,0.001
48.12,69.000,0.06561,4.910,0.001
48.40,69.200,0.06599,4.938,0.001
48.75,69.400,0.06640,4.974,0.001
49.06,69.600,0.06682,5.006,0.001
49.36,69.800,0.06723,5.037,0.001
49.66,70.000,0.06765,5.067,0.001
49.93,70.200,0.06806,5.095,0.001
50.19,70.400,0.06840,5.121,0.001
50.41,70.600,0.06873,5.144,0.001
50.65,70.800,0.06906,5.168,0.001
50.86,71.000,0.06935,5.190,0.001
51.10,71.200,0.06969,5.215,0.001
51.31,71.400,0.06993,5.236,0.001
51.50,71.600,0.07023,5.255,0.001
51.69,71.800,0.07048,5.275,0.001
51.93,72.000,0.07077,5.299,0.001
52.16,72.200,0.07102,5.322,0.001
52.38,72.400,0.07131,5.345,0.001
52.64,72.600,0.07160,5.372,0.001
51.61,72.800,0.07189,5.266,0.001
23.50,73.000,0.07218,2.398,0.001
24.37,73.200,0.07251,2.486,0.001
24.94,73.400,0.07280,2.545,0.001
25.48,73.600,0.07309,2.600,0.001
25.98,73.800,0.07343,2.651,0.001
26.46,74.000,0.07372,2.700,0.001
26.90,74.200,0.07405,2.745,0.001
27.28,74.400,0.07438,2.784,0.001
27.67,74.600,0.07476,2.824,0.001
28.03,74.800,0.07513,2.860,0.001
28.35,75.000,0.07554,2.893,0.001
28.71,75.200,0.07596,2.930,0.001
29.06,75.400,0.07638,2.965,0.002
29.36,75.600,0.07679,2.995,0.002
29.67,75.800,0.07717,3.027,0.002
29.97,76.000,0.07758,3.058,0.002
30.23,76.200,0.07796,3.084,0.002
30.49,76.400,0.07829,3.111,0.002
30.72,76.600,0.07862,3.134,0.002
30.93,76.800,0.07891,3.156,0.002
31.14,77.000,0.07920,3.178,0.002
31.36,77.200,0.07949,3.200,0.002
31.55,77.400,0.07978,3.220,0.002
31.76,77.600,0.08003,3.241,0.002
31.96,77.800,0.08032,3.262,0.002
32.17,78.000,0.08061,3.283,0.002
32.39,78.200,0.08086,3.305,0.002
32.61,78.400,0.08115,3.328,0.002
32.85,78.600,0.08145,3.352,0.002
33.08,78.800,0.08178,3.375,0.002
33.30,79.000,0.08207,3.398,0.002
33.53,79.200,0.08236,3.421,0.002
33.76,79.400,0.08269,3.445,0.002
34.00,79.600,0.08298,3.470,0.002
34.22,79.800,0.08327,3.491,0.002
34.48,80.000,0.08361,3.518,0.002
34.73,80.200,0.08394,3.544,0.002
35.04,80.400,0.08431,3.575,0.002
35.36,80.600,0.08473,3.608,0.002
35.67,80.800,0.08514,3.640,0.002
36.01,81.000,0.08556,3.675,0.002
36.35,81.200,0.08602,3.709,0.002
36.67,81.400,0.08643,3.742,0.002
37.01,81.600,0.08685,3.777,0.002
37.30,81.800,0.08722,3.806,0.002
37.58,82.000,0.08755,3.834,0.002
37.82,82.200,0.08789,3.859,0.002
38.04,82.400,0.08822,3.882,0.002
38.28,82.600,0.08851,3.906,0.002
38.50,82.800,0.08880,3.928,0.002
38.72,83.000,0.08905,3.951,0.002
38.92,83.200,0.08934,3.972,0.002
39.14,83.400,0.08959,3.994,0.002
39.36,83.600,0.08988,4.016,0.002
39.61,83.800,0.09017,4.041,0.002
39.85,84.000,0.09042,4.066,0.002
40.09,84.200,0.09075,4.091,0.002
40.34,84.400,0.09105,4.117,0.002
40.58,84.600,0.09134,4.141,0.002
40.84,84.800,0.09167,4.168,0.002
41.10,85.000,0.09196,4.193,0.002
41.36,85.200,0.09229,4.220,0.002
41.62,85.400,0.09258,4.247,0.002
41.90,85.600,0.09292,4.275,0.002
42.17,85.800,0.09329,4.303,0.002
42.51,86.000,0.09362,4.338,0.002
42.85,86.200,0.09404,4.372,0.002
43.20,86.400,0.09445,4.408,0.002
43.57,86.600,0.09487,4.446,0.002
43.96,86.800,0.09533,4.486,0.002
44.32,87.000,0.09574,4.522,0.002
44.70,87.200,0.09620,4.561,0.002
45.02,87.400,0.09657,4.594,0.002
45.33,87.600,0.09695,4.625,0.002
45.59,87.800,0.09728,4.652,0.002
45.84,88.000,0.09761,4.678,0.002
46.08,88.200,0.09790,4.702,0.002
46.31,88.400,0.09819,4.725,0.002
46.54,88.600,0.09848,4.749,0.002
46.75,88.800,0.09877,4.771,0.002
46.99,89.000,0.09902,4.795,0.002
47.22,89.200,0.09931,4.818,0.002
47.44,89.400,0.09956,4.841,0.002
47.72,89.600,0.09986,4.869,0.002
47.95,89.800,0.10019,4.893,0.002
48.21,90.000,0.10048,4.920,0.002
48.49,90.200,0.10077,4.948,0.002
48.77,90.400,0.10110,4.976,0.002
49.04,90.600,0.10139,5.004,0.002
49.30,90.800,0.10173,5.031,0.002
49.59,91.000,0.10202,5.060,0.002
49.88,91.200,0.10235,5.090,0.002
50.21,91.400,0.10268,5.123,0.002
50.55,91.600,0.10305,5.158,0.002
50.90,91.800,0.10347,5.193,0.002
51.30,92.000,0.10384,5.234,0.002
51.70,92.200,0.10430,5.276,0.002
20.28,92.400,0.10472,2.069,0.002
20.22,92.600,0.10513,2.063,0.002
20.98,92.800,0.10555,2.140,0.002
21.61,93.000,0.10596,2.205,0.002
22.16,93.200,0.10634,2.261,0.002
22.57,93.400,0.10667,2.303,0.002
22.92,93.600,0.10700,2.338,0.002
23.18,93.800,0.10729,2.365,0.002
21.71,94.000,0.10758,2.216,0.002
22.06,94.200,0.10788,2.251,0.002
22.35,94.400,0.10817,2.281,0.002
22.63,94.600,0.10842,2.309,0.002
22.89,94.800,0.10871,2.336,0.002
23.16,95.000,0.10900,2.363,0.002
23.41,95.200,0.10929,2.388,0.002
23.63,95.400,0.10958,2.411,0.002
23.82,95.600,0.10983,2.431,0.002
24.00,95.800,0.11016,2.449,0.002
24.18,96.000,0.11045,2.468,0.002
24.35,96.200,0.11078,2.485,0.002
24.50,96.400,0.11108,2.500,0.002
24.66,96.600,0.11141,2.516,0.002
24.81,96.800,0.11170,2.531,0.002
24.95,97.000,0.11203,2.546,0.002
25.11,97.200,0.11240,2.562,0.002
25.29,97.400,0.11278,2.581,0.002
25.47,97.600,0.11319,2.598,0.002
25.62,97.800,0.11361,2.614,0.002
25.77,98.000,0.11403,2.630,0.002
25.90,98.200,0.11444,2.643,0.002
26.04,98.400,0.11490,2.657,0.002
26.17,98.600,0.11527,2.670,0.002
26.27,98.800,0.11565,2.681,0.002
26.36,99.000,0.11602,2.690,0.002
26.46,99.200,0.11635,2.700,0.002
26.55,99.400,0.11664,2.709,0.002
26.64,99.600,0.11693,2.718,0.002
26.71,99.800,0.11723,2.725,0.002
26.80,100.000,0.11747,2.734,0.002
26.87,100.200,0.11777,2.742,0.002
26.96,100.400,0.11801,2.751,0.002
27.05,100.600,0.11831,2.760,0.002
27.12,100.800,0.11856,2.767,0.002
27.20,101.000,0.11885,2.775,0.002
27.29,101.200,0.11914,2.785,0.002
27.37,101.400,0.11947,2.793,0.002
27.44,101.600,0.11976,2.800,0.002
27.51,101.800,0.12005,2.808,0.002
27.58,102.000,0.12038,2.815,0.002
27.63,102.200,0.12067,2.819,0.002
27.68,102.400,0.12101,2.824,0.002
27.75,102.600,0.12134,2.831,0.002
27.85,102.800,0.12167,2.841,0.002
27.93,103.000,0.12205,2.850,0.002
28.03,103.200,0.12242,2.860,0.002
28.12,103.400,0.12284,2.870,0.002
28.26,103.600,0.12325,2.884,0.002
28.35,103.800,0.12367,2.893,0.002
28.44,104.000,0.12408,2.902,0.002
28.52,104.200,0.12450,2.910,0.002
28.58,104.400,0.12491,2.917,0.002
28.63,104.600,0.12529,2.922,0.002
28.66,104.800,0.12562,2.925,0.002
28.69,105.000,0.12595,2.928,0.002
28.73,105.200,0.12624,2.932,0.002
28.75,105.400,0.12653,2.934,0.002
28.78,105.600,0.12682,2.937,0.002
28.80,105.800,0.12707,2.939,0.003
28.85,106.000,0.12737,2.944,0.003
28.87,106.200,0.12761,2.946,0.003
28.92,106.400,0.12791,2.951,0.003
28.97,106.600,0.12820,2.956,0.003
29.00,106.800,0.12849,2.959,0.003
29.05,107.000,0.12882,2.965,0.003
29.09,107.200,0.12911,2.968,0.003
29.12,107.400,0.12940,2.972,0.003
29.12,107.600,0.12973,2.972,0.003
29.16,107.800,0.13002,2.976,0.003
29.20,108.000,0.13036,2.980,0.003
29.23,108.200,0.13069,2.982,0.003
29.27,108.400,0.13102,2.987,0.003
29.31,108.600,0.13135,2.991,0.003
29.33,108.800,0.13173,2.993,0.003
29.35,109.000,0.13214,2.995,0.003
29.42,109.200,0.13256,3.002,0.003
29.44,109.400,0.13298,3.004,0.003
29.46,109.600,0.13339,3.006,0.003
29.47,109.800,0.13381,3.007,0.003
29.45,110.000,0.13422,3.005,0.003
29.47,110.200,0.13460,3.007,0.003
29.45,110.400,0.13493,3.005,0.003
29.45,110.600,0.13526,3.005,0.003
29.43,110.800,0.13555,3.003,0.003
29.42,111.000,0.13584,3.002,0.003
29.43,111.200,0.13613,3.003,0.003
29.41,111.400,0.13642,3.001,0.003
29.40,111.600,0.13667,3.000,0.003
29.43,111.800,0.13696,3.003,0.003
29.42,112.000,0.13726,3.002,0.003
29.42,112.200,0.13750,3.002,0.003
29.43,112.400,0.13780,3.003,0.003
29.43,112.600,0.13809,3.003,0.003
29.39,112.800,0.13838,2.999,0.003
29.35,113.000,0.13867,2.995,0.003
29.32,113.200,0.13900,2.991,0.003
29.29,113.400,0.13929,2.989,0.003
29.28,113.600,0.13958,2.988,0.003
29.27,113.800,0.13991,2.987,0.003
29.29,114.000,0.14025,2.989,0.003
29.30,114.200,0.14058,2.989,0.003
29.31,114.400,0.14095,2.991,0.003
29.32,114.600,0.14133,2.992,0.003
29.35,114.800,0.14178,2.995,0.003
29.37,115.000,0.14224,2.997,0.003
29.37,115.200,0.14266,2.997,0.003
29.37,115.400,0.14307,2.997,0.003
29.37,115.600,0.14349,2.997,0.003
29.34,115.800,0.14390,2.994,0.003
29.33,116.000,0.14424,2.993,0.003
29.30,116.200,0.14457,2.989,0.003
29.30,116.400,0.14490,2.989,0.003
29.29,116.600,0.14519,2.989,0.003
29.26,116.800,0.14544,2.986,0.003
29.29,117.000,0.14573,2.989,0.003
29.28,117.200,0.14598,2.988,0.003
29.29,117.400,0.14627,2.989,0.003
29.30,117.600,0.14656,2.990,0.003
29.31,117.800,0.14681,2.991,0.003
29.32,118.000,0.14710,2.991,0.003
29.34,118.200,0.14744,2.994,0.003
29.35,118.400,0.14773,2.995,0.003
29.36,118.600,0.14802,2.996,0.003
29.38,118.800,0.14835,2.998,0.003
29.42,119.000,0.14864,3.002,0.003
29.42,119.200,0.14897,3.002,0.003
29.44,119.400,0.14926,3.004,0.003
29.43,119.600,0.14960,3.003,0.003
29.45,119.800,0.14997,3.005,0.003
29.45,120.000,0.15030,3.006,0.003
29.48,120.200,0.15072,3.008,0.003
29.53,120.400,0.15113,3.014,0.003
29.54,120.600,0.15155,3.015,0.003
29.56,120.800,0.15201,3.017,0.003
29.56,121.000,0.15242,3.017,0.003
29.55,121.200,0.15288,3.016,0.003
29.55,121.400,0.15325,3.015,0.003
29.53,121.600,0.15363,3.013,0.003
29.51,121.800,0.15396,3.012,0.003
29.52,122.000,0.15429,3.012,0.003
29.53,122.200,0.15458,3.013,0.003
29.52,122.400,0.15492,3.012,0.003
29.50,122.600,0.15517,3.010,0.003
29.50,122.800,0.15546,3.010,0.003
29.47,123.000,0.15575,3.007,0.003
29.48,123.200,0.15600,3.008,0.003
29.48,123.400,0.15629,3.008,0.003
29.46,123.600,0.15658,3.006,0.003
29.31,123.800,0.15687,2.990,0.003
29.21,124.000,0.15720,2.981,0.003
29.17,124.200,0.15749,2.977,0.003
29.17,124.400,0.15783,2.977,0.003
29.19,124.600,0.15816,2.979,0.003
29.23,124.800,0.15845,2.983,0.003
29.07,125.000,0.15878,2.967,0.003
28.98,125.200,0.15911,2.957,0.003
28.99,125.400,0.15945,2.959,0.003
29.00,125.600,0.15982,2.959,0.003
29.05,125.800,0.16019,2.964,0.003
29.16,126.000,0.16061,2.975,0.003
29.19,126.200,0.16103,2.978,0.003
29.15,126.400,0.16144,2.974,0.003
29.16,126.600,0.16186,2.975,0.003
29.12,126.800,0.16227,2.972,0.003
29.12,127.000,0.16269,2.971,0.003
29.11,127.200,0.16306,2.971,0.003
29.11,127.400,0.16339,2.970,0.003
29.06,127.600,0.16373,2.965,0.003
29.05,127.800,0.16402,2.964,0.003
29.02,128.000,0.16431,2.961,0.003
29.03,128.200,0.16460,2.963,0.003
29.04,128.400,0.16489,2.963,0.003
29.03,128.600,0.16514,2.962,0.003
29.04,128.800,0.16543,2.963,0.003
29.04,129.000,0.16568,2.964,0.003
29.07,129.200,0.16597,2.966,0.003
29.04,129.400,0.16626,2.964,0.003
29.04,129.600,0.16655,2.963,0.003
29.06,129.800,0.16684,2.966,0.003
29.06,130.000,0.16718,2.965,0.003
29.06,130.200,0.16747,2.966,0.003
29.07,130.400,0.16776,2.966,0.003
29.05,130.600,0.16809,2.964,0.003
29.06,130.800,0.16842,2.966,0.003
29.08,131.000,0.16875,2.967,0.003
29.09,131.200,0.16909,2.968,0.003
29.12,131.400,0.16946,2.971,0.003
29.15,131.600,0.16988,2.974,0.003
29.16,131.800,0.17029,2.976,0.003
29.18,132.000,0.17071,2.977,0.003
29.19,132.200,0.17112,2.979,0.003
29.20,132.400,0.17154,2.979,0.003
29.20,132.600,0.17195,2.980,0.003
29.20,132.800,0.17233,2.980,0.003
29.15,133.000,0.17266,2.975,0.003
29.16,133.200,0.17303,2.975,0.003
29.13,133.400,0.17333,2.973,0.003
29.11,133.600,0.17362,2.970,0.003
29.10,133.800,0.17391,2.969,0.003
29.09,134.000,0.17416,2.968,0.003
29.06,134.200,0.17441,2.965,0.003
29.04,134.400,0.17470,2.964,0.003
29.04,134.600,0.17499,2.963,0.003
29.05,134.800,0.17524,2.964,0.003
29.05,135.000,0.17553,2.964,0.003
29.06,135.200,0.17582,2.966,0.003
29.07,135.400,0.17611,2.967,0.003
29.10,135.600,0.17640,2.969,0.003
29.09,135.800,0.17673,2.968,0.003
29.09,136.000,0.17702,2.969,0.003
29.10,136.200,0.17732,2.970,0.003
29.13,136.400,0.17765,2.973,0.003
29.17,136.600,0.17794,2.976,0.004
29.20,136.800,0.17831,2.980,0.004
29.24,137.000,0.17864,2.983,0.004
29.28,137.200,0.17902,2.987,0.004
29.32,137.400,0.17943,2.992,0.004
29.36,137.600,0.17989,2.996,0.004
29.38,137.800,0.18031,2.998,0.004
29.41,138.000,0.18072,3.001,0.004
29.43,138.200,0.18114,3.003,0.004
29.43,138.400,0.18155,3.003,0.004
29.37,138.600,0.18189,2.997,0.004
29.36,138.800,0.18226,2.996,0.004
29.34,139.000,0.18255,2.994,0.004
29.32,139.200,0.18288,2.992,0.004
29.27,139.400,0.18317,2.986,0.004
29.24,139.600,0.18347,2.983,0.004
29.22,139.800,0.18371,2.982,0.004
29.22,140.000,0.18401,2.982,0.004
29.21,140.200,0.18426,2.980,0.004
29.24,140.400,0.18455,2.984,0.004
29.24,140.600,0.18484,2.984,0.004
29.23,140.800,0.18513,2.983,0.004
29.24,141.000,0.18542,2.983,0.004
29.22,141.200,0.18571,2.982,0.004
29.20,141.400,0.18604,2.980,0.004
29.19,141.600,0.18633,2.978,0.004
29.20,141.800,0.18667,2.979,0.004
29.20,142.000,0.18696,2.979,0.004
29.19,142.200,0.18729,2.979,0.004
29.20,142.400,0.18762,2.979,0.004
29.22,142.600,0.18795,2.982,0.004
29.20,142.800,0.18833,2.980,0.004
29.24,143.000,0.18870,2.984,0.004
29.25,143.200,0.18912,2.984,0.004
29.25,143.400,0.18953,2.985,0.004
29.22,143.600,0.18995,2.982,0.004
29.18,143.800,0.19036,2.977,0.004
29.15,144.000,0.19078,2.975,0.004
29.12,144.200,0.19115,2.971,0.004
29.05,144.400,0.19153,2.964,0.004
29.03,144.600,0.19186,2.963,0.004
29.00,144.800,0.19215,2.959,0.004
28.96,145.000,0.19248,2.955,0.004
28.95,145.200,0.19277,2.955,0.004
28.93,145.400,0.19302,2.952,0.004
28.93,145.600,0.19331,2.952,0.004
28.89,145.800,0.19361,2.948,0.004
28.90,146.000,0.19385,2.949,0.004
28.88,146.200,0.19415,2.947,0.004
28.86,146.400,0.19444,2.945,0.004
28.84,146.600,0.19473,2.943,0.004
28.83,146.800,0.19502,2.942,0.004
28.81,147.000,0.19531,2.940,0.004
28.79,147.200,0.19560,2.938,0.004
28.77,147.400,0.19593,2.936,0.004
28.73,147.600,0.19622,2.932,0.004
28.72,147.800,0.19656,2.931,0.004
28.71,148.000,0.19689,2.930,0.004
28.67,148.200,0.19722,2.925,0.004
28.65,148.400,0.19755,2.923,0.004
28.60,148.600,0.19797,2.918,0.004
28.58,148.800,0.19838,2.916,0.004
28.54,149.000,0.19880,2.913,0.004
28.51,149.200,0.19922,2.909,0.004
28.46,149.400,0.19967,2.904,0.004
28.42,149.600,0.20009,2.900,0.004
28.39,149.800,0.20046,2.896,0.004
28.32,150.000,0.20084,2.890,0.004
28.28,150.200,0.20121,2.885,0.004
28.21,150.400,0.20150,2.878,0.004
28.18,150.600,0.20183,2.875,0.004
28.14,150.800,0.20212,2.871,0.004
28.12,151.000,0.20241,2.870,0.004
28.06,151.200,0.20266,2.864,0.004
28.04,151.400,0.20296,2.861,0.004
28.00,151.600,0.20320,2.857,0.004
28.01,151.800,0.20350,2.858,0.004
27.96,152.000,0.20379,2.853,0.004
27.92,152.200,0.20408,2.849,0.004
27.89,152.400,0.20437,2.845,0.004
27.83,152.600,0.20466,2.840,0.004
27.79,152.800,0.20499,2.835,0.004
27.74,153.000,0.20528,2.830,0.004
27.66,153.200,0.20561,2.822,0.004
27.62,153.400,0.20591,2.819,0.004
27.60,153.600,0.20624,2.817,0.004
27.57,153.800,0.20657,2.814,0.004
27.56,154.000,0.20694,2.812,0.004
27.53,154.200,0.20732,2.809,0.004
27.50,154.400,0.20769,2.806,0.004
27.52,154.600,0.20811,2.808,0.004
27.47,154.800,0.20857,2.803,0.004
27.47,155.000,0.20898,2.803,0.004
27.32,155.200,0.20940,2.788,0.004
27.27,155.400,0.20981,2.783,0.004
27.28,155.600,0.21019,2.784,0.004
27.27,155.800,0.21056,2.782,0.004
27.27,156.000,0.21089,2.783,0.004
27.25,156.200,0.21122,2.781,0.004
27.24,156.400,0.21152,2.780,0.004
27.26,156.600,0.21181,2.781,0.004
27.27,156.800,0.21210,2.782,0.004
27.27,157.000,0.21235,2.783,0.004
27.27,157.200,0.21264,2.783,0.004
27.30,157.400,0.21289,2.786,0.004
27.31,157.600,0.21318,2.787,0.004
27.32,157.800,0.21351,2.788,0.004
27.35,158.000,0.21380,2.790,0.004
27.36,158.200,0.21409,2.792,0.004
27.34,158.400,0.21438,2.790,0.004
27.36,158.600,0.21472,2.792,0.004
27.34,158.800,0.21501,2.790,0.004
27.34,159.000,0.21534,2.790,0.004
27.34,159.000,0.21534,2.790,0.004