File: data-files/CWRU/0900-05-05A.txt
""
"Test Method","Will_Huddleston_Disks.msm"
"Sample I. D.","900-5-5A.mss"
"Specimen Number","1"

"Load (N)","Time (s)","Extension (mm)","Stress (MPa)","Strain (mm/mm)"

2.37,0.200,-0.06088,0.398,-0.001
2.36,0.300,-0.06088,0.397,-0.001
2.37,0.400,-0.06088,0.398,-0.001
2.37,0.500,-0.06088,0.398,-0.001
2.38,0.600,-0.06088,0.400,-0.001
2.36,0.700,-0.06088,0.397,-0.001
2.37,0.800,-0.06088,0.398,-0.001
2.37,0.900,-0.06084,0.399,-0.001
2.37,1.000,-0.06084,0.399,-0.001
2.36,1.100,-0.06084,0.396,-0.001
2.36,1.200,-0.06084,0.397,-0.001
2.36,1.300,-0.06080,0.397,-0.001
2.37,1.400,-0.06080,0.398,-0.001
2.37,1.500,-0.06080,0.398,-0.001
2.37,1.600,-0.06075,0.398,-0.001
2.36,1.700,-0.06075,0.396,-0.001
2.37,1.800,-0.06075,0.399,-0.001
2.37,1.900,-0.06071,0.398,-0.001
2.39,2.000,-0.06067,0.402,-0.001
2.44,2.100,-0.06063,0.409,-0.001
2.50,2.200,-0.06050,0.421,-0.001
2.60,2.300,-0.06038,0.436,-0.001
2.68,2.400,-0.06021,0.451,-0.001
2.74,2.500,-0.06009,0.461,-0.001
2.79,2.600,-0.05992,0.468,-0.001
2.82,2.700,-0.05980,0.473,-0.001
2.85,2.800,-0.05967,0.479,-0.001
2.90,2.900,-0.05951,0.488,-0.001
2.94,3.000,-0.05938,0.494,-0.001
2.95,3.100,-0.05926,0.496,-0.001
3.00,3.200,-0.05909,0.505,-0.001
3.03,3.300,-0.05897,0.509,-0.001
3.05,3.400,-0.05880,0.513,-0.001
3.08,3.500,-0.05868,0.518,-0.001
3.13,3.600,-0.05851,0.526,-0.001
3.17,3.700,-0.05839,0.532,-0.001
3.18,3.800,-0.05822,0.534,-0.001
3.23,3.900,-0.05805,0.542,-0.001
3.26,4.000,-0.05789,0.547,-0.001
3.30,4.100,-0.05772,0.554,-0.001
3.31,4.200,-0.05755,0.557,-0.001
3.36,4.300,-0.05739,0.564,-0.001
3.39,4.400,-0.05718,0.570,-0.001
3.44,4.500,-0.05701,0.578,-0.001
3.48,4.600,-0.05681,0.584,-0.001
3.53,4.700,-0.05660,0.593,-0.001
3.56,4.800,-0.05639,0.598,-0.001
3.60,4.900,-0.05618,0.604,-0.001
3.64,5.000,-0.05597,0.611,-0.001
3.69,5.100,-0.05577,0.620,-0.001
3.73,5.200,-0.05552,0.626,-0.001
3.77,5.300,-0.05531,0.633,-0.001
3.81,5.400,-0.05510,0.640,-0.001
3.85,5.500,-0.05494,0.647,-0.001
3.87,5.600,-0.05473,0.651,-0.001
3.92,5.700,-0.05452,0.658,-0.001
3.94,5.800,-0.05435,0.662,-0.001
3.97,5.900,-0.05419,0.666,-0.001
4.00,6.000,-0.05402,0.671,-0.001
4.03,6.100,-0.05386,0.677,-0.001
4.04,6.200,-0.05369,0.680,-0.001
4.08,6.300,-0.05352,0.685,-0.001
4.10,6.400,-0.05340,0.689,-0.001
4.12,6.500,-0.05323,0.692,-0.001
4.15,6.600,-0.05311,0.696,-0.001
4.17,6.700,-0.05298,0.701,-0.001
4.18,6.800,-0.05282,0.702,-0.001
4.19,6.900,-0.05269,0.705,-0.001
4.22,7.000,-0.05257,0.710,-0.001
4.25,7.100,-0.05240,0.714,-0.001
4.26,7.200,-0.05228,0.716,-0.001
4.28,7.300,-0.05215,0.719,-0.001
4.30,7.400,-0.05203,0.722,-0.001
4.33,7.500,-0.05190,0.727,-0.001
4.35,7.600,-0.05174,0.730,-0.001
4.37,7.700,-0.05161,0.734,-0.001
4.40,7.800,-0.05145,0.740,-0.001
4.41,7.900,-0.05132,0.742,-0.001
4.42,8.000,-0.05120,0.743,-0.001
4.45,8.100,-0.05103,0.748,-0.001
4.47,8.200,-0.05091,0.751,-0.001
4.48,8.300,-0.05074,0.753,-0.001
4.51,8.400,-0.05057,0.757,-0.001
4.52,8.500,-0.05045,0.760,-0.001
4.55,8.600,-0.05028,0.765,-0.001
4.56,8.700,-0.05012,0.766,-0.001
4.58,8.800,-0.04995,0.769,-0.001
4.59,8.900,-0.04982,0.771,-0.001
4.61,9.000,-0.04966,0.775,-0.001
4.61,9.100,-0.04949,0.775,-0.001
4.63,9.200,-0.04933,0.777,-0.001
4.64,9.300,-0.04916,0.780,-0.001
4.66,9.400,-0.04904,0.783,-0.001
4.67,9.500,-0.04887,0.785,-0.001
4.70,9.600,-0.04870,0.790,-0.001
4.72,9.700,-0.04854,0.793,-0.001
4.73,9.800,-0.04833,0.794,-0.001
4.74,9.900,-0.04816,0.797,-0.001
4.77,10.000,-0.04800,0.801,-0.001
4.79,10.100,-0.04779,0.805,-0.001
4.83,10.200,-0.04758,0.812,-0.001
4.87,10.300,-0.04737,0.819,-0.001
4.91,10.400,-0.04717,0.825,-0.001
4.93,10.500,-0.04696,0.829,-0.001
4.98,10.600,-0.04675,0.836,-0.001
5.01,10.700,-0.04650,0.841,-0.001
5.03,10.800,-0.04629,0.845,-0.001
5.07,10.900,-0.04608,0.851,-0.001
5.09,11.000,-0.04588,0.855,-0.001
5.12,11.100,-0.04567,0.860,-0.001
5.14,11.200,-0.04546,0.863,-0.001
5.20,11.300,-0.04525,0.874,-0.001
5.22,11.400,-0.04509,0.878,-0.001
5.25,11.500,-0.04488,0.882,-0.001
5.28,11.600,-0.04471,0.887,-0.001
5.29,11.700,-0.04455,0.889,-0.001
5.31,11.800,-0.04438,0.891,-0.001
5.33,11.900,-0.04421,0.895,-0.001
5.36,12.000,-0.04405,0.900,-0.001
5.39,12.100,-0.04388,0.905,-0.001
5.41,12.200,-0.04376,0.908,-0.001
5.43,12.300,-0.04359,0.913,-0.001
5.44,12.400,-0.04343,0.914,-0.001
5.47,12.500,-0.04330,0.919,-0.001
5.47,12.600,-0.04318,0.920,-0.001
5.52,12.700,-0.04301,0.928,-0.001
5.54,12.800,-0.04288,0.931,-0.001
5.55,12.900,-0.04276,0.933,-0.001
5.57,13.000,-0.04264,0.935,-0.001
5.60,13.100,-0.04247,0.940,-0.001
5.61,13.200,-0.04234,0.942,-0.001
5.62,13.300,-0.04218,0.944,-0.001
5.66,13.400,-0.04205,0.951,-0.001
5.68,13.500,-0.04193,0.954,-0.001
5.72,13.600,-0.04176,0.960,-0.001
5.72,13.700,-0.04160,0.961,-0.001
5.75,13.800,-0.04147,0.966,-0.001
5.77,13.900,-0.04131,0.969,-0.001
5.79,14.000,-0.04118,0.973,-0.001
5.81,14.100,-0.04101,0.977,-0.001
5.84,14.200,-0.04085,0.980,-0.001
5.86,14.300,-0.04068,0.984,-0.001
5.87,14.400,-0.04052,0.986,-0.001
5.90,14.500,-0.04039,0.992,-0.001
5.90,14.600,-0.04023,0.992,-0.001
5.93,14.700,-0.04006,0.997,-0.001
5.96,14.800,-0.03989,1.002,-0.001
5.98,14.900,-0.03973,1.004,-0.001
5.99,15.000,-0.03956,1.007,-0.001
6.01,15.100,-0.03939,1.009,-0.001
6.04,15.200,-0.03923,1.014,-0.001
6.05,15.300,-0.03906,1.016,-0.001
6.05,15.400,-0.03890,1.017,-0.001
6.07,15.500,-0.03869,1.019,-0.001
6.11,15.600,-0.03852,1.026,-0.001
6.12,15.700,-0.03831,1.028,-0.001
6.13,15.800,-0.03811,1.030,-0.001
6.15,15.900,-0.03790,1.034,-0.001
6.19,16.000,-0.03769,1.039,-0.001
6.20,16.100,-0.03748,1.042,-0.001
6.23,16.200,-0.03727,1.046,-0.001
6.25,16.300,-0.03707,1.050,-0.001
6.27,16.400,-0.03686,1.053,-0.001
6.27,16.500,-0.03665,1.053,-0.001
6.32,16.600,-0.03644,1.062,-0.001
6.31,16.700,-0.03624,1.061,-0.001
6.34,16.800,-0.03603,1.066,-0.001
6.36,16.900,-0.03582,1.069,-0.001
6.40,17.000,-0.03565,1.075,-0.001
6.41,17.100,-0.03545,1.077,-0.001
6.43,17.200,-0.03528,1.081,-0.001
6.43,17.300,-0.03511,1.081,-0.001
6.48,17.400,-0.03491,1.088,-0.001
6.46,17.500,-0.03478,1.086,-0.001
6.51,17.600,-0.03462,1.094,-0.001
6.51,17.700,-0.03445,1.095,-0.001
6.54,17.800,-0.03428,1.098,-0.001
6.53,17.900,-0.03412,1.098,-0.001
6.57,18.000,-0.03399,1.104,-0.001
6.56,18.100,-0.03383,1.102,-0.001
6.59,18.200,-0.03370,1.107,-0.001
6.60,18.300,-0.03358,1.109,-0.001
6.62,18.400,-0.03341,1.113,-0.001
6.65,18.500,-0.03329,1.118,-0.001
6.67,18.600,-0.03316,1.120,-0.001
6.68,18.700,-0.03299,1.122,-0.001
6.70,18.800,-0.03287,1.126,-0.001
6.71,18.900,-0.03275,1.128,-0.001
6.73,19.000,-0.03258,1.131,-0.001
6.75,19.100,-0.03245,1.135,-0.001
6.79,19.200,-0.03233,1.141,-0.001
6.78,19.300,-0.03216,1.140,-0.001
6.82,19.400,-0.03204,1.146,-0.001
6.84,19.500,-0.03187,1.149,-0.001
6.86,19.600,-0.03175,1.152,-0.001
6.88,19.700,-0.03158,1.155,-0.001
6.91,19.800,-0.03146,1.162,-0.001
6.93,19.900,-0.03129,1.164,-0.001
6.96,20.000,-0.03112,1.170,-0.001
6.99,20.100,-0.03096,1.174,-0.001
7.00,20.200,-0.03083,1.176,-0.001
7.01,20.300,-0.03067,1.177,-0.001
7.04,20.400,-0.03050,1.183,-0.001
7.06,20.500,-0.03034,1.186,-0.001
7.09,20.600,-0.03021,1.191,-0.001
7.10,20.700,-0.03004,1.193,-0.001
7.12,20.800,-0.02988,1.196,-0.001
7.16,20.900,-0.02971,1.203,-0.001
7.19,21.000,-0.02955,1.207,-0.001
7.20,21.100,-0.02938,1.210,-0.001
7.25,21.200,-0.02917,1.218,-0.001
7.28,21.300,-0.02901,1.223,-0.001
7.32,21.400,-0.02880,1.230,-0.001
7.34,21.500,-0.02863,1.233,-0.001
7.37,21.600,-0.02842,1.237,-0.001
7.40,21.700,-0.02817,1.244,-0.001
7.45,21.800,-0.02797,1.252,-0.001
7.49,21.900,-0.02776,1.258,-0.001
7.53,22.000,-0.02755,1.265,-0.001
7.55,22.100,-0.02734,1.268,-0.001
7.57,22.200,-0.02709,1.272,-0.001
7.59,22.300,-0.02689,1.275,-0.001
7.65,22.400,-0.02668,1.285,-0.001
7.67,22.500,-0.02647,1.288,-0.001
7.69,22.600,-0.02630,1.293,-0.001
7.71,22.700,-0.02610,1.296,-0.001
7.75,22.800,-0.02593,1.302,-0.001
7.78,22.900,-0.02576,1.307,-0.001
7.80,23.000,-0.02560,1.311,-0.001
7.82,23.100,-0.02543,1.313,-0.001
7.83,23.200,-0.02527,1.316,0.000
7.87,23.300,-0.02510,1.322,0.000
7.88,23.400,-0.02497,1.323,0.000
7.91,23.500,-0.02481,1.329,0.000
7.92,23.600,-0.02468,1.331,0.000
7.95,23.700,-0.02452,1.335,0.000
7.95,23.800,-0.02439,1.336,0.000
7.98,23.900,-0.02427,1.340,0.000
7.97,24.000,-0.02414,1.340,0.000
8.00,24.100,-0.02398,1.345,0.000
8.03,24.200,-0.02385,1.349,0.000
8.04,24.300,-0.02373,1.351,0.000
8.05,24.400,-0.02360,1.353,0.000
8.08,24.500,-0.02344,1.358,0.000
8.09,24.600,-0.02331,1.360,0.000
8.13,24.700,-0.02319,1.366,0.000
8.15,24.800,-0.02302,1.369,0.000
8.17,24.900,-0.02290,1.372,0.000
8.19,25.000,-0.02277,1.377,0.000
8.21,25.100,-0.02261,1.379,0.000
8.22,25.200,-0.02244,1.382,0.000
8.26,25.300,-0.02231,1.387,0.000
8.27,25.400,-0.02215,1.390,0.000
8.29,25.500,-0.02202,1.393,0.000
8.31,25.600,-0.02186,1.395,0.000
8.35,25.700,-0.02173,1.402,0.000
8.36,25.800,-0.02157,1.404,0.000
8.38,25.900,-0.02140,1.407,0.000
8.39,26.000,-0.02123,1.410,0.000
8.43,26.100,-0.02111,1.416,0.000
8.44,26.200,-0.02094,1.419,0.000
8.48,26.300,-0.02078,1.424,0.000
8.48,26.400,-0.02061,1.425,0.000
8.52,26.500,-0.02044,1.432,0.000
8.53,26.600,-0.02028,1.434,0.000
8.58,26.700,-0.02011,1.442,0.000
8.59,26.800,-0.01995,1.443,0.000
8.62,26.900,-0.01978,1.449,0.000
8.66,27.000,-0.01957,1.455,0.000
8.70,27.100,-0.01936,1.462,0.000
8.73,27.200,-0.01920,1.467,0.000
8.75,27.300,-0.01899,1.471,0.000
8.79,27.400,-0.01874,1.477,0.000
8.83,27.500,-0.01853,1.483,0.000
8.86,27.600,-0.01833,1.488,0.000
8.92,27.700,-0.01812,1.498,0.000
8.93,27.800,-0.01787,1.500,0.000
8.96,27.900,-0.01766,1.506,0.000
8.98,28.000,-0.01745,1.509,0.000
9.02,28.100,-0.01724,1.516,0.000
9.04,28.200,-0.01704,1.519,0.000
9.09,28.300,-0.01687,1.527,0.000
9.10,28.400,-0.01666,1.529,0.000
9.13,28.500,-0.01646,1.533,0.000
9.14,28.600,-0.01629,1.536,0.000
9.19,28.700,-0.01612,1.544,0.000
9.20,28.800,-0.01596,1.545,0.000
9.21,28.900,-0.01583,1.547,0.000
9.23,29.000,-0.01567,1.550,0.000
9.25,29.100,-0.01550,1.554,0.000
9.28,29.200,-0.01537,1.559,0.000
9.31,29.300,-0.01521,1.565,0.000
9.31,29.400,-0.01504,1.565,0.000
9.34,29.500,-0.01492,1.570,0.000
9.36,29.600,-0.01479,1.573,0.000
9.39,29.700,-0.01467,1.578,0.000
9.42,29.800,-0.01450,1.582,0.000
9.44,29.900,-0.01438,1.585,0.000
9.46,30.000,-0.01425,1.590,0.000
9.49,30.100,-0.01413,1.595,0.000
9.51,30.200,-0.01396,1.598,0.000
9.54,30.300,-0.01384,1.602,0.000
9.56,30.400,-0.01367,1.606,0.000
9.58,30.500,-0.01355,1.610,0.000
9.61,30.600,-0.01342,1.614,0.000
9.64,30.700,-0.01326,1.619,0.000
9.65,30.800,-0.01309,1.622,0.000
9.69,30.900,-0.01296,1.628,0.000
9.72,31.000,-0.01280,1.634,0.000
9.75,31.100,-0.01263,1.638,0.000
9.79,31.200,-0.01251,1.644,0.000
9.80,31.300,-0.01234,1.647,0.000
9.84,31.400,-0.01218,1.654,0.000
9.85,31.500,-0.01205,1.655,0.000
9.90,31.600,-0.01188,1.663,0.000
9.92,31.700,-0.01172,1.666,0.000
9.96,31.800,-0.01155,1.673,0.000
9.98,31.900,-0.01139,1.676,0.000
10.02,32.000,-0.01126,1.683,0.000
10.03,32.100,-0.01109,1.686,0.000
10.08,32.200,-0.01093,1.694,0.000
10.09,32.300,-0.01076,1.695,0.000
10.14,32.400,-0.01060,1.704,0.000
10.15,32.500,-0.01039,1.706,0.000
10.21,32.600,-0.01022,1.716,0.000
10.24,32.700,-0.01001,1.720,0.000
10.30,32.800,-0.00985,1.730,0.000
10.32,32.900,-0.00964,1.733,0.000
10.38,33.000,-0.00943,1.743,0.000
10.43,33.100,-0.00922,1.752,0.000
10.47,33.200,-0.00902,1.759,0.000
10.52,33.300,-0.00881,1.767,0.000
10.56,33.400,-0.00860,1.774,0.000
10.59,33.500,-0.00839,1.780,0.000
10.64,33.600,-0.00819,1.788,0.000
10.69,33.700,-0.00798,1.796,0.000
10.71,33.800,-0.00777,1.800,0.000
10.75,33.900,-0.00756,1.806,0.000
10.79,34.000,-0.00735,1.813,0.000
10.83,34.100,-0.00719,1.819,0.000
10.86,34.200,-0.00698,1.825,0.000
10.89,34.300,-0.00681,1.829,0.000
10.94,34.400,-0.00665,1.838,0.000
10.95,34.500,-0.00648,1.839,0.000
11.00,34.600,-0.00632,1.849,0.000
11.03,34.700,-0.00615,1.853,0.000
11.04,34.800,-0.00602,1.856,0.000
11.08,34.900,-0.00586,1.862,0.000
11.11,35.000,-0.00573,1.867,0.000
11.14,35.100,-0.00557,1.872,0.000
11.16,35.200,-0.00544,1.874,0.000
11.18,35.300,-0.00528,1.878,0.000
11.22,35.400,-0.00515,1.885,0.000
11.23,35.500,-0.00503,1.887,0.000
11.26,35.600,-0.00486,1.892,0.000
11.27,35.700,-0.00474,1.894,0.000
11.32,35.800,-0.00461,1.902,0.000
11.34,35.900,-0.00449,1.906,0.000
11.38,36.000,-0.00432,1.911,0.000
11.42,36.100,-0.00420,1.918,0.000
11.45,36.200,-0.00403,1.923,0.000
11.47,36.300,-0.00391,1.928,0.000
11.50,36.400,-0.00374,1.933,0.000
11.54,36.500,-0.00361,1.938,0.000
11.59,36.600,-0.00345,1.947,0.000
11.61,36.700,-0.00332,1.950,0.000
11.66,36.800,-0.00316,1.959,0.000
11.68,36.900,-0.00299,1.963,0.000
11.72,37.000,-0.00287,1.969,0.000
11.75,37.100,-0.00270,1.973,0.000
11.77,37.200,-0.00253,1.978,0.000
11.82,37.300,-0.00241,1.986,0.000
11.85,37.400,-0.00224,1.991,0.000
11.90,37.500,-0.00208,1.999,0.000
11.94,37.600,-0.00191,2.007,0.000
11.96,37.700,-0.00179,2.009,0.000
12.01,37.800,-0.00162,2.019,0.000
12.05,37.900,-0.00145,2.024,0.000
12.08,38.000,-0.00129,2.030,0.000
12.13,38.100,-0.00112,2.037,0.000
12.18,38.200,-0.00091,2.046,0.000
12.22,38.300,-0.00075,2.053,0.000
12.27,38.400,-0.00054,2.061,0.000
12.32,38.500,-0.00033,2.070,0.000
12.36,38.600,-0.00012,2.077,0.000
12.43,38.700,0.00008,2.088,0.000
12.46,38.800,0.00029,2.093,0.000
12.52,38.900,0.00050,2.103,0.000
12.57,39.000,0.00071,2.111,0.000
12.62,39.100,0.00096,2.121,0.000
12.68,39.200,0.00116,2.131,0.000
12.74,39.300,0.00137,2.141,0.000
12.78,39.400,0.00158,2.146,0.000
12.83,39.500,0.00179,2.156,0.000
12.87,39.600,0.00200,2.162,0.000
12.93,39.700,0.00220,2.172,0.000
12.94,39.800,0.00241,2.175,0.000
12.99,39.900,0.00258,2.182,0.000
13.01,40.000,0.00274,2.185,0.000
13.07,40.100,0.00291,2.195,0.000
13.11,40.200,0.00308,2.202,0.000
13.15,40.300,0.00324,2.209,0.000
13.18,40.400,0.00341,2.214,0.000
13.23,40.500,0.00357,2.223,0.000
13.25,40.600,0.00370,2.226,0.000
13.29,40.700,0.00382,2.233,0.000
13.32,40.800,0.00399,2.238,0.000
13.35,40.900,0.00411,2.243,0.000
13.36,41.000,0.00428,2.244,0.000
13.41,41.100,0.00441,2.253,0.000
13.43,41.200,0.00453,2.256,0.000
13.46,41.300,0.00466,2.262,0.000
13.50,41.400,0.00482,2.268,0.000
13.53,41.500,0.00495,2.273,0.000
13.57,41.600,0.00507,2.280,0.000
13.60,41.700,0.00524,2.285,0.000
13.64,41.800,0.00536,2.292,0.000
13.68,41.900,0.00553,2.298,0.000
13.72,42.000,0.00565,2.305,0.000
13.77,42.100,0.00582,2.314,0.000
13.81,42.200,0.00594,2.320,0.000
13.86,42.300,0.00611,2.329,0.000
13.89,42.400,0.00628,2.334,0.000
13.93,42.500,0.00640,2.340,0.000
13.97,42.600,0.00657,2.348,0.000
14.02,42.700,0.00673,2.355,0.000
14.04,42.800,0.00686,2.360,0.000
14.09,42.900,0.00702,2.368,0.000
14.13,43.000,0.00719,2.374,0.000
14.18,43.100,0.00736,2.383,0.000
14.22,43.200,0.00752,2.388,0.000
14.26,43.300,0.00765,2.396,0.000
14.29,43.400,0.00781,2.400,0.000
14.35,43.500,0.00798,2.411,0.000
14.38,43.600,0.00815,2.415,0.000
14.45,43.700,0.00831,2.428,0.000
14.48,43.800,0.00848,2.433,0.000
14.53,43.900,0.00869,2.442,0.000
14.59,44.000,0.00885,2.451,0.000
14.65,44.100,0.00906,2.461,0.000
14.69,44.200,0.00927,2.468,0.000
14.76,44.300,0.00948,2.480,0.000
14.82,44.400,0.00968,2.489,0.000
14.87,44.500,0.00989,2.499,0.000
14.94,44.600,0.01014,2.510,0.000
15.00,44.700,0.01035,2.520,0.000
15.06,44.800,0.01056,2.530,0.000
15.11,44.900,0.01076,2.539,0.000
15.17,45.000,0.01097,2.548,0.000
15.23,45.100,0.01118,2.559,0.000
15.27,45.200,0.01139,2.565,0.000
15.34,45.300,0.01159,2.578,0.000
15.37,45.400,0.01180,2.583,0.000
15.42,45.500,0.01197,2.591,0.000
15.47,45.600,0.01218,2.599,0.000
15.51,45.700,0.01234,2.606,0.000
15.55,45.800,0.01251,2.612,0.000
15.58,45.900,0.01263,2.618,0.000
15.64,46.000,0.01280,2.628,0.000
15.68,46.100,0.01297,2.634,0.000
15.72,46.200,0.01309,2.641,0.000
15.75,46.300,0.01326,2.646,0.000
15.79,46.400,0.01342,2.653,0.000
15.82,46.500,0.01355,2.658,0.000
15.87,46.600,0.01367,2.666,0.000
15.90,46.700,0.01384,2.671,0.000
15.94,46.800,0.01396,2.678,0.000
15.99,46.900,0.01409,2.686,0.000
16.02,47.000,0.01421,2.691,0.000
16.06,47.100,0.01438,2.698,0.000
16.11,47.200,0.01450,2.706,0.000
16.13,47.300,0.01467,2.709,0.000
16.19,47.400,0.01479,2.720,0.000
16.23,47.500,0.01496,2.728,0.000
16.29,47.600,0.01509,2.737,0.000
16.32,47.700,0.01525,2.741,0.000
16.36,47.800,0.01538,2.749,0.000
16.41,47.900,0.01554,2.757,0.000
16.45,48.000,0.01571,2.764,0.000
16.49,48.100,0.01588,2.771,0.000
16.56,48.200,0.01600,2.783,0.000
16.58,48.300,0.01617,2.785,0.000
16.63,48.400,0.01633,2.795,0.000
16.68,48.500,0.01646,2.802,0.000
16.71,48.600,0.01662,2.808,0.000
16.77,48.700,0.01679,2.818,0.000
16.84,48.800,0.01696,2.828,0.000
16.86,48.900,0.01708,2.833,0.000
16.92,49.000,0.01725,2.843,0.000
16.97,49.100,0.01741,2.852,0.000
17.02,49.200,0.01758,2.860,0.000
17.07,49.300,0.01775,2.868,0.000
17.13,49.400,0.01791,2.878,0.000
17.17,49.500,0.01812,2.885,0.000
17.24,49.600,0.01829,2.896,0.000
17.29,49.700,0.01849,2.905,0.000
17.36,49.800,0.01870,2.916,0.000
17.42,49.900,0.01887,2.927,0.000
17.49,50.000,0.01912,2.939,0.000
17.57,50.100,0.01932,2.952,0.000
17.64,50.200,0.01953,2.964,0.000
17.70,50.300,0.01974,2.975,0.000
17.76,50.400,0.01995,2.984,0.000
17.84,50.500,0.02016,2.997,0.000
17.91,50.600,0.02036,3.009,0.000
17.96,50.700,0.02057,3.017,0.000
18.02,50.800,0.02078,3.027,0.000
18.08,50.900,0.02099,3.037,0.000
18.15,51.000,0.02119,3.050,0.000
18.20,51.100,0.02136,3.058,0.000
18.25,51.200,0.02157,3.067,0.000
18.29,51.300,0.02173,3.073,0.000
18.37,51.400,0.02190,3.086,0.000
18.43,51.500,0.02207,3.096,0.000
18.46,51.600,0.02219,3.101,0.000
18.51,51.700,0.02236,3.110,0.000
18.55,51.800,0.02252,3.117,0.000
18.60,51.900,0.02265,3.125,0.000
18.64,52.000,0.02281,3.131,0.000
18.68,52.100,0.02294,3.139,0.000
18.73,52.200,0.02311,3.147,0.000
18.77,52.300,0.02323,3.153,0.000
18.82,52.400,0.02336,3.162,0.000
18.86,52.500,0.02348,3.170,0.000
18.90,52.600,0.02365,3.176,0.000
18.94,52.700,0.02377,3.182,0.000
18.99,52.800,0.02390,3.191,0.000
19.02,52.900,0.02406,3.196,0.000
19.09,53.000,0.02419,3.207,0.000
19.13,53.100,0.02431,3.215,0.000
19.18,53.200,0.02448,3.223,0.000
19.23,53.300,0.02460,3.231,0.000
19.30,53.400,0.02477,3.242,0.000
19.33,53.500,0.02489,3.248,0.000
19.37,53.600,0.02506,3.254,0.000
19.43,53.700,0.02518,3.264,0.000
19.47,53.800,0.02535,3.272,0.000
19.54,53.900,0.02552,3.284,0.001
19.59,54.000,0.02564,3.292,0.001
19.63,54.100,0.02581,3.299,0.001
19.70,54.200,0.02597,3.310,0.001
19.74,54.300,0.02610,3.317,0.001
19.79,54.400,0.02626,3.324,0.001
19.83,54.500,0.02643,3.332,0.001
19.90,54.600,0.02655,3.343,0.001
19.95,54.700,0.02672,3.351,0.001
20.02,54.800,0.02689,3.364,0.001
20.07,54.900,0.02705,3.372,0.001
20.13,55.000,0.02722,3.383,0.001
20.20,55.100,0.02739,3.393,0.001
20.26,55.200,0.02759,3.403,0.001
20.33,55.300,0.02776,3.415,0.001
20.41,55.400,0.02797,3.429,0.001
20.50,55.500,0.02818,3.443,0.001
20.56,55.600,0.02838,3.454,0.001
20.64,55.700,0.02859,3.468,0.001
20.74,55.800,0.02884,3.485,0.001
20.81,55.900,0.02905,3.496,0.001
20.90,56.000,0.02926,3.511,0.001
20.97,56.100,0.02951,3.523,0.001
21.06,56.200,0.02971,3.538,0.001
21.14,56.300,0.02992,3.552,0.001
21.21,56.400,0.03013,3.564,0.001
21.28,56.500,0.03034,3.576,0.001
21.36,56.600,0.03054,3.589,0.001
21.42,56.700,0.03071,3.599,0.001
21.47,56.800,0.03088,3.608,0.001
21.53,56.900,0.03108,3.617,0.001
21.58,57.000,0.03125,3.625,0.001
21.65,57.100,0.03142,3.638,0.001
21.70,57.200,0.03154,3.646,0.001
21.76,57.300,0.03171,3.656,0.001
21.79,57.400,0.03183,3.661,0.001
21.85,57.500,0.03200,3.670,0.001
21.91,57.600,0.03212,3.681,0.001
21.95,57.700,0.03229,3.688,0.001
21.99,57.800,0.03241,3.695,0.001
22.03,57.900,0.03254,3.702,0.001
22.08,58.000,0.03271,3.710,0.001
22.12,58.100,0.03283,3.716,0.001
22.18,58.200,0.03295,3.726,0.001
22.23,58.300,0.03308,3.735,0.001
22.28,58.400,0.03320,3.743,0.001
22.34,58.500,0.03337,3.753,0.001
22.37,58.600,0.03349,3.759,0.001
22.44,58.700,0.03362,3.771,0.001
22.48,58.800,0.03379,3.777,0.001
22.56,58.900,0.03391,3.790,0.001
22.60,59.000,0.03408,3.797,0.001
22.66,59.100,0.03420,3.808,0.001
22.74,59.200,0.03437,3.820,0.001
22.78,59.300,0.03453,3.827,0.001
22.85,59.400,0.03466,3.839,0.001
22.91,59.500,0.03482,3.849,0.001
22.97,59.600,0.03499,3.859,0.001
23.03,59.700,0.03512,3.869,0.001
23.09,59.800,0.03528,3.879,0.001
23.17,59.900,0.03541,3.893,0.001
23.23,60.000,0.03557,3.903,0.001
23.28,60.100,0.03574,3.911,0.001
23.34,60.200,0.03591,3.922,0.001
23.41,60.300,0.03607,3.933,0.001
23.48,60.400,0.03624,3.944,0.001
23.53,60.500,0.03636,3.953,0.001
23.60,60.600,0.03653,3.965,0.001
23.68,60.700,0.03669,3.978,0.001
23.74,60.800,0.03690,3.988,0.001
23.81,60.900,0.03707,4.001,0.001
23.93,61.000,0.03728,4.020,0.001
24.01,61.100,0.03748,4.034,0.001
24.08,61.200,0.03769,4.046,0.001
24.18,61.300,0.03790,4.063,0.001
24.29,61.400,0.03811,4.080,0.001
24.37,61.500,0.03832,4.095,0.001
24.46,61.600,0.03852,4.110,0.001
24.57,61.700,0.03873,4.127,0.001
24.64,61.800,0.03898,4.139,0.001
24.72,61.900,0.03919,4.153,0.001
24.82,62.000,0.03940,4.170,0.001
24.89,62.100,0.03956,4.182,0.001
24.96,62.200,0.03977,4.194,0.001
25.04,62.300,0.03998,4.207,0.001
25.15,62.400,0.04014,4.225,0.001
25.22,62.500,0.04035,4.237,0.001
25.27,62.600,0.04052,4.245,0.001
25.34,62.700,0.04068,4.257,0.001
25.41,62.800,0.04085,4.269,0.001
25.47,62.900,0.04102,4.279,0.001
25.53,63.000,0.04114,4.289,0.001
25.59,63.100,0.04131,4.299,0.001
25.64,63.200,0.04147,4.308,0.001
25.70,63.300,0.04160,4.318,0.001
25.76,63.400,0.04172,4.329,0.001
25.80,63.500,0.04189,4.334,0.001
25.86,63.600,0.04201,4.344,0.001
25.93,63.700,0.04214,4.356,0.001
25.98,63.800,0.04230,4.365,0.001
26.01,63.900,0.04243,4.369,0.001
26.08,64.000,0.04255,4.381,0.001
26.12,64.100,0.04268,4.389,0.001
26.17,64.200,0.04280,4.396,0.001
26.23,64.300,0.04293,4.407,0.001
26.30,64.400,0.04309,4.419,0.001
26.37,64.500,0.04322,4.430,0.001
26.46,64.600,0.04339,4.445,0.001
26.50,64.700,0.04351,4.452,0.001
26.59,64.800,0.04368,4.468,0.001
26.65,64.900,0.04380,4.478,0.001
26.71,65.000,0.04397,4.488,0.001
26.78,65.100,0.04413,4.499,0.001
26.86,65.200,0.04426,4.513,0.001
26.92,65.300,0.04442,4.523,0.001
26.99,65.400,0.04455,4.535,0.001
27.07,65.500,0.04471,4.547,0.001
27.15,65.600,0.04488,4.562,0.001
27.22,65.700,0.04505,4.573,0.001
27.30,65.800,0.04517,4.587,0.001
27.35,65.900,0.04534,4.595,0.001
27.41,66.000,0.04546,4.606,0.001
27.49,66.100,0.04563,4.618,0.001
27.60,66.200,0.04580,4.636,0.001
27.66,66.300,0.04596,4.647,0.001
27.74,66.400,0.04613,4.661,0.001
27.82,66.500,0.04629,4.675,0.001
27.90,66.600,0.04646,4.688,0.001
27.98,66.700,0.04667,4.700,0.001
28.06,66.800,0.04683,4.715,0.001
28.17,66.900,0.04704,4.733,0.001
28.26,67.000,0.04725,4.748,0.001
28.35,67.100,0.04742,4.764,0.001
28.45,67.200,0.04762,4.780,0.001
28.55,67.300,0.04783,4.796,0.001
28.66,67.400,0.04804,4.814,0.001
28.74,67.500,0.04825,4.829,0.001
28.84,67.600,0.04845,4.846,0.001
28.93,67.700,0.04866,4.860,0.001
29.03,67.800,0.04887,4.878,0.001
29.13,67.900,0.04908,4.894,0.001
29.21,68.000,0.04924,4.908,0.001
29.30,68.100,0.04945,4.923,0.001
29.40,68.200,0.04962,4.939,0.001
29.46,68.300,0.04983,4.950,0.001
29.56,68.400,0.04999,4.966,0.001
29.64,68.500,0.05016,4.980,0.001
29.72,68.600,0.05032,4.994,0.001
29.79,68.700,0.05049,5.005,0.001
29.86,68.800,0.05066,5.016,0.001
29.92,68.900,0.05078,5.028,0.001
30.00,69.000,0.05095,5.040,0.001
30.06,69.100,0.05107,5.050,0.001
30.12,69.200,0.05124,5.061,0.001
30.20,69.300,0.05136,5.074,0.001
30.26,69.400,0.05149,5.084,0.001
30.32,69.500,0.05165,5.094,0.001
30.39,69.600,0.05178,5.106,0.001
30.45,69.700,0.05190,5.116,0.001
30.51,69.800,0.05203,5.125,0.001
30.56,69.900,0.05215,5.135,0.001
30.62,70.000,0.05232,5.144,0.001
30.70,70.100,0.05244,5.158,0.001
30.77,70.200,0.05257,5.170,0.001
30.84,70.300,0.05269,5.181,0.001
30.91,70.400,0.05286,5.194,0.001
31.01,70.500,0.05298,5.209,0.001
31.06,70.600,0.05315,5.218,0.001
31.14,70.700,0.05328,5.233,0.001
31.22,70.800,0.05344,5.246,0.001
31.30,70.900,0.05357,5.258,0.001
31.36,71.000,0.05373,5.269,0.001
31.46,71.100,0.05390,5.286,0.001
31.53,71.200,0.05402,5.297,0.001
31.61,71.300,0.05419,5.311,0.001
31.67,71.400,0.05431,5.321,0.001
31.76,71.500,0.05448,5.336,0.001
31.82,71.600,0.05465,5.346,0.001
31.91,71.700,0.05481,5.361,0.001
31.99,71.800,0.05494,5.375,0.001
32.09,71.900,0.05510,5.391,0.001
32.15,72.000,0.05527,5.402,0.001
32.24,72.100,0.05544,5.417,0.001
32.33,72.200,0.05560,5.431,0.001
32.42,72.300,0.05577,5.448,0.001
32.53,72.400,0.05598,5.465,0.001
32.63,72.500,0.05614,5.482,0.001
32.75,72.600,0.05635,5.502,0.001
32.86,72.700,0.05656,5.521,0.001
32.96,72.800,0.05677,5.538,0.001
33.08,72.900,0.05697,5.558,0.001
33.19,73.000,0.05718,5.577,0.001
33.32,73.100,0.05739,5.598,0.001
33.44,73.200,0.05764,5.618,0.001
33.56,73.300,0.05785,5.638,0.001
33.65,73.400,0.05805,5.654,0.001
33.78,73.500,0.05826,5.675,0.001
33.89,73.600,0.05847,5.694,0.001
34.01,73.700,0.05868,5.715,0.001
34.10,73.800,0.05889,5.730,0.001
34.20,73.900,0.05905,5.746,0.001
34.31,74.000,0.05926,5.764,0.001
34.39,74.100,0.05943,5.778,0.001
34.46,74.200,0.05959,5.789,0.001
34.55,74.300,0.05976,5.804,0.001
34.63,74.400,0.05992,5.818,0.001
34.71,74.500,0.06005,5.832,0.001
34.77,74.600,0.06022,5.842,0.001
34.86,74.700,0.06034,5.857,0.001
34.92,74.800,0.06051,5.867,0.001
34.99,74.900,0.06063,5.878,0.001
35.05,75.000,0.06076,5.890,0.001
35.14,75.100,0.06092,5.904,0.001
35.19,75.200,0.06105,5.912,0.001
35.28,75.300,0.06117,5.927,0.001
35.35,75.400,0.06130,5.939,0.001
35.43,75.500,0.06146,5.952,0.001
35.50,75.600,0.06159,5.964,0.001
35.58,75.700,0.06171,5.978,0.001
35.67,75.800,0.06188,5.992,0.001
35.75,75.900,0.06200,6.007,0.001
35.82,76.000,0.06217,6.017,0.001
35.91,76.100,0.06229,6.033,0.001
36.02,76.200,0.06246,6.051,0.001
36.09,76.300,0.06263,6.064,0.001
36.17,76.400,0.06275,6.076,0.001
36.26,76.500,0.06292,6.092,0.001
36.34,76.600,0.06308,6.106,0.001
36.42,76.700,0.06321,6.119,0.001
36.50,76.800,0.06337,6.132,0.001
36.59,76.900,0.06354,6.148,0.001
36.68,77.000,0.06366,6.163,0.001
36.77,77.100,0.06383,6.178,0.001
36.85,77.200,0.06400,6.191,0.001
36.95,77.300,0.06416,6.208,0.001
37.03,77.400,0.06433,6.221,0.001
37.12,77.500,0.06445,6.237,0.001
37.20,77.600,0.06462,6.251,0.001
37.31,77.700,0.06479,6.268,0.001
37.41,77.800,0.06495,6.286,0.001
37.51,77.900,0.06512,6.302,0.001
37.61,78.000,0.06533,6.319,0.001
37.72,78.100,0.06549,6.338,0.001
37.84,78.200,0.06570,6.358,0.001
37.97,78.300,0.06591,6.380,0.001
38.09,78.400,0.06612,6.399,0.001
38.19,78.500,0.06632,6.417,0.001
38.33,78.600,0.06653,6.441,0.001
38.48,78.700,0.06674,6.465,0.001
38.62,78.800,0.06699,6.489,0.001
38.79,78.900,0.06724,6.517,0.001
38.93,79.000,0.06745,6.540,0.001
39.03,79.100,0.06765,6.558,0.001
39.16,79.200,0.06790,6.579,0.001
39.27,79.300,0.06811,6.598,0.001
39.40,79.400,0.06832,6.619,0.001
39.50,79.500,0.06848,6.637,0.001
39.61,79.600,0.06869,6.655,0.001
39.70,79.700,0.06886,6.669,0.001
39.79,79.800,0.06903,6.685,0.001
39.88,79.900,0.06919,6.700,0.001
39.98,80.000,0.06936,6.717,0.001
40.03,80.100,0.06952,6.726,0.001
40.13,80.200,0.06965,6.742,0.001
40.18,80.300,0.06981,6.751,0.001
40.28,80.400,0.06998,6.767,0.001
40.34,80.500,0.07011,6.778,0.001
40.42,80.600,0.07023,6.791,0.001
40.49,80.700,0.07040,6.803,0.001
40.57,80.800,0.07052,6.816,0.001
40.65,80.900,0.07065,6.829,0.001
40.72,81.000,0.07081,6.842,0.001
40.80,81.100,0.07094,6.854,0.001
40.87,81.200,0.07106,6.867,0.001
40.95,81.300,0.07123,6.880,0.001
41.05,81.400,0.07135,6.897,0.001
41.13,81.500,0.07152,6.910,0.001
41.20,81.600,0.07164,6.922,0.001
41.29,81.700,0.07181,6.937,0.001
41.40,81.800,0.07193,6.955,0.001
41.48,81.900,0.07210,6.968,0.001
41.59,82.000,0.07227,6.987,0.001
41.66,82.100,0.07239,6.999,0.001
41.76,82.200,0.07256,7.016,0.001
41.83,82.300,0.07272,7.028,0.001
41.93,82.400,0.07289,7.044,0.001
42.03,82.500,0.07306,7.062,0.001
42.13,82.600,0.07322,7.079,0.001
42.21,82.700,0.07335,7.092,0.001
42.33,82.800,0.07351,7.112,0.001
42.40,82.900,0.07368,7.124,0.001
42.51,83.000,0.07385,7.142,0.001
42.59,83.100,0.07401,7.155,0.001
42.71,83.200,0.07418,7.176,0.001
42.80,83.300,0.07434,7.190,0.001
42.93,83.400,0.07451,7.213,0.001
43.03,83.500,0.07468,7.229,0.001
43.15,83.600,0.07488,7.250,0.001
43.27,83.700,0.07509,7.269,0.001
43.42,83.800,0.07530,7.295,0.001
43.54,83.900,0.07551,7.315,0.001
43.68,84.000,0.07572,7.338,0.001
43.80,84.100,0.07592,7.360,0.001
43.96,84.200,0.07613,7.385,0.001
44.08,84.300,0.07634,7.406,0.002
44.21,84.400,0.07659,7.428,0.002
44.33,84.500,0.07680,7.449,0.002
44.51,84.600,0.07700,7.478,0.002
20.19,84.700,0.07721,3.391,0.002
14.01,84.800,0.07742,2.354,0.002
13.72,84.900,0.07763,2.306,0.002
13.88,85.000,0.07783,2.332,0.002
14.09,85.100,0.07804,2.368,0.002
14.32,85.200,0.07821,2.406,0.002
14.55,85.300,0.07838,2.444,0.002
14.67,85.400,0.07858,2.465,0.002
14.84,85.500,0.07871,2.493,0.002
15.01,85.600,0.07887,2.522,0.002
15.14,85.700,0.07904,2.544,0.002
15.25,85.800,0.07921,2.563,0.002
15.40,85.900,0.07937,2.587,0.002
15.53,86.000,0.07950,2.610,0.002
15.68,86.100,0.07966,2.634,0.002
15.77,86.200,0.07979,2.650,0.002
15.87,86.300,0.07995,2.666,0.002
15.98,86.400,0.08008,2.685,0.002
16.07,86.500,0.08020,2.700,0.002
16.17,86.600,0.08033,2.716,0.002
16.25,86.700,0.08049,2.730,0.002
16.37,86.800,0.08062,2.751,0.002
16.47,86.900,0.08079,2.768,0.002
16.57,87.000,0.08091,2.784,0.002
16.65,87.100,0.08103,2.797,0.002
16.75,87.200,0.08120,2.815,0.002
16.85,87.300,0.08133,2.831,0.002
16.94,87.400,0.08149,2.846,0.002
17.03,87.500,0.08162,2.862,0.002
17.13,87.600,0.08178,2.878,0.002
17.23,87.700,0.08195,2.895,0.002
17.33,87.800,0.08207,2.912,0.002
17.40,87.900,0.08224,2.924,0.002
17.49,88.000,0.08241,2.939,0.002
17.58,88.100,0.08253,2.954,0.002
17.66,88.200,0.08270,2.966,0.002
17.74,88.300,0.08286,2.981,0.002
17.84,88.400,0.08303,2.997,0.002
17.93,88.500,0.08315,3.013,0.002
18.02,88.600,0.08332,3.028,0.002
18.09,88.700,0.08349,3.039,0.002
18.18,88.800,0.08365,3.055,0.002
18.28,88.900,0.08382,3.071,0.002
18.36,89.000,0.08399,3.085,0.002
18.45,89.100,0.08415,3.100,0.002
18.54,89.200,0.08432,3.115,0.002
18.65,89.300,0.08453,3.134,0.002
18.75,89.400,0.08473,3.149,0.002
18.86,89.500,0.08494,3.168,0.002
18.95,89.600,0.08515,3.184,0.002
19.06,89.700,0.08536,3.202,0.002
19.14,89.800,0.08556,3.216,0.002
19.26,89.900,0.08577,3.237,0.002
19.35,90.000,0.08602,3.251,0.002
19.46,90.100,0.08623,3.269,0.002
19.55,90.200,0.08644,3.284,0.002
19.64,90.300,0.08664,3.299,0.002
19.74,90.400,0.08685,3.316,0.002
19.82,90.500,0.08706,3.330,0.002
19.88,90.600,0.08723,3.340,0.002
19.95,90.700,0.08743,3.352,0.002
20.03,90.800,0.08760,3.365,0.002
20.11,90.900,0.08777,3.379,0.002
20.17,91.000,0.08797,3.389,0.002
20.24,91.100,0.08814,3.400,0.002
20.31,91.200,0.08827,3.412,0.002
20.36,91.300,0.08843,3.421,0.002
20.40,91.400,0.08860,3.427,0.002
20.47,91.500,0.08872,3.440,0.002
20.54,91.600,0.08889,3.451,0.002
20.58,91.700,0.08901,3.458,0.002
20.64,91.800,0.08914,3.467,0.002
20.68,91.900,0.08930,3.475,0.002
20.75,92.000,0.08943,3.486,0.002
20.79,92.100,0.08955,3.493,0.002
20.84,92.200,0.08968,3.501,0.002
20.89,92.300,0.08984,3.509,0.002
20.94,92.400,0.08997,3.519,0.002
21.01,92.500,0.09009,3.529,0.002
21.06,92.600,0.09026,3.538,0.002
21.13,92.700,0.09038,3.549,0.002
21.16,92.800,0.09051,3.555,0.002
21.21,92.900,0.09068,3.564,0.002
21.29,93.000,0.09080,3.577,0.002
21.33,93.100,0.09097,3.584,0.002
21.40,93.200,0.09109,3.595,0.002
21.45,93.300,0.09126,3.604,0.002
21.51,93.400,0.09142,3.614,0.002
21.58,93.500,0.09155,3.626,0.002
21.62,93.600,0.09171,3.633,0.002
21.70,93.700,0.09188,3.645,0.002
21.73,93.800,0.09205,3.651,0.002
21.80,93.900,0.09217,3.663,0.002
21.86,94.000,0.09234,3.672,0.002
21.92,94.100,0.09250,3.682,0.002
21.97,94.200,0.09267,3.691,0.002
22.02,94.300,0.09284,3.699,0.002
22.06,94.400,0.09296,3.707,0.002
22.15,94.500,0.09313,3.721,0.002
22.18,94.600,0.09334,3.727,0.002
22.25,94.700,0.09350,3.739,0.002
22.31,94.800,0.09367,3.749,0.002
22.39,94.900,0.09383,3.761,0.002
22.44,95.000,0.09404,3.771,0.002
22.53,95.100,0.09425,3.785,0.002
22.59,95.200,0.09446,3.795,0.002
22.66,95.300,0.09466,3.807,0.002
22.73,95.400,0.09487,3.819,0.002
22.80,95.500,0.09508,3.830,0.002
22.86,95.600,0.09529,3.841,0.002
22.93,95.700,0.09550,3.852,0.002
23.00,95.800,0.09575,3.864,0.002
23.06,95.900,0.09595,3.875,0.002
23.12,96.000,0.09616,3.885,0.002
23.19,96.100,0.09637,3.896,0.002
23.25,96.200,0.09653,3.907,0.002
23.29,96.300,0.09674,3.913,0.002
23.37,96.400,0.09695,3.926,0.002
23.42,96.500,0.09712,3.934,0.002
23.46,96.600,0.09732,3.941,0.002
23.49,96.700,0.09749,3.947,0.002
23.55,96.800,0.09766,3.957,0.002
23.58,96.900,0.09782,3.962,0.002
23.61,97.000,0.09795,3.967,0.002
23.66,97.100,0.09811,3.975,0.002
23.70,97.200,0.09824,3.982,0.002
23.73,97.300,0.09841,3.987,0.002
23.76,97.400,0.09853,3.993,0.002
23.80,97.500,0.09870,3.999,0.002
23.84,97.600,0.09882,4.006,0.002
23.86,97.700,0.09895,4.009,0.002
23.90,97.800,0.09907,4.015,0.002
23.93,97.900,0.09924,4.021,0.002
23.97,98.000,0.09936,4.028,0.002
23.98,98.100,0.09949,4.029,0.002
24.04,98.200,0.09965,4.039,0.002
24.06,98.300,0.09978,4.042,0.002
24.12,98.400,0.09990,4.053,0.002
24.14,98.500,0.10007,4.056,0.002
23.71,98.600,0.10019,3.984,0.002
14.95,98.700,0.10036,2.512,0.002
15.14,98.800,0.10048,2.544,0.002
15.24,98.900,0.10065,2.560,0.002
15.34,99.000,0.10082,2.577,0.002
15.38,99.100,0.10094,2.585,0.002
15.46,99.200,0.10111,2.597,0.002
15.54,99.300,0.10127,2.611,0.002
15.58,99.400,0.10140,2.617,0.002
15.63,99.500,0.10156,2.625,0.002
15.67,99.600,0.10173,2.634,0.002
15.72,99.700,0.10185,2.641,0.002
15.75,99.800,0.10202,2.646,0.002
15.80,99.900,0.10219,2.654,0.002
15.82,100.000,0.10235,2.659,0.002
15.87,100.100,0.10252,2.666,0.002
15.91,100.200,0.10269,2.674,0.002
15.96,100.300,0.10285,2.681,0.002
15.99,100.400,0.10302,2.687,0.002
16.03,100.500,0.10318,2.692,0.002
16.07,100.600,0.10335,2.701,0.002
16.13,100.700,0.10356,2.710,0.002
16.17,100.800,0.10377,2.717,0.002
16.22,100.900,0.10393,2.726,0.002
16.26,101.000,0.10414,2.732,0.002
16.32,101.100,0.10435,2.741,0.002
16.34,101.200,0.10456,2.745,0.002
16.40,101.300,0.10476,2.755,0.002
16.45,101.400,0.10501,2.764,0.002
16.49,101.500,0.10522,2.771,0.002
16.51,101.600,0.10543,2.773,0.002
16.57,101.700,0.10564,2.783,0.002
16.62,101.800,0.10584,2.792,0.002
16.65,101.900,0.10601,2.797,0.002
16.66,102.000,0.10622,2.799,0.002
16.70,102.100,0.10638,2.806,0.002
16.74,102.200,0.10659,2.813,0.002
16.75,102.300,0.10676,2.814,0.002
16.78,102.400,0.10692,2.820,0.002
16.82,102.500,0.10709,2.825,0.002
16.85,102.600,0.10726,2.832,0.002
16.87,102.700,0.10738,2.834,0.002
16.90,102.800,0.10755,2.840,0.002
16.91,102.900,0.10767,2.841,0.002
16.92,103.000,0.10784,2.844,0.002
16.94,103.100,0.10796,2.846,0.002
16.98,103.200,0.10813,2.853,0.002
16.99,103.300,0.10825,2.854,0.002
17.01,103.400,0.10838,2.858,0.002
17.03,103.500,0.10854,2.861,0.002
17.07,103.600,0.10867,2.867,0.002
17.08,103.700,0.10879,2.870,0.002
17.11,103.800,0.10896,2.874,0.002
17.13,103.900,0.10908,2.877,0.002
17.15,104.000,0.10921,2.882,0.002
17.17,104.100,0.10938,2.885,0.002
17.20,104.200,0.10950,2.890,0.002
17.23,104.300,0.10963,2.895,0.002
17.25,104.400,0.10979,2.899,0.002
17.27,104.500,0.10992,2.902,0.002
17.31,104.600,0.11008,2.909,0.002
17.33,104.700,0.11021,2.912,0.002
17.34,104.800,0.11037,2.913,0.002
17.38,104.900,0.11054,2.920,0.002
17.40,105.000,0.11066,2.923,0.002
17.43,105.100,0.11083,2.929,0.002
17.46,105.200,0.11095,2.933,0.002
17.50,105.300,0.11112,2.940,0.002
17.52,105.400,0.11129,2.943,0.002
17.52,105.500,0.11141,2.944,0.002
17.56,105.600,0.11158,2.951,0.002
17.59,105.700,0.11174,2.956,0.002
17.62,105.800,0.11187,2.960,0.002
17.65,105.900,0.11204,2.966,0.002
17.69,106.000,0.11220,2.972,0.002
17.72,106.100,0.11237,2.977,0.002
17.74,106.200,0.11258,2.980,0.002
17.78,106.300,0.11274,2.987,0.002
17.82,106.400,0.11291,2.993,0.002
17.85,106.500,0.11312,2.999,0.002
17.87,106.600,0.11332,3.002,0.002
17.93,106.700,0.11353,3.012,0.002
17.96,106.800,0.11374,3.018,0.002
18.01,106.900,0.11395,3.025,0.002
18.04,107.000,0.11415,3.031,0.002
18.09,107.100,0.11440,3.039,0.002
18.11,107.200,0.11461,3.042,0.002
18.14,107.300,0.11482,3.048,0.002
18.18,107.400,0.11503,3.054,0.002
18.22,107.500,0.11524,3.061,0.002
18.22,107.600,0.11544,3.061,0.002
18.26,107.700,0.11561,3.069,0.002
18.29,107.800,0.11582,3.072,0.002
18.31,107.900,0.11598,3.076,0.002
18.30,108.000,0.11615,3.075,0.002
18.34,108.100,0.11632,3.081,0.002
18.36,108.200,0.11648,3.085,0.002
18.40,108.300,0.11665,3.091,0.002
18.39,108.400,0.11681,3.089,0.002
18.42,108.500,0.11694,3.095,0.002
18.43,108.600,0.11706,3.097,0.002
18.45,108.700,0.11723,3.100,0.002
18.45,108.800,0.11735,3.100,0.002
18.48,108.900,0.11752,3.105,0.002
18.50,109.000,0.11765,3.108,0.002
18.53,109.100,0.11777,3.113,0.002
18.53,109.200,0.11789,3.114,0.002
18.56,109.300,0.11806,3.118,0.002
18.57,109.400,0.11819,3.120,0.002
18.60,109.500,0.11831,3.126,0.002
18.62,109.600,0.11848,3.129,0.002
18.63,109.700,0.11860,3.130,0.002
18.66,109.800,0.11877,3.135,0.002
18.70,109.900,0.11889,3.141,0.002
18.71,110.000,0.11906,3.143,0.002
18.75,110.100,0.11918,3.150,0.002
18.76,110.200,0.11935,3.152,0.002
18.80,110.300,0.11947,3.158,0.002
18.80,110.400,0.11964,3.158,0.002
18.82,110.500,0.11981,3.162,0.002
18.85,110.600,0.11993,3.167,0.002
18.90,110.700,0.12010,3.175,0.002
18.89,110.800,0.12026,3.174,0.002
18.94,110.900,0.12039,3.181,0.002
18.95,111.000,0.12055,3.184,0.002
18.98,111.100,0.12072,3.189,0.002
18.99,111.200,0.12089,3.191,0.002
19.03,111.300,0.12105,3.198,0.002
19.04,111.400,0.12118,3.200,0.002
19.09,111.500,0.12134,3.207,0.002
19.09,111.600,0.12151,3.208,0.002
19.13,111.700,0.12168,3.213,0.002
19.16,111.800,0.12184,3.219,0.002
19.19,111.900,0.12205,3.224,0.002
19.21,112.000,0.12222,3.227,0.002
19.25,112.100,0.12242,3.235,0.002
19.30,112.200,0.12259,3.242,0.002
19.35,112.300,0.12280,3.251,0.002
19.37,112.400,0.12301,3.255,0.002
19.40,112.500,0.12321,3.260,0.002
19.44,112.600,0.12342,3.267,0.002
19.48,112.700,0.12367,3.273,0.002
19.50,112.800,0.12388,3.276,0.002
19.53,112.900,0.12409,3.282,0.002
19.55,113.000,0.12429,3.284,0.002
19.57,113.100,0.12450,3.288,0.002
19.60,113.200,0.12471,3.293,0.002
19.62,113.300,0.12488,3.297,0.002
19.66,113.400,0.12508,3.302,0.002
19.66,113.500,0.12529,3.303,0.002
19.70,113.600,0.12546,3.310,0.002
19.71,113.700,0.12562,3.311,0.002
19.72,113.800,0.12579,3.314,0.002
19.75,113.900,0.12596,3.318,0.002
19.77,114.000,0.12612,3.321,0.002
19.78,114.100,0.12629,3.324,0.002
19.81,114.200,0.12646,3.328,0.002
19.81,114.300,0.12658,3.328,0.002
19.86,114.400,0.12675,3.337,0.002
19.85,114.500,0.12687,3.336,0.002
19.88,114.600,0.12704,3.340,0.003
19.91,114.700,0.12716,3.345,0.003
19.92,114.800,0.12729,3.346,0.003
19.93,114.900,0.12745,3.348,0.003
19.95,115.000,0.12758,3.352,0.003
19.97,115.100,0.12770,3.355,0.003
19.99,115.200,0.12787,3.359,0.003
19.99,115.300,0.12799,3.359,0.003
20.03,115.400,0.12816,3.365,0.003
20.03,115.500,0.12828,3.365,0.003
20.09,115.600,0.12845,3.375,0.003
20.08,115.700,0.12857,3.374,0.003
20.14,115.800,0.12874,3.383,0.003
20.16,115.900,0.12887,3.387,0.003
20.20,116.000,0.12903,3.393,0.003
20.20,116.100,0.12920,3.394,0.003
20.23,116.200,0.12932,3.399,0.003
20.25,116.300,0.12949,3.402,0.003
20.26,116.400,0.12966,3.404,0.003
20.30,116.500,0.12982,3.411,0.003
20.33,116.600,0.12995,3.415,0.003
20.33,116.700,0.13011,3.415,0.003
20.37,116.800,0.13028,3.422,0.003
20.39,116.900,0.13044,3.425,0.003
20.40,117.000,0.13061,3.427,0.003
20.42,117.100,0.13078,3.430,0.003
20.46,117.200,0.13094,3.438,0.003
20.48,117.300,0.13111,3.440,0.003
20.51,117.400,0.13128,3.446,0.003
20.54,117.500,0.13144,3.451,0.003
20.57,117.600,0.13165,3.456,0.003
20.58,117.700,0.13182,3.458,0.003
20.63,117.800,0.13202,3.466,0.003
20.68,117.900,0.13219,3.474,0.003
20.70,118.000,0.13240,3.479,0.003
20.72,118.100,0.13265,3.482,0.003
20.78,118.200,0.13285,3.491,0.003
20.81,118.300,0.13306,3.497,0.003
20.83,118.400,0.13327,3.500,0.003
20.86,118.500,0.13348,3.505,0.003
20.88,118.600,0.13369,3.509,0.003
20.91,118.700,0.13389,3.514,0.003
20.95,118.800,0.13410,3.520,0.003
20.95,118.900,0.13431,3.519,0.003
20.97,119.000,0.13448,3.524,0.003
20.99,119.100,0.13468,3.527,0.003
21.03,119.200,0.13489,3.533,0.003
21.06,119.300,0.13506,3.539,0.003
21.06,119.400,0.13522,3.539,0.003
21.08,119.500,0.13539,3.541,0.003
21.09,119.600,0.13556,3.543,0.003
21.11,119.700,0.13572,3.546,0.003
21.10,119.800,0.13589,3.546,0.003
21.13,119.900,0.13601,3.550,0.003
21.16,120.000,0.13618,3.555,0.003
21.15,120.100,0.13630,3.554,0.003
21.19,120.200,0.13647,3.561,0.003
21.20,120.300,0.13659,3.563,0.003
21.21,120.400,0.13672,3.563,0.003
21.21,120.500,0.13689,3.563,0.003
21.26,120.600,0.13701,3.571,0.003
21.25,120.700,0.13714,3.570,0.003
21.26,120.800,0.13730,3.572,0.003
21.29,120.900,0.13743,3.577,0.003
21.31,121.000,0.13755,3.580,0.003
21.32,121.100,0.13772,3.582,0.003
21.34,121.200,0.13784,3.585,0.003
21.38,121.300,0.13797,3.591,0.003
21.39,121.400,0.13813,3.594,0.003
21.39,121.500,0.13826,3.594,0.003
21.43,121.600,0.13842,3.600,0.003
21.46,121.700,0.13855,3.605,0.003
21.47,121.800,0.13871,3.608,0.003
21.48,121.900,0.13884,3.609,0.003
21.53,122.000,0.13901,3.617,0.003
21.54,122.100,0.13917,3.618,0.003
21.57,122.200,0.13930,3.624,0.003
21.59,122.300,0.13946,3.627,0.003
21.60,122.400,0.13963,3.630,0.003
21.62,122.500,0.13979,3.632,0.003
21.63,122.600,0.13992,3.635,0.003
21.66,122.700,0.14009,3.639,0.003
21.68,122.800,0.14025,3.642,0.003
21.73,122.900,0.14042,3.650,0.003
21.72,123.000,0.14058,3.649,0.003
21.74,123.100,0.14075,3.652,0.003
21.78,123.200,0.14092,3.660,0.003
21.83,123.300,0.14112,3.668,0.003
21.85,123.400,0.14129,3.671,0.003
21.87,123.500,0.14150,3.675,0.003
21.92,123.600,0.14171,3.683,0.003
21.96,123.700,0.14191,3.689,0.003
22.00,123.800,0.14212,3.697,0.003
22.01,123.900,0.14233,3.698,0.003
22.05,124.000,0.14254,3.705,0.003
22.07,124.100,0.14279,3.709,0.003
22.11,124.200,0.14299,3.715,0.003
22.14,124.300,0.14320,3.720,0.003
22.18,124.400,0.14341,3.726,0.003
22.17,124.500,0.14362,3.725,0.003
22.21,124.600,0.14383,3.732,0.003
22.22,124.700,0.14403,3.734,0.003
22.24,124.800,0.14420,3.736,0.003
22.24,124.900,0.14441,3.737,0.003
22.27,125.000,0.14457,3.741,0.003
22.27,125.100,0.14474,3.741,0.003
22.29,125.200,0.14491,3.745,0.003
22.29,125.300,0.14507,3.745,0.003
22.32,125.400,0.14520,3.750,0.003
22.31,125.500,0.14536,3.749,0.003
22.31,125.600,0.14553,3.749,0.003
22.31,125.700,0.14565,3.748,0.003
22.33,125.800,0.14578,3.752,0.003
22.33,125.900,0.14594,3.751,0.003
22.35,126.000,0.14607,3.755,0.003
22.36,126.100,0.14619,3.757,0.003
22.38,126.200,0.14632,3.760,0.003
22.39,126.300,0.14649,3.762,0.003
22.41,126.400,0.14661,3.765,0.003
22.43,126.500,0.14673,3.768,0.003
22.44,126.600,0.14690,3.771,0.003
22.47,126.700,0.14703,3.776,0.003
22.49,126.800,0.14715,3.778,0.003
22.51,126.900,0.14732,3.781,0.003
22.52,127.000,0.14744,3.784,0.003
22.54,127.100,0.14761,3.787,0.003
22.57,127.200,0.14777,3.792,0.003
22.57,127.300,0.14790,3.793,0.003
22.60,127.400,0.14806,3.797,0.003
22.60,127.500,0.14819,3.798,0.003
22.63,127.600,0.14836,3.801,0.003
22.64,127.700,0.14852,3.804,0.003
22.66,127.800,0.14865,3.807,0.003
22.69,127.900,0.14881,3.812,0.003
22.69,128.000,0.14898,3.812,0.003
22.71,128.100,0.14914,3.815,0.003
22.72,128.200,0.14927,3.817,0.003
22.75,128.300,0.14944,3.822,0.003
22.75,128.400,0.14960,3.823,0.003
22.78,128.500,0.14977,3.827,0.003
22.80,128.600,0.14993,3.831,0.003
22.84,128.700,0.15010,3.838,0.003
22.84,128.800,0.15027,3.837,0.003
22.86,128.900,0.15043,3.841,0.003
22.91,129.000,0.15064,3.849,0.003
22.94,129.100,0.15081,3.854,0.003
22.96,129.200,0.15101,3.857,0.003
22.99,129.300,0.15122,3.863,0.003
23.02,129.400,0.15143,3.868,0.003
23.05,129.500,0.15164,3.873,0.003
23.07,129.600,0.15185,3.876,0.003
23.10,129.700,0.15210,3.881,0.003
23.11,129.800,0.15230,3.883,0.003
23.13,129.900,0.15251,3.886,0.003
23.14,130.000,0.15272,3.887,0.003
23.18,130.100,0.15293,3.895,0.003
23.17,130.200,0.15313,3.892,0.003
23.19,130.300,0.15330,3.897,0.003
23.21,130.400,0.15351,3.899,0.003
23.22,130.500,0.15372,3.901,0.003
23.21,130.600,0.15388,3.899,0.003
23.23,130.700,0.15405,3.902,0.003
23.24,130.800,0.15421,3.904,0.003
23.24,130.900,0.15438,3.904,0.003
23.25,131.000,0.15455,3.905,0.003
23.26,131.100,0.15467,3.908,0.003
23.25,131.200,0.15484,3.907,0.003
23.26,131.300,0.15496,3.907,0.003
23.27,131.400,0.15513,3.909,0.003
23.27,131.500,0.15525,3.910,0.003
23.27,131.600,0.15542,3.909,0.003
23.27,131.700,0.15554,3.910,0.003
23.29,131.800,0.15567,3.912,0.003
23.29,131.900,0.15579,3.912,0.003
23.29,132.000,0.15596,3.913,0.003
23.33,132.100,0.15608,3.919,0.003
23.32,132.200,0.15621,3.919,0.003
23.34,132.300,0.15638,3.921,0.003
23.35,132.400,0.15650,3.924,0.003
23.38,132.500,0.15662,3.928,0.003
23.38,132.600,0.15679,3.929,0.003
23.41,132.700,0.15692,3.933,0.003
23.42,132.800,0.15708,3.934,0.003
23.46,132.900,0.15721,3.941,0.003
23.45,133.000,0.15737,3.940,0.003
23.46,133.100,0.15750,3.942,0.003
23.48,133.200,0.15766,3.944,0.003
23.49,133.300,0.15783,3.947,0.003
23.51,133.400,0.15795,3.950,0.003
23.54,133.500,0.15812,3.955,0.003
23.55,133.600,0.15829,3.957,0.003
23.55,133.700,0.15845,3.956,0.003
23.56,133.800,0.15858,3.958,0.003
23.57,133.900,0.15874,3.960,0.003
23.58,134.000,0.15891,3.962,0.003
23.61,134.100,0.15908,3.967,0.003
23.61,134.200,0.15920,3.967,0.003
23.63,134.300,0.15937,3.971,0.003
23.63,134.400,0.15953,3.969,0.003
23.66,134.500,0.15970,3.975,0.003
23.67,134.600,0.15991,3.976,0.003
23.70,134.700,0.16007,3.981,0.003
23.71,134.800,0.16024,3.983,0.003
23.74,134.900,0.16045,3.989,0.003
23.78,135.000,0.16066,3.995,0.003
23.78,135.100,0.16082,3.996,0.003
23.83,135.200,0.16103,4.003,0.003
23.85,135.300,0.16128,4.008,0.003
23.87,135.400,0.16149,4.010,0.003
23.87,135.500,0.16169,4.010,0.003
23.90,135.600,0.16190,4.015,0.003
23.91,135.700,0.16211,4.017,0.003
23.92,135.800,0.16232,4.019,0.003
23.94,135.900,0.16248,4.022,0.003
23.95,136.000,0.16269,4.024,0.003
23.96,136.100,0.16290,4.025,0.003
23.98,136.200,0.16307,4.029,0.003
23.98,136.300,0.16327,4.029,0.003
23.97,136.400,0.16344,4.028,0.003
23.99,136.500,0.16361,4.030,0.003
24.01,136.600,0.16377,4.034,0.003
24.01,136.700,0.16394,4.034,0.003
24.00,136.800,0.16406,4.032,0.003
24.01,136.900,0.16423,4.034,0.003
24.02,137.000,0.16440,4.035,0.003
24.01,137.100,0.16452,4.035,0.003
24.02,137.200,0.16469,4.036,0.003
24.02,137.300,0.16481,4.036,0.003
24.04,137.400,0.16494,4.040,0.003
24.04,137.500,0.16510,4.038,0.003
24.04,137.600,0.16523,4.039,0.003
24.07,137.700,0.16535,4.043,0.003
24.07,137.800,0.16552,4.044,0.003
24.06,137.900,0.16564,4.043,0.003
24.10,138.000,0.16577,4.049,0.003
24.12,138.100,0.16593,4.052,0.003
24.12,138.200,0.16606,4.053,0.003
24.14,138.300,0.16618,4.055,0.003
24.16,138.400,0.16635,4.060,0.003
24.18,138.500,0.16647,4.063,0.003
24.19,138.600,0.16664,4.065,0.003
24.20,138.700,0.16676,4.066,0.003
24.24,138.800,0.16693,4.072,0.003
24.25,138.900,0.16706,4.074,0.003
24.26,139.000,0.16722,4.076,0.003
24.27,139.100,0.16739,4.078,0.003
24.30,139.200,0.16751,4.083,0.003
24.33,139.300,0.16768,4.088,0.003
24.32,139.400,0.16780,4.087,0.003
24.35,139.500,0.16797,4.091,0.003
24.36,139.600,0.16814,4.093,0.003
24.38,139.700,0.16830,4.096,0.003
24.39,139.800,0.16843,4.097,0.003
24.41,139.900,0.16859,4.101,0.003
24.42,140.000,0.16876,4.103,0.003
24.44,140.100,0.16893,4.106,0.003
24.44,140.200,0.16909,4.107,0.003
24.48,140.300,0.16930,4.113,0.003
24.49,140.400,0.16947,4.115,0.003
24.51,140.500,0.16967,4.118,0.003
24.53,140.600,0.16984,4.122,0.003
24.54,140.700,0.17005,4.123,0.003
24.58,140.800,0.17026,4.129,0.003
24.61,140.900,0.17046,4.134,0.003
24.63,141.000,0.17071,4.139,0.003
24.64,141.100,0.17092,4.139,0.003
24.65,141.200,0.17113,4.141,0.003
24.67,141.300,0.17138,4.146,0.003
24.69,141.400,0.17158,4.148,0.003
24.68,141.500,0.17179,4.147,0.003
24.69,141.600,0.17200,4.149,0.003
24.71,141.700,0.17221,4.151,0.003
24.70,141.800,0.17242,4.150,0.003
24.71,141.900,0.17258,4.152,0.003
24.72,142.000,0.17279,4.153,0.003
24.72,142.100,0.17296,4.152,0.003
24.71,142.200,0.17312,4.151,0.003
24.73,142.300,0.17329,4.155,0.003
24.73,142.400,0.17345,4.155,0.003
24.71,142.500,0.17358,4.152,0.003
24.71,142.600,0.17375,4.151,0.003
24.73,142.700,0.17387,4.155,0.003
24.74,142.800,0.17404,4.156,0.003
24.73,142.900,0.17416,4.154,0.003
24.74,143.000,0.17433,4.156,0.003
24.74,143.100,0.17445,4.156,0.003
24.72,143.200,0.17458,4.154,0.003
24.76,143.300,0.17470,4.159,0.003
24.76,143.400,0.17487,4.159,0.003
24.77,143.500,0.17499,4.161,0.003
24.77,143.600,0.17512,4.161,0.003
24.78,143.700,0.17528,4.163,0.003
24.79,143.800,0.17541,4.165,0.003
24.82,143.900,0.17557,4.170,0.003
24.83,144.000,0.17570,4.171,0.003
24.85,144.100,0.17587,4.175,0.003
24.86,144.200,0.17599,4.177,0.003
24.88,144.300,0.17616,4.181,0.003
24.91,144.400,0.17632,4.185,0.003
24.91,144.500,0.17645,4.185,0.003
24.91,144.600,0.17661,4.186,0.003
24.93,144.700,0.17678,4.188,0.003
24.95,144.800,0.17690,4.191,0.003
24.95,144.900,0.17707,4.191,0.003
24.95,145.000,0.17724,4.192,0.003
24.97,145.100,0.17740,4.195,0.003
24.96,145.200,0.17757,4.194,0.003
24.97,145.300,0.17769,4.196,0.003
24.98,145.400,0.17786,4.197,0.004
25.00,145.500,0.17803,4.200,0.004
24.99,145.600,0.17819,4.199,0.004
25.01,145.700,0.17836,4.202,0.004
25.02,145.800,0.17852,4.203,0.004
25.05,145.900,0.17873,4.209,0.004
25.06,146.000,0.17890,4.210,0.004
25.08,146.100,0.17911,4.213,0.004
25.10,146.200,0.17931,4.217,0.004
25.13,146.300,0.17948,4.222,0.004
25.16,146.400,0.17973,4.228,0.004
25.17,146.500,0.17994,4.229,0.004
25.19,146.600,0.18015,4.232,0.004
25.23,146.700,0.18039,4.238,0.004
25.24,146.800,0.18060,4.240,0.004
25.25,146.900,0.18081,4.242,0.004
25.25,147.000,0.18102,4.243,0.004
25.28,147.100,0.18123,4.247,0.004
25.27,147.200,0.18143,4.246,0.004
25.28,147.300,0.18164,4.248,0.004
25.29,147.400,0.18185,4.249,0.004
25.30,147.470,0.18202,4.251,0.004