File: data-files/CWRU/0900-05-20A.txt
""
"Test Method","Will_Huddleston_Disks.msm"
"Sample I. D.","900-5-20A.mss"
"Specimen Number","1"

"Load (N)","Time (s)","Extension (mm)","Stress (MPa)","Strain (mm/mm)"

5.95,0.200,-0.06412,0.619,-0.001
5.94,0.300,-0.06412,0.618,-0.001
5.94,0.400,-0.06412,0.618,-0.001
5.94,0.500,-0.06412,0.618,-0.001
5.95,0.600,-0.06408,0.618,-0.001
5.94,0.700,-0.06408,0.618,-0.001
5.94,0.800,-0.06408,0.618,-0.001
5.94,0.900,-0.06403,0.618,-0.001
5.95,1.000,-0.06403,0.619,-0.001
5.94,1.100,-0.06403,0.618,-0.001
5.96,1.200,-0.06399,0.620,-0.001
5.94,1.300,-0.06399,0.618,-0.001
5.93,1.400,-0.06399,0.617,-0.001
5.94,1.500,-0.06395,0.618,-0.001
5.94,1.600,-0.06395,0.618,-0.001
5.94,1.700,-0.06391,0.618,-0.001
5.95,1.800,-0.06391,0.619,-0.001
5.95,1.900,-0.06387,0.619,-0.001
5.98,2.000,-0.06383,0.622,-0.001
6.00,2.100,-0.06378,0.624,-0.001
6.07,2.200,-0.06370,0.632,-0.001
6.16,2.300,-0.06362,0.641,-0.001
6.26,2.400,-0.06345,0.652,-0.001
6.40,2.500,-0.06333,0.666,-0.001
6.51,2.600,-0.06316,0.677,-0.001
6.60,2.700,-0.06299,0.686,-0.001
6.68,2.800,-0.06283,0.695,-0.001
6.75,2.900,-0.06266,0.702,-0.001
6.82,3.000,-0.06250,0.710,-0.001
6.87,3.100,-0.06233,0.715,-0.001
6.94,3.200,-0.06216,0.722,-0.001
6.99,3.300,-0.06200,0.727,-0.001
7.05,3.400,-0.06183,0.733,-0.001
7.09,3.500,-0.06166,0.738,-0.001
7.14,3.600,-0.06146,0.743,-0.001
7.19,3.700,-0.06125,0.748,-0.001
7.26,3.800,-0.06108,0.755,-0.001
7.30,3.900,-0.06088,0.759,-0.001
7.35,4.000,-0.06067,0.764,-0.001
7.39,4.100,-0.06046,0.768,-0.001
7.44,4.200,-0.06025,0.773,-0.001
7.47,4.300,-0.06004,0.777,-0.001
7.51,4.400,-0.05988,0.782,-0.001
7.55,4.500,-0.05967,0.785,-0.001
7.59,4.600,-0.05946,0.790,-0.001
7.61,4.700,-0.05930,0.791,-0.001
7.66,4.800,-0.05913,0.797,-0.001
7.68,4.900,-0.05892,0.798,-0.001
7.72,5.000,-0.05876,0.803,-0.001
7.74,5.100,-0.05859,0.805,-0.001
7.78,5.200,-0.05842,0.809,-0.001
7.81,5.300,-0.05826,0.812,-0.001
7.85,5.400,-0.05813,0.816,-0.001
7.87,5.500,-0.05797,0.818,-0.001
7.90,5.600,-0.05780,0.822,-0.001
7.93,5.700,-0.05768,0.825,-0.001
7.97,5.800,-0.05751,0.829,-0.001
7.98,5.900,-0.05738,0.830,-0.001
8.00,6.000,-0.05726,0.832,-0.001
8.04,6.100,-0.05709,0.836,-0.001
8.07,6.200,-0.05697,0.840,-0.001
8.08,6.300,-0.05684,0.841,-0.001
8.12,6.400,-0.05668,0.845,-0.001
8.13,6.500,-0.05655,0.846,-0.001
8.18,6.600,-0.05643,0.851,-0.001
8.19,6.700,-0.05630,0.852,-0.001
8.23,6.800,-0.05614,0.857,-0.001
8.26,6.900,-0.05601,0.859,-0.001
8.29,7.000,-0.05585,0.863,-0.001
8.32,7.100,-0.05572,0.866,-0.001
8.37,7.200,-0.05556,0.871,-0.001
8.38,7.300,-0.05543,0.872,-0.001
8.41,7.400,-0.05527,0.875,-0.001
8.47,7.500,-0.05510,0.881,-0.001
8.51,7.600,-0.05497,0.885,-0.001
8.54,7.700,-0.05481,0.888,-0.001
8.58,7.800,-0.05464,0.893,-0.001
8.61,7.900,-0.05448,0.895,-0.001
8.65,8.000,-0.05435,0.900,-0.001
8.68,8.100,-0.05418,0.903,-0.001
8.73,8.200,-0.05402,0.908,-0.001
8.75,8.300,-0.05385,0.911,-0.001
8.80,8.400,-0.05369,0.915,-0.001
8.84,8.500,-0.05352,0.920,-0.001
8.89,8.600,-0.05335,0.925,-0.001
8.93,8.700,-0.05319,0.928,-0.001
8.96,8.800,-0.05302,0.932,-0.001
8.99,8.900,-0.05281,0.935,-0.001
9.04,9.000,-0.05265,0.940,-0.001
9.11,9.100,-0.05244,0.948,-0.001
9.16,9.200,-0.05227,0.953,-0.001
9.20,9.300,-0.05207,0.957,-0.001
9.27,9.400,-0.05186,0.964,-0.001
9.30,9.500,-0.05165,0.967,-0.001
9.35,9.600,-0.05144,0.973,-0.001
9.41,9.700,-0.05123,0.979,-0.001
9.47,9.800,-0.05103,0.985,-0.001
9.51,9.900,-0.05078,0.989,-0.001
9.58,10.000,-0.05057,0.997,-0.001
9.61,10.100,-0.05036,1.000,-0.001
9.67,10.200,-0.05015,1.006,-0.001
9.74,10.300,-0.04995,1.013,-0.001
9.78,10.400,-0.04978,1.017,-0.001
9.83,10.500,-0.04957,1.023,-0.001
9.87,10.600,-0.04936,1.027,-0.001
9.91,10.700,-0.04920,1.031,-0.001
9.93,10.800,-0.04903,1.033,-0.001
9.97,10.900,-0.04887,1.037,-0.001
10.02,11.000,-0.04870,1.042,-0.001
10.07,11.100,-0.04853,1.048,-0.001
10.10,11.200,-0.04837,1.050,-0.001
10.14,11.300,-0.04824,1.055,-0.001
10.18,11.400,-0.04808,1.059,-0.001
10.22,11.500,-0.04791,1.063,-0.001
10.24,11.600,-0.04779,1.065,-0.001
10.27,11.700,-0.04766,1.069,-0.001
10.33,11.800,-0.04749,1.075,-0.001
10.37,11.900,-0.04737,1.079,-0.001
10.39,12.000,-0.04724,1.081,-0.001
10.42,12.100,-0.04708,1.083,-0.001
10.47,12.200,-0.04695,1.089,-0.001
10.50,12.300,-0.04683,1.093,-0.001
10.54,12.400,-0.04666,1.096,-0.001
10.59,12.500,-0.04654,1.101,-0.001
10.62,12.600,-0.04637,1.105,-0.001
10.66,12.700,-0.04625,1.109,-0.001
10.71,12.800,-0.04608,1.114,-0.001
10.74,12.900,-0.04596,1.117,-0.001
10.78,13.000,-0.04579,1.121,-0.001
10.82,13.100,-0.04567,1.126,-0.001
10.85,13.200,-0.04550,1.129,-0.001
10.90,13.300,-0.04537,1.134,-0.001
10.95,13.400,-0.04521,1.139,-0.001
10.98,13.500,-0.04504,1.142,-0.001
11.02,13.600,-0.04492,1.147,-0.001
11.08,13.700,-0.04475,1.153,-0.001
11.13,13.800,-0.04459,1.157,-0.001
11.17,13.900,-0.04442,1.162,-0.001
11.19,14.000,-0.04429,1.164,-0.001
11.25,14.100,-0.04413,1.170,-0.001
11.27,14.200,-0.04396,1.173,-0.001
11.32,14.300,-0.04380,1.177,-0.001
11.38,14.400,-0.04363,1.184,-0.001
11.42,14.500,-0.04346,1.188,-0.001
11.48,14.600,-0.04330,1.194,-0.001
11.53,14.700,-0.04309,1.199,-0.001
11.57,14.800,-0.04292,1.204,-0.001
11.64,14.900,-0.04272,1.211,-0.001
11.70,15.000,-0.04251,1.217,-0.001
11.76,15.100,-0.04230,1.224,-0.001
11.82,15.200,-0.04209,1.229,-0.001
11.89,15.300,-0.04188,1.236,-0.001
11.94,15.400,-0.04163,1.242,-0.001
12.00,15.500,-0.04143,1.248,-0.001
12.06,15.600,-0.04122,1.255,-0.001
12.12,15.700,-0.04097,1.261,-0.001
12.19,15.800,-0.04076,1.268,-0.001
12.23,15.900,-0.04055,1.272,-0.001
12.31,16.000,-0.04035,1.280,-0.001
12.34,16.100,-0.04018,1.284,-0.001
12.39,16.200,-0.03997,1.289,-0.001
12.44,16.300,-0.03981,1.294,-0.001
12.49,16.400,-0.03960,1.300,-0.001
12.52,16.500,-0.03943,1.303,-0.001
12.56,16.600,-0.03927,1.307,-0.001
12.62,16.700,-0.03914,1.313,-0.001
12.67,16.800,-0.03898,1.318,-0.001
12.70,16.900,-0.03885,1.321,-0.001
12.75,17.000,-0.03868,1.326,-0.001
12.78,17.100,-0.03856,1.330,-0.001
12.81,17.200,-0.03839,1.332,-0.001
12.85,17.300,-0.03827,1.337,-0.001
12.89,17.400,-0.03814,1.341,-0.001
12.91,17.500,-0.03802,1.343,-0.001
12.97,17.600,-0.03785,1.349,-0.001
12.98,17.700,-0.03773,1.350,-0.001
13.04,17.800,-0.03760,1.356,-0.001
13.07,17.900,-0.03748,1.360,-0.001
13.14,18.000,-0.03731,1.367,-0.001
13.16,18.100,-0.03719,1.369,-0.001
13.21,18.200,-0.03702,1.374,-0.001
13.25,18.300,-0.03690,1.379,-0.001
13.31,18.400,-0.03673,1.384,-0.001
13.33,18.500,-0.03661,1.387,-0.001
13.39,18.600,-0.03644,1.393,-0.001
13.43,18.700,-0.03632,1.397,-0.001
13.50,18.800,-0.03615,1.404,-0.001
13.52,18.900,-0.03598,1.407,-0.001
13.58,19.000,-0.03586,1.412,-0.001
13.61,19.100,-0.03569,1.416,-0.001
13.66,19.200,-0.03553,1.421,-0.001
13.70,19.300,-0.03540,1.425,-0.001
13.76,19.400,-0.03524,1.431,-0.001
13.79,19.500,-0.03507,1.434,-0.001
13.83,19.600,-0.03490,1.439,-0.001
13.89,19.700,-0.03474,1.445,-0.001
13.92,19.800,-0.03457,1.449,-0.001
13.98,19.900,-0.03445,1.454,-0.001
14.04,20.000,-0.03424,1.460,-0.001
14.07,20.100,-0.03407,1.464,-0.001
14.14,20.200,-0.03391,1.471,-0.001
14.19,20.300,-0.03374,1.476,-0.001
14.27,20.400,-0.03353,1.484,-0.001
14.32,20.500,-0.03337,1.490,-0.001
14.39,20.600,-0.03316,1.497,-0.001
14.46,20.700,-0.03295,1.504,-0.001
14.52,20.800,-0.03274,1.510,-0.001
14.59,20.900,-0.03253,1.518,-0.001
14.67,21.000,-0.03233,1.526,-0.001
14.74,21.100,-0.03212,1.533,-0.001
14.80,21.200,-0.03187,1.540,-0.001
14.86,21.300,-0.03166,1.546,-0.001
14.95,21.400,-0.03145,1.555,-0.001
14.99,21.500,-0.03125,1.559,-0.001
15.07,21.600,-0.03104,1.568,-0.001
15.13,21.700,-0.03083,1.574,-0.001
15.19,21.800,-0.03066,1.580,-0.001
15.25,21.900,-0.03046,1.587,-0.001
15.32,22.000,-0.03029,1.593,-0.001
15.36,22.100,-0.03012,1.598,-0.001
15.41,22.200,-0.02996,1.603,-0.001
15.45,22.300,-0.02979,1.607,-0.001
15.48,22.400,-0.02963,1.610,-0.001
15.54,22.500,-0.02950,1.616,-0.001
15.58,22.600,-0.02933,1.621,-0.001
15.63,22.700,-0.02921,1.626,-0.001
15.67,22.800,-0.02904,1.630,-0.001
15.71,22.900,-0.02892,1.634,-0.001
15.75,23.000,-0.02879,1.639,-0.001
15.79,23.100,-0.02863,1.642,-0.001
15.83,23.200,-0.02850,1.647,-0.001
15.88,23.300,-0.02838,1.651,-0.001
15.92,23.400,-0.02821,1.656,-0.001
15.95,23.500,-0.02809,1.659,-0.001
16.01,23.600,-0.02796,1.665,-0.001
16.06,23.700,-0.02780,1.671,-0.001
16.10,23.800,-0.02767,1.675,-0.001
16.15,23.900,-0.02755,1.680,-0.001
16.20,24.000,-0.02738,1.685,-0.001
16.26,24.100,-0.02721,1.691,-0.001
16.31,24.200,-0.02709,1.697,-0.001
16.35,24.300,-0.02692,1.701,-0.001
16.39,24.400,-0.02680,1.706,-0.001
16.48,24.500,-0.02663,1.714,-0.001
16.52,24.600,-0.02647,1.719,-0.001
16.59,24.700,-0.02634,1.726,-0.001
16.62,24.800,-0.02618,1.729,-0.001
16.69,24.900,-0.02601,1.736,-0.001
16.74,25.000,-0.02589,1.742,-0.001
16.79,25.100,-0.02572,1.747,-0.001
16.84,25.200,-0.02555,1.751,-0.001
16.88,25.300,-0.02539,1.756,0.000
16.95,25.400,-0.02522,1.763,0.000
17.01,25.500,-0.02510,1.769,0.000
17.05,25.600,-0.02493,1.774,0.000
17.11,25.700,-0.02476,1.780,0.000
17.17,25.800,-0.02460,1.786,0.000
17.23,25.900,-0.02439,1.792,0.000
17.30,26.000,-0.02422,1.800,0.000
17.37,26.100,-0.02406,1.807,0.000
17.46,26.200,-0.02385,1.816,0.000
17.53,26.300,-0.02368,1.823,0.000
17.60,26.400,-0.02347,1.830,0.000
17.69,26.500,-0.02327,1.840,0.000
17.76,26.600,-0.02306,1.847,0.000
17.85,26.700,-0.02285,1.857,0.000
17.91,26.800,-0.02264,1.864,0.000
18.01,26.900,-0.02244,1.873,0.000
18.08,27.000,-0.02223,1.881,0.000
18.16,27.100,-0.02202,1.889,0.000
18.21,27.200,-0.02181,1.894,0.000
18.31,27.300,-0.02160,1.904,0.000
18.36,27.400,-0.02140,1.910,0.000
18.42,27.500,-0.02123,1.916,0.000
18.50,27.600,-0.02102,1.924,0.000
18.56,27.700,-0.02086,1.930,0.000
18.61,27.800,-0.02069,1.936,0.000
18.66,27.900,-0.02052,1.942,0.000
18.72,28.000,-0.02036,1.947,0.000
18.77,28.100,-0.02019,1.952,0.000
18.84,28.200,-0.02007,1.959,0.000
18.88,28.300,-0.01990,1.964,0.000
18.93,28.400,-0.01978,1.969,0.000
18.99,28.500,-0.01961,1.975,0.000
19.04,28.600,-0.01944,1.980,0.000
19.08,28.700,-0.01932,1.985,0.000
19.12,28.800,-0.01919,1.989,0.000
19.18,28.900,-0.01907,1.995,0.000
19.23,29.000,-0.01890,2.001,0.000
19.28,29.100,-0.01878,2.005,0.000
19.33,29.200,-0.01865,2.010,0.000
19.40,29.300,-0.01853,2.018,0.000
19.45,29.400,-0.01836,2.023,0.000
19.49,29.500,-0.01824,2.027,0.000
19.55,29.600,-0.01807,2.033,0.000
19.60,29.700,-0.01795,2.039,0.000
19.65,29.800,-0.01782,2.045,0.000
19.72,29.900,-0.01766,2.051,0.000
19.77,30.000,-0.01753,2.056,0.000
19.83,30.100,-0.01737,2.063,0.000
19.90,30.200,-0.01724,2.070,0.000
19.94,30.300,-0.01708,2.074,0.000
20.01,30.400,-0.01691,2.082,0.000
20.06,30.500,-0.01678,2.087,0.000
20.13,30.600,-0.01662,2.094,0.000
20.19,30.700,-0.01649,2.100,0.000
20.26,30.800,-0.01633,2.108,0.000
20.31,30.900,-0.01616,2.113,0.000
20.39,31.000,-0.01604,2.122,0.000
20.45,31.100,-0.01587,2.128,0.000
20.53,31.200,-0.01570,2.136,0.000
20.59,31.300,-0.01554,2.142,0.000
20.67,31.400,-0.01537,2.151,0.000
20.74,31.500,-0.01521,2.157,0.000
20.81,31.600,-0.01504,2.164,0.000
20.88,31.700,-0.01483,2.172,0.000
20.97,31.800,-0.01467,2.182,0.000
21.05,31.900,-0.01446,2.190,0.000
21.16,32.000,-0.01425,2.201,0.000
21.26,32.100,-0.01404,2.211,0.000
21.34,32.200,-0.01383,2.220,0.000
21.44,32.300,-0.01363,2.231,0.000
21.51,32.400,-0.01342,2.238,0.000
21.62,32.500,-0.01317,2.249,0.000
21.70,32.600,-0.01296,2.257,0.000
21.79,32.700,-0.01275,2.266,0.000
21.89,32.800,-0.01255,2.278,0.000
21.99,32.900,-0.01234,2.287,0.000
22.06,33.000,-0.01213,2.294,0.000
22.14,33.100,-0.01192,2.303,0.000
22.21,33.200,-0.01171,2.310,0.000
22.29,33.300,-0.01155,2.319,0.000
22.36,33.400,-0.01134,2.326,0.000
22.43,33.500,-0.01117,2.333,0.000
22.48,33.600,-0.01101,2.339,0.000
22.56,33.700,-0.01084,2.346,0.000
22.61,33.800,-0.01072,2.352,0.000
22.67,33.900,-0.01055,2.358,0.000
22.72,34.000,-0.01043,2.364,0.000
22.79,34.100,-0.01026,2.370,0.000
22.84,34.200,-0.01014,2.376,0.000
22.91,34.300,-0.00997,2.384,0.000
22.98,34.400,-0.00984,2.390,0.000
23.03,34.500,-0.00972,2.396,0.000
23.07,34.600,-0.00955,2.400,0.000
23.13,34.700,-0.00943,2.406,0.000
23.19,34.800,-0.00930,2.412,0.000
23.25,34.900,-0.00918,2.419,0.000
23.32,35.000,-0.00901,2.426,0.000
23.37,35.100,-0.00889,2.431,0.000
23.46,35.200,-0.00872,2.441,0.000
23.51,35.300,-0.00860,2.446,0.000
23.57,35.400,-0.00843,2.452,0.000
23.65,35.500,-0.00831,2.460,0.000
23.73,35.600,-0.00814,2.469,0.000
23.80,35.700,-0.00802,2.476,0.000
23.86,35.800,-0.00785,2.482,0.000
23.93,35.900,-0.00768,2.489,0.000
24.00,36.000,-0.00756,2.496,0.000
24.08,36.100,-0.00739,2.505,0.000
24.16,36.200,-0.00723,2.513,0.000
24.25,36.300,-0.00706,2.522,0.000
24.32,36.400,-0.00694,2.530,0.000
24.39,36.500,-0.00677,2.538,0.000
24.45,36.600,-0.00660,2.544,0.000
24.53,36.700,-0.00644,2.552,0.000
24.62,36.800,-0.00627,2.561,0.000
24.70,36.900,-0.00615,2.569,0.000
24.76,37.000,-0.00598,2.575,0.000
24.85,37.100,-0.00581,2.585,0.000
24.93,37.200,-0.00561,2.593,0.000
25.03,37.300,-0.00544,2.603,0.000
25.12,37.400,-0.00523,2.613,0.000
25.23,37.500,-0.00507,2.625,0.000
25.32,37.600,-0.00486,2.634,0.000
25.42,37.700,-0.00465,2.644,0.000
25.52,37.800,-0.00444,2.655,0.000
25.65,37.900,-0.00423,2.668,0.000
25.74,38.000,-0.00403,2.678,0.000
25.86,38.100,-0.00382,2.690,0.000
25.94,38.200,-0.00357,2.699,0.000
26.06,38.300,-0.00336,2.711,0.000
26.17,38.400,-0.00315,2.722,0.000
26.27,38.500,-0.00295,2.733,0.000
26.36,38.600,-0.00274,2.742,0.000
26.47,38.700,-0.00253,2.754,0.000
26.55,38.800,-0.00232,2.762,0.000
26.66,38.900,-0.00216,2.773,0.000
26.76,39.000,-0.00195,2.784,0.000
26.83,39.100,-0.00178,2.791,0.000
26.90,39.200,-0.00162,2.798,0.000
26.98,39.300,-0.00145,2.806,0.000
27.05,39.400,-0.00128,2.814,0.000
27.13,39.500,-0.00112,2.823,0.000
27.22,39.600,-0.00099,2.832,0.000
27.29,39.700,-0.00083,2.839,0.000
27.34,39.800,-0.00070,2.844,0.000
27.42,39.900,-0.00054,2.852,0.000
27.49,40.000,-0.00041,2.860,0.000
27.56,40.100,-0.00029,2.867,0.000
27.62,40.200,-0.00012,2.874,0.000
27.70,40.300,0.00000,2.882,0.000
27.77,40.400,0.00013,2.889,0.000
27.85,40.500,0.00030,2.897,0.000
27.93,40.600,0.00042,2.905,0.000
28.00,40.700,0.00054,2.913,0.000
28.08,40.800,0.00071,2.922,0.000
28.16,40.900,0.00084,2.930,0.000
28.24,41.000,0.00100,2.938,0.000
28.31,41.100,0.00113,2.945,0.000
28.43,41.200,0.00129,2.957,0.000
28.46,41.300,0.00146,2.961,0.000
28.56,41.400,0.00158,2.971,0.000
28.65,41.500,0.00175,2.980,0.000
28.75,41.600,0.00192,2.990,0.000
28.79,41.700,0.00204,2.995,0.000
28.89,41.800,0.00221,3.006,0.000
28.97,41.900,0.00237,3.013,0.000
29.06,42.000,0.00254,3.023,0.000
29.16,42.100,0.00266,3.033,0.000
29.23,42.200,0.00283,3.041,0.000
29.32,42.300,0.00300,3.051,0.000
29.42,42.400,0.00316,3.061,0.000
29.51,42.500,0.00333,3.069,0.000
29.60,42.600,0.00349,3.079,0.000
29.72,42.700,0.00366,3.091,0.000
29.80,42.800,0.00383,3.100,0.000
29.90,42.900,0.00404,3.111,0.000
30.01,43.000,0.00420,3.122,0.000
30.11,43.100,0.00441,3.132,0.000
30.22,43.200,0.00458,3.144,0.000
30.35,43.300,0.00478,3.157,0.000
30.47,43.400,0.00499,3.169,0.000
30.58,43.500,0.00520,3.181,0.000
30.71,43.600,0.00541,3.195,0.000
30.84,43.700,0.00561,3.208,0.000
30.98,43.800,0.00582,3.223,0.000
31.10,43.900,0.00603,3.235,0.000
31.21,44.000,0.00624,3.247,0.000
31.32,44.100,0.00645,3.258,0.000
31.45,44.200,0.00665,3.272,0.000
31.57,44.300,0.00686,3.284,0.000
31.67,44.400,0.00707,3.295,0.000
31.80,44.500,0.00728,3.308,0.000
31.89,44.600,0.00744,3.317,0.000
32.00,44.700,0.00761,3.329,0.000
32.07,44.800,0.00778,3.336,0.000
32.18,44.900,0.00794,3.348,0.000
32.26,45.000,0.00811,3.356,0.000
32.34,45.100,0.00827,3.365,0.000
32.42,45.200,0.00840,3.373,0.000
32.54,45.300,0.00856,3.385,0.000
32.61,45.400,0.00869,3.392,0.000
32.70,45.500,0.00886,3.401,0.000
32.75,45.600,0.00898,3.407,0.000
32.86,45.700,0.00915,3.418,0.000
32.92,45.800,0.00927,3.425,0.000
33.02,45.900,0.00940,3.435,0.000
33.08,46.000,0.00956,3.441,0.000
33.19,46.100,0.00969,3.452,0.000
33.24,46.200,0.00981,3.458,0.000
33.35,46.300,0.00998,3.469,0.000
33.42,46.400,0.01010,3.477,0.000
33.52,46.500,0.01023,3.487,0.000
33.60,46.600,0.01039,3.495,0.000
33.69,46.700,0.01052,3.505,0.000
33.78,46.800,0.01068,3.514,0.000
33.88,46.900,0.01081,3.524,0.000
33.96,47.000,0.01097,3.533,0.000
34.09,47.100,0.01110,3.546,0.000
34.16,47.200,0.01127,3.553,0.000
34.27,47.300,0.01139,3.565,0.000
34.35,47.400,0.01156,3.573,0.000
34.46,47.500,0.01168,3.585,0.000
34.53,47.600,0.01185,3.592,0.000
34.66,47.700,0.01201,3.605,0.000
34.74,47.800,0.01214,3.614,0.000
34.86,47.900,0.01230,3.627,0.000
34.95,48.000,0.01247,3.635,0.000
35.06,48.100,0.01260,3.647,0.000
35.13,48.200,0.01276,3.655,0.000
35.26,48.300,0.01293,3.668,0.000
35.35,48.400,0.01309,3.678,0.000
35.48,48.500,0.01326,3.691,0.000
35.58,48.600,0.01347,3.701,0.000
35.72,48.700,0.01363,3.716,0.000
35.85,48.800,0.01384,3.729,0.000
36.01,48.900,0.01401,3.745,0.000
36.13,49.000,0.01422,3.759,0.000
36.29,49.100,0.01442,3.775,0.000
36.43,49.200,0.01463,3.790,0.000
36.59,49.300,0.01484,3.807,0.000
36.73,49.400,0.01505,3.821,0.000
36.88,49.500,0.01530,3.836,0.000
37.01,49.600,0.01550,3.850,0.000
37.17,49.700,0.01571,3.867,0.000
37.30,49.800,0.01592,3.880,0.000
37.45,49.900,0.01613,3.896,0.000
37.57,50.000,0.01629,3.908,0.000
37.69,50.100,0.01650,3.921,0.000
37.82,50.200,0.01667,3.935,0.000
37.92,50.300,0.01683,3.945,0.000
38.03,50.400,0.01704,3.956,0.000
38.14,50.500,0.01721,3.968,0.000
38.24,50.600,0.01733,3.978,0.000
38.32,50.700,0.01750,3.987,0.000
38.43,50.800,0.01767,3.998,0.000
38.50,50.900,0.01779,4.005,0.000
38.60,51.000,0.01796,4.016,0.000
38.70,51.100,0.01808,4.026,0.000
38.79,51.200,0.01821,4.035,0.000
38.88,51.300,0.01837,4.044,0.000
38.96,51.400,0.01850,4.053,0.000
39.06,51.500,0.01862,4.063,0.000
39.13,51.600,0.01875,4.071,0.000
39.24,51.700,0.01891,4.082,0.000
39.35,51.800,0.01904,4.093,0.000
39.43,51.900,0.01916,4.102,0.000
39.52,52.000,0.01929,4.111,0.000
39.62,52.100,0.01945,4.121,0.000
39.73,52.200,0.01958,4.133,0.000
39.81,52.300,0.01970,4.142,0.000
39.91,52.400,0.01987,4.152,0.000
40.02,52.500,0.01999,4.163,0.000
40.14,52.600,0.02016,4.176,0.000
40.24,52.700,0.02028,4.186,0.000
40.34,52.800,0.02045,4.197,0.000
40.46,52.900,0.02062,4.209,0.000
40.58,53.000,0.02074,4.221,0.000
40.68,53.100,0.02091,4.232,0.000
40.81,53.200,0.02107,4.246,0.000
40.91,53.300,0.02120,4.256,0.000
41.04,53.400,0.02136,4.269,0.000
41.14,53.500,0.02153,4.280,0.000
41.26,53.600,0.02165,4.292,0.000
41.38,53.700,0.02182,4.304,0.000
41.51,53.800,0.02199,4.318,0.000
41.61,53.900,0.02215,4.329,0.000
41.77,54.000,0.02232,4.345,0.000
41.86,54.100,0.02249,4.355,0.000
42.03,54.200,0.02265,4.372,0.000
42.13,54.300,0.02282,4.382,0.000
42.29,54.400,0.02303,4.400,0.000
42.44,54.500,0.02319,4.415,0.000
42.62,54.600,0.02340,4.434,0.000
42.78,54.700,0.02361,4.450,0.000
42.94,54.800,0.02382,4.467,0.000
43.09,54.900,0.02402,4.482,0.000
43.28,55.000,0.02423,4.502,0.000
43.44,55.100,0.02444,4.519,0.000
43.63,55.200,0.02465,4.538,0.000
43.78,55.300,0.02485,4.555,0.000
43.94,55.400,0.02506,4.571,0.000
44.07,55.500,0.02527,4.585,0.000
44.26,55.600,0.02548,4.604,0.001
44.41,55.700,0.02569,4.620,0.001
44.58,55.800,0.02589,4.637,0.001
44.72,55.900,0.02606,4.652,0.001
44.88,56.000,0.02627,4.668,0.001
45.01,56.100,0.02643,4.682,0.001
45.13,56.200,0.02660,4.695,0.001
45.24,56.300,0.02677,4.706,0.001
45.39,56.400,0.02693,4.722,0.001
45.48,56.500,0.02710,4.731,0.001
45.60,56.600,0.02726,4.744,0.001
45.69,56.700,0.02739,4.753,0.001
45.84,56.800,0.02756,4.768,0.001
45.93,56.900,0.02768,4.778,0.001
46.05,57.000,0.02785,4.791,0.001
46.15,57.100,0.02797,4.800,0.001
46.27,57.200,0.02810,4.813,0.001
46.35,57.300,0.02826,4.821,0.001
46.46,57.400,0.02839,4.833,0.001
46.56,57.500,0.02851,4.843,0.001
46.68,57.600,0.02864,4.856,0.001
46.79,57.700,0.02880,4.867,0.001
46.91,57.800,0.02893,4.880,0.001
47.02,57.900,0.02905,4.891,0.001
47.16,58.000,0.02922,4.906,0.001
47.27,58.100,0.02934,4.918,0.001
47.40,58.200,0.02951,4.931,0.001
47.54,58.300,0.02963,4.945,0.001
47.67,58.400,0.02980,4.959,0.001
47.79,58.500,0.02997,4.972,0.001
47.93,58.600,0.03009,4.986,0.001
48.07,58.700,0.03026,5.000,0.001
48.22,58.800,0.03042,5.016,0.001
48.33,58.900,0.03055,5.028,0.001
48.47,59.000,0.03071,5.042,0.001
48.59,59.100,0.03088,5.055,0.001
48.72,59.200,0.03100,5.068,0.001
48.85,59.300,0.03117,5.081,0.001
49.01,59.400,0.03134,5.098,0.001
49.13,59.500,0.03146,5.111,0.001
49.27,59.600,0.03163,5.126,0.001
49.41,59.700,0.03179,5.140,0.001
49.55,59.800,0.03196,5.154,0.001
49.70,59.900,0.03213,5.170,0.001
49.86,60.000,0.03229,5.187,0.001
50.01,60.100,0.03250,5.203,0.001
50.16,60.200,0.03267,5.218,0.001
50.34,60.300,0.03283,5.237,0.001
50.51,60.400,0.03304,5.255,0.001
50.74,60.500,0.03325,5.278,0.001
50.88,60.600,0.03346,5.293,0.001
51.11,60.700,0.03366,5.316,0.001
51.28,60.800,0.03387,5.334,0.001
51.47,60.900,0.03408,5.355,0.001
51.66,61.000,0.03429,5.374,0.001
51.84,61.100,0.03450,5.393,0.001
52.00,61.200,0.03466,5.409,0.001
52.17,61.300,0.03487,5.428,0.001
52.36,61.400,0.03508,5.447,0.001
52.52,61.500,0.03529,5.464,0.001
52.69,61.600,0.03545,5.481,0.001
52.86,61.700,0.03566,5.498,0.001
52.99,61.800,0.03583,5.512,0.001
53.14,61.900,0.03599,5.528,0.001
53.30,62.000,0.03616,5.544,0.001
53.43,62.100,0.03632,5.558,0.001
53.58,62.200,0.03649,5.573,0.001
53.72,62.300,0.03661,5.588,0.001
53.84,62.400,0.03678,5.601,0.001
53.96,62.500,0.03691,5.613,0.001
54.09,62.600,0.03707,5.626,0.001
54.21,62.700,0.03720,5.640,0.001
54.34,62.800,0.03736,5.653,0.001
54.48,62.900,0.03749,5.668,0.001
54.58,63.000,0.03761,5.678,0.001
54.72,63.100,0.03774,5.692,0.001
54.84,63.200,0.03790,5.704,0.001
54.96,63.300,0.03803,5.717,0.001
55.08,63.400,0.03815,5.730,0.001
55.24,63.500,0.03828,5.747,0.001
55.34,63.600,0.03844,5.757,0.001
55.48,63.700,0.03857,5.771,0.001
55.61,63.800,0.03869,5.785,0.001
55.76,63.900,0.03886,5.801,0.001
55.88,64.000,0.03898,5.813,0.001
56.04,64.100,0.03911,5.830,0.001
56.19,64.200,0.03927,5.845,0.001
56.35,64.300,0.03944,5.862,0.001
56.49,64.400,0.03957,5.877,0.001
56.63,64.500,0.03973,5.891,0.001
56.78,64.600,0.03986,5.907,0.001
56.94,64.700,0.04002,5.923,0.001
57.10,64.800,0.04019,5.939,0.001
57.25,64.900,0.04031,5.955,0.001
57.37,65.000,0.04048,5.968,0.001
57.54,65.100,0.04065,5.986,0.001
57.68,65.200,0.04081,6.001,0.001
57.86,65.300,0.04094,6.019,0.001
57.99,65.400,0.04110,6.032,0.001
58.15,65.500,0.04127,6.049,0.001
58.31,65.600,0.04144,6.066,0.001
58.49,65.700,0.04160,6.085,0.001
58.65,65.800,0.04177,6.101,0.001
58.83,65.900,0.04193,6.119,0.001
59.02,66.000,0.04214,6.140,0.001
59.24,66.100,0.04235,6.163,0.001
59.46,66.200,0.04256,6.185,0.001
59.67,66.300,0.04277,6.208,0.001
59.89,66.400,0.04297,6.230,0.001
60.10,66.500,0.04318,6.252,0.001
60.35,66.600,0.04339,6.278,0.001
60.58,66.700,0.04360,6.302,0.001
60.78,66.800,0.04385,6.323,0.001
61.01,66.900,0.04405,6.347,0.001
61.25,67.000,0.04426,6.372,0.001
61.48,67.100,0.04447,6.396,0.001
61.69,67.200,0.04468,6.418,0.001
61.90,67.300,0.04488,6.439,0.001
62.10,67.400,0.04505,6.460,0.001
62.29,67.500,0.04526,6.480,0.001
62.45,67.600,0.04542,6.497,0.001
62.63,67.700,0.04559,6.515,0.001
62.80,67.800,0.04576,6.533,0.001
62.98,67.900,0.04592,6.552,0.001
63.13,68.000,0.04609,6.567,0.001
63.27,68.100,0.04621,6.582,0.001
63.41,68.200,0.04634,6.597,0.001
63.58,68.300,0.04651,6.614,0.001
63.73,68.400,0.04663,6.630,0.001
63.89,68.500,0.04680,6.646,0.001
64.02,68.600,0.04692,6.659,0.001
64.16,68.700,0.04705,6.674,0.001
64.30,68.800,0.04717,6.689,0.001
64.47,68.900,0.04729,6.706,0.001
64.64,69.000,0.04746,6.724,0.001
64.80,69.100,0.04759,6.741,0.001
64.96,69.200,0.04771,6.758,0.001
65.13,69.300,0.04788,6.775,0.001
65.32,69.400,0.04800,6.795,0.001
65.48,69.500,0.04813,6.811,0.001
65.66,69.600,0.04829,6.831,0.001
65.83,69.700,0.04842,6.848,0.001
66.02,69.800,0.04858,6.868,0.001
66.19,69.900,0.04875,6.885,0.001
66.39,70.000,0.04887,6.906,0.001
66.54,70.100,0.04904,6.922,0.001
66.75,70.200,0.04921,6.943,0.001
66.91,70.300,0.04933,6.960,0.001
67.10,70.400,0.04950,6.980,0.001
67.29,70.500,0.04966,7.000,0.001
67.50,70.600,0.04983,7.021,0.001
67.67,70.700,0.04995,7.040,0.001
67.87,70.800,0.05012,7.060,0.001
68.06,70.900,0.05029,7.080,0.001
68.26,71.000,0.05045,7.101,0.001
68.46,71.100,0.05062,7.121,0.001
68.65,71.200,0.05079,7.142,0.001
68.86,71.300,0.05095,7.164,0.001
69.10,71.400,0.05112,7.188,0.001
69.31,71.500,0.05128,7.210,0.001
69.59,71.600,0.05149,7.239,0.001
69.82,71.700,0.05170,7.263,0.001
70.11,71.800,0.05187,7.293,0.001
70.36,71.900,0.05207,7.319,0.001
70.65,72.000,0.05228,7.349,0.001
70.93,72.100,0.05253,7.379,0.001
71.23,72.200,0.05274,7.410,0.001
71.51,72.300,0.05299,7.439,0.001
71.82,72.400,0.05320,7.472,0.001
72.09,72.500,0.05340,7.499,0.001
72.40,72.600,0.05361,7.532,0.001
72.64,72.700,0.05386,7.557,0.001
72.94,72.800,0.05407,7.587,0.001
73.19,72.900,0.05428,7.614,0.001
73.45,73.000,0.05444,7.641,0.001
73.69,73.100,0.05465,7.666,0.001
73.92,73.200,0.05482,7.690,0.001
74.13,73.300,0.05498,7.712,0.001
74.36,73.400,0.05515,7.735,0.001
74.54,73.500,0.05531,7.754,0.001
74.75,73.600,0.05548,7.776,0.001
74.94,73.700,0.05565,7.796,0.001
75.17,73.800,0.05577,7.820,0.001
75.34,73.900,0.05594,7.838,0.001
75.52,74.000,0.05606,7.857,0.001
75.70,74.100,0.05623,7.875,0.001
75.90,74.200,0.05635,7.896,0.001
76.08,74.300,0.05648,7.914,0.001
76.28,74.400,0.05660,7.935,0.001
76.44,74.500,0.05677,7.952,0.001
76.64,74.600,0.05689,7.973,0.001
76.83,74.700,0.05702,7.992,0.001
77.02,74.800,0.05718,8.012,0.001
77.21,74.900,0.05731,8.032,0.001
77.40,75.000,0.05748,8.052,0.001
77.59,75.100,0.05760,8.072,0.001
77.80,75.200,0.05777,8.093,0.001
78.01,75.300,0.05793,8.115,0.001
78.22,75.400,0.05806,8.137,0.001
78.42,75.500,0.05822,8.158,0.001
78.63,75.600,0.05835,8.180,0.001
78.83,75.700,0.05851,8.201,0.001
79.07,75.800,0.05868,8.225,0.001
79.27,75.900,0.05885,8.247,0.001
79.47,76.000,0.05897,8.267,0.001
79.69,76.100,0.05914,8.290,0.001
79.92,76.200,0.05930,8.314,0.001
80.14,76.300,0.05947,8.337,0.001
80.36,76.400,0.05964,8.360,0.001
80.58,76.500,0.05976,8.382,0.001
80.80,76.600,0.05993,8.405,0.001
81.04,76.700,0.06009,8.430,0.001
81.27,76.800,0.06026,8.454,0.001
81.50,76.900,0.06043,8.478,0.001
81.75,77.000,0.06063,8.504,0.001
82.03,77.100,0.06080,8.533,0.001
82.30,77.200,0.06101,8.561,0.001
82.59,77.300,0.06117,8.592,0.001
82.88,77.400,0.06138,8.622,0.001
83.17,77.500,0.06159,8.652,0.001
83.47,77.600,0.06180,8.683,0.001
83.78,77.700,0.06205,8.716,0.001
84.10,77.800,0.06225,8.749,0.001
84.41,77.900,0.06246,8.781,0.001
84.71,78.000,0.06267,8.812,0.001
85.00,78.100,0.06288,8.842,0.001
85.29,78.200,0.06309,8.872,0.001
85.57,78.300,0.06329,8.902,0.001
85.85,78.400,0.06350,8.931,0.001
86.12,78.500,0.06367,8.959,0.001
86.40,78.600,0.06388,8.988,0.001
86.63,78.700,0.06404,9.012,0.001
86.89,78.800,0.06425,9.039,0.001
87.12,78.900,0.06442,9.063,0.001
87.35,79.000,0.06458,9.086,0.001
87.54,79.100,0.06475,9.107,0.001
87.75,79.200,0.06491,9.128,0.001
87.93,79.300,0.06504,9.147,0.001
88.12,79.400,0.06521,9.167,0.001
88.33,79.500,0.06533,9.188,0.001
88.52,79.600,0.06550,9.209,0.001
88.71,79.700,0.06562,9.228,0.001
88.92,79.800,0.06579,9.250,0.001
89.08,79.900,0.06591,9.267,0.001
89.26,80.000,0.06604,9.286,0.001
89.44,80.100,0.06620,9.304,0.001
89.61,80.200,0.06633,9.322,0.001
89.78,80.300,0.06645,9.340,0.001
89.97,80.400,0.06658,9.359,0.001
90.14,80.500,0.06674,9.377,0.001
90.34,80.600,0.06687,9.398,0.001
90.53,80.700,0.06699,9.418,0.001
90.72,80.800,0.06716,9.438,0.001
90.91,80.900,0.06728,9.458,0.001
91.09,81.000,0.06745,9.476,0.001
91.28,81.100,0.06757,9.496,0.001
91.48,81.200,0.06774,9.517,0.001
91.68,81.300,0.06786,9.537,0.001
91.85,81.400,0.06803,9.555,0.001
92.01,81.500,0.06820,9.571,0.001
92.16,81.600,0.06832,9.587,0.001
92.29,81.700,0.06849,9.601,0.001
92.39,81.800,0.06865,9.611,0.001
92.40,81.900,0.06882,9.612,0.001
92.50,82.000,0.06895,9.622,0.001
92.64,82.100,0.06911,9.637,0.001
92.84,82.200,0.06928,9.658,0.001
93.03,82.300,0.06944,9.678,0.001
93.24,82.400,0.06961,9.699,0.001
93.44,82.500,0.06978,9.720,0.001
93.68,82.600,0.06994,9.745,0.001
93.89,82.700,0.07011,9.767,0.001
94.13,82.800,0.07028,9.792,0.001
94.38,82.900,0.07048,9.818,0.001
94.65,83.000,0.07069,9.846,0.001
94.93,83.100,0.07086,9.875,0.001
95.20,83.200,0.07111,9.903,0.001
95.47,83.300,0.07131,9.931,0.001
95.78,83.400,0.07152,9.964,0.001
96.07,83.500,0.07173,9.994,0.001
96.35,83.600,0.07194,10.023,0.001
96.61,83.700,0.07219,10.050,0.001
96.89,83.800,0.07239,10.079,0.001
97.14,83.900,0.07260,10.105,0.001
97.40,84.000,0.07281,10.133,0.001
97.64,84.100,0.07302,10.157,0.001
97.90,84.200,0.07318,10.184,0.001
98.12,84.300,0.07339,10.207,0.001
98.36,84.400,0.07356,10.232,0.001
98.56,84.500,0.07377,10.253,0.001
98.80,84.600,0.07393,10.277,0.001
98.97,84.700,0.07410,10.296,0.001
99.17,84.800,0.07426,10.317,0.001
99.35,84.900,0.07439,10.335,0.001
99.53,85.000,0.07456,10.354,0.001
99.70,85.100,0.07468,10.371,0.001
99.86,85.200,0.07485,10.388,0.001
100.03,85.300,0.07497,10.406,0.001
100.23,85.400,0.07514,10.427,0.001
100.38,85.500,0.07526,10.443,0.001
100.59,85.600,0.07539,10.464,0.001
100.73,85.700,0.07551,10.479,0.001
100.91,85.800,0.07564,10.498,0.001
101.07,85.900,0.07580,10.514,0.001
101.25,86.000,0.07593,10.533,0.001
101.41,86.100,0.07605,10.549,0.001
101.60,86.200,0.07618,10.570,0.001
101.79,86.300,0.07634,10.589,0.002
101.99,86.400,0.07647,10.609,0.002
102.17,86.500,0.07663,10.629,0.002
102.37,86.600,0.07676,10.649,0.002
102.54,86.700,0.07692,10.667,0.002
102.76,86.800,0.07709,10.690,0.002
102.94,86.900,0.07721,10.709,0.002
103.15,87.000,0.07738,10.731,0.002
103.32,87.100,0.07751,10.748,0.002
103.55,87.200,0.07767,10.772,0.002
103.74,87.300,0.07784,10.792,0.002
103.94,87.400,0.07800,10.812,0.002
104.15,87.500,0.07813,10.834,0.002
104.33,87.600,0.07830,10.853,0.002
104.53,87.700,0.07846,10.874,0.002
104.72,87.800,0.07863,10.893,0.002
104.90,87.900,0.07875,10.912,0.002
105.09,88.000,0.07892,10.932,0.002
105.31,88.100,0.07908,10.955,0.002
105.50,88.200,0.07929,10.975,0.002
105.71,88.300,0.07946,10.997,0.002
105.91,88.400,0.07963,11.018,0.002
106.15,88.500,0.07979,11.043,0.002
106.35,88.600,0.08000,11.063,0.002
106.58,88.700,0.08017,11.087,0.002
106.77,88.800,0.08037,11.107,0.002
107.03,88.900,0.08058,11.134,0.002
107.27,89.000,0.08079,11.159,0.002
107.50,89.100,0.08100,11.183,0.002
107.70,89.200,0.08120,11.204,0.002
107.93,89.300,0.08145,11.228,0.002
108.10,89.400,0.08166,11.245,0.002
108.32,89.500,0.08187,11.269,0.002
108.53,89.600,0.08208,11.290,0.002
108.71,89.700,0.08228,11.309,0.002
108.92,89.800,0.08249,11.331,0.002
109.13,89.900,0.08270,11.353,0.002
109.32,90.000,0.08287,11.372,0.002
109.53,90.100,0.08307,11.394,0.002
109.73,90.200,0.08324,11.415,0.002
109.92,90.300,0.08341,11.434,0.002
110.08,90.400,0.08357,11.451,0.002
110.25,90.500,0.08374,11.469,0.002
110.39,90.600,0.08386,11.483,0.002
110.55,90.700,0.08403,11.500,0.002
110.70,90.800,0.08415,11.515,0.002
110.83,90.900,0.08432,11.530,0.002
110.99,91.000,0.08445,11.546,0.002
111.14,91.100,0.08461,11.562,0.002
111.28,91.200,0.08474,11.576,0.002
111.43,91.300,0.08486,11.592,0.002
111.57,91.400,0.08499,11.606,0.002
111.75,91.500,0.08515,11.625,0.002
111.90,91.600,0.08528,11.641,0.002
112.08,91.700,0.08540,11.659,0.002
112.24,91.800,0.08553,11.676,0.002
112.41,91.900,0.08569,11.694,0.002
112.60,92.000,0.08582,11.714,0.002
112.77,92.100,0.08598,11.731,0.002
112.94,92.200,0.08611,11.749,0.002
113.11,92.300,0.08627,11.766,0.002
113.29,92.400,0.08640,11.785,0.002
113.48,92.500,0.08656,11.805,0.002
113.64,92.600,0.08669,11.821,0.002
113.81,92.700,0.08686,11.840,0.002
113.97,92.800,0.08698,11.856,0.002
114.10,92.900,0.08715,11.870,0.002
114.25,93.000,0.08731,11.885,0.002
114.37,93.100,0.08744,11.898,0.002
114.48,93.200,0.08760,11.908,0.002
114.55,93.300,0.08773,11.916,0.002
114.60,93.400,0.08789,11.922,0.002
114.67,93.500,0.08806,11.928,0.002
114.75,93.600,0.08823,11.937,0.002
114.84,93.700,0.08839,11.946,0.002
114.96,93.800,0.08852,11.959,0.002
115.08,93.900,0.08873,11.972,0.002
115.23,94.000,0.08889,11.987,0.002
115.37,94.100,0.08906,12.002,0.002
115.54,94.200,0.08922,12.020,0.002
115.72,94.300,0.08943,12.038,0.002
115.89,94.400,0.08960,12.056,0.002
116.08,94.500,0.08981,12.076,0.002
116.31,94.600,0.09001,12.099,0.002
116.51,94.700,0.09022,12.120,0.002
116.77,94.800,0.09043,12.147,0.002
116.96,94.900,0.09068,12.167,0.002
117.19,95.000,0.09089,12.191,0.002
117.37,95.100,0.09109,12.210,0.002
117.56,95.200,0.09130,12.230,0.002
117.67,95.300,0.09151,12.241,0.002
117.79,95.400,0.09172,12.253,0.002
117.82,95.500,0.09188,12.256,0.002
117.81,95.600,0.09209,12.256,0.002
117.67,95.700,0.09230,12.241,0.002
117.53,95.800,0.09247,12.227,0.002
117.38,95.900,0.09263,12.210,0.002
117.24,96.000,0.09280,12.196,0.002
117.14,96.100,0.09296,12.186,0.002
117.07,96.200,0.09313,12.178,0.002
116.90,96.300,0.09330,12.161,0.002
116.73,96.400,0.09342,12.143,0.002
116.46,96.500,0.09359,12.115,0.002
116.22,96.600,0.09375,12.090,0.002
115.93,96.700,0.09388,12.060,0.002
115.69,96.800,0.09400,12.035,0.002
115.46,96.900,0.09417,12.011,0.002
115.26,97.000,0.09429,11.990,0.002
114.99,97.100,0.09442,11.962,0.002
114.75,97.200,0.09454,11.937,0.002
114.59,97.300,0.09471,11.920,0.002
114.52,97.400,0.09483,11.913,0.002
114.50,97.500,0.09496,11.911,0.002
114.52,97.600,0.09513,11.913,0.002
114.54,97.700,0.09525,11.915,0.002
114.59,97.800,0.09537,11.921,0.002
114.61,97.900,0.09554,11.923,0.002
114.61,98.000,0.09567,11.923,0.002
114.62,98.100,0.09583,11.924,0.002
114.63,98.200,0.09596,11.925,0.002
114.66,98.300,0.09612,11.928,0.002
114.70,98.400,0.09625,11.932,0.002
114.72,98.500,0.09641,11.934,0.002
114.80,98.600,0.09654,11.943,0.002
114.91,98.700,0.09670,11.954,0.002
115.02,98.800,0.09687,11.966,0.002
115.12,98.900,0.09700,11.976,0.002
115.24,99.000,0.09716,11.988,0.002
115.34,99.100,0.09733,11.999,0.002
115.48,99.200,0.09749,12.013,0.002
115.62,99.300,0.09766,12.027,0.002
115.72,99.400,0.09779,12.038,0.002
115.87,99.500,0.09795,12.054,0.002
116.02,99.600,0.09812,12.069,0.002
116.18,99.700,0.09828,12.086,0.002
116.33,99.800,0.09845,12.102,0.002
116.50,99.900,0.09866,12.119,0.002
116.68,100.000,0.09882,12.138,0.002
116.91,100.100,0.09903,12.162,0.002
117.13,100.200,0.09924,12.184,0.002
117.39,100.300,0.09945,12.212,0.002
117.65,100.400,0.09966,12.239,0.002
117.96,100.500,0.09990,12.271,0.002
118.23,100.600,0.10011,12.299,0.002
118.46,100.700,0.10036,12.323,0.002
118.72,100.800,0.10057,12.351,0.002
119.01,100.900,0.10078,12.381,0.002
119.27,101.000,0.10098,12.407,0.002
119.56,101.100,0.10119,12.437,0.002
119.81,101.200,0.10140,12.463,0.002
120.05,101.300,0.10161,12.488,0.002
120.29,101.400,0.10182,12.513,0.002
120.53,101.500,0.10198,12.538,0.002
120.73,101.600,0.10215,12.559,0.002
120.96,101.700,0.10231,12.583,0.002
121.13,101.800,0.10248,12.601,0.002
121.34,101.900,0.10265,12.623,0.002
121.50,102.000,0.10277,12.639,0.002
121.67,102.100,0.10294,12.657,0.002
121.83,102.200,0.10306,12.673,0.002
122.01,102.300,0.10323,12.693,0.002
122.16,102.400,0.10335,12.708,0.002
122.35,102.500,0.10348,12.727,0.002
122.50,102.600,0.10364,12.743,0.002
122.69,102.700,0.10377,12.763,0.002
122.82,102.800,0.10389,12.776,0.002
123.01,102.900,0.10402,12.796,0.002
123.16,103.000,0.10418,12.812,0.002
123.37,103.100,0.10431,12.834,0.002
123.52,103.200,0.10443,12.850,0.002
123.72,103.300,0.10460,12.870,0.002
123.89,103.400,0.10472,12.888,0.002
124.09,103.500,0.10489,12.909,0.002
124.27,103.600,0.10502,12.928,0.002
124.49,103.700,0.10518,12.951,0.002
124.68,103.800,0.10535,12.970,0.002
124.89,103.900,0.10547,12.992,0.002
125.05,104.000,0.10564,13.008,0.002
125.26,104.100,0.10581,13.030,0.002
125.44,104.200,0.10593,13.049,0.002
125.64,104.300,0.10610,13.070,0.002
125.81,104.400,0.10626,13.087,0.002
126.00,104.500,0.10643,13.107,0.002
126.17,104.600,0.10659,13.125,0.002
126.36,104.700,0.10672,13.144,0.002
126.53,104.800,0.10689,13.163,0.002
126.73,104.900,0.10705,13.184,0.002
126.90,105.000,0.10722,13.202,0.002
127.10,105.100,0.10738,13.222,0.002
127.28,105.200,0.10755,13.240,0.002
127.46,105.300,0.10772,13.259,0.002
127.67,105.400,0.10788,13.281,0.002
127.91,105.500,0.10809,13.306,0.002
128.11,105.600,0.10830,13.327,0.002
57.57,105.700,0.10846,5.989,0.002
9.12,105.730,0.10855,0.949,0.002