File: data-files/CWRU/0900-05-28y.txt
""
"Test Method","Will_Huddleston_Load_Rate.msm"
"Sample I. D.","Test_Setup.mss"
"Specimen Number","1"

"Load (N)","Time (s)","Extension (mm)","Stress (MPa)","Strain (mm/mm)"

-0.03,0.080,0.00000,-0.003,0.000
-0.05,0.180,0.00000,-0.005,0.000
-0.05,0.280,0.00000,-0.005,0.000
-0.04,0.380,0.00000,-0.004,0.000
-0.04,0.480,0.00000,-0.004,0.000
-0.03,0.580,0.00000,-0.003,0.000
-0.03,0.680,0.00000,-0.003,0.000
-0.03,0.780,0.00000,-0.003,0.000
-0.03,0.880,0.00000,-0.003,0.000
-0.04,0.980,0.00004,-0.004,0.000
-0.03,1.080,0.00004,-0.003,0.000
-0.04,1.180,0.00004,-0.004,0.000
-0.04,1.280,0.00004,-0.004,0.000
-0.03,1.380,0.00004,-0.003,0.000
-0.03,1.480,0.00004,-0.003,0.000
-0.05,1.580,0.00004,-0.005,0.000
-0.02,1.680,0.00004,-0.002,0.000
-0.03,1.780,0.00008,-0.003,0.000
-0.02,1.880,0.00008,-0.002,0.000
-0.02,1.980,0.00008,-0.002,0.000
-0.03,2.080,0.00008,-0.003,0.000
-0.03,2.180,0.00008,-0.003,0.000
-0.04,2.280,0.00008,-0.004,0.000
-0.04,2.380,0.00012,-0.004,0.000
-0.02,2.480,0.00012,-0.002,0.000
-0.02,2.580,0.00012,-0.002,0.000
-0.04,2.680,0.00012,-0.004,0.000
-0.03,2.780,0.00012,-0.003,0.000
-0.03,2.880,0.00017,-0.003,0.000
-0.02,2.980,0.00017,-0.002,0.000
-0.03,3.080,0.00017,-0.003,0.000
-0.02,3.180,0.00017,-0.002,0.000
-0.03,3.280,0.00021,-0.003,0.000
-0.04,3.380,0.00021,-0.004,0.000
-0.05,3.480,0.00021,-0.005,0.000
-0.04,3.580,0.00021,-0.004,0.000
-0.05,3.680,0.00025,-0.005,0.000
-0.05,3.780,0.00025,-0.005,0.000
-0.04,3.880,0.00029,-0.004,0.000
-0.05,3.980,0.00029,-0.005,0.000
-0.04,4.080,0.00033,-0.004,0.000
-0.05,4.180,0.00033,-0.005,0.000
-0.05,4.280,0.00037,-0.005,0.000
-0.05,4.380,0.00042,-0.005,0.000
-0.05,4.480,0.00046,-0.005,0.000
-0.06,4.580,0.00050,-0.006,0.000
-0.06,4.680,0.00054,-0.006,0.000
-0.07,4.780,0.00058,-0.007,0.000
-0.07,4.880,0.00062,-0.007,0.000
-0.07,4.980,0.00071,-0.007,0.000
-0.06,5.080,0.00079,-0.006,0.000
-0.09,5.180,0.00087,-0.009,0.000
-0.10,5.280,0.00096,-0.010,0.000
-0.08,5.380,0.00108,-0.008,0.000
-0.09,5.480,0.00116,-0.009,0.000
-0.09,5.580,0.00129,-0.009,0.000
-0.10,5.680,0.00137,-0.010,0.000
-0.09,5.780,0.00145,-0.009,0.000
-0.09,5.880,0.00154,-0.009,0.000
-0.08,5.980,0.00162,-0.008,0.000
-0.09,6.080,0.00170,-0.009,0.000
-0.09,6.180,0.00179,-0.009,0.000
-0.09,6.280,0.00183,-0.009,0.000
-0.09,6.380,0.00191,-0.009,0.000
-0.09,6.480,0.00199,-0.009,0.000
-0.11,6.580,0.00208,-0.011,0.000
-0.10,6.680,0.00216,-0.010,0.000
-0.11,6.780,0.00224,-0.011,0.000
-0.11,6.880,0.00229,-0.011,0.000
-0.11,6.980,0.00237,-0.011,0.000
-0.11,7.080,0.00245,-0.011,0.000
-0.10,7.180,0.00249,-0.010,0.000
-0.09,7.280,0.00258,-0.009,0.000
-0.10,7.380,0.00266,-0.010,0.000
-0.10,7.480,0.00274,-0.010,0.000
-0.11,7.580,0.00278,-0.011,0.000
-0.12,7.680,0.00287,-0.012,0.000
-0.10,7.780,0.00295,-0.010,0.000
-0.11,7.880,0.00299,-0.011,0.000
-0.12,7.980,0.00308,-0.012,0.000
-0.11,8.080,0.00312,-0.011,0.000
-0.11,8.180,0.00320,-0.011,0.000
-0.13,8.280,0.00324,-0.013,0.000
-0.13,8.380,0.00332,-0.013,0.000
-0.11,8.480,0.00341,-0.011,0.000
-0.11,8.580,0.00345,-0.011,0.000
-0.12,8.680,0.00353,-0.012,0.000
-0.12,8.780,0.00357,-0.012,0.000
-0.12,8.880,0.00366,-0.012,0.000
-0.12,8.980,0.00374,-0.012,0.000
-0.13,9.080,0.00378,-0.013,0.000
-0.13,9.180,0.00386,-0.013,0.000
-0.14,9.280,0.00391,-0.014,0.000
-0.13,9.380,0.00399,-0.013,0.000
-0.14,9.480,0.00403,-0.014,0.000
-0.14,9.580,0.00411,-0.014,0.000
-0.13,9.680,0.00420,-0.013,0.000
-0.14,9.780,0.00424,-0.014,0.000
-0.15,9.880,0.00432,-0.015,0.000
-0.15,9.980,0.00440,-0.015,0.000
-0.16,10.080,0.00445,-0.016,0.000
-0.17,10.180,0.00453,-0.017,0.000
-0.18,10.280,0.00461,-0.018,0.000
-0.18,10.380,0.00465,-0.018,0.000
-0.18,10.480,0.00474,-0.018,0.000
-0.20,10.580,0.00482,-0.020,0.000
-0.21,10.680,0.00490,-0.021,0.000
-0.23,10.780,0.00495,-0.023,0.000
-0.25,10.880,0.00503,-0.025,0.000
-0.26,10.980,0.00511,-0.026,0.000
-0.28,11.080,0.00515,-0.028,0.000
-0.30,11.180,0.00524,-0.030,0.000
-0.32,11.280,0.00532,-0.032,0.000
-0.34,11.380,0.00540,-0.034,0.000
-0.38,11.480,0.00549,-0.038,0.000
-0.40,11.580,0.00557,-0.040,0.000
-0.42,11.680,0.00561,-0.042,0.000
-0.46,11.780,0.00569,-0.046,0.000
-0.47,11.880,0.00578,-0.047,0.000
-0.49,11.980,0.00586,-0.049,0.000
-0.52,12.080,0.00594,-0.052,0.000
-0.53,12.180,0.00603,-0.053,0.000
-0.56,12.280,0.00607,-0.056,0.000
-0.59,12.380,0.00615,-0.059,0.000
-0.63,12.480,0.00623,-0.063,0.000
-0.65,12.580,0.00632,-0.065,0.000
-0.69,12.680,0.00640,-0.069,0.000
-0.71,12.780,0.00648,-0.071,0.000
-0.75,12.880,0.00657,-0.075,0.000
-0.79,12.980,0.00665,-0.079,0.000
-0.82,13.080,0.00673,-0.082,0.000
-0.85,13.180,0.00677,-0.085,0.000
-0.89,13.280,0.00686,-0.089,0.000
-0.92,13.380,0.00694,-0.092,0.000
-0.96,13.480,0.00702,-0.096,0.000
-1.00,13.580,0.00711,-0.100,0.000
-1.02,13.680,0.00719,-0.102,0.000
-1.07,13.780,0.00731,-0.107,0.000
-1.11,13.880,0.00740,-0.111,0.000
-1.16,13.980,0.00748,-0.116,0.000
-1.20,14.080,0.00756,-0.120,0.000
-1.23,14.180,0.00765,-0.123,0.000
-1.28,14.280,0.00773,-0.128,0.000
-1.32,14.380,0.00781,-0.132,0.000
-1.36,14.480,0.00790,-0.136,0.000
-1.41,14.580,0.00802,-0.141,0.000
-1.48,14.680,0.00810,-0.148,0.000
-1.52,14.780,0.00823,-0.152,0.000
-1.58,14.880,0.00831,-0.158,0.000
-1.64,14.980,0.00839,-0.164,0.000
-1.68,15.080,0.00852,-0.168,0.000
-1.76,15.180,0.00860,-0.176,0.000
-1.80,15.280,0.00873,-0.180,0.000
-1.86,15.380,0.00881,-0.186,0.000
-1.93,15.480,0.00893,-0.193,0.000
-2.00,15.580,0.00906,-0.200,0.000
-2.07,15.680,0.00914,-0.207,0.000
-2.13,15.780,0.00927,-0.213,0.000
-2.18,15.880,0.00939,-0.218,0.000
-2.23,15.980,0.00947,-0.223,0.000
-2.30,16.080,0.00960,-0.230,0.000
-2.36,16.180,0.00968,-0.236,0.000
-2.42,16.280,0.00981,-0.242,0.000
-2.48,16.380,0.00993,-0.248,0.000
-2.55,16.480,0.01001,-0.255,0.000
-2.61,16.580,0.01010,-0.261,0.000
-2.65,16.680,0.01022,-0.265,0.000
-2.71,16.780,0.01031,-0.271,0.000
-2.77,16.880,0.01043,-0.277,0.000
-2.85,16.980,0.01051,-0.285,0.000
-2.88,17.080,0.01064,-0.288,0.000
-2.95,17.180,0.01072,-0.295,0.000
-2.99,17.280,0.01080,-0.299,0.000
-3.05,17.380,0.01089,-0.305,0.000
-3.09,17.480,0.01101,-0.309,0.000
-3.14,17.580,0.01110,-0.314,0.000
-3.20,17.680,0.01118,-0.320,0.000
-3.24,17.780,0.01126,-0.324,0.000
-3.29,17.880,0.01134,-0.329,0.000
-3.33,17.980,0.01143,-0.333,0.000
-3.39,18.080,0.01147,-0.339,0.000
-3.43,18.180,0.01155,-0.343,0.000
-3.48,18.280,0.01164,-0.348,0.000
-3.55,18.380,0.01172,-0.355,0.000
-3.58,18.480,0.01180,-0.358,0.000
-3.63,18.580,0.01188,-0.363,0.000
-3.67,18.680,0.01197,-0.367,0.000
-3.72,18.780,0.01201,-0.372,0.000
-3.74,18.880,0.01209,-0.374,0.000
-3.80,18.980,0.01213,-0.380,0.000
-3.81,19.080,0.01222,-0.381,0.000
-3.88,19.180,0.01230,-0.388,0.000
-3.92,19.280,0.01238,-0.392,0.000
-3.99,19.380,0.01247,-0.399,0.000
-4.01,19.480,0.01251,-0.401,0.000
-4.07,19.580,0.01259,-0.407,0.000
-4.12,19.680,0.01267,-0.412,0.000
-4.15,19.780,0.01272,-0.415,0.000
-4.18,19.880,0.01280,-0.418,0.000
-4.23,19.980,0.01284,-0.423,0.000
-4.26,20.080,0.01292,-0.426,0.000
-4.32,20.180,0.01301,-0.432,0.000
-4.36,20.280,0.01305,-0.436,0.000
-4.41,20.380,0.01313,-0.441,0.000
-4.45,20.480,0.01317,-0.445,0.000
-4.49,20.580,0.01326,-0.449,0.000
-4.55,20.680,0.01334,-0.455,0.000
-4.59,20.780,0.01338,-0.459,0.000
-4.64,20.880,0.01346,-0.464,0.000
-4.66,20.980,0.01351,-0.466,0.000
-4.72,21.080,0.01359,-0.472,0.000
-4.76,21.180,0.01367,-0.476,0.000
-4.81,21.280,0.01371,-0.481,0.000
-4.85,21.380,0.01380,-0.485,0.000
-4.91,21.480,0.01388,-0.491,0.000
-4.95,21.580,0.01396,-0.495,0.000
-5.02,21.680,0.01400,-0.502,0.000
-5.06,21.780,0.01409,-0.506,0.000
-5.10,21.880,0.01417,-0.510,0.000
-5.15,21.980,0.01425,-0.515,0.000
-5.21,22.080,0.01430,-0.521,0.000
-5.25,22.180,0.01438,-0.525,0.000
-5.31,22.280,0.01446,-0.531,0.000
-5.35,22.380,0.01454,-0.535,0.000
-5.39,22.480,0.01463,-0.539,0.000
-5.45,22.580,0.01467,-0.545,0.000
-5.50,22.680,0.01475,-0.550,0.000
-5.54,22.780,0.01484,-0.554,0.000
-5.61,22.880,0.01492,-0.561,0.000
-5.65,22.980,0.01500,-0.565,0.000
-5.71,23.080,0.01508,-0.571,0.000
-5.77,23.180,0.01517,-0.577,0.000
-5.82,23.280,0.01525,-0.582,0.000
-5.87,23.380,0.01533,-0.587,0.000
-5.94,23.480,0.01538,-0.594,0.000
-5.99,23.580,0.01546,-0.599,0.000
-6.04,23.680,0.01554,-0.604,0.000
-6.09,23.780,0.01562,-0.609,0.000
-6.15,23.880,0.01571,-0.615,0.000
-6.22,23.980,0.01579,-0.622,0.000
-6.27,24.080,0.01587,-0.627,0.000
-6.34,24.180,0.01596,-0.634,0.000
-6.39,24.280,0.01604,-0.639,0.000
-6.44,24.380,0.01612,-0.644,0.000
-6.48,24.480,0.01621,-0.648,0.000
-6.56,24.580,0.01629,-0.656,0.000
-6.61,24.680,0.01637,-0.661,0.000
-6.67,24.780,0.01646,-0.667,0.000
-6.72,24.880,0.01654,-0.672,0.000
-6.78,24.980,0.01662,-0.678,0.000
-6.84,25.080,0.01671,-0.684,0.000
-6.89,25.180,0.01679,-0.689,0.000
-6.96,25.280,0.01687,-0.696,0.000
-7.02,25.380,0.01700,-0.702,0.000
-7.10,25.480,0.01708,-0.710,0.000
-7.17,25.580,0.01716,-0.717,0.000
-7.22,25.680,0.01725,-0.722,0.000
-7.28,25.780,0.01733,-0.728,0.000
-7.35,25.880,0.01745,-0.735,0.000
-7.43,25.980,0.01754,-0.743,0.000
-7.48,26.080,0.01766,-0.748,0.000
-7.56,26.180,0.01774,-0.756,0.000
-7.62,26.280,0.01787,-0.762,0.000
-7.70,26.380,0.01795,-0.770,0.000
-7.76,26.480,0.01808,-0.776,0.000
-7.82,26.580,0.01816,-0.782,0.000
-7.91,26.680,0.01828,-0.791,0.000
-7.97,26.780,0.01837,-0.797,0.000
-8.04,26.880,0.01849,-0.804,0.000
-8.13,26.980,0.01862,-0.813,0.000
-8.23,27.080,0.01874,-0.823,0.000
-8.29,27.180,0.01882,-0.829,0.000
-8.36,27.280,0.01895,-0.836,0.000
-8.42,27.380,0.01907,-0.842,0.000
-8.49,27.480,0.01916,-0.849,0.000
-8.56,27.580,0.01928,-0.856,0.000
-8.64,27.680,0.01937,-0.864,0.000
-8.71,27.780,0.01949,-0.871,0.000
-8.78,27.880,0.01961,-0.878,0.000
-8.86,27.980,0.01970,-0.886,0.000
-8.90,28.080,0.01982,-0.890,0.000
-8.98,28.180,0.01991,-0.898,0.000
-9.03,28.280,0.01999,-0.903,0.000
-9.10,28.380,0.02011,-0.910,0.000
-9.15,28.480,0.02020,-0.915,0.000
-9.22,28.580,0.02028,-0.922,0.000
-9.28,28.680,0.02040,-0.928,0.000
-9.35,28.780,0.02049,-0.935,0.000
-9.39,28.880,0.02057,-0.939,0.000
-9.45,28.980,0.02065,-0.945,0.000
-9.50,29.080,0.02074,-0.950,0.000
-9.54,29.180,0.02082,-0.954,0.000
-9.58,29.280,0.02090,-0.958,0.000
-9.64,29.380,0.02099,-0.964,0.000
-9.68,29.480,0.02107,-0.968,0.000
-9.72,29.580,0.02111,-0.972,0.000
-9.76,29.680,0.02119,-0.976,0.000
-9.81,29.780,0.02128,-0.981,0.000
-9.86,29.880,0.02136,-0.986,0.000
-9.89,29.980,0.02144,-0.989,0.000
-9.95,30.080,0.02148,-0.995,0.000
-9.99,30.180,0.02157,-0.999,0.000
-10.04,30.280,0.02165,-1.004,0.000
-10.09,30.380,0.02173,-1.009,0.000
-10.13,30.480,0.02182,-1.013,0.000
-10.17,30.580,0.02186,-1.017,0.000
-10.22,30.680,0.02194,-1.022,0.000
-10.24,30.780,0.02198,-1.024,0.000
-10.29,30.880,0.02207,-1.029,0.000
-10.33,30.980,0.02215,-1.033,0.000
-10.37,31.080,0.02219,-1.037,0.000
-10.43,31.180,0.02227,-1.043,0.000
-10.46,31.280,0.02236,-1.046,0.000
-10.48,31.380,0.02240,-1.048,0.000
-10.53,31.480,0.02248,-1.053,0.000
-10.58,31.580,0.02252,-1.058,0.000
-10.61,31.680,0.02261,-1.061,0.000
-10.65,31.780,0.02269,-1.065,0.000
-10.70,31.880,0.02273,-1.070,0.000
-10.73,31.980,0.02281,-1.073,0.000
-10.77,32.080,0.02290,-1.077,0.000
-10.80,32.180,0.02294,-1.080,0.000
-10.85,32.280,0.02302,-1.085,0.000
-10.91,32.380,0.02311,-1.091,0.000
-10.94,32.480,0.02315,-1.094,0.000
-10.99,32.580,0.02323,-1.099,0.000
-11.02,32.680,0.02331,-1.102,0.000
-11.07,32.780,0.02340,-1.107,0.000
-11.11,32.880,0.02344,-1.111,0.000
-11.14,32.980,0.02352,-1.114,0.000
-11.20,33.080,0.02360,-1.120,0.000
-11.25,33.180,0.02369,-1.125,0.000
-11.27,33.280,0.02377,-1.127,0.000
-11.32,33.380,0.02381,-1.132,0.000
-11.37,33.480,0.02389,-1.137,0.000
-11.41,33.580,0.02398,-1.141,0.000
-11.46,33.680,0.02406,-1.146,0.000
-11.49,33.780,0.02410,-1.149,0.000
-11.56,33.880,0.02419,-1.156,0.000
-11.59,33.980,0.02427,-1.159,0.000
-11.64,34.080,0.02435,-1.164,0.000
-11.68,34.180,0.02443,-1.168,0.000
-11.71,34.280,0.02452,-1.171,0.000
-11.77,34.380,0.02456,-1.177,0.000
-11.81,34.480,0.02464,-1.181,0.000
-11.86,34.580,0.02473,-1.186,0.000
-11.92,34.680,0.02481,-1.192,0.000
-11.97,34.780,0.02489,-1.197,0.000
-12.01,34.880,0.02498,-1.201,0.000
-12.06,34.980,0.02506,-1.206,0.000
-12.11,35.080,0.02514,-1.211,0.000
-12.17,35.180,0.02518,-1.217,0.000
-12.21,35.280,0.02527,-1.221,0.000
-12.26,35.380,0.02535,-1.226,0.000
-12.31,35.480,0.02543,-1.231,0.001
-12.37,35.580,0.02552,-1.237,0.001
-12.40,35.680,0.02560,-1.240,0.001
-12.45,35.780,0.02568,-1.245,0.001
-12.51,35.880,0.02576,-1.251,0.001
-12.56,35.980,0.02585,-1.256,0.001
-12.61,36.080,0.02593,-1.261,0.001
-12.66,36.180,0.02601,-1.266,0.001
-12.70,36.280,0.02610,-1.270,0.001
-12.75,36.380,0.02618,-1.275,0.001
-12.81,36.480,0.02626,-1.281,0.001
-12.87,36.580,0.02635,-1.287,0.001
-12.92,36.680,0.02643,-1.292,0.001
-12.98,36.780,0.02655,-1.298,0.001
-13.03,36.880,0.02664,-1.303,0.001
-13.12,36.980,0.02672,-1.312,0.001
-13.15,37.080,0.02680,-1.315,0.001
-13.21,37.180,0.02693,-1.321,0.001
-13.28,37.280,0.02701,-1.328,0.001
-13.34,37.380,0.02709,-1.334,0.001
-13.39,37.480,0.02722,-1.339,0.001
-13.45,37.580,0.02730,-1.345,0.001
-13.52,37.680,0.02743,-1.352,0.001
-13.59,37.780,0.02751,-1.359,0.001
-13.65,37.880,0.02763,-1.365,0.001
-13.73,37.980,0.02772,-1.373,0.001
-13.80,38.080,0.02784,-1.380,0.001
-13.87,38.180,0.02797,-1.387,0.001
-13.91,38.280,0.02805,-1.391,0.001
-13.98,38.380,0.02817,-1.398,0.001
-14.03,38.480,0.02826,-1.403,0.001
-14.11,38.580,0.02838,-1.411,0.001
-14.18,38.680,0.02847,-1.418,0.001
-14.24,38.780,0.02859,-1.424,0.001
-14.32,38.880,0.02872,-1.432,0.001
-14.39,38.980,0.02880,-1.439,0.001
-14.44,39.080,0.02888,-1.444,0.001
-14.50,39.180,0.02901,-1.450,0.001
-14.54,39.280,0.02909,-1.454,0.001
-14.59,39.380,0.02921,-1.459,0.001
-14.65,39.480,0.02930,-1.465,0.001
-14.70,39.580,0.02938,-1.470,0.001
-14.76,39.680,0.02950,-1.476,0.001
-14.81,39.780,0.02959,-1.481,0.001
-14.87,39.880,0.02967,-1.487,0.001
-14.91,39.980,0.02975,-1.491,0.001
-14.97,40.080,0.02988,-1.497,0.001
-15.01,40.180,0.02996,-1.501,0.001
-15.07,40.280,0.03004,-1.507,0.001
-15.10,40.380,0.03013,-1.510,0.001
-15.16,40.480,0.03021,-1.516,0.001
-15.19,40.580,0.03029,-1.519,0.001
-15.26,40.680,0.03038,-1.526,0.001
-15.30,40.780,0.03046,-1.530,0.001
-15.35,40.880,0.03054,-1.535,0.001
-15.37,40.980,0.03059,-1.537,0.001
-15.42,41.080,0.03067,-1.542,0.001
-15.45,41.180,0.03075,-1.545,0.001
-15.51,41.280,0.03083,-1.551,0.001
-15.54,41.380,0.03092,-1.554,0.001
-15.57,41.480,0.03100,-1.557,0.001
-15.62,41.580,0.03104,-1.562,0.001
-15.66,41.680,0.03113,-1.566,0.001
-15.68,41.780,0.03121,-1.568,0.001
-15.74,41.880,0.03129,-1.574,0.001
-15.76,41.980,0.03133,-1.576,0.001
-15.81,42.080,0.03142,-1.581,0.001
-15.84,42.180,0.03150,-1.584,0.001
-15.88,42.280,0.03154,-1.588,0.001
-15.92,42.380,0.03162,-1.592,0.001
-15.94,42.480,0.03171,-1.594,0.001
-15.98,42.580,0.03175,-1.598,0.001
-16.00,42.680,0.03183,-1.600,0.001
-16.05,42.780,0.03187,-1.605,0.001
-16.06,42.880,0.03196,-1.606,0.001
-16.11,42.980,0.03204,-1.611,0.001
-16.15,43.080,0.03208,-1.615,0.001
-16.17,43.180,0.03216,-1.617,0.001
-16.20,43.280,0.03225,-1.620,0.001
-16.25,43.380,0.03229,-1.625,0.001
-16.29,43.480,0.03237,-1.629,0.001
-16.34,43.580,0.03246,-1.634,0.001
-16.37,43.680,0.03250,-1.637,0.001
-16.42,43.780,0.03258,-1.642,0.001
-16.45,43.880,0.03266,-1.645,0.001
-16.50,43.980,0.03270,-1.650,0.001
-16.52,44.080,0.03279,-1.652,0.001
-16.57,44.180,0.03287,-1.657,0.001
-16.60,44.280,0.03291,-1.660,0.001
-16.66,44.380,0.03300,-1.666,0.001
-16.70,44.480,0.03308,-1.670,0.001
-16.75,44.580,0.03316,-1.675,0.001
-16.78,44.680,0.03320,-1.678,0.001
-16.83,44.780,0.03329,-1.683,0.001
-16.85,44.880,0.03337,-1.685,0.001
-16.92,44.980,0.03345,-1.692,0.001
-16.94,45.080,0.03349,-1.694,0.001
-17.00,45.180,0.03358,-1.700,0.001
-17.04,45.280,0.03366,-1.704,0.001
-17.08,45.380,0.03374,-1.708,0.001
-17.11,45.480,0.03383,-1.711,0.001
-17.18,45.580,0.03391,-1.718,0.001
-17.21,45.680,0.03395,-1.721,0.001
-17.26,45.780,0.03403,-1.726,0.001
-17.30,45.880,0.03412,-1.730,0.001
-17.36,45.980,0.03420,-1.736,0.001
-17.39,46.080,0.03428,-1.739,0.001
-17.45,46.180,0.03437,-1.745,0.001
-17.50,46.280,0.03445,-1.750,0.001
-17.55,46.380,0.03453,-1.755,0.001
-17.57,46.480,0.03457,-1.757,0.001
-17.64,46.580,0.03466,-1.764,0.001
-17.68,46.680,0.03474,-1.768,0.001
-17.72,46.780,0.03482,-1.772,0.001
-17.76,46.880,0.03491,-1.776,0.001
-17.82,46.980,0.03499,-1.782,0.001
-17.86,47.080,0.03507,-1.786,0.001
-17.89,47.180,0.03516,-1.789,0.001
-17.95,47.280,0.03524,-1.795,0.001
-17.99,47.380,0.03532,-1.799,0.001
-18.05,47.480,0.03541,-1.805,0.001
-18.09,47.580,0.03549,-1.809,0.001
-18.12,47.680,0.03557,-1.812,0.001
-18.18,47.780,0.03565,-1.818,0.001
-18.22,47.880,0.03574,-1.822,0.001
-18.26,47.980,0.03582,-1.826,0.001
-18.32,48.080,0.03590,-1.832,0.001
-18.36,48.180,0.03599,-1.836,0.001
-18.43,48.280,0.03607,-1.843,0.001
-18.46,48.380,0.03620,-1.846,0.001
-18.52,48.480,0.03628,-1.852,0.001
-18.55,48.580,0.03636,-1.855,0.001
-18.63,48.680,0.03649,-1.863,0.001
-18.68,48.780,0.03657,-1.868,0.001
-18.71,48.880,0.03669,-1.871,0.001
-18.74,48.980,0.03678,-1.874,0.001
-18.84,49.080,0.03690,-1.884,0.001
-18.89,49.180,0.03698,-1.889,0.001
-18.96,49.280,0.03711,-1.896,0.001
-19.00,49.380,0.03719,-1.900,0.001
-19.03,49.480,0.03732,-1.903,0.001
-19.07,49.580,0.03744,-1.907,0.001
-19.15,49.680,0.03757,-1.915,0.001
-19.20,49.780,0.03765,-1.920,0.001
-19.29,49.880,0.03777,-1.929,0.001
-19.26,49.980,0.03790,-1.926,0.001
-19.29,50.080,0.03798,-1.929,0.001
-19.34,50.180,0.03811,-1.934,0.001
-19.43,50.280,0.03819,-1.943,0.001
-19.46,50.380,0.03831,-1.946,0.001
-19.52,50.480,0.03840,-1.952,0.001
-19.55,50.580,0.03852,-1.955,0.001
-19.62,50.680,0.03865,-1.962,0.001
-19.64,50.780,0.03873,-1.964,0.001
-19.71,50.880,0.03881,-1.971,0.001
-19.72,50.980,0.03894,-1.972,0.001
-19.79,51.080,0.03902,-1.979,0.001
-19.81,51.180,0.03910,-1.981,0.001
-19.85,51.280,0.03923,-1.985,0.001
-19.89,51.380,0.03931,-1.989,0.001
-19.89,51.480,0.03939,-1.989,0.001
-19.94,51.580,0.03948,-1.994,0.001
-20.00,51.680,0.03956,-2.000,0.001
-20.01,51.780,0.03964,-2.001,0.001
-20.06,51.880,0.03973,-2.006,0.001
-20.08,51.980,0.03981,-2.008,0.001
-20.11,52.080,0.03989,-2.011,0.001
-20.14,52.180,0.03998,-2.014,0.001
-20.20,52.280,0.04006,-2.020,0.001
-20.20,52.380,0.04014,-2.020,0.001
-20.24,52.480,0.04023,-2.024,0.001
-20.26,52.580,0.04031,-2.026,0.001
-20.28,52.680,0.04035,-2.028,0.001
-20.28,52.780,0.04043,-2.028,0.001
-20.31,52.880,0.04052,-2.031,0.001
-20.35,52.980,0.04056,-2.035,0.001
-20.37,53.080,0.04064,-2.037,0.001
-20.39,53.180,0.04072,-2.039,0.001
-20.41,53.280,0.04081,-2.041,0.001
-20.44,53.380,0.04085,-2.044,0.001
-20.47,53.480,0.04093,-2.047,0.001
-20.51,53.580,0.04102,-2.051,0.001
-20.51,53.680,0.04106,-2.051,0.001
-20.55,53.780,0.04114,-2.055,0.001
-20.56,53.880,0.04122,-2.056,0.001
-20.58,53.980,0.04126,-2.058,0.001
-20.60,54.080,0.04135,-2.060,0.001
-20.62,54.180,0.04143,-2.062,0.001
-20.62,54.280,0.04147,-2.062,0.001
-20.67,54.380,0.04156,-2.067,0.001
-20.66,54.480,0.04160,-2.066,0.001
-20.69,54.580,0.04168,-2.069,0.001
-20.71,54.680,0.04176,-2.071,0.001
-20.75,54.780,0.04181,-2.075,0.001
-20.75,54.880,0.04189,-2.075,0.001
-20.79,54.980,0.04197,-2.079,0.001
-20.79,55.080,0.04201,-2.079,0.001
-20.84,55.180,0.04210,-2.084,0.001
-20.83,55.280,0.04218,-2.083,0.001
-20.88,55.380,0.04226,-2.088,0.001
-20.88,55.480,0.04230,-2.088,0.001
-20.90,55.580,0.04239,-2.090,0.001
-20.91,55.680,0.04247,-2.091,0.001
-20.94,55.780,0.04255,-2.094,0.001
-20.96,55.880,0.04259,-2.096,0.001
-20.98,55.980,0.04268,-2.098,0.001
-21.00,56.080,0.04276,-2.100,0.001
-21.04,56.180,0.04284,-2.104,0.001
-21.05,56.280,0.04293,-2.105,0.001
-21.08,56.380,0.04297,-2.108,0.001
-21.09,56.480,0.04305,-2.109,0.001
-21.13,56.580,0.04313,-2.113,0.001
-21.14,56.680,0.04322,-2.114,0.001
-21.19,56.780,0.04330,-2.119,0.001
-21.19,56.880,0.04338,-2.119,0.001
-21.23,56.980,0.04347,-2.123,0.001
-21.25,57.080,0.04351,-2.125,0.001
-21.27,57.180,0.04359,-2.127,0.001
-21.28,57.280,0.04368,-2.128,0.001
-21.32,57.380,0.04376,-2.132,0.001
-21.35,57.480,0.04384,-2.135,0.001
-21.37,57.580,0.04392,-2.137,0.001
-21.39,57.680,0.04401,-2.139,0.001
-21.40,57.780,0.04409,-2.140,0.001
-21.44,57.880,0.04417,-2.144,0.001
-21.46,57.980,0.04426,-2.146,0.001
-21.48,58.080,0.04434,-2.148,0.001
-21.48,58.180,0.04442,-2.148,0.001
-21.51,58.280,0.04451,-2.151,0.001
-21.52,58.380,0.04459,-2.152,0.001
-21.55,58.480,0.04467,-2.155,0.001
-21.56,58.580,0.04476,-2.156,0.001
-21.59,58.680,0.04484,-2.159,0.001
-21.61,58.780,0.04492,-2.161,0.001
-21.63,58.880,0.04500,-2.163,0.001
-21.63,58.980,0.04505,-2.163,0.001
-21.66,59.080,0.04513,-2.166,0.001
-21.67,59.180,0.04521,-2.167,0.001
-21.71,59.280,0.04534,-2.171,0.001
-21.73,59.380,0.04542,-2.173,0.001
-21.78,59.480,0.04550,-2.178,0.001
-21.79,59.580,0.04563,-2.179,0.001
-21.79,59.680,0.04571,-2.179,0.001
-21.80,59.780,0.04579,-2.180,0.001
-21.84,59.880,0.04588,-2.184,0.001
-21.85,59.980,0.04600,-2.185,0.001
-21.90,60.080,0.04609,-2.190,0.001
-21.90,60.180,0.04621,-2.190,0.001
-21.94,60.280,0.04629,-2.194,0.001
-21.94,60.380,0.04638,-2.194,0.001
-21.99,60.480,0.04650,-2.199,0.001
-21.98,60.580,0.04663,-2.198,0.001
-22.03,60.680,0.04671,-2.203,0.001
-22.04,60.780,0.04683,-2.204,0.001
-22.04,60.880,0.04696,-2.204,0.001
-22.06,60.980,0.04704,-2.206,0.001
-22.10,61.080,0.04717,-2.210,0.001
-22.11,61.180,0.04725,-2.211,0.001
-22.14,61.280,0.04737,-2.214,0.001
-22.15,61.380,0.04750,-2.215,0.001
-22.15,61.480,0.04758,-2.215,0.001
-22.15,61.580,0.04771,-2.215,0.001
-22.16,61.680,0.04779,-2.216,0.001
-22.16,61.780,0.04787,-2.216,0.001
-22.19,61.880,0.04800,-2.219,0.001
-22.19,61.980,0.04808,-2.219,0.001
-22.20,62.080,0.04820,-2.220,0.001
-22.21,62.180,0.04829,-2.221,0.001
-22.21,62.280,0.04841,-2.221,0.001
-22.20,62.380,0.04850,-2.220,0.001
-22.22,62.480,0.04862,-2.222,0.001
-22.23,62.580,0.04870,-2.223,0.001
-22.21,62.680,0.04879,-2.221,0.001
-22.19,62.780,0.04887,-2.219,0.001
-22.19,62.880,0.04895,-2.219,0.001
-22.14,62.980,0.04908,-2.214,0.001
-22.13,63.080,0.04916,-2.213,0.001
-22.13,63.180,0.04924,-2.213,0.001
-22.14,63.280,0.04933,-2.214,0.001
-22.12,63.380,0.04937,-2.212,0.001
-22.12,63.480,0.04945,-2.212,0.001
-22.12,63.580,0.04953,-2.212,0.001
-22.11,63.680,0.04962,-2.211,0.001
-22.09,63.780,0.04970,-2.209,0.001
-22.09,63.880,0.04978,-2.209,0.001
-22.09,63.980,0.04987,-2.209,0.001
-22.08,64.080,0.04995,-2.208,0.001
-22.08,64.180,0.04999,-2.208,0.001
-22.05,64.280,0.05007,-2.205,0.001
-22.05,64.380,0.05016,-2.205,0.001
-22.04,64.480,0.05024,-2.204,0.001
-22.04,64.580,0.05028,-2.204,0.001
-22.02,64.680,0.05037,-2.202,0.001
-22.02,64.780,0.05045,-2.202,0.001
-22.01,64.880,0.05049,-2.201,0.001
-22.02,64.980,0.05057,-2.202,0.001
-22.00,65.080,0.05066,-2.200,0.001
-22.00,65.180,0.05070,-2.200,0.001
-21.97,65.280,0.05078,-2.197,0.001
-21.97,65.380,0.05082,-2.197,0.001
-21.95,65.480,0.05091,-2.195,0.001
-21.97,65.580,0.05099,-2.197,0.001
-21.92,65.680,0.05103,-2.192,0.001
-21.96,65.780,0.05111,-2.196,0.001
-21.93,65.880,0.05120,-2.193,0.001
-21.95,65.980,0.05124,-2.195,0.001
-21.92,66.080,0.05132,-2.192,0.001
-21.93,66.180,0.05140,-2.193,0.001
-21.92,66.280,0.05149,-2.192,0.001
-21.94,66.380,0.05153,-2.194,0.001
-21.94,66.480,0.05161,-2.194,0.001
-21.94,66.580,0.05170,-2.194,0.001
-21.95,66.680,0.05178,-2.195,0.001
-21.96,66.780,0.05186,-2.196,0.001
-21.95,66.880,0.05190,-2.195,0.001
-21.97,66.980,0.05199,-2.197,0.001
-21.96,67.080,0.05207,-2.196,0.001
-21.98,67.180,0.05215,-2.198,0.001
-21.96,67.280,0.05224,-2.196,0.001
-21.98,67.380,0.05228,-2.198,0.001
-21.98,67.480,0.05236,-2.198,0.001
-21.99,67.580,0.05244,-2.199,0.001
-21.98,67.680,0.05253,-2.198,0.001
-22.00,67.780,0.05261,-2.200,0.001
-22.00,67.880,0.05269,-2.200,0.001
-21.99,67.980,0.05278,-2.199,0.001
-22.00,68.080,0.05286,-2.200,0.001
-22.02,68.180,0.05294,-2.202,0.001
-22.03,68.280,0.05298,-2.203,0.001
-22.01,68.380,0.05307,-2.201,0.001
-22.03,68.480,0.05315,-2.203,0.001
-22.03,68.580,0.05323,-2.203,0.001
-22.04,68.680,0.05332,-2.204,0.001
-22.06,68.780,0.05340,-2.206,0.001
-22.07,68.880,0.05348,-2.207,0.001
-22.07,68.980,0.05357,-2.207,0.001
-22.08,69.080,0.05365,-2.208,0.001
-22.06,69.180,0.05373,-2.206,0.001
-22.07,69.280,0.05377,-2.207,0.001
-22.08,69.380,0.05386,-2.208,0.001
-22.11,69.480,0.05394,-2.211,0.001
-22.11,69.580,0.05402,-2.211,0.001
-22.14,69.680,0.05411,-2.214,0.001
-22.15,69.780,0.05419,-2.215,0.001
-22.17,69.880,0.05427,-2.217,0.001
-22.18,69.980,0.05436,-2.218,0.001
-22.20,70.080,0.05444,-2.220,0.001
-22.22,70.180,0.05452,-2.222,0.001
-22.23,70.280,0.05460,-2.223,0.001
-22.25,70.380,0.05469,-2.225,0.001
-22.26,70.480,0.05477,-2.226,0.001
-22.30,70.580,0.05490,-2.230,0.001
-22.32,70.680,0.05498,-2.232,0.001
-22.37,70.780,0.05506,-2.237,0.001
-22.40,70.880,0.05514,-2.240,0.001
-22.42,70.980,0.05527,-2.242,0.001
-22.46,71.080,0.05535,-2.246,0.001
-22.48,71.180,0.05544,-2.248,0.001
-22.51,71.280,0.05556,-2.251,0.001
-22.54,71.380,0.05564,-2.254,0.001
-22.59,71.480,0.05573,-2.259,0.001
-22.63,71.580,0.05585,-2.263,0.001
-22.70,71.680,0.05598,-2.270,0.001
-22.73,71.780,0.05606,-2.273,0.001
-22.77,71.880,0.05618,-2.277,0.001
-22.82,71.980,0.05627,-2.282,0.001
-22.86,72.080,0.05639,-2.286,0.001
-22.92,72.180,0.05652,-2.292,0.001
-22.96,72.280,0.05660,-2.296,0.001
-22.99,72.380,0.05672,-2.299,0.001
-23.03,72.480,0.05681,-2.303,0.001
-23.07,72.580,0.05693,-2.307,0.001
-23.10,72.680,0.05701,-2.310,0.001
-23.16,72.780,0.05714,-2.316,0.001
-23.21,72.880,0.05726,-2.321,0.001
-23.25,72.980,0.05735,-2.325,0.001
-23.29,73.080,0.05747,-2.329,0.001
-23.33,73.180,0.05755,-2.333,0.001
-23.38,73.280,0.05764,-2.338,0.001
-23.42,73.380,0.05776,-2.342,0.001
-23.44,73.480,0.05785,-2.344,0.001
-23.50,73.580,0.05797,-2.350,0.001
-23.52,73.680,0.05805,-2.352,0.001
-23.55,73.780,0.05814,-2.355,0.001
-23.59,73.880,0.05822,-2.359,0.001
-23.62,73.980,0.05830,-2.362,0.001
-23.64,74.080,0.05839,-2.364,0.001
-23.69,74.180,0.05847,-2.369,0.001
-23.73,74.280,0.05855,-2.373,0.001
-23.78,74.380,0.05864,-2.378,0.001
-23.81,74.480,0.05872,-2.381,0.001
-23.85,74.580,0.05880,-2.385,0.001
-23.86,74.680,0.05888,-2.386,0.001
-23.91,74.780,0.05897,-2.391,0.001
-23.93,74.880,0.05905,-2.393,0.001
-23.96,74.980,0.05913,-2.396,0.001
-23.99,75.080,0.05922,-2.399,0.001
-24.04,75.180,0.05930,-2.404,0.001
-24.07,75.280,0.05934,-2.407,0.001
-24.11,75.380,0.05942,-2.411,0.001
-24.14,75.480,0.05951,-2.414,0.001
-24.17,75.580,0.05959,-2.417,0.001
-24.22,75.680,0.05963,-2.422,0.001
-24.24,75.780,0.05972,-2.424,0.001
-24.29,75.880,0.05980,-2.429,0.001
-24.32,75.980,0.05988,-2.432,0.001
-24.35,76.080,0.05992,-2.435,0.001
-24.38,76.180,0.06001,-2.438,0.001
-24.42,76.280,0.06005,-2.442,0.001
-24.44,76.380,0.06013,-2.444,0.001
-24.47,76.480,0.06021,-2.447,0.001
-24.51,76.580,0.06026,-2.451,0.001
-24.53,76.680,0.06034,-2.453,0.001
-24.57,76.780,0.06038,-2.457,0.001
-24.61,76.880,0.06046,-2.461,0.001
-24.66,76.980,0.06055,-2.466,0.001
-24.69,77.080,0.06059,-2.469,0.001
-24.71,77.180,0.06067,-2.471,0.001
-24.75,77.280,0.06071,-2.475,0.001
-24.79,77.380,0.06080,-2.479,0.001
-24.84,77.480,0.06088,-2.484,0.001
-24.88,77.580,0.06096,-2.488,0.001
-24.93,77.680,0.06100,-2.493,0.001
-24.97,77.780,0.06109,-2.497,0.001
-25.02,77.880,0.06117,-2.502,0.001
-25.07,77.980,0.06125,-2.507,0.001
-25.10,78.080,0.06129,-2.510,0.001
-25.13,78.180,0.06138,-2.513,0.001
-25.17,78.280,0.06146,-2.517,0.001
-25.22,78.380,0.06150,-2.522,0.001
-25.26,78.480,0.06159,-2.526,0.001
-25.30,78.580,0.06167,-2.530,0.001
-25.34,78.680,0.06175,-2.534,0.001
-25.40,78.780,0.06184,-2.540,0.001
-25.43,78.880,0.06188,-2.543,0.001
-25.49,78.980,0.06196,-2.549,0.001
-25.51,79.080,0.06204,-2.551,0.001
-25.58,79.180,0.06213,-2.558,0.001
-25.62,79.280,0.06221,-2.562,0.001
-25.67,79.380,0.06225,-2.567,0.001
-25.69,79.480,0.06233,-2.569,0.001
-25.75,79.580,0.06242,-2.575,0.001
-25.81,79.680,0.06250,-2.581,0.001
-25.86,79.780,0.06258,-2.586,0.001
-25.89,79.880,0.06267,-2.589,0.001
-25.94,79.980,0.06275,-2.594,0.001
-25.98,80.080,0.06279,-2.598,0.001
-26.04,80.180,0.06287,-2.604,0.001
-26.09,80.280,0.06296,-2.609,0.001
-26.14,80.380,0.06304,-2.614,0.001
-26.18,80.480,0.06312,-2.618,0.001
-26.25,80.580,0.06321,-2.625,0.001
-26.30,80.680,0.06329,-2.630,0.001
-26.34,80.780,0.06337,-2.634,0.001
-26.39,80.880,0.06346,-2.639,0.001
-26.46,80.980,0.06354,-2.646,0.001
-26.51,81.080,0.06362,-2.651,0.001
-26.57,81.180,0.06366,-2.657,0.001
-26.62,81.280,0.06375,-2.662,0.001
-26.68,81.380,0.06387,-2.668,0.001
-26.74,81.480,0.06391,-2.674,0.001
-26.80,81.580,0.06400,-2.680,0.001
-26.86,81.680,0.06408,-2.686,0.001
-26.91,81.780,0.06420,-2.691,0.001
-27.00,81.880,0.06429,-2.700,0.001
-27.06,81.980,0.06437,-2.706,0.001
-27.13,82.080,0.06445,-2.713,0.001
-27.19,82.180,0.06458,-2.719,0.001
-27.28,82.280,0.06466,-2.728,0.001
-27.35,82.380,0.06474,-2.735,0.001
-27.43,82.480,0.06487,-2.743,0.001
-27.49,82.580,0.06495,-2.749,0.001
-27.58,82.680,0.06508,-2.758,0.001
-27.65,82.780,0.06516,-2.765,0.001
-27.75,82.880,0.06528,-2.775,0.001
-27.81,82.980,0.06541,-2.781,0.001
-27.89,83.080,0.06549,-2.789,0.001
-27.96,83.180,0.06562,-2.796,0.001
-28.06,83.280,0.06574,-2.806,0.001
-28.14,83.380,0.06582,-2.814,0.001
-28.23,83.480,0.06595,-2.823,0.001
-28.30,83.580,0.06607,-2.830,0.001
-28.38,83.680,0.06616,-2.838,0.001
-28.46,83.780,0.06628,-2.846,0.001
-28.55,83.880,0.06641,-2.855,0.001
-28.63,83.980,0.06649,-2.863,0.001
-28.72,84.080,0.06661,-2.872,0.001
-28.80,84.180,0.06670,-2.880,0.001
-28.88,84.280,0.06682,-2.888,0.001
-28.95,84.380,0.06695,-2.895,0.001
-29.04,84.480,0.06703,-2.904,0.001
-29.12,84.580,0.06711,-2.912,0.001
-29.18,84.680,0.06724,-2.918,0.001
-29.25,84.780,0.06732,-2.925,0.001
-29.33,84.880,0.06745,-2.933,0.001
-29.40,84.980,0.06753,-2.940,0.001
-29.48,85.080,0.06761,-2.948,0.001
-29.51,85.180,0.06769,-2.951,0.001
-29.57,85.280,0.06778,-2.957,0.001
-29.64,85.380,0.06786,-2.964,0.001
-29.71,85.480,0.06794,-2.971,0.001
-29.77,85.580,0.06803,-2.977,0.001
-29.83,85.680,0.06811,-2.983,0.001
-29.88,85.780,0.06819,-2.988,0.001
-29.93,85.880,0.06828,-2.993,0.001
-29.99,85.980,0.06836,-2.999,0.001
-30.04,86.080,0.06844,-3.004,0.001
-30.10,86.180,0.06848,-3.010,0.001
-30.15,86.280,0.06857,-3.015,0.001
-30.21,86.380,0.06865,-3.021,0.001
-30.23,86.480,0.06873,-3.023,0.001
-30.29,86.580,0.06877,-3.029,0.001
-30.35,86.680,0.06886,-3.035,0.001
-30.40,86.780,0.06894,-3.040,0.001
-30.45,86.880,0.06902,-3.045,0.001
-30.51,86.980,0.06907,-3.051,0.001
-30.57,87.080,0.06915,-3.057,0.001
-30.60,87.180,0.06923,-3.060,0.001
-30.65,87.280,0.06927,-3.065,0.001
-30.69,87.380,0.06936,-3.069,0.001
-30.76,87.480,0.06940,-3.076,0.001
-30.80,87.580,0.06948,-3.080,0.001
-30.84,87.680,0.06956,-3.084,0.001
-30.90,87.780,0.06961,-3.090,0.001
-30.95,87.880,0.06969,-3.095,0.001
-31.00,87.980,0.06973,-3.100,0.001
-31.05,88.080,0.06981,-3.105,0.001
-31.11,88.180,0.06990,-3.111,0.001
-31.15,88.280,0.06994,-3.115,0.001
-31.19,88.380,0.07002,-3.119,0.001
-31.25,88.480,0.07006,-3.125,0.001
-31.30,88.580,0.07015,-3.130,0.001
-31.36,88.680,0.07023,-3.136,0.001
-31.39,88.780,0.07027,-3.139,0.001
-31.45,88.880,0.07035,-3.145,0.001
-31.50,88.980,0.07044,-3.150,0.001
-31.56,89.080,0.07048,-3.156,0.001
-31.61,89.180,0.07056,-3.161,0.001
-31.67,89.280,0.07064,-3.167,0.001
-31.72,89.380,0.07073,-3.172,0.001
-31.78,89.480,0.07077,-3.178,0.001
-31.84,89.580,0.07085,-3.184,0.001
-31.89,89.680,0.07094,-3.189,0.001
-31.95,89.780,0.07102,-3.195,0.001
-32.02,89.880,0.07106,-3.202,0.001
-32.07,89.980,0.07114,-3.207,0.001
-32.11,90.080,0.07123,-3.211,0.001
-32.16,90.180,0.07131,-3.216,0.001
-32.20,90.280,0.07135,-3.220,0.001
-32.29,90.380,0.07143,-3.229,0.001
-32.34,90.480,0.07152,-3.234,0.001
-32.39,90.580,0.07160,-3.239,0.001
-32.45,90.680,0.07168,-3.245,0.001
-32.50,90.780,0.07177,-3.250,0.001
-32.57,90.880,0.07185,-3.257,0.001
-32.63,90.980,0.07189,-3.263,0.001
-32.68,91.080,0.07197,-3.268,0.001
-32.74,91.180,0.07206,-3.274,0.001
-32.79,91.280,0.07214,-3.279,0.001
-32.85,91.380,0.07222,-3.285,0.001
-32.92,91.480,0.07231,-3.292,0.001
-32.96,91.580,0.07239,-3.296,0.001
-33.03,91.680,0.07243,-3.303,0.001
-33.07,91.780,0.07251,-3.307,0.001
-33.14,91.880,0.07260,-3.314,0.001
-33.19,91.980,0.07268,-3.319,0.001
-33.26,92.080,0.07276,-3.326,0.001
-33.32,92.180,0.07285,-3.332,0.001
-33.37,92.280,0.07293,-3.337,0.001
-33.41,92.380,0.07301,-3.341,0.001
-33.49,92.480,0.07310,-3.349,0.001
-33.56,92.580,0.07318,-3.356,0.001
-33.61,92.680,0.07326,-3.361,0.001
-33.69,92.780,0.07335,-3.369,0.001
-33.75,92.880,0.07343,-3.375,0.001
-33.83,92.980,0.07351,-3.383,0.001
-33.89,93.080,0.07360,-3.389,0.001
-33.97,93.180,0.07368,-3.397,0.001
-34.04,93.280,0.07376,-3.404,0.001
-34.11,93.380,0.07384,-3.411,0.001
-34.18,93.480,0.07397,-3.418,0.001
-34.27,93.580,0.07405,-3.427,0.001
-34.31,93.680,0.07418,-3.431,0.001
-34.38,93.780,0.07426,-3.438,0.001
-34.45,93.880,0.07434,-3.445,0.001
-34.53,93.980,0.07447,-3.453,0.001
-34.60,94.080,0.07455,-3.460,0.001
-34.67,94.180,0.07463,-3.467,0.001
-34.76,94.280,0.07476,-3.476,0.001
-34.82,94.380,0.07484,-3.482,0.001
-34.91,94.480,0.07497,-3.491,0.001
-34.98,94.580,0.07509,-3.498,0.001
-35.07,94.680,0.07517,-3.507,0.001
-35.16,94.780,0.07530,-3.516,0.001
-35.25,94.880,0.07542,-3.525,0.001
-35.33,94.980,0.07551,-3.533,0.001
-35.42,95.080,0.07563,-3.542,0.001
-35.49,95.180,0.07576,-3.549,0.001
-35.56,95.280,0.07584,-3.556,0.001
-35.62,95.380,0.07596,-3.562,0.001
-35.68,95.480,0.07605,-3.568,0.001
-35.77,95.580,0.07617,-3.577,0.001
-35.83,95.680,0.07625,-3.583,0.002
-35.90,95.780,0.07638,-3.590,0.002
-35.97,95.880,0.07650,-3.597,0.002
-36.05,95.980,0.07659,-3.605,0.002
-36.10,96.080,0.07667,-3.610,0.002
-36.16,96.180,0.07680,-3.616,0.002
-36.25,96.280,0.07688,-3.625,0.002
-36.28,96.380,0.07696,-3.628,0.002
-36.32,96.480,0.07704,-3.632,0.002
-36.38,96.580,0.07717,-3.638,0.002
-36.45,96.680,0.07725,-3.645,0.002
-36.47,96.780,0.07734,-3.647,0.002
-36.54,96.880,0.07742,-3.654,0.002
-36.57,96.980,0.07750,-3.657,0.002
-36.64,97.080,0.07758,-3.664,0.002
-36.68,97.180,0.07767,-3.668,0.002
-36.73,97.280,0.07775,-3.673,0.002
-36.75,97.380,0.07783,-3.675,0.002
-36.80,97.480,0.07788,-3.680,0.002
-36.82,97.580,0.07796,-3.682,0.002
-36.86,97.680,0.07804,-3.686,0.002
-36.90,97.780,0.07812,-3.690,0.002
-36.97,97.880,0.07821,-3.697,0.002
-37.01,97.980,0.07825,-3.701,0.002
-37.05,98.080,0.07833,-3.705,0.002
-37.08,98.180,0.07842,-3.708,0.002
-37.13,98.280,0.07850,-3.713,0.002
-37.16,98.380,0.07854,-3.716,0.002
-37.21,98.480,0.07862,-3.721,0.002
-37.22,98.580,0.07871,-3.722,0.002
-37.27,98.680,0.07875,-3.727,0.002
-37.32,98.780,0.07883,-3.732,0.002
-37.35,98.880,0.07891,-3.735,0.002
-37.38,98.980,0.07896,-3.738,0.002
-37.40,99.080,0.07904,-3.740,0.002
-37.43,99.180,0.07912,-3.743,0.002
-37.46,99.280,0.07916,-3.746,0.002
-37.48,99.380,0.07925,-3.748,0.002
-37.52,99.480,0.07929,-3.752,0.002
-37.57,99.580,0.07937,-3.757,0.002
-37.59,99.680,0.07941,-3.759,0.002
-37.64,99.780,0.07950,-3.764,0.002
-37.67,99.880,0.07958,-3.767,0.002
-37.71,99.980,0.07962,-3.771,0.002
-37.75,100.080,0.07970,-3.775,0.002
-37.80,100.180,0.07979,-3.780,0.002
-37.83,100.280,0.07983,-3.783,0.002
-37.87,100.380,0.07991,-3.787,0.002
-37.91,100.480,0.08000,-3.791,0.002
-37.96,100.580,0.08004,-3.796,0.002
-37.97,100.680,0.08012,-3.797,0.002
-38.05,100.780,0.08020,-3.805,0.002
-38.08,100.880,0.08029,-3.808,0.002
-38.12,100.980,0.08033,-3.812,0.002
-38.16,101.080,0.08041,-3.816,0.002
-38.23,101.180,0.08049,-3.823,0.002
-38.25,101.280,0.08058,-3.825,0.002
-38.31,101.380,0.08062,-3.831,0.002
-38.35,101.480,0.08070,-3.835,0.002
-38.41,101.580,0.08078,-3.841,0.002
-38.45,101.680,0.08087,-3.845,0.002
-38.52,101.780,0.08095,-3.852,0.002
-38.55,101.880,0.08099,-3.855,0.002
-38.62,101.980,0.08108,-3.862,0.002
-38.65,102.080,0.08116,-3.865,0.002
-38.71,102.180,0.08124,-3.871,0.002
-38.76,102.280,0.08132,-3.876,0.002
-38.82,102.380,0.08137,-3.882,0.002
-38.86,102.480,0.08145,-3.886,0.002
-38.93,102.580,0.08153,-3.893,0.002
-38.96,102.680,0.08162,-3.896,0.002
-39.04,102.780,0.08170,-3.904,0.002
-39.10,102.880,0.08178,-3.910,0.002
-39.16,102.980,0.08187,-3.916,0.002
-39.19,103.080,0.08195,-3.919,0.002
-39.26,103.180,0.08203,-3.926,0.002
-39.30,103.280,0.08207,-3.930,0.002
-39.36,103.380,0.08216,-3.936,0.002
-39.42,103.480,0.08224,-3.942,0.002
-39.48,103.580,0.08232,-3.948,0.002
-39.54,103.680,0.08241,-3.954,0.002
-39.62,103.780,0.08249,-3.962,0.002
-39.68,103.880,0.08257,-3.968,0.002
-39.76,103.980,0.08265,-3.976,0.002
-39.84,104.080,0.08274,-3.984,0.002
-39.91,104.180,0.08282,-3.991,0.002
-39.96,104.280,0.08290,-3.996,0.002
-40.04,104.380,0.08299,-4.004,0.002
-40.11,104.480,0.08307,-4.011,0.002
-40.19,104.580,0.08315,-4.019,0.002
-40.26,104.680,0.08324,-4.026,0.002
-40.34,104.780,0.08336,-4.034,0.002
-40.44,104.880,0.08344,-4.044,0.002
-40.52,104.980,0.08353,-4.052,0.002
-40.59,105.080,0.08361,-4.059,0.002
-40.69,105.180,0.08374,-4.069,0.002
-40.76,105.280,0.08382,-4.076,0.002
-40.83,105.380,0.08390,-4.083,0.002
-40.90,105.480,0.08398,-4.090,0.002
-40.99,105.580,0.08411,-4.099,0.002
-41.08,105.680,0.08419,-4.108,0.002
-41.19,105.780,0.08432,-4.119,0.002
-41.28,105.880,0.08440,-4.128,0.002
-41.39,105.980,0.08452,-4.139,0.002
-41.50,106.080,0.08465,-4.150,0.002
-41.58,106.180,0.08473,-4.158,0.002
-41.69,106.280,0.08486,-4.169,0.002
-41.79,106.380,0.08494,-4.179,0.002
-41.88,106.480,0.08506,-4.188,0.002
-41.98,106.580,0.08515,-4.198,0.002
-42.07,106.680,0.08523,-4.207,0.002
-42.16,106.780,0.08536,-4.216,0.002
-42.24,106.880,0.08544,-4.224,0.002
-42.34,106.980,0.08556,-4.234,0.002
-42.42,107.080,0.08565,-4.242,0.002
-42.50,107.180,0.08577,-4.250,0.002
-42.58,107.280,0.08585,-4.258,0.002
-42.67,107.380,0.08594,-4.267,0.002
-42.75,107.480,0.08606,-4.275,0.002
-42.82,107.580,0.08615,-4.282,0.002
-42.90,107.680,0.08623,-4.290,0.002
-42.98,107.780,0.08631,-4.298,0.002
-43.04,107.880,0.08644,-4.304,0.002
-43.14,107.980,0.08652,-4.314,0.002
-43.20,108.080,0.08660,-4.320,0.002
-43.29,108.180,0.08669,-4.329,0.002
-43.36,108.280,0.08677,-4.336,0.002
-43.45,108.380,0.08685,-4.345,0.002
-43.51,108.480,0.08693,-4.351,0.002
-43.59,108.580,0.08702,-4.359,0.002
-43.66,108.680,0.08710,-4.366,0.002
-43.73,108.780,0.08718,-4.373,0.002
-43.78,108.880,0.08723,-4.378,0.002
-43.86,108.980,0.08731,-4.386,0.002
-43.92,109.080,0.08739,-4.392,0.002
-44.00,109.180,0.08748,-4.400,0.002
-44.07,109.280,0.08756,-4.407,0.002
-44.14,109.380,0.08760,-4.414,0.002
-44.21,109.480,0.08768,-4.421,0.002
-44.29,109.580,0.08777,-4.429,0.002
-44.31,109.680,0.08785,-4.431,0.002
-44.41,109.780,0.08789,-4.441,0.002
-44.46,109.880,0.08797,-4.446,0.002
-44.53,109.980,0.08806,-4.453,0.002
-44.59,110.080,0.08810,-4.459,0.002
-44.66,110.180,0.08818,-4.466,0.002
-44.73,110.280,0.08826,-4.473,0.002
-12.53,110.380,0.08831,-1.253,0.002
-14.21,110.480,0.08839,-1.421,0.002
-14.34,110.580,0.08847,-1.434,0.002
-14.43,110.680,0.08851,-1.443,0.002
-14.53,110.780,0.08860,-1.453,0.002
-14.61,110.880,0.08868,-1.461,0.002
-14.68,110.980,0.08872,-1.468,0.002
-14.79,111.080,0.08880,-1.479,0.002
-14.86,111.180,0.08885,-1.486,0.002
-14.95,111.280,0.08893,-1.495,0.002
-15.03,111.380,0.08897,-1.503,0.002
-15.14,111.480,0.08905,-1.514,0.002
-15.21,111.580,0.08914,-1.521,0.002
-15.30,111.680,0.08918,-1.530,0.002
-15.38,111.780,0.08926,-1.538,0.002
-15.48,111.880,0.08930,-1.548,0.002
-15.56,111.980,0.08939,-1.556,0.002
-15.66,112.080,0.08947,-1.566,0.002
-15.74,112.180,0.08955,-1.574,0.002
-15.85,112.280,0.08959,-1.585,0.002
-15.91,112.380,0.08968,-1.591,0.002
-16.01,112.480,0.08976,-1.601,0.002
-16.10,112.580,0.08984,-1.610,0.002
-16.20,112.680,0.08989,-1.620,0.002
-16.28,112.780,0.08997,-1.628,0.002
-16.36,112.880,0.09005,-1.636,0.002
-16.45,112.980,0.09009,-1.645,0.002
-16.55,113.080,0.09018,-1.655,0.002
-16.64,113.180,0.09026,-1.664,0.002
-16.73,113.280,0.09034,-1.673,0.002
-16.81,113.380,0.09043,-1.681,0.002
-16.91,113.480,0.09051,-1.691,0.002
-16.97,113.580,0.09055,-1.697,0.002
-17.07,113.680,0.09063,-1.707,0.002
-17.17,113.780,0.09072,-1.717,0.002
-17.23,113.880,0.09080,-1.723,0.002
-17.32,113.980,0.09088,-1.732,0.002
-17.41,114.080,0.09092,-1.741,0.002
-17.49,114.180,0.09101,-1.749,0.002
-17.57,114.280,0.09109,-1.757,0.002
-17.67,114.380,0.09117,-1.767,0.002
-17.76,114.480,0.09126,-1.776,0.002
-17.85,114.580,0.09130,-1.785,0.002
-17.94,114.680,0.09138,-1.794,0.002
-18.04,114.780,0.09146,-1.804,0.002
-18.11,114.880,0.09155,-1.811,0.002
-18.19,114.980,0.09163,-1.819,0.002
-18.28,115.080,0.09171,-1.828,0.002
-18.37,115.180,0.09180,-1.837,0.002
-18.47,115.280,0.09188,-1.847,0.002
-18.55,115.380,0.09196,-1.855,0.002
-18.64,115.480,0.09205,-1.864,0.002
-18.73,115.580,0.09213,-1.873,0.002
-18.82,115.680,0.09221,-1.882,0.002
-18.91,115.780,0.09230,-1.891,0.002
-18.98,115.880,0.09234,-1.898,0.002
-18.99,115.890,0.09238,-1.899,0.002