File: data-files/CWRU/0900-05-35B.txt
""
"Test Method","Will_Huddleston_Disks.msm"
"Sample I. D.","900-5-35B.mss"
"Specimen Number","1"

"Load (N)","Time (s)","Extension (mm)","Stress (MPa)","Strain (mm/mm)"

1.82,0.200,-0.09903,0.341,-0.002
1.81,0.300,-0.09903,0.340,-0.002
1.81,0.400,-0.09899,0.339,-0.002
1.82,0.500,-0.09899,0.341,-0.002
1.81,0.600,-0.09899,0.340,-0.002
1.81,0.700,-0.09895,0.339,-0.002
1.81,0.800,-0.09895,0.338,-0.002
1.82,0.900,-0.09891,0.341,-0.002
1.83,1.000,-0.09891,0.342,-0.002
1.82,1.100,-0.09887,0.341,-0.002
1.82,1.200,-0.09887,0.341,-0.002
1.82,1.300,-0.09883,0.342,-0.002
1.81,1.400,-0.09883,0.340,-0.002
1.81,1.500,-0.09878,0.340,-0.002
1.83,1.600,-0.09874,0.343,-0.002
1.84,1.700,-0.09866,0.345,-0.002
1.88,1.800,-0.09858,0.352,-0.002
1.90,1.900,-0.09845,0.356,-0.002
1.95,2.000,-0.09829,0.366,-0.002
2.01,2.100,-0.09812,0.376,-0.002
2.07,2.200,-0.09795,0.387,-0.002
2.11,2.300,-0.09779,0.395,-0.002
2.13,2.400,-0.09762,0.399,-0.002
2.15,2.500,-0.09750,0.403,-0.002
2.16,2.600,-0.09733,0.404,-0.002
2.17,2.700,-0.09721,0.406,-0.002
2.17,2.800,-0.09708,0.407,-0.002
2.19,2.900,-0.09696,0.411,-0.002
2.20,3.000,-0.09683,0.413,-0.002
2.21,3.100,-0.09671,0.415,-0.002
2.24,3.200,-0.09658,0.420,-0.002
2.25,3.300,-0.09642,0.422,-0.002
2.25,3.400,-0.09629,0.422,-0.002
2.25,3.500,-0.09617,0.421,-0.002
2.27,3.600,-0.09604,0.425,-0.002
2.27,3.700,-0.09592,0.425,-0.002
2.29,3.800,-0.09579,0.429,-0.002
2.30,3.900,-0.09567,0.430,-0.002
2.29,4.000,-0.09554,0.429,-0.002
2.30,4.100,-0.09542,0.432,-0.002
2.32,4.200,-0.09525,0.435,-0.002
2.33,4.300,-0.09513,0.436,-0.002
2.34,4.400,-0.09496,0.438,-0.002
2.36,4.500,-0.09484,0.442,-0.002
2.38,4.600,-0.09467,0.446,-0.002
2.38,4.700,-0.09455,0.446,-0.002
2.40,4.800,-0.09438,0.449,-0.002
2.40,4.900,-0.09425,0.449,-0.002
2.41,5.000,-0.09409,0.452,-0.002
2.44,5.100,-0.09396,0.457,-0.002
2.44,5.200,-0.09380,0.457,-0.002
2.46,5.300,-0.09367,0.461,-0.002
2.48,5.400,-0.09351,0.465,-0.002
2.48,5.500,-0.09334,0.465,-0.002
2.51,5.600,-0.09322,0.470,-0.002
2.53,5.700,-0.09305,0.474,-0.002
2.55,5.800,-0.09288,0.477,-0.002
2.55,5.900,-0.09272,0.478,-0.002
2.58,6.000,-0.09255,0.483,-0.002
2.60,6.100,-0.09238,0.486,-0.002
2.61,6.200,-0.09222,0.489,-0.002
2.62,6.300,-0.09205,0.491,-0.002
2.65,6.400,-0.09184,0.497,-0.002
2.68,6.500,-0.09168,0.501,-0.002
2.69,6.600,-0.09147,0.504,-0.002
2.71,6.700,-0.09126,0.507,-0.002
2.74,6.800,-0.09106,0.513,-0.002
2.77,6.900,-0.09085,0.518,-0.002
2.78,7.000,-0.09064,0.520,-0.002
2.81,7.100,-0.09043,0.527,-0.002
2.82,7.200,-0.09022,0.528,-0.002
2.84,7.300,-0.09002,0.531,-0.002
2.85,7.400,-0.08981,0.534,-0.002
2.87,7.500,-0.08960,0.537,-0.002
2.88,7.600,-0.08939,0.540,-0.002
2.90,7.700,-0.08923,0.544,-0.002
2.91,7.800,-0.08902,0.545,-0.002
2.93,7.900,-0.08885,0.550,-0.002
2.95,8.000,-0.08864,0.553,-0.002
2.96,8.100,-0.08848,0.555,-0.002
2.96,8.200,-0.08831,0.555,-0.002
2.98,8.300,-0.08815,0.559,-0.002
3.00,8.400,-0.08802,0.563,-0.002
3.01,8.500,-0.08786,0.564,-0.002
3.02,8.600,-0.08769,0.566,-0.002
3.04,8.700,-0.08756,0.569,-0.002
3.05,8.800,-0.08740,0.572,-0.002
3.04,8.900,-0.08727,0.569,-0.002
3.06,9.000,-0.08715,0.573,-0.002
3.06,9.100,-0.08698,0.574,-0.002
3.07,9.200,-0.08686,0.575,-0.002
3.10,9.300,-0.08673,0.581,-0.002
3.10,9.400,-0.08661,0.581,-0.002
3.11,9.500,-0.08644,0.583,-0.002
3.13,9.600,-0.08632,0.586,-0.002
3.15,9.700,-0.08615,0.590,-0.002
3.15,9.800,-0.08603,0.589,-0.002
3.16,9.900,-0.08590,0.591,-0.002
3.18,10.000,-0.08574,0.595,-0.002
3.18,10.100,-0.08557,0.596,-0.002
3.19,10.200,-0.08544,0.597,-0.002
3.20,10.300,-0.08528,0.600,-0.002
3.22,10.400,-0.08511,0.603,-0.002
3.25,10.500,-0.08499,0.608,-0.002
3.25,10.600,-0.08482,0.609,-0.002
3.25,10.700,-0.08466,0.608,-0.002
3.26,10.800,-0.08449,0.610,-0.002
3.26,10.900,-0.08436,0.612,-0.002
3.29,11.000,-0.08420,0.616,-0.002
3.30,11.100,-0.08403,0.618,-0.002
3.31,11.200,-0.08387,0.619,-0.002
3.31,11.300,-0.08370,0.621,-0.002
3.33,11.400,-0.08357,0.623,-0.002
3.33,11.500,-0.08341,0.624,-0.002
3.36,11.600,-0.08324,0.629,-0.002
3.36,11.700,-0.08308,0.630,-0.002
3.37,11.800,-0.08291,0.632,-0.002
3.37,11.900,-0.08270,0.632,-0.002
3.38,12.000,-0.08254,0.632,-0.002
3.42,12.100,-0.08233,0.640,-0.002
3.41,12.200,-0.08216,0.639,-0.002
3.44,12.300,-0.08195,0.644,-0.002
3.45,12.400,-0.08175,0.646,-0.002
3.47,12.500,-0.08154,0.649,-0.002
3.50,12.600,-0.08133,0.655,-0.002
3.50,12.700,-0.08112,0.655,-0.002
3.51,12.800,-0.08092,0.657,-0.002
3.53,12.900,-0.08067,0.662,-0.002
3.56,13.000,-0.08046,0.668,-0.002
3.57,13.100,-0.08025,0.669,-0.002
3.59,13.200,-0.08008,0.673,-0.002
3.62,13.300,-0.07988,0.678,-0.002
3.62,13.400,-0.07967,0.678,-0.002
3.64,13.500,-0.07950,0.682,-0.002
3.67,13.600,-0.07934,0.687,-0.002
3.65,13.700,-0.07913,0.684,-0.002
3.65,13.800,-0.07896,0.684,-0.002
3.67,13.900,-0.07880,0.688,-0.002
3.70,14.000,-0.07867,0.693,-0.002
3.69,14.100,-0.07851,0.691,-0.002
3.71,14.200,-0.07834,0.695,-0.002
3.71,14.300,-0.07821,0.696,-0.002
3.73,14.400,-0.07805,0.698,-0.002
3.73,14.500,-0.07792,0.698,-0.002
3.74,14.600,-0.07776,0.701,-0.002
3.75,14.700,-0.07763,0.702,-0.002
3.76,14.800,-0.07751,0.704,-0.002
3.76,14.900,-0.07738,0.705,-0.002
3.78,15.000,-0.07722,0.709,-0.002
3.78,15.100,-0.07709,0.709,-0.002
3.81,15.200,-0.07697,0.714,-0.002
3.81,15.300,-0.07680,0.713,-0.002
3.81,15.400,-0.07668,0.714,-0.002
3.82,15.500,-0.07655,0.715,-0.002
3.84,15.600,-0.07639,0.719,-0.002
3.84,15.700,-0.07626,0.719,-0.002
3.86,15.800,-0.07609,0.723,-0.001
3.85,15.900,-0.07597,0.721,-0.001
3.87,16.000,-0.07580,0.724,-0.001
3.88,16.100,-0.07568,0.727,-0.001
3.88,16.200,-0.07551,0.728,-0.001
3.88,16.300,-0.07539,0.726,-0.001
3.90,16.400,-0.07522,0.731,-0.001
3.92,16.500,-0.07506,0.735,-0.001
3.93,16.600,-0.07489,0.737,-0.001
3.93,16.700,-0.07477,0.737,-0.001
3.96,16.800,-0.07460,0.742,-0.001
3.97,16.900,-0.07443,0.743,-0.001
3.97,17.000,-0.07431,0.744,-0.001
4.00,17.100,-0.07414,0.750,-0.001
4.01,17.200,-0.07398,0.751,-0.001
4.02,17.300,-0.07381,0.753,-0.001
4.03,17.400,-0.07364,0.755,-0.001
4.04,17.500,-0.07348,0.757,-0.001
4.05,17.600,-0.07331,0.758,-0.001
4.05,17.700,-0.07310,0.758,-0.001
4.08,17.800,-0.07290,0.764,-0.001
4.09,17.900,-0.07269,0.766,-0.001
4.10,18.000,-0.07248,0.768,-0.001
4.13,18.100,-0.07227,0.773,-0.001
4.13,18.200,-0.07206,0.775,-0.001
4.17,18.300,-0.07186,0.782,-0.001
4.19,18.400,-0.07165,0.785,-0.001
4.20,18.500,-0.07140,0.786,-0.001
4.21,18.600,-0.07119,0.788,-0.001
4.23,18.700,-0.07098,0.793,-0.001
4.23,18.800,-0.07078,0.793,-0.001
4.27,18.900,-0.07057,0.799,-0.001
4.30,19.000,-0.07036,0.805,-0.001
4.30,19.100,-0.07019,0.805,-0.001
4.30,19.200,-0.07003,0.806,-0.001
4.32,19.300,-0.06982,0.810,-0.001
4.32,19.400,-0.06965,0.810,-0.001
4.33,19.500,-0.06949,0.812,-0.001
4.35,19.600,-0.06936,0.814,-0.001
4.35,19.700,-0.06920,0.815,-0.001
4.36,19.800,-0.06903,0.816,-0.001
4.38,19.900,-0.06891,0.821,-0.001
4.39,20.000,-0.06874,0.823,-0.001
4.40,20.100,-0.06861,0.825,-0.001
4.40,20.200,-0.06845,0.825,-0.001
4.42,20.300,-0.06832,0.827,-0.001
4.41,20.400,-0.06820,0.827,-0.001
4.43,20.500,-0.06803,0.830,-0.001
4.45,20.600,-0.06791,0.834,-0.001
4.44,20.700,-0.06778,0.832,-0.001
4.46,20.800,-0.06766,0.835,-0.001
4.47,20.900,-0.06749,0.838,-0.001
4.49,21.000,-0.06737,0.841,-0.001
4.49,21.100,-0.06720,0.841,-0.001
4.50,21.200,-0.06708,0.842,-0.001
4.51,21.300,-0.06691,0.845,-0.001
4.51,21.400,-0.06679,0.845,-0.001
4.54,21.500,-0.06662,0.850,-0.001
4.55,21.600,-0.06650,0.853,-0.001
4.56,21.700,-0.06633,0.854,-0.001
4.57,21.800,-0.06616,0.856,-0.001
4.59,21.900,-0.06600,0.860,-0.001
4.58,22.000,-0.06587,0.858,-0.001
4.61,22.100,-0.06571,0.864,-0.001
4.61,22.200,-0.06554,0.864,-0.001
4.64,22.300,-0.06537,0.868,-0.001
4.64,22.400,-0.06525,0.870,-0.001
4.66,22.500,-0.06508,0.872,-0.001
4.66,22.600,-0.06492,0.874,-0.001
4.67,22.700,-0.06475,0.875,-0.001
4.68,22.800,-0.06458,0.876,-0.001
4.70,22.900,-0.06442,0.881,-0.001
4.73,23.000,-0.06425,0.886,-0.001
4.73,23.100,-0.06409,0.887,-0.001
4.75,23.200,-0.06388,0.891,-0.001
4.78,23.300,-0.06371,0.895,-0.001
4.77,23.400,-0.06350,0.893,-0.001
4.79,23.500,-0.06330,0.898,-0.001
4.81,23.600,-0.06309,0.900,-0.001
4.82,23.700,-0.06288,0.902,-0.001
4.84,23.800,-0.06263,0.907,-0.001
4.87,23.900,-0.06242,0.911,-0.001
4.87,24.000,-0.06222,0.913,-0.001
4.88,24.100,-0.06201,0.914,-0.001
4.89,24.200,-0.06176,0.915,-0.001
4.89,24.300,-0.06155,0.917,-0.001
4.91,24.400,-0.06134,0.920,-0.001
4.94,24.500,-0.06113,0.925,-0.001
4.94,24.600,-0.06097,0.925,-0.001
4.94,24.700,-0.06076,0.925,-0.001
4.96,24.800,-0.06055,0.929,-0.001
4.96,24.900,-0.06039,0.929,-0.001
4.97,25.000,-0.06022,0.931,-0.001
4.97,25.100,-0.06005,0.932,-0.001
4.98,25.200,-0.05989,0.934,-0.001
5.00,25.300,-0.05972,0.936,-0.001
5.01,25.400,-0.05956,0.938,-0.001
5.01,25.500,-0.05943,0.939,-0.001
5.01,25.600,-0.05926,0.939,-0.001
5.04,25.700,-0.05910,0.943,-0.001
5.01,25.800,-0.05897,0.939,-0.001
5.03,25.900,-0.05881,0.942,-0.001
5.03,26.000,-0.05868,0.943,-0.001
5.05,26.100,-0.05856,0.946,-0.001
5.04,26.200,-0.05839,0.945,-0.001
5.05,26.300,-0.05827,0.947,-0.001
5.06,26.400,-0.05814,0.948,-0.001
5.08,26.500,-0.05798,0.952,-0.001
5.08,26.600,-0.05785,0.953,-0.001
5.11,26.700,-0.05769,0.957,-0.001
5.09,26.800,-0.05756,0.954,-0.001
5.12,26.900,-0.05739,0.959,-0.001
5.13,27.000,-0.05727,0.961,-0.001
5.14,27.100,-0.05710,0.963,-0.001
5.15,27.200,-0.05698,0.965,-0.001
5.17,27.300,-0.05681,0.968,-0.001
5.17,27.400,-0.05665,0.968,-0.001
5.17,27.500,-0.05648,0.968,-0.001
5.19,27.600,-0.05636,0.972,-0.001
5.22,27.700,-0.05619,0.977,-0.001
5.22,27.800,-0.05602,0.978,-0.001
5.23,27.900,-0.05586,0.980,-0.001
5.23,28.000,-0.05573,0.980,-0.001
5.26,28.100,-0.05557,0.985,-0.001
5.26,28.200,-0.05540,0.986,-0.001
5.27,28.300,-0.05523,0.988,-0.001
5.27,28.400,-0.05507,0.987,-0.001
5.27,28.500,-0.05490,0.988,-0.001
5.29,28.600,-0.05474,0.990,-0.001
5.29,28.700,-0.05457,0.991,-0.001
5.28,28.800,-0.05440,0.989,-0.001
5.30,28.900,-0.05419,0.993,-0.001
5.32,29.000,-0.05403,0.997,-0.001
5.33,29.100,-0.05382,0.999,-0.001
5.35,29.200,-0.05361,1.002,-0.001
5.36,29.300,-0.05341,1.005,-0.001
5.36,29.400,-0.05320,1.003,-0.001
5.36,29.500,-0.05299,1.004,-0.001
5.37,29.600,-0.05278,1.006,-0.001
5.38,29.700,-0.05257,1.008,-0.001
5.39,29.800,-0.05237,1.009,-0.001
5.41,29.900,-0.05216,1.014,-0.001
5.42,30.000,-0.05195,1.015,-0.001
5.41,30.100,-0.05174,1.014,-0.001
5.44,30.200,-0.05158,1.019,-0.001
5.45,30.300,-0.05137,1.020,-0.001
5.44,30.400,-0.05116,1.020,-0.001
5.45,30.500,-0.05100,1.022,-0.001
5.46,30.600,-0.05083,1.022,-0.001
5.45,30.700,-0.05066,1.021,-0.001
5.47,30.800,-0.05050,1.025,-0.001
5.48,30.900,-0.05033,1.026,-0.001
5.47,31.000,-0.05016,1.024,-0.001
5.48,31.100,-0.05000,1.027,-0.001
5.50,31.200,-0.04983,1.031,-0.001
5.47,31.300,-0.04971,1.025,-0.001
5.49,31.400,-0.04954,1.029,-0.001
5.50,31.500,-0.04942,1.030,-0.001
5.50,31.600,-0.04925,1.030,-0.001
5.50,31.700,-0.04913,1.030,-0.001
5.51,31.800,-0.04900,1.032,-0.001
5.52,31.900,-0.04883,1.035,-0.001
5.50,32.000,-0.04871,1.031,-0.001
5.54,32.100,-0.04858,1.037,-0.001
5.53,32.200,-0.04846,1.036,-0.001
5.54,32.300,-0.04829,1.038,-0.001
5.55,32.400,-0.04817,1.040,-0.001
5.55,32.500,-0.04800,1.039,-0.001
5.55,32.600,-0.04788,1.040,-0.001
5.57,32.700,-0.04771,1.044,-0.001
5.56,32.800,-0.04759,1.042,-0.001
5.56,32.900,-0.04742,1.042,-0.001
5.59,33.000,-0.04726,1.046,-0.001
5.59,33.100,-0.04713,1.047,-0.001
5.61,33.200,-0.04696,1.050,-0.001
5.62,33.300,-0.04684,1.053,-0.001
5.63,33.400,-0.04667,1.054,-0.001
5.63,33.500,-0.04655,1.055,-0.001
5.63,33.600,-0.04638,1.055,-0.001
5.64,33.700,-0.04622,1.056,-0.001
5.64,33.800,-0.04605,1.056,-0.001
5.66,33.900,-0.04593,1.060,-0.001
5.68,34.000,-0.04576,1.064,-0.001
5.68,34.100,-0.04559,1.065,-0.001
5.69,34.200,-0.04543,1.066,-0.001
5.69,34.300,-0.04526,1.067,-0.001
5.72,34.400,-0.04509,1.072,-0.001
5.73,34.500,-0.04493,1.073,-0.001
5.73,34.600,-0.04472,1.073,-0.001
5.76,34.700,-0.04455,1.079,-0.001
5.78,34.800,-0.04435,1.082,-0.001
5.77,34.900,-0.04414,1.081,-0.001
5.79,35.000,-0.04393,1.084,-0.001
5.80,35.100,-0.04372,1.087,-0.001
5.81,35.200,-0.04352,1.088,-0.001
5.81,35.300,-0.04331,1.088,-0.001
5.84,35.400,-0.04310,1.093,-0.001
5.85,35.500,-0.04289,1.095,-0.001
5.85,35.600,-0.04268,1.096,-0.001
5.88,35.700,-0.04248,1.102,-0.001
5.89,35.800,-0.04227,1.104,-0.001
5.91,35.900,-0.04206,1.107,-0.001
5.92,36.000,-0.04185,1.109,-0.001
5.94,36.100,-0.04169,1.113,-0.001
5.94,36.200,-0.04148,1.113,-0.001
5.94,36.300,-0.04131,1.112,-0.001
5.95,36.400,-0.04115,1.115,-0.001
5.96,36.500,-0.04098,1.117,-0.001
5.99,36.600,-0.04081,1.122,-0.001
5.99,36.700,-0.04069,1.123,-0.001
6.01,36.800,-0.04052,1.126,-0.001
6.01,36.900,-0.04040,1.126,-0.001
6.04,37.000,-0.04023,1.132,-0.001
6.05,37.100,-0.04011,1.134,-0.001
6.06,37.200,-0.03998,1.135,-0.001
6.07,37.300,-0.03982,1.137,-0.001
6.08,37.400,-0.03969,1.139,-0.001
6.11,37.500,-0.03957,1.144,-0.001
6.12,37.600,-0.03944,1.147,-0.001
6.15,37.700,-0.03932,1.151,-0.001
6.17,37.800,-0.03915,1.155,-0.001
6.18,37.900,-0.03903,1.158,-0.001
6.21,38.000,-0.03890,1.163,-0.001
6.21,38.100,-0.03874,1.164,-0.001
6.24,38.200,-0.03861,1.169,-0.001
6.26,38.300,-0.03845,1.172,-0.001
6.28,38.400,-0.03832,1.176,-0.001
6.29,38.500,-0.03815,1.179,-0.001
6.31,38.600,-0.03803,1.183,-0.001
6.34,38.700,-0.03786,1.188,-0.001
6.34,38.800,-0.03770,1.189,-0.001
6.37,38.900,-0.03757,1.193,-0.001
6.40,39.000,-0.03741,1.199,-0.001
6.41,39.100,-0.03724,1.200,-0.001
6.44,39.200,-0.03712,1.206,-0.001
6.45,39.300,-0.03695,1.207,-0.001
6.47,39.400,-0.03678,1.211,-0.001
6.48,39.500,-0.03662,1.214,-0.001
6.51,39.600,-0.03649,1.219,-0.001
6.52,39.700,-0.03633,1.221,-0.001
6.55,39.800,-0.03616,1.227,-0.001
6.58,39.900,-0.03599,1.232,-0.001
6.59,40.000,-0.03583,1.234,-0.001
6.62,40.100,-0.03566,1.240,-0.001
6.66,40.200,-0.03549,1.248,-0.001
6.68,40.300,-0.03529,1.252,-0.001
6.70,40.400,-0.03512,1.255,-0.001
6.73,40.500,-0.03491,1.261,-0.001
6.75,40.600,-0.03471,1.265,-0.001
6.79,40.700,-0.03450,1.271,-0.001
6.82,40.800,-0.03429,1.278,-0.001
6.85,40.900,-0.03408,1.284,-0.001
6.87,41.000,-0.03387,1.287,-0.001
6.90,41.100,-0.03367,1.292,-0.001
6.92,41.200,-0.03346,1.297,-0.001
6.96,41.300,-0.03325,1.303,-0.001
7.00,41.400,-0.03304,1.310,-0.001
7.02,41.500,-0.03284,1.314,-0.001
7.06,41.600,-0.03263,1.322,-0.001
7.08,41.700,-0.03246,1.326,-0.001
7.11,41.800,-0.03225,1.331,-0.001
7.12,41.900,-0.03209,1.335,-0.001
7.15,42.000,-0.03188,1.339,-0.001
7.15,42.100,-0.03171,1.340,-0.001
7.17,42.200,-0.03159,1.343,-0.001
7.18,42.300,-0.03142,1.345,-0.001
7.20,42.400,-0.03126,1.348,-0.001
7.24,42.500,-0.03113,1.356,-0.001
7.26,42.600,-0.03097,1.360,-0.001
7.27,42.700,-0.03080,1.363,-0.001
7.30,42.800,-0.03067,1.367,-0.001
7.32,42.900,-0.03055,1.371,-0.001
7.34,43.000,-0.03038,1.375,-0.001
7.35,43.100,-0.03026,1.377,-0.001
7.36,43.200,-0.03013,1.379,-0.001
7.39,43.300,-0.02997,1.385,-0.001
7.40,43.400,-0.02984,1.387,-0.001
7.43,43.500,-0.02972,1.393,-0.001
7.44,43.600,-0.02955,1.394,-0.001
7.47,43.700,-0.02943,1.399,-0.001
7.50,43.800,-0.02926,1.404,-0.001
7.52,43.900,-0.02914,1.409,-0.001
7.54,44.000,-0.02901,1.413,-0.001
7.56,44.100,-0.02885,1.415,-0.001
7.58,44.200,-0.02868,1.420,-0.001
7.60,44.300,-0.02856,1.423,-0.001
7.62,44.400,-0.02839,1.428,-0.001
7.66,44.500,-0.02826,1.434,-0.001
7.66,44.600,-0.02810,1.435,-0.001
7.70,44.700,-0.02793,1.442,-0.001
7.73,44.800,-0.02781,1.447,-0.001
7.76,44.900,-0.02764,1.454,-0.001
7.76,45.000,-0.02747,1.454,-0.001
7.80,45.100,-0.02731,1.461,-0.001
7.82,45.200,-0.02718,1.465,-0.001
7.84,45.300,-0.02702,1.469,-0.001
7.87,45.400,-0.02685,1.475,-0.001
7.88,45.500,-0.02668,1.477,-0.001
7.92,45.600,-0.02652,1.483,-0.001
7.94,45.700,-0.02635,1.487,-0.001
7.97,45.800,-0.02619,1.493,-0.001
8.01,45.900,-0.02602,1.500,-0.001
8.03,46.000,-0.02581,1.504,-0.001
8.08,46.100,-0.02565,1.514,-0.001
8.10,46.200,-0.02544,1.518,-0.001
8.14,46.300,-0.02523,1.526,0.000
8.17,46.400,-0.02506,1.531,0.000
8.20,46.500,-0.02486,1.536,0.000
8.25,46.600,-0.02461,1.546,0.000
8.29,46.700,-0.02440,1.552,0.000
8.32,46.800,-0.02419,1.559,0.000
8.35,46.900,-0.02398,1.563,0.000
8.40,47.000,-0.02378,1.573,0.000
8.45,47.100,-0.02357,1.582,0.000
8.46,47.200,-0.02336,1.586,0.000
8.50,47.300,-0.02319,1.593,0.000
8.54,47.400,-0.02299,1.600,0.000
8.56,47.500,-0.02278,1.603,0.000
8.59,47.600,-0.02261,1.610,0.000
8.61,47.700,-0.02245,1.612,0.000
8.63,47.800,-0.02228,1.617,0.000
8.66,47.900,-0.02211,1.623,0.000
8.69,48.000,-0.02195,1.628,0.000
8.71,48.100,-0.02178,1.631,0.000
8.74,48.200,-0.02166,1.637,0.000
8.77,48.300,-0.02149,1.643,0.000
8.78,48.400,-0.02137,1.644,0.000
8.81,48.500,-0.02120,1.649,0.000
8.83,48.600,-0.02107,1.654,0.000
8.86,48.700,-0.02091,1.660,0.000
8.88,48.800,-0.02078,1.664,0.000
8.91,48.900,-0.02066,1.670,0.000
8.92,49.000,-0.02049,1.672,0.000
8.96,49.100,-0.02037,1.678,0.000
8.99,49.200,-0.02024,1.684,0.000
9.00,49.300,-0.02012,1.686,0.000
9.03,49.400,-0.01995,1.691,0.000
9.04,49.500,-0.01983,1.694,0.000
9.08,49.600,-0.01966,1.702,0.000
9.11,49.700,-0.01954,1.707,0.000
9.13,49.800,-0.01941,1.711,0.000
9.16,49.900,-0.01925,1.716,0.000
9.19,50.000,-0.01912,1.722,0.000
9.23,50.100,-0.01896,1.728,0.000
9.26,50.200,-0.01879,1.735,0.000
9.28,50.300,-0.01866,1.739,0.000
9.31,50.400,-0.01850,1.743,0.000
9.34,50.500,-0.01837,1.749,0.000
9.35,50.600,-0.01821,1.752,0.000
9.40,50.700,-0.01804,1.761,0.000
9.43,50.800,-0.01792,1.767,0.000
9.45,50.900,-0.01775,1.770,0.000
9.50,51.000,-0.01758,1.779,0.000
9.52,51.100,-0.01746,1.784,0.000
9.55,51.200,-0.01729,1.789,0.000
9.58,51.300,-0.01713,1.795,0.000
9.62,51.400,-0.01696,1.803,0.000
9.66,51.500,-0.01679,1.810,0.000
9.70,51.600,-0.01663,1.817,0.000
9.73,51.700,-0.01642,1.824,0.000
9.80,51.800,-0.01621,1.836,0.000
9.83,51.900,-0.01605,1.842,0.000
9.87,52.000,-0.01584,1.849,0.000
9.92,52.100,-0.01563,1.857,0.000
9.96,52.200,-0.01542,1.866,0.000
10.01,52.300,-0.01517,1.876,0.000
10.07,52.400,-0.01497,1.885,0.000
10.11,52.500,-0.01476,1.894,0.000
10.15,52.600,-0.01455,1.901,0.000
10.21,52.700,-0.01434,1.912,0.000
10.25,52.800,-0.01414,1.919,0.000
10.27,52.900,-0.01393,1.923,0.000
10.31,53.000,-0.01372,1.932,0.000
10.36,53.100,-0.01351,1.941,0.000
10.40,53.200,-0.01330,1.948,0.000
10.43,53.300,-0.01314,1.954,0.000
10.48,53.400,-0.01297,1.963,0.000
10.49,53.500,-0.01276,1.965,0.000
10.54,53.600,-0.01260,1.975,0.000
10.58,53.700,-0.01247,1.982,0.000
10.59,53.800,-0.01231,1.984,0.000
10.63,53.900,-0.01214,1.990,0.000
10.65,54.000,-0.01202,1.995,0.000
10.70,54.100,-0.01185,2.003,0.000
10.73,54.200,-0.01172,2.009,0.000
10.76,54.300,-0.01156,2.016,0.000
10.79,54.400,-0.01143,2.021,0.000
10.82,54.500,-0.01131,2.026,0.000
10.85,54.600,-0.01118,2.033,0.000
10.87,54.700,-0.01102,2.037,0.000
10.91,54.800,-0.01089,2.044,0.000
10.95,54.900,-0.01077,2.050,0.000
10.98,55.000,-0.01060,2.056,0.000
11.01,55.100,-0.01048,2.062,0.000
11.05,55.200,-0.01035,2.069,0.000
11.07,55.300,-0.01019,2.075,0.000
11.12,55.400,-0.01006,2.083,0.000
11.16,55.500,-0.00990,2.090,0.000
11.18,55.600,-0.00973,2.095,0.000
11.22,55.700,-0.00961,2.103,0.000
11.25,55.800,-0.00944,2.108,0.000
11.30,55.900,-0.00927,2.117,0.000
11.34,56.000,-0.00915,2.124,0.000
11.38,56.100,-0.00898,2.132,0.000
11.42,56.200,-0.00882,2.139,0.000
11.45,56.300,-0.00865,2.145,0.000
11.49,56.400,-0.00853,2.152,0.000
11.54,56.500,-0.00836,2.162,0.000
11.57,56.600,-0.00819,2.167,0.000
11.62,56.700,-0.00803,2.176,0.000
11.66,56.800,-0.00786,2.184,0.000
11.70,56.900,-0.00769,2.192,0.000
11.75,57.000,-0.00753,2.201,0.000
11.79,57.100,-0.00736,2.208,0.000
11.83,57.200,-0.00720,2.216,0.000
11.88,57.300,-0.00699,2.225,0.000
11.92,57.400,-0.00682,2.233,0.000
11.98,57.500,-0.00661,2.243,0.000
12.04,57.600,-0.00641,2.256,0.000
12.08,57.700,-0.00620,2.264,0.000
12.14,57.800,-0.00599,2.274,0.000
12.20,57.900,-0.00578,2.285,0.000
12.24,58.000,-0.00557,2.294,0.000
12.30,58.100,-0.00537,2.304,0.000
12.35,58.200,-0.00516,2.314,0.000
12.42,58.300,-0.00495,2.327,0.000
12.45,58.400,-0.00474,2.332,0.000
12.51,58.500,-0.00454,2.343,0.000
12.57,58.600,-0.00433,2.355,0.000
12.60,58.700,-0.00412,2.361,0.000
12.65,58.800,-0.00391,2.369,0.000
12.70,58.900,-0.00375,2.379,0.000
12.76,59.000,-0.00358,2.390,0.000
12.78,59.100,-0.00337,2.394,0.000
12.83,59.200,-0.00321,2.403,0.000
12.87,59.300,-0.00308,2.411,0.000
12.91,59.400,-0.00292,2.418,0.000
12.95,59.500,-0.00275,2.425,0.000
12.98,59.600,-0.00258,2.432,0.000
13.02,59.700,-0.00246,2.438,0.000
13.06,59.800,-0.00229,2.446,0.000
13.09,59.900,-0.00217,2.452,0.000
13.12,60.000,-0.00200,2.458,0.000
13.17,60.100,-0.00188,2.466,0.000
13.20,60.200,-0.00175,2.473,0.000
13.23,60.300,-0.00159,2.477,0.000
13.28,60.400,-0.00146,2.488,0.000
13.32,60.500,-0.00134,2.496,0.000
13.35,60.600,-0.00117,2.502,0.000
13.39,60.700,-0.00105,2.508,0.000
13.44,60.800,-0.00088,2.518,0.000
13.47,60.900,-0.00075,2.524,0.000
13.53,61.000,-0.00059,2.534,0.000
13.56,61.100,-0.00046,2.541,0.000
13.61,61.200,-0.00030,2.549,0.000
13.65,61.300,-0.00013,2.556,0.000
13.69,61.400,-0.00001,2.565,0.000
13.74,61.500,0.00016,2.573,0.000
13.79,61.600,0.00033,2.583,0.000
13.82,61.700,0.00045,2.590,0.000
13.87,61.800,0.00062,2.598,0.000
13.91,61.900,0.00078,2.606,0.000
13.94,62.000,0.00095,2.612,0.000
14.01,62.100,0.00112,2.625,0.000
14.04,62.200,0.00124,2.631,0.000
14.08,62.300,0.00141,2.638,0.000
14.15,62.400,0.00157,2.651,0.000
14.19,62.500,0.00174,2.658,0.000
14.23,62.600,0.00191,2.665,0.000
14.29,62.700,0.00207,2.677,0.000
14.33,62.800,0.00228,2.685,0.000
14.38,62.900,0.00245,2.693,0.000
14.43,63.000,0.00261,2.702,0.000
14.48,63.100,0.00282,2.713,0.000
14.55,63.200,0.00303,2.726,0.000
14.61,63.300,0.00319,2.737,0.000
14.68,63.400,0.00340,2.749,0.000
14.72,63.500,0.00361,2.758,0.000
14.79,63.600,0.00382,2.771,0.000
14.86,63.700,0.00402,2.784,0.000
14.91,63.800,0.00423,2.794,0.000
14.99,63.900,0.00444,2.807,0.000
15.04,64.000,0.00465,2.817,0.000
15.10,64.100,0.00486,2.829,0.000
15.16,64.200,0.00506,2.841,0.000
15.22,64.300,0.00527,2.850,0.000
15.26,64.400,0.00548,2.859,0.000
15.32,64.500,0.00565,2.869,0.000
15.36,64.600,0.00581,2.878,0.000
15.41,64.700,0.00602,2.887,0.000
15.45,64.800,0.00619,2.894,0.000
15.51,64.900,0.00635,2.905,0.000
15.55,65.000,0.00648,2.913,0.000
15.60,65.100,0.00664,2.922,0.000
15.63,65.200,0.00681,2.927,0.000
15.69,65.300,0.00693,2.939,0.000
15.73,65.400,0.00710,2.946,0.000
15.75,65.500,0.00722,2.951,0.000
15.80,65.600,0.00739,2.960,0.000
15.83,65.700,0.00752,2.966,0.000
15.89,65.800,0.00764,2.976,0.000
15.92,65.900,0.00781,2.982,0.000
15.96,66.000,0.00793,2.990,0.000
16.00,66.100,0.00806,2.998,0.000
16.05,66.200,0.00822,3.007,0.000
16.09,66.300,0.00835,3.014,0.000
16.12,66.400,0.00847,3.020,0.000
16.16,66.500,0.00864,3.027,0.000
16.21,66.600,0.00876,3.037,0.000
16.25,66.700,0.00893,3.044,0.000
16.30,66.800,0.00905,3.053,0.000
16.35,66.900,0.00922,3.063,0.000
16.39,67.000,0.00934,3.071,0.000
16.44,67.100,0.00951,3.080,0.000
16.49,67.200,0.00963,3.090,0.000
16.54,67.300,0.00980,3.098,0.000
16.58,67.400,0.00997,3.106,0.000
16.63,67.500,0.01013,3.115,0.000
16.66,67.600,0.01026,3.122,0.000
16.73,67.700,0.01042,3.133,0.000
16.77,67.800,0.01059,3.141,0.000
16.83,67.900,0.01072,3.152,0.000
16.88,68.000,0.01088,3.162,0.000
16.92,68.100,0.01105,3.169,0.000
16.96,68.200,0.01121,3.178,0.000
17.01,68.300,0.01138,3.187,0.000
17.07,68.400,0.01155,3.199,0.000
17.13,68.500,0.01171,3.209,0.000
17.21,68.600,0.01192,3.223,0.000
17.26,68.700,0.01209,3.234,0.000
17.32,68.800,0.01229,3.245,0.000
17.42,68.900,0.01250,3.262,0.000
17.48,69.000,0.01271,3.275,0.000
17.55,69.100,0.01292,3.287,0.000
17.62,69.200,0.01313,3.301,0.000
17.70,69.300,0.01333,3.316,0.000
17.77,69.400,0.01354,3.329,0.000
17.84,69.500,0.01379,3.341,0.000
17.92,69.600,0.01400,3.356,0.000
17.97,69.700,0.01421,3.366,0.000
18.06,69.800,0.01441,3.383,0.000
18.11,69.900,0.01462,3.392,0.000
18.18,70.000,0.01479,3.406,0.000
18.23,70.100,0.01500,3.415,0.000
18.29,70.200,0.01516,3.426,0.000
18.33,70.300,0.01537,3.434,0.000
18.38,70.400,0.01554,3.443,0.000
18.43,70.500,0.01566,3.452,0.000
18.48,70.600,0.01583,3.462,0.000
18.53,70.700,0.01599,3.471,0.000
18.57,70.800,0.01616,3.478,0.000
18.62,70.900,0.01628,3.487,0.000
18.66,71.000,0.01645,3.495,0.000
18.72,71.100,0.01657,3.506,0.000
18.76,71.200,0.01670,3.514,0.000
18.80,71.300,0.01687,3.522,0.000
18.84,71.400,0.01699,3.529,0.000
18.87,71.500,0.01711,3.535,0.000
18.92,71.600,0.01724,3.544,0.000
18.97,71.700,0.01741,3.554,0.000
19.01,71.800,0.01753,3.562,0.000
19.06,71.900,0.01770,3.570,0.000
19.11,72.000,0.01782,3.580,0.000
19.16,72.100,0.01795,3.589,0.000
19.20,72.200,0.01811,3.597,0.000
19.26,72.300,0.01824,3.608,0.000
19.31,72.400,0.01840,3.618,0.000
19.36,72.500,0.01853,3.626,0.000
19.42,72.600,0.01869,3.637,0.000
19.48,72.700,0.01882,3.649,0.000
19.52,72.800,0.01898,3.656,0.000
19.58,72.900,0.01915,3.667,0.000
19.63,73.000,0.01928,3.677,0.000
19.68,73.100,0.01944,3.687,0.000
19.75,73.200,0.01961,3.699,0.000
19.79,73.300,0.01973,3.707,0.000
19.84,73.400,0.01990,3.717,0.000
19.91,73.500,0.02007,3.730,0.000
19.97,73.600,0.02023,3.741,0.000
20.01,73.700,0.02036,3.749,0.000
20.07,73.800,0.02052,3.760,0.000
20.12,73.900,0.02069,3.770,0.000
20.20,74.000,0.02085,3.784,0.000
20.26,74.100,0.02102,3.794,0.000
20.32,74.200,0.02123,3.806,0.000
20.40,74.300,0.02140,3.821,0.000
20.48,74.400,0.02160,3.837,0.000
20.54,74.500,0.02181,3.848,0.000
20.63,74.600,0.02198,3.864,0.000
20.71,74.700,0.02218,3.880,0.000
20.79,74.800,0.02239,3.895,0.000
20.88,74.900,0.02260,3.910,0.000
20.94,75.000,0.02285,3.922,0.000
21.03,75.100,0.02306,3.939,0.000
21.11,75.200,0.02327,3.955,0.000
21.18,75.300,0.02347,3.967,0.000
21.26,75.400,0.02368,3.982,0.000
21.31,75.500,0.02389,3.993,0.000
21.40,75.600,0.02405,4.009,0.000
21.48,75.700,0.02426,4.023,0.000
21.55,75.800,0.02447,4.037,0.000
21.59,75.900,0.02464,4.044,0.000
21.65,76.000,0.02480,4.055,0.000
21.73,76.100,0.02497,4.070,0.000
21.78,76.200,0.02514,4.080,0.000
21.83,76.300,0.02530,4.089,0.000
21.89,76.400,0.02547,4.100,0.001
21.95,76.500,0.02559,4.111,0.001
21.99,76.600,0.02576,4.120,0.001
22.04,76.700,0.02588,4.128,0.001
22.10,76.800,0.02605,4.140,0.001
22.15,76.900,0.02622,4.150,0.001
22.19,77.000,0.02634,4.157,0.001
22.23,77.100,0.02646,4.164,0.001
22.28,77.200,0.02659,4.174,0.001
22.34,77.300,0.02676,4.185,0.001
22.39,77.400,0.02688,4.194,0.001
22.43,77.500,0.02701,4.203,0.001
22.49,77.600,0.02717,4.213,0.001
22.55,77.700,0.02730,4.225,0.001
22.61,77.800,0.02742,4.236,0.001
22.66,77.900,0.02759,4.246,0.001
22.72,78.000,0.02771,4.255,0.001
22.77,78.100,0.02788,4.266,0.001
22.83,78.200,0.02800,4.277,0.001
22.88,78.300,0.02817,4.285,0.001
22.95,78.400,0.02829,4.298,0.001
23.01,78.500,0.02846,4.310,0.001
23.09,78.600,0.02863,4.325,0.001
23.13,78.700,0.02875,4.333,0.001
23.20,78.800,0.02892,4.346,0.001
23.26,78.900,0.02904,4.357,0.001
23.32,79.000,0.02921,4.368,0.001
23.38,79.100,0.02937,4.379,0.001
23.44,79.200,0.02950,4.391,0.001
23.50,79.300,0.02966,4.402,0.001
23.57,79.400,0.02983,4.415,0.001
23.64,79.500,0.03000,4.429,0.001
23.70,79.600,0.03016,4.439,0.001
23.77,79.700,0.03033,4.452,0.001
23.84,79.800,0.03050,4.466,0.001
23.91,79.900,0.03066,4.479,0.001
23.99,80.000,0.03083,4.493,0.001
24.06,80.100,0.03104,4.507,0.001
24.14,80.200,0.03120,4.523,0.001
24.21,80.300,0.03141,4.535,0.001
24.30,80.400,0.03162,4.551,0.001
24.37,80.500,0.03178,4.566,0.001
24.49,80.600,0.03199,4.587,0.001
24.56,80.700,0.03220,4.600,0.001
24.66,80.800,0.03241,4.619,0.001
24.73,80.900,0.03262,4.632,0.001
24.80,81.000,0.03282,4.646,0.001
24.90,81.100,0.03303,4.664,0.001
24.97,81.200,0.03324,4.678,0.001
25.06,81.300,0.03345,4.694,0.001
25.15,81.400,0.03361,4.712,0.001
25.23,81.500,0.03382,4.726,0.001
25.30,81.600,0.03403,4.739,0.001
25.37,81.700,0.03419,4.752,0.001
25.42,81.800,0.03436,4.762,0.001
25.50,81.900,0.03453,4.777,0.001
25.56,82.000,0.03469,4.788,0.001
25.62,82.100,0.03486,4.799,0.001
25.67,82.200,0.03498,4.810,0.001
25.75,82.300,0.03515,4.824,0.001
25.82,82.400,0.03532,4.837,0.001
25.88,82.500,0.03544,4.849,0.001
25.94,82.600,0.03561,4.860,0.001
26.00,82.700,0.03573,4.870,0.001
26.06,82.800,0.03590,4.882,0.001
26.12,82.900,0.03602,4.893,0.001
26.17,83.000,0.03615,4.903,0.001
26.22,83.100,0.03627,4.911,0.001
26.28,83.200,0.03644,4.922,0.001
26.34,83.300,0.03656,4.935,0.001
26.42,83.400,0.03669,4.948,0.001
26.48,83.500,0.03685,4.960,0.001
26.53,83.600,0.03698,4.969,0.001
26.59,83.700,0.03710,4.981,0.001
26.67,83.800,0.03727,4.996,0.001
26.73,83.900,0.03739,5.008,0.001
26.80,84.000,0.03756,5.019,0.001
26.86,84.100,0.03769,5.032,0.001
26.93,84.200,0.03785,5.044,0.001
26.98,84.300,0.03802,5.054,0.001
27.04,84.400,0.03814,5.066,0.001
27.12,84.500,0.03831,5.080,0.001
27.18,84.600,0.03843,5.092,0.001
27.25,84.700,0.03860,5.104,0.001
27.33,84.800,0.03877,5.119,0.001
27.40,84.900,0.03889,5.132,0.001
27.45,85.000,0.03906,5.142,0.001
27.54,85.100,0.03922,5.158,0.001
27.60,85.200,0.03939,5.170,0.001
27.66,85.300,0.03951,5.181,0.001
27.74,85.400,0.03968,5.196,0.001
27.82,85.500,0.03985,5.211,0.001
27.88,85.600,0.04001,5.223,0.001
27.97,85.700,0.04018,5.240,0.001
28.07,85.800,0.04039,5.257,0.001
28.15,85.900,0.04055,5.273,0.001
28.25,86.000,0.04076,5.291,0.001
28.36,86.100,0.04097,5.312,0.001
28.45,86.200,0.04118,5.330,0.001
28.55,86.300,0.04138,5.348,0.001
28.64,86.400,0.04159,5.365,0.001
28.74,86.500,0.04180,5.385,0.001
28.85,86.600,0.04201,5.404,0.001
28.94,86.700,0.04221,5.421,0.001
29.02,86.800,0.04246,5.437,0.001
29.13,86.900,0.04267,5.456,0.001
29.24,87.000,0.04288,5.477,0.001
29.31,87.100,0.04309,5.491,0.001
29.40,87.200,0.04325,5.508,0.001
29.50,87.300,0.04346,5.526,0.001
29.58,87.400,0.04363,5.540,0.001
29.65,87.500,0.04384,5.555,0.001
29.72,87.600,0.04396,5.568,0.001
29.80,87.700,0.04413,5.583,0.001
29.86,87.800,0.04429,5.594,0.001
29.92,87.900,0.04446,5.605,0.001
30.00,88.000,0.04458,5.619,0.001
30.06,88.100,0.04475,5.631,0.001
30.13,88.200,0.04487,5.645,0.001
30.20,88.300,0.04504,5.657,0.001
30.25,88.400,0.04517,5.666,0.001
30.31,88.500,0.04529,5.678,0.001
30.37,88.600,0.04541,5.690,0.001
30.44,88.700,0.04558,5.702,0.001
30.49,88.800,0.04571,5.711,0.001
30.56,88.900,0.04583,5.725,0.001
30.63,89.000,0.04595,5.737,0.001
30.70,89.100,0.04612,5.750,0.001
30.77,89.200,0.04625,5.764,0.001
30.83,89.300,0.04641,5.776,0.001
30.90,89.400,0.04654,5.788,0.001
30.97,89.500,0.04670,5.801,0.001
31.05,89.600,0.04683,5.816,0.001
31.12,89.700,0.04699,5.829,0.001
31.20,89.800,0.04716,5.845,0.001
31.28,89.900,0.04728,5.859,0.001
31.35,90.000,0.04745,5.872,0.001
31.42,90.100,0.04758,5.886,0.001
31.48,90.200,0.04774,5.898,0.001
31.57,90.300,0.04791,5.915,0.001
31.64,90.400,0.04807,5.927,0.001
31.72,90.500,0.04820,5.942,0.001
31.79,90.600,0.04836,5.954,0.001
31.86,90.700,0.04853,5.968,0.001
31.96,90.800,0.04870,5.986,0.001
32.02,90.900,0.04886,5.999,0.001
32.11,91.000,0.04903,6.016,0.001
32.20,91.100,0.04920,6.031,0.001
32.30,91.200,0.04936,6.050,0.001
32.37,91.300,0.04953,6.064,0.001
32.47,91.400,0.04974,6.083,0.001
32.58,91.500,0.04990,6.104,0.001
32.68,91.600,0.05011,6.122,0.001
32.80,91.700,0.05032,6.145,0.001
32.92,91.800,0.05053,6.166,0.001
33.03,91.900,0.05073,6.188,0.001
33.14,92.000,0.05098,6.208,0.001
33.26,92.100,0.05119,6.230,0.001
33.37,92.200,0.05140,6.251,0.001
33.48,92.300,0.05165,6.272,0.001
33.59,92.400,0.05186,6.292,0.001
33.70,92.500,0.05206,6.313,0.001
33.81,92.600,0.05227,6.333,0.001
33.91,92.700,0.05248,6.351,0.001
34.02,92.800,0.05269,6.372,0.001
34.11,92.900,0.05285,6.390,0.001
34.19,93.000,0.05302,6.405,0.001
34.29,93.100,0.05323,6.423,0.001
34.37,93.200,0.05339,6.438,0.001
34.46,93.300,0.05356,6.455,0.001
34.54,93.400,0.05373,6.470,0.001
34.61,93.500,0.05385,6.484,0.001
34.69,93.600,0.05402,6.499,0.001
34.77,93.700,0.05418,6.513,0.001
34.84,93.800,0.05431,6.526,0.001
34.91,93.900,0.05447,6.540,0.001
34.98,94.000,0.05460,6.553,0.001
35.05,94.100,0.05476,6.566,0.001
35.11,94.200,0.05489,6.577,0.001
35.19,94.300,0.05501,6.592,0.001
35.26,94.400,0.05518,6.605,0.001
35.32,94.500,0.05530,6.616,0.001
35.41,94.600,0.05547,6.634,0.001
35.49,94.700,0.05560,6.648,0.001
35.56,94.800,0.05572,6.662,0.001
35.65,94.900,0.05589,6.678,0.001
35.72,95.000,0.05601,6.692,0.001
35.79,95.100,0.05618,6.705,0.001
35.87,95.200,0.05634,6.719,0.001
35.96,95.300,0.05651,6.737,0.001
36.04,95.400,0.05663,6.752,0.001
36.14,95.500,0.05680,6.769,0.001
36.23,95.600,0.05697,6.786,0.001
36.32,95.700,0.05713,6.804,0.001
36.41,95.800,0.05726,6.820,0.001
36.49,95.900,0.05742,6.836,0.001
36.58,96.000,0.05759,6.852,0.001
36.65,96.100,0.05776,6.865,0.001
36.74,96.200,0.05788,6.882,0.001
36.83,96.300,0.05805,6.900,0.001
36.91,96.400,0.05821,6.914,0.001
37.01,96.500,0.05838,6.932,0.001
37.07,96.600,0.05855,6.945,0.001
37.18,96.700,0.05871,6.964,0.001
37.27,96.800,0.05888,6.982,0.001
37.36,96.900,0.05909,6.998,0.001
37.49,97.000,0.05925,7.023,0.001
37.60,97.100,0.05942,7.044,0.001
37.71,97.200,0.05963,7.063,0.001
37.81,97.300,0.05983,7.083,0.001
37.94,97.400,0.06004,7.108,0.001
38.06,97.500,0.06025,7.129,0.001
38.17,97.600,0.06046,7.151,0.001
38.29,97.700,0.06067,7.173,0.001
38.41,97.800,0.06087,7.195,0.001
38.52,97.900,0.06108,7.215,0.001
38.65,98.000,0.06129,7.240,0.001
38.75,98.100,0.06150,7.260,0.001
38.85,98.200,0.06170,7.277,0.001
38.93,98.300,0.06187,7.292,0.001
39.04,98.400,0.06208,7.313,0.001
39.14,98.500,0.06229,7.332,0.001
39.22,98.600,0.06245,7.347,0.001
39.31,98.700,0.06262,7.364,0.001
39.40,98.800,0.06278,7.380,0.001
39.47,98.900,0.06295,7.393,0.001
39.56,99.000,0.06312,7.411,0.001
39.64,99.100,0.06324,7.426,0.001
39.71,99.200,0.06341,7.438,0.001
39.79,99.300,0.06357,7.453,0.001
39.88,99.400,0.06370,7.470,0.001
39.96,99.500,0.06387,7.485,0.001
40.03,99.600,0.06399,7.498,0.001
40.10,99.700,0.06411,7.511,0.001
40.19,99.800,0.06428,7.528,0.001
40.25,99.900,0.06441,7.540,0.001
40.32,100.000,0.06453,7.553,0.001
40.39,100.100,0.06470,7.566,0.001
40.46,100.200,0.06482,7.579,0.001
40.53,100.300,0.06495,7.592,0.001
40.61,100.400,0.06507,7.608,0.001
40.69,100.500,0.06524,7.622,0.001
40.76,100.600,0.06536,7.635,0.001
40.86,100.700,0.06549,7.653,0.001
40.93,100.800,0.06565,7.667,0.001
41.01,100.900,0.06578,7.681,0.001
41.09,101.000,0.06590,7.697,0.001
41.17,101.100,0.06607,7.713,0.001
41.27,101.200,0.06619,7.730,0.001
41.35,101.300,0.06636,7.746,0.001
41.45,101.400,0.06652,7.765,0.001
41.53,101.500,0.06665,7.780,0.001
41.62,101.600,0.06682,7.797,0.001
41.70,101.700,0.06694,7.812,0.001
41.81,101.800,0.06711,7.831,0.001
41.90,101.900,0.06727,7.850,0.001
41.98,102.000,0.06740,7.864,0.001
42.07,102.100,0.06756,7.881,0.001
42.16,102.200,0.06773,7.898,0.001
42.27,102.300,0.06790,7.917,0.001
42.36,102.400,0.06806,7.935,0.001
42.46,102.500,0.06823,7.954,0.001
42.55,102.600,0.06839,7.970,0.001
42.66,102.700,0.06856,7.992,0.001
42.77,102.800,0.06877,8.012,0.001
42.89,102.900,0.06894,8.034,0.001
43.00,103.000,0.06914,8.054,0.001
43.12,103.100,0.06935,8.078,0.001
43.24,103.200,0.06956,8.100,0.001
43.36,103.300,0.06977,8.123,0.001
43.49,103.400,0.06997,8.148,0.001
43.60,103.500,0.07018,8.168,0.001
43.72,103.600,0.07039,8.191,0.001
43.85,103.700,0.07060,8.215,0.001
43.98,103.800,0.07081,8.239,0.001
44.11,103.900,0.07101,8.262,0.001
44.22,104.000,0.07122,8.284,0.001
44.32,104.100,0.07143,8.302,0.001
44.43,104.200,0.07159,8.323,0.001
44.53,104.300,0.07180,8.341,0.001
44.64,104.400,0.07197,8.362,0.001
44.72,104.500,0.07213,8.378,0.001
44.82,104.600,0.07230,8.396,0.001
44.89,104.700,0.07247,8.408,0.001
44.98,104.800,0.07263,8.425,0.001
45.08,104.900,0.07280,8.445,0.001
45.15,105.000,0.07292,8.458,0.001
45.25,105.100,0.07309,8.476,0.001
45.32,105.200,0.07322,8.489,0.001
45.39,105.300,0.07334,8.503,0.001
45.47,105.400,0.07351,8.518,0.001
45.56,105.500,0.07363,8.534,0.001
45.65,105.600,0.07376,8.551,0.001
45.72,105.700,0.07388,8.564,0.001
45.80,105.800,0.07405,8.580,0.001
45.86,105.900,0.07417,8.591,0.001
45.96,106.000,0.07430,8.609,0.001
46.02,106.100,0.07442,8.621,0.001
46.13,106.200,0.07459,8.641,0.001
46.21,106.300,0.07471,8.656,0.001
46.30,106.400,0.07488,8.673,0.001
46.38,106.500,0.07500,8.689,0.001
46.50,106.600,0.07517,8.710,0.001
46.58,106.700,0.07529,8.725,0.001
46.66,106.800,0.07546,8.741,0.001
46.76,106.900,0.07558,8.759,0.001
46.83,107.000,0.07575,8.771,0.001
46.91,107.100,0.07587,8.788,0.001
47.02,107.200,0.07604,8.808,0.001
47.13,107.300,0.07621,8.828,0.002
47.21,107.400,0.07633,8.844,0.002
47.32,107.500,0.07650,8.863,0.002
47.41,107.600,0.07666,8.882,0.002
47.51,107.700,0.07679,8.901,0.002
47.61,107.800,0.07696,8.919,0.002
47.69,107.900,0.07712,8.933,0.002
47.80,108.000,0.07729,8.953,0.002
47.89,108.100,0.07741,8.971,0.002
48.00,108.200,0.07758,8.991,0.002
48.10,108.300,0.07779,9.010,0.002
48.20,108.400,0.07795,9.029,0.002
48.32,108.500,0.07812,9.052,0.002
48.45,108.600,0.07833,9.076,0.002
48.58,108.700,0.07849,9.100,0.002
48.69,108.800,0.07870,9.122,0.002
48.82,108.900,0.07891,9.146,0.002
48.95,109.000,0.07912,9.169,0.002
49.10,109.100,0.07932,9.198,0.002
49.23,109.200,0.07953,9.222,0.002
49.34,109.300,0.07974,9.243,0.002
49.49,109.400,0.07995,9.272,0.002
49.62,109.500,0.08016,9.295,0.002
49.75,109.600,0.08036,9.319,0.002
49.86,109.700,0.08057,9.339,0.002
49.99,109.800,0.08078,9.365,0.002
50.10,109.900,0.08094,9.385,0.002
50.22,110.000,0.08115,9.407,0.002
50.33,110.100,0.08132,9.428,0.002
50.45,110.200,0.08153,9.450,0.002
50.56,110.300,0.08169,9.471,0.002
50.67,110.400,0.08186,9.493,0.002
50.76,110.500,0.08203,9.509,0.002
50.84,110.600,0.08215,9.524,0.002
50.93,110.700,0.08232,9.541,0.002
51.04,110.800,0.08244,9.560,0.002
51.13,110.900,0.08261,9.577,0.002
51.21,111.000,0.08273,9.593,0.002
51.30,111.100,0.08290,9.609,0.002
51.38,111.200,0.08302,9.624,0.002
51.46,111.300,0.08315,9.640,0.002
51.54,111.400,0.08331,9.655,0.002
51.63,111.500,0.08344,9.672,0.002
51.72,111.600,0.08356,9.688,0.002
51.79,111.700,0.08369,9.702,0.002
51.87,111.800,0.08385,9.717,0.002
51.97,111.900,0.08398,9.736,0.002
52.06,112.000,0.08410,9.753,0.002
52.14,112.100,0.08427,9.766,0.002
52.23,112.200,0.08439,9.783,0.002
52.32,112.300,0.08452,9.801,0.002
52.43,112.400,0.08468,9.821,0.002
52.52,112.500,0.08481,9.837,0.002
52.59,112.600,0.08498,9.852,0.002
52.71,112.700,0.08514,9.873,0.002
52.79,112.800,0.08527,9.889,0.002
52.90,112.900,0.08543,9.910,0.002
52.99,113.000,0.08560,9.925,0.002
53.09,113.100,0.08572,9.946,0.002
53.20,113.200,0.08589,9.966,0.002
53.29,113.300,0.08606,9.982,0.002
53.38,113.400,0.08618,9.999,0.002
53.50,113.500,0.08635,10.021,0.002
53.57,113.600,0.08651,10.036,0.002
53.68,113.700,0.08668,10.055,0.002
53.76,113.800,0.08685,10.070,0.002
53.85,113.900,0.08701,10.088,0.002
53.96,114.000,0.08718,10.108,0.002
54.05,114.100,0.08734,10.125,0.002
54.16,114.200,0.08751,10.145,0.002
54.25,114.300,0.08772,10.163,0.002
54.35,114.400,0.08788,10.182,0.002
54.46,114.500,0.08809,10.202,0.002
54.59,114.600,0.08826,10.226,0.002
54.72,114.700,0.08847,10.250,0.002
54.85,114.800,0.08867,10.274,0.002
54.97,114.900,0.08888,10.298,0.002
55.11,115.000,0.08913,10.323,0.002
55.24,115.100,0.08934,10.347,0.002
55.37,115.200,0.08955,10.372,0.002
55.49,115.300,0.08971,10.394,0.002
55.61,115.400,0.08992,10.416,0.002
55.74,115.500,0.09013,10.441,0.002
55.85,115.600,0.09034,10.461,0.002
55.96,115.700,0.09050,10.483,0.002
56.08,115.800,0.09071,10.505,0.002
56.18,115.900,0.09088,10.524,0.002
56.29,116.000,0.09104,10.545,0.002
39.68,116.100,0.09121,7.434,0.002
28.58,116.200,0.09138,5.354,0.002
28.08,116.300,0.09154,5.260,0.002
28.20,116.400,0.09171,5.283,0.002
28.39,116.500,0.09183,5.319,0.002
28.59,116.600,0.09200,5.355,0.002
28.78,116.700,0.09216,5.392,0.002
28.91,116.800,0.09229,5.415,0.002
29.07,116.900,0.09241,5.446,0.002
29.24,117.000,0.09258,5.478,0.002
29.39,117.100,0.09270,5.505,0.002
29.54,117.200,0.09283,5.533,0.002
29.69,117.300,0.09300,5.561,0.002
29.83,117.400,0.09312,5.588,0.002
29.93,117.500,0.09325,5.607,0.002
30.09,117.600,0.09337,5.636,0.002
30.20,117.700,0.09354,5.658,0.002
30.33,117.800,0.09366,5.681,0.002
30.46,117.900,0.09383,5.706,0.002
30.60,118.000,0.09395,5.732,0.002
30.70,118.100,0.09412,5.751,0.002
30.82,118.200,0.09424,5.773,0.002
30.95,118.300,0.09441,5.798,0.002
31.06,118.400,0.09453,5.818,0.002
31.17,118.500,0.09470,5.840,0.002
31.29,118.600,0.09487,5.862,0.002
31.39,118.700,0.09499,5.881,0.002
31.52,118.800,0.09516,5.904,0.002
31.62,118.900,0.09532,5.923,0.002
31.73,119.000,0.09549,5.943,0.002
31.83,119.100,0.09561,5.962,0.002
31.94,119.200,0.09578,5.984,0.002
32.04,119.300,0.09595,6.002,0.002
32.14,119.400,0.09611,6.021,0.002
32.25,119.500,0.09624,6.041,0.002
32.34,119.600,0.09640,6.059,0.002
32.46,119.700,0.09661,6.080,0.002
32.57,119.800,0.09678,6.101,0.002
32.68,119.900,0.09694,6.122,0.002
32.79,120.000,0.09715,6.142,0.002
32.92,120.100,0.09732,6.167,0.002
33.04,120.200,0.09753,6.190,0.002
33.15,120.300,0.09773,6.209,0.002
33.29,120.400,0.09794,6.236,0.002
33.41,120.500,0.09815,6.259,0.002
33.52,120.600,0.09840,6.279,0.002
33.65,120.700,0.09861,6.303,0.002
33.75,120.800,0.09881,6.322,0.002
33.85,120.900,0.09902,6.341,0.002
33.95,121.000,0.09923,6.360,0.002
34.04,121.100,0.09944,6.377,0.002
34.12,121.200,0.09964,6.391,0.002
34.20,121.300,0.09985,6.406,0.002
34.28,121.400,0.10002,6.421,0.002
34.32,121.500,0.10019,6.429,0.002
34.37,121.600,0.10035,6.439,0.002
34.43,121.700,0.10056,6.450,0.002
34.49,121.800,0.10068,6.461,0.002
34.54,121.900,0.10085,6.470,0.002
34.58,122.000,0.10102,6.477,0.002
34.61,122.100,0.10114,6.484,0.002
34.64,122.200,0.10131,6.490,0.002
34.69,122.300,0.10147,6.498,0.002
34.73,122.400,0.10160,6.505,0.002
34.75,122.500,0.10172,6.509,0.002
34.79,122.600,0.10189,6.516,0.002
34.82,122.700,0.10201,6.522,0.002
34.85,122.800,0.10214,6.528,0.002
34.89,122.900,0.10230,6.535,0.002
34.94,123.000,0.10243,6.545,0.002
34.96,123.100,0.10255,6.548,0.002
34.98,123.200,0.10272,6.553,0.002
35.02,123.300,0.10284,6.559,0.002
35.05,123.400,0.10297,6.566,0.002
35.09,123.500,0.10314,6.573,0.002
35.12,123.600,0.10326,6.578,0.002
35.16,123.700,0.10343,6.586,0.002
35.19,123.800,0.10355,6.593,0.002
35.22,123.900,0.10372,6.598,0.002
35.25,124.000,0.10388,6.602,0.002
35.28,124.100,0.10401,6.609,0.002
35.31,124.200,0.10417,6.615,0.002
35.34,124.300,0.10434,6.619,0.002
35.37,124.400,0.10447,6.626,0.002
35.39,124.500,0.10463,6.630,0.002
35.42,124.600,0.10480,6.634,0.002
35.44,124.700,0.10496,6.638,0.002
35.46,124.800,0.10513,6.643,0.002
35.47,124.900,0.10525,6.644,0.002
35.49,125.000,0.10542,6.648,0.002
35.51,125.100,0.10559,6.653,0.002
33.92,125.200,0.10575,6.354,0.002
15.26,125.300,0.10592,2.859,0.002
15.47,125.400,0.10609,2.898,0.002
15.65,125.500,0.10629,2.933,0.002
15.84,125.600,0.10646,2.967,0.002
15.99,125.700,0.10667,2.996,0.002
16.17,125.800,0.10683,3.030,0.002
16.32,125.900,0.10704,3.056,0.002
16.45,126.000,0.10725,3.082,0.002
16.59,126.100,0.10750,3.108,0.002
16.75,126.200,0.10771,3.137,0.002
16.88,126.300,0.10791,3.161,0.002
16.99,126.400,0.10816,3.182,0.002
17.10,126.500,0.10837,3.204,0.002
17.20,126.600,0.10858,3.222,0.002
17.31,126.700,0.10879,3.242,0.002
17.40,126.800,0.10899,3.259,0.002
17.48,126.900,0.10920,3.274,0.002
17.57,127.000,0.10937,3.290,0.002
17.64,127.100,0.10958,3.305,0.002
17.71,127.200,0.10974,3.317,0.002
17.78,127.300,0.10995,3.331,0.002
17.83,127.400,0.11012,3.341,0.002
17.88,127.500,0.11028,3.350,0.002
17.94,127.600,0.11041,3.361,0.002
18.01,127.700,0.11057,3.374,0.002
18.06,127.800,0.11074,3.383,0.002
18.11,127.900,0.11091,3.392,0.002
18.15,128.000,0.11103,3.400,0.002
18.20,128.100,0.11120,3.409,0.002
18.23,128.200,0.11132,3.415,0.002
18.27,128.300,0.11149,3.421,0.002
18.29,128.400,0.11161,3.427,0.002
18.30,128.500,0.11174,3.429,0.002
18.32,128.600,0.11190,3.432,0.002
18.27,128.700,0.11203,3.423,0.002
18.21,128.800,0.11215,3.410,0.002
18.19,128.900,0.11232,3.408,0.002
18.18,129.000,0.11244,3.406,0.002
18.20,129.100,0.11261,3.409,0.002
18.25,129.200,0.11273,3.418,0.002
18.29,129.300,0.11290,3.425,0.002
18.31,129.400,0.11303,3.431,0.002
18.36,129.500,0.11319,3.440,0.002
18.40,129.600,0.11336,3.447,0.002
18.43,129.700,0.11348,3.453,0.002
18.47,129.800,0.11365,3.460,0.002
18.53,129.900,0.11382,3.471,0.002
18.56,130.000,0.11394,3.476,0.002
18.60,130.100,0.11411,3.484,0.002
18.65,130.200,0.11427,3.493,0.002
18.67,130.300,0.11444,3.497,0.002
18.71,130.400,0.11460,3.505,0.002
18.75,130.500,0.11473,3.513,0.002
18.80,130.600,0.11490,3.522,0.002
18.83,130.700,0.11506,3.527,0.002
18.86,130.800,0.11523,3.533,0.002
18.88,130.900,0.11544,3.536,0.002
18.90,131.000,0.11560,3.541,0.002
18.96,131.100,0.11577,3.552,0.002
18.99,131.200,0.11598,3.558,0.002
19.05,131.300,0.11614,3.568,0.002
19.12,131.400,0.11635,3.582,0.002
19.15,131.500,0.11656,3.587,0.002
19.19,131.600,0.11677,3.595,0.002
19.23,131.700,0.11697,3.603,0.002
19.27,131.800,0.11718,3.609,0.002
19.31,131.900,0.11739,3.618,0.002
19.34,132.000,0.11760,3.624,0.002
19.39,132.100,0.11780,3.632,0.002
19.41,132.200,0.11801,3.636,0.002
19.43,132.300,0.11822,3.640,0.002
19.47,132.400,0.11843,3.647,0.002
19.49,132.500,0.11864,3.651,0.002
19.50,132.600,0.11880,3.654,0.002
19.53,132.700,0.11901,3.658,0.002
19.55,132.800,0.11918,3.662,0.002
19.56,132.900,0.11938,3.664,0.002
19.56,133.000,0.11955,3.665,0.002
19.57,133.100,0.11972,3.666,0.002
19.58,133.200,0.11988,3.667,0.002
19.58,133.300,0.12001,3.668,0.002
19.60,133.400,0.12017,3.671,0.002
19.62,133.500,0.12034,3.676,0.002
19.62,133.600,0.12046,3.676,0.002
19.62,133.700,0.12063,3.674,0.002
19.64,133.800,0.12076,3.679,0.002
19.63,133.900,0.12092,3.677,0.002
19.64,134.000,0.12105,3.679,0.002
19.64,134.100,0.12117,3.680,0.002
19.64,134.200,0.12134,3.679,0.002
19.65,134.300,0.12146,3.681,0.002
19.65,134.400,0.12159,3.681,0.002
19.66,134.500,0.12171,3.683,0.002
19.68,134.600,0.12188,3.687,0.002
19.69,134.700,0.12200,3.688,0.002
19.69,134.800,0.12217,3.689,0.002
19.70,134.900,0.12229,3.690,0.002
19.71,135.000,0.12246,3.692,0.002
19.72,135.100,0.12258,3.695,0.002
19.73,135.200,0.12275,3.697,0.002
19.74,135.300,0.12287,3.699,0.002
19.75,135.400,0.12304,3.701,0.002
19.78,135.500,0.12317,3.706,0.002
19.77,135.600,0.12333,3.704,0.002
19.76,135.700,0.12350,3.702,0.002
19.78,135.800,0.12366,3.704,0.002
19.79,135.900,0.12379,3.707,0.002
19.77,136.000,0.12395,3.703,0.002
19.79,136.100,0.12412,3.706,0.002
19.78,136.200,0.12429,3.706,0.002
19.78,136.300,0.12445,3.705,0.002
19.77,136.400,0.12462,3.703,0.002
19.78,136.500,0.12474,3.705,0.002
19.80,136.600,0.12495,3.708,0.002
19.78,136.700,0.12512,3.704,0.002
19.80,136.800,0.12528,3.709,0.002
19.80,136.900,0.12545,3.708,0.002
19.81,137.000,0.12566,3.712,0.002
19.83,137.100,0.12587,3.714,0.002
19.84,137.200,0.12607,3.716,0.002
19.86,137.300,0.12628,3.720,0.002
19.87,137.400,0.12649,3.721,0.002
19.89,137.500,0.12670,3.726,0.002
19.88,137.600,0.12695,3.724,0.002
19.89,137.670,0.12707,3.726,0.003