File: data-files/CWRU/0900-10-40C.txt
""
"Test Method","Will_Huddleston_Disks.msm"
"Sample I. D.","900-10-40C.mss"
"Specimen Number","1"

"Load (N)","Time (s)","Extension (mm)","Stress (MPa)","Strain (mm/mm)"

2.55,0.200,-0.06918,0.480,-0.001
2.54,0.300,-0.06918,0.479,-0.001
2.55,0.400,-0.06918,0.480,-0.001
2.56,0.500,-0.06914,0.481,-0.001
2.55,0.600,-0.06914,0.479,-0.001
2.55,0.700,-0.06914,0.480,-0.001
2.54,0.800,-0.06910,0.477,-0.001
2.55,0.900,-0.06910,0.479,-0.001
2.53,1.000,-0.06910,0.476,-0.001
2.54,1.100,-0.06906,0.477,-0.001
2.55,1.200,-0.06906,0.479,-0.001
2.54,1.300,-0.06906,0.477,-0.001
2.54,1.400,-0.06902,0.479,-0.001
2.55,1.500,-0.06902,0.480,-0.001
2.55,1.600,-0.06897,0.480,-0.001
2.54,1.700,-0.06893,0.478,-0.001
2.55,1.800,-0.06893,0.480,-0.001
2.58,1.900,-0.06885,0.485,-0.001
2.59,2.000,-0.06877,0.487,-0.001
2.64,2.100,-0.06860,0.497,-0.001
2.70,2.200,-0.06843,0.509,-0.001
2.77,2.300,-0.06823,0.522,-0.001
2.82,2.400,-0.06806,0.530,-0.001
2.87,2.500,-0.06785,0.539,-0.001
2.90,2.600,-0.06769,0.546,-0.001
2.93,2.700,-0.06752,0.551,-0.001
2.94,2.800,-0.06735,0.553,-0.001
2.97,2.900,-0.06723,0.558,-0.001
2.99,3.000,-0.06706,0.563,-0.001
3.01,3.100,-0.06690,0.566,-0.001
3.02,3.200,-0.06677,0.569,-0.001
3.05,3.300,-0.06661,0.574,-0.001
3.07,3.400,-0.06648,0.578,-0.001
3.08,3.500,-0.06631,0.579,-0.001
3.10,3.600,-0.06619,0.583,-0.001
3.11,3.700,-0.06602,0.586,-0.001
3.13,3.800,-0.06590,0.589,-0.001
3.13,3.900,-0.06577,0.590,-0.001
3.15,4.000,-0.06565,0.593,-0.001
3.17,4.100,-0.06553,0.597,-0.001
3.18,4.200,-0.06536,0.598,-0.001
3.20,4.300,-0.06523,0.603,-0.001
3.22,4.400,-0.06511,0.606,-0.001
3.24,4.500,-0.06499,0.610,-0.001
3.25,4.600,-0.06482,0.611,-0.001
3.27,4.700,-0.06469,0.616,-0.001
3.29,4.800,-0.06457,0.619,-0.001
3.30,4.900,-0.06440,0.621,-0.001
3.31,5.000,-0.06428,0.622,-0.001
3.33,5.100,-0.06415,0.627,-0.001
3.35,5.200,-0.06399,0.629,-0.001
3.37,5.300,-0.06386,0.634,-0.001
3.38,5.400,-0.06370,0.636,-0.001
3.41,5.500,-0.06357,0.642,-0.001
3.40,5.600,-0.06341,0.640,-0.001
3.43,5.700,-0.06324,0.645,-0.001
3.45,5.800,-0.06307,0.648,-0.001
3.47,5.900,-0.06295,0.653,-0.001
3.49,6.000,-0.06278,0.656,-0.001
3.50,6.100,-0.06266,0.658,-0.001
3.50,6.200,-0.06249,0.658,-0.001
3.53,6.300,-0.06233,0.663,-0.001
3.56,6.400,-0.06216,0.669,-0.001
3.58,6.500,-0.06203,0.673,-0.001
3.60,6.600,-0.06187,0.677,-0.001
3.61,6.700,-0.06170,0.678,-0.001
3.63,6.800,-0.06149,0.684,-0.001
3.64,6.900,-0.06133,0.685,-0.001
3.68,7.000,-0.06112,0.693,-0.001
3.70,7.100,-0.06095,0.696,-0.001
3.74,7.200,-0.06075,0.703,-0.001
3.74,7.300,-0.06054,0.703,-0.001
3.78,7.400,-0.06033,0.711,-0.001
3.79,7.500,-0.06012,0.713,-0.001
3.80,7.600,-0.05992,0.715,-0.001
3.83,7.700,-0.05971,0.720,-0.001
3.86,7.800,-0.05950,0.725,-0.001
3.86,7.900,-0.05929,0.727,-0.001
3.90,8.000,-0.05908,0.733,-0.001
3.91,8.100,-0.05888,0.736,-0.001
3.94,8.200,-0.05867,0.741,-0.001
3.96,8.300,-0.05846,0.744,-0.001
3.98,8.400,-0.05825,0.749,-0.001
3.99,8.500,-0.05809,0.751,-0.001
4.01,8.600,-0.05788,0.754,-0.001
4.01,8.700,-0.05771,0.755,-0.001
4.03,8.800,-0.05755,0.758,-0.001
4.05,8.900,-0.05742,0.762,-0.001
4.07,9.000,-0.05726,0.765,-0.001
4.08,9.100,-0.05709,0.767,-0.001
4.07,9.200,-0.05696,0.766,-0.001
4.11,9.300,-0.05680,0.773,-0.001
4.11,9.400,-0.05667,0.774,-0.001
4.12,9.500,-0.05651,0.775,-0.001
4.14,9.600,-0.05638,0.779,-0.001
4.16,9.700,-0.05626,0.782,-0.001
4.17,9.800,-0.05609,0.785,-0.001
4.19,9.900,-0.05597,0.788,-0.001
4.20,10.000,-0.05584,0.790,-0.001
4.20,10.100,-0.05572,0.791,-0.001
4.23,10.200,-0.05555,0.796,-0.001
4.24,10.300,-0.05543,0.798,-0.001
4.26,10.400,-0.05530,0.801,-0.001
4.26,10.500,-0.05514,0.801,-0.001
4.29,10.600,-0.05501,0.807,-0.001
4.30,10.700,-0.05485,0.809,-0.001
4.32,10.800,-0.05468,0.812,-0.001
4.33,10.900,-0.05455,0.814,-0.001
4.35,11.000,-0.05439,0.819,-0.001
4.36,11.100,-0.05422,0.820,-0.001
4.38,11.200,-0.05410,0.824,-0.001
4.39,11.300,-0.05393,0.826,-0.001
4.41,11.400,-0.05377,0.829,-0.001
4.43,11.500,-0.05360,0.833,-0.001
4.44,11.600,-0.05347,0.835,-0.001
4.44,11.700,-0.05331,0.835,-0.001
4.47,11.800,-0.05314,0.841,-0.001
4.50,11.900,-0.05298,0.846,-0.001
4.50,12.000,-0.05281,0.847,-0.001
4.51,12.100,-0.05264,0.848,-0.001
4.53,12.200,-0.05248,0.853,-0.001
4.55,12.300,-0.05231,0.856,-0.001
4.55,12.400,-0.05214,0.856,-0.001
4.58,12.500,-0.05198,0.861,-0.001
4.60,12.600,-0.05177,0.866,-0.001
4.63,12.700,-0.05156,0.871,-0.001
4.63,12.800,-0.05140,0.872,-0.001
4.65,12.900,-0.05119,0.875,-0.001
4.67,13.000,-0.05098,0.879,-0.001
4.70,13.100,-0.05077,0.884,-0.001
4.70,13.200,-0.05052,0.885,-0.001
4.72,13.300,-0.05032,0.888,-0.001
4.74,13.400,-0.05011,0.892,-0.001
4.75,13.500,-0.04990,0.894,-0.001
4.75,13.600,-0.04969,0.894,-0.001
4.79,13.700,-0.04948,0.900,-0.001
4.79,13.800,-0.04932,0.901,-0.001
4.80,13.900,-0.04911,0.902,-0.001
4.81,14.000,-0.04890,0.904,-0.001
4.82,14.100,-0.04870,0.906,-0.001
4.83,14.200,-0.04853,0.909,-0.001
4.84,14.300,-0.04832,0.910,-0.001
4.82,14.400,-0.04816,0.907,-0.001
4.84,14.500,-0.04799,0.910,-0.001
4.84,14.600,-0.04786,0.910,-0.001
4.85,14.700,-0.04770,0.912,-0.001
4.86,14.800,-0.04753,0.915,-0.001
4.86,14.900,-0.04737,0.914,-0.001
4.86,15.000,-0.04724,0.914,-0.001
4.87,15.100,-0.04707,0.916,-0.001
4.88,15.200,-0.04695,0.919,-0.001
4.91,15.300,-0.04683,0.923,-0.001
4.89,15.400,-0.04666,0.920,-0.001
4.92,15.500,-0.04653,0.925,-0.001
4.92,15.600,-0.04641,0.925,-0.001
4.92,15.700,-0.04629,0.926,-0.001
4.92,15.800,-0.04612,0.926,-0.001
4.94,15.900,-0.04599,0.928,-0.001
4.94,16.000,-0.04583,0.930,-0.001
4.95,16.100,-0.04570,0.931,-0.001
4.96,16.200,-0.04554,0.933,-0.001
4.96,16.300,-0.04541,0.933,-0.001
4.98,16.400,-0.04525,0.937,-0.001
5.01,16.500,-0.04508,0.942,-0.001
5.00,16.600,-0.04496,0.940,-0.001
5.00,16.700,-0.04479,0.941,-0.001
5.00,16.800,-0.04462,0.941,-0.001
5.02,16.900,-0.04450,0.945,-0.001
5.01,17.000,-0.04433,0.942,-0.001
5.03,17.100,-0.04417,0.946,-0.001
5.05,17.200,-0.04400,0.949,-0.001
5.05,17.300,-0.04383,0.950,-0.001
5.06,17.400,-0.04371,0.951,-0.001
5.08,17.500,-0.04354,0.956,-0.001
5.07,17.600,-0.04338,0.954,-0.001
5.09,17.700,-0.04321,0.957,-0.001
5.10,17.800,-0.04304,0.958,-0.001
5.10,17.900,-0.04288,0.960,-0.001
5.10,18.000,-0.04271,0.960,-0.001
5.13,18.100,-0.04254,0.964,-0.001
5.16,18.200,-0.04234,0.971,-0.001
5.17,18.300,-0.04213,0.973,-0.001
5.19,18.400,-0.04196,0.976,-0.001
5.22,18.500,-0.04176,0.982,-0.001
5.22,18.600,-0.04155,0.983,-0.001
5.24,18.700,-0.04134,0.986,-0.001
5.26,18.800,-0.04113,0.989,-0.001
5.26,18.900,-0.04092,0.989,-0.001
5.28,19.000,-0.04072,0.994,-0.001
5.31,19.100,-0.04051,0.998,-0.001
5.31,19.200,-0.04030,0.999,-0.001
5.32,19.300,-0.04009,1.001,-0.001
5.34,19.400,-0.03989,1.004,-0.001
5.34,19.500,-0.03968,1.004,-0.001
5.34,19.600,-0.03947,1.005,-0.001
5.35,19.700,-0.03930,1.006,-0.001
5.36,19.800,-0.03910,1.007,-0.001
5.36,19.900,-0.03893,1.008,-0.001
5.37,20.000,-0.03876,1.011,-0.001
5.37,20.100,-0.03860,1.010,-0.001
5.39,20.200,-0.03843,1.014,-0.001
5.38,20.300,-0.03826,1.012,-0.001
5.40,20.400,-0.03814,1.015,-0.001
5.40,20.500,-0.03797,1.016,-0.001
5.41,20.600,-0.03781,1.017,-0.001
5.40,20.700,-0.03768,1.015,-0.001
5.41,20.800,-0.03756,1.017,-0.001
5.39,20.900,-0.03739,1.014,-0.001
5.40,21.000,-0.03727,1.015,-0.001
5.41,21.100,-0.03714,1.017,-0.001
5.42,21.200,-0.03698,1.019,-0.001
5.40,21.300,-0.03685,1.017,-0.001
5.43,21.400,-0.03673,1.021,-0.001
5.44,21.500,-0.03656,1.024,-0.001
5.44,21.600,-0.03644,1.024,-0.001
5.46,21.700,-0.03627,1.026,-0.001
5.46,21.800,-0.03615,1.027,-0.001
5.46,21.900,-0.03598,1.027,-0.001
5.47,22.000,-0.03585,1.028,-0.001
5.46,22.100,-0.03569,1.027,-0.001
5.47,22.200,-0.03556,1.029,-0.001
5.48,22.300,-0.03540,1.031,-0.001
5.49,22.400,-0.03527,1.033,-0.001
5.52,22.500,-0.03511,1.038,-0.001
5.51,22.600,-0.03494,1.036,-0.001
5.51,22.700,-0.03477,1.037,-0.001
5.52,22.800,-0.03465,1.038,-0.001
5.52,22.900,-0.03448,1.039,-0.001
5.53,23.000,-0.03432,1.039,-0.001
5.53,23.100,-0.03415,1.041,-0.001
5.53,23.200,-0.03403,1.039,-0.001
5.53,23.300,-0.03386,1.040,-0.001
5.53,23.400,-0.03369,1.041,-0.001
5.53,23.500,-0.03353,1.041,-0.001
5.55,23.600,-0.03336,1.044,-0.001
5.55,23.700,-0.03315,1.043,-0.001
5.55,23.800,-0.03299,1.043,-0.001
5.53,23.900,-0.03282,1.041,-0.001
5.54,24.000,-0.03261,1.043,-0.001
5.57,24.100,-0.03241,1.047,-0.001
5.57,24.200,-0.03220,1.048,-0.001
5.57,24.300,-0.03199,1.048,-0.001
5.56,24.400,-0.03178,1.046,-0.001
5.53,24.500,-0.03153,1.040,-0.001
5.52,24.600,-0.03132,1.038,-0.001
5.57,24.700,-0.03112,1.047,-0.001
5.56,24.800,-0.03087,1.046,-0.001
5.56,24.900,-0.03066,1.046,-0.001
5.59,25.000,-0.03045,1.051,-0.001
5.58,25.100,-0.03024,1.049,-0.001
5.60,25.200,-0.03008,1.053,-0.001
5.61,25.300,-0.02987,1.056,-0.001
5.60,25.400,-0.02970,1.053,-0.001
5.61,25.500,-0.02954,1.055,-0.001
5.59,25.600,-0.02937,1.052,-0.001
5.60,25.700,-0.02921,1.054,-0.001
5.62,25.800,-0.02904,1.057,-0.001
5.63,25.900,-0.02887,1.060,-0.001
5.63,26.000,-0.02875,1.059,-0.001
5.66,26.100,-0.02858,1.065,-0.001
5.65,26.200,-0.02846,1.064,-0.001
5.65,26.300,-0.02829,1.063,-0.001
5.68,26.400,-0.02817,1.068,-0.001
5.68,26.500,-0.02804,1.068,-0.001
5.69,26.600,-0.02788,1.069,-0.001
5.69,26.700,-0.02775,1.069,-0.001
5.69,26.800,-0.02763,1.070,-0.001
5.71,26.900,-0.02750,1.075,-0.001
5.72,27.000,-0.02734,1.076,-0.001
5.74,27.100,-0.02721,1.079,-0.001
5.73,27.200,-0.02709,1.078,-0.001
5.74,27.300,-0.02692,1.080,-0.001
5.75,27.400,-0.02680,1.081,-0.001
5.75,27.500,-0.02663,1.082,-0.001
5.77,27.600,-0.02650,1.085,-0.001
5.78,27.700,-0.02634,1.088,-0.001
5.79,27.800,-0.02621,1.090,-0.001
5.81,27.900,-0.02605,1.093,-0.001
5.82,28.000,-0.02588,1.094,-0.001
5.82,28.100,-0.02576,1.095,-0.001
5.84,28.200,-0.02559,1.099,-0.001
5.84,28.300,-0.02542,1.098,-0.001
5.85,28.400,-0.02530,1.100,0.000
5.86,28.500,-0.02513,1.101,0.000
5.87,28.600,-0.02497,1.105,0.000
5.90,28.700,-0.02484,1.110,0.000
5.90,28.800,-0.02468,1.110,0.000
5.90,28.900,-0.02451,1.110,0.000
5.91,29.000,-0.02434,1.112,0.000
5.92,29.100,-0.02418,1.113,0.000
5.92,29.200,-0.02401,1.114,0.000
5.93,29.300,-0.02384,1.116,0.000
5.96,29.400,-0.02368,1.120,0.000
5.96,29.500,-0.02351,1.121,0.000
5.98,29.600,-0.02330,1.125,0.000
5.98,29.700,-0.02310,1.125,0.000
5.98,29.800,-0.02293,1.125,0.000
5.99,29.900,-0.02272,1.127,0.000
6.00,30.000,-0.02247,1.130,0.000
6.01,30.100,-0.02227,1.130,0.000
6.03,30.200,-0.02206,1.134,0.000
6.05,30.300,-0.02185,1.137,0.000
6.03,30.400,-0.02164,1.135,0.000
6.04,30.500,-0.02143,1.137,0.000
6.06,30.600,-0.02123,1.139,0.000
6.04,30.700,-0.02102,1.137,0.000
6.06,30.800,-0.02085,1.140,0.000
6.06,30.900,-0.02065,1.140,0.000
6.07,31.000,-0.02044,1.142,0.000
6.08,31.100,-0.02027,1.144,0.000
6.08,31.200,-0.02006,1.144,0.000
6.07,31.300,-0.01990,1.142,0.000
6.09,31.400,-0.01973,1.145,0.000
6.09,31.500,-0.01961,1.145,0.000
6.10,31.600,-0.01944,1.147,0.000
6.10,31.700,-0.01927,1.148,0.000
6.11,31.800,-0.01915,1.149,0.000
6.12,31.900,-0.01898,1.150,0.000
6.12,32.000,-0.01886,1.151,0.000
6.13,32.100,-0.01869,1.153,0.000
6.14,32.200,-0.01857,1.154,0.000
6.14,32.300,-0.01844,1.155,0.000
6.13,32.400,-0.01828,1.154,0.000
6.16,32.500,-0.01815,1.158,0.000
6.15,32.600,-0.01803,1.158,0.000
6.17,32.700,-0.01786,1.161,0.000
6.17,32.800,-0.01774,1.160,0.000
6.20,32.900,-0.01761,1.167,0.000
6.22,33.000,-0.01745,1.170,0.000
6.23,33.100,-0.01732,1.172,0.000
6.24,33.200,-0.01720,1.173,0.000
6.26,33.300,-0.01703,1.177,0.000
6.28,33.400,-0.01686,1.182,0.000
6.30,33.500,-0.01674,1.186,0.000
6.32,33.600,-0.01657,1.188,0.000
6.34,33.700,-0.01645,1.193,0.000
6.38,33.800,-0.01628,1.200,0.000
6.40,33.900,-0.01612,1.204,0.000
6.44,34.000,-0.01599,1.212,0.000
6.45,34.100,-0.01582,1.213,0.000
6.47,34.200,-0.01566,1.216,0.000
6.49,34.300,-0.01553,1.221,0.000
6.51,34.400,-0.01537,1.225,0.000
6.54,34.500,-0.01520,1.230,0.000
6.56,34.600,-0.01504,1.235,0.000
6.60,34.700,-0.01491,1.241,0.000
6.62,34.800,-0.01474,1.245,0.000
6.64,34.900,-0.01454,1.249,0.000
6.67,35.000,-0.01437,1.255,0.000
6.69,35.100,-0.01420,1.259,0.000
6.72,35.200,-0.01404,1.264,0.000
6.76,35.300,-0.01383,1.271,0.000
6.77,35.400,-0.01366,1.273,0.000
6.80,35.500,-0.01346,1.280,0.000
6.86,35.600,-0.01329,1.290,0.000
6.89,35.700,-0.01308,1.295,0.000
6.90,35.800,-0.01287,1.299,0.000
6.94,35.900,-0.01267,1.306,0.000
6.97,36.000,-0.01246,1.312,0.000
7.00,36.100,-0.01225,1.316,0.000
7.02,36.200,-0.01204,1.321,0.000
7.05,36.300,-0.01184,1.327,0.000
7.07,36.400,-0.01167,1.331,0.000
7.10,36.500,-0.01146,1.336,0.000
7.15,36.600,-0.01125,1.345,0.000
7.16,36.700,-0.01105,1.347,0.000
7.18,36.800,-0.01088,1.351,0.000
7.22,36.900,-0.01071,1.357,0.000
7.24,37.000,-0.01055,1.362,0.000
7.26,37.100,-0.01034,1.366,0.000
7.30,37.200,-0.01021,1.372,0.000
7.31,37.300,-0.01005,1.375,0.000
7.34,37.400,-0.00988,1.380,0.000
7.35,37.500,-0.00972,1.383,0.000
7.39,37.600,-0.00959,1.389,0.000
7.40,37.700,-0.00942,1.392,0.000
7.42,37.800,-0.00930,1.395,0.000
7.46,37.900,-0.00918,1.403,0.000
7.46,38.000,-0.00901,1.404,0.000
7.48,38.100,-0.00888,1.408,0.000
7.51,38.200,-0.00876,1.412,0.000
7.52,38.300,-0.00864,1.414,0.000
7.54,38.400,-0.00847,1.418,0.000
7.56,38.500,-0.00834,1.422,0.000
7.59,38.600,-0.00822,1.428,0.000
7.61,38.700,-0.00810,1.431,0.000
7.63,38.800,-0.00793,1.436,0.000
7.65,38.900,-0.00780,1.440,0.000
7.69,39.000,-0.00764,1.446,0.000
7.72,39.100,-0.00751,1.451,0.000
7.74,39.200,-0.00735,1.456,0.000
7.77,39.300,-0.00722,1.462,0.000
7.80,39.400,-0.00706,1.468,0.000
7.83,39.500,-0.00693,1.473,0.000
7.84,39.600,-0.00677,1.475,0.000
7.85,39.700,-0.00660,1.477,0.000
7.89,39.800,-0.00643,1.484,0.000
7.91,39.900,-0.00631,1.488,0.000
7.92,40.000,-0.00614,1.490,0.000
7.96,40.100,-0.00602,1.497,0.000
7.99,40.200,-0.00585,1.503,0.000
8.02,40.300,-0.00568,1.509,0.000
8.06,40.400,-0.00552,1.515,0.000
8.08,40.500,-0.00535,1.519,0.000
8.11,40.600,-0.00519,1.525,0.000
8.12,40.700,-0.00502,1.528,0.000
8.16,40.800,-0.00490,1.535,0.000
8.19,40.900,-0.00469,1.541,0.000
8.22,41.000,-0.00452,1.546,0.000
8.26,41.100,-0.00436,1.553,0.000
8.30,41.200,-0.00415,1.562,0.000
8.33,41.300,-0.00394,1.568,0.000
8.36,41.400,-0.00373,1.573,0.000
8.40,41.500,-0.00352,1.581,0.000
8.44,41.600,-0.00332,1.588,0.000
8.47,41.700,-0.00311,1.593,0.000
8.52,41.800,-0.00290,1.603,0.000
8.55,41.900,-0.00269,1.608,0.000
8.58,42.000,-0.00249,1.614,0.000
8.61,42.100,-0.00228,1.619,0.000
8.64,42.200,-0.00207,1.625,0.000
8.69,42.300,-0.00186,1.634,0.000
8.73,42.400,-0.00165,1.642,0.000
8.75,42.500,-0.00149,1.646,0.000
8.78,42.600,-0.00128,1.652,0.000
8.82,42.700,-0.00111,1.659,0.000
8.83,42.800,-0.00095,1.661,0.000
8.86,42.900,-0.00078,1.667,0.000
8.89,43.000,-0.00062,1.672,0.000
8.90,43.100,-0.00045,1.675,0.000
8.92,43.200,-0.00032,1.678,0.000
8.95,43.300,-0.00016,1.683,0.000
8.98,43.400,-0.00003,1.688,0.000
8.99,43.500,0.00009,1.691,0.000
9.02,43.600,0.00026,1.697,0.000
9.04,43.700,0.00038,1.701,0.000
9.07,43.800,0.00055,1.707,0.000
9.09,43.900,0.00067,1.711,0.000
9.12,44.000,0.00080,1.715,0.000
9.13,44.100,0.00092,1.717,0.000
9.17,44.200,0.00109,1.724,0.000
9.19,44.300,0.00121,1.729,0.000
9.22,44.400,0.00138,1.734,0.000
9.23,44.500,0.00150,1.736,0.000
9.28,44.600,0.00163,1.745,0.000
9.31,44.700,0.00180,1.751,0.000
9.33,44.800,0.00192,1.754,0.000
9.37,44.900,0.00209,1.762,0.000
9.38,45.000,0.00225,1.764,0.000
9.40,45.100,0.00238,1.769,0.000
9.45,45.200,0.00254,1.777,0.000
9.47,45.300,0.00271,1.782,0.000
9.48,45.400,0.00283,1.784,0.000
9.51,45.500,0.00300,1.790,0.000
9.55,45.600,0.00317,1.796,0.000
9.56,45.700,0.00333,1.799,0.000
9.59,45.800,0.00346,1.804,0.000
9.63,45.900,0.00362,1.811,0.000
9.66,46.000,0.00379,1.817,0.000
9.68,46.100,0.00396,1.821,0.000
9.71,46.200,0.00412,1.826,0.000
9.76,46.300,0.00429,1.835,0.000
9.77,46.400,0.00445,1.838,0.000
9.81,46.500,0.00462,1.845,0.000
9.85,46.600,0.00479,1.853,0.000
9.88,46.700,0.00499,1.859,0.000
9.93,46.800,0.00520,1.867,0.000
9.97,46.900,0.00537,1.875,0.000
10.02,47.000,0.00558,1.884,0.000
10.06,47.100,0.00578,1.893,0.000
10.10,47.200,0.00603,1.901,0.000
10.15,47.300,0.00624,1.910,0.000
10.19,47.400,0.00645,1.917,0.000
10.24,47.500,0.00670,1.926,0.000
10.27,47.600,0.00691,1.932,0.000
10.31,47.700,0.00711,1.939,0.000
10.34,47.800,0.00732,1.945,0.000
10.39,47.900,0.00753,1.954,0.000
10.44,48.000,0.00774,1.964,0.000
10.46,48.100,0.00795,1.967,0.000
10.50,48.200,0.00811,1.975,0.000
10.52,48.300,0.00832,1.980,0.000
10.55,48.400,0.00849,1.985,0.000
10.58,48.500,0.00865,1.990,0.000
10.60,48.600,0.00882,1.994,0.000
10.65,48.700,0.00898,2.003,0.000
10.67,48.800,0.00911,2.008,0.000
10.71,48.900,0.00928,2.015,0.000
10.74,49.000,0.00944,2.020,0.000
10.76,49.100,0.00957,2.023,0.000
10.79,49.200,0.00973,2.030,0.000
10.80,49.300,0.00986,2.032,0.000
10.83,49.400,0.00998,2.036,0.000
10.85,49.500,0.01011,2.040,0.000
10.88,49.600,0.01027,2.046,0.000
10.89,49.700,0.01040,2.049,0.000
10.93,49.800,0.01052,2.056,0.000
10.97,49.900,0.01069,2.063,0.000
10.98,50.000,0.01081,2.066,0.000
11.01,50.100,0.01098,2.071,0.000
11.06,50.200,0.01110,2.081,0.000
11.09,50.300,0.01127,2.087,0.000
11.12,50.400,0.01139,2.092,0.000
11.15,50.500,0.01156,2.097,0.000
11.18,50.600,0.01173,2.103,0.000
11.21,50.700,0.01185,2.109,0.000
11.25,50.800,0.01202,2.116,0.000
11.28,50.900,0.01218,2.121,0.000
11.31,51.000,0.01231,2.128,0.000
11.33,51.100,0.01247,2.131,0.000
11.37,51.200,0.01264,2.139,0.000
11.40,51.300,0.01281,2.144,0.000
11.43,51.400,0.01293,2.150,0.000
11.47,51.500,0.01310,2.158,0.000
11.50,51.600,0.01326,2.164,0.000
11.52,51.700,0.01343,2.167,0.000
11.55,51.800,0.01360,2.173,0.000
11.60,51.900,0.01372,2.182,0.000
11.64,52.000,0.01393,2.189,0.000
11.65,52.100,0.01410,2.192,0.000
11.70,52.200,0.01426,2.201,0.000
11.74,52.300,0.01447,2.208,0.000
11.80,52.400,0.01464,2.219,0.000
11.84,52.500,0.01484,2.228,0.000
11.90,52.600,0.01505,2.239,0.000
11.94,52.700,0.01526,2.245,0.000
11.97,52.800,0.01547,2.252,0.000
12.02,52.900,0.01567,2.261,0.000
12.05,53.000,0.01588,2.268,0.000
12.10,53.100,0.01609,2.276,0.000
12.14,53.200,0.01630,2.283,0.000
12.19,53.300,0.01646,2.293,0.000
12.23,53.400,0.01667,2.300,0.000
12.26,53.500,0.01688,2.306,0.000
12.29,53.600,0.01705,2.312,0.000
12.34,53.700,0.01725,2.321,0.000
12.36,53.800,0.01742,2.326,0.000
12.41,53.900,0.01763,2.335,0.000
12.43,54.000,0.01779,2.338,0.000
12.48,54.100,0.01796,2.347,0.000
12.52,54.200,0.01813,2.355,0.000
12.53,54.300,0.01829,2.358,0.000
12.58,54.400,0.01842,2.365,0.000
12.60,54.500,0.01858,2.370,0.000
12.64,54.600,0.01875,2.378,0.000
12.67,54.700,0.01887,2.383,0.000
12.69,54.800,0.01900,2.387,0.000
12.71,54.900,0.01917,2.390,0.000
12.75,55.000,0.01929,2.398,0.000
12.78,55.100,0.01946,2.403,0.000
12.80,55.200,0.01958,2.409,0.000
12.83,55.300,0.01971,2.414,0.000
12.86,55.400,0.01983,2.418,0.000
12.88,55.500,0.02000,2.423,0.000
12.91,55.600,0.02012,2.429,0.000
12.94,55.700,0.02025,2.434,0.000
12.97,55.800,0.02037,2.440,0.000
13.00,55.900,0.02054,2.446,0.000
13.04,56.000,0.02066,2.452,0.000
13.10,56.100,0.02083,2.464,0.000
13.11,56.200,0.02095,2.466,0.000
13.14,56.300,0.02108,2.472,0.000
13.18,56.400,0.02124,2.478,0.000
13.20,56.500,0.02141,2.484,0.000
13.24,56.600,0.02153,2.491,0.000
13.28,56.700,0.02170,2.498,0.000
13.31,56.800,0.02187,2.504,0.000
13.36,56.900,0.02199,2.513,0.000
13.39,57.000,0.02216,2.518,0.000
13.43,57.100,0.02228,2.526,0.000
13.45,57.200,0.02245,2.530,0.000
13.51,57.300,0.02261,2.541,0.000
13.53,57.400,0.02278,2.545,0.000
13.57,57.500,0.02291,2.553,0.000
13.61,57.600,0.02307,2.561,0.000
13.67,57.700,0.02324,2.571,0.000
13.70,57.800,0.02340,2.578,0.000
13.74,57.900,0.02357,2.584,0.000
13.79,58.000,0.02378,2.593,0.000
13.82,58.100,0.02394,2.600,0.000
13.87,58.200,0.02415,2.608,0.000
13.93,58.300,0.02436,2.621,0.000
13.97,58.400,0.02457,2.629,0.000
14.03,58.500,0.02478,2.640,0.000
14.08,58.600,0.02498,2.649,0.000
14.14,58.700,0.02519,2.660,0.000
14.19,58.800,0.02540,2.670,0.000
14.25,58.900,0.02561,2.680,0.001
14.28,59.000,0.02581,2.687,0.001
14.32,59.100,0.02602,2.693,0.001
14.38,59.200,0.02623,2.704,0.001
14.41,59.300,0.02640,2.711,0.001
14.45,59.400,0.02660,2.719,0.001
14.49,59.500,0.02677,2.726,0.001
14.53,59.600,0.02698,2.734,0.001
14.57,59.700,0.02714,2.741,0.001
14.60,59.800,0.02731,2.747,0.001
14.64,59.900,0.02748,2.754,0.001
14.66,60.000,0.02764,2.758,0.001
14.70,60.100,0.02781,2.765,0.001
14.75,60.200,0.02793,2.774,0.001
14.79,60.300,0.02810,2.782,0.001
14.82,60.400,0.02822,2.787,0.001
14.84,60.500,0.02835,2.792,0.001
14.87,60.600,0.02852,2.797,0.001
14.92,60.700,0.02864,2.807,0.001
14.94,60.800,0.02876,2.811,0.001
14.98,60.900,0.02889,2.817,0.001
15.02,61.000,0.02906,2.825,0.001
15.04,61.100,0.02918,2.829,0.001
15.07,61.200,0.02931,2.835,0.001
15.10,61.300,0.02943,2.841,0.001
15.14,61.400,0.02955,2.847,0.001
15.18,61.500,0.02972,2.855,0.001
15.22,61.600,0.02985,2.863,0.001
15.26,61.700,0.02997,2.870,0.001
15.30,61.800,0.03014,2.877,0.001
15.34,61.900,0.03026,2.886,0.001
15.37,62.000,0.03043,2.891,0.001
15.42,62.100,0.03055,2.900,0.001
15.46,62.200,0.03072,2.909,0.001
15.49,62.300,0.03088,2.913,0.001
15.54,62.400,0.03101,2.922,0.001
15.58,62.500,0.03118,2.930,0.001
15.62,62.600,0.03134,2.939,0.001
15.67,62.700,0.03147,2.947,0.001
15.71,62.800,0.03163,2.955,0.001
15.74,62.900,0.03180,2.961,0.001
15.78,63.000,0.03196,2.969,0.001
15.83,63.100,0.03209,2.977,0.001
15.87,63.200,0.03226,2.985,0.001
15.91,63.300,0.03242,2.992,0.001
15.94,63.400,0.03259,2.999,0.001
15.99,63.500,0.03275,3.008,0.001
16.03,63.600,0.03292,3.016,0.001
16.09,63.700,0.03309,3.027,0.001
16.14,63.800,0.03329,3.036,0.001
16.18,63.900,0.03346,3.044,0.001
16.25,64.000,0.03363,3.058,0.001
16.31,64.100,0.03383,3.068,0.001
16.35,64.200,0.03404,3.076,0.001
16.42,64.300,0.03425,3.089,0.001
16.46,64.400,0.03446,3.097,0.001
16.53,64.500,0.03467,3.108,0.001
16.59,64.600,0.03487,3.120,0.001
16.64,64.700,0.03508,3.130,0.001
16.69,64.800,0.03529,3.140,0.001
16.75,64.900,0.03550,3.151,0.001
16.81,65.000,0.03570,3.161,0.001
16.85,65.100,0.03591,3.170,0.001
16.89,65.200,0.03608,3.178,0.001
16.95,65.300,0.03629,3.189,0.001
17.01,65.400,0.03645,3.200,0.001
17.04,65.500,0.03662,3.206,0.001
17.07,65.600,0.03679,3.211,0.001
17.13,65.700,0.03695,3.223,0.001
17.18,65.800,0.03712,3.231,0.001
17.21,65.900,0.03728,3.237,0.001
17.24,66.000,0.03745,3.244,0.001
17.29,66.100,0.03757,3.252,0.001
17.32,66.200,0.03774,3.258,0.001
17.36,66.300,0.03787,3.265,0.001
17.38,66.400,0.03803,3.270,0.001
17.43,66.500,0.03816,3.279,0.001
17.45,66.600,0.03828,3.282,0.001
17.48,66.700,0.03841,3.289,0.001
17.53,66.800,0.03853,3.298,0.001
17.58,66.900,0.03866,3.306,0.001
17.61,67.000,0.03882,3.312,0.001
17.65,67.100,0.03895,3.320,0.001
17.69,67.200,0.03907,3.327,0.001
17.74,67.300,0.03924,3.336,0.001
17.78,67.400,0.03936,3.344,0.001
17.81,67.500,0.03949,3.351,0.001
17.86,67.600,0.03965,3.359,0.001
17.90,67.700,0.03978,3.367,0.001
17.93,67.800,0.03994,3.373,0.001
17.99,67.900,0.04011,3.384,0.001
18.01,68.000,0.04023,3.388,0.001
18.06,68.100,0.04040,3.398,0.001
18.12,68.200,0.04057,3.408,0.001
18.17,68.300,0.04069,3.418,0.001
18.19,68.400,0.04086,3.421,0.001
18.24,68.500,0.04102,3.432,0.001
18.29,68.600,0.04115,3.440,0.001
18.34,68.700,0.04131,3.449,0.001
18.37,68.800,0.04148,3.455,0.001
18.44,68.900,0.04165,3.469,0.001
18.46,69.000,0.04177,3.473,0.001
18.53,69.100,0.04194,3.485,0.001
18.56,69.200,0.04210,3.492,0.001
18.63,69.300,0.04231,3.504,0.001
18.67,69.400,0.04248,3.512,0.001
18.73,69.500,0.04264,3.522,0.001
18.77,69.600,0.04281,3.530,0.001
18.85,69.700,0.04302,3.546,0.001
18.89,69.800,0.04323,3.554,0.001
18.97,69.900,0.04343,3.567,0.001
19.03,70.000,0.04364,3.580,0.001
19.09,70.100,0.04385,3.592,0.001
19.16,70.200,0.04406,3.604,0.001
19.22,70.300,0.04427,3.616,0.001
19.27,70.400,0.04447,3.625,0.001
19.33,70.500,0.04468,3.636,0.001
19.39,70.600,0.04489,3.647,0.001
19.44,70.700,0.04510,3.658,0.001
19.50,70.800,0.04530,3.668,0.001
19.55,70.900,0.04547,3.677,0.001
19.61,71.000,0.04568,3.688,0.001
19.66,71.100,0.04584,3.698,0.001
19.70,71.200,0.04605,3.706,0.001
19.74,71.300,0.04622,3.713,0.001
19.78,71.400,0.04634,3.721,0.001
19.83,71.500,0.04651,3.729,0.001
19.86,71.600,0.04668,3.736,0.001
19.92,71.700,0.04684,3.747,0.001
19.97,71.800,0.04697,3.757,0.001
20.00,71.900,0.04713,3.762,0.001
20.05,72.000,0.04726,3.771,0.001
20.08,72.100,0.04742,3.777,0.001
20.12,72.200,0.04755,3.785,0.001
20.16,72.300,0.04767,3.793,0.001
20.21,72.400,0.04784,3.802,0.001
20.25,72.500,0.04796,3.809,0.001
20.29,72.600,0.04809,3.817,0.001
20.33,72.700,0.04821,3.824,0.001
20.34,72.800,0.04834,3.827,0.001
20.39,72.900,0.04850,3.836,0.001
20.44,73.000,0.04863,3.844,0.001
20.50,73.100,0.04875,3.856,0.001
20.52,73.200,0.04892,3.859,0.001
20.58,73.300,0.04904,3.871,0.001
20.61,73.400,0.04921,3.877,0.001
20.65,73.500,0.04934,3.884,0.001
20.70,73.600,0.04946,3.893,0.001
20.75,73.700,0.04963,3.903,0.001
20.78,73.800,0.04979,3.908,0.001
20.83,73.900,0.04992,3.918,0.001
20.87,74.000,0.05008,3.926,0.001
20.93,74.100,0.05021,3.937,0.001
20.97,74.200,0.05037,3.946,0.001
21.03,74.300,0.05054,3.955,0.001
21.07,74.400,0.05066,3.964,0.001
21.11,74.500,0.05083,3.971,0.001
21.17,74.600,0.05100,3.982,0.001
21.23,74.700,0.05116,3.994,0.001
21.27,74.800,0.05133,4.001,0.001
21.31,74.900,0.05150,4.009,0.001
21.38,75.000,0.05166,4.022,0.001
21.42,75.100,0.05183,4.029,0.001
21.48,75.200,0.05199,4.041,0.001
21.55,75.300,0.05220,4.053,0.001
21.62,75.400,0.05237,4.067,0.001
21.68,75.500,0.05258,4.078,0.001
21.75,75.600,0.05278,4.091,0.001
21.83,75.700,0.05299,4.106,0.001
21.91,75.800,0.05320,4.122,0.001
21.97,75.900,0.05345,4.133,0.001
22.05,76.000,0.05366,4.147,0.001
22.11,76.100,0.05386,4.160,0.001
22.16,76.200,0.05407,4.168,0.001
22.23,76.300,0.05428,4.182,0.001
22.29,76.400,0.05449,4.193,0.001
22.35,76.500,0.05470,4.205,0.001
22.42,76.600,0.05486,4.217,0.001
22.48,76.700,0.05507,4.228,0.001
22.52,76.800,0.05524,4.236,0.001
22.57,76.900,0.05544,4.245,0.001
22.62,77.000,0.05561,4.254,0.001
22.67,77.100,0.05573,4.264,0.001
22.71,77.200,0.05590,4.271,0.001
22.76,77.300,0.05607,4.282,0.001
22.78,77.400,0.05623,4.285,0.001
22.83,77.500,0.05636,4.294,0.001
22.88,77.600,0.05652,4.304,0.001
22.91,77.700,0.05665,4.309,0.001
22.95,77.800,0.05677,4.318,0.001
23.00,77.900,0.05694,4.326,0.001
23.03,78.000,0.05706,4.332,0.001
23.09,78.100,0.05719,4.344,0.001
23.13,78.200,0.05736,4.350,0.001
23.17,78.300,0.05748,4.358,0.001
23.20,78.400,0.05760,4.365,0.001
23.24,78.500,0.05773,4.372,0.001
23.30,78.600,0.05790,4.383,0.001
23.34,78.700,0.05802,4.390,0.001
23.38,78.800,0.05819,4.398,0.001
23.44,78.900,0.05831,4.410,0.001
23.47,79.000,0.05848,4.415,0.001
23.52,79.100,0.05860,4.425,0.001
23.58,79.200,0.05877,4.435,0.001
23.63,79.300,0.05889,4.445,0.001
23.68,79.400,0.05906,4.455,0.001
23.74,79.500,0.05923,4.466,0.001
23.79,79.600,0.05935,4.476,0.001
23.84,79.700,0.05952,4.485,0.001
23.89,79.800,0.05968,4.493,0.001
23.94,79.900,0.05985,4.504,0.001
24.01,80.000,0.06001,4.516,0.001
24.06,80.100,0.06018,4.525,0.001
24.11,80.200,0.06031,4.536,0.001
24.16,80.300,0.06047,4.545,0.001
24.22,80.400,0.06064,4.556,0.001
24.27,80.500,0.06080,4.566,0.001
24.33,80.600,0.06097,4.577,0.001
24.38,80.700,0.06114,4.586,0.001
24.45,80.800,0.06134,4.598,0.001
24.52,80.900,0.06151,4.612,0.001
24.60,81.000,0.06172,4.627,0.001
24.64,81.100,0.06188,4.636,0.001
24.73,81.200,0.06209,4.652,0.001
24.82,81.300,0.06230,4.669,0.001
24.88,81.400,0.06251,4.680,0.001
24.97,81.500,0.06276,4.697,0.001
25.05,81.600,0.06297,4.713,0.001
25.13,81.700,0.06321,4.727,0.001
25.19,81.800,0.06342,4.739,0.001
25.27,81.900,0.06363,4.754,0.001
25.34,82.000,0.06384,4.767,0.001
25.40,82.100,0.06405,4.778,0.001
25.46,82.200,0.06425,4.790,0.001
25.53,82.300,0.06442,4.802,0.001
25.59,82.400,0.06463,4.813,0.001
25.65,82.500,0.06479,4.825,0.001
25.71,82.600,0.06496,4.835,0.001
25.76,82.700,0.06517,4.845,0.001
25.81,82.800,0.06529,4.855,0.001
25.87,82.900,0.06546,4.866,0.001
25.91,83.000,0.06562,4.874,0.001
25.95,83.100,0.06579,4.882,0.001
26.01,83.200,0.06596,4.893,0.001
26.07,83.300,0.06608,4.904,0.001
26.12,83.400,0.06625,4.913,0.001
26.17,83.500,0.06637,4.922,0.001
26.21,83.600,0.06654,4.931,0.001
26.24,83.700,0.06666,4.936,0.001
26.29,83.800,0.06679,4.945,0.001
26.35,83.900,0.06695,4.956,0.001
26.39,84.000,0.06708,4.964,0.001
26.43,84.100,0.06720,4.972,0.001
26.48,84.200,0.06737,4.981,0.001
26.55,84.300,0.06749,4.993,0.001
26.59,84.400,0.06762,5.002,0.001
26.65,84.500,0.06779,5.013,0.001
26.71,84.600,0.06795,5.025,0.001
26.76,84.700,0.06808,5.033,0.001
26.83,84.800,0.06824,5.047,0.001
26.89,84.900,0.06837,5.058,0.001
26.93,85.000,0.06853,5.067,0.001
27.01,85.100,0.06870,5.081,0.001
27.07,85.200,0.06887,5.092,0.001
27.12,85.300,0.06899,5.101,0.001
27.19,85.400,0.06916,5.114,0.001
27.26,85.500,0.06932,5.127,0.001
27.30,85.600,0.06949,5.135,0.001
27.36,85.700,0.06966,5.147,0.001
27.43,85.800,0.06982,5.159,0.001
27.49,85.900,0.06999,5.172,0.001
27.56,86.000,0.07015,5.183,0.001
27.62,86.100,0.07032,5.196,0.001
27.69,86.200,0.07049,5.209,0.001
27.76,86.300,0.07065,5.222,0.001
27.82,86.400,0.07082,5.233,0.001
27.89,86.500,0.07103,5.247,0.001
27.98,86.600,0.07119,5.264,0.001
28.08,86.700,0.07140,5.281,0.001
28.15,86.800,0.07161,5.296,0.001
28.24,86.900,0.07182,5.312,0.001
28.30,87.000,0.07202,5.324,0.001
28.38,87.100,0.07223,5.339,0.001
28.48,87.200,0.07244,5.357,0.001
28.56,87.300,0.07265,5.372,0.001
28.63,87.400,0.07286,5.386,0.001
28.73,87.500,0.07306,5.404,0.001
28.79,87.600,0.07327,5.415,0.001
28.88,87.700,0.07348,5.432,0.001
28.95,87.800,0.07369,5.445,0.001
29.02,87.900,0.07385,5.458,0.001
29.08,88.000,0.07406,5.471,0.001
29.17,88.100,0.07423,5.487,0.001
29.23,88.200,0.07439,5.499,0.001
29.30,88.300,0.07460,5.511,0.001
29.36,88.400,0.07477,5.523,0.001
29.41,88.500,0.07489,5.533,0.001
29.48,88.600,0.07506,5.545,0.001
29.55,88.700,0.07522,5.558,0.001
29.61,88.800,0.07539,5.571,0.001
29.66,88.900,0.07552,5.580,0.001
29.72,89.000,0.07568,5.591,0.001
29.78,89.100,0.07581,5.601,0.001
29.81,89.200,0.07597,5.608,0.001
29.88,89.300,0.07610,5.621,0.001
29.93,89.400,0.07622,5.630,0.002
29.98,89.500,0.07639,5.640,0.002
30.04,89.600,0.07651,5.651,0.002
30.09,89.700,0.07664,5.661,0.002
30.17,89.800,0.07676,5.674,0.002
30.21,89.900,0.07693,5.684,0.002
30.28,90.000,0.07705,5.697,0.002
30.34,90.100,0.07722,5.708,0.002
30.41,90.200,0.07734,5.720,0.002
30.46,90.300,0.07747,5.730,0.002
30.54,90.400,0.07763,5.745,0.002
30.61,90.500,0.07780,5.757,0.002
30.68,90.600,0.07793,5.771,0.002
30.75,90.700,0.07809,5.785,0.002
30.83,90.800,0.07826,5.799,0.002
30.89,90.900,0.07838,5.810,0.002
30.96,91.000,0.07855,5.823,0.002
31.02,91.100,0.07871,5.835,0.002
31.10,91.200,0.07888,5.850,0.002
31.16,91.300,0.07901,5.861,0.002
31.23,91.400,0.07917,5.875,0.002
31.29,91.500,0.07934,5.887,0.002
31.37,91.600,0.07950,5.901,0.002
31.44,91.700,0.07967,5.914,0.002
31.51,91.800,0.07984,5.927,0.002
31.57,91.900,0.08000,5.939,0.002
31.66,92.000,0.08017,5.956,0.002
31.72,92.100,0.08034,5.967,0.002
31.79,92.200,0.08054,5.981,0.002
31.89,92.300,0.08075,5.999,0.002
31.99,92.400,0.08092,6.018,0.002
29.86,92.500,0.08113,5.618,0.002
12.75,92.600,0.08133,2.398,0.002
11.44,92.700,0.08154,2.152,0.002
11.40,92.800,0.08179,2.145,0.002
11.39,92.900,0.08200,2.142,0.002
11.36,93.000,0.08225,2.136,0.002
11.31,93.100,0.08246,2.128,0.002
11.29,93.200,0.08266,2.124,0.002
11.29,93.300,0.08287,2.123,0.002
11.29,93.400,0.08308,2.123,0.002
11.28,93.500,0.08329,2.122,0.002
11.27,93.600,0.08349,2.120,0.002
11.26,93.700,0.08366,2.118,0.002
11.26,93.800,0.08383,2.118,0.002
11.26,93.900,0.08399,2.119,0.002
11.26,94.000,0.08420,2.119,0.002
11.28,94.100,0.08433,2.121,0.002
11.28,94.200,0.08449,2.122,0.002
11.28,94.300,0.08466,2.122,0.002
11.29,94.400,0.08482,2.123,0.002
11.30,94.500,0.08495,2.125,0.002
11.30,94.600,0.08511,2.125,0.002
11.32,94.700,0.08524,2.129,0.002
11.32,94.800,0.08536,2.130,0.002
11.34,94.900,0.08553,2.132,0.002
11.33,95.000,0.08565,2.131,0.002
11.33,95.100,0.08578,2.132,0.002
11.35,95.200,0.08590,2.135,0.002
11.36,95.300,0.08607,2.137,0.002
11.37,95.400,0.08620,2.139,0.002
11.38,95.500,0.08632,2.141,0.002
11.40,95.600,0.08649,2.145,0.002
11.39,95.700,0.08661,2.143,0.002
11.42,95.800,0.08678,2.148,0.002
11.43,95.900,0.08690,2.150,0.002
11.44,96.000,0.08707,2.152,0.002
11.46,96.100,0.08723,2.156,0.002
11.45,96.200,0.08736,2.153,0.002
11.46,96.300,0.08752,2.156,0.002
11.48,96.400,0.08769,2.160,0.002
11.49,96.500,0.08786,2.162,0.002
11.49,96.600,0.08798,2.162,0.002
11.50,96.700,0.08815,2.163,0.002
11.51,96.800,0.08831,2.165,0.002
11.52,96.900,0.08848,2.167,0.002
11.51,97.000,0.08865,2.166,0.002
11.52,97.100,0.08881,2.166,0.002
11.51,97.200,0.08898,2.166,0.002
11.51,97.300,0.08915,2.165,0.002
11.52,97.400,0.08931,2.166,0.002
11.52,97.500,0.08948,2.166,0.002
11.51,97.600,0.08964,2.165,0.002
11.51,97.700,0.08981,2.165,0.002
11.51,97.800,0.09002,2.165,0.002
11.52,97.900,0.09018,2.166,0.002
11.51,98.000,0.09039,2.165,0.002
11.52,98.100,0.09060,2.167,0.002
11.54,98.200,0.09081,2.171,0.002
11.56,98.300,0.09106,2.174,0.002
11.57,98.400,0.09126,2.176,0.002
11.57,98.500,0.09151,2.177,0.002
11.60,98.600,0.09172,2.182,0.002
11.61,98.700,0.09197,2.183,0.002
11.63,98.800,0.09218,2.188,0.002
11.65,98.900,0.09239,2.191,0.002
11.66,99.000,0.09259,2.194,0.002
11.68,99.100,0.09280,2.198,0.002
11.70,99.200,0.09301,2.200,0.002
11.73,99.300,0.09318,2.207,0.002
11.73,99.400,0.09334,2.207,0.002
11.75,99.500,0.09355,2.210,0.002
11.77,99.600,0.09372,2.214,0.002
11.79,99.700,0.09388,2.218,0.002
11.80,99.800,0.09401,2.220,0.002
11.83,99.900,0.09417,2.226,0.002
11.84,100.000,0.09434,2.227,0.002
11.86,100.100,0.09446,2.232,0.002
11.87,100.200,0.09463,2.233,0.002
11.91,100.300,0.09476,2.240,0.002
11.92,100.400,0.09492,2.243,0.002
11.95,100.500,0.09505,2.248,0.002
11.98,100.600,0.09517,2.254,0.002
11.98,100.700,0.09534,2.253,0.002
12.00,100.800,0.09546,2.258,0.002
12.03,100.900,0.09559,2.263,0.002
12.04,101.000,0.09575,2.265,0.002
12.06,101.100,0.09588,2.269,0.002
12.09,101.200,0.09604,2.274,0.002
12.10,101.300,0.09617,2.276,0.002
12.14,101.400,0.09633,2.284,0.002
12.16,101.500,0.09646,2.287,0.002
12.19,101.600,0.09663,2.292,0.002
12.21,101.700,0.09675,2.297,0.002
12.23,101.800,0.09692,2.301,0.002
12.25,101.900,0.09708,2.305,0.002
12.26,102.000,0.09725,2.306,0.002
12.30,102.100,0.09737,2.314,0.002
12.33,102.200,0.09754,2.320,0.002
12.35,102.300,0.09771,2.323,0.002
12.38,102.400,0.09783,2.329,0.002
12.40,102.500,0.09800,2.333,0.002
12.43,102.600,0.09816,2.339,0.002
12.46,102.700,0.09833,2.343,0.002
12.50,102.800,0.09850,2.351,0.002
12.52,102.900,0.09866,2.355,0.002
12.54,103.000,0.09883,2.359,0.002
12.57,103.100,0.09899,2.365,0.002
12.60,103.200,0.09916,2.371,0.002
12.63,103.300,0.09933,2.376,0.002
12.67,103.400,0.09953,2.383,0.002
12.71,103.500,0.09970,2.391,0.002
12.75,103.600,0.09991,2.399,0.002
12.81,103.700,0.10012,2.409,0.002
12.85,103.800,0.10032,2.417,0.002
12.89,103.900,0.10053,2.424,0.002
12.93,104.000,0.10074,2.432,0.002
12.96,104.100,0.10095,2.437,0.002
13.00,104.200,0.10120,2.446,0.002
13.05,104.300,0.10140,2.455,0.002
13.09,104.400,0.10161,2.462,0.002
13.12,104.500,0.10182,2.468,0.002
13.16,104.600,0.10199,2.476,0.002
13.20,104.700,0.10219,2.482,0.002
13.22,104.800,0.10240,2.487,0.002
13.25,104.900,0.10257,2.493,0.002
13.30,105.000,0.10278,2.501,0.002
13.33,105.100,0.10294,2.507,0.002
13.34,105.200,0.10311,2.509,0.002
13.37,105.300,0.10327,2.514,0.002
13.38,105.400,0.10344,2.516,0.002
13.40,105.500,0.10361,2.521,0.002
13.44,105.600,0.10373,2.527,0.002
13.46,105.700,0.10390,2.532,0.002
13.49,105.800,0.10402,2.537,0.002
13.50,105.900,0.10419,2.539,0.002
13.53,106.000,0.10431,2.545,0.002
13.55,106.100,0.10448,2.548,0.002
13.55,106.200,0.10460,2.549,0.002
13.58,106.300,0.10473,2.554,0.002
13.59,106.400,0.10490,2.557,0.002
13.61,106.500,0.10502,2.560,0.002
13.64,106.600,0.10514,2.566,0.002
13.67,106.700,0.10531,2.572,0.002
13.67,106.800,0.10544,2.572,0.002
13.70,106.900,0.10556,2.578,0.002
13.73,107.000,0.10573,2.583,0.002
13.76,107.100,0.10585,2.588,0.002
13.77,107.200,0.10602,2.590,0.002
13.81,107.300,0.10614,2.598,0.002
13.82,107.400,0.10631,2.599,0.002
13.88,107.500,0.10647,2.610,0.002
13.89,107.600,0.10660,2.612,0.002
13.92,107.700,0.10677,2.618,0.002
13.93,107.800,0.10689,2.620,0.002
13.95,107.900,0.10706,2.625,0.002
13.98,108.000,0.10722,2.629,0.002
14.01,108.100,0.10739,2.635,0.002
14.05,108.200,0.10751,2.642,0.002
14.07,108.300,0.10768,2.647,0.002
14.10,108.400,0.10785,2.652,0.002
14.13,108.500,0.10801,2.659,0.002
14.16,108.600,0.10814,2.664,0.002
14.20,108.700,0.10830,2.671,0.002
14.22,108.800,0.10847,2.675,0.002
14.26,108.900,0.10868,2.683,0.002
14.31,109.000,0.10884,2.692,0.002
14.32,109.100,0.10901,2.694,0.002
14.38,109.200,0.10922,2.705,0.002
14.39,109.300,0.10942,2.706,0.002
14.41,109.400,0.10959,2.712,0.002
14.46,109.500,0.10984,2.721,0.002
14.48,109.600,0.11001,2.724,0.002
14.50,109.700,0.11021,2.728,0.002
14.55,109.800,0.11042,2.737,0.002
14.57,109.900,0.11067,2.740,0.002
14.59,110.000,0.11088,2.745,0.002
14.63,110.100,0.11109,2.751,0.002
14.65,110.200,0.11129,2.757,0.002
14.68,110.300,0.11150,2.761,0.002
14.70,110.400,0.11167,2.766,0.002
14.75,110.500,0.11188,2.774,0.002
14.78,110.600,0.11208,2.781,0.002
14.82,110.700,0.11225,2.788,0.002
14.85,110.800,0.11242,2.793,0.002
14.87,110.900,0.11258,2.798,0.002
14.92,111.000,0.11275,2.807,0.002
14.97,111.100,0.11292,2.815,0.002
14.99,111.200,0.11304,2.821,0.002
15.02,111.300,0.11321,2.825,0.002
15.03,111.400,0.11333,2.828,0.002
15.08,111.500,0.11350,2.837,0.002
15.11,111.600,0.11362,2.842,0.002
15.14,111.700,0.11379,2.848,0.002
15.17,111.800,0.11391,2.853,0.002
15.19,111.900,0.11404,2.858,0.002
15.21,112.000,0.11416,2.862,0.002
15.25,112.100,0.11433,2.868,0.002
15.27,112.200,0.11445,2.872,0.002
15.28,112.300,0.11458,2.874,0.002
14.83,112.400,0.11474,2.790,0.002
14.88,112.500,0.11487,2.800,0.002
10.17,112.600,0.11503,1.913,0.002
3.15,112.640,0.11508,0.592,0.002