File: data-files/CWRU/0900-15-35C.txt
""
"Test Method","Will_Huddleston_Disks.msm"
"Sample I. D.","900-150-35C.mss"
"Specimen Number","1"

"Load (N)","Time (s)","Extension (mm)","Stress (MPa)","Strain (mm/mm)"

2.51,0.200,-0.03617,0.471,-0.001
2.51,0.400,-0.03617,0.472,-0.001
2.49,0.600,-0.03612,0.468,-0.001
2.51,0.800,-0.03612,0.470,-0.001
2.51,1.000,-0.03608,0.470,-0.001
2.49,1.200,-0.03608,0.468,-0.001
2.50,1.400,-0.03604,0.470,-0.001
2.50,1.600,-0.03600,0.469,-0.001
2.51,1.800,-0.03596,0.471,-0.001
2.58,2.000,-0.03579,0.484,-0.001
2.81,2.200,-0.03534,0.527,-0.001
2.88,2.400,-0.03496,0.541,-0.001
2.93,2.600,-0.03459,0.550,-0.001
2.99,2.800,-0.03421,0.561,-0.001
3.04,3.000,-0.03388,0.572,-0.001
3.08,3.200,-0.03355,0.579,-0.001
3.13,3.400,-0.03322,0.588,-0.001
3.17,3.600,-0.03293,0.596,-0.001
3.23,3.800,-0.03263,0.606,-0.001
3.26,4.000,-0.03238,0.612,-0.001
3.31,4.200,-0.03209,0.621,-0.001
3.35,4.400,-0.03184,0.630,-0.001
3.39,4.600,-0.03155,0.637,-0.001
3.44,4.800,-0.03130,0.646,-0.001
3.50,5.000,-0.03101,0.657,-0.001
3.53,5.200,-0.03076,0.664,-0.001
3.57,5.400,-0.03047,0.671,-0.001
3.63,5.600,-0.03018,0.681,-0.001
3.68,5.800,-0.02985,0.690,-0.001
3.74,6.000,-0.02956,0.701,-0.001
3.77,6.200,-0.02927,0.709,-0.001
3.83,6.400,-0.02894,0.720,-0.001
3.88,6.600,-0.02864,0.727,-0.001
3.92,6.800,-0.02831,0.735,-0.001
3.31,7.000,-0.02798,0.621,-0.001
3.56,7.200,-0.02761,0.668,-0.001
3.75,7.400,-0.02723,0.704,-0.001
3.89,7.600,-0.02686,0.731,-0.001
4.00,7.800,-0.02644,0.750,-0.001
4.09,8.000,-0.02599,0.768,-0.001
4.16,8.200,-0.02557,0.781,-0.001
4.22,8.400,-0.02520,0.792,0.000
4.30,8.600,-0.02478,0.807,0.000
4.33,8.800,-0.02441,0.813,0.000
4.39,9.000,-0.02407,0.824,0.000
4.42,9.200,-0.02374,0.829,0.000
4.47,9.400,-0.02345,0.839,0.000
4.51,9.600,-0.02316,0.847,0.000
4.54,9.800,-0.02287,0.852,0.000
4.57,10.000,-0.02258,0.858,0.000
4.60,10.200,-0.02233,0.863,0.000
4.65,10.400,-0.02204,0.872,0.000
4.67,10.600,-0.02179,0.877,0.000
4.71,10.800,-0.02150,0.885,0.000
4.75,11.000,-0.02121,0.892,0.000
4.79,11.200,-0.02092,0.899,0.000
4.84,11.400,-0.02062,0.908,0.000
4.87,11.600,-0.02029,0.914,0.000
4.92,11.800,-0.02000,0.924,0.000
4.97,12.000,-0.01967,0.933,0.000
4.99,12.200,-0.01938,0.937,0.000
5.04,12.400,-0.01905,0.946,0.000
5.09,12.600,-0.01871,0.956,0.000
5.13,12.800,-0.01838,0.964,0.000
5.20,13.000,-0.01801,0.976,0.000
5.24,13.200,-0.01763,0.984,0.000
5.30,13.400,-0.01722,0.994,0.000
5.35,13.600,-0.01680,1.005,0.000
5.40,13.800,-0.01639,1.014,0.000
5.46,14.000,-0.01597,1.025,0.000
5.51,14.200,-0.01560,1.034,0.000
5.55,14.400,-0.01518,1.041,0.000
5.59,14.600,-0.01485,1.050,0.000
5.63,14.800,-0.01447,1.057,0.000
5.66,15.000,-0.01414,1.063,0.000
5.72,15.200,-0.01385,1.074,0.000
5.74,15.400,-0.01356,1.078,0.000
5.78,15.600,-0.01327,1.085,0.000
5.82,15.800,-0.01302,1.092,0.000
5.86,16.000,-0.01273,1.101,0.000
5.90,16.200,-0.01248,1.107,0.000
5.94,16.400,-0.01219,1.116,0.000
5.95,16.600,-0.01190,1.116,0.000
6.01,16.800,-0.01165,1.129,0.000
6.06,17.000,-0.01136,1.137,0.000
6.10,17.200,-0.01103,1.145,0.000
6.13,17.400,-0.01073,1.151,0.000
6.16,17.600,-0.01044,1.157,0.000
6.22,17.800,-0.01015,1.168,0.000
6.26,18.000,-0.00986,1.175,0.000
6.30,18.200,-0.00953,1.183,0.000
6.36,18.400,-0.00920,1.194,0.000
6.42,18.600,-0.00886,1.204,0.000
6.48,18.800,-0.00849,1.216,0.000
6.53,19.000,-0.00812,1.225,0.000
6.60,19.200,-0.00770,1.238,0.000
6.66,19.400,-0.00729,1.250,0.000
6.73,19.600,-0.00683,1.263,0.000
6.78,19.800,-0.00641,1.272,0.000
6.85,20.000,-0.00600,1.286,0.000
6.92,20.200,-0.00562,1.298,0.000
6.97,20.400,-0.00529,1.308,0.000
7.01,20.600,-0.00496,1.316,0.000
7.07,20.800,-0.00463,1.327,0.000
7.10,21.000,-0.00433,1.332,0.000
7.15,21.200,-0.00404,1.342,0.000
7.16,21.400,-0.00375,1.345,0.000
7.22,21.600,-0.00350,1.354,0.000
7.25,21.800,-0.00321,1.361,0.000
7.29,22.000,-0.00296,1.369,0.000
7.36,22.200,-0.00267,1.381,0.000
7.38,22.400,-0.00238,1.386,0.000
7.45,22.600,-0.00209,1.398,0.000
7.50,22.800,-0.00180,1.407,0.000
7.54,23.000,-0.00151,1.415,0.000
7.58,23.200,-0.00118,1.422,0.000
7.63,23.400,-0.00089,1.433,0.000
7.68,23.600,-0.00055,1.441,0.000
7.75,23.800,-0.00026,1.454,0.000
7.78,24.000,0.00007,1.460,0.000
7.83,24.200,0.00040,1.470,0.000
7.91,24.400,0.00078,1.485,0.000
7.99,24.600,0.00115,1.500,0.000
8.04,24.800,0.00157,1.510,0.000
8.12,25.000,0.00198,1.525,0.000
8.19,25.200,0.00244,1.538,0.000
8.27,25.400,0.00285,1.552,0.000
8.34,25.600,0.00327,1.565,0.000
8.40,25.800,0.00364,1.576,0.000
8.46,26.000,0.00406,1.587,0.000
8.51,26.200,0.00439,1.598,0.000
8.57,26.400,0.00472,1.608,0.000
8.59,26.600,0.00502,1.613,0.000
8.67,26.800,0.00531,1.627,0.000
8.69,27.000,0.00560,1.632,0.000
8.76,27.200,0.00589,1.644,0.000
8.80,27.400,0.00614,1.651,0.000
8.83,27.600,0.00643,1.658,0.000
8.88,27.800,0.00672,1.667,0.000
8.92,28.000,0.00701,1.675,0.000
9.00,28.200,0.00730,1.689,0.000
9.03,28.400,0.00759,1.695,0.000
9.09,28.600,0.00792,1.707,0.000
9.15,28.800,0.00822,1.717,0.000
9.21,29.000,0.00855,1.729,0.000
9.26,29.200,0.00884,1.738,0.000
9.32,29.400,0.00917,1.749,0.000
9.37,29.600,0.00950,1.759,0.000
9.44,29.800,0.00984,1.773,0.000
9.53,30.000,0.01021,1.790,0.000
9.60,30.200,0.01058,1.802,0.000
9.69,30.400,0.01100,1.819,0.000
9.77,30.600,0.01141,1.835,0.000
9.86,30.800,0.01187,1.852,0.000
9.93,31.000,0.01229,1.864,0.000
10.01,31.200,0.01266,1.879,0.000
10.08,31.400,0.01308,1.893,0.000
10.12,31.600,0.01345,1.900,0.000
10.20,31.800,0.01378,1.914,0.000
10.24,32.000,0.01412,1.923,0.000
10.31,32.200,0.01445,1.935,0.000
10.38,32.400,0.01474,1.949,0.000
10.42,32.600,0.01503,1.957,0.000
10.46,32.800,0.01532,1.963,0.000
10.50,33.000,0.01561,1.970,0.000
10.56,33.200,0.01586,1.983,0.000
10.63,33.400,0.01615,1.994,0.000
10.68,33.600,0.01644,2.004,0.000
10.75,33.800,0.01673,2.019,0.000
10.79,34.000,0.01698,2.026,0.000
10.88,34.200,0.01732,2.042,0.000
10.95,34.400,0.01761,2.055,0.000
11.00,34.600,0.01790,2.065,0.000
11.07,34.800,0.01823,2.078,0.000
11.15,35.000,0.01852,2.093,0.000
11.22,35.200,0.01885,2.107,0.000
11.28,35.400,0.01919,2.117,0.000
11.35,35.600,0.01952,2.131,0.000
11.45,35.800,0.01989,2.149,0.000
11.55,36.000,0.02027,2.169,0.000
11.66,36.200,0.02072,2.189,0.000
11.76,36.400,0.02114,2.207,0.000
11.86,36.600,0.02160,2.226,0.000
11.94,36.800,0.02201,2.242,0.000
12.02,37.000,0.02239,2.257,0.000
12.11,37.200,0.02276,2.273,0.000
12.18,37.400,0.02313,2.286,0.000
12.24,37.600,0.02347,2.297,0.000
12.32,37.800,0.02380,2.312,0.000
12.36,38.000,0.02409,2.320,0.000
12.42,38.200,0.02434,2.331,0.000
12.49,38.400,0.02463,2.345,0.000
12.53,38.600,0.02492,2.352,0.000
12.60,38.800,0.02517,2.364,0.000
12.67,39.000,0.02546,2.378,0.001
12.73,39.200,0.02571,2.390,0.001
12.82,39.400,0.02600,2.407,0.001
12.87,39.600,0.02629,2.415,0.001
12.94,39.800,0.02658,2.430,0.001
13.04,40.000,0.02692,2.448,0.001
13.12,40.200,0.02721,2.463,0.001
13.18,40.400,0.02750,2.475,0.001
13.26,40.600,0.02783,2.490,0.001
13.34,40.800,0.02812,2.504,0.001
13.42,41.000,0.02845,2.519,0.001
13.51,41.200,0.02879,2.535,0.001
13.62,41.400,0.02916,2.556,0.001
13.71,41.600,0.02957,2.574,0.001
13.83,41.800,0.02995,2.597,0.001
13.92,42.000,0.03041,2.612,0.001
14.02,42.200,0.03082,2.632,0.001
14.13,42.400,0.03124,2.652,0.001
14.22,42.600,0.03165,2.669,0.001
14.32,42.800,0.03207,2.688,0.001
14.41,43.000,0.03244,2.704,0.001
14.49,43.200,0.03277,2.720,0.001
14.57,43.400,0.03311,2.735,0.001
14.63,43.600,0.03344,2.746,0.001
14.69,43.800,0.03369,2.758,0.001
14.76,44.000,0.03398,2.771,0.001
14.82,44.200,0.03427,2.782,0.001
14.87,44.400,0.03456,2.792,0.001
14.96,44.600,0.03481,2.808,0.001
15.03,44.800,0.03510,2.822,0.001
15.11,45.000,0.03535,2.836,0.001
15.18,45.200,0.03564,2.850,0.001
15.27,45.400,0.03597,2.867,0.001
15.36,45.600,0.03627,2.883,0.001
15.44,45.800,0.03656,2.898,0.001
15.53,46.000,0.03685,2.915,0.001
15.60,46.200,0.03718,2.929,0.001
15.68,46.400,0.03747,2.944,0.001
15.77,46.600,0.03780,2.961,0.001
15.87,46.800,0.03814,2.978,0.001
15.96,47.000,0.03847,2.996,0.001
16.08,47.200,0.03884,3.018,0.001
16.19,47.400,0.03922,3.039,0.001
16.31,47.600,0.03963,3.061,0.001
16.44,47.800,0.04005,3.086,0.001
16.56,48.000,0.04046,3.109,0.001
16.67,48.200,0.04088,3.128,0.001
16.77,48.400,0.04125,3.149,0.001
16.88,48.600,0.04167,3.168,0.001
16.97,48.800,0.04200,3.185,0.001
17.06,49.000,0.04233,3.202,0.001
17.14,49.200,0.04262,3.217,0.001
17.23,49.400,0.04296,3.233,0.001
17.30,49.600,0.04325,3.248,0.001
17.36,49.800,0.04350,3.259,0.001
17.45,50.000,0.04379,3.275,0.001
17.52,50.200,0.04404,3.289,0.001
17.60,50.400,0.04433,3.303,0.001
17.67,50.600,0.04458,3.317,0.001
17.76,50.800,0.04487,3.334,0.001
17.85,51.000,0.04516,3.351,0.001
17.93,51.200,0.04545,3.365,0.001
18.02,51.400,0.04574,3.383,0.001
18.10,51.600,0.04607,3.398,0.001
18.18,51.800,0.04636,3.414,0.001
18.31,52.000,0.04665,3.436,0.001
18.39,52.200,0.04699,3.452,0.001
18.47,52.400,0.04728,3.468,0.001
18.57,52.600,0.04765,3.486,0.001
18.70,52.800,0.04798,3.511,0.001
18.83,53.000,0.04836,3.534,0.001
18.94,53.200,0.04877,3.555,0.001
19.11,53.400,0.04923,3.587,0.001
19.22,53.600,0.04969,3.607,0.001
19.35,53.800,0.05010,3.632,0.001
19.49,54.000,0.05052,3.658,0.001
19.58,54.200,0.05093,3.676,0.001
19.68,54.400,0.05131,3.694,0.001
19.78,54.600,0.05164,3.714,0.001
19.86,54.800,0.05197,3.728,0.001
19.92,55.000,0.05226,3.739,0.001
20.02,55.200,0.05256,3.758,0.001
20.09,55.400,0.05285,3.771,0.001
20.17,55.600,0.05310,3.786,0.001
20.24,55.800,0.05339,3.799,0.001
20.32,56.000,0.05364,3.815,0.001
20.42,56.200,0.05393,3.834,0.001
20.51,56.400,0.05422,3.850,0.001
20.60,56.600,0.05451,3.867,0.001
20.69,56.800,0.05484,3.883,0.001
20.79,57.000,0.05513,3.903,0.001
20.88,57.200,0.05542,3.920,0.001
20.97,57.400,0.05576,3.937,0.001
21.08,57.600,0.05609,3.957,0.001
21.18,57.800,0.05638,3.976,0.001
21.29,58.000,0.05671,3.996,0.001
21.38,58.200,0.05704,4.014,0.001
21.51,58.400,0.05742,4.037,0.001
21.65,58.600,0.05779,4.064,0.001
21.79,58.800,0.05821,4.091,0.001
21.93,59.000,0.05862,4.116,0.001
22.08,59.200,0.05908,4.145,0.001
22.19,59.400,0.05950,4.165,0.001
22.30,59.600,0.05991,4.187,0.001
22.42,59.800,0.06028,4.209,0.001
22.53,60.000,0.06070,4.229,0.001
22.64,60.200,0.06103,4.249,0.001
22.71,60.400,0.06137,4.263,0.001
22.82,60.600,0.06166,4.283,0.001
22.90,60.800,0.06199,4.298,0.001
22.97,61.000,0.06228,4.311,0.001
23.05,61.200,0.06253,4.327,0.001
23.14,61.400,0.06282,4.345,0.001
23.21,61.600,0.06307,4.357,0.001
23.28,61.800,0.06336,4.370,0.001
23.38,62.000,0.06365,4.388,0.001
23.47,62.200,0.06394,4.407,0.001
23.58,62.400,0.06423,4.427,0.001
23.67,62.600,0.06452,4.442,0.001
23.79,62.800,0.06486,4.466,0.001
23.90,63.000,0.06515,4.486,0.001
24.00,63.200,0.06548,4.505,0.001
24.11,63.400,0.06581,4.525,0.001
24.21,63.600,0.06610,4.545,0.001
24.33,63.800,0.06643,4.567,0.001
24.45,64.000,0.06681,4.589,0.001
24.59,64.200,0.06718,4.616,0.001
24.72,64.400,0.06756,4.641,0.001
24.86,64.600,0.06797,4.666,0.001
25.00,64.800,0.06839,4.694,0.001
25.15,65.000,0.06885,4.720,0.001
25.28,65.200,0.06922,4.745,0.001
25.40,65.400,0.06963,4.769,0.001
25.52,65.600,0.07001,4.791,0.001
25.63,65.800,0.07038,4.811,0.001
25.72,66.000,0.07072,4.828,0.001
25.82,66.200,0.07105,4.847,0.001
25.93,66.400,0.07134,4.867,0.001
26.02,66.600,0.07167,4.884,0.001
26.11,66.800,0.07192,4.902,0.001
26.20,67.000,0.07221,4.918,0.001
26.28,67.200,0.07246,4.933,0.001
26.38,67.400,0.07275,4.952,0.001
26.48,67.600,0.07304,4.971,0.001
26.56,67.800,0.07333,4.986,0.001
26.67,68.000,0.07358,5.006,0.001
26.77,68.200,0.07391,5.026,0.001
26.89,68.400,0.07421,5.048,0.001
26.99,68.600,0.07450,5.066,0.001
27.10,68.800,0.07483,5.087,0.001
27.22,69.000,0.07512,5.110,0.001
27.33,69.200,0.07545,5.131,0.001
27.44,69.400,0.07578,5.151,0.001
27.56,69.600,0.07612,5.173,0.001
27.69,69.800,0.07645,5.198,0.002
27.83,70.000,0.07687,5.224,0.002
27.99,70.200,0.07728,5.254,0.002
28.16,70.400,0.07770,5.287,0.002
28.31,70.600,0.07811,5.315,0.002
28.45,70.800,0.07853,5.340,0.002
28.60,71.000,0.07894,5.368,0.002
28.72,71.200,0.07936,5.392,0.002
28.83,71.400,0.07973,5.413,0.002
28.94,71.600,0.08007,5.432,0.002
29.04,71.800,0.08040,5.451,0.002
29.13,72.000,0.08069,5.468,0.002
29.23,72.200,0.08098,5.487,0.002
29.32,72.400,0.08123,5.504,0.002
29.41,72.600,0.08152,5.521,0.002
29.51,72.800,0.08177,5.540,0.002
29.59,73.000,0.08206,5.554,0.002
29.70,73.200,0.08231,5.576,0.002
29.79,73.400,0.08260,5.593,0.002
29.90,73.600,0.08289,5.612,0.002
30.02,73.800,0.08318,5.636,0.002
30.12,74.000,0.08351,5.654,0.002
30.22,74.200,0.08381,5.672,0.002
30.34,74.400,0.08410,5.695,0.002
30.45,74.600,0.08443,5.715,0.002
30.56,74.800,0.08476,5.737,0.002
30.69,75.000,0.08505,5.761,0.002
30.79,75.200,0.08538,5.780,0.002
30.92,75.400,0.08576,5.805,0.002
31.07,75.600,0.08613,5.833,0.002
31.24,75.800,0.08651,5.864,0.002
31.39,76.000,0.08696,5.893,0.002
31.58,76.200,0.08742,5.929,0.002
31.72,76.400,0.08784,5.955,0.002
31.88,76.600,0.08825,5.984,0.002
32.02,76.800,0.08867,6.011,0.002
32.15,77.000,0.08904,6.035,0.002
32.27,77.200,0.08942,6.058,0.002
32.37,77.400,0.08975,6.077,0.002
32.46,77.600,0.09004,6.092,0.002
32.55,77.800,0.09037,6.110,0.002
32.64,78.000,0.09062,6.126,0.002
32.72,78.200,0.09091,6.141,0.002
32.82,78.400,0.09120,6.161,0.002
32.90,78.600,0.09145,6.176,0.002
33.01,78.800,0.09174,6.196,0.002
33.12,79.000,0.09203,6.217,0.002
33.21,79.200,0.09232,6.234,0.002
33.32,79.400,0.09262,6.254,0.002
33.43,79.600,0.09295,6.275,0.002
33.53,79.800,0.09324,6.294,0.002
33.65,80.000,0.09353,6.316,0.002
33.76,80.200,0.09386,6.336,0.002
33.88,80.400,0.09415,6.360,0.002
33.98,80.600,0.09449,6.379,0.002
34.09,80.800,0.09482,6.400,0.002
34.22,81.000,0.09515,6.424,0.002
34.36,81.200,0.09552,6.449,0.002
34.53,81.400,0.09590,6.482,0.002
34.68,81.600,0.09631,6.509,0.002
34.83,81.800,0.09673,6.538,0.002
34.98,82.000,0.09714,6.567,0.002
35.12,82.200,0.09756,6.592,0.002
35.24,82.400,0.09793,6.616,0.002
35.36,82.600,0.09831,6.638,0.002
35.48,82.800,0.09868,6.660,0.002
35.58,83.000,0.09901,6.680,0.002
35.69,83.200,0.09935,6.700,0.002
35.78,83.400,0.09968,6.717,0.002
35.87,83.600,0.09997,6.734,0.002
35.96,83.800,0.10022,6.751,0.002
36.04,84.000,0.10051,6.766,0.002
36.13,84.200,0.10076,6.782,0.002
36.23,84.400,0.10105,6.800,0.002
36.30,84.600,0.10134,6.815,0.002
36.40,84.800,0.10159,6.833,0.002
36.52,85.000,0.10188,6.855,0.002
36.62,85.200,0.10217,6.875,0.002
36.76,85.400,0.10246,6.900,0.002
36.86,85.600,0.10280,6.919,0.002
36.97,85.800,0.10309,6.940,0.002
37.09,86.000,0.10338,6.962,0.002
37.19,86.200,0.10371,6.981,0.002
37.32,86.400,0.10400,7.006,0.002
37.43,86.600,0.10433,7.027,0.002
37.56,86.800,0.10471,7.050,0.002
37.71,87.000,0.10508,7.079,0.002
37.86,87.200,0.10546,7.107,0.002
38.01,87.400,0.10587,7.136,0.002
38.19,87.600,0.10633,7.168,0.002
38.34,87.800,0.10674,7.198,0.002
38.50,88.000,0.10716,7.227,0.002
38.63,88.200,0.10758,7.251,0.002
38.77,88.400,0.10799,7.278,0.002
38.87,88.600,0.10832,7.297,0.002
38.97,88.800,0.10866,7.315,0.002
39.06,89.000,0.10899,7.332,0.002
39.15,89.200,0.10928,7.349,0.002
39.24,89.400,0.10957,7.366,0.002
39.35,89.600,0.10986,7.387,0.002
39.42,89.800,0.11011,7.399,0.002
39.51,90.000,0.11040,7.417,0.002
39.63,90.200,0.11069,7.439,0.002
39.73,90.400,0.11098,7.458,0.002
39.84,90.600,0.11127,7.479,0.002
39.97,90.800,0.11156,7.502,0.002
40.09,91.000,0.11186,7.526,0.002
40.20,91.200,0.11219,7.547,0.002
40.33,91.400,0.11248,7.571,0.002
40.45,91.600,0.11281,7.594,0.002
40.57,91.800,0.11314,7.616,0.002
40.70,92.000,0.11348,7.640,0.002
40.83,92.200,0.11377,7.665,0.002
40.96,92.400,0.11414,7.689,0.002
41.11,92.600,0.11452,7.718,0.002
41.27,92.800,0.11493,7.747,0.002
41.43,93.000,0.11535,7.777,0.002
41.59,93.200,0.11580,7.808,0.002
41.77,93.400,0.11622,7.840,0.002
41.90,93.600,0.11663,7.866,0.002
42.04,93.800,0.11705,7.891,0.002
42.17,94.000,0.11742,7.916,0.002
42.28,94.200,0.11780,7.936,0.002
42.38,94.400,0.11813,7.955,0.002
42.48,94.600,0.11846,7.974,0.002
42.56,94.800,0.11875,7.990,0.002
42.66,95.000,0.11904,8.009,0.002
42.76,95.200,0.11934,8.026,0.002
42.84,95.400,0.11963,8.043,0.002
42.95,95.600,0.11988,8.061,0.002
43.05,95.800,0.12017,8.081,0.002
43.16,96.000,0.12046,8.103,0.002
43.29,96.200,0.12075,8.126,0.002
43.40,96.400,0.12104,8.146,0.002
43.51,96.600,0.12137,8.168,0.002
43.61,96.800,0.12166,8.186,0.002
43.74,97.000,0.12200,8.210,0.002
43.85,97.200,0.12229,8.232,0.002
43.95,97.400,0.12262,8.250,0.002
44.09,97.600,0.12295,8.276,0.002
44.18,97.800,0.12328,8.294,0.002
44.34,98.000,0.12362,8.323,0.002
44.48,98.200,0.12399,8.349,0.002
44.64,98.400,0.12441,8.380,0.002
44.81,98.600,0.12482,8.411,0.002
44.97,98.800,0.12524,8.441,0.002
45.11,99.000,0.12569,8.468,0.002
45.25,99.200,0.12607,8.495,0.002
45.39,99.400,0.12648,8.521,0.002
45.52,99.600,0.12686,8.544,0.002
45.64,99.800,0.12723,8.567,0.003
45.75,100.000,0.12756,8.587,0.003
45.83,100.200,0.12785,8.603,0.003
45.92,100.400,0.12819,8.621,0.003
46.01,100.600,0.12848,8.637,0.003
46.09,100.800,0.12877,8.651,0.003
46.18,101.000,0.12902,8.669,0.003
46.26,101.200,0.12931,8.684,0.003
46.35,101.400,0.12956,8.701,0.003
46.44,101.600,0.12985,8.718,0.003
46.55,101.800,0.13014,8.737,0.003
46.65,102.000,0.13043,8.758,0.003
46.75,102.200,0.13072,8.775,0.003
46.85,102.400,0.13101,8.794,0.003
46.96,102.600,0.13135,8.816,0.003
47.07,102.800,0.13164,8.836,0.003
47.16,103.000,0.13197,8.854,0.003
47.28,103.200,0.13226,8.876,0.003
47.38,103.400,0.13259,8.895,0.003
47.51,103.600,0.13297,8.918,0.003
47.66,103.800,0.13334,8.947,0.003
47.81,104.000,0.13371,8.975,0.003
47.96,104.200,0.13413,9.003,0.003
48.13,104.400,0.13459,9.035,0.003
48.26,104.600,0.13500,9.060,0.003
48.40,104.800,0.13546,9.085,0.003
48.50,105.000,0.13583,9.105,0.003
48.60,105.200,0.13625,9.124,0.003
48.68,105.400,0.13658,9.137,0.003
48.74,105.600,0.13691,9.149,0.003
48.78,105.800,0.13725,9.156,0.003
48.86,106.000,0.13754,9.171,0.003
48.92,106.200,0.13783,9.183,0.003
48.96,106.400,0.13808,9.191,0.003
49.05,106.600,0.13837,9.208,0.003
49.12,106.800,0.13862,9.220,0.003
49.18,107.000,0.13891,9.232,0.003
49.27,107.200,0.13920,9.249,0.003
49.34,107.400,0.13949,9.262,0.003
49.42,107.600,0.13978,9.276,0.003
49.52,107.800,0.14007,9.295,0.003
49.59,108.000,0.14036,9.309,0.003
49.67,108.200,0.14065,9.324,0.003
49.76,108.400,0.14099,9.340,0.003
49.83,108.600,0.14128,9.354,0.003
49.92,108.800,0.14161,9.371,0.003
50.00,109.000,0.14194,9.387,0.003
50.09,109.200,0.14227,9.402,0.003
50.19,109.400,0.14265,9.422,0.003
50.27,109.600,0.14302,9.436,0.003
50.26,109.800,0.14344,9.435,0.003
50.32,110.000,0.14390,9.445,0.003
50.30,110.200,0.14431,9.443,0.003
50.06,110.400,0.14473,9.397,0.003
49.54,110.600,0.14514,9.300,0.003
49.07,110.800,0.14552,9.211,0.003
48.72,111.000,0.14593,9.146,0.003
48.36,111.200,0.14626,9.077,0.003
48.02,111.400,0.14660,9.014,0.003
47.66,111.600,0.14689,8.947,0.003
47.37,111.800,0.14718,8.892,0.003
47.11,112.000,0.14747,8.843,0.003
46.88,112.200,0.14772,8.801,0.003
46.68,112.400,0.14801,8.763,0.003
46.51,112.600,0.14826,8.731,0.003
46.36,112.800,0.14855,8.702,0.003
46.20,113.000,0.14884,8.672,0.003
46.04,113.200,0.14913,8.642,0.003
45.82,113.400,0.14942,8.601,0.003
45.27,113.600,0.14971,8.498,0.003
44.23,113.800,0.15005,8.302,0.003
42.19,114.000,0.15034,7.919,0.003
39.65,114.200,0.15067,7.442,0.003
36.52,114.400,0.15096,6.855,0.003
35.21,114.600,0.15129,6.610,0.003
34.69,114.800,0.15162,6.512,0.003
34.40,115.000,0.15196,6.456,0.003
34.21,115.200,0.15233,6.421,0.003
34.04,115.400,0.15275,6.390,0.003
33.90,115.600,0.15312,6.363,0.003
33.80,115.800,0.15354,6.344,0.003
33.68,116.000,0.15395,6.321,0.003
33.54,116.200,0.15437,6.296,0.003
33.33,116.400,0.15474,6.256,0.003
33.16,116.600,0.15512,6.225,0.003
32.97,116.800,0.15549,6.189,0.003
32.81,117.000,0.15582,6.160,0.003
32.66,117.200,0.15615,6.130,0.003
32.52,117.400,0.15644,6.105,0.003
32.42,117.600,0.15674,6.085,0.003
32.35,117.800,0.15703,6.073,0.003
32.27,118.000,0.15732,6.058,0.003
32.20,118.200,0.15757,6.045,0.003
32.15,118.400,0.15786,6.035,0.003
32.09,118.600,0.15815,6.023,0.003
32.03,118.800,0.15844,6.013,0.003
31.96,119.000,0.15873,6.000,0.003
31.88,119.200,0.15898,5.985,0.003
31.83,119.400,0.15927,5.975,0.003
31.77,119.600,0.15960,5.964,0.003
31.69,119.800,0.15989,5.948,0.003
31.60,120.000,0.16018,5.933,0.003
31.51,120.200,0.16048,5.916,0.003
31.44,120.400,0.16081,5.902,0.003
31.30,120.600,0.16114,5.875,0.003
30.83,120.800,0.16147,5.787,0.003
28.25,121.000,0.16185,5.303,0.003
27.57,121.200,0.16222,5.176,0.003
27.35,121.400,0.16268,5.135,0.003
27.21,121.600,0.16309,5.107,0.003
27.06,121.800,0.16351,5.080,0.003
26.93,122.000,0.16392,5.056,0.003
26.81,122.200,0.16434,5.033,0.003
26.71,122.400,0.16471,5.014,0.003
26.57,122.600,0.16509,4.987,0.003
26.44,122.800,0.16542,4.964,0.003
26.17,123.000,0.16571,4.912,0.003
26.02,123.200,0.16600,4.885,0.003
25.93,123.400,0.16629,4.867,0.003
25.87,123.600,0.16654,4.857,0.003
25.80,123.800,0.16683,4.844,0.003
25.75,124.000,0.16708,4.833,0.003
25.71,124.200,0.16737,4.826,0.003
25.64,124.400,0.16762,4.814,0.003
25.61,124.600,0.16791,4.806,0.003
25.54,124.800,0.16825,4.794,0.003
25.47,125.000,0.16854,4.781,0.003
25.40,125.200,0.16883,4.768,0.003
25.21,125.400,0.16916,4.733,0.003
25.01,125.600,0.16945,4.695,0.003
24.83,125.800,0.16978,4.661,0.003
24.66,126.000,0.17012,4.628,0.003
24.47,126.200,0.17041,4.594,0.003
24.18,126.400,0.17078,4.540,0.003
17.89,126.600,0.17116,3.358,0.003
17.56,126.800,0.17157,3.296,0.003
17.37,127.000,0.17199,3.260,0.003
17.23,127.200,0.17240,3.234,0.003
17.08,127.400,0.17286,3.205,0.003
16.94,127.600,0.17328,3.179,0.003
16.77,127.800,0.17369,3.149,0.003
16.65,128.000,0.17406,3.126,0.003
16.51,128.200,0.17444,3.100,0.003
16.37,128.400,0.17477,3.074,0.003
16.26,128.600,0.17510,3.052,0.003
16.15,128.800,0.17539,3.032,0.003
16.07,129.000,0.17569,3.016,0.003
15.95,129.200,0.17598,2.995,0.003
15.86,129.400,0.17627,2.977,0.003
15.78,129.600,0.17652,2.962,0.003
15.73,129.800,0.17681,2.952,0.003
15.66,130.000,0.17710,2.939,0.003
15.57,130.200,0.17739,2.923,0.003
15.52,130.400,0.17768,2.914,0.003
15.47,130.600,0.17797,2.904,0.004
15.40,130.800,0.17826,2.891,0.004
15.35,131.000,0.17859,2.881,0.004
15.28,131.200,0.17889,2.868,0.004
15.22,131.400,0.17922,2.858,0.004
15.18,131.600,0.17951,2.849,0.004
15.12,131.800,0.17984,2.838,0.004
15.06,132.000,0.18017,2.826,0.004
15.02,132.200,0.18055,2.820,0.004
14.97,132.400,0.18092,2.810,0.004
14.92,132.600,0.18134,2.800,0.004
14.86,132.800,0.18175,2.790,0.004
14.78,133.000,0.18221,2.774,0.004
14.69,133.200,0.18258,2.758,0.004
14.64,133.400,0.18300,2.749,0.004
14.54,133.600,0.18337,2.730,0.004
14.46,133.800,0.18375,2.715,0.004
14.38,134.000,0.18408,2.698,0.004
14.29,134.200,0.18441,2.683,0.004
14.22,134.400,0.18470,2.669,0.004
14.13,134.600,0.18504,2.653,0.004
14.07,134.800,0.18533,2.640,0.004
13.98,135.000,0.18558,2.624,0.004
13.93,135.200,0.18587,2.614,0.004
13.88,135.400,0.18612,2.605,0.004
13.83,135.600,0.18641,2.595,0.004
13.79,135.800,0.18670,2.589,0.004
13.74,136.000,0.18695,2.580,0.004
13.72,136.200,0.18724,2.575,0.004
13.67,136.400,0.18753,2.566,0.004
13.63,136.600,0.18786,2.558,0.004
13.59,136.800,0.18815,2.550,0.004
13.53,137.000,0.18848,2.540,0.004
13.52,137.200,0.18878,2.538,0.004
13.47,137.400,0.18907,2.529,0.004
13.43,137.600,0.18940,2.522,0.004
13.40,137.800,0.18977,2.516,0.004
13.39,138.000,0.19015,2.514,0.004
13.37,138.200,0.19052,2.510,0.004
13.35,138.400,0.19094,2.506,0.004
13.31,138.600,0.19139,2.499,0.004
13.28,138.800,0.19181,2.492,0.004
13.22,139.000,0.19222,2.482,0.004
13.19,139.200,0.19264,2.476,0.004
13.14,139.400,0.19301,2.466,0.004
13.10,139.600,0.19339,2.459,0.004
13.05,139.800,0.19372,2.450,0.004
13.02,140.000,0.19401,2.444,0.004
13.00,140.200,0.19434,2.441,0.004
12.96,140.400,0.19463,2.433,0.004
12.93,140.600,0.19488,2.428,0.004
12.90,140.800,0.19517,2.421,0.004
12.89,141.000,0.19542,2.420,0.004
12.87,141.200,0.19572,2.416,0.004
12.87,141.400,0.19596,2.415,0.004
12.83,141.600,0.19626,2.409,0.004
12.81,141.800,0.19655,2.405,0.004
12.81,142.000,0.19684,2.405,0.004
12.79,142.200,0.19713,2.400,0.004
12.79,142.400,0.19746,2.401,0.004
12.77,142.600,0.19775,2.398,0.004
12.77,142.800,0.19808,2.397,0.004
12.75,143.000,0.19837,2.394,0.004
12.74,143.200,0.19871,2.391,0.004
12.72,143.400,0.19904,2.388,0.004
12.70,143.600,0.19941,2.384,0.004
12.71,143.800,0.19979,2.386,0.004
12.70,144.000,0.20016,2.383,0.004
12.67,144.200,0.20058,2.379,0.004
12.66,144.400,0.20103,2.377,0.004
12.64,144.600,0.20145,2.373,0.004
12.61,144.800,0.20187,2.367,0.004
12.58,145.000,0.20224,2.362,0.004
12.56,145.200,0.20261,2.357,0.004
12.54,145.400,0.20299,2.354,0.004
12.51,145.600,0.20328,2.349,0.004
12.49,145.800,0.20361,2.345,0.004
12.46,146.000,0.20390,2.339,0.004
12.44,146.200,0.20419,2.335,0.004
12.43,146.400,0.20444,2.333,0.004
12.41,146.600,0.20473,2.330,0.004
12.41,146.800,0.20498,2.329,0.004
12.42,147.000,0.20527,2.331,0.004
12.38,147.200,0.20552,2.325,0.004
12.38,147.400,0.20581,2.324,0.004
12.37,147.600,0.20615,2.322,0.004
12.37,147.800,0.20644,2.321,0.004
12.35,148.000,0.20673,2.318,0.004
12.34,148.200,0.20706,2.316,0.004
12.33,148.400,0.20735,2.314,0.004
12.31,148.600,0.20764,2.310,0.004
12.29,148.800,0.20797,2.308,0.004
12.29,149.000,0.20831,2.306,0.004
12.29,149.200,0.20864,2.308,0.004
12.27,149.400,0.20901,2.304,0.004
12.26,149.600,0.20939,2.302,0.004
12.26,149.800,0.20980,2.301,0.004
12.25,150.000,0.21022,2.299,0.004
12.22,150.200,0.21063,2.294,0.004
12.19,150.400,0.21105,2.288,0.004
12.16,150.600,0.21142,2.283,0.004
12.14,150.800,0.21180,2.279,0.004
12.10,151.000,0.21217,2.272,0.004
12.09,151.080,0.21230,2.270,0.004