File: data-files/CWRU/0900-05-24A.txt
""
"Test Method","Will_Huddleston_Disks.msm"
"Sample I. D.","900-5-24A.mss"
"Specimen Number","1"

"Load (N)","Time (s)","Extension (mm)","Stress (MPa)","Strain (mm/mm)"

3.91,0.200,-0.08182,0.429,-0.002
3.91,0.400,-0.08182,0.429,-0.002
3.90,0.600,-0.08182,0.428,-0.002
3.92,0.800,-0.08182,0.430,-0.002
3.90,1.000,-0.08178,0.428,-0.002
3.91,1.200,-0.08174,0.429,-0.002
3.93,1.400,-0.08170,0.432,-0.002
3.96,1.600,-0.08166,0.434,-0.002
4.00,1.800,-0.08153,0.439,-0.002
4.11,2.000,-0.08128,0.451,-0.002
4.32,2.200,-0.08087,0.474,-0.002
4.47,2.400,-0.08049,0.490,-0.002
4.56,2.600,-0.08012,0.500,-0.002
4.62,2.800,-0.07979,0.507,-0.002
4.66,3.000,-0.07950,0.511,-0.002
4.69,3.200,-0.07925,0.514,-0.002
4.73,3.400,-0.07896,0.519,-0.002
4.76,3.600,-0.07871,0.523,-0.002
4.77,3.800,-0.07842,0.523,-0.002
4.82,4.000,-0.07817,0.528,-0.002
4.86,4.200,-0.07792,0.533,-0.002
4.89,4.400,-0.07767,0.537,-0.002
4.93,4.600,-0.07738,0.540,-0.002
4.96,4.800,-0.07709,0.545,-0.002
4.99,5.000,-0.07680,0.548,-0.002
5.01,5.200,-0.07650,0.550,-0.002
5.07,5.400,-0.07621,0.556,-0.002
5.10,5.600,-0.07592,0.560,-0.001
5.13,5.800,-0.07563,0.562,-0.001
5.18,6.000,-0.07530,0.568,-0.001
5.21,6.200,-0.07501,0.572,-0.001
5.27,6.400,-0.07468,0.578,-0.001
5.32,6.600,-0.07434,0.583,-0.001
5.36,6.800,-0.07401,0.589,-0.001
5.40,7.000,-0.07364,0.593,-0.001
5.45,7.200,-0.07322,0.598,-0.001
5.52,7.400,-0.07281,0.605,-0.001
5.57,7.600,-0.07239,0.611,-0.001
5.62,7.800,-0.07198,0.616,-0.001
5.66,8.000,-0.07156,0.621,-0.001
5.73,8.200,-0.07119,0.628,-0.001
5.77,8.400,-0.07081,0.633,-0.001
5.81,8.600,-0.07044,0.638,-0.001
5.84,8.800,-0.07011,0.641,-0.001
5.89,9.000,-0.06981,0.647,-0.001
5.93,9.200,-0.06948,0.651,-0.001
5.96,9.400,-0.06919,0.654,-0.001
5.99,9.600,-0.06894,0.657,-0.001
6.03,9.800,-0.06865,0.661,-0.001
6.08,10.000,-0.06840,0.667,-0.001
6.10,10.200,-0.06811,0.669,-0.001
6.16,10.400,-0.06782,0.676,-0.001
6.20,10.600,-0.06753,0.680,-0.001
6.24,10.800,-0.06720,0.685,-0.001
6.28,11.000,-0.06691,0.689,-0.001
6.31,11.200,-0.06661,0.693,-0.001
6.38,11.400,-0.06628,0.700,-0.001
6.41,11.600,-0.06599,0.703,-0.001
6.46,11.800,-0.06566,0.709,-0.001
6.50,12.000,-0.06533,0.713,-0.001
6.55,12.200,-0.06499,0.719,-0.001
6.62,12.400,-0.06466,0.726,-0.001
6.66,12.600,-0.06429,0.730,-0.001
6.74,12.800,-0.06387,0.739,-0.001
6.81,13.000,-0.06346,0.747,-0.001
6.86,13.200,-0.06304,0.752,-0.001
6.94,13.400,-0.06258,0.761,-0.001
6.98,13.600,-0.06217,0.765,-0.001
7.06,13.800,-0.06179,0.775,-0.001
7.12,14.000,-0.06138,0.781,-0.001
7.18,14.200,-0.06105,0.788,-0.001
7.21,14.400,-0.06071,0.791,-0.001
7.25,14.600,-0.06038,0.796,-0.001
7.30,14.800,-0.06009,0.801,-0.001
7.35,15.000,-0.05980,0.806,-0.001
7.38,15.200,-0.05951,0.810,-0.001
7.42,15.400,-0.05926,0.815,-0.001
7.48,15.600,-0.05897,0.820,-0.001
7.53,15.800,-0.05872,0.826,-0.001
7.57,16.000,-0.05843,0.831,-0.001
7.62,16.200,-0.05814,0.836,-0.001
7.69,16.400,-0.05785,0.843,-0.001
7.72,16.600,-0.05756,0.847,-0.001
7.76,16.800,-0.05722,0.852,-0.001
7.83,17.000,-0.05693,0.859,-0.001
7.89,17.200,-0.05664,0.866,-0.001
7.92,17.400,-0.05631,0.869,-0.001
7.98,17.600,-0.05598,0.876,-0.001
8.06,17.800,-0.05569,0.884,-0.001
8.12,18.000,-0.05531,0.890,-0.001
8.19,18.200,-0.05498,0.899,-0.001
8.26,18.400,-0.05456,0.906,-0.001
8.34,18.600,-0.05415,0.916,-0.001
8.43,18.800,-0.05369,0.925,-0.001
8.51,19.000,-0.05328,0.933,-0.001
8.56,19.200,-0.05286,0.939,-0.001
8.63,19.400,-0.05244,0.947,-0.001
8.69,19.600,-0.05203,0.953,-0.001
8.73,19.800,-0.05170,0.958,-0.001
8.79,20.000,-0.05136,0.964,-0.001
8.85,20.200,-0.05107,0.971,-0.001
8.87,20.400,-0.05078,0.973,-0.001
8.91,20.600,-0.05049,0.978,-0.001
8.97,20.800,-0.05020,0.984,-0.001
9.02,21.000,-0.04995,0.990,-0.001
9.07,21.200,-0.04970,0.995,-0.001
9.11,21.400,-0.04941,0.999,-0.001
9.17,21.600,-0.04912,1.006,-0.001
9.22,21.800,-0.04883,1.011,-0.001
9.30,22.000,-0.04854,1.020,-0.001
9.35,22.200,-0.04825,1.026,-0.001
9.40,22.400,-0.04796,1.032,-0.001
9.46,22.600,-0.04762,1.038,-0.001
9.54,22.800,-0.04733,1.047,-0.001
9.59,23.000,-0.04704,1.052,-0.001
9.65,23.200,-0.04671,1.058,-0.001
9.71,23.400,-0.04638,1.065,-0.001
9.79,23.600,-0.04604,1.074,-0.001
9.85,23.800,-0.04567,1.081,-0.001
9.94,24.000,-0.04530,1.091,-0.001
10.01,24.200,-0.04492,1.098,-0.001
10.10,24.400,-0.04447,1.108,-0.001
10.19,24.600,-0.04405,1.118,-0.001
10.28,24.800,-0.04363,1.128,-0.001
10.33,25.000,-0.04322,1.134,-0.001
10.40,25.200,-0.04284,1.141,-0.001
10.48,25.400,-0.04247,1.150,-0.001
10.55,25.600,-0.04210,1.158,-0.001
10.61,25.800,-0.04181,1.165,-0.001
10.66,26.000,-0.04147,1.169,-0.001
10.71,26.200,-0.04118,1.175,-0.001
10.76,26.400,-0.04089,1.181,-0.001
10.83,26.600,-0.04064,1.188,-0.001
10.87,26.800,-0.04035,1.193,-0.001
10.93,27.000,-0.04010,1.199,-0.001
10.98,27.200,-0.03981,1.205,-0.001
11.04,27.400,-0.03952,1.211,-0.001
11.13,27.600,-0.03927,1.221,-0.001
11.18,27.800,-0.03894,1.227,-0.001
11.25,28.000,-0.03865,1.234,-0.001
11.32,28.200,-0.03836,1.242,-0.001
11.37,28.400,-0.03807,1.248,-0.001
11.44,28.600,-0.03773,1.255,-0.001
11.51,28.800,-0.03744,1.263,-0.001
11.59,29.000,-0.03711,1.272,-0.001
11.66,29.200,-0.03682,1.279,-0.001
11.74,29.400,-0.03645,1.288,-0.001
11.83,29.600,-0.03611,1.298,-0.001
11.92,29.800,-0.03574,1.308,-0.001
12.02,30.000,-0.03532,1.319,-0.001
12.12,30.200,-0.03487,1.330,-0.001
12.22,30.400,-0.03445,1.341,-0.001
12.30,30.600,-0.03408,1.350,-0.001
12.38,30.800,-0.03366,1.359,-0.001
12.47,31.000,-0.03329,1.368,-0.001
12.57,31.200,-0.03291,1.379,-0.001
12.62,31.400,-0.03254,1.385,-0.001
12.69,31.600,-0.03225,1.393,-0.001
12.75,31.800,-0.03192,1.399,-0.001
12.80,32.000,-0.03162,1.404,-0.001
12.88,32.200,-0.03133,1.414,-0.001
12.95,32.400,-0.03108,1.421,-0.001
13.01,32.600,-0.03079,1.428,-0.001
13.08,32.800,-0.03054,1.435,-0.001
13.14,33.000,-0.03025,1.442,-0.001
13.23,33.200,-0.02996,1.451,-0.001
13.30,33.400,-0.02967,1.459,-0.001
13.40,33.600,-0.02938,1.470,-0.001
13.43,33.800,-0.02909,1.474,-0.001
13.53,34.000,-0.02880,1.484,-0.001
13.59,34.200,-0.02851,1.491,-0.001
13.69,34.400,-0.02818,1.502,-0.001
13.76,34.600,-0.02788,1.510,-0.001
13.85,34.800,-0.02755,1.520,-0.001
13.94,35.000,-0.02726,1.529,-0.001
14.01,35.200,-0.02689,1.537,-0.001
14.13,35.400,-0.02651,1.551,-0.001
14.22,35.600,-0.02614,1.561,-0.001
14.35,35.800,-0.02572,1.574,-0.001
14.49,36.000,-0.02531,1.590,0.000
14.59,36.200,-0.02485,1.601,0.000
14.72,36.400,-0.02444,1.615,0.000
14.82,36.600,-0.02402,1.626,0.000
14.93,36.800,-0.02365,1.638,0.000
15.00,37.000,-0.02327,1.646,0.000
15.09,37.200,-0.02294,1.656,0.000
15.17,37.400,-0.02265,1.664,0.000
15.23,37.600,-0.02236,1.671,0.000
15.30,37.800,-0.02207,1.678,0.000
15.38,38.000,-0.02178,1.687,0.000
15.45,38.200,-0.02153,1.696,0.000
15.54,38.400,-0.02124,1.705,0.000
15.62,38.600,-0.02094,1.713,0.000
15.68,38.800,-0.02070,1.720,0.000
15.76,39.000,-0.02040,1.729,0.000
15.85,39.200,-0.02011,1.739,0.000
15.93,39.400,-0.01978,1.748,0.000
16.03,39.600,-0.01949,1.759,0.000
16.13,39.800,-0.01916,1.770,0.000
16.24,40.000,-0.01887,1.782,0.000
16.32,40.200,-0.01853,1.791,0.000
16.41,40.400,-0.01820,1.801,0.000
16.52,40.600,-0.01787,1.812,0.000
16.63,40.800,-0.01754,1.824,0.000
16.75,41.000,-0.01716,1.838,0.000
16.88,41.200,-0.01679,1.852,0.000
17.02,41.400,-0.01637,1.867,0.000
17.16,41.600,-0.01592,1.883,0.000
17.31,41.800,-0.01546,1.900,0.000
17.43,42.000,-0.01504,1.912,0.000
17.58,42.200,-0.01463,1.929,0.000
17.71,42.400,-0.01421,1.944,0.000
17.83,42.600,-0.01384,1.956,0.000
17.94,42.800,-0.01351,1.968,0.000
17.98,43.000,-0.01322,1.973,0.000
18.08,43.200,-0.01288,1.984,0.000
18.18,43.400,-0.01259,1.994,0.000
18.25,43.600,-0.01230,2.003,0.000
18.33,43.800,-0.01205,2.011,0.000
18.41,44.000,-0.01176,2.020,0.000
18.51,44.200,-0.01147,2.031,0.000
18.59,44.400,-0.01118,2.040,0.000
18.70,44.600,-0.01089,2.052,0.000
18.82,44.800,-0.01060,2.065,0.000
18.90,45.000,-0.01031,2.074,0.000
18.99,45.200,-0.00997,2.083,0.000
19.09,45.400,-0.00968,2.095,0.000
19.19,45.600,-0.00935,2.106,0.000
19.33,45.800,-0.00902,2.120,0.000
19.44,46.000,-0.00873,2.133,0.000
19.55,46.200,-0.00839,2.145,0.000
19.69,46.400,-0.00802,2.160,0.000
19.82,46.600,-0.00765,2.174,0.000
19.97,46.800,-0.00727,2.191,0.000
20.14,47.000,-0.00686,2.209,0.000
20.31,47.200,-0.00640,2.228,0.000
20.44,47.400,-0.00598,2.243,0.000
20.59,47.600,-0.00557,2.260,0.000
20.75,47.800,-0.00515,2.277,0.000
20.87,48.000,-0.00478,2.290,0.000
20.98,48.200,-0.00445,2.302,0.000
21.09,48.400,-0.00411,2.314,0.000
21.19,48.600,-0.00378,2.325,0.000
21.31,48.800,-0.00345,2.338,0.000
21.41,49.000,-0.00316,2.349,0.000
21.51,49.200,-0.00287,2.360,0.000
21.59,49.400,-0.00262,2.369,0.000
21.69,49.600,-0.00233,2.380,0.000
21.79,49.800,-0.00208,2.391,0.000
21.88,50.000,-0.00179,2.401,0.000
22.01,50.200,-0.00150,2.415,0.000
22.13,50.400,-0.00121,2.428,0.000
22.24,50.600,-0.00091,2.440,0.000
22.36,50.800,-0.00062,2.453,0.000
22.46,51.000,-0.00033,2.464,0.000
22.60,51.200,-0.00004,2.480,0.000
22.74,51.400,0.00029,2.495,0.000
22.86,51.600,0.00062,2.508,0.000
23.00,51.800,0.00091,2.523,0.000
23.13,52.000,0.00129,2.538,0.000
23.30,52.200,0.00162,2.556,0.000
23.45,52.400,0.00204,2.573,0.000
23.63,52.600,0.00245,2.593,0.000
23.82,52.800,0.00287,2.614,0.000
23.99,53.000,0.00332,2.632,0.000
24.17,53.200,0.00374,2.652,0.000
24.32,53.400,0.00415,2.668,0.000
24.45,53.600,0.00457,2.683,0.000
24.59,53.800,0.00494,2.698,0.000
24.71,54.000,0.00528,2.712,0.000
24.81,54.200,0.00561,2.722,0.000
24.82,54.400,0.00590,2.723,0.000
24.92,54.600,0.00619,2.735,0.000
25.02,54.800,0.00648,2.745,0.000
25.12,55.000,0.00673,2.757,0.000
25.21,55.200,0.00702,2.766,0.000
25.33,55.400,0.00727,2.779,0.000
25.47,55.600,0.00756,2.794,0.000
25.59,55.800,0.00781,2.807,0.000
25.70,56.000,0.00810,2.820,0.000
25.85,56.200,0.00839,2.837,0.000
25.98,56.400,0.00873,2.851,0.000
26.12,56.600,0.00902,2.866,0.000
26.26,56.800,0.00931,2.881,0.000
26.40,57.000,0.00964,2.896,0.000
26.53,57.200,0.00993,2.911,0.000
26.67,57.400,0.01026,2.926,0.000
26.83,57.600,0.01060,2.944,0.000
26.99,57.800,0.01097,2.962,0.000
27.15,58.000,0.01134,2.979,0.000
27.34,58.200,0.01172,3.000,0.000
27.54,58.400,0.01213,3.022,0.000
27.73,58.600,0.01255,3.043,0.000
27.91,58.800,0.01296,3.062,0.000
28.09,59.000,0.01338,3.082,0.000
28.28,59.200,0.01380,3.103,0.000
28.45,59.400,0.01417,3.121,0.000
28.58,59.600,0.01454,3.136,0.000
28.75,59.800,0.01488,3.154,0.000
28.87,60.000,0.01521,3.168,0.000
29.01,60.200,0.01550,3.183,0.000
29.14,60.400,0.01579,3.198,0.000
29.26,60.600,0.01604,3.211,0.000
29.39,60.800,0.01633,3.224,0.000
29.53,61.000,0.01658,3.240,0.000
29.66,61.200,0.01687,3.255,0.000
29.81,61.400,0.01716,3.271,0.000
29.97,61.600,0.01745,3.289,0.000
30.14,61.800,0.01774,3.307,0.000
30.30,62.000,0.01803,3.324,0.000
30.44,62.200,0.01833,3.340,0.000
30.62,62.400,0.01866,3.359,0.000
30.78,62.600,0.01895,3.377,0.000
30.91,62.800,0.01924,3.391,0.000
31.08,63.000,0.01957,3.410,0.000
31.24,63.200,0.01990,3.428,0.000
31.43,63.400,0.02024,3.449,0.000
31.63,63.600,0.02061,3.471,0.000
31.82,63.800,0.02099,3.492,0.000
32.05,64.000,0.02136,3.517,0.000
32.30,64.200,0.02177,3.544,0.000
32.51,64.400,0.02219,3.567,0.000
32.75,64.600,0.02261,3.593,0.000
32.96,64.800,0.02302,3.616,0.000
33.18,65.000,0.02340,3.640,0.000
33.35,65.200,0.02377,3.659,0.000
33.49,65.400,0.02410,3.674,0.000
33.67,65.600,0.02443,3.694,0.000
33.82,65.800,0.02473,3.710,0.000
33.99,66.000,0.02502,3.730,0.000
34.15,66.200,0.02531,3.747,0.000
34.28,66.400,0.02560,3.761,0.001
34.42,66.600,0.02585,3.776,0.001
34.57,66.800,0.02610,3.793,0.001
34.75,67.000,0.02639,3.813,0.001
34.90,67.200,0.02668,3.830,0.001
35.07,67.400,0.02697,3.848,0.001
35.22,67.600,0.02722,3.865,0.001
35.42,67.800,0.02755,3.886,0.001
35.59,68.000,0.02784,3.905,0.001
35.74,68.200,0.02813,3.921,0.001
35.93,68.400,0.02842,3.943,0.001
36.08,68.600,0.02876,3.959,0.001
36.24,68.800,0.02905,3.976,0.001
36.43,69.000,0.02938,3.997,0.001
36.64,69.200,0.02971,4.020,0.001
36.84,69.400,0.03009,4.042,0.001
37.12,69.600,0.03046,4.073,0.001
37.38,69.800,0.03088,4.101,0.001
37.66,70.000,0.03133,4.132,0.001
37.95,70.200,0.03175,4.164,0.001
38.19,70.400,0.03221,4.190,0.001
38.43,70.600,0.03262,4.216,0.001
38.65,70.800,0.03299,4.241,0.001
38.86,71.000,0.03337,4.263,0.001
39.01,71.200,0.03370,4.281,0.001
39.18,71.400,0.03399,4.299,0.001
39.34,71.600,0.03428,4.316,0.001
39.45,71.800,0.03457,4.329,0.001
39.62,72.000,0.03482,4.347,0.001
39.76,72.200,0.03511,4.363,0.001
39.91,72.400,0.03536,4.379,0.001
40.05,72.600,0.03565,4.394,0.001
40.21,72.800,0.03590,4.412,0.001
40.38,73.000,0.03619,4.430,0.001
40.56,73.200,0.03649,4.451,0.001
40.75,73.400,0.03678,4.471,0.001
40.93,73.600,0.03707,4.491,0.001
41.13,73.800,0.03740,4.513,0.001
41.33,74.000,0.03769,4.535,0.001
41.53,74.200,0.03802,4.557,0.001
41.73,74.400,0.03831,4.579,0.001
41.95,74.600,0.03865,4.603,0.001
42.14,74.800,0.03898,4.624,0.001
42.40,75.000,0.03935,4.653,0.001
42.68,75.200,0.03973,4.683,0.001
42.97,75.400,0.04014,4.715,0.001
43.31,75.600,0.04056,4.752,0.001
43.63,75.800,0.04097,4.787,0.001
43.93,76.000,0.04143,4.820,0.001
44.20,76.200,0.04185,4.850,0.001
44.45,76.400,0.04222,4.877,0.001
44.72,76.600,0.04264,4.907,0.001
44.95,76.800,0.04297,4.932,0.001
45.16,77.000,0.04330,4.955,0.001
45.36,77.200,0.04359,4.977,0.001
45.56,77.400,0.04392,4.999,0.001
45.76,77.600,0.04421,5.021,0.001
45.95,77.800,0.04446,5.042,0.001
46.15,78.000,0.04476,5.064,0.001
46.35,78.200,0.04505,5.086,0.001
46.57,78.400,0.04534,5.109,0.001
46.77,78.600,0.04563,5.132,0.001
47.00,78.800,0.04592,5.157,0.001
47.26,79.000,0.04621,5.186,0.001
47.52,79.200,0.04650,5.214,0.001
47.79,79.400,0.04683,5.243,0.001
48.00,79.600,0.04712,5.267,0.001
48.26,79.800,0.04746,5.295,0.001
48.52,80.000,0.04779,5.324,0.001
48.77,80.200,0.04812,5.352,0.001
49.06,80.400,0.04845,5.383,0.001
49.32,80.600,0.04883,5.411,0.001
49.62,80.800,0.04920,5.444,0.001
49.92,81.000,0.04958,5.477,0.001
50.25,81.200,0.04999,5.514,0.001
50.62,81.400,0.05045,5.554,0.001
50.97,81.600,0.05086,5.593,0.001
51.29,81.800,0.05128,5.628,0.001
51.61,82.000,0.05165,5.663,0.001
51.90,82.200,0.05203,5.695,0.001
52.15,82.400,0.05240,5.722,0.001
52.42,82.600,0.05273,5.751,0.001
52.62,82.800,0.05307,5.774,0.001
52.86,83.000,0.05336,5.800,0.001
53.04,83.200,0.05365,5.820,0.001
53.25,83.400,0.05394,5.843,0.001
53.46,83.600,0.05419,5.866,0.001
53.69,83.800,0.05448,5.891,0.001
53.91,84.000,0.05477,5.915,0.001
54.17,84.200,0.05502,5.943,0.001
54.36,84.400,0.05535,5.964,0.001
54.57,84.600,0.05564,5.988,0.001
54.81,84.800,0.05593,6.014,0.001
55.09,85.000,0.05622,6.045,0.001
55.36,85.200,0.05656,6.074,0.001
55.62,85.400,0.05685,6.102,0.001
55.89,85.600,0.05718,6.132,0.001
56.18,85.800,0.05747,6.164,0.001
56.47,86.000,0.05780,6.195,0.001
56.77,86.200,0.05814,6.229,0.001
57.11,86.400,0.05851,6.266,0.001
57.47,86.600,0.05893,6.306,0.001
57.85,86.800,0.05934,6.347,0.001
58.28,87.000,0.05976,6.394,0.001
58.66,87.200,0.06021,6.436,0.001
59.04,87.400,0.06063,6.478,0.001
59.42,87.600,0.06104,6.520,0.001
59.75,87.800,0.06142,6.556,0.001
60.07,88.000,0.06179,6.590,0.001
60.35,88.200,0.06213,6.622,0.001
60.64,88.400,0.06246,6.653,0.001
60.90,88.600,0.06275,6.682,0.001
61.15,88.800,0.06300,6.709,0.001
61.40,89.000,0.06329,6.737,0.001
61.65,89.200,0.06354,6.764,0.001
61.91,89.400,0.06383,6.792,0.001
62.17,89.600,0.06408,6.822,0.001
62.46,89.800,0.06437,6.853,0.001
62.71,90.000,0.06466,6.880,0.001
62.95,90.200,0.06495,6.907,0.001
63.26,90.400,0.06524,6.941,0.001
63.53,90.600,0.06553,6.971,0.001
63.84,90.800,0.06587,7.005,0.001
64.13,91.000,0.06616,7.036,0.001
64.44,91.200,0.06649,7.071,0.001
64.76,91.400,0.06678,7.105,0.001
65.08,91.600,0.06711,7.141,0.001
65.43,91.800,0.06744,7.179,0.001
65.79,92.000,0.06782,7.219,0.001
66.17,92.200,0.06819,7.260,0.001
66.57,92.400,0.06861,7.304,0.001
66.99,92.600,0.06902,7.351,0.001
67.45,92.800,0.06948,7.400,0.001
67.85,93.000,0.06990,7.444,0.001
68.27,93.200,0.07031,7.490,0.001
68.66,93.400,0.07069,7.533,0.001
69.03,93.600,0.07106,7.574,0.001
69.40,93.800,0.07143,7.614,0.001
69.67,94.000,0.07172,7.644,0.001
69.97,94.200,0.07206,7.677,0.001
70.25,94.400,0.07235,7.708,0.001
70.53,94.600,0.07264,7.739,0.001
70.80,94.800,0.07289,7.768,0.001
71.04,95.000,0.07318,7.794,0.001
71.31,95.200,0.07343,7.824,0.001
71.57,95.400,0.07372,7.853,0.001
71.87,95.600,0.07401,7.886,0.001
72.17,95.800,0.07430,7.919,0.001
72.47,96.000,0.07459,7.951,0.001
72.73,96.200,0.07488,7.980,0.001
73.01,96.400,0.07517,8.011,0.001
73.28,96.600,0.07546,8.041,0.001
73.56,96.800,0.07580,8.071,0.001
73.81,97.000,0.07609,8.098,0.001
74.08,97.200,0.07642,8.128,0.002
74.34,97.400,0.07675,8.157,0.002
74.63,97.600,0.07709,8.189,0.002
74.95,97.800,0.07746,8.224,0.002
75.27,98.000,0.07783,8.258,0.002
75.65,98.200,0.07825,8.300,0.002
17.91,98.400,0.07866,1.965,0.002
16.01,98.600,0.07912,1.757,0.002
16.65,98.800,0.07954,1.827,0.002
17.30,99.000,0.07991,1.898,0.002
17.88,99.200,0.08029,1.962,0.002
18.40,99.400,0.08066,2.019,0.002
18.91,99.600,0.08099,2.074,0.002
19.36,99.800,0.08128,2.124,0.002
19.77,100.000,0.08162,2.169,0.002
20.17,100.200,0.08191,2.213,0.002
20.57,100.400,0.08216,2.257,0.002
20.89,100.600,0.08245,2.292,0.002
21.24,100.800,0.08270,2.330,0.002
21.56,101.000,0.08299,2.365,0.002
21.89,101.200,0.08324,2.402,0.002
22.18,101.400,0.08353,2.434,0.002
22.49,101.600,0.08382,2.467,0.002
22.78,101.800,0.08411,2.499,0.002
23.09,102.000,0.08440,2.533,0.002
23.38,102.200,0.08469,2.565,0.002
23.63,102.400,0.08502,2.593,0.002
23.89,102.600,0.08531,2.621,0.002
24.14,102.800,0.08565,2.649,0.002
24.41,103.000,0.08594,2.678,0.002
24.64,103.200,0.08627,2.703,0.002
24.91,103.400,0.08664,2.733,0.002
25.17,103.600,0.08702,2.762,0.002
25.46,103.800,0.08743,2.794,0.002
25.72,104.000,0.08785,2.823,0.002
26.04,104.200,0.08826,2.857,0.002
26.34,104.400,0.08872,2.890,0.002
26.61,104.600,0.08914,2.920,0.002
26.86,104.800,0.08955,2.947,0.002
27.09,105.000,0.08993,2.973,0.002
27.33,105.200,0.09030,2.999,0.002
27.53,105.400,0.09063,3.020,0.002
27.72,105.600,0.09092,3.041,0.002
27.91,105.800,0.09121,3.062,0.002
28.09,106.000,0.09151,3.082,0.002
28.27,106.200,0.09175,3.101,0.002
28.44,106.400,0.09205,3.121,0.002
28.62,106.600,0.09229,3.140,0.002
28.81,106.800,0.09259,3.161,0.002
29.00,107.000,0.09288,3.182,0.002
29.20,107.200,0.09317,3.203,0.002
29.37,107.400,0.09346,3.223,0.002
29.60,107.600,0.09375,3.247,0.002
29.79,107.800,0.09408,3.268,0.002
30.02,108.000,0.09437,3.293,0.002
30.23,108.200,0.09471,3.317,0.002
30.45,108.400,0.09504,3.341,0.002
30.66,108.600,0.09533,3.364,0.002
30.88,108.800,0.09570,3.388,0.002
31.13,109.000,0.09603,3.415,0.002
31.39,109.200,0.09645,3.445,0.002
31.65,109.400,0.09682,3.472,0.002
31.92,109.600,0.09728,3.502,0.002
32.22,109.800,0.09774,3.535,0.002
32.49,110.000,0.09815,3.565,0.002
32.74,110.200,0.09857,3.592,0.002
32.98,110.400,0.09899,3.619,0.002
33.21,110.600,0.09940,3.644,0.002
33.43,110.800,0.09977,3.667,0.002
33.60,111.000,0.10011,3.686,0.002
33.75,111.200,0.10040,3.703,0.002
33.92,111.400,0.10069,3.721,0.002
34.09,111.600,0.10098,3.740,0.002
34.23,111.800,0.10127,3.756,0.002
34.39,112.000,0.10156,3.773,0.002
34.53,112.200,0.10181,3.788,0.002
34.72,112.400,0.10210,3.809,0.002
34.90,112.600,0.10239,3.829,0.002
35.08,112.800,0.10268,3.849,0.002
35.27,113.000,0.10297,3.870,0.002
35.45,113.200,0.10331,3.890,0.002
35.65,113.400,0.10360,3.912,0.002
35.81,113.600,0.10393,3.930,0.002
36.02,113.800,0.10422,3.952,0.002
36.20,114.000,0.10455,3.971,0.002
36.41,114.200,0.10489,3.995,0.002
36.60,114.400,0.10522,4.016,0.002
36.81,114.600,0.10555,4.039,0.002
37.03,114.800,0.10597,4.063,0.002
37.25,115.000,0.10634,4.087,0.002
37.49,115.200,0.10676,4.114,0.002
37.73,115.400,0.10721,4.140,0.002
37.96,115.600,0.10763,4.165,0.002
38.13,115.800,0.10804,4.184,0.002
38.35,116.000,0.10846,4.208,0.002
38.54,116.200,0.10883,4.229,0.002
38.70,116.400,0.10917,4.246,0.002
38.84,116.600,0.10950,4.262,0.002
38.99,116.800,0.10983,4.278,0.002
39.12,117.000,0.11012,4.293,0.002
39.22,117.200,0.11041,4.304,0.002
39.32,117.400,0.11070,4.314,0.002
39.42,117.600,0.11095,4.325,0.002
39.51,117.800,0.11124,4.335,0.002
39.57,118.000,0.11149,4.342,0.002
39.67,118.200,0.11178,4.352,0.002
39.74,118.400,0.11208,4.361,0.002
39.83,118.600,0.11241,4.370,0.002
39.92,118.800,0.11270,4.380,0.002
40.04,119.000,0.11299,4.393,0.002
40.16,119.200,0.11332,4.406,0.002
40.28,119.400,0.11361,4.420,0.002
40.40,119.600,0.11390,4.432,0.002
40.52,119.800,0.11424,4.446,0.002
40.68,120.000,0.11457,4.463,0.002
40.82,120.200,0.11490,4.478,0.002
41.01,120.400,0.11528,4.499,0.002
41.19,120.600,0.11569,4.519,0.002
41.37,120.800,0.11611,4.540,0.002
41.53,121.000,0.11656,4.556,0.002
41.71,121.200,0.11698,4.576,0.002
41.87,121.400,0.11744,4.594,0.002
42.00,121.600,0.11781,4.608,0.002
42.13,121.800,0.11823,4.622,0.002
42.22,122.000,0.11856,4.632,0.002
42.32,122.200,0.11889,4.643,0.002
42.43,122.400,0.11918,4.656,0.002
42.52,122.600,0.11951,4.665,0.002
42.61,122.800,0.11976,4.675,0.002
42.72,123.000,0.12005,4.688,0.002
42.82,123.200,0.12030,4.698,0.002
42.91,123.400,0.12059,4.709,0.002
43.05,123.600,0.12084,4.724,0.002
43.17,123.800,0.12113,4.737,0.002
43.29,124.000,0.12143,4.750,0.002
43.41,124.200,0.12172,4.763,0.002
43.55,124.400,0.12201,4.778,0.002
43.68,124.600,0.12230,4.793,0.002
43.81,124.800,0.12263,4.806,0.002
43.93,125.000,0.12292,4.820,0.002
44.06,125.200,0.12325,4.834,0.002
44.19,125.400,0.12354,4.849,0.002
44.30,125.600,0.12388,4.860,0.002
44.42,125.800,0.12421,4.874,0.002
44.57,126.000,0.12458,4.890,0.002
44.72,126.200,0.12496,4.907,0.002
44.87,126.400,0.12537,4.923,0.002
45.06,126.600,0.12579,4.944,0.002
45.19,126.800,0.12625,4.958,0.002
45.30,127.000,0.12666,4.970,0.002
45.42,127.200,0.12708,4.983,0.003
45.54,127.400,0.12745,4.996,0.003
45.62,127.600,0.12783,5.005,0.003
45.67,127.800,0.12816,5.011,0.003
45.73,128.000,0.12849,5.018,0.003
45.81,128.200,0.12882,5.026,0.003
45.87,128.400,0.12911,5.033,0.003
45.92,128.600,0.12936,5.038,0.003
46.01,128.800,0.12965,5.048,0.003
46.05,129.000,0.12994,5.053,0.003
46.10,129.200,0.13019,5.058,0.003
46.17,129.400,0.13048,5.066,0.003
46.25,129.600,0.13078,5.074,0.003
46.32,129.800,0.13102,5.082,0.003
46.44,130.000,0.13136,5.095,0.003
46.51,130.200,0.13165,5.103,0.003
46.59,130.400,0.13194,5.112,0.003
46.68,130.600,0.13223,5.121,0.003
46.72,130.800,0.13256,5.126,0.003
46.77,131.000,0.13285,5.132,0.003
46.79,131.200,0.13319,5.134,0.003
46.85,131.400,0.13352,5.140,0.003
46.95,131.600,0.13385,5.151,0.003
47.04,131.800,0.13422,5.162,0.003
47.07,132.000,0.13460,5.164,0.003
47.17,132.200,0.13501,5.175,0.003
47.22,132.400,0.13543,5.181,0.003
47.23,132.600,0.13585,5.183,0.003
47.30,132.800,0.13622,5.190,0.003
47.33,133.000,0.13664,5.193,0.003
47.37,133.200,0.13701,5.197,0.003
47.39,133.400,0.13738,5.200,0.003
47.42,133.600,0.13772,5.203,0.003
47.44,133.800,0.13805,5.206,0.003
47.47,134.000,0.13834,5.208,0.003
47.51,134.200,0.13863,5.213,0.003
47.53,134.400,0.13892,5.215,0.003
47.59,134.600,0.13917,5.222,0.003
47.63,134.800,0.13946,5.226,0.003
47.68,135.000,0.13971,5.231,0.003
47.72,135.200,0.14000,5.236,0.003
47.77,135.400,0.14025,5.241,0.003
47.78,135.600,0.14054,5.243,0.003
47.82,135.800,0.14083,5.246,0.003
47.85,136.000,0.14112,5.250,0.003
47.91,136.200,0.14146,5.256,0.003
47.94,136.400,0.14175,5.260,0.003
47.95,136.600,0.14204,5.262,0.003
48.00,136.800,0.14237,5.266,0.003
47.94,137.000,0.14266,5.260,0.003
47.98,137.200,0.14299,5.265,0.003
48.01,137.400,0.14333,5.267,0.003
48.12,137.600,0.14374,5.280,0.003
48.18,137.800,0.14412,5.287,0.003
48.19,138.000,0.14453,5.287,0.003
48.20,138.200,0.14499,5.289,0.003
48.17,138.400,0.14540,5.285,0.003
48.08,138.600,0.14582,5.275,0.003
48.01,138.800,0.14623,5.267,0.003
47.95,139.000,0.14661,5.261,0.003
47.89,139.200,0.14698,5.255,0.003
47.88,139.400,0.14727,5.254,0.003
47.89,139.600,0.14761,5.255,0.003
47.88,139.800,0.14790,5.253,0.003
47.89,140.000,0.14819,5.255,0.003
47.92,140.200,0.14844,5.258,0.003
47.93,140.400,0.14873,5.259,0.003
47.94,140.600,0.14902,5.260,0.003
47.94,140.800,0.14927,5.260,0.003
47.97,141.000,0.14956,5.263,0.003
48.03,141.200,0.14985,5.270,0.003
48.07,141.400,0.15014,5.274,0.003
48.11,141.600,0.15047,5.279,0.003
48.12,141.800,0.15076,5.280,0.003
48.12,142.000,0.15105,5.280,0.003
48.11,142.200,0.15139,5.278,0.003
48.05,142.400,0.15168,5.272,0.003
48.04,142.600,0.15201,5.271,0.003
47.97,142.800,0.15234,5.263,0.003
47.95,143.000,0.15272,5.261,0.003
47.94,143.200,0.15309,5.260,0.003
47.94,143.400,0.15347,5.260,0.003
47.93,143.600,0.15388,5.259,0.003
47.88,143.800,0.15434,5.253,0.003
47.75,144.000,0.15479,5.240,0.003
47.69,144.200,0.15521,5.232,0.003
47.58,144.400,0.15563,5.221,0.003
47.52,144.600,0.15600,5.214,0.003
47.47,144.800,0.15637,5.208,0.003
47.37,145.000,0.15671,5.198,0.003
47.30,145.200,0.15704,5.189,0.003
47.18,145.400,0.15733,5.177,0.003
47.08,145.600,0.15762,5.166,0.003
47.02,145.800,0.15791,5.159,0.003
46.98,146.000,0.15816,5.154,0.003
46.94,146.200,0.15845,5.150,0.003
46.93,146.400,0.15870,5.150,0.003
46.96,146.600,0.15899,5.152,0.003
46.96,146.800,0.15928,5.152,0.003
46.97,147.000,0.15962,5.153,0.003
46.98,147.200,0.15991,5.155,0.003
46.96,147.400,0.16020,5.152,0.003
46.98,147.600,0.16053,5.155,0.003
47.01,147.800,0.16086,5.158,0.003
47.00,148.000,0.16115,5.157,0.003
47.01,148.200,0.16149,5.158,0.003
47.00,148.400,0.16182,5.157,0.003
47.02,148.600,0.16215,5.159,0.003
46.99,148.800,0.16252,5.156,0.003
46.96,149.000,0.16290,5.152,0.003
46.96,149.200,0.16331,5.152,0.003
46.93,149.400,0.16373,5.149,0.003
46.88,149.600,0.16419,5.144,0.003
46.83,149.800,0.16460,5.138,0.003
46.79,150.000,0.16502,5.134,0.003
46.74,150.200,0.16539,5.129,0.003
46.69,150.400,0.16572,5.123,0.003
46.66,150.600,0.16610,5.120,0.003
46.64,150.800,0.16639,5.118,0.003
46.63,151.000,0.16672,5.116,0.003
46.65,151.200,0.16701,5.119,0.003
46.64,151.400,0.16726,5.117,0.003
46.66,151.600,0.16755,5.119,0.003
46.64,151.800,0.16780,5.118,0.003
46.64,152.000,0.16809,5.117,0.003
46.62,152.200,0.16834,5.115,0.003
46.59,152.400,0.16863,5.112,0.003
46.59,152.600,0.16892,5.112,0.003
46.58,152.800,0.16921,5.111,0.003
46.60,153.000,0.16951,5.113,0.003
46.61,153.200,0.16980,5.114,0.003
46.59,153.400,0.17013,5.112,0.003
46.57,153.600,0.17042,5.110,0.003
46.57,153.800,0.17075,5.110,0.003
46.56,154.000,0.17104,5.108,0.003
46.55,154.200,0.17138,5.107,0.003
46.49,154.400,0.17171,5.101,0.003
46.44,154.600,0.17208,5.096,0.003
46.40,154.800,0.17250,5.091,0.003
46.33,155.000,0.17291,5.084,0.003
46.31,155.200,0.17337,5.081,0.003
46.26,155.400,0.17383,5.076,0.003
46.27,155.600,0.17424,5.076,0.003
46.18,155.800,0.17462,5.067,0.003
46.14,156.000,0.17503,5.063,0.003
46.09,156.200,0.17537,5.057,0.003
46.09,156.400,0.17570,5.057,0.003
46.04,156.600,0.17599,5.052,0.003
46.02,156.800,0.17628,5.050,0.003
46.02,157.000,0.17657,5.049,0.003
45.99,157.200,0.17682,5.046,0.003
46.02,157.400,0.17711,5.050,0.003
46.05,157.600,0.17736,5.053,0.003
46.06,157.800,0.17761,5.054,0.003
46.07,158.000,0.17790,5.054,0.004
46.06,158.200,0.17819,5.054,0.004
46.08,158.400,0.17848,5.056,0.004
46.14,158.600,0.17877,5.062,0.004
46.16,158.800,0.17906,5.065,0.004
46.20,159.000,0.17940,5.069,0.004
46.20,159.200,0.17969,5.070,0.004
46.22,159.400,0.18002,5.072,0.004
46.22,159.600,0.18035,5.071,0.004
46.23,159.800,0.18068,5.072,0.004
46.27,160.000,0.18102,5.077,0.004
46.35,160.200,0.18139,5.085,0.004
46.38,160.400,0.18181,5.088,0.004
46.33,160.600,0.18222,5.084,0.004
46.34,160.800,0.18264,5.084,0.004
46.32,161.000,0.18309,5.082,0.004
46.30,161.200,0.18355,5.080,0.004
46.20,161.400,0.18393,5.070,0.004
46.17,161.600,0.18434,5.066,0.004
46.10,161.800,0.18472,5.058,0.004
46.01,162.000,0.18505,5.049,0.004
45.81,162.200,0.18534,5.026,0.004
45.71,162.400,0.18567,5.015,0.004
45.65,162.600,0.18596,5.009,0.004
45.57,162.800,0.18621,5.000,0.004
45.47,163.000,0.18650,4.990,0.004
45.46,163.200,0.18675,4.987,0.004
45.45,163.400,0.18704,4.987,0.004
45.47,163.600,0.18729,4.989,0.004
45.44,163.800,0.18758,4.986,0.004
45.44,164.000,0.18791,4.985,0.004
45.38,164.200,0.18821,4.979,0.004
45.33,164.400,0.18850,4.974,0.004
45.29,164.600,0.18879,4.970,0.004
45.28,164.800,0.18912,4.968,0.004
45.26,165.000,0.18941,4.966,0.004
45.22,165.200,0.18974,4.961,0.004
45.22,165.400,0.19003,4.962,0.004
45.23,165.600,0.19037,4.962,0.004
45.26,165.800,0.19074,4.966,0.004
45.29,166.000,0.19111,4.969,0.004
45.31,166.200,0.19149,4.971,0.004
45.31,166.400,0.19195,4.971,0.004
45.33,166.600,0.19236,4.973,0.004
45.28,166.800,0.19278,4.968,0.004
45.20,167.000,0.19319,4.959,0.004
45.16,167.200,0.19357,4.955,0.004
45.13,167.400,0.19394,4.952,0.004
45.12,167.600,0.19431,4.951,0.004
45.14,167.800,0.19461,4.952,0.004
45.16,168.000,0.19490,4.955,0.004
45.22,168.200,0.19523,4.962,0.004
45.27,168.400,0.19552,4.967,0.004
45.28,168.600,0.19577,4.968,0.004
45.35,168.800,0.19606,4.976,0.004
45.39,169.000,0.19631,4.980,0.004
45.42,169.200,0.19656,4.983,0.004
45.48,169.400,0.19685,4.990,0.004
45.56,169.600,0.19714,4.999,0.004
45.61,169.800,0.19743,5.004,0.004
45.64,170.000,0.19772,5.007,0.004
45.62,170.200,0.19801,5.005,0.004
45.64,170.400,0.19830,5.007,0.004
45.68,170.600,0.19864,5.012,0.004
45.68,170.800,0.19893,5.012,0.004
45.62,171.000,0.19926,5.006,0.004
45.57,171.200,0.19959,5.000,0.004
45.50,171.400,0.19992,4.992,0.004
45.35,171.600,0.20030,4.976,0.004
45.29,171.800,0.20067,4.969,0.004
45.30,172.000,0.20109,4.971,0.004
45.33,172.200,0.20155,4.974,0.004
45.42,172.400,0.20200,4.984,0.004
45.47,172.600,0.20242,4.989,0.004
45.53,172.800,0.20288,4.996,0.004
45.54,173.000,0.20325,4.997,0.004
45.50,173.200,0.20362,4.992,0.004
45.47,173.400,0.20396,4.989,0.004
45.46,173.600,0.20425,4.988,0.004
45.48,173.800,0.20454,4.990,0.004
45.51,174.000,0.20483,4.993,0.004
45.56,174.200,0.20512,4.999,0.004
45.61,174.400,0.20537,5.004,0.004
45.65,174.600,0.20562,5.008,0.004
45.68,174.800,0.20591,5.012,0.004
45.79,175.000,0.20620,5.024,0.004
45.89,175.200,0.20649,5.035,0.004
45.96,175.400,0.20678,5.043,0.004
46.02,175.600,0.20707,5.049,0.004
46.08,175.800,0.20736,5.056,0.004
46.20,176.000,0.20770,5.069,0.004
46.33,176.200,0.20799,5.083,0.004
46.44,176.400,0.20832,5.096,0.004
46.57,176.600,0.20865,5.109,0.004
46.69,176.800,0.20898,5.123,0.004
46.82,177.000,0.20932,5.137,0.004
46.95,177.200,0.20969,5.151,0.004
47.11,177.400,0.21011,5.169,0.004
47.31,177.600,0.21052,5.191,0.004
47.51,177.800,0.21094,5.213,0.004
47.74,178.000,0.21139,5.238,0.004
47.88,178.200,0.21181,5.254,0.004
48.07,178.400,0.21223,5.275,0.004
48.19,178.600,0.21260,5.287,0.004
48.28,178.800,0.21297,5.297,0.004
48.35,179.000,0.21335,5.305,0.004
48.41,179.200,0.21364,5.311,0.004
48.52,179.400,0.21393,5.323,0.004
48.55,179.600,0.21426,5.327,0.004
48.65,179.800,0.21455,5.338,0.004
48.68,180.000,0.21480,5.342,0.004
48.74,180.200,0.21509,5.348,0.004
48.81,180.400,0.21534,5.355,0.004
48.89,180.600,0.21563,5.365,0.004
49.04,180.800,0.21592,5.380,0.004
49.09,181.000,0.21621,5.387,0.004
49.23,181.200,0.21655,5.402,0.004
49.36,181.400,0.21684,5.416,0.004
49.48,181.600,0.21717,5.429,0.004
49.62,181.800,0.21746,5.445,0.004
49.81,182.000,0.21779,5.465,0.004
49.98,182.200,0.21813,5.484,0.004
50.13,182.400,0.21842,5.501,0.004
50.31,182.600,0.21879,5.520,0.004
50.46,182.800,0.21912,5.537,0.004
50.66,183.000,0.21950,5.558,0.004
50.91,183.200,0.21991,5.586,0.004
51.17,183.400,0.22033,5.615,0.004
51.44,183.600,0.22074,5.644,0.004
51.65,183.800,0.22116,5.668,0.004
51.83,184.000,0.22158,5.687,0.004
51.96,184.200,0.22199,5.701,0.004
52.08,184.400,0.22236,5.715,0.004
52.24,184.600,0.22270,5.732,0.004
52.35,184.800,0.22303,5.744,0.004
52.46,185.000,0.22332,5.756,0.004
52.61,185.200,0.22365,5.773,0.004
52.75,185.400,0.22394,5.787,0.004
52.91,185.600,0.22419,5.805,0.004
53.03,185.800,0.22448,5.818,0.004
53.15,186.000,0.22473,5.832,0.004
53.27,186.200,0.22502,5.845,0.004
53.42,186.400,0.22532,5.861,0.004
53.59,186.600,0.22561,5.880,0.004
53.76,186.800,0.22590,5.899,0.004
53.92,187.000,0.22619,5.916,0.004
54.08,187.200,0.22652,5.934,0.004
54.22,187.400,0.22681,5.949,0.004
54.39,187.600,0.22714,5.968,0.004
54.55,187.800,0.22743,5.985,0.004
54.76,188.000,0.22777,6.009,0.004
54.94,188.200,0.22810,6.028,0.004
55.11,188.400,0.22843,6.047,0.004
55.33,188.600,0.22881,6.071,0.005
55.54,188.800,0.22922,6.094,0.005
55.76,189.000,0.22964,6.118,0.005
55.98,189.200,0.23009,6.142,0.005
56.17,189.400,0.23055,6.163,0.005
56.32,189.600,0.23097,6.180,0.005
56.48,189.800,0.23138,6.197,0.005
56.61,190.000,0.23176,6.212,0.005
56.68,190.200,0.23213,6.219,0.005
56.74,190.400,0.23246,6.226,0.005
56.80,190.600,0.23275,6.232,0.005
56.81,190.800,0.23304,6.234,0.005
56.83,191.000,0.23334,6.235,0.005
56.79,191.200,0.23358,6.231,0.005
56.73,191.400,0.23388,6.224,0.005
56.66,191.600,0.23413,6.217,0.005
56.64,191.800,0.23442,6.215,0.005
56.65,192.000,0.23471,6.216,0.005
56.64,192.200,0.23500,6.215,0.005
56.62,192.400,0.23529,6.212,0.005
56.64,192.600,0.23558,6.215,0.005
56.64,192.800,0.23587,6.214,0.005
56.57,193.000,0.23620,6.207,0.005
56.53,193.200,0.23649,6.203,0.005
56.43,193.400,0.23683,6.192,0.005
56.45,193.600,0.23716,6.194,0.005
56.44,193.800,0.23749,6.192,0.005
56.48,194.000,0.23782,6.197,0.005
56.58,194.200,0.23820,6.208,0.005
56.66,194.400,0.23857,6.216,0.005
56.74,194.600,0.23903,6.226,0.005
56.80,194.800,0.23949,6.232,0.005
56.77,195.000,0.23990,6.229,0.005
56.75,195.200,0.24032,6.226,0.005
56.77,195.400,0.24073,6.228,0.005
56.80,195.600,0.24115,6.232,0.005
56.86,195.800,0.24148,6.239,0.005
56.96,196.000,0.24181,6.249,0.005
57.00,196.200,0.24215,6.254,0.005
57.06,196.400,0.24244,6.261,0.005
57.11,196.600,0.24273,6.267,0.005
57.20,196.800,0.24302,6.276,0.005
57.24,197.000,0.24327,6.281,0.005
57.32,197.200,0.24356,6.289,0.005
57.39,197.400,0.24385,6.297,0.005
57.47,197.600,0.24410,6.306,0.005
57.55,197.800,0.24439,6.315,0.005
57.66,198.000,0.24468,6.327,0.005
57.75,198.200,0.24501,6.337,0.005
57.83,198.400,0.24530,6.345,0.005
57.86,198.600,0.24559,6.349,0.005
57.89,198.800,0.24593,6.352,0.005
57.95,199.000,0.24622,6.358,0.005
57.98,199.200,0.24655,6.362,0.005
58.05,199.400,0.24688,6.369,0.005
58.13,199.600,0.24722,6.378,0.005
58.19,199.800,0.24755,6.385,0.005
58.32,200.000,0.24792,6.399,0.005
58.45,200.200,0.24834,6.413,0.005
58.57,200.400,0.24875,6.426,0.005
58.67,200.600,0.24917,6.438,0.005
58.68,200.800,0.24958,6.438,0.005
58.71,201.000,0.24996,6.442,0.005
58.73,201.200,0.25037,6.444,0.005
58.75,201.400,0.25071,6.447,0.005
58.75,201.600,0.25104,6.446,0.005
58.77,201.800,0.25137,6.448,0.005
58.79,202.000,0.25170,6.450,0.005
58.81,202.200,0.25199,6.453,0.005
58.82,202.400,0.25228,6.453,0.005
58.83,202.600,0.25253,6.455,0.005
58.85,202.800,0.25283,6.457,0.005
58.85,203.000,0.25307,6.457,0.005
58.84,203.200,0.25337,6.456,0.005
58.85,203.400,0.25361,6.457,0.005
58.84,203.600,0.25391,6.456,0.005
58.74,203.800,0.25420,6.445,0.005
58.69,204.000,0.25449,6.440,0.005
58.67,204.200,0.25482,6.437,0.005
58.69,204.400,0.25511,6.439,0.005
58.74,204.600,0.25540,6.445,0.005
58.82,204.800,0.25573,6.454,0.005
58.91,205.000,0.25602,6.463,0.005
59.02,205.200,0.25636,6.476,0.005
59.14,205.400,0.25669,6.489,0.005
59.24,205.600,0.25706,6.500,0.005
59.39,205.800,0.25748,6.517,0.005
59.58,206.000,0.25789,6.537,0.005
59.79,206.200,0.25831,6.560,0.005
59.98,206.400,0.25873,6.581,0.005
60.11,206.600,0.25918,6.596,0.005
60.21,206.800,0.25956,6.607,0.005
60.41,207.000,0.25997,6.628,0.005
60.56,207.200,0.26035,6.645,0.005
60.68,207.400,0.26068,6.658,0.005
60.78,207.600,0.26097,6.669,0.005
60.86,207.800,0.26130,6.678,0.005
60.95,208.000,0.26155,6.687,0.005
61.05,208.200,0.26184,6.699,0.005
61.17,208.400,0.26213,6.712,0.005
61.31,208.600,0.26238,6.727,0.005
61.48,208.800,0.26267,6.745,0.005
61.64,209.000,0.26296,6.764,0.005
61.80,209.200,0.26326,6.781,0.005
61.96,209.400,0.26355,6.799,0.005
62.13,209.600,0.26384,6.817,0.005
62.25,209.800,0.26413,6.830,0.005
62.42,210.000,0.26446,6.849,0.005
62.57,210.200,0.26475,6.865,0.005
62.70,210.400,0.26508,6.880,0.005
62.87,210.600,0.26542,6.898,0.005
63.03,210.800,0.26575,6.916,0.005
63.17,211.000,0.26608,6.931,0.005
63.33,211.200,0.26646,6.949,0.005
63.48,211.400,0.26683,6.965,0.005
63.55,211.600,0.26725,6.972,0.005
63.65,211.800,0.26770,6.984,0.005
63.74,212.000,0.26812,6.993,0.005
63.75,212.200,0.26857,6.995,0.005
63.76,212.400,0.26899,6.996,0.005
63.50,212.600,0.26936,6.967,0.005
63.42,212.800,0.26974,6.958,0.005
63.46,213.000,0.27011,6.963,0.005
63.54,213.200,0.27040,6.971,0.005
63.60,213.400,0.27074,6.979,0.005
63.69,213.600,0.27103,6.988,0.005
63.78,213.800,0.27132,6.998,0.005
63.89,214.000,0.27161,7.010,0.005
64.00,214.200,0.27186,7.022,0.005
64.13,214.400,0.27215,7.036,0.005
64.28,214.600,0.27244,7.053,0.005
64.40,214.800,0.27273,7.066,0.005
64.53,215.000,0.27302,7.081,0.005
64.72,215.200,0.27335,7.101,0.005
64.88,215.400,0.27364,7.118,0.005
65.05,215.600,0.27394,7.138,0.005
65.20,215.800,0.27427,7.154,0.005
65.36,216.000,0.27456,7.171,0.005
65.53,216.200,0.27489,7.190,0.005
65.74,216.400,0.27522,7.213,0.005
65.98,216.600,0.27560,7.239,0.005
66.23,216.800,0.27593,7.267,0.005
66.49,217.000,0.27635,7.296,0.005
66.77,217.200,0.27672,7.327,0.005
67.05,217.400,0.27718,7.357,0.005
67.32,217.600,0.27759,7.386,0.005
67.59,217.800,0.27801,7.416,0.005
67.82,218.000,0.27842,7.441,0.005
68.01,218.200,0.27880,7.462,0.005
68.23,218.400,0.27917,7.487,0.005
68.41,218.600,0.27950,7.506,0.006
68.58,218.800,0.27984,7.525,0.006
68.75,219.000,0.28013,7.543,0.006
68.89,219.200,0.28042,7.558,0.006
69.01,219.400,0.28071,7.572,0.006
69.07,219.600,0.28100,7.579,0.006
69.07,219.800,0.28125,7.578,0.006
69.09,220.000,0.28154,7.581,0.006
69.13,220.200,0.28179,7.586,0.006
69.23,220.400,0.28208,7.596,0.006
69.31,220.600,0.28237,7.605,0.006
69.43,220.800,0.28266,7.618,0.006
69.52,221.000,0.28295,7.628,0.006
69.67,221.200,0.28324,7.644,0.006
69.80,221.400,0.28358,7.658,0.006
69.93,221.600,0.28387,7.673,0.006
70.10,221.800,0.28420,7.692,0.006
70.29,222.000,0.28449,7.713,0.006
70.49,222.200,0.28482,7.734,0.006
70.69,222.400,0.28516,7.757,0.006
70.98,222.600,0.28553,7.788,0.006
71.26,222.800,0.28595,7.819,0.006
71.51,223.000,0.28636,7.846,0.006
71.77,223.200,0.28682,7.875,0.006
72.04,223.400,0.28723,7.904,0.006
72.34,223.600,0.28769,7.937,0.006
72.56,223.800,0.28806,7.962,0.006
72.81,224.000,0.28844,7.989,0.006
73.00,224.200,0.28881,8.010,0.006
73.20,224.400,0.28914,8.031,0.006
73.38,224.600,0.28944,8.052,0.006
73.55,224.800,0.28973,8.070,0.006
73.72,225.000,0.28998,8.089,0.006
73.87,225.200,0.29027,8.105,0.006
74.03,225.400,0.29052,8.123,0.006
74.17,225.600,0.29081,8.138,0.006
74.34,225.800,0.29106,8.157,0.006
74.50,226.000,0.29135,8.174,0.006
74.67,226.200,0.29164,8.193,0.006
74.87,226.400,0.29193,8.215,0.006
75.08,226.600,0.29222,8.238,0.006
75.28,226.800,0.29255,8.260,0.006
75.48,227.000,0.29284,8.282,0.006
75.68,227.200,0.29313,8.304,0.006
75.91,227.400,0.29347,8.329,0.006
76.09,227.600,0.29380,8.349,0.006
76.32,227.800,0.29413,8.374,0.006
0.99,227.950,0.29438,0.109,0.006