File: data-files/CWRU/0900-05-24D.txt
""
"Test Method","Will_Huddleston_Disks.msm"
"Sample I. D.","900-5-24D.mss"
"Specimen Number","1"

"Load (N)","Time (s)","Extension (mm)","Stress (MPa)","Strain (mm/mm)"

5.05,0.200,-0.07956,0.328,-0.002
5.04,0.300,-0.07956,0.327,-0.002
5.05,0.400,-0.07951,0.327,-0.002
5.04,0.500,-0.07951,0.327,-0.002
5.04,0.600,-0.07951,0.327,-0.002
5.04,0.700,-0.07947,0.327,-0.002
5.04,0.800,-0.07947,0.327,-0.002
5.04,0.900,-0.07947,0.327,-0.002
5.04,1.000,-0.07943,0.327,-0.002
5.04,1.100,-0.07943,0.327,-0.002
5.04,1.200,-0.07939,0.327,-0.002
5.04,1.300,-0.07939,0.327,-0.002
5.04,1.400,-0.07939,0.327,-0.002
5.05,1.500,-0.07935,0.327,-0.002
5.04,1.600,-0.07935,0.327,-0.002
5.07,1.700,-0.07931,0.329,-0.002
5.06,1.800,-0.07931,0.328,-0.002
5.06,1.900,-0.07927,0.328,-0.002
5.07,2.000,-0.07922,0.329,-0.002
5.08,2.100,-0.07922,0.330,-0.002
5.11,2.200,-0.07914,0.332,-0.002
5.14,2.300,-0.07910,0.333,-0.002
5.20,2.400,-0.07902,0.337,-0.002
5.29,2.500,-0.07893,0.343,-0.002
5.43,2.600,-0.07881,0.352,-0.002
5.57,2.700,-0.07860,0.361,-0.002
5.64,2.800,-0.07843,0.366,-0.002
5.70,2.900,-0.07823,0.370,-0.002
5.75,3.000,-0.07806,0.373,-0.002
5.80,3.100,-0.07785,0.376,-0.002
5.86,3.200,-0.07769,0.380,-0.002
5.93,3.300,-0.07748,0.385,-0.002
5.99,3.400,-0.07731,0.389,-0.002
6.06,3.500,-0.07710,0.393,-0.002
6.14,3.600,-0.07690,0.398,-0.002
6.21,3.700,-0.07669,0.403,-0.002
6.25,3.800,-0.07652,0.406,-0.002
6.32,3.900,-0.07631,0.410,-0.002
6.40,4.000,-0.07615,0.415,-0.001
6.44,4.100,-0.07594,0.418,-0.001
6.49,4.200,-0.07577,0.421,-0.001
6.55,4.300,-0.07557,0.425,-0.001
6.59,4.400,-0.07540,0.428,-0.001
6.64,4.500,-0.07523,0.431,-0.001
6.66,4.600,-0.07507,0.432,-0.001
6.72,4.700,-0.07490,0.436,-0.001
6.76,4.800,-0.07474,0.439,-0.001
6.76,4.900,-0.07457,0.439,-0.001
6.78,5.000,-0.07444,0.440,-0.001
6.80,5.100,-0.07432,0.441,-0.001
6.82,5.200,-0.07415,0.442,-0.001
6.84,5.300,-0.07403,0.444,-0.001
6.84,5.400,-0.07390,0.444,-0.001
6.85,5.500,-0.07374,0.444,-0.001
6.88,5.600,-0.07361,0.446,-0.001
6.90,5.700,-0.07349,0.448,-0.001
6.92,5.800,-0.07336,0.449,-0.001
6.93,5.900,-0.07320,0.450,-0.001
6.93,6.000,-0.07307,0.449,-0.001
6.97,6.100,-0.07295,0.452,-0.001
6.97,6.200,-0.07282,0.452,-0.001
6.99,6.300,-0.07266,0.454,-0.001
7.03,6.400,-0.07253,0.456,-0.001
7.05,6.500,-0.07241,0.458,-0.001
7.08,6.600,-0.07224,0.459,-0.001
7.11,6.700,-0.07212,0.462,-0.001
7.14,6.800,-0.07195,0.463,-0.001
7.18,6.900,-0.07179,0.466,-0.001
7.21,7.000,-0.07166,0.468,-0.001
7.26,7.100,-0.07149,0.471,-0.001
7.28,7.200,-0.07137,0.472,-0.001
7.33,7.300,-0.07120,0.475,-0.001
7.37,7.400,-0.07104,0.478,-0.001
7.39,7.500,-0.07087,0.479,-0.001
7.45,7.600,-0.07070,0.483,-0.001
7.49,7.700,-0.07058,0.486,-0.001
7.53,7.800,-0.07041,0.489,-0.001
7.58,7.900,-0.07025,0.491,-0.001
7.61,8.000,-0.07008,0.493,-0.001
7.67,8.100,-0.06992,0.498,-0.001
7.72,8.200,-0.06975,0.501,-0.001
7.77,8.300,-0.06958,0.504,-0.001
7.81,8.400,-0.06942,0.507,-0.001
7.88,8.500,-0.06921,0.511,-0.001
7.92,8.600,-0.06904,0.514,-0.001
7.99,8.700,-0.06883,0.518,-0.001
8.07,8.800,-0.06863,0.523,-0.001
8.12,8.900,-0.06846,0.527,-0.001
8.20,9.000,-0.06825,0.532,-0.001
8.27,9.100,-0.06800,0.536,-0.001
8.36,9.200,-0.06780,0.542,-0.001
8.45,9.300,-0.06755,0.548,-0.001
8.51,9.400,-0.06734,0.552,-0.001
8.59,9.500,-0.06713,0.557,-0.001
8.68,9.600,-0.06692,0.563,-0.001
8.74,9.700,-0.06667,0.567,-0.001
8.83,9.800,-0.06647,0.572,-0.001
8.91,9.900,-0.06626,0.578,-0.001
8.97,10.000,-0.06609,0.582,-0.001
9.05,10.100,-0.06588,0.587,-0.001
9.14,10.200,-0.06572,0.593,-0.001
9.18,10.300,-0.06551,0.595,-0.001
9.24,10.400,-0.06534,0.599,-0.001
9.28,10.500,-0.06518,0.602,-0.001
9.35,10.600,-0.06505,0.607,-0.001
9.41,10.700,-0.06489,0.610,-0.001
9.46,10.800,-0.06472,0.614,-0.001
9.52,10.900,-0.06460,0.618,-0.001
9.56,11.000,-0.06443,0.620,-0.001
9.63,11.100,-0.06431,0.625,-0.001
9.68,11.200,-0.06418,0.628,-0.001
9.72,11.300,-0.06401,0.631,-0.001
9.79,11.400,-0.06389,0.635,-0.001
9.84,11.500,-0.06376,0.638,-0.001
9.88,11.600,-0.06360,0.641,-0.001
9.94,11.700,-0.06347,0.645,-0.001
10.01,11.800,-0.06335,0.649,-0.001
10.07,11.900,-0.06318,0.653,-0.001
10.11,12.000,-0.06306,0.656,-0.001
10.17,12.100,-0.06289,0.660,-0.001
10.24,12.200,-0.06277,0.664,-0.001
10.29,12.300,-0.06260,0.667,-0.001
10.36,12.400,-0.06248,0.672,-0.001
10.43,12.500,-0.06231,0.677,-0.001
10.49,12.600,-0.06214,0.681,-0.001
10.56,12.700,-0.06202,0.685,-0.001
10.62,12.800,-0.06185,0.689,-0.001
10.68,12.900,-0.06169,0.693,-0.001
10.75,13.000,-0.06156,0.697,-0.001
10.82,13.100,-0.06140,0.702,-0.001
10.87,13.200,-0.06123,0.705,-0.001
10.95,13.300,-0.06106,0.710,-0.001
11.01,13.400,-0.06094,0.714,-0.001
11.07,13.500,-0.06077,0.718,-0.001
11.15,13.600,-0.06061,0.723,-0.001
11.22,13.700,-0.06044,0.728,-0.001
11.29,13.800,-0.06027,0.733,-0.001
11.36,13.900,-0.06011,0.737,-0.001
11.44,14.000,-0.05994,0.742,-0.001
11.54,14.100,-0.05978,0.748,-0.001
11.61,14.200,-0.05957,0.753,-0.001
11.70,14.300,-0.05940,0.759,-0.001
11.78,14.400,-0.05919,0.764,-0.001
11.88,14.500,-0.05899,0.771,-0.001
11.97,14.600,-0.05878,0.777,-0.001
12.08,14.700,-0.05857,0.784,-0.001
12.17,14.800,-0.05836,0.789,-0.001
12.29,14.900,-0.05815,0.797,-0.001
12.36,15.000,-0.05795,0.802,-0.001
12.47,15.100,-0.05774,0.809,-0.001
12.55,15.200,-0.05753,0.814,-0.001
12.64,15.300,-0.05732,0.820,-0.001
12.73,15.400,-0.05712,0.826,-0.001
12.83,15.500,-0.05691,0.832,-0.001
12.91,15.600,-0.05674,0.838,-0.001
12.98,15.700,-0.05653,0.842,-0.001
13.06,15.800,-0.05633,0.848,-0.001
13.13,15.900,-0.05616,0.852,-0.001
13.19,16.000,-0.05599,0.856,-0.001
13.28,16.100,-0.05583,0.861,-0.001
13.34,16.200,-0.05566,0.865,-0.001
13.41,16.300,-0.05550,0.870,-0.001
13.48,16.400,-0.05537,0.874,-0.001
13.56,16.500,-0.05520,0.880,-0.001
13.60,16.600,-0.05508,0.882,-0.001
13.69,16.700,-0.05491,0.888,-0.001
13.73,16.800,-0.05479,0.891,-0.001
13.80,16.900,-0.05462,0.895,-0.001
13.85,17.000,-0.05450,0.899,-0.001
13.91,17.100,-0.05437,0.902,-0.001
13.96,17.200,-0.05421,0.906,-0.001
14.03,17.300,-0.05408,0.910,-0.001
14.09,17.400,-0.05396,0.914,-0.001
14.17,17.500,-0.05379,0.919,-0.001
14.21,17.600,-0.05367,0.922,-0.001
14.27,17.700,-0.05354,0.926,-0.001
14.35,17.800,-0.05338,0.931,-0.001
14.40,17.900,-0.05325,0.934,-0.001
14.47,18.000,-0.05309,0.939,-0.001
14.57,18.100,-0.05296,0.945,-0.001
14.63,18.200,-0.05279,0.949,-0.001
14.67,18.300,-0.05267,0.952,-0.001
14.76,18.400,-0.05250,0.958,-0.001
14.85,18.500,-0.05234,0.963,-0.001
14.93,18.600,-0.05217,0.968,-0.001
14.98,18.700,-0.05205,0.972,-0.001
15.07,18.800,-0.05188,0.978,-0.001
15.15,18.900,-0.05171,0.983,-0.001
15.21,19.000,-0.05155,0.987,-0.001
15.28,19.100,-0.05138,0.991,-0.001
15.35,19.200,-0.05122,0.996,-0.001
15.45,19.300,-0.05109,1.002,-0.001
15.51,19.400,-0.05092,1.006,-0.001
15.60,19.500,-0.05076,1.012,-0.001
15.70,19.600,-0.05059,1.018,-0.001
15.76,19.700,-0.05043,1.023,-0.001
15.85,19.800,-0.05022,1.028,-0.001
15.94,19.900,-0.05005,1.034,-0.001
16.05,20.000,-0.04984,1.041,-0.001
16.13,20.100,-0.04968,1.046,-0.001
16.24,20.200,-0.04947,1.053,-0.001
16.33,20.300,-0.04926,1.059,-0.001
16.45,20.400,-0.04905,1.067,-0.001
16.56,20.500,-0.04880,1.074,-0.001
16.64,20.600,-0.04860,1.080,-0.001
16.77,20.700,-0.04839,1.088,-0.001
16.86,20.800,-0.04818,1.093,-0.001
16.96,20.900,-0.04797,1.100,-0.001
17.06,21.000,-0.04777,1.106,-0.001
17.14,21.100,-0.04756,1.112,-0.001
17.24,21.200,-0.04735,1.119,-0.001
17.33,21.300,-0.04718,1.124,-0.001
17.42,21.400,-0.04698,1.130,-0.001
17.49,21.500,-0.04681,1.134,-0.001
17.56,21.600,-0.04664,1.139,-0.001
17.66,21.700,-0.04648,1.145,-0.001
17.72,21.800,-0.04631,1.150,-0.001
17.80,21.900,-0.04615,1.155,-0.001
17.87,22.000,-0.04598,1.159,-0.001
17.92,22.100,-0.04585,1.163,-0.001
17.99,22.200,-0.04569,1.167,-0.001
18.08,22.300,-0.04556,1.173,-0.001
18.13,22.400,-0.04544,1.176,-0.001
18.19,22.500,-0.04527,1.180,-0.001
18.25,22.600,-0.04515,1.184,-0.001
18.31,22.700,-0.04502,1.188,-0.001
18.37,22.800,-0.04490,1.192,-0.001
18.43,22.900,-0.04473,1.196,-0.001
18.51,23.000,-0.04461,1.201,-0.001
18.57,23.100,-0.04448,1.204,-0.001
18.63,23.200,-0.04436,1.208,-0.001
18.71,23.300,-0.04423,1.214,-0.001
18.78,23.400,-0.04407,1.218,-0.001
18.86,23.500,-0.04394,1.223,-0.001
18.94,23.600,-0.04378,1.229,-0.001
19.01,23.700,-0.04365,1.233,-0.001
19.08,23.800,-0.04349,1.238,-0.001
19.17,23.900,-0.04336,1.243,-0.001
19.24,24.000,-0.04319,1.248,-0.001
19.31,24.100,-0.04307,1.253,-0.001
19.41,24.200,-0.04290,1.259,-0.001
19.49,24.300,-0.04278,1.264,-0.001
19.55,24.400,-0.04261,1.268,-0.001
19.63,24.500,-0.04245,1.273,-0.001
19.71,24.600,-0.04228,1.279,-0.001
19.80,24.700,-0.04216,1.284,-0.001
19.88,24.800,-0.04199,1.289,-0.001
19.97,24.900,-0.04182,1.296,-0.001
20.05,25.000,-0.04166,1.301,-0.001
20.15,25.100,-0.04149,1.307,-0.001
20.22,25.200,-0.04132,1.312,-0.001
20.33,25.300,-0.04116,1.319,-0.001
20.38,25.400,-0.04099,1.322,-0.001
20.46,25.500,-0.04083,1.327,-0.001
20.56,25.600,-0.04066,1.334,-0.001
20.70,25.700,-0.04045,1.343,-0.001
20.78,25.800,-0.04024,1.348,-0.001
20.89,25.900,-0.04008,1.355,-0.001
21.00,26.000,-0.03987,1.362,-0.001
21.13,26.100,-0.03962,1.371,-0.001
21.25,26.200,-0.03941,1.378,-0.001
21.36,26.300,-0.03921,1.385,-0.001
21.46,26.400,-0.03896,1.392,-0.001
21.59,26.500,-0.03875,1.400,-0.001
21.69,26.600,-0.03854,1.407,-0.001
21.81,26.700,-0.03833,1.415,-0.001
21.91,26.800,-0.03812,1.421,-0.001
22.03,26.900,-0.03792,1.429,-0.001
22.14,27.000,-0.03775,1.436,-0.001
22.23,27.100,-0.03754,1.442,-0.001
22.33,27.200,-0.03738,1.448,-0.001
22.42,27.300,-0.03721,1.454,-0.001
22.49,27.400,-0.03700,1.459,-0.001
22.58,27.500,-0.03684,1.465,-0.001
22.66,27.600,-0.03671,1.470,-0.001
22.74,27.700,-0.03655,1.475,-0.001
22.81,27.800,-0.03638,1.480,-0.001
22.91,27.900,-0.03625,1.486,-0.001
22.98,28.000,-0.03609,1.491,-0.001
23.06,28.100,-0.03596,1.496,-0.001
23.12,28.200,-0.03580,1.500,-0.001
23.19,28.300,-0.03567,1.504,-0.001
23.27,28.400,-0.03555,1.510,-0.001
23.34,28.500,-0.03542,1.514,-0.001
23.41,28.600,-0.03526,1.519,-0.001
23.49,28.700,-0.03513,1.524,-0.001
23.56,28.800,-0.03501,1.529,-0.001
23.65,28.900,-0.03488,1.534,-0.001
23.72,29.000,-0.03472,1.539,-0.001
23.81,29.100,-0.03459,1.545,-0.001
23.89,29.200,-0.03447,1.550,-0.001
23.98,29.300,-0.03430,1.556,-0.001
24.07,29.400,-0.03418,1.561,-0.001
24.17,29.500,-0.03401,1.568,-0.001
24.24,29.600,-0.03384,1.572,-0.001
24.33,29.700,-0.03372,1.578,-0.001
24.43,29.800,-0.03355,1.585,-0.001
24.50,29.900,-0.03339,1.589,-0.001
24.61,30.000,-0.03322,1.596,-0.001
24.69,30.100,-0.03310,1.601,-0.001
24.78,30.200,-0.03293,1.607,-0.001
24.87,30.300,-0.03276,1.613,-0.001
24.98,30.400,-0.03260,1.620,-0.001
25.06,30.500,-0.03247,1.626,-0.001
25.15,30.600,-0.03231,1.632,-0.001
25.25,30.700,-0.03214,1.638,-0.001
25.34,30.800,-0.03197,1.644,-0.001
25.41,30.900,-0.03181,1.649,-0.001
25.52,31.000,-0.03164,1.656,-0.001
25.62,31.100,-0.03148,1.662,-0.001
25.73,31.200,-0.03131,1.669,-0.001
25.82,31.300,-0.03114,1.675,-0.001
25.95,31.400,-0.03094,1.684,-0.001
26.05,31.500,-0.03077,1.690,-0.001
26.18,31.600,-0.03056,1.698,-0.001
26.32,31.700,-0.03035,1.707,-0.001
26.46,31.800,-0.03010,1.716,-0.001
26.57,31.900,-0.02990,1.724,-0.001
26.71,32.000,-0.02969,1.733,-0.001
26.84,32.100,-0.02948,1.741,-0.001
26.98,32.200,-0.02927,1.750,-0.001
27.08,32.300,-0.02902,1.757,-0.001
27.22,32.400,-0.02886,1.765,-0.001
27.33,32.500,-0.02865,1.773,-0.001
27.42,32.600,-0.02844,1.779,-0.001
27.55,32.700,-0.02828,1.787,-0.001
27.66,32.800,-0.02807,1.795,-0.001
27.76,32.900,-0.02790,1.801,-0.001
27.84,33.000,-0.02774,1.806,-0.001
27.93,33.100,-0.02757,1.812,-0.001
28.04,33.200,-0.02740,1.819,-0.001
28.13,33.300,-0.02724,1.825,-0.001
28.21,33.400,-0.02711,1.830,-0.001
28.29,33.500,-0.02695,1.835,-0.001
28.40,33.600,-0.02678,1.843,-0.001
28.47,33.700,-0.02666,1.847,-0.001
28.55,33.800,-0.02653,1.852,-0.001
28.64,33.900,-0.02636,1.858,-0.001
28.73,34.000,-0.02624,1.864,-0.001
28.81,34.100,-0.02612,1.869,-0.001
28.89,34.200,-0.02595,1.874,-0.001
28.96,34.300,-0.02582,1.879,-0.001
29.05,34.400,-0.02570,1.885,-0.001
29.12,34.500,-0.02558,1.889,-0.001
29.21,34.600,-0.02541,1.895,-0.001
29.31,34.700,-0.02528,1.901,0.000
29.37,34.800,-0.02516,1.905,0.000
29.46,34.900,-0.02499,1.911,0.000
29.56,35.000,-0.02487,1.918,0.000
29.64,35.100,-0.02474,1.923,0.000
29.73,35.200,-0.02458,1.928,0.000
29.84,35.300,-0.02441,1.936,0.000
29.97,35.400,-0.02429,1.944,0.000
30.05,35.500,-0.02412,1.949,0.000
30.13,35.600,-0.02400,1.955,0.000
30.21,35.700,-0.02383,1.960,0.000
30.35,35.800,-0.02366,1.969,0.000
30.41,35.900,-0.02354,1.973,0.000
30.50,36.000,-0.02337,1.978,0.000
30.61,36.100,-0.02321,1.986,0.000
30.71,36.200,-0.02304,1.992,0.000
30.84,36.300,-0.02292,2.001,0.000
30.92,36.400,-0.02275,2.006,0.000
31.05,36.500,-0.02258,2.014,0.000
31.15,36.600,-0.02242,2.020,0.000
31.27,36.700,-0.02225,2.029,0.000
31.37,36.800,-0.02208,2.035,0.000
31.49,36.900,-0.02192,2.043,0.000
31.60,37.000,-0.02175,2.050,0.000
31.73,37.100,-0.02154,2.059,0.000
31.89,37.200,-0.02134,2.069,0.000
32.04,37.300,-0.02113,2.079,0.000
32.20,37.400,-0.02092,2.089,0.000
32.34,37.500,-0.02071,2.098,0.000
32.51,37.600,-0.02046,2.109,0.000
32.67,37.700,-0.02026,2.119,0.000
32.81,37.800,-0.02005,2.128,0.000
32.95,37.900,-0.01980,2.137,0.000
33.11,38.000,-0.01959,2.148,0.000
33.26,38.100,-0.01938,2.157,0.000
33.37,38.200,-0.01918,2.165,0.000
33.51,38.300,-0.01897,2.174,0.000
33.65,38.400,-0.01876,2.183,0.000
33.76,38.500,-0.01859,2.190,0.000
33.85,38.600,-0.01843,2.196,0.000
33.96,38.700,-0.01826,2.203,0.000
34.07,38.800,-0.01810,2.210,0.000
34.16,38.900,-0.01793,2.216,0.000
34.23,39.000,-0.01776,2.220,0.000
34.35,39.100,-0.01764,2.228,0.000
34.43,39.200,-0.01747,2.233,0.000
34.53,39.300,-0.01735,2.240,0.000
34.62,39.400,-0.01718,2.246,0.000
34.71,39.500,-0.01706,2.252,0.000
34.81,39.600,-0.01693,2.258,0.000
34.90,39.700,-0.01677,2.264,0.000
35.00,39.800,-0.01664,2.270,0.000
35.08,39.900,-0.01652,2.276,0.000
35.16,40.000,-0.01635,2.281,0.000
35.24,40.100,-0.01623,2.286,0.000
35.35,40.200,-0.01610,2.293,0.000
35.46,40.300,-0.01598,2.301,0.000
35.55,40.400,-0.01581,2.306,0.000
35.67,40.500,-0.01568,2.314,0.000
35.78,40.600,-0.01552,2.321,0.000
35.85,40.700,-0.01539,2.326,0.000
35.97,40.800,-0.01523,2.334,0.000
36.08,40.900,-0.01506,2.341,0.000
36.19,41.000,-0.01494,2.348,0.000
36.29,41.100,-0.01477,2.354,0.000
36.40,41.200,-0.01460,2.362,0.000
36.51,41.300,-0.01448,2.369,0.000
36.64,41.400,-0.01431,2.377,0.000
36.72,41.500,-0.01415,2.382,0.000
36.87,41.600,-0.01398,2.392,0.000
36.95,41.700,-0.01386,2.397,0.000
37.09,41.800,-0.01369,2.406,0.000
37.22,41.900,-0.01352,2.414,0.000
37.34,42.000,-0.01336,2.423,0.000
37.44,42.100,-0.01319,2.429,0.000
37.57,42.200,-0.01303,2.437,0.000
37.68,42.300,-0.01286,2.445,0.000
37.84,42.400,-0.01269,2.455,0.000
37.94,42.500,-0.01253,2.461,0.000
38.10,42.600,-0.01232,2.472,0.000
38.25,42.700,-0.01215,2.481,0.000
38.40,42.800,-0.01194,2.491,0.000
38.56,42.900,-0.01174,2.501,0.000
38.70,43.000,-0.01153,2.510,0.000
38.87,43.100,-0.01132,2.522,0.000
39.04,43.200,-0.01111,2.533,0.000
39.21,43.300,-0.01086,2.543,0.000
39.37,43.400,-0.01066,2.554,0.000
39.53,43.500,-0.01045,2.564,0.000
39.66,43.600,-0.01024,2.573,0.000
39.81,43.700,-0.01003,2.582,0.000
39.98,43.800,-0.00983,2.594,0.000
40.12,43.900,-0.00962,2.603,0.000
40.24,44.000,-0.00945,2.610,0.000
40.38,44.100,-0.00924,2.619,0.000
40.51,44.200,-0.00908,2.628,0.000
40.63,44.300,-0.00887,2.636,0.000
40.73,44.400,-0.00870,2.642,0.000
40.85,44.500,-0.00858,2.650,0.000
40.96,44.600,-0.00841,2.657,0.000
41.07,44.700,-0.00825,2.664,0.000
41.17,44.800,-0.00808,2.671,0.000
41.29,44.900,-0.00796,2.678,0.000
41.38,45.000,-0.00779,2.684,0.000
41.49,45.100,-0.00762,2.692,0.000
41.60,45.200,-0.00750,2.699,0.000
41.71,45.300,-0.00737,2.706,0.000
41.79,45.400,-0.00721,2.711,0.000
41.89,45.500,-0.00708,2.717,0.000
42.00,45.600,-0.00696,2.724,0.000
42.10,45.700,-0.00679,2.731,0.000
42.20,45.800,-0.00667,2.738,0.000
42.30,45.900,-0.00650,2.744,0.000
42.42,46.000,-0.00638,2.752,0.000
42.55,46.100,-0.00621,2.760,0.000
42.66,46.200,-0.00609,2.767,0.000
42.81,46.300,-0.00592,2.777,0.000
42.90,46.400,-0.00579,2.783,0.000
43.03,46.500,-0.00563,2.792,0.000
43.14,46.600,-0.00546,2.798,0.000
43.31,46.700,-0.00530,2.810,0.000
43.41,46.800,-0.00517,2.816,0.000
43.54,46.900,-0.00500,2.824,0.000
43.66,47.000,-0.00484,2.832,0.000
43.81,47.100,-0.00467,2.842,0.000
43.92,47.200,-0.00455,2.849,0.000
44.07,47.300,-0.00438,2.859,0.000
44.16,47.400,-0.00422,2.865,0.000
44.33,47.500,-0.00405,2.876,0.000
44.43,47.600,-0.00388,2.882,0.000
44.59,47.700,-0.00372,2.892,0.000
44.70,47.800,-0.00355,2.899,0.000
44.87,47.900,-0.00338,2.911,0.000
44.99,48.000,-0.00322,2.919,0.000
45.14,48.100,-0.00305,2.929,0.000
45.28,48.200,-0.00284,2.937,0.000
45.50,48.300,-0.00268,2.951,0.000
45.62,48.400,-0.00247,2.959,0.000
45.82,48.500,-0.00226,2.973,0.000
45.98,48.600,-0.00205,2.983,0.000
46.17,48.700,-0.00181,2.995,0.000
46.34,48.800,-0.00160,3.006,0.000
46.54,48.900,-0.00139,3.019,0.000
46.67,49.000,-0.00118,3.027,0.000
46.87,49.100,-0.00097,3.041,0.000
47.01,49.200,-0.00077,3.050,0.000
47.21,49.300,-0.00056,3.062,0.000
47.35,49.400,-0.00035,3.071,0.000
47.54,49.500,-0.00014,3.084,0.000
47.68,49.600,0.00006,3.093,0.000
47.86,49.700,0.00023,3.105,0.000
47.97,49.800,0.00040,3.112,0.000
48.12,49.900,0.00061,3.122,0.000
48.25,50.000,0.00077,3.130,0.000
48.41,50.100,0.00094,3.140,0.000
48.50,50.200,0.00110,3.146,0.000
48.64,50.300,0.00127,3.155,0.000
48.77,50.400,0.00139,3.163,0.000
48.91,50.500,0.00156,3.173,0.000
49.01,50.600,0.00173,3.179,0.000
49.14,50.700,0.00185,3.188,0.000
49.24,50.800,0.00198,3.194,0.000
49.34,50.900,0.00214,3.201,0.000
49.47,51.000,0.00227,3.209,0.000
49.58,51.100,0.00239,3.216,0.000
49.68,51.200,0.00256,3.223,0.000
49.83,51.300,0.00268,3.232,0.000
49.92,51.400,0.00281,3.238,0.000
50.05,51.500,0.00297,3.247,0.000
50.18,51.600,0.00310,3.255,0.000
50.31,51.700,0.00322,3.264,0.000
50.43,51.800,0.00339,3.272,0.000
50.56,51.900,0.00351,3.280,0.000
50.70,52.000,0.00368,3.289,0.000
50.81,52.100,0.00380,3.296,0.000
50.93,52.200,0.00397,3.304,0.000
51.08,52.300,0.00410,3.313,0.000
51.22,52.400,0.00426,3.323,0.000
51.37,52.500,0.00443,3.332,0.000
51.51,52.600,0.00455,3.341,0.000
51.65,52.700,0.00472,3.350,0.000
51.80,52.800,0.00489,3.360,0.000
51.91,52.900,0.00505,3.367,0.000
52.06,53.000,0.00518,3.377,0.000
52.20,53.100,0.00534,3.386,0.000
52.33,53.200,0.00551,3.395,0.000
52.49,53.300,0.00567,3.405,0.000
52.64,53.400,0.00584,3.415,0.000
52.78,53.500,0.00601,3.424,0.000
52.96,53.600,0.00617,3.435,0.000
53.11,53.700,0.00634,3.445,0.000
53.28,53.800,0.00651,3.456,0.000
53.46,53.900,0.00671,3.468,0.000
53.65,54.000,0.00692,3.481,0.000
53.82,54.100,0.00709,3.492,0.000
54.03,54.200,0.00730,3.505,0.000
54.22,54.300,0.00754,3.517,0.000
54.46,54.400,0.00775,3.533,0.000
54.63,54.500,0.00796,3.544,0.000
54.81,54.600,0.00817,3.556,0.000
55.02,54.700,0.00838,3.569,0.000
55.24,54.800,0.00858,3.583,0.000
55.42,54.900,0.00879,3.595,0.000
55.62,55.000,0.00900,3.608,0.000
55.80,55.100,0.00921,3.620,0.000
56.01,55.200,0.00941,3.634,0.000
56.16,55.300,0.00962,3.643,0.000
56.36,55.400,0.00979,3.656,0.000
56.52,55.500,0.00996,3.667,0.000
56.67,55.600,0.01012,3.676,0.000
56.81,55.700,0.01029,3.685,0.000
56.96,55.800,0.01045,3.695,0.000
57.11,55.900,0.01062,3.705,0.000
57.24,56.000,0.01079,3.713,0.000
57.36,56.100,0.01091,3.721,0.000
57.48,56.200,0.01108,3.729,0.000
57.59,56.300,0.01120,3.736,0.000
57.75,56.400,0.01137,3.746,0.000
57.87,56.500,0.01149,3.754,0.000
58.01,56.600,0.01162,3.763,0.000
58.10,56.700,0.01174,3.769,0.000
58.25,56.800,0.01187,3.779,0.000
58.36,56.900,0.01203,3.786,0.000
58.50,57.000,0.01216,3.795,0.000
58.66,57.100,0.01228,3.805,0.000
58.79,57.200,0.01245,3.814,0.000
58.91,57.300,0.01257,3.821,0.000
59.04,57.400,0.01270,3.830,0.000
59.16,57.500,0.01286,3.838,0.000
59.34,57.600,0.01299,3.849,0.000
59.50,57.700,0.01311,3.859,0.000
59.64,57.800,0.01328,3.869,0.000
59.79,57.900,0.01345,3.878,0.000
59.91,58.000,0.01357,3.887,0.000
60.07,58.100,0.01374,3.896,0.000
60.23,58.200,0.01386,3.907,0.000
60.37,58.300,0.01403,3.916,0.000
60.52,58.400,0.01419,3.926,0.000
60.70,58.500,0.01432,3.938,0.000
60.84,58.600,0.01448,3.947,0.000
61.02,58.700,0.01465,3.959,0.000
61.15,58.800,0.01482,3.967,0.000
61.32,58.900,0.01494,3.978,0.000
61.49,59.000,0.01511,3.989,0.000
61.68,59.100,0.01527,4.001,0.000
61.84,59.200,0.01544,4.012,0.000
62.03,59.300,0.01561,4.024,0.000
62.20,59.400,0.01581,4.035,0.000
62.43,59.500,0.01598,4.050,0.000
62.60,59.600,0.01615,4.061,0.000
62.81,59.700,0.01635,4.074,0.000
63.05,59.800,0.01656,4.090,0.000
63.27,59.900,0.01677,4.104,0.000
63.51,60.000,0.01698,4.120,0.000
63.75,60.100,0.01719,4.135,0.000
63.98,60.200,0.01739,4.151,0.000
64.22,60.300,0.01760,4.166,0.000
64.43,60.400,0.01785,4.180,0.000
64.70,60.500,0.01806,4.197,0.000
64.91,60.600,0.01827,4.211,0.000
65.14,60.700,0.01847,4.225,0.000
65.34,60.800,0.01868,4.239,0.000
65.55,60.900,0.01885,4.252,0.000
65.75,61.000,0.01906,4.265,0.000
65.96,61.100,0.01926,4.279,0.000
66.13,61.200,0.01943,4.290,0.000
66.31,61.300,0.01960,4.301,0.000
66.50,61.400,0.01976,4.314,0.000
66.66,61.500,0.01993,4.324,0.000
66.80,61.600,0.02005,4.333,0.000
66.97,61.700,0.02022,4.344,0.000
67.11,61.800,0.02039,4.353,0.000
67.28,61.900,0.02051,4.364,0.000
67.43,62.000,0.02068,4.374,0.000
67.59,62.100,0.02080,4.385,0.000
67.73,62.200,0.02097,4.394,0.000
67.87,62.300,0.02109,4.403,0.000
68.03,62.400,0.02122,4.413,0.000
68.17,62.500,0.02134,4.422,0.000
68.32,62.600,0.02147,4.432,0.000
68.46,62.700,0.02163,4.441,0.000
68.61,62.800,0.02176,4.451,0.000
68.78,62.900,0.02188,4.462,0.000
68.93,63.000,0.02205,4.472,0.000
69.11,63.100,0.02217,4.483,0.000
69.28,63.200,0.02234,4.494,0.000
69.47,63.300,0.02246,4.506,0.000
69.62,63.400,0.02263,4.516,0.000
69.77,63.500,0.02275,4.526,0.000
69.97,63.600,0.02292,4.539,0.000
70.17,63.700,0.02309,4.552,0.000
70.32,63.800,0.02321,4.562,0.000
70.52,63.900,0.02338,4.574,0.000
70.70,64.000,0.02350,4.586,0.000
70.87,64.100,0.02367,4.598,0.000
71.06,64.200,0.02383,4.610,0.000
71.25,64.300,0.02396,4.622,0.000
71.43,64.400,0.02413,4.634,0.000
71.63,64.500,0.02429,4.647,0.000
71.83,64.600,0.02446,4.659,0.000
72.02,64.700,0.02458,4.672,0.000
72.22,64.800,0.02475,4.685,0.000
72.42,64.900,0.02492,4.698,0.000
72.64,65.000,0.02508,4.712,0.000
72.86,65.100,0.02525,4.727,0.000
73.09,65.200,0.02541,4.741,0.001
73.38,65.300,0.02562,4.760,0.001
73.63,65.400,0.02579,4.776,0.001
73.90,65.500,0.02600,4.794,0.001
74.17,65.600,0.02620,4.811,0.001
74.47,65.700,0.02641,4.831,0.001
74.77,65.800,0.02662,4.851,0.001
75.09,65.900,0.02683,4.871,0.001
75.37,66.000,0.02703,4.889,0.001
75.64,66.100,0.02724,4.907,0.001
75.90,66.200,0.02745,4.924,0.001
76.21,66.300,0.02766,4.944,0.001
76.48,66.400,0.02787,4.961,0.001
76.76,66.500,0.02807,4.979,0.001
77.04,66.600,0.02828,4.998,0.001
77.27,66.700,0.02845,5.013,0.001
77.52,66.800,0.02861,5.029,0.001
77.75,66.900,0.02882,5.044,0.001
77.99,67.000,0.02899,5.059,0.001
78.22,67.100,0.02915,5.074,0.001
78.47,67.200,0.02932,5.090,0.001
78.68,67.300,0.02949,5.104,0.001
78.86,67.400,0.02961,5.116,0.001
79.07,67.500,0.02978,5.129,0.001
79.29,67.600,0.02994,5.144,0.001
79.48,67.700,0.03007,5.156,0.001
79.69,67.800,0.03023,5.170,0.001
79.89,67.900,0.03036,5.183,0.001
80.09,68.000,0.03048,5.195,0.001
80.27,68.100,0.03065,5.207,0.001
80.49,68.200,0.03077,5.221,0.001
80.68,68.300,0.03090,5.233,0.001
80.87,68.400,0.03107,5.246,0.001
81.08,68.500,0.03119,5.260,0.001
81.26,68.600,0.03131,5.271,0.001
81.47,68.700,0.03148,5.285,0.001
81.69,68.800,0.03161,5.299,0.001
81.90,68.900,0.03173,5.313,0.001
82.13,69.000,0.03190,5.328,0.001
82.35,69.100,0.03202,5.342,0.001
82.59,69.200,0.03219,5.358,0.001
82.81,69.300,0.03231,5.372,0.001
83.04,69.400,0.03248,5.387,0.001
83.28,69.500,0.03264,5.403,0.001
83.49,69.600,0.03277,5.416,0.001
83.74,69.700,0.03294,5.432,0.001
83.99,69.800,0.03310,5.449,0.001
84.27,69.900,0.03323,5.466,0.001
84.49,70.000,0.03339,5.481,0.001
84.76,70.100,0.03356,5.498,0.001
84.96,70.200,0.03373,5.512,0.001
85.22,70.300,0.03385,5.528,0.001
85.47,70.400,0.03402,5.545,0.001
85.71,70.500,0.03418,5.560,0.001
85.97,70.600,0.03435,5.577,0.001
86.25,70.700,0.03451,5.595,0.001
86.52,70.800,0.03468,5.613,0.001
86.80,70.900,0.03485,5.631,0.001
87.06,71.000,0.03501,5.647,0.001
87.40,71.100,0.03522,5.670,0.001
87.75,71.200,0.03543,5.692,0.001
88.11,71.300,0.03564,5.716,0.001
88.41,71.400,0.03584,5.735,0.001
88.77,71.500,0.03605,5.759,0.001
89.12,71.600,0.03626,5.782,0.001
89.49,71.700,0.03647,5.805,0.001
89.82,71.800,0.03668,5.826,0.001
90.19,71.900,0.03688,5.850,0.001
90.50,72.000,0.03709,5.871,0.001
90.84,72.100,0.03730,5.893,0.001
91.16,72.200,0.03751,5.914,0.001
91.50,72.300,0.03771,5.936,0.001
91.79,72.400,0.03792,5.955,0.001
92.10,72.500,0.03809,5.974,0.001
92.37,72.600,0.03830,5.992,0.001
92.64,72.700,0.03846,6.010,0.001
92.89,72.800,0.03863,6.026,0.001
93.17,72.900,0.03879,6.044,0.001
93.45,73.000,0.03896,6.062,0.001
93.68,73.100,0.03909,6.077,0.001
93.91,73.200,0.03925,6.092,0.001
94.11,73.300,0.03938,6.105,0.001
94.33,73.400,0.03950,6.119,0.001
94.57,73.500,0.03967,6.135,0.001
94.81,73.600,0.03979,6.151,0.001
95.08,73.700,0.03992,6.168,0.001
95.28,73.800,0.04008,6.181,0.001
95.51,73.900,0.04021,6.196,0.001
95.71,74.000,0.04033,6.209,0.001
95.98,74.100,0.04046,6.226,0.001
96.21,74.200,0.04062,6.241,0.001
96.47,74.300,0.04075,6.258,0.001
96.71,74.400,0.04087,6.274,0.001
96.94,74.500,0.04104,6.288,0.001
97.19,74.600,0.04116,6.304,0.001
97.47,74.700,0.04133,6.323,0.001
97.76,74.800,0.04145,6.342,0.001
98.02,74.900,0.04162,6.359,0.001
98.29,75.000,0.04175,6.376,0.001
98.57,75.100,0.04191,6.395,0.001
98.84,75.200,0.04208,6.412,0.001
99.12,75.300,0.04220,6.430,0.001
99.39,75.400,0.04237,6.447,0.001
99.68,75.500,0.04253,6.466,0.001
99.96,75.600,0.04270,6.484,0.001
100.28,75.700,0.04287,6.505,0.001
100.58,75.800,0.04303,6.524,0.001
100.83,75.900,0.04316,6.541,0.001
101.10,76.000,0.04332,6.559,0.001
101.38,76.100,0.04349,6.576,0.001
101.69,76.200,0.04366,6.596,0.001
101.98,76.300,0.04382,6.615,0.001
102.29,76.400,0.04399,6.636,0.001
102.60,76.500,0.04416,6.656,0.001
102.93,76.600,0.04432,6.677,0.001
103.26,76.700,0.04453,6.699,0.001
103.64,76.800,0.04470,6.723,0.001
103.98,76.900,0.04490,6.745,0.001
104.37,77.000,0.04511,6.770,0.001
104.75,77.100,0.04532,6.795,0.001
105.16,77.200,0.04553,6.822,0.001
105.54,77.300,0.04573,6.847,0.001
105.96,77.400,0.04594,6.874,0.001
106.34,77.500,0.04615,6.898,0.001
106.73,77.600,0.04640,6.923,0.001
107.11,77.700,0.04661,6.948,0.001
107.50,77.800,0.04682,6.974,0.001
107.84,77.900,0.04702,6.995,0.001
108.27,78.000,0.04723,7.023,0.001
108.61,78.100,0.04740,7.046,0.001
108.98,78.200,0.04760,7.070,0.001
109.29,78.300,0.04777,7.090,0.001
109.67,78.400,0.04798,7.114,0.001
109.95,78.500,0.04814,7.132,0.001
110.27,78.600,0.04831,7.153,0.001
110.55,78.700,0.04848,7.171,0.001
110.91,78.800,0.04864,7.195,0.001
111.15,78.900,0.04877,7.210,0.001
111.45,79.000,0.04893,7.230,0.001
111.68,79.100,0.04906,7.244,0.001
111.98,79.200,0.04923,7.264,0.001
112.23,79.300,0.04935,7.280,0.001
112.51,79.400,0.04947,7.299,0.001
112.75,79.500,0.04964,7.314,0.001
113.04,79.600,0.04977,7.333,0.001
113.25,79.700,0.04989,7.347,0.001
113.56,79.800,0.05002,7.366,0.001
113.82,79.900,0.05018,7.383,0.001
114.12,80.000,0.05031,7.403,0.001
114.36,80.100,0.05043,7.419,0.001
114.70,80.200,0.05060,7.441,0.001
114.95,80.300,0.05072,7.457,0.001
115.24,80.400,0.05089,7.476,0.001
115.54,80.500,0.05101,7.495,0.001
115.89,80.600,0.05118,7.518,0.001
116.15,80.700,0.05134,7.535,0.001
116.47,80.800,0.05147,7.556,0.001
116.78,80.900,0.05164,7.576,0.001
117.09,81.000,0.05176,7.596,0.001
117.39,81.100,0.05193,7.615,0.001
117.70,81.200,0.05209,7.635,0.001
118.00,81.300,0.05226,7.655,0.001
118.33,81.400,0.05243,7.676,0.001
118.64,81.500,0.05255,7.696,0.001
118.93,81.600,0.05272,7.715,0.001
119.23,81.700,0.05288,7.735,0.001
119.58,81.800,0.05301,7.757,0.001
119.88,81.900,0.05317,7.777,0.001
120.22,82.000,0.05334,7.799,0.001
120.59,82.100,0.05355,7.823,0.001
120.96,82.200,0.05371,7.847,0.001
121.33,82.300,0.05388,7.871,0.001
121.70,82.400,0.05409,7.895,0.001
122.06,82.500,0.05425,7.918,0.001
122.45,82.600,0.05442,7.943,0.001
122.89,82.700,0.05463,7.972,0.001
123.36,82.800,0.05488,8.002,0.001
123.80,82.900,0.05508,8.031,0.001
124.25,83.000,0.05529,8.060,0.001
124.71,83.100,0.05550,8.090,0.001
125.16,83.200,0.05571,8.119,0.001
125.60,83.300,0.05592,8.147,0.001
126.02,83.400,0.05612,8.175,0.001
126.47,83.500,0.05633,8.204,0.001
126.91,83.600,0.05654,8.232,0.001
127.30,83.700,0.05675,8.258,0.001
127.66,83.800,0.05691,8.281,0.001
128.04,83.900,0.05712,8.306,0.001
128.37,84.000,0.05729,8.328,0.001
128.73,84.100,0.05745,8.351,0.001
129.05,84.200,0.05762,8.371,0.001
129.39,84.300,0.05779,8.393,0.001
129.73,84.400,0.05795,8.416,0.001
130.04,84.500,0.05812,8.435,0.001
130.31,84.600,0.05824,8.453,0.001
130.65,84.700,0.05841,8.475,0.001
130.94,84.800,0.05853,8.494,0.001
131.24,84.900,0.05870,8.513,0.001
131.53,85.000,0.05882,8.532,0.001
131.82,85.100,0.05899,8.551,0.001
132.09,85.200,0.05912,8.569,0.001
132.35,85.300,0.05924,8.585,0.001
132.63,85.400,0.05937,8.604,0.001
132.94,85.500,0.05949,8.624,0.001
133.21,85.600,0.05966,8.641,0.001
133.51,85.700,0.05978,8.661,0.001
133.80,85.800,0.05995,8.680,0.001
134.12,85.900,0.06007,8.700,0.001
134.40,86.000,0.06020,8.718,0.001
134.74,86.100,0.06036,8.740,0.001
135.04,86.200,0.06049,8.760,0.001
135.38,86.300,0.06065,8.782,0.001
135.70,86.400,0.06082,8.803,0.001
136.03,86.500,0.06094,8.824,0.001
136.34,86.600,0.06111,8.844,0.001
136.66,86.700,0.06124,8.865,0.001
137.00,86.800,0.06140,8.887,0.001
137.31,86.900,0.06157,8.908,0.001
137.66,87.000,0.06173,8.930,0.001
138.01,87.100,0.06186,8.953,0.001
138.31,87.200,0.06202,8.972,0.001
138.67,87.300,0.06219,8.995,0.001
139.02,87.400,0.06236,9.018,0.001
139.38,87.500,0.06248,9.041,0.001
139.69,87.600,0.06265,9.062,0.001
140.05,87.700,0.06281,9.085,0.001
140.45,87.800,0.06298,9.111,0.001
140.82,87.900,0.06315,9.135,0.001
141.27,88.000,0.06335,9.164,0.001
141.73,88.100,0.06356,9.194,0.001
142.17,88.200,0.06373,9.223,0.001
142.67,88.300,0.06394,9.255,0.001
143.13,88.400,0.06414,9.285,0.001
143.64,88.500,0.06439,9.318,0.001
144.17,88.600,0.06460,9.353,0.001
144.72,88.700,0.06481,9.388,0.001
145.19,88.800,0.06506,9.419,0.001
145.68,88.900,0.06527,9.450,0.001
146.17,89.000,0.06547,9.482,0.001
146.64,89.100,0.06568,9.513,0.001
147.14,89.200,0.06589,9.545,0.001
147.58,89.300,0.06610,9.574,0.001
148.02,89.400,0.06626,9.602,0.001
148.44,89.500,0.06647,9.629,0.001
148.83,89.600,0.06664,9.655,0.001
149.21,89.700,0.06680,9.680,0.001
149.59,89.800,0.06701,9.704,0.001
149.97,89.900,0.06718,9.729,0.001
150.27,90.000,0.06730,9.748,0.001
150.58,90.100,0.06747,9.768,0.001
150.91,90.200,0.06759,9.789,0.001
151.24,90.300,0.06776,9.811,0.001
151.57,90.400,0.06788,9.832,0.001
151.87,90.500,0.06805,9.852,0.001
152.16,90.600,0.06817,9.871,0.001
152.46,90.700,0.06830,9.890,0.001
152.78,90.800,0.06842,9.911,0.001
153.05,90.900,0.06855,9.928,0.001
153.35,91.000,0.06872,9.948,0.001
153.69,91.100,0.06884,9.970,0.001
153.99,91.200,0.06896,9.989,0.001
154.33,91.300,0.06913,10.011,0.001
154.64,91.400,0.06926,10.031,0.001
154.97,91.500,0.06938,10.053,0.001
155.31,91.600,0.06955,10.075,0.001
155.63,91.700,0.06967,10.096,0.001
155.98,91.800,0.06980,10.119,0.001
156.32,91.900,0.06996,10.140,0.001
156.67,92.000,0.07013,10.163,0.001
157.03,92.100,0.07025,10.186,0.001
157.40,92.200,0.07042,10.210,0.001
157.77,92.300,0.07059,10.235,0.001
158.12,92.400,0.07071,10.257,0.001
158.46,92.500,0.07088,10.280,0.001
158.81,92.600,0.07100,10.302,0.001
159.17,92.700,0.07117,10.325,0.001
159.52,92.800,0.07133,10.348,0.001
159.91,92.900,0.07146,10.374,0.001
160.27,93.000,0.07162,10.397,0.001
160.55,93.100,0.07179,10.415,0.001
159.73,93.200,0.07196,10.362,0.001
33.29,93.300,0.07212,2.160,0.001
45.98,93.400,0.07229,2.983,0.001
47.60,93.500,0.07246,3.088,0.001
48.35,93.600,0.07266,3.137,0.001
49.09,93.700,0.07283,3.185,0.001
49.81,93.800,0.07304,3.231,0.001
50.53,93.900,0.07320,3.278,0.001
51.27,94.000,0.07341,3.326,0.001
51.96,94.100,0.07362,3.371,0.001
52.68,94.200,0.07383,3.417,0.001
53.39,94.300,0.07403,3.463,0.001
54.12,94.400,0.07424,3.511,0.001
54.82,94.500,0.07449,3.556,0.001
55.44,94.600,0.07470,3.596,0.001
56.08,94.700,0.07491,3.638,0.001
56.63,94.800,0.07507,3.674,0.001
57.16,94.900,0.07528,3.708,0.001
57.66,95.000,0.07549,3.740,0.001
58.13,95.100,0.07565,3.771,0.001
58.56,95.200,0.07586,3.799,0.001
58.96,95.300,0.07603,3.825,0.001
59.27,95.400,0.07620,3.845,0.001
59.58,95.500,0.07636,3.865,0.002
59.82,95.600,0.07653,3.881,0.002
60.07,95.700,0.07669,3.897,0.002
60.27,95.800,0.07682,3.910,0.002
60.49,95.900,0.07698,3.924,0.002
60.66,96.000,0.07715,3.935,0.002
60.84,96.100,0.07728,3.947,0.002
60.98,96.200,0.07744,3.956,0.002
61.12,96.300,0.07757,3.965,0.002
61.21,96.400,0.07773,3.971,0.002
61.32,96.500,0.07786,3.978,0.002
61.39,96.600,0.07798,3.983,0.002
61.52,96.700,0.07811,3.991,0.002
61.57,96.800,0.07823,3.994,0.002
61.66,96.900,0.07840,4.000,0.002
61.69,97.000,0.07852,4.002,0.002
61.73,97.100,0.07865,4.005,0.002
61.75,97.200,0.07881,4.006,0.002
61.76,97.300,0.07894,4.006,0.002
61.77,97.400,0.07910,4.007,0.002
61.71,97.500,0.07923,4.003,0.002
44.80,97.600,0.07939,2.906,0.002
15.30,97.640,0.07944,0.992,0.002