File: data-files/CWRU/0900-05-40B.txt
""
"Test Method","Will_Huddleston_Disks.msm"
"Sample I. D.","900-5-40B.mss"
"Specimen Number","1"

"Load (N)","Time (s)","Extension (mm)","Stress (MPa)","Strain (mm/mm)"

2.23,0.200,-0.08678,0.416,-0.002
2.24,0.300,-0.08678,0.417,-0.002
2.23,0.400,-0.08678,0.414,-0.002
2.23,0.500,-0.08678,0.415,-0.002
2.24,0.600,-0.08673,0.417,-0.002
2.25,0.700,-0.08673,0.419,-0.002
2.23,0.800,-0.08673,0.416,-0.002
2.22,0.900,-0.08669,0.414,-0.002
2.23,1.000,-0.08669,0.415,-0.002
2.23,1.100,-0.08669,0.415,-0.002
2.23,1.200,-0.08665,0.415,-0.002
2.24,1.300,-0.08665,0.417,-0.002
2.23,1.400,-0.08661,0.415,-0.002
2.24,1.500,-0.08661,0.417,-0.002
2.24,1.600,-0.08657,0.416,-0.002
2.25,1.700,-0.08657,0.418,-0.002
2.26,1.800,-0.08653,0.421,-0.002
2.28,1.900,-0.08648,0.424,-0.002
2.28,2.000,-0.08644,0.425,-0.002
2.32,2.100,-0.08640,0.432,-0.002
2.36,2.200,-0.08632,0.440,-0.002
2.40,2.300,-0.08619,0.447,-0.002
2.45,2.400,-0.08603,0.457,-0.002
2.53,2.500,-0.08586,0.471,-0.002
2.60,2.600,-0.08570,0.484,-0.002
2.64,2.700,-0.08553,0.491,-0.002
2.71,2.800,-0.08536,0.505,-0.002
2.75,2.900,-0.08520,0.511,-0.002
2.77,3.000,-0.08503,0.516,-0.002
2.81,3.100,-0.08482,0.523,-0.002
2.86,3.200,-0.08466,0.532,-0.002
2.87,3.300,-0.08445,0.534,-0.002
2.90,3.400,-0.08424,0.541,-0.002
2.94,3.500,-0.08407,0.547,-0.002
2.97,3.600,-0.08387,0.552,-0.002
3.01,3.700,-0.08366,0.560,-0.002
3.04,3.800,-0.08349,0.565,-0.002
3.07,3.900,-0.08328,0.571,-0.002
3.08,4.000,-0.08308,0.574,-0.002
3.13,4.100,-0.08287,0.582,-0.002
3.15,4.200,-0.08270,0.587,-0.002
3.19,4.300,-0.08250,0.593,-0.002
3.20,4.400,-0.08233,0.595,-0.002
3.23,4.500,-0.08216,0.601,-0.002
3.25,4.600,-0.08200,0.604,-0.002
3.27,4.700,-0.08179,0.608,-0.002
3.29,4.800,-0.08166,0.612,-0.002
3.33,4.900,-0.08150,0.620,-0.002
3.34,5.000,-0.08137,0.621,-0.002
3.35,5.100,-0.08121,0.623,-0.002
3.37,5.200,-0.08108,0.627,-0.002
3.39,5.300,-0.08092,0.631,-0.002
3.41,5.400,-0.08079,0.635,-0.002
3.43,5.500,-0.08067,0.639,-0.002
3.45,5.600,-0.08054,0.642,-0.002
3.47,5.700,-0.08038,0.646,-0.002
3.46,5.800,-0.08025,0.645,-0.002
3.50,5.900,-0.08013,0.651,-0.002
3.50,6.000,-0.08000,0.651,-0.002
3.51,6.100,-0.07988,0.654,-0.002
3.53,6.200,-0.07975,0.657,-0.002
3.56,6.300,-0.07959,0.663,-0.002
3.59,6.400,-0.07946,0.668,-0.002
3.59,6.500,-0.07934,0.669,-0.002
3.62,6.600,-0.07917,0.673,-0.002
3.63,6.700,-0.07905,0.675,-0.002
3.65,6.800,-0.07888,0.679,-0.002
3.68,6.900,-0.07876,0.685,-0.002
3.69,7.000,-0.07859,0.686,-0.002
3.71,7.100,-0.07846,0.692,-0.002
3.73,7.200,-0.07830,0.694,-0.002
3.76,7.300,-0.07813,0.700,-0.002
3.76,7.400,-0.07801,0.701,-0.002
3.79,7.500,-0.07784,0.706,-0.002
3.80,7.600,-0.07767,0.708,-0.002
3.82,7.700,-0.07755,0.711,-0.002
3.84,7.800,-0.07738,0.714,-0.002
3.86,7.900,-0.07722,0.718,-0.002
3.88,8.000,-0.07705,0.723,-0.002
3.90,8.100,-0.07693,0.725,-0.002
3.91,8.200,-0.07676,0.728,-0.002
3.93,8.300,-0.07659,0.732,-0.002
3.95,8.400,-0.07643,0.735,-0.002
3.97,8.500,-0.07626,0.740,-0.002
4.00,8.600,-0.07605,0.744,-0.001
4.00,8.700,-0.07589,0.745,-0.001
4.05,8.800,-0.07568,0.754,-0.001
4.08,8.900,-0.07551,0.760,-0.001
4.08,9.000,-0.07531,0.760,-0.001
4.13,9.100,-0.07510,0.768,-0.001
4.14,9.200,-0.07489,0.770,-0.001
4.17,9.300,-0.07464,0.777,-0.001
4.20,9.400,-0.07443,0.782,-0.001
4.23,9.500,-0.07423,0.787,-0.001
4.26,9.600,-0.07398,0.792,-0.001
4.28,9.700,-0.07377,0.797,-0.001
4.32,9.800,-0.07356,0.803,-0.001
4.33,9.900,-0.07335,0.806,-0.001
4.36,10.000,-0.07319,0.812,-0.001
4.36,10.100,-0.07298,0.812,-0.001
4.39,10.200,-0.07277,0.818,-0.001
4.42,10.300,-0.07261,0.823,-0.001
4.43,10.400,-0.07240,0.825,-0.001
4.43,10.500,-0.07223,0.824,-0.001
4.47,10.600,-0.07206,0.831,-0.001
4.49,10.700,-0.07194,0.836,-0.001
4.52,10.800,-0.07177,0.842,-0.001
4.53,10.900,-0.07161,0.842,-0.001
4.55,11.000,-0.07144,0.846,-0.001
4.56,11.100,-0.07132,0.848,-0.001
4.57,11.200,-0.07115,0.850,-0.001
4.57,11.300,-0.07103,0.851,-0.001
4.59,11.400,-0.07090,0.855,-0.001
4.62,11.500,-0.07073,0.860,-0.001
4.62,11.600,-0.07061,0.860,-0.001
4.63,11.700,-0.07049,0.861,-0.001
4.67,11.800,-0.07032,0.869,-0.001
4.66,11.900,-0.07019,0.868,-0.001
4.67,12.000,-0.07007,0.870,-0.001
4.69,12.100,-0.06990,0.873,-0.001
4.71,12.200,-0.06978,0.877,-0.001
4.74,12.300,-0.06961,0.882,-0.001
4.75,12.400,-0.06949,0.884,-0.001
4.77,12.500,-0.06932,0.888,-0.001
4.79,12.600,-0.06916,0.892,-0.001
4.79,12.700,-0.06903,0.892,-0.001
4.81,12.800,-0.06886,0.896,-0.001
4.84,12.900,-0.06870,0.900,-0.001
4.83,13.000,-0.06853,0.900,-0.001
4.86,13.100,-0.06841,0.904,-0.001
4.85,13.200,-0.06824,0.903,-0.001
4.88,13.300,-0.06808,0.909,-0.001
4.88,13.400,-0.06791,0.908,-0.001
4.88,13.500,-0.06774,0.909,-0.001
4.91,13.600,-0.06762,0.913,-0.001
4.93,13.700,-0.06745,0.917,-0.001
4.95,13.800,-0.06729,0.921,-0.001
4.96,13.900,-0.06712,0.923,-0.001
4.97,14.000,-0.06695,0.926,-0.001
4.98,14.100,-0.06679,0.927,-0.001
4.98,14.200,-0.06658,0.928,-0.001
5.00,14.300,-0.06641,0.932,-0.001
5.01,14.400,-0.06621,0.933,-0.001
5.04,14.500,-0.06600,0.938,-0.001
5.07,14.600,-0.06583,0.944,-0.001
5.09,14.700,-0.06562,0.947,-0.001
5.08,14.800,-0.06542,0.945,-0.001
5.10,14.900,-0.06521,0.950,-0.001
5.10,15.000,-0.06496,0.950,-0.001
5.12,15.100,-0.06475,0.952,-0.001
5.13,15.200,-0.06454,0.955,-0.001
5.15,15.300,-0.06434,0.959,-0.001
5.19,15.400,-0.06413,0.966,-0.001
5.20,15.500,-0.06392,0.968,-0.001
5.21,15.600,-0.06371,0.969,-0.001
5.22,15.700,-0.06355,0.972,-0.001
5.22,15.800,-0.06334,0.972,-0.001
5.24,15.900,-0.06317,0.975,-0.001
5.24,16.000,-0.06301,0.976,-0.001
5.22,16.100,-0.06280,0.972,-0.001
5.26,16.200,-0.06263,0.979,-0.001
5.26,16.300,-0.06251,0.979,-0.001
5.28,16.400,-0.06234,0.983,-0.001
5.28,16.500,-0.06217,0.983,-0.001
5.30,16.600,-0.06205,0.987,-0.001
5.30,16.700,-0.06188,0.986,-0.001
5.31,16.800,-0.06176,0.988,-0.001
5.30,16.900,-0.06159,0.987,-0.001
5.32,17.000,-0.06147,0.990,-0.001
5.31,17.100,-0.06130,0.989,-0.001
5.33,17.200,-0.06118,0.993,-0.001
5.32,17.300,-0.06105,0.991,-0.001
5.34,17.400,-0.06093,0.994,-0.001
5.34,17.500,-0.06076,0.994,-0.001
5.34,17.600,-0.06064,0.994,-0.001
5.35,17.700,-0.06051,0.997,-0.001
5.37,17.800,-0.06035,1.000,-0.001
5.38,17.900,-0.06022,1.002,-0.001
5.40,18.000,-0.06010,1.005,-0.001
5.40,18.100,-0.05993,1.005,-0.001
5.40,18.200,-0.05976,1.006,-0.001
5.40,18.300,-0.05964,1.005,-0.001
5.43,18.400,-0.05947,1.011,-0.001
5.44,18.500,-0.05935,1.012,-0.001
5.45,18.600,-0.05918,1.014,-0.001
5.46,18.700,-0.05906,1.016,-0.001
5.48,18.800,-0.05889,1.019,-0.001
5.49,18.900,-0.05873,1.021,-0.001
5.48,19.000,-0.05860,1.021,-0.001
5.48,19.100,-0.05843,1.021,-0.001
5.50,19.200,-0.05827,1.024,-0.001
5.52,19.300,-0.05810,1.028,-0.001
5.53,19.400,-0.05798,1.029,-0.001
5.54,19.500,-0.05781,1.032,-0.001
5.56,19.600,-0.05764,1.035,-0.001
5.56,19.700,-0.05748,1.035,-0.001
5.59,19.800,-0.05731,1.040,-0.001
5.60,19.900,-0.05715,1.042,-0.001
5.59,20.000,-0.05694,1.041,-0.001
5.62,20.100,-0.05673,1.046,-0.001
5.65,20.200,-0.05656,1.052,-0.001
5.67,20.300,-0.05636,1.055,-0.001
5.69,20.400,-0.05615,1.060,-0.001
5.73,20.500,-0.05594,1.066,-0.001
5.73,20.600,-0.05569,1.067,-0.001
5.75,20.700,-0.05548,1.070,-0.001
5.79,20.800,-0.05528,1.078,-0.001
5.79,20.900,-0.05507,1.078,-0.001
5.81,21.000,-0.05486,1.082,-0.001
5.82,21.100,-0.05465,1.084,-0.001
5.85,21.200,-0.05445,1.088,-0.001
5.86,21.300,-0.05428,1.090,-0.001
5.89,21.400,-0.05407,1.097,-0.001
5.91,21.500,-0.05386,1.099,-0.001
5.91,21.600,-0.05370,1.101,-0.001
5.93,21.700,-0.05353,1.105,-0.001
5.97,21.800,-0.05336,1.110,-0.001
5.97,21.900,-0.05320,1.111,-0.001
5.99,22.000,-0.05303,1.116,-0.001
6.02,22.100,-0.05287,1.120,-0.001
6.04,22.200,-0.05274,1.123,-0.001
6.06,22.300,-0.05258,1.129,-0.001
6.08,22.400,-0.05245,1.132,-0.001
6.11,22.500,-0.05228,1.138,-0.001
6.14,22.600,-0.05216,1.143,-0.001
6.16,22.700,-0.05203,1.147,-0.001
6.19,22.800,-0.05191,1.152,-0.001
6.21,22.900,-0.05174,1.155,-0.001
6.24,23.000,-0.05162,1.162,-0.001
6.27,23.100,-0.05149,1.167,-0.001
6.31,23.200,-0.05137,1.174,-0.001
6.32,23.300,-0.05120,1.177,-0.001
6.37,23.400,-0.05108,1.185,-0.001
6.39,23.500,-0.05095,1.190,-0.001
6.43,23.600,-0.05079,1.196,-0.001
6.46,23.700,-0.05066,1.202,-0.001
6.49,23.800,-0.05050,1.208,-0.001
6.52,23.900,-0.05037,1.214,-0.001
6.57,24.000,-0.05021,1.223,-0.001
6.58,24.100,-0.05004,1.226,-0.001
6.62,24.200,-0.04992,1.232,-0.001
6.66,24.300,-0.04975,1.239,-0.001
6.68,24.400,-0.04958,1.244,-0.001
6.72,24.500,-0.04942,1.251,-0.001
6.76,24.600,-0.04929,1.259,-0.001
6.79,24.700,-0.04913,1.264,-0.001
6.83,24.800,-0.04896,1.271,-0.001
6.87,24.900,-0.04879,1.279,-0.001
6.89,25.000,-0.04867,1.283,-0.001
6.92,25.100,-0.04850,1.289,-0.001
6.97,25.200,-0.04834,1.298,-0.001
7.00,25.300,-0.04817,1.304,-0.001
7.04,25.400,-0.04800,1.311,-0.001
7.08,25.500,-0.04780,1.317,-0.001
7.12,25.600,-0.04763,1.326,-0.001
7.17,25.700,-0.04746,1.334,-0.001
7.21,25.800,-0.04726,1.342,-0.001
7.25,25.900,-0.04709,1.350,-0.001
7.30,26.000,-0.04688,1.358,-0.001
7.34,26.100,-0.04667,1.366,-0.001
7.37,26.200,-0.04647,1.372,-0.001
7.45,26.300,-0.04626,1.386,-0.001
7.49,26.400,-0.04605,1.395,-0.001
7.54,26.500,-0.04584,1.403,-0.001
7.58,26.600,-0.04564,1.411,-0.001
7.62,26.700,-0.04539,1.418,-0.001
7.67,26.800,-0.04518,1.428,-0.001
7.69,26.900,-0.04497,1.432,-0.001
7.75,27.000,-0.04476,1.442,-0.001
7.79,27.100,-0.04460,1.450,-0.001
7.84,27.200,-0.04439,1.459,-0.001
7.85,27.300,-0.04418,1.462,-0.001
7.89,27.400,-0.04401,1.470,-0.001
7.93,27.500,-0.04385,1.476,-0.001
7.95,27.600,-0.04368,1.480,-0.001
8.00,27.700,-0.04352,1.490,-0.001
8.03,27.800,-0.04339,1.495,-0.001
8.06,27.900,-0.04323,1.500,-0.001
8.09,28.000,-0.04310,1.506,-0.001
8.11,28.100,-0.04293,1.510,-0.001
8.14,28.200,-0.04281,1.516,-0.001
8.19,28.300,-0.04264,1.524,-0.001
8.20,28.400,-0.04252,1.527,-0.001
8.24,28.500,-0.04239,1.533,-0.001
8.26,28.600,-0.04227,1.538,-0.001
8.29,28.700,-0.04210,1.544,-0.001
8.31,28.800,-0.04198,1.547,-0.001
8.35,28.900,-0.04185,1.554,-0.001
8.38,29.000,-0.04169,1.560,-0.001
8.41,29.100,-0.04156,1.566,-0.001
8.45,29.200,-0.04144,1.573,-0.001
8.49,29.300,-0.04127,1.581,-0.001
8.53,29.400,-0.04115,1.587,-0.001
8.55,29.500,-0.04098,1.592,-0.001
8.60,29.600,-0.04081,1.600,-0.001
8.65,29.700,-0.04069,1.609,-0.001
8.66,29.800,-0.04052,1.612,-0.001
8.71,29.900,-0.04040,1.622,-0.001
8.74,30.000,-0.04023,1.626,-0.001
8.77,30.100,-0.04007,1.632,-0.001
8.80,30.200,-0.03994,1.639,-0.001
8.84,30.300,-0.03978,1.645,-0.001
8.88,30.400,-0.03961,1.653,-0.001
8.91,30.500,-0.03944,1.659,-0.001
8.94,30.600,-0.03932,1.665,-0.001
8.97,30.700,-0.03915,1.670,-0.001
9.02,30.800,-0.03899,1.680,-0.001
9.06,30.900,-0.03882,1.686,-0.001
9.09,31.000,-0.03865,1.693,-0.001
9.14,31.100,-0.03849,1.701,-0.001
9.17,31.200,-0.03832,1.707,-0.001
9.22,31.300,-0.03816,1.717,-0.001
9.26,31.400,-0.03795,1.723,-0.001
9.31,31.500,-0.03778,1.734,-0.001
9.36,31.600,-0.03757,1.743,-0.001
9.41,31.700,-0.03737,1.751,-0.001
9.48,31.800,-0.03716,1.764,-0.001
9.52,31.900,-0.03695,1.773,-0.001
9.59,32.000,-0.03674,1.785,-0.001
9.64,32.100,-0.03653,1.794,-0.001
9.68,32.200,-0.03633,1.801,-0.001
9.74,32.300,-0.03612,1.812,-0.001
9.78,32.400,-0.03591,1.821,-0.001
9.83,32.500,-0.03570,1.830,-0.001
9.89,32.600,-0.03550,1.840,-0.001
9.93,32.700,-0.03533,1.848,-0.001
9.99,32.800,-0.03512,1.859,-0.001
10.01,32.900,-0.03496,1.864,-0.001
10.06,33.000,-0.03475,1.873,-0.001
10.11,33.100,-0.03458,1.883,-0.001
10.16,33.200,-0.03442,1.890,-0.001
10.20,33.300,-0.03425,1.898,-0.001
10.23,33.400,-0.03408,1.903,-0.001
10.27,33.500,-0.03396,1.911,-0.001
10.30,33.600,-0.03379,1.917,-0.001
10.32,33.700,-0.03363,1.920,-0.001
10.37,33.800,-0.03350,1.931,-0.001
10.41,33.900,-0.03333,1.938,-0.001
10.45,34.000,-0.03321,1.945,-0.001
10.46,34.100,-0.03309,1.948,-0.001
10.51,34.200,-0.03292,1.956,-0.001
10.53,34.300,-0.03279,1.960,-0.001
10.56,34.400,-0.03267,1.966,-0.001
10.61,34.500,-0.03255,1.975,-0.001
10.63,34.600,-0.03238,1.979,-0.001
10.68,34.700,-0.03225,1.987,-0.001
10.71,34.800,-0.03213,1.993,-0.001
10.75,34.900,-0.03196,2.001,-0.001
10.79,35.000,-0.03184,2.009,-0.001
10.82,35.100,-0.03171,2.014,-0.001
10.87,35.200,-0.03155,2.023,-0.001
10.90,35.300,-0.03142,2.030,-0.001
10.94,35.400,-0.03126,2.036,-0.001
10.98,35.500,-0.03109,2.044,-0.001
11.02,35.600,-0.03097,2.051,-0.001
11.06,35.700,-0.03080,2.059,-0.001
11.10,35.800,-0.03068,2.067,-0.001
11.13,35.900,-0.03051,2.073,-0.001
11.20,36.000,-0.03034,2.084,-0.001
11.23,36.100,-0.03018,2.090,-0.001
11.28,36.200,-0.03005,2.100,-0.001
11.31,36.300,-0.02989,2.106,-0.001
11.37,36.400,-0.02972,2.116,-0.001
11.39,36.500,-0.02959,2.120,-0.001
11.43,36.600,-0.02943,2.128,-0.001
11.48,36.700,-0.02926,2.136,-0.001
11.53,36.800,-0.02910,2.146,-0.001
11.59,36.900,-0.02893,2.157,-0.001
11.64,37.000,-0.02872,2.166,-0.001
11.70,37.100,-0.02856,2.178,-0.001
11.76,37.200,-0.02835,2.190,-0.001
11.80,37.300,-0.02814,2.196,-0.001
11.87,37.400,-0.02793,2.209,-0.001
11.93,37.500,-0.02772,2.221,-0.001
12.00,37.600,-0.02752,2.233,-0.001
12.06,37.700,-0.02731,2.245,-0.001
12.14,37.800,-0.02710,2.260,-0.001
12.20,37.900,-0.02689,2.271,-0.001
12.25,38.000,-0.02664,2.280,-0.001
12.31,38.100,-0.02644,2.291,-0.001
12.37,38.200,-0.02623,2.303,-0.001
12.43,38.300,-0.02602,2.314,-0.001
12.49,38.400,-0.02581,2.324,-0.001
12.54,38.500,-0.02565,2.334,-0.001
12.60,38.600,-0.02544,2.345,-0.001
12.64,38.700,-0.02527,2.352,0.000
12.66,38.800,-0.02511,2.356,0.000
12.71,38.900,-0.02494,2.367,0.000
12.75,39.000,-0.02477,2.374,0.000
12.79,39.100,-0.02465,2.380,0.000
12.82,39.200,-0.02448,2.386,0.000
12.86,39.300,-0.02436,2.394,0.000
12.90,39.400,-0.02419,2.401,0.000
12.92,39.500,-0.02407,2.405,0.000
12.97,39.600,-0.02390,2.415,0.000
13.01,39.700,-0.02378,2.421,0.000
13.04,39.800,-0.02365,2.428,0.000
13.08,39.900,-0.02349,2.435,0.000
13.12,40.000,-0.02336,2.443,0.000
13.17,40.100,-0.02324,2.451,0.000
13.21,40.200,-0.02307,2.458,0.000
13.24,40.300,-0.02295,2.465,0.000
13.29,40.400,-0.02282,2.474,0.000
13.32,40.500,-0.02265,2.479,0.000
13.36,40.600,-0.02253,2.486,0.000
13.42,40.700,-0.02236,2.497,0.000
13.45,40.800,-0.02224,2.504,0.000
13.51,40.900,-0.02207,2.515,0.000
13.54,41.000,-0.02191,2.520,0.000
13.59,41.100,-0.02178,2.531,0.000
13.65,41.200,-0.02162,2.541,0.000
13.68,41.300,-0.02149,2.546,0.000
13.71,41.400,-0.02133,2.553,0.000
13.76,41.500,-0.02116,2.561,0.000
13.81,41.600,-0.02099,2.571,0.000
13.86,41.700,-0.02087,2.580,0.000
13.91,41.800,-0.02070,2.589,0.000
13.97,41.900,-0.02054,2.600,0.000
14.01,42.000,-0.02037,2.608,0.000
14.06,42.100,-0.02024,2.618,0.000
14.10,42.200,-0.02008,2.624,0.000
14.16,42.300,-0.01991,2.636,0.000
14.22,42.400,-0.01975,2.646,0.000
14.28,42.500,-0.01954,2.658,0.000
14.33,42.600,-0.01937,2.667,0.000
14.40,42.700,-0.01921,2.681,0.000
14.47,42.800,-0.01900,2.693,0.000
14.55,42.900,-0.01879,2.708,0.000
14.61,43.000,-0.01858,2.720,0.000
14.68,43.100,-0.01837,2.732,0.000
14.75,43.200,-0.01817,2.746,0.000
14.81,43.300,-0.01796,2.757,0.000
14.87,43.400,-0.01771,2.769,0.000
14.95,43.500,-0.01750,2.783,0.000
15.01,43.600,-0.01729,2.794,0.000
15.07,43.700,-0.01709,2.804,0.000
15.13,43.800,-0.01688,2.817,0.000
15.18,43.900,-0.01667,2.826,0.000
15.24,44.000,-0.01646,2.837,0.000
15.30,44.100,-0.01626,2.848,0.000
15.35,44.200,-0.01609,2.857,0.000
15.41,44.300,-0.01588,2.868,0.000
15.45,44.400,-0.01572,2.876,0.000
15.51,44.500,-0.01555,2.887,0.000
15.55,44.600,-0.01538,2.894,0.000
15.59,44.700,-0.01522,2.903,0.000
15.63,44.800,-0.01505,2.909,0.000
15.67,44.900,-0.01488,2.917,0.000
15.71,45.000,-0.01476,2.924,0.000
15.76,45.100,-0.01459,2.933,0.000
15.80,45.200,-0.01447,2.941,0.000
15.85,45.300,-0.01430,2.951,0.000
15.90,45.400,-0.01418,2.959,0.000
15.92,45.500,-0.01401,2.964,0.000
15.96,45.600,-0.01389,2.971,0.000
16.00,45.700,-0.01376,2.979,0.000
16.04,45.800,-0.01360,2.985,0.000
16.08,45.900,-0.01347,2.993,0.000
16.13,46.000,-0.01335,3.002,0.000
16.18,46.100,-0.01318,3.012,0.000
16.23,46.200,-0.01306,3.021,0.000
16.27,46.300,-0.01289,3.028,0.000
16.33,46.400,-0.01272,3.040,0.000
16.38,46.500,-0.01260,3.049,0.000
16.43,46.600,-0.01243,3.058,0.000
16.47,46.700,-0.01227,3.067,0.000
16.55,46.800,-0.01214,3.080,0.000
16.59,46.900,-0.01198,3.087,0.000
16.63,47.000,-0.01181,3.096,0.000
16.69,47.100,-0.01168,3.108,0.000
16.73,47.200,-0.01152,3.114,0.000
16.80,47.300,-0.01135,3.126,0.000
16.85,47.400,-0.01119,3.137,0.000
16.89,47.500,-0.01106,3.144,0.000
16.94,47.600,-0.01089,3.154,0.000
16.98,47.700,-0.01073,3.161,0.000
17.05,47.800,-0.01056,3.173,0.000
17.10,47.900,-0.01040,3.182,0.000
17.15,48.000,-0.01023,3.192,0.000
17.22,48.100,-0.01002,3.205,0.000
17.29,48.200,-0.00986,3.218,0.000
17.34,48.300,-0.00969,3.228,0.000
17.41,48.400,-0.00948,3.241,0.000
17.48,48.500,-0.00927,3.254,0.000
17.54,48.600,-0.00911,3.265,0.000
17.61,48.700,-0.00890,3.278,0.000
17.69,48.800,-0.00869,3.293,0.000
17.76,48.900,-0.00844,3.305,0.000
17.83,49.000,-0.00823,3.319,0.000
17.90,49.100,-0.00803,3.332,0.000
17.96,49.200,-0.00782,3.343,0.000
18.03,49.300,-0.00761,3.355,0.000
18.09,49.400,-0.00740,3.368,0.000
18.16,49.500,-0.00720,3.380,0.000
18.23,49.600,-0.00703,3.393,0.000
18.28,49.700,-0.00682,3.403,0.000
18.34,49.800,-0.00661,3.414,0.000
18.39,49.900,-0.00645,3.424,0.000
18.45,50.000,-0.00628,3.434,0.000
18.49,50.100,-0.00612,3.442,0.000
18.56,50.200,-0.00595,3.454,0.000
18.58,50.300,-0.00578,3.459,0.000
18.64,50.400,-0.00562,3.470,0.000
18.68,50.500,-0.00545,3.478,0.000
18.73,50.600,-0.00533,3.487,0.000
18.74,50.700,-0.00516,3.488,0.000
18.81,50.800,-0.00499,3.502,0.000
18.85,50.900,-0.00487,3.508,0.000
18.90,51.000,-0.00474,3.518,0.000
18.94,51.100,-0.00458,3.526,0.000
18.99,51.200,-0.00445,3.535,0.000
19.02,51.300,-0.00433,3.541,0.000
19.08,51.400,-0.00416,3.551,0.000
19.11,51.500,-0.00404,3.558,0.000
19.17,51.600,-0.00391,3.569,0.000
19.19,51.700,-0.00375,3.573,0.000
19.25,51.800,-0.00362,3.584,0.000
19.31,51.900,-0.00346,3.594,0.000
19.36,52.000,-0.00333,3.603,0.000
19.40,52.100,-0.00317,3.612,0.000
19.47,52.200,-0.00304,3.625,0.000
19.51,52.300,-0.00287,3.632,0.000
19.58,52.400,-0.00275,3.645,0.000
19.61,52.500,-0.00258,3.651,0.000
19.66,52.600,-0.00246,3.659,0.000
19.72,52.700,-0.00229,3.670,0.000
19.77,52.800,-0.00213,3.680,0.000
19.83,52.900,-0.00196,3.692,0.000
19.89,53.000,-0.00184,3.701,0.000
19.93,53.100,-0.00167,3.710,0.000
19.98,53.200,-0.00150,3.720,0.000
20.04,53.300,-0.00138,3.730,0.000
20.10,53.400,-0.00121,3.741,0.000
20.16,53.500,-0.00105,3.752,0.000
20.22,53.600,-0.00088,3.763,0.000
20.27,53.700,-0.00071,3.772,0.000
20.35,53.800,-0.00055,3.787,0.000
20.41,53.900,-0.00038,3.799,0.000
20.48,54.000,-0.00017,3.813,0.000
20.54,54.100,-0.00001,3.824,0.000
20.62,54.200,0.00020,3.838,0.000
20.71,54.300,0.00041,3.854,0.000
20.77,54.400,0.00062,3.866,0.000
20.85,54.500,0.00082,3.882,0.000
20.93,54.600,0.00103,3.897,0.000
21.00,54.700,0.00124,3.909,0.000
21.10,54.800,0.00149,3.928,0.000
21.17,54.900,0.00170,3.941,0.000
21.24,55.000,0.00190,3.954,0.000
21.31,55.100,0.00211,3.966,0.000
21.37,55.200,0.00232,3.977,0.000
21.44,55.300,0.00253,3.990,0.000
21.51,55.400,0.00269,4.003,0.000
21.56,55.500,0.00290,4.014,0.000
21.63,55.600,0.00307,4.026,0.000
21.67,55.700,0.00323,4.033,0.000
21.72,55.800,0.00340,4.044,0.000
21.79,55.900,0.00357,4.057,0.000
21.84,56.000,0.00373,4.066,0.000
21.90,56.100,0.00390,4.077,0.000
21.94,56.200,0.00402,4.084,0.000
21.98,56.300,0.00419,4.091,0.000
22.03,56.400,0.00431,4.101,0.000
22.07,56.500,0.00444,4.109,0.000
22.11,56.600,0.00461,4.116,0.000
22.17,56.700,0.00473,4.128,0.000
22.20,56.800,0.00486,4.132,0.000
22.26,56.900,0.00498,4.143,0.000
22.31,57.000,0.00515,4.153,0.000
22.35,57.100,0.00527,4.161,0.000
22.41,57.200,0.00540,4.172,0.000
22.47,57.300,0.00552,4.183,0.000
22.52,57.400,0.00569,4.192,0.000
22.56,57.500,0.00581,4.200,0.000
22.59,57.600,0.00598,4.206,0.000
22.66,57.700,0.00610,4.218,0.000
22.72,57.800,0.00627,4.229,0.000
22.79,57.900,0.00639,4.242,0.000
22.85,58.000,0.00656,4.253,0.000
22.90,58.100,0.00673,4.263,0.000
22.94,58.200,0.00685,4.271,0.000
23.01,58.300,0.00702,4.283,0.000
23.06,58.400,0.00718,4.292,0.000
23.11,58.500,0.00731,4.302,0.000
23.16,58.600,0.00747,4.311,0.000
23.22,58.700,0.00764,4.323,0.000
23.27,58.800,0.00776,4.331,0.000
23.35,58.900,0.00793,4.346,0.000
23.41,59.000,0.00810,4.357,0.000
23.46,59.100,0.00826,4.366,0.000
23.51,59.200,0.00843,4.376,0.000
23.57,59.300,0.00855,4.388,0.000
23.63,59.400,0.00872,4.399,0.000
23.70,59.500,0.00893,4.411,0.000
23.76,59.600,0.00909,4.423,0.000
23.84,59.700,0.00926,4.437,0.000
23.91,59.800,0.00947,4.451,0.000
23.98,59.900,0.00963,4.465,0.000
24.05,60.000,0.00984,4.478,0.000
24.17,60.100,0.01005,4.498,0.000
24.25,60.200,0.01026,4.513,0.000
24.33,60.300,0.01047,4.528,0.000
24.42,60.400,0.01067,4.545,0.000
24.51,60.500,0.01092,4.562,0.000
24.59,60.600,0.01113,4.577,0.000
24.67,60.700,0.01134,4.592,0.000
24.75,60.800,0.01155,4.607,0.000
24.83,60.900,0.01171,4.622,0.000
24.90,61.000,0.01192,4.634,0.000
24.96,61.100,0.01213,4.647,0.000
25.03,61.200,0.01229,4.659,0.000
25.09,61.300,0.01250,4.670,0.000
25.17,61.400,0.01267,4.685,0.000
25.21,61.500,0.01283,4.693,0.000
25.29,61.600,0.01300,4.708,0.000
25.32,61.700,0.01317,4.714,0.000
25.38,61.800,0.01333,4.725,0.000
25.43,61.900,0.01346,4.734,0.000
25.48,62.000,0.01362,4.744,0.000
25.54,62.100,0.01375,4.755,0.000
25.59,62.200,0.01391,4.764,0.000
25.63,62.300,0.01404,4.770,0.000
25.67,62.400,0.01416,4.778,0.000
25.72,62.500,0.01433,4.788,0.000
25.77,62.600,0.01445,4.798,0.000
25.82,62.700,0.01458,4.805,0.000
25.87,62.800,0.01470,4.816,0.000
25.91,62.900,0.01487,4.823,0.000
25.98,63.000,0.01499,4.836,0.000
26.03,63.100,0.01512,4.846,0.000
26.10,63.200,0.01529,4.858,0.000
26.14,63.300,0.01541,4.865,0.000
26.20,63.400,0.01558,4.878,0.000
26.25,63.500,0.01570,4.887,0.000
26.32,63.600,0.01587,4.899,0.000
26.37,63.700,0.01599,4.908,0.000
26.44,63.800,0.01616,4.922,0.000
26.49,63.900,0.01632,4.931,0.000
26.56,64.000,0.01645,4.945,0.000
26.62,64.100,0.01662,4.956,0.000
26.69,64.200,0.01678,4.967,0.000
26.76,64.300,0.01691,4.980,0.000
26.80,64.400,0.01707,4.990,0.000
26.88,64.500,0.01724,5.003,0.000
26.94,64.600,0.01740,5.015,0.000
27.00,64.700,0.01753,5.027,0.000
27.07,64.800,0.01770,5.039,0.000
27.14,64.900,0.01786,5.051,0.000
27.21,65.000,0.01803,5.066,0.000
27.28,65.100,0.01819,5.077,0.000
27.36,65.200,0.01836,5.093,0.000
27.43,65.300,0.01853,5.106,0.000
27.51,65.400,0.01873,5.121,0.000
27.60,65.500,0.01890,5.137,0.000
27.70,65.600,0.01911,5.156,0.000
27.79,65.700,0.01932,5.172,0.000
27.88,65.800,0.01948,5.190,0.000
27.98,65.900,0.01969,5.208,0.000
28.06,66.000,0.01990,5.224,0.000
28.15,66.100,0.02011,5.240,0.000
28.24,66.200,0.02031,5.256,0.000
28.32,66.300,0.02052,5.272,0.000
28.42,66.400,0.02073,5.290,0.000
28.49,66.500,0.02094,5.304,0.000
28.58,66.600,0.02114,5.321,0.000
28.67,66.700,0.02135,5.337,0.000
28.73,66.800,0.02156,5.348,0.000
28.81,66.900,0.02173,5.363,0.000
28.87,67.000,0.02189,5.374,0.000
28.95,67.100,0.02210,5.389,0.000
29.02,67.200,0.02227,5.401,0.000
29.08,67.300,0.02243,5.413,0.000
29.14,67.400,0.02260,5.424,0.000
29.21,67.500,0.02272,5.437,0.000
29.24,67.600,0.02289,5.443,0.000
29.29,67.700,0.02306,5.452,0.000
29.36,67.800,0.02318,5.465,0.000
29.43,67.900,0.02335,5.477,0.000
29.48,68.000,0.02347,5.487,0.000
29.54,68.100,0.02364,5.498,0.000
29.59,68.200,0.02376,5.509,0.000
29.63,68.300,0.02389,5.516,0.000
29.69,68.400,0.02401,5.527,0.000
29.74,68.500,0.02418,5.536,0.000
29.81,68.600,0.02430,5.549,0.000
29.86,68.700,0.02443,5.559,0.000
29.94,68.800,0.02459,5.572,0.000
30.00,68.900,0.02472,5.583,0.000
30.07,69.000,0.02489,5.598,0.000
30.13,69.100,0.02501,5.609,0.000
30.20,69.200,0.02518,5.622,0.000
30.27,69.300,0.02530,5.634,0.000
30.34,69.400,0.02547,5.647,0.001
30.41,69.500,0.02559,5.660,0.001
30.48,69.600,0.02576,5.674,0.001
30.55,69.700,0.02588,5.686,0.001
30.61,69.800,0.02605,5.698,0.001
30.69,69.900,0.02621,5.714,0.001
30.77,70.000,0.02634,5.728,0.001
30.84,70.100,0.02651,5.741,0.001
30.92,70.200,0.02667,5.755,0.001
31.00,70.300,0.02680,5.770,0.001
31.08,70.400,0.02696,5.786,0.001
31.16,70.500,0.02713,5.800,0.001
31.23,70.600,0.02730,5.813,0.001
31.31,70.700,0.02746,5.828,0.001
31.39,70.800,0.02763,5.842,0.001
31.47,70.900,0.02779,5.859,0.001
31.56,71.000,0.02796,5.874,0.001
31.65,71.100,0.02813,5.892,0.001
31.76,71.200,0.02833,5.912,0.001
31.85,71.300,0.02850,5.930,0.001
31.96,71.400,0.02871,5.949,0.001
32.06,71.500,0.02892,5.968,0.001
32.19,71.600,0.02912,5.992,0.001
32.29,71.700,0.02933,6.010,0.001
32.41,71.800,0.02958,6.032,0.001
32.51,71.900,0.02979,6.052,0.001
32.63,72.000,0.03000,6.073,0.001
32.73,72.100,0.03020,6.093,0.001
32.83,72.200,0.03041,6.111,0.001
32.92,72.300,0.03062,6.127,0.001
33.02,72.400,0.03083,6.146,0.001
33.11,72.500,0.03099,6.163,0.001
33.20,72.600,0.03120,6.180,0.001
33.30,72.700,0.03137,6.199,0.001
33.36,72.800,0.03158,6.211,0.001
33.43,72.900,0.03174,6.223,0.001
33.52,73.000,0.03187,6.240,0.001
33.59,73.100,0.03203,6.253,0.001
33.66,73.200,0.03220,6.266,0.001
33.73,73.300,0.03237,6.279,0.001
33.80,73.400,0.03249,6.292,0.001
33.88,73.500,0.03266,6.306,0.001
33.94,73.600,0.03278,6.317,0.001
34.02,73.700,0.03295,6.333,0.001
34.08,73.800,0.03307,6.344,0.001
34.14,73.900,0.03320,6.355,0.001
34.20,74.000,0.03336,6.367,0.001
34.28,74.100,0.03349,6.381,0.001
34.35,74.200,0.03361,6.394,0.001
34.42,74.300,0.03374,6.406,0.001
34.48,74.400,0.03390,6.418,0.001
34.58,74.500,0.03403,6.436,0.001
34.65,74.600,0.03419,6.449,0.001
34.72,74.700,0.03432,6.463,0.001
34.82,74.800,0.03448,6.481,0.001
34.90,74.900,0.03461,6.497,0.001
34.97,75.000,0.03478,6.509,0.001
35.06,75.100,0.03494,6.527,0.001
35.16,75.200,0.03511,6.545,0.001
35.25,75.300,0.03523,6.561,0.001
35.34,75.400,0.03540,6.578,0.001
35.43,75.500,0.03556,6.595,0.001
35.53,75.600,0.03573,6.613,0.001
35.60,75.700,0.03586,6.626,0.001
35.68,75.800,0.03602,6.641,0.001
35.78,75.900,0.03619,6.660,0.001
35.87,76.000,0.03635,6.678,0.001
35.95,76.100,0.03652,6.693,0.001
36.05,76.200,0.03669,6.710,0.001
36.14,76.300,0.03685,6.727,0.001
36.24,76.400,0.03702,6.746,0.001
36.35,76.500,0.03719,6.766,0.001
36.45,76.600,0.03735,6.785,0.001
36.57,76.700,0.03756,6.808,0.001
36.69,76.800,0.03777,6.830,0.001
36.81,76.900,0.03793,6.852,0.001
36.91,77.000,0.03814,6.871,0.001
37.04,77.100,0.03835,6.894,0.001
37.14,77.200,0.03856,6.914,0.001
37.27,77.300,0.03876,6.938,0.001
37.39,77.400,0.03897,6.961,0.001
37.51,77.500,0.03918,6.983,0.001
37.63,77.600,0.03939,7.005,0.001
37.74,77.700,0.03964,7.026,0.001
37.86,77.800,0.03985,7.048,0.001
37.99,77.900,0.04005,7.071,0.001
38.11,78.000,0.04026,7.094,0.001
38.23,78.100,0.04043,7.116,0.001
38.32,78.200,0.04063,7.133,0.001
38.43,78.300,0.04084,7.153,0.001
38.54,78.400,0.04101,7.174,0.001
38.63,78.500,0.04117,7.191,0.001
38.73,78.600,0.04134,7.209,0.001
38.79,78.700,0.04151,7.221,0.001
38.91,78.800,0.04167,7.243,0.001
38.98,78.900,0.04184,7.256,0.001
39.06,79.000,0.04196,7.271,0.001
39.13,79.100,0.04213,7.284,0.001
39.24,79.200,0.04230,7.304,0.001
39.31,79.300,0.04242,7.318,0.001
39.39,79.400,0.04255,7.332,0.001
39.47,79.500,0.04271,7.348,0.001
39.56,79.600,0.04284,7.363,0.001
39.63,79.700,0.04296,7.377,0.001
39.73,79.800,0.04313,7.395,0.001
39.81,79.900,0.04325,7.410,0.001
39.88,80.000,0.04338,7.424,0.001
39.96,80.100,0.04354,7.438,0.001
40.06,80.200,0.04367,7.457,0.001
40.15,80.300,0.04383,7.474,0.001
40.23,80.400,0.04400,7.489,0.001
40.33,80.500,0.04413,7.507,0.001
40.42,80.600,0.04429,7.525,0.001
40.50,80.700,0.04442,7.539,0.001
40.62,80.800,0.04458,7.560,0.001
40.70,80.900,0.04475,7.576,0.001
40.81,81.000,0.04491,7.596,0.001
40.88,81.100,0.04504,7.610,0.001
40.99,81.200,0.04521,7.630,0.001
41.07,81.300,0.04537,7.645,0.001
41.17,81.400,0.04554,7.663,0.001
41.27,81.500,0.04566,7.681,0.001
41.37,81.600,0.04583,7.700,0.001
41.45,81.700,0.04600,7.716,0.001
41.56,81.800,0.04616,7.736,0.001
41.66,81.900,0.04633,7.755,0.001
41.77,82.000,0.04649,7.776,0.001
41.87,82.100,0.04666,7.793,0.001
41.97,82.200,0.04683,7.813,0.001
42.09,82.300,0.04703,7.834,0.001
42.21,82.400,0.04720,7.858,0.001
42.33,82.500,0.04741,7.880,0.001
42.46,82.600,0.04757,7.903,0.001
42.58,82.700,0.04778,7.926,0.001
42.71,82.800,0.04799,7.951,0.001
42.86,82.900,0.04820,7.977,0.001
43.00,83.000,0.04841,8.005,0.001
43.14,83.100,0.04861,8.031,0.001
43.26,83.200,0.04882,8.053,0.001
43.40,83.300,0.04903,8.079,0.001
43.53,83.400,0.04924,8.102,0.001
43.67,83.500,0.04944,8.128,0.001
43.81,83.600,0.04965,8.154,0.001
43.92,83.700,0.04986,8.176,0.001
44.04,83.800,0.05007,8.198,0.001
44.16,83.900,0.05023,8.220,0.001
44.26,84.000,0.05044,8.239,0.001
44.38,84.100,0.05061,8.262,0.001
44.48,84.200,0.05077,8.279,0.001
44.58,84.300,0.05094,8.299,0.001
44.66,84.400,0.05107,8.314,0.001
44.76,84.500,0.05123,8.332,0.001
44.87,84.600,0.05140,8.351,0.001
44.95,84.700,0.05152,8.367,0.001
45.03,84.800,0.05169,8.383,0.001
45.12,84.900,0.05181,8.399,0.001
45.21,85.000,0.05194,8.415,0.001
45.30,85.100,0.05210,8.432,0.001
45.40,85.200,0.05223,8.450,0.001
45.48,85.300,0.05235,8.466,0.001
45.55,85.400,0.05252,8.479,0.001
45.64,85.500,0.05264,8.496,0.001
45.73,85.600,0.05277,8.513,0.001
45.83,85.700,0.05289,8.531,0.001
45.93,85.800,0.05306,8.549,0.001
46.01,85.900,0.05318,8.564,0.001
46.10,86.000,0.05335,8.582,0.001
46.21,86.100,0.05348,8.602,0.001
46.30,86.200,0.05364,8.618,0.001
46.40,86.300,0.05377,8.637,0.001
46.51,86.400,0.05393,8.657,0.001
46.61,86.500,0.05406,8.675,0.001
46.71,86.600,0.05422,8.694,0.001
46.80,86.700,0.05435,8.712,0.001
46.91,86.800,0.05451,8.732,0.001
47.03,86.900,0.05468,8.754,0.001
47.12,87.000,0.05481,8.771,0.001
47.23,87.100,0.05497,8.791,0.001
47.33,87.200,0.05514,8.811,0.001
47.44,87.300,0.05526,8.831,0.001
47.56,87.400,0.05543,8.852,0.001
47.67,87.500,0.05559,8.873,0.001
47.78,87.600,0.05576,8.894,0.001
47.91,87.700,0.05593,8.917,0.001
48.02,87.800,0.05609,8.938,0.001
48.15,87.900,0.05626,8.963,0.001
48.30,88.000,0.05647,8.991,0.001
48.43,88.100,0.05663,9.016,0.001
48.58,88.200,0.05684,9.043,0.001
48.73,88.300,0.05705,9.070,0.001
48.89,88.400,0.05726,9.100,0.001
49.05,88.500,0.05746,9.130,0.001
49.21,88.600,0.05767,9.160,0.001
49.36,88.700,0.05788,9.189,0.001
49.54,88.800,0.05813,9.222,0.001
49.68,88.900,0.05834,9.248,0.001
49.85,89.000,0.05855,9.279,0.001
49.99,89.100,0.05875,9.305,0.001
50.13,89.200,0.05896,9.331,0.001
50.27,89.300,0.05913,9.357,0.001
50.41,89.400,0.05933,9.383,0.001
50.53,89.500,0.05954,9.406,0.001
50.66,89.600,0.05971,9.429,0.001
50.76,89.700,0.05992,9.448,0.001
50.87,89.800,0.06004,9.470,0.001
50.96,89.900,0.06021,9.486,0.001
51.06,90.000,0.06037,9.504,0.001
51.16,90.100,0.06054,9.523,0.001
51.24,90.200,0.06066,9.538,0.001
51.34,90.300,0.06083,9.557,0.001
51.44,90.400,0.06096,9.576,0.001
51.54,90.500,0.06112,9.595,0.001
51.64,90.600,0.06125,9.612,0.001
51.71,90.700,0.06141,9.625,0.001
51.82,90.800,0.06154,9.645,0.001
51.92,90.900,0.06166,9.664,0.001
51.99,91.000,0.06179,9.677,0.001
52.07,91.100,0.06191,9.693,0.001
52.18,91.200,0.06208,9.714,0.001
52.30,91.300,0.06220,9.735,0.001
52.40,91.400,0.06233,9.754,0.001
52.50,91.500,0.06249,9.773,0.001
52.61,91.600,0.06262,9.792,0.001
52.71,91.700,0.06278,9.811,0.001
52.80,91.800,0.06291,9.829,0.001
52.92,91.900,0.06307,9.851,0.001
53.02,92.000,0.06320,9.870,0.001
53.11,92.100,0.06337,9.887,0.001
53.24,92.200,0.06349,9.910,0.001
53.36,92.300,0.06366,9.933,0.001
53.47,92.400,0.06382,9.953,0.001
53.60,92.500,0.06395,9.977,0.001
53.71,92.600,0.06411,9.998,0.001
53.81,92.700,0.06428,10.017,0.001
53.93,92.800,0.06445,10.038,0.001
54.07,92.900,0.06457,10.065,0.001
54.18,93.000,0.06474,10.085,0.001
54.31,93.100,0.06490,10.110,0.001
54.43,93.200,0.06507,10.131,0.001
54.54,93.300,0.06524,10.152,0.001
54.67,93.400,0.06540,10.177,0.001
54.79,93.500,0.06557,10.199,0.001
54.92,93.600,0.06573,10.224,0.001
55.07,93.700,0.06594,10.251,0.001
55.23,93.800,0.06611,10.280,0.001
55.39,93.900,0.06632,10.311,0.001
55.55,94.000,0.06652,10.340,0.001
55.73,94.100,0.06673,10.374,0.001
55.89,94.200,0.06694,10.404,0.001
56.07,94.300,0.06715,10.438,0.001
56.24,94.400,0.06740,10.469,0.001
56.41,94.500,0.06760,10.501,0.001
56.58,94.600,0.06781,10.531,0.001
56.74,94.700,0.06802,10.562,0.001
56.88,94.800,0.06823,10.587,0.001
57.02,94.900,0.06844,10.614,0.001
57.16,95.000,0.06860,10.640,0.001
57.31,95.100,0.06881,10.668,0.001
57.45,95.200,0.06898,10.694,0.001
57.60,95.300,0.06918,10.722,0.001
57.74,95.400,0.06935,10.748,0.001
57.87,95.500,0.06952,10.773,0.001
57.99,95.600,0.06968,10.795,0.001
58.11,95.700,0.06985,10.816,0.001
58.22,95.800,0.07001,10.837,0.001
58.33,95.900,0.07018,10.858,0.001
58.46,96.000,0.07031,10.882,0.001
58.56,96.100,0.07047,10.901,0.001
58.69,96.200,0.07064,10.924,0.001
58.79,96.300,0.07076,10.944,0.001
58.90,96.400,0.07089,10.965,0.001
59.01,96.500,0.07101,10.984,0.001
59.12,96.600,0.07118,11.005,0.001
59.23,96.700,0.07130,11.025,0.001
59.34,96.800,0.07143,11.045,0.001
59.44,96.900,0.07159,11.065,0.001
59.56,97.000,0.07172,11.088,0.001
59.66,97.100,0.07184,11.105,0.001
59.78,97.200,0.07201,11.128,0.001
59.90,97.300,0.07213,11.150,0.001
60.02,97.400,0.07226,11.172,0.001
60.13,97.500,0.07242,11.192,0.001
60.26,97.600,0.07255,11.218,0.001
60.41,97.700,0.07272,11.244,0.001
60.54,97.800,0.07288,11.269,0.001
60.66,97.900,0.07301,11.292,0.001
60.78,98.000,0.07317,11.314,0.001
60.94,98.100,0.07334,11.343,0.001
61.07,98.200,0.07346,11.367,0.001
61.20,98.300,0.07363,11.392,0.001
61.33,98.400,0.07380,11.417,0.001
61.48,98.500,0.07392,11.444,0.001
61.61,98.600,0.07409,11.468,0.001
61.75,98.700,0.07425,11.495,0.001
61.88,98.800,0.07442,11.519,0.001
62.03,98.900,0.07459,11.546,0.001
62.18,99.000,0.07471,11.574,0.001
62.33,99.100,0.07488,11.603,0.001
62.47,99.200,0.07504,11.629,0.001
62.64,99.300,0.07525,11.659,0.001
62.81,99.400,0.07542,11.691,0.001
62.96,99.500,0.07562,11.720,0.001
63.14,99.600,0.07579,11.753,0.001
63.31,99.700,0.07600,11.785,0.001
63.50,99.800,0.07621,11.820,0.002
63.67,99.900,0.07641,11.853,0.002
63.87,100.000,0.07658,11.889,0.002
64.07,100.100,0.07679,11.927,0.002
64.25,100.200,0.07700,11.960,0.002
64.44,100.300,0.07720,11.995,0.002
64.62,100.400,0.07741,12.028,0.002
64.81,100.500,0.07762,12.063,0.002
64.97,100.600,0.07783,12.094,0.002
65.14,100.700,0.07799,12.126,0.002
65.34,100.800,0.07820,12.163,0.002
65.48,100.900,0.07841,12.190,0.002
65.65,101.000,0.07858,12.221,0.002
65.81,101.100,0.07878,12.251,0.002
65.96,101.200,0.07895,12.278,0.002
66.11,101.300,0.07912,12.305,0.002
66.25,101.400,0.07928,12.333,0.002
66.38,101.500,0.07941,12.356,0.002
66.52,101.600,0.07957,12.382,0.002
66.64,101.700,0.07974,12.405,0.002
66.77,101.800,0.07986,12.429,0.002
66.89,101.900,0.08003,12.452,0.002
67.04,102.000,0.08015,12.478,0.002
67.16,102.100,0.08032,12.502,0.002
27.58,102.200,0.08045,5.133,0.002
30.37,102.300,0.08057,5.654,0.002
30.81,102.400,0.08069,5.735,0.002
31.01,102.500,0.08086,5.772,0.002
31.19,102.600,0.08099,5.805,0.002
31.36,102.700,0.08111,5.837,0.002
31.53,102.800,0.08123,5.870,0.002
31.68,102.900,0.08140,5.897,0.002
31.82,103.000,0.08153,5.924,0.002
31.99,103.100,0.08169,5.955,0.002
32.11,103.200,0.08182,5.976,0.002
32.25,103.300,0.08194,6.003,0.002
32.37,103.400,0.08211,6.026,0.002
32.48,103.500,0.08227,6.046,0.002
32.60,103.600,0.08240,6.068,0.002
32.69,103.700,0.08256,6.085,0.002
32.79,103.800,0.08269,6.104,0.002
32.90,103.900,0.08286,6.124,0.002
32.98,104.000,0.08302,6.139,0.002
33.09,104.100,0.08315,6.160,0.002
33.18,104.200,0.08331,6.176,0.002
33.28,104.300,0.08348,6.195,0.002
33.37,104.400,0.08364,6.211,0.002
33.45,104.500,0.08377,6.227,0.002
33.51,104.600,0.08394,6.238,0.002
33.61,104.700,0.08410,6.257,0.002
33.69,104.800,0.08427,6.270,0.002
33.79,104.900,0.08443,6.289,0.002
33.87,105.000,0.08460,6.304,0.002
33.95,105.100,0.08481,6.319,0.002
34.03,105.200,0.08497,6.334,0.002
34.13,105.300,0.08518,6.353,0.002
34.21,105.400,0.08535,6.368,0.002
34.30,105.500,0.08556,6.385,0.002
34.38,105.600,0.08581,6.399,0.002
34.48,105.700,0.08601,6.419,0.002
34.57,105.800,0.08622,6.435,0.002
34.65,105.900,0.08643,6.450,0.002
34.74,106.000,0.08664,6.466,0.002
34.82,106.100,0.08684,6.482,0.002
34.89,106.200,0.08705,6.494,0.002
34.98,106.300,0.08726,6.511,0.002
35.06,106.400,0.08747,6.526,0.002
35.11,106.500,0.08768,6.536,0.002
35.13,106.570,0.08780,6.540,0.002