File: data-files/CWRU/0900-05-24C.txt
""
"Test Method","Will_Huddleston_Load_Rate.msm"
"Sample I. D.","900-5-24C.mss"
"Specimen Number","2"

"Load (N)","Time (s)","Extension (mm)"

-9.93,0.040,-0.00965
-9.95,0.200,-0.00965
-9.94,0.360,-0.00965
-9.95,0.520,-0.00965
-9.95,0.680,-0.00965
-9.95,0.840,-0.00965
-9.94,1.000,-0.00965
-9.95,1.160,-0.00965
-9.95,1.320,-0.00965
-9.94,1.480,-0.00965
-9.93,1.640,-0.00965
-9.94,1.800,-0.00965
-9.95,1.960,-0.00965
-9.94,2.120,-0.00965
-9.95,2.280,-0.00965
-9.94,2.440,-0.00965
-9.94,2.600,-0.00965
-9.94,2.760,-0.00965
-9.94,2.920,-0.00965
-9.94,3.080,-0.00965
-9.94,3.240,-0.00965
-9.95,3.400,-0.00965
-9.95,3.560,-0.00965
-9.93,3.720,-0.00965
-9.95,3.880,-0.00965
-9.94,4.040,-0.00965
-9.95,4.200,-0.00965
-9.94,4.360,-0.00965
-9.96,4.520,-0.00965
-9.94,4.680,-0.00965
-9.94,4.840,-0.00965
-9.94,5.000,-0.00965
-9.94,5.160,-0.00965
-9.94,5.320,-0.00965
-9.94,5.480,-0.00965
-9.94,5.640,-0.00965
-9.93,5.800,-0.00965
-9.94,5.960,-0.00965
-9.94,6.120,-0.00965
-9.93,6.280,-0.00965
-9.93,6.440,-0.00965
-9.93,6.600,-0.00965
-9.94,6.760,-0.00965
-9.93,6.920,-0.00965
-9.94,7.080,-0.00965
-9.94,7.240,-0.00965
-9.94,7.400,-0.00965
-9.93,7.560,-0.00965
-9.95,7.720,-0.00965
-9.93,7.880,-0.00965
-9.93,8.040,-0.00965
-9.94,8.200,-0.00965
-9.93,8.360,-0.00965
-9.93,8.520,-0.00965
-9.94,8.680,-0.00965
-9.93,8.840,-0.00965
-9.92,9.000,-0.00965
-9.94,9.160,-0.00965
-9.93,9.320,-0.00965
-9.94,9.480,-0.00965
-9.94,9.640,-0.00965
-9.94,9.800,-0.00965
-9.93,9.960,-0.00965
-9.92,10.120,-0.00965
-9.94,10.280,-0.00965
-9.94,10.440,-0.00965
-9.94,10.600,-0.00969
-9.95,10.760,-0.00969
-9.94,10.920,-0.00969
-9.93,11.080,-0.00969
-9.95,11.240,-0.00969
-9.95,11.400,-0.00969
-9.94,11.560,-0.00969
-9.94,11.720,-0.00969
-9.94,11.880,-0.00969
-9.95,12.040,-0.00969
-9.94,12.200,-0.00969
-9.94,12.360,-0.00969
-9.93,12.520,-0.00969
-9.94,12.680,-0.00969
-9.94,12.840,-0.00969
-9.94,13.000,-0.00969
-9.94,13.160,-0.00969
-9.94,13.320,-0.00969
-9.93,13.480,-0.00969
-9.93,13.640,-0.00969
-9.95,13.800,-0.00969
-9.93,13.960,-0.00969
-9.95,14.120,-0.00969
-9.95,14.280,-0.00969
-9.95,14.440,-0.00969
-9.95,14.600,-0.00969
-9.95,14.760,-0.00969
-9.95,14.920,-0.00973
-9.94,15.080,-0.00973
-9.94,15.240,-0.00973
-9.94,15.400,-0.00973
-9.94,15.560,-0.00973
-9.94,15.720,-0.00973
-9.94,15.880,-0.00973
-9.94,16.040,-0.00973
-9.94,16.200,-0.00973
-9.93,16.360,-0.00973
-9.94,16.520,-0.00973
-9.93,16.680,-0.00973
-9.94,16.840,-0.00973
-9.94,17.000,-0.00973
-9.93,17.160,-0.00973
-9.93,17.320,-0.00973
-9.94,17.480,-0.00973
-9.94,17.640,-0.00973
-9.93,17.800,-0.00973
-9.94,17.960,-0.00973
-9.93,18.120,-0.00973
-9.94,18.280,-0.00973
-9.95,18.440,-0.00973
-9.93,18.600,-0.00973
-9.94,18.760,-0.00977
-9.94,18.920,-0.00977
-9.94,19.080,-0.00977
-9.94,19.240,-0.00977
-9.93,19.400,-0.00977
-9.95,19.560,-0.00977
-9.94,19.720,-0.00977
-9.97,19.880,-0.00977
-9.95,20.040,-0.00977
-9.96,20.200,-0.00977
-9.96,20.360,-0.00977
-9.94,20.520,-0.00977
-9.94,20.680,-0.00977
-9.95,20.840,-0.00977
-9.95,21.000,-0.00977
-9.95,21.160,-0.00977
-9.94,21.320,-0.00977
-9.95,21.480,-0.00977
-9.96,21.640,-0.00977
-9.95,21.800,-0.00981
-9.95,21.960,-0.00981
-9.95,22.120,-0.00981
-9.95,22.280,-0.00981
-9.96,22.440,-0.00981
-9.97,22.600,-0.00981
-9.96,22.760,-0.00981
-9.96,22.920,-0.00981
-9.95,23.080,-0.00981
-9.97,23.240,-0.00981
-9.95,23.400,-0.00981
-9.95,23.560,-0.00981
-9.97,23.720,-0.00981
-9.97,23.880,-0.00981
-9.97,24.040,-0.00985
-9.97,24.200,-0.00985
-9.98,24.360,-0.00985
-9.98,24.520,-0.00985
-9.99,24.680,-0.00985
-9.98,24.840,-0.00985
-9.98,25.000,-0.00985
-9.97,25.160,-0.00985
-9.99,25.320,-0.00985
-9.99,25.480,-0.00990
-10.00,25.640,-0.00990
-9.98,25.800,-0.00990
-9.98,25.960,-0.00990
-10.00,26.120,-0.00990
-9.99,26.280,-0.00990
-10.00,26.440,-0.00990
-10.01,26.600,-0.00994
-10.02,26.760,-0.00994
-10.02,26.920,-0.00994
-10.03,27.080,-0.00994
-10.03,27.240,-0.00994
-10.03,27.400,-0.00994
-10.05,27.560,-0.00998
-10.05,27.720,-0.00998
-10.05,27.880,-0.00998
-10.06,28.040,-0.00998
-10.06,28.200,-0.00998
-10.06,28.360,-0.00998
-10.06,28.520,-0.01002
-10.09,28.680,-0.01002
-10.09,28.840,-0.01002
-10.08,29.000,-0.01002
-10.10,29.160,-0.01002
-10.09,29.320,-0.01006
-10.11,29.480,-0.01006
-10.10,29.640,-0.01006
-10.11,29.800,-0.01006
-10.11,29.960,-0.01010
-10.12,30.120,-0.01010
-10.13,30.280,-0.01010
-10.15,30.440,-0.01010
-10.16,30.600,-0.01010
-10.16,30.760,-0.01014
-10.17,30.920,-0.01014
-10.17,31.080,-0.01014
-10.19,31.240,-0.01014
-10.20,31.400,-0.01019
-10.20,31.560,-0.01019
-10.20,31.720,-0.01019
-10.22,31.880,-0.01019
-10.22,32.040,-0.01023
-10.25,32.200,-0.01023
-10.24,32.360,-0.01023
-10.25,32.520,-0.01023
-10.27,32.680,-0.01027
-10.27,32.840,-0.01027
-10.29,33.000,-0.01027
-10.31,33.160,-0.01031
-10.31,33.320,-0.01031
-10.33,33.480,-0.01031
-10.34,33.640,-0.01031
-10.35,33.800,-0.01035
-10.36,33.960,-0.01035
-10.38,34.120,-0.01035
-10.38,34.280,-0.01039
-10.40,34.440,-0.01039
-10.41,34.600,-0.01039
-10.42,34.760,-0.01044
-10.44,34.920,-0.01044
-10.46,35.080,-0.01044
-10.48,35.240,-0.01048
-10.48,35.400,-0.01048
-10.51,35.560,-0.01048
-10.52,35.720,-0.01052
-10.53,35.880,-0.01052
-10.56,36.040,-0.01052
-10.58,36.200,-0.01056
-10.59,36.360,-0.01056
-10.59,36.520,-0.01060
-10.62,36.680,-0.01060
-10.62,36.840,-0.01060
-10.65,37.000,-0.01064
-10.66,37.160,-0.01064
-10.69,37.320,-0.01064
-10.70,37.480,-0.01069
-10.72,37.640,-0.01069
-10.75,37.800,-0.01069
-10.74,37.960,-0.01073
-10.76,38.120,-0.01073
-10.78,38.280,-0.01077
-10.80,38.440,-0.01077
-10.79,38.600,-0.01077
-10.82,38.760,-0.01081
-10.83,38.920,-0.01081
-10.83,39.080,-0.01081
-10.86,39.240,-0.01085
-10.88,39.400,-0.01085
-10.88,39.560,-0.01085
-10.91,39.720,-0.01089
-10.92,39.880,-0.01089
-10.93,40.040,-0.01093
-10.95,40.200,-0.01093
-10.97,40.360,-0.01093
-10.97,40.520,-0.01098
-10.99,40.680,-0.01098
-11.00,40.840,-0.01098
-11.02,41.000,-0.01102
-11.03,41.160,-0.01102
-11.03,41.320,-0.01102
-11.06,41.480,-0.01106
-11.06,41.640,-0.01106
-11.07,41.800,-0.01106
-11.08,41.960,-0.01110
-11.09,42.120,-0.01110
-11.11,42.280,-0.01110
-11.13,42.440,-0.01114
-11.15,42.600,-0.01114
-11.14,42.760,-0.01114
-11.16,42.920,-0.01118
-11.16,43.080,-0.01118
-11.17,43.240,-0.01118
-11.19,43.400,-0.01123
-11.21,43.560,-0.01123
-11.21,43.720,-0.01123
-11.22,43.880,-0.01127
-11.24,44.040,-0.01127
-11.26,44.200,-0.01127
-11.26,44.360,-0.01131
-11.26,44.520,-0.01131
-11.28,44.680,-0.01131
-11.29,44.840,-0.01135
-11.30,45.000,-0.01135
-11.29,45.160,-0.01135
-11.32,45.320,-0.01139
-11.35,45.480,-0.01139
-11.34,45.640,-0.01139
-11.37,45.800,-0.01143
-11.36,45.960,-0.01143
-11.36,46.120,-0.01143
-11.39,46.280,-0.01147
-11.39,46.440,-0.01147
-11.39,46.600,-0.01147
-11.41,46.760,-0.01152
-11.42,46.920,-0.01152
-11.43,47.080,-0.01152
-11.43,47.240,-0.01156
-11.46,47.400,-0.01156
-11.47,47.560,-0.01156
-11.46,47.720,-0.01160
-11.48,47.880,-0.01160
-11.49,48.040,-0.01160
-11.48,48.200,-0.01160
-11.50,48.360,-0.01164
-11.50,48.520,-0.01164
-11.52,48.680,-0.01164
-11.53,48.840,-0.01168
-11.53,49.000,-0.01168
-11.54,49.160,-0.01168
-11.55,49.320,-0.01172
-11.55,49.480,-0.01172
-11.57,49.640,-0.01172
-11.58,49.800,-0.01177
-11.59,49.960,-0.01177
-11.60,50.120,-0.01177
-11.60,50.280,-0.01177
-11.63,50.440,-0.01181
-11.62,50.600,-0.01181
-11.63,50.760,-0.01181
-11.64,50.920,-0.01185
-11.66,51.080,-0.01185
-11.67,51.240,-0.01185
-11.68,51.400,-0.01189
-11.68,51.560,-0.01189
-11.68,51.720,-0.01189
-11.69,51.880,-0.01189
-11.71,52.040,-0.01193
-11.71,52.200,-0.01193
-11.73,52.360,-0.01193
-11.73,52.520,-0.01197
-11.73,52.680,-0.01197
-11.74,52.840,-0.01197
-11.74,53.000,-0.01201
-11.75,53.160,-0.01201
-11.76,53.320,-0.01201
-11.77,53.480,-0.01201
-11.78,53.640,-0.01206
-11.80,53.800,-0.01206
-11.79,53.960,-0.01206
-11.81,54.120,-0.01210
-11.82,54.280,-0.01210
-11.83,54.440,-0.01210
-11.82,54.600,-0.01214
-11.84,54.760,-0.01214
-11.85,54.920,-0.01214
-11.85,55.080,-0.01218
-11.87,55.240,-0.01218
-11.87,55.400,-0.01218
-11.88,55.560,-0.01218
-11.89,55.720,-0.01222
-11.90,55.880,-0.01222
-11.92,56.040,-0.01222
-11.91,56.200,-0.01226
-11.93,56.360,-0.01226
-11.93,56.520,-0.01226
-11.94,56.680,-0.01231
-11.94,56.840,-0.01231
-11.95,57.000,-0.01231
-11.95,57.160,-0.01231
-11.97,57.320,-0.01235
-11.97,57.480,-0.01235
-11.97,57.640,-0.01235
-11.99,57.800,-0.01239
-12.00,57.960,-0.01239
-12.00,58.120,-0.01239
-12.02,58.280,-0.01239
-12.01,58.440,-0.01243
-12.03,58.600,-0.01243
-12.05,58.760,-0.01243
-12.05,58.920,-0.01247
-12.05,59.080,-0.01247
-12.07,59.240,-0.01247
-12.07,59.400,-0.01251
-12.08,59.560,-0.01251
-12.08,59.720,-0.01251
-12.09,59.880,-0.01251
-12.12,60.040,-0.01256
-12.11,60.200,-0.01256
-12.12,60.360,-0.01256
-12.13,60.520,-0.01260
-12.13,60.680,-0.01260
-12.14,60.840,-0.01260
-12.15,61.000,-0.01260
-12.15,61.160,-0.01264
-12.16,61.320,-0.01264
-12.18,61.480,-0.01264
-12.17,61.640,-0.01268
-12.17,61.800,-0.01268
-12.19,61.960,-0.01268
-12.18,62.120,-0.01268
-12.20,62.280,-0.01272
-12.22,62.440,-0.01272
-12.22,62.600,-0.01272
-12.21,62.760,-0.01276
-12.23,62.920,-0.01276
-12.23,63.080,-0.01276
-12.25,63.240,-0.01276
-12.25,63.400,-0.01280
-12.25,63.560,-0.01280
-12.26,63.720,-0.01280
-12.28,63.880,-0.01285
-12.29,64.040,-0.01285
-12.29,64.200,-0.01285
-12.30,64.360,-0.01289
-12.32,64.520,-0.01289
-12.31,64.680,-0.01289
-12.32,64.840,-0.01289
-12.34,65.000,-0.01293
-12.34,65.160,-0.01293
-12.35,65.320,-0.01293
-12.37,65.480,-0.01297
-12.35,65.640,-0.01297
-12.38,65.800,-0.01297
-12.37,65.960,-0.01297
-12.39,66.120,-0.01301
-12.38,66.280,-0.01301
-12.39,66.440,-0.01301
-12.42,66.600,-0.01305
-12.42,66.760,-0.01305
-12.43,66.920,-0.01305
-12.43,67.080,-0.01305
-12.44,67.240,-0.01310
-12.45,67.400,-0.01310
-12.46,67.560,-0.01310
-12.46,67.720,-0.01314
-12.48,67.880,-0.01314
-12.48,68.040,-0.01314
-12.50,68.200,-0.01318
-12.50,68.360,-0.01318
-12.50,68.520,-0.01318
-12.52,68.680,-0.01322
-12.52,68.840,-0.01322
-12.53,69.000,-0.01322
-12.55,69.160,-0.01322
-12.54,69.320,-0.01326
-12.56,69.480,-0.01326
-12.54,69.640,-0.01326
-12.56,69.800,-0.01330
-12.57,69.960,-0.01330
-12.57,70.120,-0.01330
-12.58,70.280,-0.01330
-12.59,70.440,-0.01334
-12.59,70.600,-0.01334
-12.61,70.760,-0.01334
-12.61,70.920,-0.01339
-12.62,71.080,-0.01339
-12.62,71.240,-0.01339
-12.63,71.400,-0.01343
-12.63,71.560,-0.01343
-12.65,71.720,-0.01343
-12.65,71.880,-0.01343
-12.67,72.040,-0.01347
-12.67,72.200,-0.01347
-12.68,72.360,-0.01347
-12.69,72.520,-0.01351
-12.69,72.680,-0.01351
-12.69,72.840,-0.01351
-12.71,73.000,-0.01355
-12.70,73.160,-0.01355
-12.73,73.320,-0.01355
-12.74,73.480,-0.01355
-12.75,73.640,-0.01359
-12.76,73.800,-0.01359
-12.77,73.960,-0.01359
-12.78,74.120,-0.01364
-12.79,74.280,-0.01364
-12.79,74.440,-0.01364
-12.80,74.600,-0.01368
-12.80,74.760,-0.01368
-12.81,74.920,-0.01368
-12.83,75.080,-0.01372
-12.84,75.240,-0.01372
-12.83,75.400,-0.01372
-12.86,75.560,-0.01376
-12.88,75.720,-0.01376
-12.87,75.880,-0.01376
-12.87,76.040,-0.01376
-12.87,76.200,-0.01380
-12.89,76.360,-0.01380
-12.88,76.520,-0.01380
-12.89,76.680,-0.01384
-12.91,76.840,-0.01384
-12.91,77.000,-0.01384
-12.94,77.160,-0.01388
-12.94,77.320,-0.01388
-12.94,77.480,-0.01388
-12.95,77.640,-0.01393
-12.96,77.800,-0.01393
-12.98,77.960,-0.01393
-12.97,78.120,-0.01397
-12.99,78.280,-0.01397
-12.99,78.440,-0.01397
-13.01,78.600,-0.01397
-13.00,78.760,-0.01401
-13.02,78.920,-0.01401
-13.03,79.080,-0.01401
-13.04,79.240,-0.01405
-13.03,79.400,-0.01405
-13.05,79.560,-0.01405
-13.06,79.720,-0.01409
-13.06,79.880,-0.01409
-13.07,80.040,-0.01409
-13.08,80.200,-0.01413
-13.09,80.360,-0.01413
-13.10,80.520,-0.01413
-13.11,80.680,-0.01418
-13.11,80.840,-0.01418
-13.12,81.000,-0.01418
-13.14,81.160,-0.01422
-13.14,81.320,-0.01422
-13.15,81.480,-0.01422
-13.17,81.640,-0.01422
-13.17,81.800,-0.01426
-13.18,81.960,-0.01426
-13.18,82.120,-0.01426
-13.20,82.280,-0.01430
-13.20,82.440,-0.01430
-13.21,82.600,-0.01430
-13.22,82.760,-0.01434
-13.21,82.920,-0.01434
-13.25,83.080,-0.01434
-13.24,83.240,-0.01438
-13.24,83.400,-0.01438
-13.26,83.560,-0.01438
-13.26,83.720,-0.01443
-13.27,83.880,-0.01443
-13.28,84.040,-0.01443
-13.29,84.200,-0.01447
-13.29,84.360,-0.01447
-13.31,84.520,-0.01447
-13.30,84.680,-0.01451
-13.34,84.840,-0.01451
-13.33,85.000,-0.01451
-13.34,85.160,-0.01455
-13.34,85.320,-0.01455
-13.35,85.480,-0.01455
-13.35,85.640,-0.01459
-13.37,85.800,-0.01459
-13.38,85.960,-0.01459
-13.37,86.120,-0.01463
-13.39,86.280,-0.01463
-13.41,86.440,-0.01463
-13.42,86.600,-0.01467
-13.42,86.760,-0.01467
-13.43,86.920,-0.01467
-13.44,87.080,-0.01472
-13.45,87.240,-0.01472
-13.46,87.400,-0.01472
-13.47,87.560,-0.01476
-13.48,87.720,-0.01476
-13.48,87.880,-0.01476
-13.49,88.040,-0.01480
-13.49,88.200,-0.01480
-13.50,88.360,-0.01480
-13.52,88.520,-0.01484
-13.53,88.680,-0.01484
-13.53,88.840,-0.01484
-13.56,89.000,-0.01488
-13.57,89.160,-0.01488
-13.57,89.320,-0.01488
-13.57,89.480,-0.01492
-13.57,89.640,-0.01492
-13.59,89.800,-0.01492
-13.58,89.960,-0.01497
-13.60,90.120,-0.01497
-13.62,90.280,-0.01497
-13.62,90.440,-0.01501
-13.63,90.600,-0.01501
-13.62,90.760,-0.01501
-13.64,90.920,-0.01505
-13.64,91.080,-0.01505
-13.64,91.240,-0.01505
-13.68,91.400,-0.01509
-13.68,91.560,-0.01509
-13.69,91.720,-0.01509
-13.69,91.880,-0.01513
-13.71,92.040,-0.01513
-13.71,92.200,-0.01513
-13.73,92.360,-0.01517
-13.75,92.520,-0.01517
-13.74,92.680,-0.01517
-13.76,92.840,-0.01521
-13.76,93.000,-0.01521
-13.76,93.160,-0.01521
-13.78,93.320,-0.01526
-13.77,93.480,-0.01526
-13.79,93.640,-0.01526
-13.80,93.800,-0.01530
-13.80,93.960,-0.01530
-13.82,94.120,-0.01530
-13.83,94.280,-0.01534
-13.84,94.440,-0.01534
-13.87,94.600,-0.01538
-13.87,94.760,-0.01538
-13.88,94.920,-0.01538
-13.88,95.080,-0.01542
-13.89,95.240,-0.01542
-13.90,95.400,-0.01542
-13.91,95.560,-0.01546
-13.92,95.720,-0.01546
-13.92,95.880,-0.01546
-13.92,96.040,-0.01551
-13.95,96.200,-0.01551
-13.95,96.360,-0.01551
-13.96,96.520,-0.01555
-13.95,96.680,-0.01555
-13.97,96.840,-0.01559
-13.99,97.000,-0.01559
-14.00,97.160,-0.01559
-14.01,97.320,-0.01563
-14.01,97.480,-0.01563
-14.02,97.640,-0.01563
-14.03,97.800,-0.01567
-14.05,97.960,-0.01567
-14.06,98.120,-0.01567
-14.08,98.280,-0.01571
-14.08,98.440,-0.01571
-14.07,98.600,-0.01571
-14.10,98.760,-0.01575
-14.09,98.920,-0.01575
-14.09,99.080,-0.01575
-14.11,99.240,-0.01580
-14.12,99.400,-0.01580
-14.13,99.560,-0.01580
-14.14,99.720,-0.01584
-14.16,99.880,-0.01584
-14.17,100.040,-0.01588
-14.16,100.200,-0.01588
-14.17,100.360,-0.01588
-14.19,100.520,-0.01592
-14.21,100.680,-0.01592
-14.21,100.840,-0.01592
-14.21,101.000,-0.01596
-14.23,101.160,-0.01596
-14.23,101.320,-0.01596
-14.24,101.480,-0.01600
-14.24,101.640,-0.01600
-14.25,101.800,-0.01600
-14.26,101.960,-0.01605
-14.26,102.120,-0.01605
-14.29,102.280,-0.01605
-14.30,102.440,-0.01609
-14.29,102.600,-0.01609
-14.31,102.760,-0.01613
-14.32,102.920,-0.01613
-14.31,103.080,-0.01613
-14.34,103.240,-0.01617
-14.35,103.400,-0.01617
-14.36,103.560,-0.01617
-14.36,103.720,-0.01621
-14.39,103.880,-0.01621
-14.39,104.040,-0.01625
-14.39,104.200,-0.01625
-14.40,104.360,-0.01625
-14.43,104.520,-0.01630
-14.44,104.680,-0.01630
-14.44,104.840,-0.01630
-14.45,105.000,-0.01634
-14.45,105.160,-0.01634
-14.47,105.320,-0.01638
-14.46,105.480,-0.01638
-14.48,105.640,-0.01638
-14.50,105.800,-0.01642
-14.49,105.960,-0.01642
-14.52,106.120,-0.01646
-14.53,106.280,-0.01646
-14.54,106.440,-0.01646
-14.54,106.600,-0.01650
-14.55,106.760,-0.01650
-14.56,106.920,-0.01654
-14.57,107.080,-0.01654
-14.58,107.240,-0.01654
-14.59,107.400,-0.01659
-14.61,107.560,-0.01659
-14.63,107.720,-0.01663
-14.63,107.880,-0.01663
-14.62,108.040,-0.01663
-14.64,108.200,-0.01667
-14.65,108.360,-0.01667
-14.66,108.520,-0.01667
-14.67,108.680,-0.01671
-14.69,108.840,-0.01671
-14.70,109.000,-0.01675
-14.71,109.160,-0.01675
-14.72,109.320,-0.01679
-14.72,109.480,-0.01679
-14.73,109.640,-0.01679
-14.75,109.800,-0.01684
-14.76,109.960,-0.01684
-14.78,110.120,-0.01688
-14.78,110.280,-0.01688
-14.79,110.440,-0.01688
-14.79,110.600,-0.01692
-14.80,110.760,-0.01692
-14.81,110.920,-0.01696
-14.83,111.080,-0.01696
-14.83,111.240,-0.01700
-14.85,111.400,-0.01700
-14.86,111.560,-0.01700
-14.87,111.720,-0.01704
-14.88,111.880,-0.01704
-14.88,112.040,-0.01708
-14.90,112.200,-0.01708
-14.90,112.360,-0.01713
-14.90,112.520,-0.01713
-14.93,112.680,-0.01713
-14.93,112.840,-0.01717
-14.94,113.000,-0.01717
-14.95,113.160,-0.01721
-14.96,113.320,-0.01721
-15.00,113.480,-0.01725
-15.00,113.640,-0.01725
-15.01,113.800,-0.01729
-15.03,113.960,-0.01729
-15.03,114.120,-0.01733
-15.04,114.280,-0.01733
-15.07,114.440,-0.01733
-15.06,114.600,-0.01738
-15.08,114.760,-0.01738
-15.10,114.920,-0.01742
-15.10,115.080,-0.01742
-15.12,115.240,-0.01746
-15.12,115.400,-0.01746
-15.14,115.560,-0.01750
-15.16,115.720,-0.01750
-15.16,115.880,-0.01754
-15.17,116.040,-0.01754
-15.17,116.200,-0.01758
-15.19,116.360,-0.01758
-15.21,116.520,-0.01762
-15.20,116.680,-0.01762
-15.22,116.840,-0.01767
-15.25,117.000,-0.01767
-15.25,117.160,-0.01771
-15.25,117.320,-0.01771
-15.27,117.480,-0.01775
-15.28,117.640,-0.01775
-15.29,117.800,-0.01775
-15.31,117.960,-0.01779
-15.31,118.120,-0.01779
-15.32,118.280,-0.01783
-15.33,118.440,-0.01783
-15.34,118.600,-0.01787
-15.36,118.760,-0.01787
-15.38,118.920,-0.01792
-15.38,119.080,-0.01792
-15.40,119.240,-0.01796
-15.39,119.400,-0.01796
-15.41,119.560,-0.01800
-15.41,119.720,-0.01800
-15.43,119.880,-0.01804
-15.45,120.040,-0.01804
-15.45,120.200,-0.01808
-15.46,120.360,-0.01808
-15.46,120.520,-0.01812
-15.48,120.680,-0.01812
-15.50,120.840,-0.01817
-15.52,121.000,-0.01817
-15.52,121.160,-0.01821
-15.53,121.320,-0.01821
-15.53,121.480,-0.01825
-15.55,121.640,-0.01825
-15.55,121.800,-0.01829
-15.55,121.960,-0.01829
-15.58,122.120,-0.01833
-15.57,122.280,-0.01833
-15.58,122.440,-0.01833
-15.61,122.600,-0.01837
-15.60,122.760,-0.01837
-15.63,122.920,-0.01841
-15.63,123.080,-0.01841
-15.64,123.240,-0.01846
-15.66,123.400,-0.01846
-15.66,123.560,-0.01850
-15.67,123.720,-0.01850
-15.68,123.880,-0.01854
-15.70,124.040,-0.01854
-15.70,124.200,-0.01858
-15.72,124.360,-0.01858
-15.73,124.520,-0.01862
-15.75,124.680,-0.01862
-15.75,124.840,-0.01866
-15.75,125.000,-0.01866
-15.77,125.160,-0.01871
-15.78,125.320,-0.01871
-15.80,125.480,-0.01875
-15.80,125.640,-0.01875
-15.80,125.800,-0.01879
-15.82,125.960,-0.01879
-15.84,126.120,-0.01883
-15.84,126.280,-0.01883
-15.87,126.440,-0.01883
-15.86,126.600,-0.01887
-15.88,126.760,-0.01887
-15.88,126.920,-0.01891
-15.88,127.080,-0.01891
-15.89,127.240,-0.01895
-15.91,127.400,-0.01895
-15.91,127.560,-0.01900
-15.93,127.720,-0.01900
-15.94,127.880,-0.01904
-15.96,128.040,-0.01904
-15.97,128.200,-0.01908
-15.97,128.360,-0.01908
-15.98,128.520,-0.01908
-15.99,128.680,-0.01912
-16.00,128.840,-0.01912
-16.02,129.000,-0.01916
-16.01,129.160,-0.01916
-16.02,129.320,-0.01920
-16.05,129.480,-0.01920
-16.04,129.640,-0.01925
-16.06,129.800,-0.01925
-16.08,129.960,-0.01929
-16.08,130.120,-0.01929
-16.10,130.280,-0.01933
-16.10,130.440,-0.01933
-16.10,130.600,-0.01933
-16.13,130.760,-0.01937
-16.13,130.920,-0.01937
-16.15,131.080,-0.01941
-16.16,131.240,-0.01941
-16.16,131.400,-0.01945
-16.17,131.560,-0.01945
-16.19,131.720,-0.01949
-16.19,131.880,-0.01949
-16.21,132.040,-0.01954
-16.20,132.200,-0.01954
-16.22,132.360,-0.01954
-16.23,132.520,-0.01958
-16.24,132.680,-0.01958
-16.25,132.840,-0.01962
-16.26,133.000,-0.01962
-16.24,133.160,-0.01966
-16.27,133.320,-0.01966
-16.28,133.480,-0.01966
-16.28,133.640,-0.01970
-16.29,133.800,-0.01970
-16.29,133.960,-0.01974
-16.31,134.120,-0.01974
-16.30,134.280,-0.01974
-16.31,134.440,-0.01979
-16.34,134.600,-0.01979
-16.35,134.760,-0.01983
-16.36,134.920,-0.01983
-16.36,135.080,-0.01987
-16.37,135.240,-0.01987
-16.37,135.400,-0.01987
-16.39,135.560,-0.01991
-16.39,135.720,-0.01991
-16.41,135.880,-0.01995
-16.41,136.040,-0.01995
-16.42,136.200,-0.01995
-16.43,136.360,-0.01999
-16.43,136.520,-0.01999
-16.45,136.680,-0.02004
-16.45,136.840,-0.02004
-16.47,137.000,-0.02004
-16.49,137.160,-0.02008
-16.48,137.320,-0.02008
-16.49,137.480,-0.02012
-16.50,137.640,-0.02012
-16.51,137.800,-0.02012
-16.52,137.960,-0.02016
-16.52,138.120,-0.02016
-16.54,138.280,-0.02020
-16.55,138.440,-0.02020
-16.55,138.600,-0.02020
-16.57,138.760,-0.02024
-16.57,138.920,-0.02024
-16.57,139.080,-0.02028
-16.58,139.240,-0.02028
-16.60,139.400,-0.02028
-16.61,139.560,-0.02033
-16.61,139.720,-0.02033
-16.61,139.880,-0.02033
-16.62,140.040,-0.02037
-16.64,140.200,-0.02037
-16.64,140.360,-0.02041
-16.64,140.520,-0.02041
-16.66,140.680,-0.02041
-16.66,140.840,-0.02045
-16.68,141.000,-0.02045
-16.68,141.160,-0.02045
-16.69,141.320,-0.02049
-16.71,141.480,-0.02049
-16.71,141.640,-0.02049
-16.70,141.800,-0.02053
-16.70,141.960,-0.02053
-16.71,142.120,-0.02058
-16.72,142.280,-0.02058
-16.73,142.440,-0.02058
-16.73,142.600,-0.02062
-16.75,142.760,-0.02062
-16.75,142.920,-0.02062
-16.77,143.080,-0.02066
-16.77,143.240,-0.02066
-16.78,143.400,-0.02066
-16.79,143.560,-0.02070
-16.79,143.720,-0.02070
-16.80,143.880,-0.02070
-16.82,144.040,-0.02074
-16.83,144.200,-0.02074
-16.82,144.360,-0.02074
-16.83,144.520,-0.02078
-16.84,144.680,-0.02078
-16.86,144.840,-0.02082
-16.85,145.000,-0.02082
-16.86,145.160,-0.02082
-16.88,145.320,-0.02087
-16.87,145.480,-0.02087
-16.87,145.640,-0.02087
-16.87,145.800,-0.02091
-16.90,145.960,-0.02091
-16.90,146.120,-0.02091
-16.90,146.280,-0.02095
-16.91,146.440,-0.02095
-16.93,146.600,-0.02095
-16.92,146.760,-0.02099
-16.93,146.920,-0.02099
-16.95,147.080,-0.02099
-16.94,147.240,-0.02103
-16.96,147.400,-0.02103
-16.96,147.560,-0.02103
-16.97,147.720,-0.02107
-16.98,147.880,-0.02107
-16.99,148.040,-0.02107
-16.99,148.200,-0.02112
-16.99,148.360,-0.02112
-17.00,148.520,-0.02112
-17.01,148.680,-0.02116
-17.02,148.840,-0.02116
-17.03,149.000,-0.02116
-17.05,149.160,-0.02120
-17.05,149.320,-0.02120
-17.05,149.480,-0.02120
-17.06,149.640,-0.02124
-17.06,149.800,-0.02124
-17.08,149.960,-0.02124
-17.09,150.120,-0.02128
-17.08,150.280,-0.02128
-17.09,150.440,-0.02128
-17.10,150.600,-0.02132
-17.10,150.760,-0.02132
-17.11,150.920,-0.02132
-17.12,151.080,-0.02132
-17.12,151.240,-0.02136
-17.14,151.400,-0.02136
-17.14,151.560,-0.02136
-17.15,151.720,-0.02141
-17.14,151.880,-0.02141
-17.14,152.040,-0.02141
-17.15,152.200,-0.02145
-17.16,152.360,-0.02145
-17.17,152.520,-0.02145
-17.19,152.680,-0.02149
-17.18,152.840,-0.02149
-17.21,153.000,-0.02149
-17.21,153.160,-0.02153
-17.21,153.320,-0.02153
-17.23,153.480,-0.02153
-17.23,153.640,-0.02157
-17.23,153.800,-0.02157
-17.23,153.960,-0.02157
-17.24,154.120,-0.02161
-17.26,154.280,-0.02161
-17.27,154.440,-0.02161
-17.26,154.600,-0.02161
-17.28,154.760,-0.02166
-17.28,154.920,-0.02166
-17.26,155.080,-0.02166
-17.29,155.240,-0.02170
-17.28,155.400,-0.02170
-17.31,155.560,-0.02170
-17.29,155.720,-0.02174
-17.29,155.880,-0.02174
-17.32,156.040,-0.02174
-17.32,156.200,-0.02174
-17.33,156.360,-0.02178
-17.34,156.520,-0.02178
-17.34,156.680,-0.02178
-17.35,156.840,-0.02182
-17.36,157.000,-0.02182
-17.36,157.160,-0.02182
-17.38,157.320,-0.02186
-17.37,157.480,-0.02186
-17.38,157.640,-0.02186
-17.40,157.800,-0.02191
-17.40,157.960,-0.02191
-17.41,158.120,-0.02191
-17.41,158.280,-0.02195
-17.41,158.440,-0.02195
-17.43,158.600,-0.02195
-17.42,158.760,-0.02195
-17.44,158.920,-0.02199
-17.44,159.080,-0.02199
-17.43,159.240,-0.02199
-17.45,159.400,-0.02203
-17.46,159.560,-0.02203
-17.46,159.720,-0.02203
-17.48,159.880,-0.02207
-17.49,160.040,-0.02207
-17.49,160.200,-0.02207
-17.50,160.360,-0.02207
-17.49,160.520,-0.02211
-17.51,160.680,-0.02211
-17.51,160.840,-0.02211
-17.52,161.000,-0.02215
-17.53,161.160,-0.02215
-17.54,161.320,-0.02215
-17.55,161.480,-0.02220
-17.55,161.640,-0.02220
-17.56,161.800,-0.02220
-17.57,161.960,-0.02224
-17.59,162.120,-0.02224
-17.57,162.280,-0.02224
-17.59,162.440,-0.02224
-17.59,162.600,-0.02228
-17.61,162.760,-0.02228
-17.60,162.920,-0.02228
-17.61,163.080,-0.02232
-17.62,163.240,-0.02232
-17.62,163.400,-0.02232
-17.62,163.560,-0.02236
-17.65,163.720,-0.02236
-17.65,163.880,-0.02236
-17.66,164.040,-0.02240
-17.66,164.200,-0.02240
-17.67,164.360,-0.02240
-17.66,164.520,-0.02240
-17.67,164.680,-0.02245
-17.69,164.840,-0.02245
-17.68,165.000,-0.02245
-17.70,165.160,-0.02249
-17.71,165.320,-0.02249
-17.72,165.480,-0.02249
-17.72,165.640,-0.02253
-17.73,165.800,-0.02253
-17.75,165.960,-0.02253
-17.74,166.120,-0.02253
-17.74,166.280,-0.02257
-17.74,166.440,-0.02257
-17.77,166.600,-0.02257
-17.77,166.760,-0.02261
-17.77,166.920,-0.02261
-17.77,167.080,-0.02261
-17.78,167.240,-0.02265
-17.78,167.400,-0.02265
-17.80,167.560,-0.02265
-17.82,167.720,-0.02269
-17.80,167.880,-0.02269
-17.81,168.040,-0.02269
-17.82,168.200,-0.02274
-17.82,168.360,-0.02274
-17.82,168.520,-0.02274
-17.83,168.680,-0.02278
-17.84,168.840,-0.02278
-17.84,169.000,-0.02278
-17.87,169.160,-0.02282
-17.86,169.320,-0.02282
-17.86,169.480,-0.02282
-17.89,169.640,-0.02286
-17.88,169.800,-0.02286
-17.87,169.960,-0.02286
-17.89,170.120,-0.02286
-17.90,170.280,-0.02290
-17.90,170.440,-0.02290
-17.92,170.600,-0.02290
-17.92,170.760,-0.02294
-17.92,170.920,-0.02294
-17.92,171.080,-0.02294
-17.94,171.240,-0.02299
-17.93,171.400,-0.02299
-17.95,171.560,-0.02299
-17.95,171.720,-0.02303
-17.96,171.880,-0.02303
-17.97,172.040,-0.02303
-17.97,172.200,-0.02307
-17.98,172.360,-0.02307
-17.99,172.520,-0.02307
-18.00,172.680,-0.02311
-18.00,172.840,-0.02311
-18.01,173.000,-0.02311
-18.02,173.160,-0.02315
-18.01,173.320,-0.02315
-18.04,173.480,-0.02315
-18.05,173.640,-0.02319
-18.05,173.800,-0.02319
-18.05,173.960,-0.02319
-18.05,174.120,-0.02323
-18.06,174.280,-0.02323
-18.08,174.440,-0.02323
-18.08,174.600,-0.02328
-18.09,174.760,-0.02328
-18.09,174.920,-0.02328
-18.09,175.080,-0.02332
-18.10,175.240,-0.02332
-18.12,175.400,-0.02332
-18.13,175.560,-0.02336
-18.14,175.720,-0.02336
-18.15,175.880,-0.02336
-18.15,176.040,-0.02340
-18.16,176.200,-0.02340
-18.17,176.360,-0.02340
-18.18,176.520,-0.02344
-18.18,176.680,-0.02344
-18.20,176.840,-0.02344
-18.20,177.000,-0.02348
-18.20,177.160,-0.02348
-18.21,177.320,-0.02353
-18.23,177.480,-0.02353
-18.24,177.640,-0.02353
-18.24,177.800,-0.02357
-18.25,177.960,-0.02357
-18.25,178.120,-0.02357
-18.26,178.280,-0.02361
-18.27,178.440,-0.02361
-18.28,178.600,-0.02361
-18.27,178.760,-0.02365
-18.29,178.920,-0.02365
-18.28,179.080,-0.02365
-18.30,179.240,-0.02369
-18.31,179.400,-0.02369
-18.32,179.560,-0.02369
-18.32,179.720,-0.02373
-18.32,179.880,-0.02373
-18.33,180.040,-0.02373
-18.34,180.200,-0.02378
-18.35,180.360,-0.02378
-18.35,180.520,-0.02378
-18.36,180.680,-0.02382
-18.37,180.840,-0.02382
-18.38,181.000,-0.02382
-18.41,181.160,-0.02386
-18.40,181.320,-0.02386
-18.40,181.480,-0.02386
-18.41,181.640,-0.02390
-18.42,181.800,-0.02390
-18.44,181.960,-0.02390
-18.43,182.120,-0.02394
-18.43,182.280,-0.02394
-18.44,182.440,-0.02394
-18.45,182.600,-0.02398
-18.46,182.760,-0.02398
-18.46,182.920,-0.02398
-18.47,183.080,-0.02402
-18.47,183.240,-0.02402
-18.49,183.400,-0.02407
-18.50,183.560,-0.02407
-18.50,183.720,-0.02407
-18.52,183.880,-0.02411
-18.53,184.040,-0.02411
-18.53,184.200,-0.02411
-18.52,184.360,-0.02415
-18.54,184.520,-0.02415
-18.55,184.680,-0.02415
-18.57,184.840,-0.02419
-18.58,185.000,-0.02419
-18.59,185.160,-0.02419
-18.59,185.320,-0.02423
-18.60,185.480,-0.02423
-18.60,185.640,-0.02423
-18.60,185.800,-0.02427
-18.61,185.960,-0.02427
-18.63,186.120,-0.02427
-18.63,186.280,-0.02432
-18.65,186.440,-0.02432
-18.64,186.600,-0.02436
-18.65,186.760,-0.02436
-18.66,186.920,-0.02436
-18.67,187.080,-0.02440
-18.69,187.240,-0.02440
-18.68,187.400,-0.02440
-18.67,187.560,-0.02444
-18.69,187.720,-0.02444
-18.70,187.880,-0.02444
-18.71,188.040,-0.02448
-18.73,188.200,-0.02448
-18.71,188.360,-0.02448
-18.74,188.520,-0.02452
-18.74,188.680,-0.02452
-18.75,188.840,-0.02452
-18.77,189.000,-0.02456
-18.76,189.160,-0.02456
-18.78,189.320,-0.02461
-18.79,189.480,-0.02461
-18.78,189.640,-0.02461
-18.80,189.800,-0.02465
-18.79,189.960,-0.02465
-18.82,190.120,-0.02465
-18.82,190.280,-0.02469
-18.82,190.440,-0.02469
-18.84,190.600,-0.02469
-18.85,190.760,-0.02473
-18.85,190.920,-0.02473
-18.86,191.080,-0.02473
-18.87,191.240,-0.02477
-18.87,191.400,-0.02477
-18.88,191.560,-0.02477
-18.91,191.720,-0.02481
-18.90,191.880,-0.02481
-18.92,192.040,-0.02486
-18.91,192.200,-0.02486
-18.91,192.360,-0.02486
-18.93,192.520,-0.02490
-18.94,192.680,-0.02490
-18.94,192.840,-0.02490
-18.95,193.000,-0.02494
-18.95,193.160,-0.02494
-18.97,193.320,-0.02494
-18.98,193.480,-0.02498
-18.98,193.640,-0.02498
-19.00,193.800,-0.02502
-19.00,193.960,-0.02502
-19.00,194.120,-0.02502
-19.01,194.280,-0.02506
-19.03,194.440,-0.02506
-19.04,194.600,-0.02506
-19.04,194.760,-0.02510
-19.02,194.920,-0.02510
-19.04,195.080,-0.02515
-19.06,195.240,-0.02515
-19.06,195.400,-0.02515
-19.07,195.560,-0.02519
-19.07,195.720,-0.02519
-19.08,195.880,-0.02519
-19.09,196.040,-0.02523
-19.08,196.200,-0.02523
-19.10,196.360,-0.02527
-19.09,196.520,-0.02527
-19.10,196.680,-0.02527
-19.12,196.840,-0.02531
-19.12,197.000,-0.02531
-19.12,197.160,-0.02531
-19.14,197.320,-0.02535
-19.13,197.480,-0.02535
-19.16,197.640,-0.02540
-19.15,197.800,-0.02540
-19.16,197.960,-0.02540
-19.17,198.120,-0.02544
-19.18,198.280,-0.02544
-19.18,198.440,-0.02544
-19.19,198.600,-0.02548
-19.21,198.760,-0.02548
-19.21,198.920,-0.02552
-19.22,199.080,-0.02552
-19.22,199.240,-0.02552
-19.23,199.400,-0.02556
-19.24,199.560,-0.02556
-19.23,199.720,-0.02556
-19.05,199.880,-0.02560
-18.93,200.040,-0.02560
-18.86,200.200,-0.02565
-18.78,200.360,-0.02565
-18.70,200.520,-0.02565
-11.59,200.680,-0.02569
-5.92,200.840,-0.02569
-6.02,201.000,-0.02569
-6.05,201.160,-0.02573
-6.07,201.320,-0.02573
-6.08,201.480,-0.02577
-6.09,201.640,-0.02577
-6.11,201.800,-0.02577
-6.11,201.960,-0.02581
-6.14,202.120,-0.02581
-6.15,202.280,-0.02585
-6.16,202.440,-0.02585
-6.17,202.600,-0.02585
-6.17,202.760,-0.02589
-6.20,202.920,-0.02589
-6.20,203.080,-0.02594
-6.20,203.240,-0.02594
-6.22,203.400,-0.02594
-6.23,203.560,-0.02598
-6.26,203.720,-0.02598
-6.26,203.880,-0.02602
-6.26,204.040,-0.02602
-6.27,204.200,-0.02606
-6.28,204.360,-0.02606
-6.30,204.520,-0.02606
-6.30,204.680,-0.02610
-6.30,204.840,-0.02610
-6.32,205.000,-0.02614
-6.34,205.160,-0.02614
-6.33,205.320,-0.02614
-6.35,205.480,-0.02619
-6.36,205.640,-0.02619
-6.37,205.800,-0.02623
-6.37,205.960,-0.02623
-6.38,206.120,-0.02627
-6.39,206.280,-0.02627
-6.40,206.440,-0.02627
-6.40,206.600,-0.02631
-6.42,206.760,-0.02631
-6.43,206.920,-0.02635
-6.43,207.080,-0.02635
-6.45,207.240,-0.02639
-6.44,207.400,-0.02639
-6.46,207.560,-0.02639
-6.46,207.720,-0.02643
-6.45,207.880,-0.02643
-6.47,208.040,-0.02648
-6.48,208.200,-0.02648
-6.49,208.360,-0.02652
-6.49,208.520,-0.02652
-6.51,208.680,-0.02656
-6.51,208.840,-0.02656
-6.52,209.000,-0.02656
-6.51,209.160,-0.02660
-6.52,209.320,-0.02660
-6.53,209.480,-0.02664
-6.54,209.640,-0.02664
-6.55,209.800,-0.02668
-6.55,209.960,-0.02668
-6.55,210.120,-0.02668
-6.57,210.280,-0.02673
-6.57,210.440,-0.02673
-6.57,210.600,-0.02677
-6.58,210.760,-0.02677
-6.59,210.920,-0.02681
-6.61,211.080,-0.02681
-6.60,211.240,-0.02685
-6.61,211.400,-0.02685
-6.61,211.560,-0.02689
-6.62,211.720,-0.02689
-6.63,211.880,-0.02689
-6.63,212.040,-0.02693
-6.64,212.200,-0.02693
-6.64,212.360,-0.02697
-6.65,212.520,-0.02697
-6.67,212.680,-0.02702
-6.66,212.840,-0.02702
-6.68,213.000,-0.02706
-6.68,213.160,-0.02706
-6.69,213.320,-0.02710
-6.70,213.480,-0.02710
-6.70,213.640,-0.02714
-6.70,213.800,-0.02714
-6.72,213.960,-0.02718
-6.70,214.120,-0.02718
-6.69,214.280,-0.02722
-6.69,214.440,-0.02722
-6.70,214.600,-0.02727
-6.69,214.760,-0.02727
-6.68,214.920,-0.02731
-6.69,215.080,-0.02731
-6.70,215.240,-0.02731
-6.70,215.400,-0.02735
-6.71,215.560,-0.02735
-6.70,215.720,-0.02739
-6.70,215.880,-0.02739
-6.70,216.040,-0.02743
-6.70,216.200,-0.02743
-6.70,216.360,-0.02747
-6.71,216.520,-0.02747
-6.71,216.680,-0.02752
-6.71,216.840,-0.02752
-6.71,217.000,-0.02756
-6.73,217.160,-0.02756
-6.73,217.320,-0.02760
-6.73,217.480,-0.02760
-6.75,217.640,-0.02764
-6.74,217.800,-0.02764
-6.76,217.960,-0.02768
-6.74,218.120,-0.02768
-6.74,218.280,-0.02772
-6.76,218.440,-0.02772
-6.77,218.600,-0.02776
-6.76,218.760,-0.02776
-6.77,218.920,-0.02781
-6.78,219.080,-0.02781
-6.78,219.240,-0.02785
-6.78,219.400,-0.02785
-6.79,219.560,-0.02789
-6.78,219.720,-0.02789
-6.79,219.880,-0.02793
-6.79,220.040,-0.02793
-6.81,220.200,-0.02797
-6.81,220.360,-0.02797
-6.81,220.520,-0.02801
-6.81,220.680,-0.02801
-6.83,220.840,-0.02806
-6.82,221.000,-0.02806
-6.84,221.160,-0.02810
-6.84,221.320,-0.02810
-6.84,221.480,-0.02814
-6.83,221.640,-0.02814
-6.85,221.800,-0.02818
-6.85,221.960,-0.02818
-6.86,222.120,-0.02822
-6.85,222.280,-0.02822
-6.86,222.440,-0.02826
-6.87,222.600,-0.02826
-6.87,222.760,-0.02830
-6.86,222.920,-0.02830
-6.88,223.080,-0.02835
-6.87,223.240,-0.02835
-6.89,223.400,-0.02839
-6.88,223.560,-0.02839
-6.88,223.720,-0.02839
-6.90,223.880,-0.02843
-6.91,224.040,-0.02843
-6.91,224.200,-0.02847
-6.92,224.360,-0.02847
-6.91,224.520,-0.02851
-6.93,224.680,-0.02851
-6.92,224.840,-0.02855
-6.93,225.000,-0.02855
-6.94,225.040,-0.02855