File: data-files/CWRU/0900-05-20D.txt
""
"Test Method","Will_Huddleston_Disks.msm"
"Sample I. D.","900-5-20D.mss"
"Specimen Number","2"

"Load (N)","Time (s)","Extension (mm)","Stress (MPa)","Strain (mm/mm)"

1.94,0.200,-0.01047,0.171,0.000
1.94,0.400,-0.01047,0.170,0.000
1.96,0.600,-0.01043,0.172,0.000
1.96,0.800,-0.01043,0.173,0.000
1.95,1.000,-0.01043,0.171,0.000
1.94,1.200,-0.01043,0.171,0.000
1.95,1.400,-0.01039,0.172,0.000
1.95,1.600,-0.01039,0.172,0.000
1.96,1.800,-0.01039,0.172,0.000
1.95,2.000,-0.01034,0.171,0.000
1.95,2.200,-0.01034,0.172,0.000
1.96,2.400,-0.01034,0.173,0.000
1.95,2.600,-0.01030,0.172,0.000
1.96,2.800,-0.01030,0.173,0.000
1.98,3.000,-0.01026,0.174,0.000
1.97,3.200,-0.01026,0.174,0.000
1.99,3.400,-0.01026,0.175,0.000
2.00,3.600,-0.01022,0.176,0.000
2.01,3.800,-0.01018,0.177,0.000
2.01,4.000,-0.01018,0.177,0.000
2.02,4.200,-0.01010,0.178,0.000
2.04,4.400,-0.01005,0.180,0.000
2.11,4.600,-0.00997,0.186,0.000
2.13,4.800,-0.00993,0.188,0.000
2.17,5.000,-0.00985,0.191,0.000
2.22,5.200,-0.00972,0.195,0.000
2.33,5.400,-0.00960,0.205,0.000
2.43,5.600,-0.00943,0.214,0.000
2.56,5.800,-0.00926,0.225,0.000
2.69,6.000,-0.00906,0.237,0.000
2.82,6.200,-0.00889,0.248,0.000
2.96,6.400,-0.00872,0.260,0.000
3.10,6.600,-0.00856,0.273,0.000
3.22,6.800,-0.00835,0.283,0.000
3.38,7.000,-0.00814,0.297,0.000
3.55,7.200,-0.00798,0.312,0.000
3.70,7.400,-0.00777,0.326,0.000
3.85,7.600,-0.00756,0.339,0.000
4.00,7.800,-0.00735,0.353,0.000
4.17,8.000,-0.00714,0.367,0.000
4.32,8.200,-0.00698,0.381,0.000
4.47,8.400,-0.00677,0.394,0.000
4.65,8.600,-0.00656,0.409,0.000
4.81,8.800,-0.00640,0.423,0.000
4.98,9.000,-0.00619,0.438,0.000
5.13,9.200,-0.00602,0.452,0.000
5.29,9.400,-0.00586,0.466,0.000
5.43,9.600,-0.00569,0.478,0.000
5.60,9.800,-0.00552,0.493,0.000
5.73,10.000,-0.00536,0.504,0.000
5.87,10.200,-0.00519,0.517,0.000
5.98,10.400,-0.00503,0.527,0.000
6.09,10.600,-0.00490,0.536,0.000
6.21,10.800,-0.00473,0.547,0.000
6.32,11.000,-0.00461,0.556,0.000
6.43,11.200,-0.00448,0.566,0.000
6.52,11.400,-0.00432,0.574,0.000
6.64,11.600,-0.00419,0.584,0.000
6.72,11.800,-0.00407,0.592,0.000
6.82,12.000,-0.00394,0.601,0.000
6.94,12.200,-0.00378,0.611,0.000
7.03,12.400,-0.00365,0.619,0.000
7.12,12.600,-0.00353,0.627,0.000
7.24,12.800,-0.00340,0.638,0.000
7.34,13.000,-0.00328,0.646,0.000
7.45,13.200,-0.00311,0.656,0.000
7.55,13.400,-0.00299,0.665,0.000
7.67,13.600,-0.00286,0.675,0.000
7.79,13.800,-0.00270,0.686,0.000
7.90,14.000,-0.00257,0.696,0.000
8.02,14.200,-0.00241,0.706,0.000
8.12,14.400,-0.00228,0.715,0.000
8.25,14.600,-0.00212,0.727,0.000
8.36,14.800,-0.00199,0.736,0.000
8.47,15.000,-0.00183,0.746,0.000
8.60,15.200,-0.00166,0.757,0.000
8.72,15.400,-0.00153,0.767,0.000
8.83,15.600,-0.00137,0.777,0.000
8.94,15.800,-0.00120,0.787,0.000
9.08,16.000,-0.00108,0.799,0.000
9.20,16.200,-0.00091,0.810,0.000
9.32,16.400,-0.00074,0.820,0.000
9.44,16.600,-0.00058,0.831,0.000
9.58,16.800,-0.00045,0.843,0.000
9.69,17.000,-0.00029,0.853,0.000
9.82,17.200,-0.00012,0.865,0.000
9.96,17.400,0.00004,0.877,0.000
10.11,17.600,0.00021,0.890,0.000
10.24,17.800,0.00038,0.902,0.000
10.41,18.000,0.00058,0.916,0.000
10.55,18.200,0.00075,0.929,0.000
10.72,18.400,0.00096,0.944,0.000
10.88,18.600,0.00117,0.958,0.000
11.07,18.800,0.00137,0.975,0.000
11.26,19.000,0.00158,0.991,0.000
11.43,19.200,0.00179,1.007,0.000
11.62,19.400,0.00200,1.023,0.000
11.81,19.600,0.00225,1.040,0.000
11.98,19.800,0.00245,1.055,0.000
12.15,20.000,0.00266,1.070,0.000
12.34,20.200,0.00283,1.086,0.000
12.51,20.400,0.00304,1.101,0.000
12.66,20.600,0.00324,1.115,0.000
12.82,20.800,0.00341,1.128,0.000
12.97,21.000,0.00358,1.142,0.000
13.13,21.200,0.00374,1.156,0.000
13.28,21.400,0.00395,1.169,0.000
13.43,21.600,0.00408,1.183,0.000
13.57,21.800,0.00424,1.195,0.000
13.71,22.000,0.00441,1.207,0.000
13.84,22.200,0.00453,1.219,0.000
13.99,22.400,0.00470,1.232,0.000
14.10,22.600,0.00482,1.242,0.000
14.23,22.800,0.00499,1.253,0.000
14.35,23.000,0.00511,1.264,0.000
14.48,23.200,0.00524,1.275,0.000
14.60,23.400,0.00541,1.286,0.000
14.73,23.600,0.00553,1.297,0.000
14.83,23.800,0.00565,1.306,0.000
14.95,24.000,0.00578,1.316,0.000
15.07,24.200,0.00595,1.326,0.000
15.19,24.400,0.00607,1.338,0.000
15.31,24.600,0.00619,1.348,0.000
15.43,24.800,0.00632,1.358,0.000
15.55,25.000,0.00649,1.369,0.000
15.67,25.200,0.00661,1.380,0.000
15.81,25.400,0.00674,1.392,0.000
15.93,25.600,0.00690,1.403,0.000
16.07,25.800,0.00703,1.414,0.000
16.18,26.000,0.00719,1.424,0.000
16.33,26.200,0.00732,1.438,0.000
16.46,26.400,0.00748,1.449,0.000
16.59,26.600,0.00765,1.460,0.000
16.70,26.800,0.00777,1.471,0.000
16.85,27.000,0.00794,1.483,0.000
16.99,27.200,0.00811,1.496,0.000
17.14,27.400,0.00823,1.509,0.000
17.27,27.600,0.00840,1.521,0.000
17.41,27.800,0.00856,1.533,0.000
17.54,28.000,0.00869,1.544,0.000
17.70,28.200,0.00885,1.559,0.000
17.84,28.400,0.00902,1.570,0.000
18.00,28.600,0.00919,1.584,0.000
18.15,28.800,0.00935,1.598,0.000
18.30,29.000,0.00952,1.612,0.000
18.47,29.200,0.00969,1.626,0.000
18.64,29.400,0.00989,1.641,0.000
18.83,29.600,0.01006,1.658,0.000
19.02,29.800,0.01027,1.675,0.000
19.21,30.000,0.01048,1.691,0.000
19.42,30.200,0.01068,1.710,0.000
19.62,30.400,0.01093,1.727,0.000
19.82,30.600,0.01114,1.745,0.000
20.02,30.800,0.01135,1.763,0.000
20.25,31.000,0.01156,1.783,0.000
20.47,31.200,0.01180,1.803,0.000
20.66,31.400,0.01201,1.819,0.000
20.85,31.600,0.01222,1.836,0.000
21.04,31.800,0.01239,1.852,0.000
21.23,32.000,0.01259,1.869,0.000
21.41,32.200,0.01280,1.885,0.000
21.57,32.400,0.01297,1.899,0.000
21.73,32.600,0.01313,1.913,0.000
21.88,32.800,0.01330,1.927,0.000
22.04,33.000,0.01347,1.941,0.000
22.19,33.200,0.01363,1.954,0.000
22.31,33.400,0.01376,1.965,0.000
22.45,33.600,0.01392,1.977,0.000
22.58,33.800,0.01405,1.988,0.000
22.71,34.000,0.01422,2.000,0.000
22.83,34.200,0.01434,2.010,0.000
22.97,34.400,0.01451,2.022,0.000
23.11,34.600,0.01463,2.035,0.000
23.23,34.800,0.01476,2.045,0.000
23.34,35.000,0.01492,2.055,0.000
23.46,35.200,0.01505,2.066,0.000
23.58,35.400,0.01517,2.076,0.000
23.73,35.600,0.01530,2.090,0.000
23.84,35.800,0.01546,2.099,0.000
23.97,36.000,0.01559,2.110,0.000
24.11,36.200,0.01571,2.123,0.000
24.25,36.400,0.01588,2.135,0.000
24.39,36.600,0.01600,2.148,0.000
24.52,36.800,0.01617,2.158,0.000
24.64,37.000,0.01629,2.170,0.000
24.79,37.200,0.01646,2.183,0.000
24.92,37.400,0.01663,2.195,0.000
25.07,37.600,0.01675,2.207,0.000
25.21,37.800,0.01692,2.220,0.000
25.34,38.000,0.01708,2.231,0.000
25.50,38.200,0.01721,2.245,0.000
25.66,38.400,0.01737,2.259,0.000
25.81,38.600,0.01754,2.272,0.000
25.97,38.800,0.01771,2.286,0.000
26.11,39.000,0.01787,2.299,0.000
26.27,39.200,0.01800,2.313,0.000
26.43,39.400,0.01816,2.327,0.000
26.60,39.600,0.01833,2.342,0.000
26.76,39.800,0.01850,2.356,0.000
26.90,40.000,0.01866,2.368,0.000
27.10,40.200,0.01887,2.386,0.000
27.26,40.400,0.01904,2.400,0.000
27.45,40.600,0.01920,2.417,0.000
27.65,40.800,0.01941,2.435,0.000
27.85,41.000,0.01962,2.452,0.000
28.05,41.200,0.01983,2.470,0.000
28.27,41.400,0.02003,2.489,0.000
28.48,41.600,0.02024,2.507,0.000
28.69,41.800,0.02045,2.526,0.000
28.91,42.000,0.02066,2.546,0.000
29.13,42.200,0.02091,2.565,0.000
29.33,42.400,0.02111,2.583,0.000
29.54,42.600,0.02132,2.601,0.000
29.76,42.800,0.02153,2.620,0.000
29.96,43.000,0.02174,2.637,0.000
30.16,43.200,0.02194,2.656,0.000
30.34,43.400,0.02215,2.671,0.000
30.54,43.600,0.02232,2.689,0.000
30.71,43.800,0.02253,2.704,0.000
30.91,44.000,0.02269,2.721,0.000
31.06,44.200,0.02286,2.735,0.000
31.21,44.400,0.02302,2.748,0.000
31.37,44.600,0.02319,2.762,0.000
31.53,44.800,0.02336,2.776,0.000
31.68,45.000,0.02348,2.789,0.000
31.84,45.200,0.02365,2.804,0.000
31.99,45.400,0.02381,2.816,0.000
32.13,45.600,0.02394,2.829,0.000
32.28,45.800,0.02411,2.842,0.000
32.41,46.000,0.02423,2.854,0.000
32.55,46.200,0.02435,2.866,0.000
32.70,46.400,0.02452,2.879,0.000
32.84,46.600,0.02465,2.891,0.000
32.97,46.800,0.02477,2.903,0.000
33.11,47.000,0.02494,2.915,0.000
33.25,47.200,0.02506,2.928,0.000
33.41,47.400,0.02519,2.941,0.000
33.56,47.600,0.02535,2.955,0.000
33.69,47.800,0.02548,2.966,0.001
33.85,48.000,0.02564,2.980,0.001
34.01,48.200,0.02577,2.995,0.001
34.18,48.400,0.02593,3.009,0.001
34.34,48.600,0.02610,3.023,0.001
34.52,48.800,0.02622,3.040,0.001
34.69,49.000,0.02639,3.054,0.001
34.85,49.200,0.02656,3.068,0.001
35.02,49.400,0.02672,3.083,0.001
35.20,49.600,0.02685,3.099,0.001
35.36,49.800,0.02701,3.113,0.001
35.55,50.000,0.02718,3.130,0.001
35.71,50.200,0.02735,3.144,0.001
35.88,50.400,0.02751,3.159,0.001
36.06,50.600,0.02768,3.175,0.001
36.25,50.800,0.02785,3.191,0.001
36.43,51.000,0.02801,3.208,0.001
36.62,51.200,0.02818,3.224,0.001
36.82,51.400,0.02834,3.242,0.001
37.01,51.600,0.02851,3.258,0.001
37.21,51.800,0.02872,3.277,0.001
37.42,52.000,0.02888,3.294,0.001
37.65,52.200,0.02909,3.315,0.001
37.86,52.400,0.02930,3.334,0.001
38.10,52.600,0.02951,3.354,0.001
38.32,52.800,0.02972,3.374,0.001
38.58,53.000,0.02992,3.397,0.001
38.83,53.200,0.03017,3.419,0.001
39.05,53.400,0.03038,3.438,0.001
39.31,53.600,0.03059,3.461,0.001
39.55,53.800,0.03080,3.482,0.001
39.76,54.000,0.03100,3.501,0.001
39.98,54.200,0.03121,3.520,0.001
40.20,54.400,0.03138,3.539,0.001
40.41,54.600,0.03159,3.558,0.001
40.62,54.800,0.03179,3.577,0.001
40.82,55.000,0.03196,3.594,0.001
41.02,55.200,0.03213,3.612,0.001
41.19,55.400,0.03229,3.627,0.001
41.37,55.600,0.03246,3.643,0.001
41.55,55.800,0.03262,3.659,0.001
41.73,56.000,0.03279,3.674,0.001
41.89,56.200,0.03292,3.689,0.001
42.07,56.400,0.03308,3.704,0.001
42.25,56.600,0.03325,3.720,0.001
42.41,56.800,0.03337,3.734,0.001
42.58,57.000,0.03354,3.749,0.001
42.73,57.200,0.03366,3.762,0.001
42.89,57.400,0.03379,3.776,0.001
43.05,57.600,0.03391,3.791,0.001
43.21,57.800,0.03408,3.805,0.001
43.38,58.000,0.03420,3.819,0.001
43.53,58.200,0.03433,3.833,0.001
43.72,58.400,0.03449,3.849,0.001
43.88,58.600,0.03462,3.863,0.001
44.06,58.800,0.03479,3.879,0.001
44.22,59.000,0.03491,3.893,0.001
44.37,59.200,0.03503,3.906,0.001
44.56,59.400,0.03520,3.923,0.001
44.71,59.600,0.03533,3.937,0.001
44.91,59.800,0.03549,3.954,0.001
45.09,60.000,0.03566,3.970,0.001
45.27,60.200,0.03578,3.986,0.001
45.47,60.400,0.03595,4.003,0.001
45.67,60.600,0.03612,4.021,0.001
45.85,60.800,0.03628,4.037,0.001
46.05,61.000,0.03641,4.054,0.001
46.23,61.200,0.03657,4.070,0.001
46.43,61.400,0.03674,4.088,0.001
46.62,61.600,0.03690,4.105,0.001
46.80,61.800,0.03707,4.120,0.001
46.99,62.000,0.03724,4.137,0.001
47.17,62.200,0.03740,4.153,0.001
47.39,62.400,0.03757,4.172,0.001
47.61,62.600,0.03774,4.192,0.001
47.83,62.800,0.03790,4.211,0.001
48.05,63.000,0.03811,4.230,0.001
48.30,63.200,0.03828,4.252,0.001
48.55,63.400,0.03848,4.275,0.001
48.79,63.600,0.03869,4.296,0.001
49.05,63.800,0.03890,4.318,0.001
49.32,64.000,0.03911,4.342,0.001
49.59,64.200,0.03936,4.366,0.001
49.89,64.400,0.03956,4.392,0.001
50.12,64.600,0.03977,4.413,0.001
50.40,64.800,0.04002,4.437,0.001
50.68,65.000,0.04023,4.462,0.001
50.94,65.200,0.04044,4.485,0.001
51.23,65.400,0.04064,4.511,0.001
51.51,65.600,0.04085,4.535,0.001
51.75,65.800,0.04106,4.556,0.001
52.00,66.000,0.04127,4.578,0.001
52.24,66.200,0.04143,4.599,0.001
52.45,66.400,0.04164,4.618,0.001
52.65,66.600,0.04181,4.636,0.001
52.86,66.800,0.04193,4.654,0.001
53.05,67.000,0.04210,4.671,0.001
53.26,67.200,0.04227,4.689,0.001
53.43,67.400,0.04239,4.704,0.001
53.62,67.600,0.04256,4.721,0.001
53.78,67.800,0.04268,4.735,0.001
53.98,68.000,0.04285,4.753,0.001
54.17,68.200,0.04297,4.769,0.001
54.34,68.400,0.04310,4.784,0.001
54.50,68.600,0.04326,4.798,0.001
54.69,68.800,0.04339,4.815,0.001
54.86,69.000,0.04351,4.830,0.001
55.03,69.200,0.04364,4.845,0.001
55.20,69.400,0.04380,4.860,0.001
55.38,69.600,0.04393,4.876,0.001
55.59,69.800,0.04405,4.894,0.001
55.76,70.000,0.04422,4.909,0.001
55.97,70.200,0.04434,4.928,0.001
56.17,70.400,0.04451,4.945,0.001
56.37,70.600,0.04468,4.963,0.001
56.58,70.800,0.04480,4.981,0.001
56.76,71.000,0.04497,4.997,0.001
56.98,71.200,0.04513,5.017,0.001
57.18,71.400,0.04526,5.035,0.001
57.38,71.600,0.04542,5.052,0.001
57.61,71.800,0.04559,5.072,0.001
57.81,72.000,0.04576,5.090,0.001
58.02,72.200,0.04592,5.109,0.001
58.23,72.400,0.04609,5.127,0.001
58.46,72.600,0.04625,5.147,0.001
58.66,72.800,0.04642,5.165,0.001
58.88,73.000,0.04655,5.184,0.001
59.10,73.200,0.04671,5.204,0.001
59.31,73.400,0.04688,5.222,0.001
59.54,73.600,0.04704,5.242,0.001
59.77,73.800,0.04725,5.263,0.001
60.02,74.000,0.04742,5.284,0.001
60.29,74.200,0.04758,5.308,0.001
60.54,74.400,0.04779,5.331,0.001
60.81,74.600,0.04800,5.354,0.001
61.10,74.800,0.04817,5.379,0.001
61.39,75.000,0.04837,5.405,0.001
61.67,75.200,0.04862,5.430,0.001
61.98,75.400,0.04883,5.457,0.001
62.29,75.600,0.04904,5.485,0.001
62.60,75.800,0.04929,5.511,0.001
62.89,76.000,0.04950,5.537,0.001
63.16,76.200,0.04970,5.561,0.001
14.66,76.400,0.04995,1.290,0.001
20.10,76.600,0.05016,1.770,0.001
20.57,76.800,0.05037,1.811,0.001
21.02,77.000,0.05058,1.851,0.001
21.40,77.200,0.05074,1.884,0.001
21.77,77.400,0.05095,1.917,0.001
22.13,77.600,0.05112,1.948,0.001
22.47,77.800,0.05128,1.978,0.001
22.74,78.000,0.05145,2.002,0.001
23.02,78.200,0.05162,2.027,0.001
23.29,78.400,0.05174,2.051,0.001
23.56,78.600,0.05191,2.074,0.001
23.81,78.800,0.05207,2.096,0.001
24.08,79.000,0.05220,2.120,0.001
24.32,79.200,0.05236,2.141,0.001
24.57,79.400,0.05249,2.163,0.001
24.79,79.600,0.05265,2.183,0.001
25.01,79.800,0.05278,2.202,0.001
25.21,80.000,0.05290,2.219,0.001
25.42,80.200,0.05307,2.238,0.001
25.63,80.400,0.05319,2.257,0.001
25.82,80.600,0.05332,2.273,0.001
26.01,80.800,0.05349,2.290,0.001
26.21,81.000,0.05361,2.308,0.001
26.40,81.200,0.05378,2.324,0.001
26.59,81.400,0.05390,2.341,0.001
26.78,81.600,0.05407,2.358,0.001
26.97,81.800,0.05419,2.375,0.001
27.14,82.000,0.05436,2.389,0.001
27.31,82.200,0.05448,2.404,0.001
27.48,82.400,0.05465,2.419,0.001
27.65,82.600,0.05482,2.434,0.001
27.80,82.800,0.05494,2.448,0.001
27.97,83.000,0.05511,2.463,0.001
28.12,83.200,0.05527,2.476,0.001
28.28,83.400,0.05544,2.490,0.001
28.44,83.600,0.05560,2.504,0.001
28.59,83.800,0.05573,2.517,0.001
28.73,84.000,0.05590,2.530,0.001
28.89,84.200,0.05606,2.543,0.001
29.06,84.400,0.05623,2.559,0.001
29.21,84.600,0.05639,2.572,0.001
29.37,84.800,0.05656,2.586,0.001
29.54,85.000,0.05673,2.601,0.001
29.71,85.200,0.05693,2.616,0.001
29.88,85.400,0.05710,2.631,0.001
30.05,85.600,0.05731,2.646,0.001
30.24,85.800,0.05752,2.662,0.001
30.42,86.000,0.05768,2.678,0.001
30.62,86.200,0.05789,2.696,0.001
30.81,86.400,0.05814,2.712,0.001
30.99,86.600,0.05835,2.729,0.001
31.19,86.800,0.05856,2.746,0.001
31.38,87.000,0.05876,2.763,0.001
31.56,87.200,0.05897,2.779,0.001
31.73,87.400,0.05922,2.794,0.001
31.91,87.600,0.05939,2.809,0.001
32.08,87.800,0.05959,2.824,0.001
32.25,88.000,0.05980,2.839,0.001
32.43,88.200,0.06001,2.855,0.001
32.59,88.400,0.06022,2.870,0.001
32.74,88.600,0.06038,2.882,0.001
32.88,88.800,0.06055,2.894,0.001
33.00,89.000,0.06072,2.905,0.001
33.13,89.200,0.06088,2.917,0.001
33.26,89.400,0.06105,2.929,0.001
33.38,89.600,0.06121,2.939,0.001
33.50,89.800,0.06134,2.949,0.001
33.63,90.000,0.06151,2.961,0.001
33.73,90.200,0.06163,2.970,0.001
33.87,90.400,0.06180,2.982,0.001
34.00,90.600,0.06192,2.993,0.001
34.11,90.800,0.06209,3.004,0.001
34.23,91.000,0.06221,3.013,0.001
34.32,91.200,0.06234,3.022,0.001
34.42,91.400,0.06250,3.031,0.001
34.53,91.600,0.06263,3.041,0.001
34.64,91.800,0.06275,3.050,0.001
34.74,92.000,0.06292,3.058,0.001
34.85,92.200,0.06304,3.068,0.001
34.98,92.400,0.06317,3.080,0.001
35.08,92.600,0.06333,3.089,0.001
35.19,92.800,0.06346,3.098,0.001
35.31,93.000,0.06363,3.109,0.001
35.45,93.200,0.06375,3.121,0.001
35.57,93.400,0.06392,3.132,0.001
35.68,93.600,0.06404,3.142,0.001
35.83,93.800,0.06421,3.155,0.001
35.97,94.000,0.06433,3.167,0.001
36.11,94.200,0.06450,3.179,0.001
36.22,94.400,0.06466,3.189,0.001
36.37,94.600,0.06479,3.202,0.001
36.50,94.800,0.06495,3.214,0.001
36.67,95.000,0.06512,3.228,0.001
36.79,95.200,0.06529,3.239,0.001
36.94,95.400,0.06541,3.252,0.001
37.06,95.600,0.06558,3.263,0.001
37.23,95.800,0.06574,3.278,0.001
37.37,96.000,0.06591,3.290,0.001
37.52,96.200,0.06608,3.303,0.001
37.65,96.400,0.06624,3.315,0.001
37.83,96.600,0.06641,3.331,0.001
38.00,96.800,0.06662,3.346,0.001
38.20,97.000,0.06678,3.364,0.001
38.37,97.200,0.06699,3.378,0.001
38.56,97.400,0.06720,3.395,0.001
38.75,97.600,0.06741,3.412,0.001
38.93,97.800,0.06761,3.428,0.001
39.13,98.000,0.06786,3.445,0.001
39.32,98.200,0.06807,3.462,0.001
39.50,98.400,0.06828,3.477,0.001
39.68,98.600,0.06849,3.494,0.001
39.84,98.800,0.06869,3.508,0.001
40.03,99.000,0.06890,3.524,0.001
40.21,99.200,0.06911,3.540,0.001
40.35,99.400,0.06932,3.552,0.001
40.50,99.600,0.06953,3.565,0.001
40.63,99.800,0.06973,3.577,0.001
40.74,100.000,0.06990,3.587,0.001
40.85,100.200,0.07007,3.596,0.001
40.95,100.400,0.07023,3.605,0.001
41.08,100.600,0.07040,3.616,0.001
41.24,100.800,0.07056,3.631,0.001
41.35,101.000,0.07069,3.641,0.001
41.46,101.200,0.07086,3.651,0.001
41.59,101.400,0.07098,3.661,0.001
41.72,101.600,0.07115,3.673,0.001
41.83,101.800,0.07127,3.683,0.001
41.97,102.000,0.07144,3.695,0.001
42.08,102.200,0.07156,3.705,0.001
42.20,102.400,0.07169,3.716,0.001
42.34,102.600,0.07185,3.727,0.001
42.46,102.800,0.07198,3.738,0.001
42.60,103.000,0.07210,3.751,0.001
42.72,103.200,0.07227,3.761,0.001
42.85,103.400,0.07239,3.773,0.001
42.97,103.600,0.07252,3.783,0.001
43.13,103.800,0.07268,3.798,0.001
43.28,104.000,0.07281,3.810,0.001
43.43,104.200,0.07298,3.824,0.001
43.57,104.400,0.07314,3.836,0.001
43.70,104.600,0.07327,3.848,0.001
43.88,104.800,0.07343,3.863,0.001
44.00,105.000,0.07360,3.874,0.001
44.16,105.200,0.07372,3.888,0.001
44.29,105.400,0.07389,3.900,0.001
44.44,105.600,0.07406,3.913,0.001
44.57,105.800,0.07422,3.924,0.001
44.70,106.000,0.07435,3.935,0.001
44.85,106.200,0.07451,3.949,0.001
44.99,106.400,0.07468,3.961,0.001
45.13,106.600,0.07485,3.974,0.001
45.28,106.800,0.07501,3.987,0.001
45.43,107.000,0.07514,4.000,0.001
45.57,107.200,0.07530,4.012,0.001
45.74,107.400,0.07547,4.027,0.001
45.89,107.600,0.07568,4.041,0.001
46.06,107.800,0.07584,4.055,0.001
46.25,108.000,0.07605,4.072,0.001
46.45,108.200,0.07622,4.090,0.002
46.64,108.400,0.07642,4.106,0.002
46.83,108.600,0.07663,4.123,0.002
47.03,108.800,0.07684,4.141,0.002
47.26,109.000,0.07705,4.161,0.002
47.46,109.200,0.07726,4.179,0.002
47.70,109.400,0.07750,4.200,0.002
47.92,109.600,0.07771,4.219,0.002
48.14,109.800,0.07792,4.239,0.002
48.36,110.000,0.07817,4.258,0.002
48.56,110.200,0.07838,4.275,0.002
48.76,110.400,0.07859,4.293,0.002
48.97,110.600,0.07879,4.312,0.002
49.16,110.800,0.07900,4.328,0.002
49.36,111.000,0.07917,4.346,0.002
49.56,111.200,0.07937,4.363,0.002
49.71,111.400,0.07954,4.377,0.002
49.87,111.600,0.07971,4.391,0.002
50.04,111.800,0.07987,4.406,0.002
50.21,112.000,0.08004,4.420,0.002
50.36,112.200,0.08021,4.434,0.002
50.51,112.400,0.08033,4.447,0.002
50.66,112.600,0.08050,4.460,0.002
50.81,112.800,0.08062,4.474,0.002
50.95,113.000,0.08079,4.486,0.002
51.10,113.200,0.08091,4.499,0.002
51.24,113.400,0.08108,4.512,0.002
51.39,113.600,0.08120,4.525,0.002
51.53,113.800,0.08133,4.537,0.002
51.69,114.000,0.08149,4.551,0.002
51.80,114.200,0.08162,4.561,0.002
51.96,114.400,0.08174,4.575,0.002
52.10,114.600,0.08191,4.587,0.002
52.24,114.800,0.08203,4.600,0.002
52.39,115.000,0.08216,4.613,0.002
52.56,115.200,0.08233,4.627,0.002
52.74,115.400,0.08249,4.643,0.002
52.89,115.600,0.08262,4.656,0.002
53.04,115.800,0.08278,4.670,0.002
53.20,116.000,0.08295,4.684,0.002
53.37,116.200,0.08307,4.699,0.002
53.53,116.400,0.08324,4.713,0.002
53.67,116.600,0.08341,4.725,0.002
53.81,116.800,0.08353,4.738,0.002
53.99,117.000,0.08370,4.753,0.002
54.14,117.200,0.08386,4.766,0.002
54.30,117.400,0.08403,4.781,0.002
54.47,117.600,0.08415,4.796,0.002
54.61,117.800,0.08432,4.808,0.002
54.76,118.000,0.08449,4.822,0.002
54.91,118.200,0.08465,4.835,0.002
55.08,118.400,0.08482,4.849,0.002
55.23,118.600,0.08498,4.863,0.002
55.40,118.800,0.08515,4.878,0.002
55.54,119.000,0.08536,4.890,0.002
55.69,119.200,0.08552,4.903,0.002
55.84,119.400,0.08573,4.916,0.002
55.89,119.600,0.08590,4.921,0.002
56.01,119.800,0.08611,4.931,0.002
56.17,120.000,0.08631,4.945,0.002
56.32,120.200,0.08652,4.959,0.002
56.50,120.400,0.08677,4.975,0.002
56.65,120.600,0.08698,4.988,0.002
56.84,120.800,0.08719,5.004,0.002
57.02,121.000,0.08740,5.021,0.002
57.21,121.200,0.08760,5.037,0.002
57.39,121.400,0.08781,5.053,0.002
57.59,121.600,0.08802,5.070,0.002
57.77,121.800,0.08823,5.086,0.002
57.97,122.000,0.08839,5.104,0.002
58.15,122.200,0.08860,5.120,0.002
58.33,122.400,0.08877,5.136,0.002
58.52,122.600,0.08897,5.152,0.002
58.69,122.800,0.08914,5.168,0.002
58.83,123.000,0.08931,5.179,0.002
58.98,123.200,0.08947,5.193,0.002
59.15,123.400,0.08960,5.208,0.002
59.31,123.600,0.08976,5.222,0.002
59.47,123.800,0.08993,5.236,0.002
59.62,124.000,0.09005,5.250,0.002
59.79,124.200,0.09022,5.264,0.002
59.94,124.400,0.09035,5.277,0.002
60.09,124.600,0.09047,5.290,0.002
60.22,124.800,0.09064,5.302,0.002
60.36,125.000,0.09076,5.315,0.002
60.51,125.200,0.09089,5.328,0.002
60.71,125.400,0.09105,5.345,0.002
60.84,125.600,0.09118,5.357,0.002
61.00,125.800,0.09130,5.371,0.002
61.17,126.000,0.09147,5.386,0.002
61.32,126.200,0.09159,5.399,0.002
61.49,126.400,0.09172,5.414,0.002
61.68,126.600,0.09188,5.431,0.002
61.86,126.800,0.09205,5.447,0.002
62.00,127.000,0.09217,5.459,0.002
62.16,127.200,0.09230,5.473,0.002
62.36,127.400,0.09246,5.491,0.002
62.54,127.600,0.09263,5.507,0.002
62.72,127.800,0.09276,5.522,0.002
62.90,128.000,0.09292,5.538,0.002
63.09,128.200,0.09309,5.555,0.002
63.25,128.400,0.09321,5.569,0.002
63.44,128.600,0.09338,5.586,0.002
63.62,128.800,0.09355,5.601,0.002
63.78,129.000,0.09367,5.616,0.002
63.95,129.200,0.09384,5.630,0.002
64.12,129.400,0.09400,5.646,0.002
64.29,129.600,0.09417,5.661,0.002
64.46,129.800,0.09433,5.676,0.002
64.67,130.000,0.09450,5.694,0.002
64.89,130.200,0.09467,5.714,0.002
65.10,130.400,0.09483,5.731,0.002
65.32,130.600,0.09504,5.751,0.002
65.58,130.800,0.09521,5.774,0.002
65.83,131.000,0.09542,5.796,0.002
66.09,131.200,0.09562,5.819,0.002
66.35,131.400,0.09583,5.842,0.002
66.63,131.600,0.09604,5.866,0.002
66.92,131.800,0.09629,5.892,0.002
67.18,132.000,0.09650,5.915,0.002
67.47,132.200,0.09670,5.940,0.002
67.74,132.400,0.09691,5.964,0.002
68.01,132.600,0.09716,5.988,0.002
68.27,132.800,0.09737,6.011,0.002
68.51,133.000,0.09758,6.032,0.002
68.76,133.200,0.09778,6.054,0.002
68.98,133.400,0.09799,6.073,0.002
69.14,133.600,0.09816,6.087,0.002
69.37,133.800,0.09832,6.107,0.002
69.56,134.000,0.09849,6.124,0.002
69.75,134.200,0.09866,6.142,0.002
69.88,134.400,0.09882,6.153,0.002
70.07,134.600,0.09899,6.170,0.002
70.22,134.800,0.09911,6.182,0.002
70.37,135.000,0.09928,6.196,0.002
70.54,135.200,0.09940,6.211,0.002
70.70,135.400,0.09957,6.225,0.002
70.85,135.600,0.09970,6.238,0.002
70.99,135.800,0.09982,6.251,0.002
71.14,136.000,0.09999,6.264,0.002
71.28,136.200,0.10011,6.276,0.002
71.42,136.400,0.10024,6.288,0.002
71.56,136.600,0.10036,6.301,0.002
71.71,136.800,0.10053,6.314,0.002
71.85,137.000,0.10065,6.326,0.002
72.01,137.200,0.10078,6.340,0.002
72.21,137.400,0.10094,6.358,0.002
72.35,137.600,0.10107,6.370,0.002
72.49,137.800,0.10119,6.382,0.002
72.67,138.000,0.10136,6.398,0.002
72.83,138.200,0.10148,6.413,0.002
73.00,138.400,0.10165,6.428,0.002
73.15,138.600,0.10177,6.440,0.002
73.32,138.800,0.10194,6.455,0.002
73.49,139.000,0.10211,6.470,0.002
73.64,139.200,0.10227,6.483,0.002
73.81,139.400,0.10240,6.499,0.002
73.96,139.600,0.10256,6.511,0.002
74.10,139.800,0.10269,6.524,0.002
74.24,140.000,0.10285,6.537,0.002
74.43,140.200,0.10302,6.553,0.002
74.58,140.400,0.10319,6.566,0.002
74.75,140.600,0.10331,6.582,0.002
74.91,140.800,0.10348,6.595,0.002
75.08,141.000,0.10364,6.611,0.002
75.25,141.200,0.10381,6.626,0.002
75.43,141.400,0.10398,6.641,0.002
75.63,141.600,0.10414,6.659,0.002
75.83,141.800,0.10435,6.677,0.002
76.03,142.000,0.10452,6.694,0.002
76.24,142.200,0.10472,6.713,0.002
76.44,142.400,0.10493,6.730,0.002
76.63,142.600,0.10514,6.747,0.002
76.86,142.800,0.10535,6.767,0.002
77.07,143.000,0.10555,6.786,0.002
77.29,143.200,0.10576,6.805,0.002
77.51,143.400,0.10597,6.824,0.002
77.66,143.600,0.10618,6.838,0.002
77.86,143.800,0.10639,6.856,0.002
78.08,144.000,0.10659,6.875,0.002
78.27,144.200,0.10680,6.891,0.002
78.47,144.400,0.10701,6.909,0.002
78.65,144.600,0.10722,6.925,0.002
78.78,144.800,0.10738,6.936,0.002
78.94,145.000,0.10759,6.950,0.002
79.08,145.200,0.10776,6.962,0.002
79.22,145.400,0.10797,6.975,0.002
79.35,145.600,0.10813,6.986,0.002
79.47,145.800,0.10826,6.997,0.002
79.58,146.000,0.10842,7.007,0.002
79.71,146.200,0.10859,7.018,0.002
79.84,146.400,0.10871,7.029,0.002
79.95,146.600,0.10888,7.039,0.002
80.08,146.800,0.10900,7.050,0.002
80.21,147.000,0.10917,7.062,0.002
76.08,147.200,0.10929,6.698,0.002
75.59,147.400,0.10946,6.656,0.002
75.56,147.600,0.10959,6.653,0.002
75.65,147.800,0.10971,6.661,0.002
75.78,148.000,0.10984,6.672,0.002
75.95,148.200,0.11000,6.687,0.002
76.12,148.400,0.11013,6.702,0.002
76.31,148.600,0.11025,6.719,0.002
76.52,148.800,0.11042,6.737,0.002
76.72,149.000,0.11054,6.755,0.002
76.89,149.200,0.11071,6.769,0.002
77.11,149.400,0.11083,6.789,0.002
77.32,149.600,0.11100,6.808,0.002
77.50,149.800,0.11112,6.824,0.002
77.66,150.000,0.11129,6.838,0.002
77.82,150.200,0.11141,6.851,0.002
78.10,150.400,0.11158,6.876,0.002
78.38,150.600,0.11175,6.901,0.002
78.67,150.800,0.11191,6.926,0.002
78.94,151.000,0.11204,6.950,0.002
79.20,151.200,0.11220,6.973,0.002
79.42,151.400,0.11237,6.993,0.002
79.65,151.600,0.11249,7.012,0.002
79.86,151.800,0.11266,7.032,0.002
80.06,152.000,0.11283,7.049,0.002
80.28,152.200,0.11299,7.068,0.002
80.52,152.400,0.11316,7.089,0.002
80.72,152.600,0.11333,7.107,0.002
80.95,152.800,0.11349,7.127,0.002
81.17,153.000,0.11366,7.147,0.002
81.37,153.200,0.11382,7.165,0.002
81.61,153.400,0.11403,7.185,0.002
81.82,153.600,0.11420,7.204,0.002
82.05,153.800,0.11441,7.224,0.002
82.28,154.000,0.11461,7.245,0.002
82.51,154.200,0.11482,7.265,0.002
82.74,154.400,0.11503,7.285,0.002
83.01,154.600,0.11524,7.309,0.002
83.26,154.800,0.11545,7.330,0.002
83.47,155.000,0.11565,7.349,0.002
83.68,155.200,0.11586,7.367,0.002
83.90,155.400,0.11607,7.387,0.002
84.09,155.600,0.11628,7.403,0.002
84.29,155.800,0.11648,7.421,0.002
84.48,156.000,0.11669,7.438,0.002
84.65,156.200,0.11686,7.453,0.002
84.82,156.400,0.11707,7.468,0.002
84.99,156.600,0.11723,7.483,0.002
85.13,156.800,0.11740,7.496,0.002
85.28,157.000,0.11761,7.509,0.002
85.40,157.200,0.11773,7.519,0.002
85.55,157.400,0.11790,7.532,0.002
85.71,157.600,0.11806,7.546,0.002
85.85,157.800,0.11819,7.559,0.002
85.97,158.000,0.11835,7.569,0.002
86.12,158.200,0.11848,7.583,0.002
86.26,158.400,0.11865,7.595,0.002
86.40,158.600,0.11877,7.607,0.002
86.51,158.800,0.11894,7.617,0.002
86.65,159.000,0.11906,7.629,0.002
86.78,159.200,0.11919,7.640,0.002
86.92,159.400,0.11931,7.653,0.002
87.03,159.600,0.11948,7.662,0.002
87.17,159.800,0.11960,7.675,0.002
87.28,160.000,0.11973,7.685,0.002
87.42,160.200,0.11989,7.697,0.002
87.56,160.400,0.12002,7.709,0.002
87.72,160.600,0.12018,7.724,0.002
87.86,160.800,0.12031,7.736,0.002
87.99,161.000,0.12047,7.747,0.002
88.15,161.200,0.12060,7.761,0.002
88.28,161.400,0.12076,7.772,0.002
88.45,161.600,0.12089,7.788,0.002
88.60,161.800,0.12106,7.800,0.002
88.73,162.000,0.12118,7.812,0.002
88.89,162.200,0.12135,7.826,0.002
89.05,162.400,0.12151,7.840,0.002
89.19,162.600,0.12168,7.853,0.002
89.33,162.800,0.12180,7.865,0.002
89.48,163.000,0.12197,7.879,0.002
89.62,163.200,0.12214,7.891,0.002
89.76,163.400,0.12226,7.903,0.002
89.94,163.600,0.12243,7.919,0.002
90.09,163.800,0.12259,7.932,0.002
90.23,164.000,0.12276,7.944,0.002
90.41,164.200,0.12293,7.960,0.002
90.59,164.400,0.12313,7.976,0.002
90.78,164.600,0.12330,7.993,0.002
90.99,164.800,0.12351,8.012,0.002
91.24,165.000,0.12367,8.033,0.002
91.41,165.200,0.12388,8.049,0.002
91.61,165.400,0.12409,8.066,0.002
91.84,165.600,0.12430,8.086,0.002
92.07,165.800,0.12450,8.106,0.002
92.30,166.000,0.12471,8.127,0.002
92.52,166.200,0.12496,8.146,0.002
92.72,166.400,0.12517,8.164,0.002
92.89,166.600,0.12538,8.179,0.002
93.11,166.800,0.12558,8.198,0.002
93.33,167.000,0.12579,8.217,0.002
93.55,167.200,0.12600,8.236,0.002
93.72,167.400,0.12621,8.252,0.002
93.88,167.600,0.12642,8.266,0.002
94.07,167.800,0.12658,8.282,0.002
94.21,168.000,0.12679,8.295,0.002
94.33,168.200,0.12696,8.306,0.002
94.47,168.400,0.12712,8.317,0.003
94.56,168.600,0.12725,8.326,0.003
94.65,168.800,0.12741,8.333,0.003
94.77,169.000,0.12758,8.344,0.003
94.86,169.200,0.12770,8.352,0.003
94.97,169.400,0.12783,8.362,0.003
95.12,169.600,0.12800,8.375,0.003
95.23,169.800,0.12812,8.385,0.003
95.33,170.000,0.12829,8.393,0.003
95.42,170.200,0.12841,8.401,0.003
95.55,170.400,0.12854,8.413,0.003
95.69,170.600,0.12866,8.425,0.003
95.80,170.800,0.12883,8.435,0.003
95.91,171.000,0.12895,8.444,0.003
96.01,171.200,0.12908,8.453,0.003
96.17,171.400,0.12924,8.467,0.003
96.30,171.600,0.12937,8.479,0.003
96.45,171.800,0.12953,8.492,0.003
96.62,172.000,0.12966,8.507,0.003
96.76,172.200,0.12982,8.519,0.003
96.90,172.400,0.12995,8.532,0.003
97.06,172.600,0.13011,8.546,0.003
97.21,172.800,0.13028,8.559,0.003
97.37,173.000,0.13041,8.573,0.003
97.52,173.200,0.13057,8.586,0.003
97.67,173.400,0.13074,8.600,0.003
97.81,173.600,0.13090,8.612,0.003
96.19,173.800,0.13107,8.469,0.003
95.89,174.000,0.13119,8.443,0.003
95.96,174.200,0.13136,8.448,0.003
96.11,174.400,0.13153,8.462,0.003
96.32,174.600,0.13169,8.480,0.003
96.53,174.800,0.13186,8.499,0.003
96.76,175.000,0.13198,8.519,0.003
96.98,175.200,0.13215,8.539,0.003
97.22,175.400,0.13236,8.560,0.003
97.48,175.600,0.13252,8.583,0.003
97.71,175.800,0.13269,8.603,0.003
97.97,176.000,0.13290,8.626,0.003
98.21,176.200,0.13311,8.647,0.003
98.43,176.400,0.13331,8.667,0.003
98.65,176.600,0.13352,8.685,0.003
98.87,176.800,0.13373,8.705,0.003
99.10,177.000,0.13394,8.725,0.003
99.31,177.200,0.13419,8.744,0.003
99.51,177.400,0.13439,8.761,0.003
99.68,177.600,0.13460,8.777,0.003
99.91,177.800,0.13485,8.796,0.003
100.08,178.000,0.13506,8.811,0.003
100.21,178.200,0.13527,8.823,0.003
100.38,178.400,0.13548,8.838,0.003
100.54,178.600,0.13568,8.852,0.003
100.65,178.800,0.13589,8.862,0.003
100.74,179.000,0.13606,8.870,0.003
100.62,179.200,0.13626,8.860,0.003
100.59,179.400,0.13643,8.856,0.003
100.56,179.600,0.13660,8.854,0.003
100.56,179.800,0.13676,8.854,0.003
100.61,180.000,0.13689,8.858,0.003
100.67,180.200,0.13705,8.863,0.003
100.73,180.400,0.13722,8.869,0.003
100.81,180.600,0.13735,8.876,0.003
100.88,180.800,0.13751,8.882,0.003
100.97,181.000,0.13764,8.890,0.003
101.05,181.200,0.13776,8.897,0.003
101.14,181.400,0.13793,8.905,0.003
101.19,181.600,0.13805,8.910,0.003
101.28,181.800,0.13818,8.918,0.003
101.37,182.000,0.13834,8.925,0.003
101.48,182.200,0.13847,8.935,0.003
101.56,182.400,0.13863,8.941,0.003
101.65,182.600,0.13876,8.950,0.003
101.77,182.800,0.13892,8.960,0.003
101.87,183.000,0.13905,8.969,0.003
102.00,183.200,0.13922,8.981,0.003
102.13,183.400,0.13934,8.992,0.003
102.24,183.600,0.13951,9.002,0.003
102.36,183.800,0.13967,9.012,0.003
102.49,184.000,0.13980,9.024,0.003
102.60,184.200,0.13996,9.033,0.003
102.69,184.400,0.14013,9.041,0.003
102.78,184.600,0.14025,9.049,0.003
102.90,184.800,0.14042,9.060,0.003
103.04,185.000,0.14059,9.073,0.003
103.18,185.200,0.14075,9.084,0.003
103.30,185.400,0.14092,9.095,0.003
103.44,185.600,0.14104,9.108,0.003
103.55,185.800,0.14121,9.117,0.003
103.68,186.000,0.14138,9.128,0.003
103.80,186.200,0.14154,9.139,0.003
103.96,186.400,0.14171,9.153,0.003
104.13,186.600,0.14187,9.169,0.003
104.28,186.800,0.14204,9.182,0.003
104.46,187.000,0.14225,9.197,0.003
104.65,187.200,0.14241,9.214,0.003
104.84,187.400,0.14262,9.230,0.003
104.97,187.600,0.14283,9.242,0.003
105.11,187.800,0.14304,9.254,0.003
105.25,188.000,0.14325,9.267,0.003
105.39,188.200,0.14350,9.279,0.003
105.52,188.400,0.14370,9.291,0.003
105.65,188.600,0.14391,9.302,0.003
105.77,188.800,0.14412,9.312,0.003
105.88,189.000,0.14433,9.322,0.003
105.99,189.200,0.14458,9.332,0.003
106.08,189.400,0.14478,9.339,0.003
106.16,189.600,0.14499,9.347,0.003
106.19,189.800,0.14516,9.349,0.003
106.25,190.000,0.14537,9.355,0.003
106.32,190.200,0.14553,9.361,0.003
106.36,190.400,0.14574,9.364,0.003
106.40,190.600,0.14591,9.368,0.003
106.43,190.800,0.14607,9.371,0.003
106.50,191.000,0.14624,9.377,0.003
106.50,191.200,0.14636,9.377,0.003
106.50,191.400,0.14653,9.377,0.003
106.50,191.600,0.14670,9.377,0.003
106.48,191.800,0.14682,9.375,0.003
106.48,192.000,0.14699,9.375,0.003
106.42,192.200,0.14711,9.370,0.003
106.36,192.400,0.14724,9.365,0.003
106.31,192.600,0.14740,9.360,0.003
106.27,192.800,0.14753,9.357,0.003
106.21,193.000,0.14765,9.351,0.003
106.18,193.200,0.14782,9.348,0.003
106.15,193.400,0.14794,9.346,0.003
106.13,193.600,0.14807,9.345,0.003
106.11,193.800,0.14823,9.343,0.003
106.07,194.000,0.14836,9.339,0.003
106.04,194.200,0.14852,9.336,0.003
105.97,194.400,0.14865,9.330,0.003
105.50,194.600,0.14877,9.289,0.003
104.99,194.800,0.14894,9.244,0.003
104.61,195.000,0.14906,9.211,0.003
104.24,195.200,0.14923,9.178,0.003
103.96,195.400,0.14935,9.153,0.003
102.81,195.600,0.14952,9.052,0.003
102.04,195.800,0.14969,8.984,0.003
101.84,196.000,0.14981,8.966,0.003
101.72,196.200,0.14998,8.956,0.003
101.62,196.400,0.15014,8.947,0.003
101.63,196.600,0.15027,8.948,0.003
101.66,196.800,0.15044,8.950,0.003
101.69,197.000,0.15060,8.954,0.003
101.71,197.200,0.15073,8.955,0.003
21.78,197.400,0.15089,1.917,0.003
22.82,197.600,0.15106,2.009,0.003
23.25,197.800,0.15122,2.047,0.003
23.62,198.000,0.15139,2.079,0.003
23.99,198.200,0.15156,2.112,0.003
24.34,198.400,0.15172,2.143,0.003
24.71,198.580,0.15189,2.175,0.003