File: data-files/CWRU/1000-05-35B.txt
""
"Test Method","Will_Huddleston_Disks.msm"
"Sample I. D.","1000-5-35B.mss"
"Specimen Number","1"

"Load (N)","Time (s)","Extension (mm)","Stress (MPa)","Strain (mm/mm)"

2.85,0.200,-0.00966,0.535,0.000
2.87,0.300,-0.00966,0.538,0.000
2.87,0.400,-0.00966,0.537,0.000
2.87,0.500,-0.00962,0.538,0.000
2.87,0.600,-0.00962,0.537,0.000
2.88,0.700,-0.00958,0.539,0.000
2.86,0.800,-0.00958,0.537,0.000
2.86,0.900,-0.00958,0.536,0.000
2.86,1.000,-0.00954,0.536,0.000
2.86,1.100,-0.00954,0.536,0.000
2.87,1.200,-0.00950,0.537,0.000
2.87,1.300,-0.00950,0.538,0.000
2.89,1.400,-0.00945,0.542,0.000
2.90,1.500,-0.00941,0.544,0.000
2.95,1.600,-0.00933,0.553,0.000
3.02,1.700,-0.00921,0.566,0.000
3.11,1.800,-0.00908,0.582,0.000
3.21,1.900,-0.00887,0.601,0.000
3.30,2.000,-0.00871,0.618,0.000
3.37,2.100,-0.00854,0.631,0.000
3.44,2.200,-0.00842,0.644,0.000
3.48,2.300,-0.00825,0.652,0.000
3.53,2.400,-0.00812,0.662,0.000
3.58,2.500,-0.00796,0.670,0.000
3.61,2.600,-0.00783,0.677,0.000
3.65,2.700,-0.00771,0.683,0.000
3.68,2.800,-0.00754,0.688,0.000
3.72,2.900,-0.00742,0.696,0.000
3.75,3.000,-0.00729,0.703,0.000
3.78,3.100,-0.00717,0.708,0.000
3.80,3.200,-0.00704,0.711,0.000
3.82,3.300,-0.00688,0.715,0.000
3.86,3.400,-0.00675,0.723,0.000
3.87,3.500,-0.00663,0.725,0.000
3.90,3.600,-0.00650,0.731,0.000
3.92,3.700,-0.00638,0.735,0.000
3.95,3.800,-0.00621,0.739,0.000
3.97,3.900,-0.00609,0.744,0.000
4.00,4.000,-0.00596,0.749,0.000
4.03,4.100,-0.00580,0.755,0.000
4.04,4.200,-0.00567,0.758,0.000
4.07,4.300,-0.00555,0.762,0.000
4.08,4.400,-0.00538,0.765,0.000
4.11,4.500,-0.00526,0.770,0.000
4.14,4.600,-0.00509,0.775,0.000
4.15,4.700,-0.00497,0.778,0.000
4.18,4.800,-0.00480,0.783,0.000
4.19,4.900,-0.00468,0.786,0.000
4.23,5.000,-0.00451,0.792,0.000
4.25,5.100,-0.00434,0.795,0.000
4.27,5.200,-0.00422,0.800,0.000
4.30,5.300,-0.00405,0.805,0.000
4.31,5.400,-0.00389,0.808,0.000
4.34,5.500,-0.00372,0.813,0.000
4.36,5.600,-0.00360,0.818,0.000
4.39,5.700,-0.00339,0.823,0.000
4.41,5.800,-0.00322,0.826,0.000
4.44,5.900,-0.00306,0.831,0.000
4.47,6.000,-0.00289,0.838,0.000
4.49,6.100,-0.00268,0.840,0.000
4.50,6.200,-0.00251,0.843,0.000
4.54,6.300,-0.00231,0.851,0.000
4.58,6.400,-0.00210,0.858,0.000
4.61,6.500,-0.00189,0.864,0.000
4.64,6.600,-0.00168,0.869,0.000
4.66,6.700,-0.00148,0.874,0.000
4.70,6.800,-0.00127,0.881,0.000
4.72,6.900,-0.00106,0.883,0.000
4.73,7.000,-0.00085,0.887,0.000
4.77,7.100,-0.00064,0.894,0.000
4.81,7.200,-0.00044,0.901,0.000
4.82,7.300,-0.00023,0.902,0.000
4.85,7.400,-0.00006,0.908,0.000
4.89,7.500,0.00014,0.915,0.000
4.89,7.600,0.00031,0.916,0.000
4.93,7.700,0.00052,0.924,0.000
4.94,7.800,0.00068,0.926,0.000
4.98,7.900,0.00081,0.932,0.000
4.99,8.000,0.00098,0.934,0.000
5.01,8.100,0.00114,0.938,0.000
5.03,8.200,0.00127,0.943,0.000
5.03,8.300,0.00143,0.943,0.000
5.06,8.400,0.00156,0.949,0.000
5.07,8.500,0.00168,0.950,0.000
5.07,8.600,0.00185,0.950,0.000
5.10,8.700,0.00197,0.956,0.000
5.12,8.800,0.00210,0.959,0.000
5.15,8.900,0.00222,0.965,0.000
5.16,9.000,0.00239,0.966,0.000
5.17,9.100,0.00251,0.968,0.000
5.18,9.200,0.00264,0.970,0.000
5.22,9.300,0.00276,0.977,0.000
5.24,9.400,0.00293,0.981,0.000
5.26,9.500,0.00305,0.985,0.000
5.28,9.600,0.00322,0.989,0.000
5.29,9.700,0.00334,0.991,0.000
5.33,9.800,0.00351,0.999,0.000
5.34,9.900,0.00364,1.001,0.000
5.37,10.000,0.00380,1.005,0.000
5.39,10.100,0.00393,1.010,0.000
5.41,10.200,0.00409,1.014,0.000
5.43,10.300,0.00422,1.017,0.000
5.45,10.400,0.00438,1.021,0.000
5.47,10.500,0.00455,1.024,0.000
5.50,10.600,0.00467,1.031,0.000
5.53,10.700,0.00484,1.035,0.000
5.56,10.800,0.00501,1.041,0.000
5.59,10.900,0.00513,1.047,0.000
5.61,11.000,0.00530,1.050,0.000
5.62,11.100,0.00546,1.053,0.000
5.64,11.200,0.00563,1.056,0.000
5.67,11.300,0.00580,1.062,0.000
5.68,11.400,0.00596,1.065,0.000
5.71,11.500,0.00613,1.070,0.000
5.73,11.600,0.00629,1.074,0.000
5.78,11.700,0.00650,1.083,0.000
5.79,11.800,0.00667,1.085,0.000
5.82,11.900,0.00688,1.091,0.000
5.85,12.000,0.00708,1.097,0.000
5.91,12.100,0.00729,1.108,0.000
5.94,12.200,0.00750,1.112,0.000
5.98,12.300,0.00771,1.120,0.000
5.98,12.400,0.00792,1.121,0.000
6.03,12.500,0.00812,1.129,0.000
6.06,12.600,0.00833,1.135,0.000
6.08,12.700,0.00854,1.139,0.000
6.10,12.800,0.00875,1.142,0.000
6.14,12.900,0.00895,1.149,0.000
6.17,13.000,0.00916,1.157,0.000
6.20,13.100,0.00933,1.161,0.000
6.23,13.200,0.00954,1.166,0.000
6.24,13.300,0.00970,1.170,0.000
6.26,13.400,0.00987,1.173,0.000
6.29,13.500,0.01008,1.178,0.000
6.30,13.600,0.01020,1.181,0.000
6.32,13.700,0.01037,1.185,0.000
6.36,13.800,0.01053,1.191,0.000
6.37,13.900,0.01066,1.193,0.000
6.38,14.000,0.01082,1.196,0.000
6.42,14.100,0.01099,1.202,0.000
6.43,14.200,0.01112,1.205,0.000
6.45,14.300,0.01128,1.209,0.000
6.47,14.400,0.01141,1.211,0.000
6.48,14.500,0.01153,1.214,0.000
6.52,14.600,0.01166,1.220,0.000
6.53,14.700,0.01182,1.224,0.000
6.55,14.800,0.01195,1.228,0.000
6.58,14.900,0.01207,1.233,0.000
6.61,15.000,0.01224,1.239,0.000
6.62,15.100,0.01236,1.241,0.000
6.66,15.200,0.01249,1.247,0.000
6.68,15.300,0.01265,1.251,0.000
6.69,15.400,0.01278,1.254,0.000
6.71,15.500,0.01294,1.256,0.000
6.74,15.600,0.01307,1.262,0.000
6.77,15.700,0.01323,1.268,0.000
6.80,15.800,0.01340,1.273,0.000
6.82,15.900,0.01353,1.277,0.000
6.86,16.000,0.01369,1.285,0.000
6.89,16.100,0.01386,1.290,0.000
6.93,16.200,0.01402,1.297,0.000
6.95,16.300,0.01415,1.303,0.000
6.97,16.400,0.01432,1.305,0.000
6.99,16.500,0.01444,1.310,0.000
7.02,16.600,0.01461,1.315,0.000
7.05,16.700,0.01477,1.320,0.000
7.06,16.800,0.01494,1.323,0.000
7.09,16.900,0.01510,1.328,0.000
7.12,17.000,0.01523,1.333,0.000
7.15,17.100,0.01540,1.340,0.000
7.17,17.200,0.01560,1.344,0.000
7.20,17.300,0.01577,1.349,0.000
7.23,17.400,0.01594,1.354,0.000
7.26,17.500,0.01614,1.360,0.000
7.29,17.600,0.01631,1.366,0.000
7.33,17.700,0.01652,1.372,0.000
7.36,17.800,0.01673,1.379,0.000
7.40,17.900,0.01693,1.386,0.000
7.44,18.000,0.01710,1.393,0.000
7.47,18.100,0.01735,1.400,0.000
7.51,18.200,0.01756,1.407,0.000
7.55,18.300,0.01776,1.414,0.000
7.57,18.400,0.01797,1.419,0.000
7.62,18.500,0.01818,1.427,0.000
7.64,18.600,0.01839,1.432,0.000
7.67,18.700,0.01860,1.438,0.000
7.70,18.800,0.01876,1.441,0.000
7.73,18.900,0.01897,1.448,0.000
7.77,19.000,0.01914,1.455,0.000
7.81,19.100,0.01930,1.463,0.000
7.82,19.200,0.01947,1.465,0.000
7.84,19.300,0.01968,1.469,0.000
7.87,19.400,0.01980,1.474,0.000
7.90,19.500,0.01997,1.480,0.000
7.90,19.600,0.02013,1.480,0.000
7.93,19.700,0.02030,1.486,0.000
7.96,19.800,0.02042,1.490,0.000
7.99,19.900,0.02055,1.497,0.000
8.00,20.000,0.02071,1.498,0.000
8.03,20.100,0.02084,1.505,0.000
8.03,20.200,0.02101,1.505,0.000
8.07,20.300,0.02113,1.511,0.000
8.08,20.400,0.02126,1.513,0.000
8.10,20.500,0.02138,1.517,0.000
8.13,20.600,0.02155,1.524,0.000
8.15,20.700,0.02167,1.526,0.000
8.16,20.800,0.02180,1.529,0.000
8.21,20.900,0.02196,1.537,0.000
8.21,21.000,0.02209,1.539,0.000
8.24,21.100,0.02221,1.544,0.000
8.27,21.200,0.02238,1.549,0.000
8.29,21.300,0.02250,1.553,0.000
8.31,21.400,0.02267,1.557,0.000
8.36,21.500,0.02279,1.565,0.000
8.38,21.600,0.02296,1.569,0.000
8.39,21.700,0.02313,1.571,0.000
8.41,21.800,0.02325,1.576,0.000
8.44,21.900,0.02342,1.582,0.000
8.48,22.000,0.02354,1.588,0.000
8.51,22.100,0.02371,1.594,0.000
8.53,22.200,0.02387,1.598,0.000
8.56,22.300,0.02404,1.604,0.000
8.58,22.400,0.02416,1.606,0.000
8.62,22.500,0.02433,1.615,0.000
8.65,22.600,0.02450,1.620,0.000
8.66,22.700,0.02466,1.623,0.000
8.70,22.800,0.02483,1.629,0.000
8.73,22.900,0.02500,1.636,0.000
8.76,23.000,0.02516,1.641,0.000
8.81,23.100,0.02533,1.651,0.000
8.83,23.200,0.02554,1.654,0.001
8.86,23.300,0.02574,1.660,0.001
8.90,23.400,0.02591,1.667,0.001
8.93,23.500,0.02612,1.674,0.001
8.97,23.600,0.02632,1.680,0.001
9.03,23.700,0.02653,1.691,0.001
9.05,23.800,0.02674,1.695,0.001
9.10,23.900,0.02699,1.705,0.001
9.12,24.000,0.02720,1.708,0.001
9.16,24.100,0.02741,1.717,0.001
9.20,24.200,0.02761,1.723,0.001
9.23,24.300,0.02782,1.728,0.001
9.26,24.400,0.02803,1.735,0.001
9.31,24.500,0.02819,1.744,0.001
9.34,24.600,0.02840,1.750,0.001
9.37,24.700,0.02861,1.755,0.001
9.40,24.800,0.02878,1.760,0.001
9.42,24.900,0.02894,1.765,0.001
9.45,25.000,0.02911,1.770,0.001
9.48,25.100,0.02928,1.776,0.001
9.52,25.200,0.02944,1.783,0.001
9.54,25.300,0.02957,1.787,0.001
9.57,25.400,0.02973,1.792,0.001
9.58,25.500,0.02986,1.795,0.001
9.61,25.600,0.03002,1.800,0.001
9.64,25.700,0.03015,1.807,0.001
9.67,25.800,0.03027,1.811,0.001
9.69,25.900,0.03044,1.814,0.001
9.71,26.000,0.03056,1.819,0.001
9.72,26.100,0.03069,1.820,0.001
9.75,26.200,0.03081,1.827,0.001
9.77,26.300,0.03098,1.830,0.001
9.81,26.400,0.03110,1.838,0.001
9.83,26.500,0.03123,1.841,0.001
9.86,26.600,0.03139,1.848,0.001
9.90,26.700,0.03152,1.854,0.001
9.92,26.800,0.03164,1.859,0.001
9.94,26.900,0.03181,1.861,0.001
9.98,27.000,0.03198,1.870,0.001
10.02,27.100,0.03210,1.876,0.001
10.06,27.200,0.03227,1.884,0.001
10.08,27.300,0.03243,1.888,0.001
10.11,27.400,0.03260,1.894,0.001
10.13,27.500,0.03272,1.898,0.001
10.17,27.600,0.03289,1.906,0.001
10.20,27.700,0.03306,1.910,0.001
10.23,27.800,0.03318,1.917,0.001
10.26,27.900,0.03335,1.923,0.001
10.30,28.000,0.03351,1.929,0.001
10.33,28.100,0.03368,1.935,0.001
10.36,28.200,0.03385,1.941,0.001
10.40,28.300,0.03401,1.949,0.001
10.43,28.400,0.03414,1.953,0.001
10.47,28.500,0.03430,1.961,0.001
10.51,28.600,0.03447,1.968,0.001
10.52,28.700,0.03468,1.971,0.001
10.57,28.800,0.03484,1.979,0.001
10.62,28.900,0.03505,1.989,0.001
10.64,29.000,0.03522,1.994,0.001
10.70,29.100,0.03543,2.004,0.001
10.77,29.200,0.03563,2.017,0.001
10.80,29.300,0.03584,2.023,0.001
10.84,29.400,0.03605,2.030,0.001
10.88,29.500,0.03626,2.038,0.001
10.94,29.600,0.03646,2.049,0.001
10.98,29.700,0.03667,2.057,0.001
11.02,29.800,0.03692,2.063,0.001
11.06,29.900,0.03713,2.071,0.001
11.11,30.000,0.03730,2.081,0.001
11.15,30.100,0.03750,2.088,0.001
11.18,30.200,0.03771,2.094,0.001
11.21,30.300,0.03792,2.100,0.001
11.24,30.400,0.03809,2.106,0.001
11.27,30.500,0.03825,2.111,0.001
11.30,30.600,0.03846,2.117,0.001
11.33,30.700,0.03858,2.122,0.001
11.36,30.800,0.03875,2.128,0.001
11.38,30.900,0.03892,2.132,0.001
11.41,31.000,0.03908,2.138,0.001
11.45,31.100,0.03925,2.145,0.001
11.46,31.200,0.03937,2.147,0.001
11.50,31.300,0.03950,2.154,0.001
11.53,31.400,0.03966,2.160,0.001
11.56,31.500,0.03979,2.165,0.001
11.56,31.600,0.03996,2.165,0.001
11.59,31.700,0.04008,2.171,0.001
11.61,31.800,0.04020,2.176,0.001
11.65,31.900,0.04033,2.182,0.001
11.66,32.000,0.04050,2.184,0.001
11.68,32.100,0.04062,2.189,0.001
11.73,32.200,0.04079,2.198,0.001
11.75,32.300,0.04091,2.201,0.001
11.75,32.400,0.04104,2.202,0.001
11.80,32.500,0.04120,2.210,0.001
11.83,32.600,0.04137,2.217,0.001
11.85,32.700,0.04149,2.220,0.001
11.88,32.800,0.04166,2.225,0.001
11.94,32.900,0.04183,2.236,0.001
11.94,33.000,0.04195,2.237,0.001
11.99,33.100,0.04212,2.246,0.001
12.00,33.200,0.04228,2.248,0.001
12.04,33.300,0.04241,2.256,0.001
12.08,33.400,0.04257,2.264,0.001
12.12,33.500,0.04274,2.270,0.001
12.13,33.600,0.04291,2.273,0.001
12.18,33.700,0.04303,2.281,0.001
12.21,33.800,0.04320,2.286,0.001
12.24,33.900,0.04336,2.293,0.001
12.27,34.000,0.04353,2.299,0.001
12.31,34.100,0.04370,2.307,0.001
12.34,34.200,0.04386,2.311,0.001
12.39,34.300,0.04403,2.320,0.001
12.42,34.400,0.04419,2.326,0.001
12.47,34.500,0.04440,2.335,0.001
12.48,34.600,0.04457,2.338,0.001
12.55,34.700,0.04478,2.351,0.001
12.60,34.800,0.04498,2.360,0.001
12.65,34.900,0.04519,2.370,0.001
12.70,35.000,0.04540,2.379,0.001
12.77,35.100,0.04561,2.392,0.001
12.81,35.200,0.04581,2.399,0.001
12.85,35.300,0.04602,2.407,0.001
12.88,35.400,0.04623,2.413,0.001
12.94,35.500,0.04644,2.424,0.001
12.97,35.600,0.04665,2.430,0.001
13.01,35.700,0.04685,2.437,0.001
13.05,35.800,0.04706,2.444,0.001
13.09,35.900,0.04723,2.453,0.001
13.13,36.000,0.04744,2.459,0.001
13.16,36.100,0.04760,2.464,0.001
13.18,36.200,0.04781,2.468,0.001
13.21,36.300,0.04798,2.475,0.001
13.24,36.400,0.04814,2.480,0.001
13.28,36.500,0.04827,2.487,0.001
13.30,36.600,0.04843,2.491,0.001
13.34,36.700,0.04860,2.498,0.001
13.36,36.800,0.04872,2.503,0.001
13.39,36.900,0.04889,2.509,0.001
13.42,37.000,0.04906,2.514,0.001
13.43,37.100,0.04918,2.515,0.001
13.48,37.200,0.04931,2.525,0.001
13.49,37.300,0.04947,2.527,0.001
13.51,37.400,0.04960,2.531,0.001
13.54,37.500,0.04972,2.536,0.001
13.57,37.600,0.04989,2.543,0.001
13.62,37.700,0.05001,2.551,0.001
13.64,37.800,0.05014,2.556,0.001
13.68,37.900,0.05030,2.564,0.001
13.71,38.000,0.05043,2.568,0.001
13.73,38.100,0.05055,2.572,0.001
13.77,38.200,0.05072,2.579,0.001
13.79,38.300,0.05088,2.583,0.001
13.82,38.400,0.05101,2.589,0.001
13.85,38.500,0.05118,2.594,0.001
13.88,38.600,0.05130,2.601,0.001
13.90,38.700,0.05147,2.605,0.001
13.95,38.800,0.05159,2.612,0.001
13.96,38.900,0.05176,2.615,0.001
14.02,39.000,0.05192,2.625,0.001
14.04,39.100,0.05205,2.629,0.001
14.07,39.200,0.05221,2.635,0.001
14.09,39.300,0.05234,2.640,0.001
14.14,39.400,0.05251,2.648,0.001
14.18,39.500,0.05267,2.656,0.001
14.21,39.600,0.05284,2.662,0.001
14.24,39.700,0.05296,2.668,0.001
14.28,39.800,0.05313,2.676,0.001
14.32,39.900,0.05329,2.683,0.001
14.35,40.000,0.05346,2.689,0.001
14.39,40.100,0.05367,2.696,0.001
14.43,40.200,0.05383,2.704,0.001
14.49,40.300,0.05404,2.714,0.001
14.53,40.400,0.05421,2.722,0.001
14.57,40.500,0.05442,2.729,0.001
14.63,40.600,0.05462,2.741,0.001
14.67,40.700,0.05483,2.748,0.001
14.73,40.800,0.05504,2.760,0.001
14.77,40.900,0.05529,2.767,0.001
14.83,41.000,0.05550,2.778,0.001
14.87,41.100,0.05570,2.785,0.001
14.93,41.200,0.05591,2.797,0.001
14.96,41.300,0.05612,2.803,0.001
14.99,41.400,0.05629,2.809,0.001
15.02,41.500,0.05649,2.814,0.001
15.09,41.600,0.05670,2.826,0.001
15.10,41.700,0.05687,2.828,0.001
15.15,41.800,0.05708,2.838,0.001
15.17,41.900,0.05724,2.841,0.001
15.21,42.000,0.05741,2.849,0.001
15.24,42.100,0.05757,2.855,0.001
15.28,42.200,0.05770,2.861,0.001
15.30,42.300,0.05787,2.866,0.001
15.33,42.400,0.05799,2.871,0.001
15.35,42.500,0.05816,2.875,0.001
15.38,42.600,0.05828,2.881,0.001
15.41,42.700,0.05845,2.886,0.001
15.43,42.800,0.05857,2.891,0.001
15.45,42.900,0.05870,2.895,0.001
15.50,43.000,0.05886,2.904,0.001
15.53,43.100,0.05899,2.909,0.001
15.55,43.200,0.05911,2.912,0.001
15.59,43.300,0.05924,2.920,0.001
15.61,43.400,0.05940,2.924,0.001
15.65,43.500,0.05953,2.932,0.001
15.67,43.600,0.05965,2.935,0.001
15.72,43.700,0.05982,2.944,0.001
15.75,43.800,0.05994,2.950,0.001
15.77,43.900,0.06011,2.955,0.001
15.80,44.000,0.06023,2.960,0.001
15.84,44.100,0.06040,2.967,0.001
15.88,44.200,0.06053,2.975,0.001
15.92,44.300,0.06069,2.982,0.001
15.95,44.400,0.06082,2.988,0.001
16.00,44.500,0.06098,2.998,0.001
16.03,44.600,0.06115,3.003,0.001
16.08,44.700,0.06127,3.011,0.001
16.11,44.800,0.06144,3.018,0.001
16.13,44.900,0.06161,3.022,0.001
16.18,45.000,0.06173,3.031,0.001
16.22,45.100,0.06190,3.038,0.001
16.26,45.200,0.06206,3.046,0.001
16.30,45.300,0.06223,3.053,0.001
16.32,45.400,0.06235,3.057,0.001
16.37,45.500,0.06252,3.066,0.001
16.40,45.600,0.06269,3.072,0.001
16.44,45.700,0.06285,3.079,0.001
16.47,45.800,0.06306,3.085,0.001
16.52,45.900,0.06323,3.095,0.001
16.56,46.000,0.06343,3.103,0.001
16.62,46.100,0.06360,3.113,0.001
16.67,46.200,0.06381,3.122,0.001
16.71,46.300,0.06402,3.130,0.001
16.77,46.400,0.06422,3.141,0.001
16.83,46.500,0.06443,3.153,0.001
16.86,46.600,0.06464,3.158,0.001
16.91,46.700,0.06485,3.168,0.001
16.97,46.800,0.06505,3.179,0.001
17.01,46.900,0.06526,3.187,0.001
17.06,47.000,0.06547,3.197,0.001
17.08,47.100,0.06564,3.200,0.001
17.13,47.200,0.06584,3.208,0.001
17.18,47.300,0.06605,3.218,0.001
17.24,47.400,0.06626,3.230,0.001
17.27,47.500,0.06643,3.236,0.001
17.31,47.600,0.06663,3.244,0.001
17.35,47.700,0.06680,3.250,0.001
17.38,47.800,0.06697,3.255,0.001
17.42,47.900,0.06713,3.263,0.001
17.46,48.000,0.06730,3.271,0.001
17.48,48.100,0.06742,3.275,0.001
17.51,48.200,0.06759,3.280,0.001
17.55,48.300,0.06771,3.288,0.001
17.60,48.400,0.06788,3.296,0.001
17.63,48.500,0.06801,3.303,0.001
17.66,48.600,0.06817,3.307,0.001
17.69,48.700,0.06830,3.313,0.001
17.72,48.800,0.06842,3.320,0.001
17.75,48.900,0.06859,3.324,0.001
17.78,49.000,0.06871,3.330,0.001
17.80,49.100,0.06884,3.334,0.001
17.85,49.200,0.06896,3.343,0.001
17.86,49.300,0.06913,3.345,0.001
17.89,49.400,0.06925,3.352,0.001
17.93,49.500,0.06942,3.359,0.001
17.96,49.600,0.06954,3.364,0.001
18.01,49.700,0.06971,3.375,0.001
18.05,49.800,0.06983,3.382,0.001
18.07,49.900,0.07000,3.386,0.001
18.12,50.000,0.07012,3.394,0.001
18.14,50.100,0.07029,3.398,0.001
18.19,50.200,0.07046,3.408,0.001
18.22,50.300,0.07058,3.413,0.001
18.26,50.400,0.07075,3.421,0.001
18.28,50.500,0.07091,3.423,0.001
18.33,50.600,0.07104,3.434,0.001
18.36,50.700,0.07121,3.440,0.001
18.41,50.800,0.07137,3.448,0.001
18.43,50.900,0.07154,3.452,0.001
18.47,51.000,0.07166,3.460,0.001
18.52,51.100,0.07183,3.469,0.001
18.56,51.200,0.07199,3.478,0.001
18.60,51.300,0.07216,3.485,0.001
18.65,51.400,0.07233,3.494,0.001
18.70,51.500,0.07249,3.503,0.001
18.74,51.600,0.07266,3.511,0.001
18.78,51.700,0.07287,3.518,0.001
18.83,51.800,0.07303,3.527,0.001
18.88,51.900,0.07324,3.536,0.001
18.93,52.000,0.07345,3.547,0.001
18.98,52.100,0.07366,3.556,0.001
19.04,52.200,0.07386,3.567,0.001
19.10,52.300,0.07407,3.577,0.001
19.16,52.400,0.07428,3.589,0.001
19.19,52.500,0.07449,3.595,0.001
19.26,52.600,0.07470,3.608,0.001
19.29,52.700,0.07490,3.614,0.001
19.34,52.800,0.07507,3.623,0.001
19.40,52.900,0.07528,3.633,0.001
19.46,53.000,0.07544,3.645,0.001
19.49,53.100,0.07565,3.651,0.001
19.54,53.200,0.07582,3.660,0.001
19.57,53.300,0.07603,3.666,0.001
19.63,53.400,0.07619,3.677,0.001
19.65,53.500,0.07636,3.681,0.002
19.69,53.600,0.07652,3.688,0.002
19.73,53.700,0.07665,3.696,0.002
19.77,53.800,0.07682,3.703,0.002
19.80,53.900,0.07698,3.710,0.002
19.84,54.000,0.07711,3.717,0.002
19.86,54.100,0.07727,3.721,0.002
19.90,54.200,0.07740,3.728,0.002
19.93,54.300,0.07752,3.734,0.002
19.97,54.400,0.07769,3.742,0.002
20.00,54.500,0.07781,3.746,0.002
20.03,54.600,0.07794,3.751,0.002
20.06,54.700,0.07806,3.757,0.002
20.10,54.800,0.07823,3.765,0.002
20.15,54.900,0.07835,3.774,0.002
20.17,55.000,0.07848,3.779,0.002
20.20,55.100,0.07864,3.785,0.002
20.24,55.200,0.07877,3.791,0.002
20.26,55.300,0.07889,3.796,0.002
20.30,55.400,0.07906,3.803,0.002
20.34,55.500,0.07918,3.810,0.002
20.38,55.600,0.07935,3.818,0.002
20.42,55.700,0.07947,3.826,0.002
20.45,55.800,0.07964,3.831,0.002
20.50,55.900,0.07981,3.841,0.002
20.53,56.000,0.07993,3.846,0.002
20.59,56.100,0.08010,3.857,0.002
20.62,56.200,0.08026,3.863,0.002
20.67,56.300,0.08039,3.872,0.002
20.69,56.400,0.08056,3.876,0.002
20.74,56.500,0.08072,3.884,0.002
20.78,56.600,0.08085,3.892,0.002
20.82,56.700,0.08101,3.901,0.002
20.85,56.800,0.08118,3.905,0.002
20.91,56.900,0.08134,3.917,0.002
20.94,57.000,0.08147,3.923,0.002
20.98,57.100,0.08164,3.931,0.002
21.01,57.200,0.08180,3.937,0.002
21.08,57.300,0.08201,3.949,0.002
21.14,57.400,0.08218,3.960,0.002
21.19,57.500,0.08238,3.970,0.002
21.24,57.600,0.08255,3.979,0.002
21.32,57.700,0.08276,3.993,0.002
21.38,57.800,0.08297,4.004,0.002
21.43,57.900,0.08317,4.014,0.002
21.50,58.000,0.08342,4.027,0.002
21.56,58.100,0.08363,4.040,0.002
21.60,58.200,0.08384,4.046,0.002
21.67,58.300,0.08405,4.059,0.002
21.72,58.400,0.08425,4.069,0.002
21.80,58.500,0.08446,4.084,0.002
21.83,58.600,0.08467,4.089,0.002
21.89,58.700,0.08488,4.100,0.002
21.93,58.800,0.08504,4.109,0.002
21.97,58.900,0.08525,4.115,0.002
22.00,59.000,0.08542,4.121,0.002
22.06,59.100,0.08558,4.132,0.002
22.09,59.200,0.08575,4.137,0.002
22.12,59.300,0.08592,4.144,0.002
22.16,59.400,0.08608,4.152,0.002
22.20,59.500,0.08621,4.159,0.002
22.21,59.600,0.08637,4.161,0.002
22.27,59.700,0.08650,4.172,0.002
22.28,59.800,0.08666,4.174,0.002
22.31,59.900,0.08679,4.180,0.002
22.35,60.000,0.08695,4.186,0.002
22.38,60.100,0.08708,4.192,0.002
22.41,60.200,0.08720,4.197,0.002
22.45,60.300,0.08733,4.205,0.002
22.47,60.400,0.08750,4.209,0.002
22.51,60.500,0.08762,4.217,0.002
22.53,60.600,0.08774,4.221,0.002
22.57,60.700,0.08787,4.228,0.002
22.61,60.800,0.08804,4.236,0.002
22.66,60.900,0.08816,4.245,0.002
22.70,61.000,0.08833,4.252,0.002
22.72,61.100,0.08845,4.257,0.002
22.76,61.200,0.08862,4.264,0.002
22.81,61.300,0.08874,4.272,0.002
22.85,61.400,0.08891,4.281,0.002
22.89,61.500,0.08907,4.287,0.002
22.92,61.600,0.08924,4.294,0.002
22.97,61.700,0.08937,4.302,0.002
23.00,61.800,0.08953,4.309,0.002
23.05,61.900,0.08966,4.317,0.002
23.10,62.000,0.08982,4.327,0.002
23.13,62.100,0.08999,4.333,0.002
23.18,62.200,0.09015,4.342,0.002
23.21,62.300,0.09032,4.347,0.002
23.25,62.400,0.09049,4.355,0.002
23.29,62.500,0.09065,4.364,0.002
23.34,62.600,0.09082,4.372,0.002
23.40,62.700,0.09099,4.384,0.002
23.44,62.800,0.09115,4.391,0.002
23.50,62.900,0.09132,4.402,0.002
23.55,63.000,0.09153,4.411,0.002
23.60,63.100,0.09169,4.421,0.002
23.67,63.200,0.09190,4.435,0.002
23.71,63.300,0.09211,4.442,0.002
23.78,63.400,0.09232,4.455,0.002
23.85,63.500,0.09252,4.468,0.002
23.91,63.600,0.09277,4.479,0.002
23.96,63.700,0.09298,4.489,0.002
24.04,63.800,0.09319,4.504,0.002
18.52,63.900,0.09344,3.469,0.002
14.48,64.000,0.09365,2.712,0.002
14.37,64.100,0.09385,2.691,0.002
14.44,64.200,0.09406,2.705,0.002
14.51,64.300,0.09427,2.719,0.002
14.58,64.400,0.09443,2.732,0.002
14.66,64.500,0.09464,2.746,0.002
14.72,64.600,0.09481,2.758,0.002
14.78,64.700,0.09498,2.768,0.002
14.84,64.800,0.09514,2.780,0.002
14.89,64.900,0.09531,2.788,0.002
14.95,65.000,0.09547,2.800,0.002
14.99,65.100,0.09564,2.808,0.002
15.04,65.200,0.09581,2.818,0.002
15.08,65.300,0.09597,2.826,0.002
15.14,65.400,0.09610,2.836,0.002
15.17,65.500,0.09626,2.841,0.002
15.22,65.600,0.09639,2.850,0.002
15.24,65.700,0.09651,2.855,0.002
15.28,65.800,0.09668,2.862,0.002
15.31,65.900,0.09680,2.868,0.002
15.35,66.000,0.09693,2.875,0.002
15.39,66.100,0.09709,2.882,0.002
15.43,66.200,0.09722,2.890,0.002
15.47,66.300,0.09739,2.898,0.002
15.51,66.400,0.09751,2.906,0.002
15.54,66.500,0.09763,2.910,0.002
15.59,66.600,0.09780,2.921,0.002
15.62,66.700,0.09797,2.927,0.002
15.65,66.800,0.09809,2.933,0.002
15.70,66.900,0.09826,2.941,0.002
15.75,67.000,0.09838,2.950,0.002
15.77,67.100,0.09855,2.954,0.002
15.83,67.200,0.09872,2.965,0.002
15.85,67.300,0.09884,2.970,0.002
15.90,67.400,0.09901,2.978,0.002
15.93,67.500,0.09917,2.983,0.002
15.97,67.600,0.09934,2.992,0.002
16.02,67.700,0.09946,3.000,0.002
16.04,67.800,0.09963,3.005,0.002
16.08,67.900,0.09980,3.013,0.002
16.12,68.000,0.09996,3.019,0.002
16.17,68.100,0.10013,3.029,0.002
16.19,68.200,0.10029,3.032,0.002
16.24,68.300,0.10046,3.042,0.002
16.29,68.400,0.10063,3.052,0.002
16.34,68.500,0.10083,3.060,0.002
16.38,68.600,0.10100,3.068,0.002
16.43,68.700,0.10121,3.079,0.002
16.47,68.800,0.10137,3.085,0.002
16.52,68.900,0.10158,3.094,0.002
16.56,69.000,0.10179,3.102,0.002
16.61,69.100,0.10200,3.111,0.002
16.65,69.200,0.10221,3.119,0.002
16.69,69.300,0.10241,3.127,0.002
16.76,69.400,0.10262,3.139,0.002
16.79,69.500,0.10283,3.146,0.002
16.83,69.600,0.10304,3.153,0.002
16.87,69.700,0.10324,3.160,0.002
16.92,69.800,0.10345,3.169,0.002
16.94,69.900,0.10362,3.172,0.002
16.97,70.000,0.10383,3.179,0.002
17.01,70.100,0.10403,3.187,0.002
17.03,70.200,0.10420,3.191,0.002
17.08,70.300,0.10437,3.200,0.002
17.12,70.400,0.10453,3.207,0.002
17.12,70.500,0.10474,3.207,0.002
17.16,70.600,0.10487,3.214,0.002
17.18,70.700,0.10503,3.218,0.002
17.23,70.800,0.10520,3.227,0.002
17.25,70.900,0.10536,3.231,0.002
17.28,71.000,0.10549,3.237,0.002
17.31,71.100,0.10566,3.243,0.002
17.34,71.200,0.10578,3.249,0.002
17.34,71.300,0.10595,3.249,0.002
17.39,71.400,0.10607,3.257,0.002
17.42,71.500,0.10620,3.264,0.002
17.44,71.600,0.10636,3.266,0.002
17.47,71.700,0.10649,3.273,0.002
17.49,71.800,0.10661,3.276,0.002
17.53,71.900,0.10678,3.283,0.002
17.56,72.000,0.10690,3.289,0.002
17.59,72.100,0.10707,3.295,0.002
17.61,72.200,0.10719,3.299,0.002
17.66,72.300,0.10732,3.309,0.002
17.68,72.400,0.10748,3.312,0.002
17.72,72.500,0.10765,3.319,0.002
17.76,72.600,0.10777,3.326,0.002
17.77,72.700,0.10794,3.329,0.002
17.81,72.800,0.10807,3.336,0.002
17.84,72.900,0.10823,3.341,0.002
17.86,73.000,0.10840,3.346,0.002
17.91,73.100,0.10852,3.355,0.002
17.95,73.200,0.10869,3.363,0.002
17.97,73.300,0.10885,3.367,0.002
18.00,73.400,0.10898,3.371,0.002
18.04,73.500,0.10915,3.380,0.002
18.06,73.600,0.10931,3.383,0.002
18.10,73.700,0.10944,3.390,0.002
18.13,73.800,0.10960,3.396,0.002
18.16,73.900,0.10977,3.402,0.002
18.20,74.000,0.10994,3.409,0.002
18.24,74.100,0.11010,3.418,0.002
18.28,74.200,0.11027,3.424,0.002
18.32,74.300,0.11043,3.431,0.002
18.36,74.400,0.11064,3.439,0.002
18.41,74.500,0.11081,3.448,0.002
18.45,74.600,0.11102,3.456,0.002
18.50,74.700,0.11122,3.466,0.002
18.55,74.800,0.11143,3.474,0.002
18.60,74.900,0.11168,3.484,0.002
18.63,75.000,0.11189,3.490,0.002
18.70,75.100,0.11210,3.502,0.002
18.74,75.200,0.11230,3.510,0.002
18.80,75.300,0.11251,3.522,0.002
18.83,75.400,0.11272,3.526,0.002
18.88,75.500,0.11293,3.538,0.002
18.93,75.600,0.11314,3.545,0.002
18.96,75.700,0.11334,3.551,0.002
18.98,75.800,0.11351,3.555,0.002
19.03,75.900,0.11372,3.565,0.002
19.06,76.000,0.11388,3.571,0.002
19.08,76.100,0.11405,3.575,0.002
19.11,76.200,0.11422,3.579,0.002
19.17,76.300,0.11438,3.591,0.002
19.18,76.400,0.11451,3.593,0.002
19.19,76.500,0.11467,3.594,0.002
19.22,76.600,0.11480,3.601,0.002
19.25,76.700,0.11496,3.607,0.002
19.26,76.800,0.11509,3.607,0.002
19.29,76.900,0.11521,3.614,0.002
19.32,77.000,0.11538,3.619,0.002
19.35,77.100,0.11550,3.624,0.002
19.35,77.200,0.11563,3.625,0.002
19.38,77.300,0.11575,3.630,0.002
19.42,77.400,0.11592,3.637,0.002
19.45,77.500,0.11604,3.643,0.002
19.46,77.600,0.11617,3.645,0.002
19.50,77.700,0.11629,3.654,0.002
19.53,77.800,0.11646,3.659,0.002
19.55,77.900,0.11658,3.662,0.002
19.57,78.000,0.11671,3.667,0.002
19.62,78.100,0.11688,3.676,0.002
19.65,78.200,0.11704,3.681,0.002
19.69,78.300,0.11717,3.688,0.002
19.72,78.400,0.11733,3.694,0.002
19.75,78.500,0.11746,3.700,0.002
19.77,78.600,0.11762,3.704,0.002
19.80,78.700,0.11775,3.709,0.002
19.83,78.800,0.11791,3.715,0.002
19.86,78.900,0.11808,3.721,0.002
19.90,79.000,0.11820,3.727,0.002
19.93,79.100,0.11837,3.733,0.002
19.95,79.200,0.11854,3.737,0.002
19.98,79.300,0.11866,3.743,0.002
20.02,79.400,0.11883,3.751,0.002
20.05,79.500,0.11899,3.756,0.002
20.10,79.600,0.11916,3.765,0.002
20.11,79.700,0.11933,3.766,0.002
20.16,79.800,0.11949,3.777,0.002
20.21,79.900,0.11970,3.785,0.002
20.24,80.000,0.11987,3.791,0.002
20.28,80.100,0.12003,3.798,0.002
20.32,80.200,0.12024,3.807,0.002
20.37,80.300,0.12045,3.815,0.002
20.41,80.400,0.12062,3.824,0.002
20.45,80.500,0.12082,3.832,0.002
20.50,80.600,0.12103,3.840,0.002
20.55,80.700,0.12124,3.850,0.002
20.61,80.800,0.12149,3.860,0.002
20.66,80.900,0.12170,3.871,0.002
20.69,81.000,0.12190,3.876,0.002
20.73,81.100,0.12211,3.884,0.002
20.78,81.200,0.12232,3.893,0.002
20.81,81.300,0.12253,3.898,0.002
20.86,81.400,0.12269,3.907,0.002
20.88,81.500,0.12290,3.912,0.002
20.93,81.600,0.12307,3.920,0.002
20.95,81.700,0.12323,3.924,0.002
21.00,81.800,0.12340,3.933,0.002
21.01,81.900,0.12357,3.935,0.002
21.04,82.000,0.12373,3.941,0.002
21.06,82.100,0.12390,3.946,0.002
21.08,82.200,0.12406,3.949,0.002
21.11,82.300,0.12419,3.955,0.002
21.15,82.400,0.12436,3.961,0.002
21.15,82.500,0.12448,3.962,0.002
21.18,82.600,0.12465,3.967,0.002
21.20,82.700,0.12477,3.970,0.002
21.23,82.800,0.12490,3.976,0.002
21.26,82.900,0.12506,3.983,0.002
21.28,83.000,0.12519,3.985,0.002
21.31,83.100,0.12531,3.991,0.002
21.33,83.200,0.12544,3.997,0.002
21.36,83.300,0.12556,4.001,0.002
21.38,83.400,0.12573,4.005,0.002
21.40,83.500,0.12585,4.009,0.002
21.43,83.600,0.12602,4.015,0.002
21.45,83.700,0.12614,4.018,0.002
21.48,83.800,0.12631,4.023,0.002
21.52,83.900,0.12643,4.031,0.002
21.54,84.000,0.12660,4.036,0.002
21.57,84.100,0.12672,4.041,0.002
21.61,84.200,0.12689,4.049,0.002
21.64,84.300,0.12701,4.054,0.003
21.68,84.400,0.12718,4.062,0.003
21.71,84.500,0.12735,4.067,0.003
21.74,84.600,0.12747,4.073,0.003
21.77,84.700,0.12764,4.078,0.003
11.48,84.800,0.12780,2.150,0.003
12.24,84.900,0.12793,2.293,0.003
12.35,85.000,0.12810,2.314,0.003
12.40,85.100,0.12826,2.323,0.003
12.47,85.200,0.12839,2.335,0.003
12.51,85.300,0.12855,2.344,0.003
12.59,85.400,0.12872,2.358,0.003
12.62,85.500,0.12888,2.363,0.003
12.67,85.600,0.12905,2.374,0.003
12.72,85.700,0.12922,2.382,0.003
12.79,85.800,0.12942,2.395,0.003
12.84,85.900,0.12959,2.405,0.003
12.89,86.000,0.12980,2.414,0.003
12.95,86.100,0.12997,2.426,0.003
13.00,86.200,0.13017,2.435,0.003
13.05,86.300,0.13038,2.444,0.003
13.12,86.400,0.13059,2.457,0.003
13.17,86.500,0.13080,2.467,0.003
13.22,86.600,0.13100,2.476,0.003
13.27,86.700,0.13121,2.486,0.003
13.31,86.800,0.13142,2.494,0.003
13.37,86.900,0.13163,2.504,0.003
13.39,87.000,0.13184,2.508,0.003
13.45,87.100,0.13200,2.520,0.003
13.49,87.200,0.13221,2.527,0.003
13.51,87.300,0.13238,2.531,0.003
13.56,87.400,0.13258,2.541,0.003
13.60,87.500,0.13275,2.548,0.003
13.62,87.600,0.13292,2.552,0.003
13.66,87.700,0.13308,2.559,0.003
13.68,87.800,0.13321,2.563,0.003
13.69,87.810,0.13325,2.564,0.003