File: data-files/CWRU/1000-05-35C.txt
""
"Test Method","Will_Huddleston_Disks.msm"
"Sample I. D.","1000-5-35C.mss"
"Specimen Number","1"

"Load (N)","Time (s)","Extension (mm)","Stress (MPa)","Strain (mm/mm)"

3.52,0.200,-0.03438,0.662,-0.001
3.55,0.300,-0.03438,0.666,-0.001
3.51,0.400,-0.03434,0.660,-0.001
3.56,0.500,-0.03434,0.669,-0.001
3.54,0.600,-0.03434,0.665,-0.001
3.55,0.700,-0.03430,0.667,-0.001
3.52,0.800,-0.03430,0.661,-0.001
3.55,0.900,-0.03430,0.667,-0.001
3.54,1.000,-0.03426,0.664,-0.001
3.55,1.100,-0.03426,0.667,-0.001
3.53,1.200,-0.03426,0.663,-0.001
3.56,1.300,-0.03422,0.669,-0.001
3.54,1.400,-0.03422,0.665,-0.001
3.55,1.500,-0.03418,0.667,-0.001
3.54,1.600,-0.03418,0.666,-0.001
3.56,1.700,-0.03414,0.670,-0.001
3.56,1.800,-0.03414,0.670,-0.001
3.59,1.900,-0.03409,0.674,-0.001
3.59,2.000,-0.03405,0.675,-0.001
3.63,2.100,-0.03401,0.682,-0.001
3.68,2.200,-0.03393,0.691,-0.001
3.78,2.300,-0.03380,0.711,-0.001
3.87,2.400,-0.03364,0.728,-0.001
3.96,2.500,-0.03347,0.744,-0.001
4.02,2.600,-0.03330,0.755,-0.001
4.08,2.700,-0.03310,0.767,-0.001
4.12,2.800,-0.03293,0.775,-0.001
4.17,2.900,-0.03276,0.784,-0.001
4.20,3.000,-0.03260,0.790,-0.001
4.28,3.100,-0.03243,0.804,-0.001
4.33,3.200,-0.03222,0.813,-0.001
4.37,3.300,-0.03202,0.821,-0.001
4.42,3.400,-0.03181,0.830,-0.001
4.48,3.500,-0.03164,0.841,-0.001
4.51,3.600,-0.03143,0.847,-0.001
4.55,3.700,-0.03123,0.856,-0.001
4.60,3.800,-0.03102,0.865,-0.001
4.64,3.900,-0.03081,0.871,-0.001
4.68,4.000,-0.03060,0.879,-0.001
4.71,4.100,-0.03044,0.886,-0.001
4.74,4.200,-0.03023,0.891,-0.001
4.78,4.300,-0.03006,0.899,-0.001
4.83,4.400,-0.02985,0.907,-0.001
4.86,4.500,-0.02969,0.913,-0.001
4.88,4.600,-0.02952,0.917,-0.001
4.91,4.700,-0.02936,0.923,-0.001
4.93,4.800,-0.02919,0.927,-0.001
4.97,4.900,-0.02902,0.933,-0.001
4.98,5.000,-0.02890,0.936,-0.001
4.99,5.100,-0.02873,0.938,-0.001
5.02,5.200,-0.02861,0.942,-0.001
5.04,5.300,-0.02844,0.947,-0.001
5.07,5.400,-0.02832,0.952,-0.001
5.08,5.500,-0.02815,0.955,-0.001
5.10,5.600,-0.02803,0.959,-0.001
5.13,5.700,-0.02790,0.964,-0.001
5.15,5.800,-0.02778,0.967,-0.001
5.16,5.900,-0.02761,0.969,-0.001
5.19,6.000,-0.02749,0.974,-0.001
5.23,6.100,-0.02736,0.983,-0.001
5.22,6.200,-0.02720,0.982,-0.001
5.25,6.300,-0.02707,0.986,-0.001
5.28,6.400,-0.02695,0.993,-0.001
5.31,6.500,-0.02678,0.998,-0.001
5.33,6.600,-0.02661,1.002,-0.001
5.36,6.700,-0.02649,1.007,-0.001
5.38,6.800,-0.02632,1.010,-0.001
5.41,6.900,-0.02620,1.017,-0.001
5.43,7.000,-0.02603,1.020,-0.001
5.46,7.100,-0.02587,1.027,-0.001
5.49,7.200,-0.02574,1.031,-0.001
5.50,7.300,-0.02557,1.034,-0.001
5.53,7.400,-0.02541,1.039,-0.001
5.58,7.500,-0.02524,1.048,0.000
5.60,7.600,-0.02512,1.051,0.000
5.61,7.700,-0.02495,1.055,0.000
5.64,7.800,-0.02479,1.060,0.000
5.67,7.900,-0.02466,1.066,0.000
5.68,8.000,-0.02449,1.067,0.000
5.71,8.100,-0.02433,1.073,0.000
5.75,8.200,-0.02416,1.080,0.000
5.76,8.300,-0.02400,1.083,0.000
5.79,8.400,-0.02379,1.087,0.000
5.82,8.500,-0.02362,1.093,0.000
5.84,8.600,-0.02346,1.098,0.000
5.88,8.700,-0.02325,1.104,0.000
5.91,8.800,-0.02308,1.111,0.000
5.96,8.900,-0.02287,1.119,0.000
5.98,9.000,-0.02267,1.124,0.000
6.02,9.100,-0.02246,1.132,0.000
6.05,9.200,-0.02225,1.137,0.000
6.09,9.300,-0.02204,1.145,0.000
6.13,9.400,-0.02183,1.151,0.000
6.16,9.500,-0.02163,1.157,0.000
6.19,9.600,-0.02142,1.163,0.000
6.22,9.700,-0.02121,1.169,0.000
6.25,9.800,-0.02100,1.174,0.000
6.27,9.900,-0.02080,1.179,0.000
6.31,10.000,-0.02063,1.186,0.000
6.35,10.100,-0.02042,1.193,0.000
6.35,10.200,-0.02026,1.194,0.000
6.38,10.300,-0.02005,1.199,0.000
6.40,10.400,-0.01988,1.203,0.000
6.44,10.500,-0.01972,1.211,0.000
6.46,10.600,-0.01955,1.213,0.000
6.48,10.700,-0.01942,1.218,0.000
6.50,10.800,-0.01926,1.221,0.000
6.52,10.900,-0.01909,1.225,0.000
6.54,11.000,-0.01897,1.229,0.000
6.56,11.100,-0.01884,1.232,0.000
6.58,11.200,-0.01868,1.237,0.000
6.59,11.300,-0.01855,1.239,0.000
6.62,11.400,-0.01839,1.245,0.000
6.63,11.500,-0.01826,1.246,0.000
6.64,11.600,-0.01814,1.248,0.000
6.67,11.700,-0.01797,1.253,0.000
6.69,11.800,-0.01785,1.258,0.000
6.71,11.900,-0.01772,1.260,0.000
6.72,12.000,-0.01755,1.263,0.000
6.76,12.100,-0.01743,1.270,0.000
6.77,12.200,-0.01726,1.273,0.000
6.79,12.300,-0.01714,1.276,0.000
6.79,12.400,-0.01701,1.277,0.000
6.84,12.500,-0.01685,1.286,0.000
6.85,12.600,-0.01672,1.287,0.000
6.87,12.700,-0.01656,1.291,0.000
6.89,12.800,-0.01639,1.294,0.000
6.93,12.900,-0.01627,1.301,0.000
6.94,13.000,-0.01610,1.305,0.000
6.98,13.100,-0.01598,1.312,0.000
7.01,13.200,-0.01581,1.317,0.000
7.02,13.300,-0.01564,1.319,0.000
7.05,13.400,-0.01548,1.325,0.000
7.08,13.500,-0.01535,1.331,0.000
7.10,13.600,-0.01519,1.335,0.000
7.13,13.700,-0.01502,1.340,0.000
7.17,13.800,-0.01485,1.347,0.000
7.19,13.900,-0.01469,1.351,0.000
7.23,14.000,-0.01452,1.358,0.000
7.22,14.100,-0.01435,1.357,0.000
7.26,14.200,-0.01419,1.365,0.000
7.29,14.300,-0.01398,1.369,0.000
7.33,14.400,-0.01377,1.377,0.000
7.36,14.500,-0.01361,1.383,0.000
7.40,14.600,-0.01340,1.391,0.000
7.43,14.700,-0.01319,1.397,0.000
7.47,14.800,-0.01298,1.404,0.000
7.51,14.900,-0.01278,1.411,0.000
7.55,15.000,-0.01257,1.419,0.000
7.56,15.100,-0.01236,1.421,0.000
7.61,15.200,-0.01211,1.430,0.000
7.65,15.300,-0.01190,1.437,0.000
7.67,15.400,-0.01170,1.441,0.000
7.70,15.500,-0.01149,1.447,0.000
7.74,15.600,-0.01132,1.455,0.000
7.75,15.700,-0.01111,1.457,0.000
7.78,15.800,-0.01091,1.462,0.000
7.80,15.900,-0.01074,1.467,0.000
7.83,16.000,-0.01057,1.471,0.000
7.84,16.100,-0.01037,1.473,0.000
7.85,16.200,-0.01024,1.475,0.000
7.89,16.300,-0.01007,1.482,0.000
7.91,16.400,-0.00991,1.486,0.000
7.91,16.500,-0.00974,1.486,0.000
7.94,16.600,-0.00962,1.492,0.000
7.95,16.700,-0.00945,1.494,0.000
7.97,16.800,-0.00933,1.497,0.000
7.99,16.900,-0.00920,1.501,0.000
8.00,17.000,-0.00904,1.503,0.000
8.02,17.100,-0.00891,1.507,0.000
8.05,17.200,-0.00879,1.513,0.000
8.05,17.300,-0.00866,1.513,0.000
8.07,17.400,-0.00850,1.517,0.000
8.10,17.500,-0.00837,1.522,0.000
8.12,17.600,-0.00825,1.525,0.000
8.15,17.700,-0.00812,1.531,0.000
8.16,17.800,-0.00796,1.533,0.000
8.18,17.900,-0.00783,1.538,0.000
8.21,18.000,-0.00766,1.543,0.000
8.22,18.100,-0.00754,1.546,0.000
8.26,18.200,-0.00737,1.551,0.000
8.27,18.300,-0.00725,1.555,0.000
8.29,18.400,-0.00708,1.558,0.000
8.34,18.500,-0.00692,1.567,0.000
8.37,18.600,-0.00679,1.573,0.000
8.39,18.700,-0.00663,1.576,0.000
8.44,18.800,-0.00646,1.585,0.000
8.43,18.900,-0.00633,1.583,0.000
8.46,19.000,-0.00617,1.590,0.000
8.48,19.100,-0.00600,1.594,0.000
8.52,19.200,-0.00584,1.601,0.000
8.52,19.300,-0.00571,1.602,0.000
8.55,19.400,-0.00554,1.606,0.000
8.59,19.500,-0.00538,1.614,0.000
8.60,19.600,-0.00521,1.616,0.000
8.64,19.700,-0.00505,1.623,0.000
8.67,19.800,-0.00488,1.629,0.000
8.71,19.900,-0.00471,1.636,0.000
8.73,20.000,-0.00451,1.641,0.000
8.77,20.100,-0.00434,1.647,0.000
8.79,20.200,-0.00413,1.652,0.000
8.82,20.300,-0.00392,1.657,0.000
8.87,20.400,-0.00372,1.666,0.000
8.90,20.500,-0.00351,1.673,0.000
8.95,20.600,-0.00330,1.682,0.000
8.99,20.700,-0.00309,1.688,0.000
9.00,20.800,-0.00289,1.692,0.000
9.05,20.900,-0.00268,1.700,0.000
9.06,21.000,-0.00247,1.703,0.000
9.10,21.100,-0.00226,1.710,0.000
9.13,21.200,-0.00210,1.715,0.000
9.17,21.300,-0.00189,1.723,0.000
9.19,21.400,-0.00168,1.726,0.000
9.24,21.500,-0.00151,1.736,0.000
9.26,21.600,-0.00131,1.739,0.000
9.29,21.700,-0.00114,1.746,0.000
9.31,21.800,-0.00097,1.749,0.000
9.32,21.900,-0.00081,1.752,0.000
9.34,22.000,-0.00064,1.756,0.000
9.38,22.100,-0.00047,1.762,0.000
9.39,22.200,-0.00031,1.765,0.000
9.41,22.300,-0.00018,1.768,0.000
9.42,22.400,-0.00002,1.771,0.000
9.45,22.500,0.00011,1.776,0.000
9.46,22.600,0.00023,1.777,0.000
9.49,22.700,0.00040,1.783,0.000
9.51,22.800,0.00052,1.787,0.000
9.53,22.900,0.00065,1.791,0.000
9.56,23.000,0.00081,1.796,0.000
9.58,23.100,0.00094,1.801,0.000
9.60,23.200,0.00106,1.803,0.000
9.62,23.300,0.00119,1.809,0.000
9.64,23.400,0.00135,1.811,0.000
9.67,23.500,0.00148,1.816,0.000
9.69,23.600,0.00160,1.820,0.000
9.72,23.700,0.00177,1.826,0.000
9.73,23.800,0.00189,1.828,0.000
9.77,23.900,0.00206,1.836,0.000
9.78,24.000,0.00223,1.838,0.000
9.82,24.100,0.00235,1.845,0.000
9.84,24.200,0.00252,1.850,0.000
9.87,24.300,0.00264,1.855,0.000
9.90,24.400,0.00281,1.861,0.000
9.92,24.500,0.00297,1.863,0.000
9.95,24.600,0.00314,1.870,0.000
9.99,24.700,0.00327,1.877,0.000
10.00,24.800,0.00343,1.879,0.000
10.02,24.900,0.00360,1.884,0.000
10.04,25.000,0.00372,1.886,0.000
10.08,25.100,0.00389,1.895,0.000
10.10,25.200,0.00405,1.898,0.000
10.14,25.300,0.00422,1.905,0.000
10.15,25.400,0.00439,1.908,0.000
10.20,25.500,0.00455,1.918,0.000
10.23,25.600,0.00472,1.923,0.000
10.26,25.700,0.00493,1.929,0.000
10.31,25.800,0.00509,1.936,0.000
10.34,25.900,0.00530,1.943,0.000
10.36,26.000,0.00551,1.947,0.000
10.40,26.100,0.00572,1.954,0.000
10.44,26.200,0.00592,1.963,0.000
10.49,26.300,0.00613,1.971,0.000
10.53,26.400,0.00634,1.979,0.000
10.56,26.500,0.00655,1.984,0.000
10.61,26.600,0.00676,1.994,0.000
10.64,26.700,0.00696,2.000,0.000
10.67,26.800,0.00717,2.006,0.000
10.71,26.900,0.00734,2.012,0.000
10.74,27.000,0.00755,2.017,0.000
10.75,27.100,0.00775,2.021,0.000
10.79,27.200,0.00792,2.027,0.000
10.82,27.300,0.00809,2.033,0.000
10.84,27.400,0.00829,2.037,0.000
10.89,27.500,0.00846,2.046,0.000
10.91,27.600,0.00863,2.050,0.000
10.93,27.700,0.00879,2.053,0.000
10.94,27.800,0.00892,2.056,0.000
10.98,27.900,0.00908,2.063,0.000
11.00,28.000,0.00925,2.067,0.000
11.02,28.100,0.00937,2.071,0.000
11.03,28.200,0.00954,2.073,0.000
11.06,28.300,0.00966,2.078,0.000
11.08,28.400,0.00979,2.082,0.000
11.11,28.500,0.00996,2.087,0.000
11.12,28.600,0.01008,2.090,0.000
11.14,28.700,0.01020,2.094,0.000
11.16,28.800,0.01033,2.097,0.000
11.18,28.900,0.01050,2.100,0.000
11.21,29.000,0.01062,2.106,0.000
11.22,29.100,0.01075,2.108,0.000
11.25,29.200,0.01091,2.114,0.000
11.27,29.300,0.01104,2.118,0.000
11.30,29.400,0.01116,2.123,0.000
11.31,29.500,0.01133,2.126,0.000
11.34,29.600,0.01145,2.130,0.000
11.38,29.700,0.01162,2.138,0.000
11.40,29.800,0.01174,2.142,0.000
11.42,29.900,0.01191,2.145,0.000
11.45,30.000,0.01207,2.152,0.000
11.46,30.100,0.01220,2.154,0.000
11.50,30.200,0.01237,2.162,0.000
11.54,30.300,0.01253,2.168,0.000
11.57,30.400,0.01266,2.174,0.000
11.59,30.500,0.01282,2.177,0.000
11.61,30.600,0.01299,2.182,0.000
11.66,30.700,0.01311,2.190,0.000
11.67,30.800,0.01328,2.193,0.000
11.70,30.900,0.01345,2.199,0.000
11.73,31.000,0.01361,2.204,0.000
11.78,31.100,0.01378,2.213,0.000
11.81,31.200,0.01394,2.219,0.000
11.84,31.300,0.01411,2.224,0.000
11.87,31.400,0.01428,2.230,0.000
11.91,31.500,0.01449,2.238,0.000
11.95,31.600,0.01469,2.246,0.000
11.99,31.700,0.01486,2.254,0.000
12.04,31.800,0.01507,2.262,0.000
12.08,31.900,0.01532,2.270,0.000
12.14,32.000,0.01552,2.281,0.000
12.17,32.100,0.01573,2.287,0.000
12.23,32.200,0.01594,2.299,0.000
12.25,32.300,0.01615,2.302,0.000
12.30,32.400,0.01636,2.311,0.000
12.32,32.500,0.01656,2.315,0.000
12.36,32.600,0.01677,2.322,0.000
12.38,32.700,0.01698,2.326,0.000
12.45,32.800,0.01719,2.339,0.000
12.46,32.900,0.01735,2.342,0.000
12.50,33.000,0.01752,2.348,0.000
12.52,33.100,0.01773,2.353,0.000
12.54,33.200,0.01789,2.356,0.000
12.56,33.300,0.01806,2.359,0.000
12.59,33.400,0.01818,2.366,0.000
12.59,33.500,0.01835,2.366,0.000
12.63,33.600,0.01852,2.373,0.000
12.63,33.700,0.01864,2.374,0.000
12.66,33.800,0.01881,2.380,0.000
12.69,33.900,0.01893,2.385,0.000
12.70,34.000,0.01906,2.386,0.000
12.72,34.100,0.01922,2.391,0.000
12.76,34.200,0.01935,2.397,0.000
12.77,34.300,0.01947,2.400,0.000
12.80,34.400,0.01964,2.405,0.000
12.81,34.500,0.01976,2.408,0.000
12.84,34.600,0.01989,2.412,0.000
12.85,34.700,0.02005,2.415,0.000
12.89,34.800,0.02018,2.421,0.000
12.91,34.900,0.02030,2.426,0.000
12.94,35.000,0.02047,2.431,0.000
12.96,35.100,0.02059,2.435,0.000
12.99,35.200,0.02076,2.441,0.000
13.02,35.300,0.02088,2.446,0.000
13.04,35.400,0.02105,2.450,0.000
13.07,35.500,0.02122,2.457,0.000
13.10,35.600,0.02134,2.462,0.000
13.14,35.700,0.02151,2.469,0.000
13.18,35.800,0.02167,2.476,0.000
13.20,35.900,0.02180,2.481,0.000
13.24,36.000,0.02197,2.488,0.000
13.29,36.100,0.02213,2.497,0.000
13.30,36.200,0.02230,2.500,0.000
13.34,36.300,0.02246,2.507,0.000
13.36,36.400,0.02263,2.510,0.000
13.39,36.500,0.02280,2.515,0.000
13.43,36.600,0.02296,2.523,0.000
13.46,36.700,0.02313,2.530,0.000
13.49,36.800,0.02329,2.536,0.000
13.53,36.900,0.02346,2.543,0.000
13.59,37.000,0.02367,2.553,0.000
13.61,37.100,0.02384,2.558,0.000
13.65,37.200,0.02404,2.565,0.000
13.71,37.300,0.02425,2.576,0.000
13.75,37.400,0.02446,2.584,0.000
13.80,37.500,0.02467,2.594,0.000
13.85,37.600,0.02487,2.602,0.000
13.89,37.700,0.02508,2.610,0.000
13.92,37.800,0.02533,2.616,0.000
13.96,37.900,0.02554,2.623,0.001
14.01,38.000,0.02575,2.633,0.001
14.06,38.100,0.02595,2.643,0.001
14.09,38.200,0.02616,2.647,0.001
14.13,38.300,0.02637,2.654,0.001
14.16,38.400,0.02658,2.660,0.001
14.18,38.500,0.02674,2.664,0.001
14.22,38.600,0.02695,2.672,0.001
14.24,38.700,0.02712,2.676,0.001
14.26,38.800,0.02733,2.680,0.001
14.30,38.900,0.02749,2.687,0.001
14.32,39.000,0.02766,2.691,0.001
14.34,39.100,0.02778,2.694,0.001
14.37,39.200,0.02795,2.701,0.001
14.39,39.300,0.02812,2.705,0.001
14.42,39.400,0.02828,2.711,0.001
14.46,39.500,0.02841,2.717,0.001
14.48,39.600,0.02857,2.721,0.001
14.50,39.700,0.02870,2.725,0.001
14.53,39.800,0.02886,2.731,0.001
14.54,39.900,0.02899,2.733,0.001
14.57,40.000,0.02911,2.737,0.001
14.58,40.100,0.02928,2.739,0.001
14.61,40.200,0.02940,2.745,0.001
14.63,40.300,0.02953,2.749,0.001
14.68,40.400,0.02969,2.759,0.001
14.71,40.500,0.02982,2.765,0.001
14.74,40.600,0.02999,2.769,0.001
14.76,40.700,0.03011,2.774,0.001
14.80,40.800,0.03028,2.781,0.001
14.82,40.900,0.03040,2.784,0.001
14.85,41.000,0.03057,2.791,0.001
14.88,41.100,0.03073,2.796,0.001
14.92,41.200,0.03086,2.804,0.001
14.94,41.300,0.03102,2.808,0.001
14.98,41.400,0.03119,2.814,0.001
14.99,41.500,0.03136,2.816,0.001
15.03,41.600,0.03148,2.824,0.001
15.07,41.700,0.03165,2.832,0.001
15.08,41.800,0.03181,2.833,0.001
15.10,41.900,0.03198,2.838,0.001
15.16,42.000,0.03210,2.848,0.001
15.20,42.100,0.03227,2.856,0.001
15.23,42.200,0.03244,2.861,0.001
15.25,42.300,0.03260,2.866,0.001
15.29,42.400,0.03277,2.873,0.001
15.31,42.500,0.03294,2.877,0.001
15.35,42.600,0.03310,2.884,0.001
15.39,42.700,0.03331,2.892,0.001
15.44,42.800,0.03348,2.901,0.001
15.49,42.900,0.03368,2.910,0.001
15.52,43.000,0.03389,2.916,0.001
15.55,43.100,0.03410,2.922,0.001
15.61,43.200,0.03431,2.934,0.001
15.63,43.300,0.03452,2.938,0.001
15.70,43.400,0.03472,2.951,0.001
15.74,43.500,0.03493,2.957,0.001
15.78,43.600,0.03514,2.965,0.001
15.81,43.700,0.03535,2.971,0.001
15.86,43.800,0.03551,2.981,0.001
15.89,43.900,0.03572,2.986,0.001
15.91,44.000,0.03593,2.989,0.001
15.95,44.100,0.03614,2.998,0.001
15.99,44.200,0.03630,3.005,0.001
16.02,44.300,0.03647,3.009,0.001
16.05,44.400,0.03668,3.017,0.001
16.10,44.500,0.03684,3.026,0.001
16.13,44.600,0.03701,3.030,0.001
16.14,44.700,0.03713,3.033,0.001
16.16,44.800,0.03730,3.036,0.001
16.20,44.900,0.03747,3.044,0.001
16.22,45.000,0.03763,3.047,0.001
16.26,45.100,0.03776,3.055,0.001
16.28,45.200,0.03792,3.058,0.001
16.31,45.300,0.03805,3.064,0.001
16.33,45.400,0.03817,3.068,0.001
16.36,45.500,0.03834,3.073,0.001
16.37,45.600,0.03846,3.076,0.001
16.39,45.700,0.03859,3.080,0.001
16.44,45.800,0.03875,3.089,0.001
16.45,45.900,0.03888,3.091,0.001
16.48,46.000,0.03900,3.096,0.001
16.51,46.100,0.03917,3.102,0.001
16.52,46.200,0.03929,3.105,0.001
16.56,46.300,0.03942,3.112,0.001
16.59,46.400,0.03958,3.117,0.001
16.61,46.500,0.03971,3.120,0.001
16.64,46.600,0.03988,3.126,0.001
16.67,46.700,0.04000,3.132,0.001
16.70,46.800,0.04017,3.138,0.001
16.73,46.900,0.04033,3.144,0.001
16.75,47.000,0.04046,3.147,0.001
16.80,47.100,0.04062,3.157,0.001
16.82,47.200,0.04075,3.161,0.001
16.86,47.300,0.04091,3.168,0.001
16.88,47.400,0.04108,3.172,0.001
16.92,47.500,0.04125,3.179,0.001
16.96,47.600,0.04137,3.187,0.001
16.99,47.700,0.04154,3.192,0.001
17.01,47.800,0.04170,3.197,0.001
17.06,47.900,0.04187,3.205,0.001
17.08,48.000,0.04204,3.209,0.001
17.13,48.100,0.04220,3.218,0.001
17.16,48.200,0.04237,3.224,0.001
17.19,48.300,0.04254,3.229,0.001
17.24,48.400,0.04270,3.239,0.001
17.27,48.500,0.04291,3.246,0.001
17.32,48.600,0.04308,3.255,0.001
17.37,48.700,0.04328,3.264,0.001
17.42,48.800,0.04349,3.274,0.001
17.48,48.900,0.04370,3.285,0.001
17.53,49.000,0.04395,3.293,0.001
17.57,49.100,0.04416,3.302,0.001
17.62,49.200,0.04436,3.310,0.001
17.66,49.300,0.04457,3.319,0.001
17.71,49.400,0.04482,3.328,0.001
17.76,49.500,0.04503,3.337,0.001
17.79,49.600,0.04524,3.342,0.001
17.84,49.700,0.04540,3.352,0.001
17.87,49.800,0.04561,3.358,0.001
17.91,49.900,0.04582,3.366,0.001
17.94,50.000,0.04598,3.372,0.001
17.98,50.100,0.04615,3.379,0.001
18.01,50.200,0.04632,3.385,0.001
18.05,50.300,0.04648,3.391,0.001
18.08,50.400,0.04665,3.397,0.001
18.09,50.500,0.04682,3.398,0.001
18.12,50.600,0.04694,3.405,0.001
18.14,50.700,0.04711,3.408,0.001
18.17,50.800,0.04723,3.414,0.001
18.19,50.900,0.04736,3.419,0.001
18.22,51.000,0.04752,3.423,0.001
18.24,51.100,0.04765,3.428,0.001
18.25,51.200,0.04777,3.430,0.001
18.29,51.300,0.04790,3.436,0.001
18.33,51.400,0.04806,3.443,0.001
18.33,51.500,0.04819,3.445,0.001
18.38,51.600,0.04831,3.454,0.001
18.40,51.700,0.04844,3.458,0.001
18.43,51.800,0.04860,3.463,0.001
18.46,51.900,0.04873,3.469,0.001
18.49,52.000,0.04885,3.474,0.001
18.52,52.100,0.04902,3.481,0.001
18.56,52.200,0.04918,3.487,0.001
18.59,52.300,0.04931,3.493,0.001
18.63,52.400,0.04948,3.501,0.001
18.65,52.500,0.04960,3.505,0.001
18.70,52.600,0.04977,3.514,0.001
18.72,52.700,0.04993,3.517,0.001
18.75,52.800,0.05010,3.524,0.001
18.81,52.900,0.05022,3.534,0.001
18.84,53.000,0.05039,3.540,0.001
18.86,53.100,0.05056,3.545,0.001
18.90,53.200,0.05068,3.552,0.001
18.94,53.300,0.05085,3.559,0.001
18.97,53.400,0.05101,3.565,0.001
19.01,53.500,0.05118,3.572,0.001
19.05,53.600,0.05135,3.579,0.001
19.09,53.700,0.05151,3.587,0.001
19.13,53.800,0.05168,3.595,0.001
19.16,53.900,0.05184,3.601,0.001
19.22,54.000,0.05201,3.611,0.001
19.25,54.100,0.05222,3.618,0.001
19.30,54.200,0.05238,3.628,0.001
19.35,54.300,0.05259,3.636,0.001
19.42,54.400,0.05280,3.648,0.001
19.46,54.500,0.05301,3.657,0.001
19.51,54.600,0.05322,3.665,0.001
19.55,54.700,0.05342,3.673,0.001
19.63,54.800,0.05363,3.688,0.001
19.66,54.900,0.05384,3.694,0.001
19.71,55.000,0.05405,3.703,0.001
19.75,55.100,0.05425,3.712,0.001
19.81,55.200,0.05446,3.722,0.001
19.86,55.300,0.05467,3.732,0.001
19.90,55.400,0.05488,3.740,0.001
19.94,55.500,0.05509,3.747,0.001
19.97,55.600,0.05525,3.752,0.001
19.99,55.700,0.05546,3.756,0.001
20.04,55.800,0.05563,3.766,0.001
20.06,55.900,0.05579,3.769,0.001
20.10,56.000,0.05596,3.777,0.001
20.11,56.100,0.05612,3.779,0.001
20.14,56.200,0.05629,3.785,0.001
20.17,56.300,0.05641,3.790,0.001
20.20,56.400,0.05658,3.795,0.001
20.23,56.500,0.05671,3.801,0.001
20.25,56.600,0.05687,3.805,0.001
20.28,56.700,0.05700,3.811,0.001
20.31,56.800,0.05712,3.816,0.001
20.34,56.900,0.05729,3.821,0.001
20.34,57.000,0.05741,3.823,0.001
20.37,57.100,0.05754,3.829,0.001
20.41,57.200,0.05770,3.836,0.001
20.45,57.300,0.05783,3.843,0.001
20.47,57.400,0.05795,3.847,0.001
20.50,57.500,0.05812,3.853,0.001
20.52,57.600,0.05824,3.856,0.001
20.55,57.700,0.05841,3.861,0.001
20.58,57.800,0.05853,3.868,0.001
20.63,57.900,0.05870,3.877,0.001
20.67,58.000,0.05883,3.884,0.001
20.70,58.100,0.05899,3.890,0.001
20.74,58.200,0.05912,3.897,0.001
20.79,58.300,0.05928,3.906,0.001
20.80,58.400,0.05945,3.909,0.001
20.83,58.500,0.05957,3.914,0.001
20.86,58.600,0.05974,3.921,0.001
20.91,58.700,0.05991,3.929,0.001
20.94,58.800,0.06007,3.935,0.001
20.97,58.900,0.06020,3.940,0.001
21.01,59.000,0.06036,3.947,0.001
21.07,59.100,0.06053,3.960,0.001
21.09,59.200,0.06070,3.963,0.001
21.14,59.300,0.06086,3.972,0.001
21.17,59.400,0.06103,3.978,0.001
21.20,59.500,0.06119,3.984,0.001
21.24,59.600,0.06136,3.991,0.001
21.31,59.700,0.06153,4.004,0.001
21.35,59.800,0.06173,4.013,0.001
21.38,59.900,0.06190,4.017,0.001
21.46,60.000,0.06211,4.032,0.001
21.51,60.100,0.06232,4.042,0.001
21.56,60.200,0.06252,4.052,0.001
21.61,60.300,0.06273,4.061,0.001
21.67,60.400,0.06294,4.072,0.001
21.72,60.500,0.06315,4.081,0.001
21.76,60.600,0.06340,4.089,0.001
21.83,60.700,0.06360,4.102,0.001
21.87,60.800,0.06381,4.109,0.001
21.90,60.900,0.06398,4.116,0.001
21.96,61.000,0.06419,4.126,0.001
22.01,61.100,0.06439,4.135,0.001
22.05,61.200,0.06460,4.144,0.001
22.07,61.300,0.06477,4.148,0.001
22.12,61.400,0.06498,4.157,0.001
22.14,61.500,0.06514,4.161,0.001
22.19,61.600,0.06531,4.170,0.001
22.20,61.700,0.06547,4.172,0.001
22.25,61.800,0.06564,4.181,0.001
22.26,61.900,0.06577,4.183,0.001
22.30,62.000,0.06593,4.190,0.001
22.32,62.100,0.06610,4.194,0.001
22.35,62.200,0.06622,4.200,0.001
22.37,62.300,0.06639,4.204,0.001
22.40,62.400,0.06651,4.209,0.001
22.44,62.500,0.06668,4.216,0.001
22.45,62.600,0.06680,4.219,0.001
22.47,62.700,0.06693,4.223,0.001
22.50,62.800,0.06705,4.229,0.001
22.55,62.900,0.06722,4.237,0.001
22.57,63.000,0.06734,4.241,0.001
22.59,63.100,0.06747,4.245,0.001
22.62,63.200,0.06764,4.250,0.001
22.66,63.300,0.06776,4.258,0.001
22.69,63.400,0.06793,4.263,0.001
22.72,63.500,0.06805,4.269,0.001
22.74,63.600,0.06822,4.274,0.001
22.78,63.700,0.06834,4.281,0.001
22.82,63.800,0.06851,4.289,0.001
22.87,63.900,0.06863,4.298,0.001
22.92,64.000,0.06880,4.307,0.001
22.95,64.100,0.06896,4.313,0.001
22.98,64.200,0.06909,4.318,0.001
23.02,64.300,0.06926,4.326,0.001
23.05,64.400,0.06938,4.332,0.001
23.09,64.500,0.06955,4.339,0.001
23.11,64.600,0.06971,4.343,0.001
23.17,64.700,0.06988,4.354,0.001
23.21,64.800,0.07000,4.361,0.001
23.24,64.900,0.07017,4.367,0.001
23.29,65.000,0.07034,4.376,0.001
23.33,65.100,0.07050,4.384,0.001
23.38,65.200,0.07067,4.393,0.001
23.41,65.300,0.07083,4.400,0.001
23.47,65.400,0.07100,4.410,0.001
23.53,65.500,0.07121,4.421,0.001
23.56,65.600,0.07138,4.428,0.001
23.62,65.700,0.07158,4.439,0.001
23.68,65.800,0.07179,4.449,0.001
23.74,65.900,0.07200,4.461,0.001
23.77,66.000,0.07221,4.467,0.001
23.84,66.100,0.07241,4.480,0.001
23.87,66.200,0.07262,4.486,0.001
23.92,66.300,0.07283,4.494,0.001
23.97,66.400,0.07304,4.503,0.001
24.03,66.500,0.07329,4.515,0.001
24.09,66.600,0.07349,4.526,0.001
24.13,66.700,0.07366,4.534,0.001
24.18,66.800,0.07387,4.544,0.001
24.22,66.900,0.07408,4.552,0.001
24.27,67.000,0.07428,4.561,0.001
24.30,67.100,0.07445,4.566,0.001
24.33,67.200,0.07462,4.573,0.001
24.37,67.300,0.07478,4.579,0.001
24.40,67.400,0.07495,4.585,0.001
24.42,67.500,0.07512,4.589,0.001
24.45,67.600,0.07524,4.595,0.001
24.48,67.700,0.07541,4.599,0.001
24.52,67.800,0.07557,4.607,0.001
24.55,67.900,0.07570,4.612,0.001
24.58,68.000,0.07582,4.619,0.001
24.60,68.100,0.07599,4.623,0.001
24.63,68.200,0.07611,4.629,0.001
24.67,68.300,0.07624,4.635,0.002
24.69,68.400,0.07636,4.639,0.002
24.71,68.500,0.07653,4.643,0.002
24.76,68.600,0.07665,4.652,0.002
24.79,68.700,0.07678,4.659,0.002
24.82,68.800,0.07694,4.664,0.002
24.87,68.900,0.07707,4.673,0.002
24.91,69.000,0.07723,4.682,0.002
24.94,69.100,0.07736,4.687,0.002
24.98,69.200,0.07753,4.695,0.002
25.02,69.300,0.07765,4.701,0.002
25.05,69.400,0.07782,4.708,0.002
25.10,69.500,0.07798,4.717,0.002
25.15,69.600,0.07811,4.725,0.002
25.19,69.700,0.07827,4.734,0.002
25.24,69.800,0.07844,4.743,0.002
25.28,69.900,0.07856,4.751,0.002
25.33,70.000,0.07873,4.760,0.002
25.36,70.100,0.07890,4.766,0.002
25.39,70.200,0.07906,4.771,0.002
25.43,70.300,0.07923,4.778,0.002
25.47,70.400,0.07935,4.787,0.002
25.52,70.500,0.07952,4.795,0.002
25.56,70.600,0.07969,4.802,0.002
25.59,70.700,0.07985,4.809,0.002
25.65,70.800,0.08002,4.820,0.002
25.70,70.900,0.08023,4.829,0.002
25.75,71.000,0.08039,4.839,0.002
25.80,71.100,0.08056,4.848,0.002
25.86,71.200,0.08077,4.860,0.002
25.91,71.300,0.08097,4.869,0.002
25.97,71.400,0.08118,4.880,0.002
26.01,71.500,0.08139,4.888,0.002
26.10,71.600,0.08160,4.904,0.002
26.14,71.700,0.08181,4.913,0.002
26.20,71.800,0.08201,4.923,0.002
26.27,71.900,0.08222,4.936,0.002
26.32,72.000,0.08243,4.946,0.002
26.36,72.100,0.08268,4.954,0.002
26.43,72.200,0.08289,4.966,0.002
26.46,72.300,0.08309,4.973,0.002
26.53,72.400,0.08330,4.985,0.002
26.57,72.500,0.08351,4.994,0.002
26.62,72.600,0.08368,5.001,0.002
26.68,72.700,0.08388,5.013,0.002
26.71,72.800,0.08405,5.019,0.002
26.74,72.900,0.08422,5.025,0.002
26.79,73.000,0.08438,5.035,0.002
26.81,73.100,0.08455,5.038,0.002
26.85,73.200,0.08471,5.045,0.002
26.89,73.300,0.08488,5.053,0.002
26.91,73.400,0.08501,5.057,0.002
26.95,73.500,0.08517,5.065,0.002
26.99,73.600,0.08530,5.071,0.002
27.03,73.700,0.08546,5.078,0.002
27.07,73.800,0.08559,5.086,0.002
27.09,73.900,0.08571,5.090,0.002
27.13,74.000,0.08588,5.097,0.002
27.16,74.100,0.08600,5.103,0.002
27.20,74.200,0.08613,5.111,0.002
27.23,74.300,0.08629,5.116,0.002
27.28,74.400,0.08642,5.126,0.002
27.30,74.500,0.08658,5.131,0.002
27.35,74.600,0.08671,5.138,0.002
27.37,74.700,0.08688,5.144,0.002
27.43,74.800,0.08700,5.154,0.002
27.46,74.900,0.08717,5.161,0.002
27.49,75.000,0.08733,5.166,0.002
27.53,75.100,0.08746,5.173,0.002
27.58,75.200,0.08762,5.182,0.002
27.62,75.300,0.08779,5.189,0.002
27.67,75.400,0.08791,5.200,0.002
27.70,75.500,0.08808,5.206,0.002
27.74,75.600,0.08825,5.213,0.002
27.78,75.700,0.08841,5.220,0.002
27.83,75.800,0.08854,5.229,0.002
27.88,75.900,0.08870,5.238,0.002
27.91,76.000,0.08887,5.244,0.002
27.96,76.100,0.08904,5.253,0.002
28.01,76.200,0.08920,5.264,0.002
28.05,76.300,0.08937,5.271,0.002
28.11,76.400,0.08953,5.281,0.002
28.14,76.500,0.08970,5.288,0.002
28.20,76.600,0.08987,5.298,0.002
28.25,76.700,0.09008,5.308,0.002
28.31,76.800,0.09024,5.319,0.002
28.36,76.900,0.09045,5.329,0.002
28.42,77.000,0.09066,5.341,0.002
28.48,77.100,0.09086,5.352,0.002
28.54,77.200,0.09107,5.363,0.002
28.61,77.300,0.09128,5.377,0.002
28.67,77.400,0.09149,5.388,0.002
28.73,77.500,0.09170,5.399,0.002
28.80,77.600,0.09190,5.411,0.002
28.86,77.700,0.09211,5.422,0.002
28.90,77.800,0.09232,5.431,0.002
28.95,77.900,0.09253,5.441,0.002
29.01,78.000,0.09269,5.452,0.002
29.07,78.100,0.09290,5.463,0.002
29.11,78.200,0.09311,5.471,0.002
29.17,78.300,0.09328,5.482,0.002
29.22,78.400,0.09348,5.491,0.002
29.25,78.500,0.09361,5.497,0.002
29.31,78.600,0.09377,5.508,0.002
29.34,78.700,0.09394,5.513,0.002
29.37,78.800,0.09411,5.520,0.002
29.43,78.900,0.09427,5.530,0.002
29.44,79.000,0.09440,5.533,0.002
29.47,79.100,0.09456,5.538,0.002
29.51,79.200,0.09469,5.546,0.002
29.54,79.300,0.09485,5.551,0.002
29.59,79.400,0.09498,5.560,0.002
29.62,79.500,0.09510,5.566,0.002
29.65,79.600,0.09527,5.572,0.002
29.70,79.700,0.09539,5.580,0.002
29.73,79.800,0.09552,5.586,0.002
29.76,79.900,0.09569,5.591,0.002
29.78,80.000,0.09581,5.596,0.002
29.84,80.100,0.09593,5.607,0.002
29.87,80.200,0.09610,5.613,0.002
29.93,80.300,0.09623,5.624,0.002
29.95,80.400,0.09639,5.629,0.002
30.00,80.500,0.09652,5.637,0.002
30.03,80.600,0.09668,5.643,0.002
30.08,80.700,0.09681,5.652,0.002
30.13,80.800,0.09697,5.662,0.002
30.19,80.900,0.09710,5.673,0.002
30.22,81.000,0.09726,5.679,0.002
30.26,81.100,0.09743,5.687,0.002
30.33,81.200,0.09756,5.699,0.002
30.36,81.300,0.09772,5.705,0.002
30.41,81.400,0.09789,5.715,0.002
30.46,81.500,0.09801,5.723,0.002
30.50,81.600,0.09818,5.731,0.002
30.55,81.700,0.09834,5.740,0.002
30.59,81.800,0.09851,5.748,0.002
30.64,81.900,0.09864,5.757,0.002
30.69,82.000,0.09880,5.767,0.002
30.76,82.100,0.09897,5.780,0.002
30.81,82.200,0.09918,5.789,0.002
30.86,82.300,0.09934,5.799,0.002
30.92,82.400,0.09951,5.811,0.002
30.99,82.500,0.09972,5.823,0.002
31.07,82.600,0.09992,5.838,0.002
31.14,82.700,0.10013,5.851,0.002
31.20,82.800,0.10034,5.863,0.002
31.28,82.900,0.10055,5.878,0.002
31.33,83.000,0.10076,5.888,0.002
31.41,83.100,0.10096,5.902,0.002
31.48,83.200,0.10117,5.915,0.002
31.54,83.300,0.10142,5.927,0.002
31.62,83.400,0.10163,5.942,0.002
31.69,83.500,0.10184,5.954,0.002
31.74,83.600,0.10204,5.964,0.002
31.80,83.700,0.10221,5.975,0.002
31.85,83.800,0.10242,5.985,0.002
31.89,83.900,0.10258,5.993,0.002
31.96,84.000,0.10279,6.005,0.002
32.00,84.100,0.10296,6.013,0.002
32.03,84.200,0.10312,6.019,0.002
32.07,84.300,0.10329,6.027,0.002
32.12,84.400,0.10341,6.035,0.002
32.15,84.500,0.10358,6.041,0.002
32.18,84.600,0.10371,6.047,0.002
32.23,84.700,0.10387,6.056,0.002
32.26,84.800,0.10400,6.061,0.002
32.29,84.900,0.10416,6.068,0.002
32.32,85.000,0.10429,6.073,0.002
32.37,85.100,0.10441,6.083,0.002
32.40,85.200,0.10454,6.088,0.002
32.43,85.300,0.10470,6.094,0.002
32.48,85.400,0.10483,6.103,0.002
32.50,85.500,0.10495,6.107,0.002
32.56,85.600,0.10508,6.118,0.002
32.59,85.700,0.10524,6.124,0.002
32.62,85.800,0.10537,6.130,0.002
32.68,85.900,0.10549,6.141,0.002
32.71,86.000,0.10566,6.147,0.002
32.75,86.100,0.10578,6.154,0.002
32.80,86.200,0.10595,6.164,0.002
32.85,86.300,0.10612,6.174,0.002
32.92,86.400,0.10624,6.185,0.002
32.94,86.500,0.10641,6.190,0.002
33.02,86.600,0.10657,6.204,0.002
33.05,86.700,0.10670,6.211,0.002
33.11,86.800,0.10686,6.222,0.002
33.14,86.900,0.10699,6.227,0.002
33.21,87.000,0.10715,6.240,0.002
33.24,87.100,0.10732,6.247,0.002
33.32,87.200,0.10749,6.262,0.002
33.35,87.300,0.10761,6.266,0.002
33.41,87.400,0.10778,6.277,0.002
33.44,87.500,0.10794,6.285,0.002
33.51,87.600,0.10811,6.296,0.002
33.54,87.700,0.10828,6.303,0.002
33.60,87.800,0.10844,6.314,0.002
33.66,87.900,0.10861,6.326,0.002
33.74,88.000,0.10878,6.341,0.002
33.81,88.100,0.10898,6.353,0.002
33.88,88.200,0.10915,6.367,0.002
33.94,88.300,0.10936,6.377,0.002
34.01,88.400,0.10956,6.390,0.002
34.06,88.500,0.10977,6.401,0.002
34.16,88.600,0.10998,6.418,0.002
34.23,88.700,0.11019,6.433,0.002
34.31,88.800,0.11040,6.446,0.002
34.38,88.900,0.11060,6.460,0.002
34.44,89.000,0.11081,6.472,0.002
34.52,89.100,0.11102,6.486,0.002
34.58,89.200,0.11123,6.499,0.002
34.65,89.300,0.11143,6.510,0.002
34.70,89.400,0.11164,6.520,0.002
34.75,89.500,0.11181,6.530,0.002
34.80,89.600,0.11202,6.539,0.002
34.85,89.700,0.11218,6.549,0.002
34.90,89.800,0.11239,6.559,0.002
34.95,89.900,0.11256,6.568,0.002
34.99,90.000,0.11272,6.575,0.002
35.04,90.100,0.11289,6.584,0.002
35.07,90.200,0.11301,6.589,0.002
35.12,90.300,0.11318,6.599,0.002
35.16,90.400,0.11335,6.607,0.002
35.19,90.500,0.11347,6.613,0.002
35.23,90.600,0.11364,6.620,0.002
35.29,90.700,0.11376,6.631,0.002
35.32,90.800,0.11389,6.637,0.002
35.36,90.900,0.11405,6.644,0.002
35.39,91.000,0.11418,6.650,0.002
35.42,91.100,0.11430,6.655,0.002
35.46,91.200,0.11443,6.663,0.002
35.50,91.300,0.11455,6.671,0.002
35.54,91.400,0.11472,6.678,0.002
35.58,91.500,0.11484,6.686,0.002
35.62,91.600,0.11501,6.693,0.002
35.67,91.700,0.11513,6.703,0.002
35.71,91.800,0.11526,6.711,0.002
35.78,91.900,0.11542,6.723,0.002
35.81,92.000,0.11559,6.730,0.002
35.88,92.100,0.11572,6.743,0.002
35.94,92.200,0.11588,6.753,0.002
36.00,92.300,0.11605,6.765,0.002
36.04,92.400,0.11617,6.773,0.002
36.10,92.500,0.11634,6.784,0.002
36.15,92.600,0.11650,6.794,0.002
36.21,92.700,0.11663,6.804,0.002
36.26,92.800,0.11680,6.814,0.002
36.31,92.900,0.11696,6.823,0.002
36.38,93.000,0.11713,6.836,0.002
36.42,93.100,0.11725,6.843,0.002
36.47,93.200,0.11742,6.853,0.002
36.54,93.300,0.11759,6.865,0.002
36.58,93.400,0.11775,6.874,0.002
36.65,93.500,0.11792,6.887,0.002
36.70,93.600,0.11813,6.897,0.002
36.77,93.700,0.11829,6.910,0.002
36.85,93.800,0.11850,6.924,0.002
36.91,93.900,0.11867,6.936,0.002
36.98,94.000,0.11887,6.948,0.002
37.04,94.100,0.11904,6.961,0.002
37.12,94.200,0.11925,6.975,0.002
37.21,94.300,0.11946,6.991,0.002
37.27,94.400,0.11966,7.004,0.002
37.33,94.500,0.11987,7.015,0.002
37.42,94.600,0.12008,7.032,0.002
37.47,94.700,0.12029,7.041,0.002
20.52,94.800,0.12049,3.856,0.002
21.03,94.900,0.12070,3.951,0.002
21.10,95.000,0.12091,3.966,0.002
21.18,95.100,0.12112,3.981,0.002
21.27,95.200,0.12128,3.996,0.002
21.36,95.300,0.12149,4.014,0.002
21.42,95.400,0.12166,4.026,0.002
21.50,95.500,0.12187,4.041,0.002
21.55,95.600,0.12199,4.050,0.002
21.60,95.700,0.12216,4.059,0.002
21.67,95.800,0.12232,4.072,0.002
21.73,95.900,0.12249,4.083,0.002
21.78,96.000,0.12266,4.093,0.002
21.83,96.100,0.12278,4.101,0.002
21.86,96.200,0.12295,4.107,0.002
21.93,96.300,0.12307,4.121,0.002
21.97,96.400,0.12324,4.129,0.002
22.03,96.500,0.12336,4.139,0.002
22.06,96.600,0.12349,4.146,0.002
22.10,96.700,0.12361,4.153,0.002
22.14,96.800,0.12378,4.161,0.002
22.19,96.900,0.12390,4.170,0.002
22.23,97.000,0.12403,4.177,0.002
22.28,97.100,0.12419,4.186,0.002
22.32,97.200,0.12432,4.195,0.002
22.37,97.300,0.12444,4.204,0.002
22.41,97.400,0.12461,4.211,0.002
22.46,97.500,0.12473,4.221,0.002
22.51,97.600,0.12490,4.230,0.002
22.57,97.700,0.12507,4.242,0.002
22.63,97.800,0.12519,4.252,0.002
22.66,97.900,0.12536,4.258,0.002
22.72,98.000,0.12548,4.269,0.002
22.76,98.100,0.12565,4.278,0.002
22.81,98.200,0.12581,4.287,0.002
22.86,98.300,0.12594,4.296,0.002
22.90,98.400,0.12610,4.304,0.002
22.95,98.500,0.12623,4.313,0.002
23.00,98.600,0.12640,4.323,0.002
23.05,98.700,0.12656,4.332,0.002
23.10,98.800,0.12673,4.341,0.002
23.15,98.900,0.12685,4.349,0.002
23.20,99.000,0.12702,4.360,0.003
23.25,99.100,0.12718,4.368,0.003
23.32,99.200,0.12735,4.381,0.003
23.33,99.300,0.12752,4.384,0.003
23.40,99.400,0.12768,4.397,0.003
23.47,99.500,0.12789,4.411,0.003
23.54,99.600,0.12810,4.424,0.003
23.61,99.700,0.12827,4.436,0.003
23.67,99.800,0.12847,4.448,0.003
23.75,99.900,0.12868,4.462,0.003
23.80,100.000,0.12889,4.472,0.003
23.88,100.100,0.12910,4.486,0.003
23.94,100.200,0.12930,4.498,0.003
24.02,100.300,0.12951,4.514,0.003
24.08,100.400,0.12976,4.525,0.003
24.14,100.500,0.12997,4.536,0.003
24.22,100.600,0.13018,4.551,0.003
24.26,100.700,0.13034,4.560,0.003
24.33,100.800,0.13055,4.571,0.003
24.38,100.900,0.13076,4.582,0.003
24.44,101.000,0.13097,4.593,0.003
24.49,101.100,0.13113,4.601,0.003
24.52,101.200,0.13130,4.607,0.003
24.59,101.300,0.13146,4.621,0.003
24.63,101.400,0.13163,4.628,0.003
24.68,101.500,0.13180,4.637,0.003
24.72,101.600,0.13196,4.646,0.003
24.76,101.700,0.13209,4.653,0.003
24.80,101.800,0.13225,4.659,0.003
24.84,101.900,0.13238,4.667,0.003
24.89,102.000,0.13255,4.678,0.003
24.92,102.100,0.13267,4.682,0.003
24.95,102.200,0.13279,4.689,0.003
24.99,102.300,0.13296,4.697,0.003
25.02,102.400,0.13309,4.702,0.003
25.06,102.500,0.13321,4.710,0.003
25.10,102.600,0.13338,4.717,0.003
25.15,102.700,0.13350,4.725,0.003
25.18,102.800,0.13363,4.732,0.003
25.22,102.900,0.13379,4.740,0.003
25.25,103.000,0.13392,4.745,0.003
25.31,103.100,0.13404,4.756,0.003
25.34,103.200,0.13421,4.762,0.003
25.39,103.300,0.13433,4.771,0.003
25.44,103.400,0.13450,4.781,0.003
12.03,103.500,0.13462,2.260,0.003
13.20,103.600,0.13479,2.480,0.003
13.37,103.700,0.13491,2.513,0.003
13.44,103.800,0.13508,2.525,0.003
13.50,103.900,0.13525,2.536,0.003
13.55,104.000,0.13537,2.546,0.003
13.60,104.100,0.13554,2.556,0.003
13.65,104.200,0.13570,2.565,0.003
13.68,104.300,0.13587,2.570,0.003
13.72,104.400,0.13599,2.578,0.003
13.76,104.500,0.13616,2.585,0.003
13.79,104.600,0.13633,2.591,0.003
13.83,104.680,0.13641,2.599,0.003
13.84,104.700,0.13641,2.600,0.003