File: data-files/CWRU/1000-05-35A.txt
""
"Test Method","Will_Huddleston_Disks.msm"
"Sample I. D.","1000-5-35A.mss"
"Specimen Number","1"

"Load (N)","Time (s)","Extension (mm)","Stress (MPa)","Strain (mm/mm)"

2.86,0.200,-0.02307,0.536,0.000
2.87,0.300,-0.02302,0.537,0.000
2.88,0.400,-0.02302,0.540,0.000
2.87,0.500,-0.02302,0.538,0.000
2.86,0.600,-0.02298,0.536,0.000
2.87,0.700,-0.02298,0.538,0.000
2.87,0.800,-0.02298,0.538,0.000
2.89,0.900,-0.02294,0.541,0.000
2.87,1.000,-0.02294,0.538,0.000
2.88,1.100,-0.02294,0.540,0.000
2.88,1.200,-0.02290,0.539,0.000
2.88,1.300,-0.02290,0.539,0.000
2.87,1.400,-0.02286,0.537,0.000
2.89,1.500,-0.02286,0.542,0.000
2.89,1.600,-0.02282,0.541,0.000
2.90,1.700,-0.02277,0.543,0.000
2.93,1.800,-0.02277,0.548,0.000
2.98,1.900,-0.02269,0.558,0.000
3.07,2.000,-0.02257,0.575,0.000
3.18,2.100,-0.02244,0.597,0.000
3.28,2.200,-0.02232,0.614,0.000
3.37,2.300,-0.02215,0.632,0.000
3.44,2.400,-0.02203,0.645,0.000
3.50,2.500,-0.02186,0.656,0.000
3.56,2.600,-0.02174,0.667,0.000
3.61,2.700,-0.02157,0.676,0.000
3.66,2.800,-0.02144,0.686,0.000
3.69,2.900,-0.02128,0.692,0.000
3.73,3.000,-0.02115,0.698,0.000
3.78,3.100,-0.02099,0.708,0.000
3.81,3.200,-0.02086,0.714,0.000
3.86,3.300,-0.02070,0.723,0.000
3.88,3.400,-0.02057,0.726,0.000
3.92,3.500,-0.02041,0.735,0.000
3.97,3.600,-0.02024,0.744,0.000
3.99,3.700,-0.02011,0.748,0.000
4.01,3.800,-0.01995,0.752,0.000
4.06,3.900,-0.01978,0.761,0.000
4.09,4.000,-0.01966,0.767,0.000
4.13,4.100,-0.01949,0.774,0.000
4.17,4.200,-0.01933,0.781,0.000
4.21,4.300,-0.01916,0.789,0.000
4.26,4.400,-0.01895,0.797,0.000
4.28,4.500,-0.01879,0.802,0.000
4.34,4.600,-0.01858,0.812,0.000
4.38,4.700,-0.01841,0.820,0.000
4.42,4.800,-0.01820,0.827,0.000
4.47,4.900,-0.01800,0.837,0.000
4.52,5.000,-0.01779,0.846,0.000
4.57,5.100,-0.01762,0.856,0.000
4.60,5.200,-0.01741,0.862,0.000
4.67,5.300,-0.01721,0.874,0.000
4.72,5.400,-0.01700,0.883,0.000
4.74,5.500,-0.01679,0.887,0.000
4.78,5.600,-0.01658,0.895,0.000
4.83,5.700,-0.01637,0.905,0.000
4.88,5.800,-0.01621,0.914,0.000
4.93,5.900,-0.01600,0.923,0.000
4.96,6.000,-0.01583,0.930,0.000
5.00,6.100,-0.01563,0.937,0.000
5.04,6.200,-0.01546,0.943,0.000
5.07,6.300,-0.01529,0.950,0.000
5.09,6.400,-0.01513,0.954,0.000
5.11,6.500,-0.01496,0.958,0.000
5.15,6.600,-0.01484,0.965,0.000
5.19,6.700,-0.01467,0.971,0.000
5.22,6.800,-0.01450,0.977,0.000
5.25,6.900,-0.01438,0.983,0.000
5.28,7.000,-0.01421,0.988,0.000
5.32,7.100,-0.01409,0.996,0.000
5.33,7.200,-0.01396,0.999,0.000
5.37,7.300,-0.01380,1.005,0.000
5.40,7.400,-0.01367,1.012,0.000
5.43,7.500,-0.01355,1.016,0.000
5.46,7.600,-0.01342,1.023,0.000
5.47,7.700,-0.01326,1.025,0.000
5.51,7.800,-0.01313,1.033,0.000
5.54,7.900,-0.01301,1.038,0.000
5.58,8.000,-0.01284,1.044,0.000
5.60,8.100,-0.01272,1.049,0.000
5.64,8.200,-0.01255,1.057,0.000
5.67,8.300,-0.01243,1.063,0.000
5.71,8.400,-0.01230,1.070,0.000
5.74,8.500,-0.01214,1.075,0.000
5.78,8.600,-0.01197,1.083,0.000
5.81,8.700,-0.01185,1.088,0.000
5.84,8.800,-0.01168,1.095,0.000
5.89,8.900,-0.01155,1.103,0.000
5.92,9.000,-0.01139,1.109,0.000
5.95,9.100,-0.01122,1.115,0.000
6.01,9.200,-0.01110,1.125,0.000
6.04,9.300,-0.01093,1.131,0.000
6.07,9.400,-0.01076,1.137,0.000
6.11,9.500,-0.01064,1.145,0.000
6.14,9.600,-0.01047,1.150,0.000
6.18,9.700,-0.01031,1.158,0.000
6.22,9.800,-0.01014,1.166,0.000
6.26,9.900,-0.00998,1.173,0.000
6.32,10.000,-0.00981,1.184,0.000
6.36,10.100,-0.00964,1.192,0.000
6.41,10.200,-0.00944,1.201,0.000
6.46,10.300,-0.00927,1.210,0.000
6.52,10.400,-0.00906,1.221,0.000
6.56,10.500,-0.00885,1.228,0.000
6.61,10.600,-0.00865,1.238,0.000
6.66,10.700,-0.00844,1.248,0.000
6.72,10.800,-0.00823,1.258,0.000
6.77,10.900,-0.00802,1.267,0.000
6.82,11.000,-0.00781,1.277,0.000
6.86,11.100,-0.00761,1.284,0.000
6.92,11.200,-0.00740,1.296,0.000
6.98,11.300,-0.00719,1.307,0.000
7.03,11.400,-0.00698,1.317,0.000
7.07,11.500,-0.00678,1.324,0.000
7.11,11.600,-0.00657,1.332,0.000
7.16,11.700,-0.00640,1.342,0.000
7.20,11.800,-0.00619,1.349,0.000
7.24,11.900,-0.00603,1.356,0.000
7.29,12.000,-0.00586,1.365,0.000
7.31,12.100,-0.00569,1.370,0.000
7.35,12.200,-0.00553,1.376,0.000
7.40,12.300,-0.00536,1.385,0.000
7.43,12.400,-0.00520,1.393,0.000
7.46,12.500,-0.00507,1.397,0.000
7.51,12.600,-0.00491,1.407,0.000
7.51,12.700,-0.00478,1.408,0.000
7.56,12.800,-0.00466,1.416,0.000
7.59,12.900,-0.00449,1.422,0.000
7.62,13.000,-0.00437,1.427,0.000
7.65,13.100,-0.00424,1.434,0.000
7.68,13.200,-0.00407,1.438,0.000
7.71,13.300,-0.00395,1.445,0.000
7.75,13.400,-0.00382,1.452,0.000
7.79,13.500,-0.00370,1.460,0.000
7.81,13.600,-0.00358,1.464,0.000
7.87,13.700,-0.00341,1.475,0.000
7.90,13.800,-0.00328,1.480,0.000
7.94,13.900,-0.00312,1.488,0.000
7.97,14.000,-0.00299,1.493,0.000
8.02,14.100,-0.00283,1.503,0.000
8.05,14.200,-0.00270,1.509,0.000
8.11,14.300,-0.00254,1.519,0.000
8.15,14.400,-0.00241,1.527,0.000
8.19,14.500,-0.00225,1.534,0.000
8.23,14.600,-0.00208,1.541,0.000
8.27,14.700,-0.00195,1.549,0.000
8.31,14.800,-0.00179,1.556,0.000
8.36,14.900,-0.00162,1.566,0.000
8.40,15.000,-0.00146,1.574,0.000
8.45,15.100,-0.00133,1.584,0.000
8.49,15.200,-0.00117,1.590,0.000
8.54,15.300,-0.00100,1.600,0.000
8.58,15.400,-0.00083,1.606,0.000
8.62,15.500,-0.00067,1.615,0.000
8.66,15.600,-0.00050,1.622,0.000
8.72,15.700,-0.00033,1.633,0.000
8.78,15.800,-0.00017,1.644,0.000
8.83,15.900,0.00000,1.653,0.000
8.88,16.000,0.00021,1.664,0.000
8.94,16.100,0.00041,1.676,0.000
9.00,16.200,0.00058,1.686,0.000
9.07,16.300,0.00079,1.699,0.000
9.12,16.400,0.00100,1.709,0.000
9.19,16.500,0.00120,1.721,0.000
9.25,16.600,0.00141,1.733,0.000
9.32,16.700,0.00162,1.746,0.000
9.38,16.800,0.00183,1.758,0.000
9.44,16.900,0.00203,1.768,0.000
9.49,17.000,0.00224,1.778,0.000
9.56,17.100,0.00245,1.790,0.000
9.61,17.200,0.00266,1.800,0.000
9.67,17.300,0.00287,1.811,0.000
9.72,17.400,0.00303,1.821,0.000
9.77,17.500,0.00324,1.830,0.000
9.82,17.600,0.00341,1.840,0.000
9.87,17.700,0.00357,1.850,0.000
9.91,17.800,0.00374,1.857,0.000
9.96,17.900,0.00390,1.866,0.000
9.99,18.000,0.00407,1.871,0.000
10.03,18.100,0.00420,1.878,0.000
10.08,18.200,0.00436,1.888,0.000
10.11,18.300,0.00449,1.894,0.000
10.14,18.400,0.00465,1.900,0.000
10.19,18.500,0.00478,1.908,0.000
10.23,18.600,0.00490,1.917,0.000
10.27,18.700,0.00507,1.925,0.000
10.31,18.800,0.00519,1.932,0.000
10.35,18.900,0.00532,1.938,0.000
10.39,19.000,0.00544,1.947,0.000
10.43,19.100,0.00561,1.954,0.000
10.47,19.200,0.00573,1.961,0.000
10.52,19.300,0.00586,1.970,0.000
10.56,19.400,0.00602,1.978,0.000
10.60,19.500,0.00615,1.986,0.000
10.65,19.600,0.00631,1.994,0.000
10.69,19.700,0.00644,2.002,0.000
10.76,19.800,0.00656,2.015,0.000
10.79,19.900,0.00673,2.022,0.000
10.85,20.000,0.00690,2.032,0.000
10.89,20.100,0.00702,2.039,0.000
10.93,20.200,0.00719,2.048,0.000
10.99,20.300,0.00735,2.059,0.000
11.05,20.400,0.00748,2.069,0.000
11.07,20.500,0.00764,2.074,0.000
11.11,20.600,0.00781,2.082,0.000
11.18,20.700,0.00794,2.095,0.000
11.22,20.800,0.00810,2.102,0.000
11.26,20.900,0.00827,2.110,0.000
11.31,21.000,0.00843,2.119,0.000
11.36,21.100,0.00860,2.128,0.000
11.41,21.200,0.00872,2.137,0.000
11.46,21.300,0.00889,2.146,0.000
11.51,21.400,0.00906,2.156,0.000
11.57,21.500,0.00927,2.168,0.000
11.63,21.600,0.00943,2.178,0.000
11.69,21.700,0.00964,2.189,0.000
11.75,21.800,0.00981,2.200,0.000
11.81,21.900,0.01001,2.212,0.000
11.87,22.000,0.01022,2.224,0.000
11.96,22.100,0.01043,2.240,0.000
12.02,22.200,0.01064,2.252,0.000
12.09,22.300,0.01084,2.264,0.000
12.15,22.400,0.01105,2.276,0.000
12.22,22.500,0.01126,2.289,0.000
12.29,22.600,0.01147,2.303,0.000
12.35,22.700,0.01168,2.313,0.000
12.41,22.800,0.01188,2.325,0.000
12.46,22.900,0.01205,2.335,0.000
12.54,23.000,0.01226,2.348,0.000
12.56,23.100,0.01246,2.353,0.000
12.62,23.200,0.01263,2.364,0.000
12.68,23.300,0.01280,2.375,0.000
12.73,23.400,0.01296,2.386,0.000
12.78,23.500,0.01313,2.395,0.000
12.84,23.600,0.01330,2.405,0.000
12.88,23.700,0.01346,2.413,0.000
12.94,23.800,0.01363,2.423,0.000
12.97,23.900,0.01375,2.430,0.000
13.02,24.000,0.01392,2.438,0.000
13.06,24.100,0.01409,2.447,0.000
13.09,24.200,0.01421,2.453,0.000
13.14,24.300,0.01433,2.461,0.000
13.20,24.400,0.01450,2.473,0.000
13.23,24.500,0.01463,2.479,0.000
13.27,24.600,0.01475,2.486,0.000
13.31,24.700,0.01492,2.493,0.000
13.36,24.800,0.01504,2.502,0.000
13.39,24.900,0.01517,2.509,0.000
13.44,25.000,0.01533,2.517,0.000
13.49,25.100,0.01546,2.526,0.000
13.53,25.200,0.01558,2.534,0.000
13.56,25.300,0.01575,2.541,0.000
13.61,25.400,0.01587,2.549,0.000
13.66,25.500,0.01604,2.559,0.000
13.71,25.600,0.01616,2.568,0.000
13.75,25.700,0.01633,2.576,0.000
13.79,25.800,0.01650,2.584,0.000
13.83,25.900,0.01662,2.591,0.000
13.89,26.000,0.01679,2.602,0.000
13.95,26.100,0.01695,2.613,0.000
13.98,26.200,0.01708,2.619,0.000
14.03,26.300,0.01724,2.628,0.000
14.07,26.400,0.01741,2.636,0.000
14.13,26.500,0.01753,2.646,0.000
14.16,26.600,0.01770,2.652,0.000
14.21,26.700,0.01787,2.662,0.000
14.27,26.800,0.01803,2.673,0.000
14.30,26.900,0.01820,2.678,0.000
14.36,27.000,0.01837,2.691,0.000
14.43,27.100,0.01853,2.703,0.000
14.49,27.200,0.01870,2.714,0.000
14.54,27.300,0.01886,2.724,0.000
14.62,27.400,0.01907,2.738,0.000
14.69,27.500,0.01924,2.751,0.000
14.75,27.600,0.01945,2.763,0.000
14.82,27.700,0.01965,2.777,0.000
14.91,27.800,0.01990,2.793,0.000
14.98,27.900,0.02011,2.806,0.000
15.04,28.000,0.02032,2.818,0.000
15.14,28.100,0.02053,2.835,0.000
15.21,28.200,0.02073,2.849,0.000
15.28,28.300,0.02094,2.862,0.000
15.34,28.400,0.02115,2.874,0.000
15.41,28.500,0.02136,2.887,0.000
15.47,28.600,0.02157,2.897,0.000
15.52,28.700,0.02177,2.907,0.000
15.58,28.800,0.02194,2.919,0.000
15.63,28.900,0.02215,2.929,0.000
15.68,29.000,0.02231,2.937,0.000
15.72,29.100,0.02248,2.945,0.000
15.77,29.200,0.02265,2.954,0.000
15.82,29.300,0.02277,2.963,0.000
15.87,29.400,0.02294,2.973,0.000
15.92,29.500,0.02310,2.983,0.000
15.95,29.600,0.02323,2.988,0.000
15.99,29.700,0.02339,2.996,0.000
16.03,29.800,0.02352,3.004,0.000
16.09,29.900,0.02364,3.013,0.000
16.14,30.000,0.02381,3.023,0.000
16.17,30.100,0.02393,3.028,0.000
16.20,30.200,0.02406,3.035,0.000
16.24,30.300,0.02418,3.042,0.000
16.28,30.400,0.02431,3.050,0.000
16.33,30.500,0.02447,3.058,0.000
16.38,30.600,0.02460,3.069,0.000
16.42,30.700,0.02472,3.076,0.000
16.47,30.800,0.02489,3.086,0.000
16.52,30.900,0.02501,3.095,0.000
16.56,31.000,0.02514,3.103,0.000
16.62,31.100,0.02531,3.114,0.000
16.68,31.200,0.02547,3.124,0.001
16.72,31.300,0.02560,3.132,0.001
16.77,31.400,0.02576,3.142,0.001
16.81,31.500,0.02589,3.148,0.001
16.86,31.600,0.02605,3.158,0.001
16.91,31.700,0.02622,3.167,0.001
16.98,31.800,0.02634,3.180,0.001
17.03,31.900,0.02651,3.190,0.001
17.07,32.000,0.02668,3.197,0.001
17.13,32.100,0.02684,3.208,0.001
17.18,32.200,0.02697,3.218,0.001
17.25,32.300,0.02713,3.230,0.001
17.29,32.400,0.02730,3.238,0.001
17.34,32.500,0.02747,3.247,0.001
17.39,32.600,0.02763,3.258,0.001
17.45,32.700,0.02780,3.269,0.001
17.51,32.800,0.02797,3.280,0.001
17.57,32.900,0.02813,3.291,0.001
17.64,33.000,0.02834,3.304,0.001
17.72,33.100,0.02851,3.319,0.001
17.79,33.200,0.02871,3.333,0.001
17.86,33.300,0.02892,3.346,0.001
17.93,33.400,0.02913,3.359,0.001
18.01,33.500,0.02934,3.373,0.001
18.09,33.600,0.02954,3.389,0.001
18.15,33.700,0.02975,3.401,0.001
18.23,33.800,0.03000,3.415,0.001
18.32,33.900,0.03021,3.431,0.001
18.39,34.000,0.03042,3.445,0.001
18.45,34.100,0.03062,3.457,0.001
18.52,34.200,0.03083,3.469,0.001
18.58,34.300,0.03100,3.481,0.001
18.64,34.400,0.03121,3.492,0.001
18.70,34.500,0.03141,3.502,0.001
18.76,34.600,0.03158,3.515,0.001
18.80,34.700,0.03175,3.521,0.001
18.86,34.800,0.03195,3.533,0.001
18.91,34.900,0.03208,3.543,0.001
18.97,35.000,0.03225,3.553,0.001
18.99,35.100,0.03241,3.558,0.001
19.07,35.200,0.03258,3.572,0.001
19.12,35.300,0.03274,3.581,0.001
19.17,35.400,0.03287,3.592,0.001
19.22,35.500,0.03304,3.600,0.001
19.27,35.600,0.03316,3.610,0.001
19.30,35.700,0.03333,3.615,0.001
19.34,35.800,0.03345,3.623,0.001
19.40,35.900,0.03358,3.634,0.001
19.43,36.000,0.03370,3.639,0.001
19.49,36.100,0.03387,3.651,0.001
19.53,36.200,0.03399,3.659,0.001
19.59,36.300,0.03416,3.669,0.001
19.64,36.400,0.03428,3.679,0.001
19.69,36.500,0.03441,3.688,0.001
19.74,36.600,0.03457,3.698,0.001
19.78,36.700,0.03474,3.705,0.001
19.83,36.800,0.03486,3.715,0.001
19.90,36.900,0.03503,3.728,0.001
19.96,37.000,0.03515,3.740,0.001
20.01,37.100,0.03532,3.747,0.001
20.06,37.200,0.03549,3.758,0.001
20.13,37.300,0.03561,3.770,0.001
20.18,37.400,0.03578,3.780,0.001
20.24,37.500,0.03594,3.792,0.001
20.29,37.600,0.03611,3.801,0.001
20.34,37.700,0.03623,3.811,0.001
20.39,37.800,0.03640,3.820,0.001
20.46,37.900,0.03657,3.833,0.001
20.53,38.000,0.03673,3.846,0.001
20.59,38.100,0.03690,3.856,0.001
20.64,38.200,0.03707,3.867,0.001
20.72,38.300,0.03723,3.881,0.001
20.78,38.400,0.03740,3.892,0.001
20.84,38.500,0.03761,3.903,0.001
20.92,38.600,0.03777,3.920,0.001
21.00,38.700,0.03798,3.934,0.001
21.06,38.800,0.03815,3.945,0.001
21.14,38.900,0.03835,3.959,0.001
21.21,39.000,0.03856,3.973,0.001
21.28,39.100,0.03877,3.987,0.001
21.36,39.200,0.03898,4.002,0.001
21.45,39.300,0.03919,4.017,0.001
21.52,39.400,0.03939,4.031,0.001
21.60,39.500,0.03960,4.047,0.001
21.66,39.600,0.03981,4.058,0.001
21.75,39.700,0.04002,4.074,0.001
21.82,39.800,0.04018,4.088,0.001
21.87,39.900,0.04039,4.097,0.001
21.94,40.000,0.04060,4.109,0.001
21.99,40.100,0.04076,4.119,0.001
22.06,40.200,0.04097,4.133,0.001
22.11,40.300,0.04114,4.141,0.001
22.17,40.400,0.04130,4.153,0.001
22.24,40.500,0.04147,4.165,0.001
22.30,40.600,0.04164,4.176,0.001
22.34,40.700,0.04180,4.185,0.001
22.39,40.800,0.04197,4.195,0.001
22.45,40.900,0.04214,4.206,0.001
22.51,41.000,0.04226,4.217,0.001
22.55,41.100,0.04243,4.224,0.001
22.60,41.200,0.04255,4.234,0.001
22.65,41.300,0.04272,4.244,0.001
22.70,41.400,0.04284,4.252,0.001
22.75,41.500,0.04297,4.261,0.001
22.79,41.600,0.04313,4.270,0.001
22.84,41.700,0.04326,4.279,0.001
22.88,41.800,0.04338,4.285,0.001
22.94,41.900,0.04351,4.297,0.001
23.00,42.000,0.04367,4.308,0.001
23.05,42.100,0.04380,4.318,0.001
23.11,42.200,0.04392,4.329,0.001
23.18,42.300,0.04409,4.342,0.001
23.21,42.400,0.04421,4.347,0.001
23.28,42.500,0.04438,4.361,0.001
23.33,42.600,0.04450,4.371,0.001
23.37,42.700,0.04467,4.378,0.001
23.44,42.800,0.04484,4.391,0.001
23.50,42.900,0.04496,4.402,0.001
23.55,43.000,0.04513,4.412,0.001
23.61,43.100,0.04529,4.424,0.001
23.65,43.200,0.04542,4.430,0.001
23.73,43.300,0.04558,4.445,0.001
23.80,43.400,0.04575,4.459,0.001
23.85,43.500,0.04588,4.467,0.001
23.91,43.600,0.04604,4.479,0.001
23.97,43.700,0.04621,4.490,0.001
24.03,43.800,0.04637,4.502,0.001
24.09,43.900,0.04654,4.513,0.001
24.15,44.000,0.04671,4.524,0.001
24.21,44.100,0.04687,4.535,0.001
24.27,44.200,0.04704,4.546,0.001
24.35,44.300,0.04721,4.561,0.001
24.44,44.400,0.04741,4.578,0.001
24.52,44.500,0.04758,4.592,0.001
24.59,44.600,0.04779,4.607,0.001
24.68,44.700,0.04800,4.624,0.001
24.76,44.800,0.04820,4.638,0.001
24.86,44.900,0.04845,4.657,0.001
24.94,45.000,0.04866,4.671,0.001
25.01,45.100,0.04887,4.686,0.001
25.10,45.200,0.04908,4.701,0.001
25.18,45.300,0.04928,4.717,0.001
25.25,45.400,0.04949,4.730,0.001
25.34,45.500,0.04970,4.746,0.001
25.43,45.600,0.04991,4.763,0.001
25.50,45.700,0.05011,4.777,0.001
25.58,45.800,0.05028,4.791,0.001
25.65,45.900,0.05049,4.805,0.001
25.72,46.000,0.05065,4.818,0.001
25.77,46.100,0.05082,4.828,0.001
25.83,46.200,0.05099,4.839,0.001
25.91,46.300,0.05115,4.853,0.001
25.95,46.400,0.05132,4.861,0.001
26.02,46.500,0.05149,4.874,0.001
26.07,46.600,0.05161,4.883,0.001
26.12,46.700,0.05178,4.893,0.001
26.18,46.800,0.05190,4.904,0.001
26.24,46.900,0.05203,4.915,0.001
26.29,47.000,0.05219,4.925,0.001
26.34,47.100,0.05232,4.934,0.001
26.38,47.200,0.05244,4.941,0.001
26.43,47.300,0.05261,4.952,0.001
26.49,47.400,0.05273,4.962,0.001
26.55,47.500,0.05286,4.974,0.001
26.61,47.600,0.05302,4.984,0.001
26.66,47.700,0.05315,4.994,0.001
26.73,47.800,0.05331,5.007,0.001
26.78,47.900,0.05344,5.017,0.001
26.83,48.000,0.05356,5.026,0.001
26.89,48.100,0.05373,5.037,0.001
26.95,48.200,0.05390,5.049,0.001
27.02,48.300,0.05402,5.061,0.001
27.08,48.400,0.05419,5.072,0.001
27.15,48.500,0.05435,5.085,0.001
27.21,48.600,0.05448,5.097,0.001
27.27,48.700,0.05464,5.109,0.001
27.33,48.800,0.05481,5.120,0.001
27.39,48.900,0.05493,5.130,0.001
27.45,49.000,0.05510,5.143,0.001
27.52,49.100,0.05527,5.156,0.001
27.58,49.200,0.05543,5.167,0.001
27.65,49.300,0.05560,5.179,0.001
27.72,49.400,0.05572,5.192,0.001
27.78,49.500,0.05589,5.204,0.001
27.85,49.600,0.05606,5.218,0.001
27.92,49.700,0.05622,5.231,0.001
28.00,49.800,0.05643,5.245,0.001
28.07,49.900,0.05660,5.259,0.001
28.15,50.000,0.05681,5.273,0.001
28.25,50.100,0.05697,5.291,0.001
28.33,50.200,0.05718,5.307,0.001
28.41,50.300,0.05739,5.322,0.001
28.52,50.400,0.05759,5.343,0.001
28.59,50.500,0.05780,5.356,0.001
28.69,50.600,0.05801,5.374,0.001
28.78,50.700,0.05822,5.392,0.001
28.88,50.800,0.05843,5.410,0.001
28.97,50.900,0.05863,5.426,0.001
29.05,51.000,0.05884,5.443,0.001
29.14,51.100,0.05905,5.458,0.001
29.24,51.200,0.05926,5.477,0.001
29.32,51.300,0.05942,5.492,0.001
29.40,51.400,0.05963,5.508,0.001
29.50,51.500,0.05984,5.525,0.001
29.57,51.600,0.06000,5.539,0.001
29.65,51.700,0.06017,5.553,0.001
29.71,51.800,0.06034,5.565,0.001
29.77,51.900,0.06050,5.577,0.001
29.85,52.000,0.06067,5.592,0.001
29.90,52.100,0.06084,5.601,0.001
29.97,52.200,0.06096,5.614,0.001
30.03,52.300,0.06113,5.625,0.001
30.08,52.400,0.06125,5.635,0.001
30.14,52.500,0.06142,5.646,0.001
30.20,52.600,0.06154,5.657,0.001
30.27,52.700,0.06171,5.671,0.001
30.31,52.800,0.06183,5.678,0.001
30.37,52.900,0.06196,5.689,0.001
30.42,53.000,0.06208,5.699,0.001
30.50,53.100,0.06225,5.714,0.001
30.54,53.200,0.06237,5.720,0.001
30.61,53.300,0.06250,5.735,0.001
30.67,53.400,0.06266,5.745,0.001
30.74,53.500,0.06279,5.758,0.001
30.79,53.600,0.06296,5.768,0.001
30.85,53.700,0.06308,5.780,0.001
30.92,53.800,0.06320,5.791,0.001
30.98,53.900,0.06337,5.803,0.001
31.05,54.000,0.06354,5.816,0.001
31.11,54.100,0.06366,5.828,0.001
31.19,54.200,0.06383,5.843,0.001
31.26,54.300,0.06395,5.855,0.001
31.33,54.400,0.06412,5.869,0.001
31.40,54.500,0.06429,5.882,0.001
31.47,54.600,0.06441,5.895,0.001
31.54,54.700,0.06458,5.909,0.001
31.60,54.800,0.06474,5.919,0.001
31.67,54.900,0.06491,5.933,0.001
31.74,55.000,0.06503,5.945,0.001
31.80,55.100,0.06520,5.957,0.001
31.88,55.200,0.06537,5.972,0.001
31.96,55.300,0.06553,5.986,0.001
32.03,55.400,0.06566,6.000,0.001
32.11,55.500,0.06586,6.015,0.001
32.20,55.600,0.06603,6.031,0.001
32.29,55.700,0.06620,6.048,0.001
32.35,55.800,0.06636,6.060,0.001
32.43,55.900,0.06657,6.076,0.001
32.54,56.000,0.06678,6.096,0.001
32.63,56.100,0.06694,6.113,0.001
32.74,56.200,0.06715,6.134,0.001
32.83,56.300,0.06736,6.151,0.001
32.94,56.400,0.06757,6.171,0.001
33.04,56.500,0.06778,6.189,0.001
33.14,56.600,0.06798,6.208,0.001
33.23,56.700,0.06819,6.225,0.001
33.30,56.800,0.06840,6.238,0.001
33.41,56.900,0.06861,6.259,0.001
33.50,57.000,0.06881,6.275,0.001
33.56,57.100,0.06898,6.287,0.001
33.64,57.200,0.06919,6.302,0.001
33.75,57.300,0.06935,6.322,0.001
33.81,57.400,0.06956,6.334,0.001
33.87,57.500,0.06969,6.345,0.001
33.94,57.600,0.06990,6.358,0.001
34.02,57.700,0.07002,6.373,0.001
34.08,57.800,0.07019,6.383,0.001
34.15,57.900,0.07035,6.397,0.001
34.22,58.000,0.07052,6.409,0.001
34.28,58.100,0.07064,6.422,0.001
34.35,58.200,0.07081,6.434,0.001
34.41,58.300,0.07093,6.446,0.001
34.47,58.400,0.07110,6.458,0.001
34.53,58.500,0.07122,6.468,0.001
34.59,58.600,0.07135,6.480,0.001
34.64,58.700,0.07147,6.490,0.001
34.70,58.800,0.07164,6.501,0.001
34.77,58.900,0.07177,6.512,0.001
34.82,59.000,0.07189,6.523,0.001
34.91,59.100,0.07206,6.539,0.001
34.97,59.200,0.07218,6.551,0.001
35.03,59.300,0.07235,6.563,0.001
35.09,59.400,0.07247,6.573,0.001
35.17,59.500,0.07260,6.588,0.001
35.24,59.600,0.07276,6.601,0.001
35.30,59.700,0.07289,6.613,0.001
35.39,59.800,0.07305,6.628,0.001
35.46,59.900,0.07322,6.642,0.001
35.53,60.000,0.07334,6.655,0.001
35.59,60.100,0.07351,6.666,0.001
35.66,60.200,0.07364,6.680,0.001
35.75,60.300,0.07380,6.696,0.001
35.81,60.400,0.07397,6.708,0.001
35.89,60.500,0.07409,6.723,0.001
35.98,60.600,0.07426,6.740,0.001
36.06,60.700,0.07442,6.755,0.001
36.13,60.800,0.07459,6.768,0.001
36.20,60.900,0.07472,6.782,0.001
36.29,61.000,0.07488,6.798,0.001
36.38,61.100,0.07505,6.814,0.001
36.47,61.200,0.07521,6.832,0.001
36.55,61.300,0.07542,6.846,0.001
36.63,61.400,0.07559,6.861,0.001
36.72,61.500,0.07575,6.879,0.001
36.83,61.600,0.07596,6.899,0.001
36.93,61.700,0.07617,6.917,0.001
37.02,61.800,0.07638,6.935,0.002
37.12,61.900,0.07659,6.953,0.002
37.23,62.000,0.07679,6.973,0.002
37.33,62.100,0.07700,6.992,0.002
37.45,62.200,0.07721,7.015,0.002
37.54,62.300,0.07742,7.033,0.002
37.64,62.400,0.07762,7.050,0.002
37.74,62.500,0.07783,7.069,0.002
37.85,62.600,0.07804,7.089,0.002
37.93,62.700,0.07825,7.106,0.002
38.00,62.800,0.07846,7.118,0.002
38.10,62.900,0.07862,7.137,0.002
38.19,63.000,0.07883,7.154,0.002
38.27,63.100,0.07900,7.169,0.002
38.35,63.200,0.07916,7.185,0.002
38.42,63.300,0.07933,7.197,0.002
38.50,63.400,0.07949,7.211,0.002
38.56,63.500,0.07966,7.223,0.002
38.63,63.600,0.07983,7.236,0.002
38.69,63.700,0.07995,7.248,0.002
38.75,63.800,0.08008,7.259,0.002
38.83,63.900,0.08024,7.274,0.002
38.89,64.000,0.08037,7.285,0.002
38.96,64.100,0.08053,7.297,0.002
39.02,64.200,0.08066,7.309,0.002
39.08,64.300,0.08078,7.321,0.002
39.14,64.400,0.08095,7.332,0.002
39.19,64.500,0.08107,7.342,0.002
39.27,64.600,0.08120,7.356,0.002
39.33,64.700,0.08132,7.368,0.002
39.40,64.800,0.08149,7.381,0.002
39.47,64.900,0.08161,7.393,0.002
39.56,65.000,0.08178,7.410,0.002
39.62,65.100,0.08190,7.422,0.002
39.69,65.200,0.08207,7.435,0.002
39.77,65.300,0.08220,7.451,0.002
39.85,65.400,0.08236,7.465,0.002
39.92,65.500,0.08253,7.477,0.002
40.00,65.600,0.08265,7.493,0.002
40.08,65.700,0.08282,7.508,0.002
40.16,65.800,0.08299,7.524,0.002
40.24,65.900,0.08315,7.538,0.002
40.31,66.000,0.08328,7.551,0.002
40.41,66.100,0.08344,7.569,0.002
40.47,66.200,0.08361,7.581,0.002
40.56,66.300,0.08377,7.597,0.002
40.62,66.400,0.08390,7.609,0.002
40.70,66.500,0.08407,7.625,0.002
40.78,66.600,0.08423,7.640,0.002
40.86,66.700,0.08440,7.653,0.002
40.96,66.800,0.08456,7.672,0.002
41.05,66.900,0.08477,7.689,0.002
41.14,67.000,0.08494,7.706,0.002
41.26,67.100,0.08515,7.729,0.002
41.34,67.200,0.08531,7.745,0.002
41.44,67.300,0.08552,7.762,0.002
41.54,67.400,0.08573,7.782,0.002
41.66,67.500,0.08594,7.804,0.002
41.77,67.600,0.08614,7.824,0.002
41.88,67.700,0.08635,7.844,0.002
41.98,67.800,0.08656,7.864,0.002
42.09,67.900,0.08677,7.884,0.002
42.21,68.000,0.08697,7.907,0.002
42.30,68.100,0.08718,7.925,0.002
42.40,68.200,0.08739,7.943,0.002
42.51,68.300,0.08760,7.963,0.002
42.61,68.400,0.08781,7.981,0.002
42.71,68.500,0.08801,8.000,0.002
42.79,68.600,0.08822,8.015,0.002
42.89,68.700,0.08839,8.034,0.002
14.86,68.800,0.08860,2.783,0.002
16.66,68.900,0.08876,3.121,0.002
16.89,69.000,0.08893,3.165,0.002
17.00,69.100,0.08909,3.185,0.002
17.11,69.200,0.08922,3.205,0.002
17.25,69.300,0.08938,3.232,0.002
17.36,69.400,0.08955,3.253,0.002
17.48,69.500,0.08968,3.275,0.002
17.57,69.600,0.08984,3.292,0.002
17.66,69.700,0.08997,3.308,0.002
17.74,69.800,0.09013,3.324,0.002
17.84,69.900,0.09026,3.341,0.002
17.94,70.000,0.09038,3.361,0.002
18.01,70.100,0.09051,3.373,0.002
18.09,70.200,0.09067,3.388,0.002
18.17,70.300,0.09080,3.404,0.002
18.23,70.400,0.09092,3.415,0.002
18.30,70.500,0.09109,3.429,0.002
18.39,70.600,0.09125,3.445,0.002
18.46,70.700,0.09138,3.458,0.002
18.51,70.800,0.09155,3.467,0.002
18.60,70.900,0.09167,3.484,0.002
18.68,71.000,0.09184,3.498,0.002
18.75,71.100,0.09200,3.513,0.002
18.81,71.200,0.09213,3.524,0.002
18.90,71.300,0.09229,3.541,0.002
18.97,71.400,0.09246,3.554,0.002
19.02,71.500,0.09258,3.564,0.002
19.08,71.600,0.09275,3.574,0.002
19.14,71.700,0.09292,3.586,0.002
19.22,71.800,0.09308,3.600,0.002
19.27,71.900,0.09325,3.610,0.002
19.36,72.000,0.09337,3.627,0.002
19.41,72.100,0.09354,3.636,0.002
19.47,72.200,0.09371,3.648,0.002
19.54,72.300,0.09387,3.660,0.002
19.60,72.400,0.09408,3.672,0.002
19.66,72.500,0.09425,3.684,0.002
19.75,72.600,0.09441,3.700,0.002
19.82,72.700,0.09462,3.713,0.002
19.88,72.800,0.09479,3.724,0.002
19.96,72.900,0.09499,3.739,0.002
20.03,73.000,0.09520,3.751,0.002
20.11,73.100,0.09541,3.766,0.002
20.18,73.200,0.09562,3.781,0.002
20.26,73.300,0.09583,3.794,0.002
20.34,73.400,0.09603,3.809,0.002
20.38,73.500,0.09624,3.818,0.002
20.45,73.600,0.09645,3.831,0.002
20.52,73.700,0.09666,3.844,0.002
20.58,73.800,0.09686,3.855,0.002
20.66,73.900,0.09707,3.870,0.002
20.72,74.000,0.09728,3.882,0.002
20.79,74.100,0.09749,3.894,0.002
20.84,74.200,0.09765,3.904,0.002
20.90,74.300,0.09786,3.915,0.002
20.94,74.400,0.09803,3.922,0.002
20.99,74.500,0.09819,3.933,0.002
21.03,74.600,0.09836,3.940,0.002
21.08,74.700,0.09853,3.950,0.002
21.12,74.800,0.09869,3.956,0.002
21.18,74.900,0.09882,3.968,0.002
21.22,75.000,0.09898,3.976,0.002
21.26,75.100,0.09911,3.983,0.002
21.29,75.200,0.09928,3.988,0.002
21.33,75.300,0.09940,3.995,0.002
21.36,75.400,0.09957,4.002,0.002
21.41,75.500,0.09969,4.011,0.002
21.44,75.600,0.09982,4.017,0.002
21.48,75.700,0.09998,4.024,0.002
21.52,75.800,0.10011,4.031,0.002
21.55,75.900,0.10023,4.037,0.002
21.62,76.000,0.10040,4.049,0.002
21.64,76.100,0.10052,4.053,0.002
21.68,76.200,0.10065,4.061,0.002
21.72,76.300,0.10081,4.068,0.002
21.75,76.400,0.10094,4.075,0.002
21.79,76.500,0.10110,4.083,0.002
21.84,76.600,0.10123,4.092,0.002
21.89,76.700,0.10139,4.101,0.002
21.93,76.800,0.10156,4.108,0.002
21.97,76.900,0.10169,4.116,0.002
22.02,77.000,0.10185,4.126,0.002
22.05,77.100,0.10202,4.131,0.002
22.11,77.200,0.10218,4.142,0.002
22.14,77.300,0.10231,4.148,0.002
22.19,77.400,0.10247,4.156,0.002
22.22,77.500,0.10260,4.163,0.002
22.27,77.600,0.10277,4.171,0.002
22.31,77.700,0.10293,4.180,0.002
22.36,77.800,0.10310,4.188,0.002
22.41,77.900,0.10326,4.197,0.002
22.46,78.000,0.10343,4.207,0.002
22.48,78.100,0.10360,4.212,0.002
22.55,78.200,0.10376,4.224,0.002
22.61,78.300,0.10397,4.235,0.002
22.69,78.400,0.10418,4.250,0.002
22.72,78.500,0.10434,4.255,0.002
22.78,78.600,0.10455,4.268,0.002
22.85,78.700,0.10476,4.281,0.002
22.91,78.800,0.10497,4.292,0.002
22.97,78.900,0.10522,4.302,0.002
23.02,79.000,0.10543,4.313,0.002
23.09,79.100,0.10563,4.325,0.002
23.17,79.200,0.10584,4.339,0.002
23.21,79.300,0.10609,4.348,0.002
23.26,79.400,0.10630,4.358,0.002
23.31,79.500,0.10651,4.367,0.002
23.37,79.600,0.10667,4.378,0.002
23.42,79.700,0.10688,4.387,0.002
23.47,79.800,0.10709,4.397,0.002
23.51,79.900,0.10725,4.403,0.002
23.55,80.000,0.10742,4.411,0.002
23.57,80.100,0.10759,4.416,0.002
23.61,80.200,0.10775,4.423,0.002
23.64,80.300,0.10792,4.428,0.002
23.67,80.400,0.10808,4.434,0.002
23.71,80.500,0.10821,4.442,0.002
23.74,80.600,0.10838,4.448,0.002
23.76,80.700,0.10850,4.451,0.002
23.80,80.800,0.10867,4.458,0.002
23.85,80.900,0.10879,4.468,0.002
23.87,81.000,0.10892,4.472,0.002
23.90,81.100,0.10904,4.477,0.002
23.93,81.200,0.10921,4.483,0.002
23.97,81.300,0.10933,4.490,0.002
23.99,81.400,0.10946,4.494,0.002
24.03,81.500,0.10958,4.501,0.002
24.07,81.600,0.10975,4.509,0.002
24.10,81.700,0.10987,4.515,0.002
24.15,81.800,0.11000,4.525,0.002
24.19,81.900,0.11016,4.531,0.002
24.23,82.000,0.11029,4.540,0.002
24.26,82.100,0.11045,4.544,0.002
24.29,82.200,0.11058,4.551,0.002
24.35,82.300,0.11074,4.560,0.002
24.39,82.400,0.11087,4.569,0.002
24.43,82.500,0.11104,4.575,0.002
24.46,82.600,0.11120,4.582,0.002
24.51,82.700,0.11133,4.592,0.002
24.55,82.800,0.11149,4.600,0.002
24.60,82.900,0.11166,4.608,0.002
24.63,83.000,0.11178,4.614,0.002
24.67,83.100,0.11195,4.621,0.002
24.71,83.200,0.11212,4.629,0.002
24.75,83.300,0.11228,4.636,0.002
24.81,83.400,0.11241,4.647,0.002
24.85,83.500,0.11257,4.655,0.002
24.89,83.600,0.11274,4.663,0.002
24.94,83.700,0.11291,4.672,0.002
24.98,83.800,0.11307,4.679,0.002
25.04,83.900,0.11328,4.691,0.002
25.09,84.000,0.11345,4.700,0.002
25.15,84.100,0.11365,4.712,0.002
25.22,84.200,0.11386,4.725,0.002
25.29,84.300,0.11407,4.737,0.002
25.34,84.400,0.11424,4.747,0.002
25.41,84.500,0.11448,4.759,0.002
25.47,84.600,0.11469,4.771,0.002
25.53,84.700,0.11490,4.782,0.002
25.60,84.800,0.11511,4.795,0.002
25.65,84.900,0.11532,4.804,0.002
25.70,85.000,0.11552,4.813,0.002
25.76,85.100,0.11573,4.826,0.002
25.79,85.200,0.11594,4.830,0.002
25.82,85.300,0.11615,4.837,0.002
25.89,85.400,0.11631,4.849,0.002
25.93,85.500,0.11652,4.856,0.002
25.97,85.600,0.11669,4.865,0.002
26.01,85.700,0.11685,4.873,0.002
26.04,85.800,0.11702,4.879,0.002
26.08,85.900,0.11719,4.885,0.002
26.10,86.000,0.11735,4.889,0.002
26.15,86.100,0.11752,4.899,0.002
26.18,86.200,0.11764,4.904,0.002
26.21,86.300,0.11781,4.910,0.002
26.25,86.400,0.11798,4.918,0.002
26.31,86.500,0.11810,4.928,0.002
26.33,86.600,0.11827,4.931,0.002
26.37,86.700,0.11839,4.939,0.002
26.40,86.800,0.11852,4.945,0.002
26.43,86.900,0.11864,4.950,0.002
26.46,87.000,0.11881,4.956,0.002
26.49,87.100,0.11893,4.963,0.002
26.52,87.200,0.11906,4.968,0.002
26.55,87.300,0.11918,4.974,0.002
26.59,87.400,0.11935,4.982,0.002
26.64,87.500,0.11947,4.991,0.002
26.68,87.600,0.11964,4.998,0.002
26.72,87.700,0.11976,5.005,0.002
26.74,87.800,0.11993,5.009,0.002
26.79,87.900,0.12005,5.019,0.002
26.84,88.000,0.12022,5.027,0.002
26.88,88.100,0.12034,5.036,0.002
26.93,88.200,0.12051,5.044,0.002
26.95,88.300,0.12068,5.049,0.002
26.99,88.400,0.12080,5.057,0.002
27.06,88.500,0.12097,5.069,0.002
27.09,88.600,0.12109,5.075,0.002
27.13,88.700,0.12126,5.082,0.002
27.19,88.800,0.12142,5.093,0.002
27.22,88.900,0.12155,5.099,0.002
27.26,89.000,0.12172,5.106,0.002
27.30,89.100,0.12188,5.115,0.002
27.34,89.200,0.12201,5.122,0.002
27.38,89.300,0.12217,5.129,0.002
27.43,89.400,0.12234,5.139,0.002
27.49,89.500,0.12250,5.150,0.002
27.52,89.600,0.12267,5.155,0.002
27.59,89.700,0.12284,5.168,0.002
27.64,89.800,0.12305,5.177,0.002
27.70,89.900,0.12321,5.188,0.002
27.77,90.000,0.12342,5.201,0.002
27.81,90.100,0.12363,5.210,0.002
27.88,90.200,0.12379,5.222,0.002
27.95,90.300,0.12400,5.235,0.002
28.00,90.400,0.12421,5.246,0.002
28.06,90.500,0.12442,5.256,0.002
28.10,90.600,0.12462,5.264,0.002
28.18,90.700,0.12483,5.279,0.002
28.22,90.800,0.12504,5.286,0.002
28.28,90.900,0.12525,5.298,0.002
28.34,91.000,0.12546,5.309,0.002
28.38,91.100,0.12562,5.316,0.002
28.44,91.200,0.12583,5.327,0.002
28.50,91.300,0.12600,5.338,0.002
28.54,91.400,0.12620,5.346,0.002
28.58,91.500,0.12637,5.353,0.002
8.60,91.600,0.12654,1.611,0.002
10.36,91.700,0.12670,1.942,0.002
10.59,91.800,0.12687,1.984,0.002
10.67,91.900,0.12699,1.998,0.002
10.75,92.000,0.12716,2.014,0.003
10.84,92.100,0.12733,2.030,0.003
10.93,92.200,0.12745,2.048,0.003
11.00,92.300,0.12762,2.061,0.003
11.07,92.400,0.12774,2.074,0.003
11.14,92.500,0.12787,2.087,0.003
11.21,92.600,0.12799,2.099,0.003
11.28,92.700,0.12816,2.114,0.003
11.35,92.800,0.12828,2.126,0.003
11.39,92.900,0.12841,2.134,0.003
11.45,93.000,0.12853,2.144,0.003
11.51,93.100,0.12870,2.156,0.003
11.58,93.200,0.12882,2.169,0.003
11.63,93.300,0.12895,2.178,0.003
11.68,93.400,0.12911,2.188,0.003
11.71,93.450,0.12915,2.194,0.003