File: data-files/CWRU/1100-05-35A.txt
""
"Test Method","Will_Huddleston_Disks.msm"
"Sample I. D.","1100-5-35A.mss"
"Specimen Number","1"

"Load (N)","Time (s)","Extension (mm)","Stress (MPa)","Strain (mm/mm)"

3.35,0.200,-0.00198,0.630,0.000
3.33,0.300,-0.00198,0.628,0.000
3.33,0.400,-0.00198,0.628,0.000
3.32,0.500,-0.00198,0.625,0.000
3.33,0.600,-0.00198,0.627,0.000
3.35,0.700,-0.00194,0.630,0.000
3.34,0.800,-0.00194,0.629,0.000
3.33,0.900,-0.00194,0.628,0.000
3.35,1.000,-0.00190,0.630,0.000
3.35,1.100,-0.00190,0.631,0.000
3.34,1.200,-0.00186,0.630,0.000
3.35,1.300,-0.00186,0.631,0.000
3.37,1.400,-0.00186,0.634,0.000
3.36,1.500,-0.00181,0.634,0.000
3.39,1.600,-0.00177,0.639,0.000
3.43,1.700,-0.00173,0.645,0.000
3.50,1.800,-0.00165,0.659,0.000
3.58,1.900,-0.00156,0.674,0.000
3.68,2.000,-0.00140,0.693,0.000
3.81,2.100,-0.00119,0.718,0.000
3.93,2.200,-0.00098,0.740,0.000
4.04,2.300,-0.00082,0.760,0.000
4.13,2.400,-0.00061,0.778,0.000
4.19,2.500,-0.00044,0.789,0.000
4.25,2.600,-0.00028,0.801,0.000
4.30,2.700,-0.00011,0.810,0.000
4.36,2.800,0.00006,0.821,0.000
4.39,2.900,0.00022,0.826,0.000
4.42,3.000,0.00035,0.833,0.000
4.46,3.100,0.00051,0.840,0.000
4.50,3.200,0.00064,0.848,0.000
4.52,3.300,0.00076,0.851,0.000
4.56,3.400,0.00093,0.858,0.000
4.58,3.500,0.00105,0.862,0.000
4.61,3.600,0.00118,0.868,0.000
4.65,3.700,0.00130,0.875,0.000
4.70,3.800,0.00147,0.885,0.000
4.69,3.900,0.00159,0.883,0.000
4.72,4.000,0.00172,0.888,0.000
4.75,4.100,0.00184,0.894,0.000
4.78,4.200,0.00197,0.900,0.000
4.81,4.300,0.00209,0.906,0.000
4.82,4.400,0.00226,0.908,0.000
4.86,4.500,0.00238,0.915,0.000
4.86,4.600,0.00251,0.916,0.000
4.91,4.700,0.00267,0.924,0.000
4.94,4.800,0.00280,0.931,0.000
4.95,4.900,0.00296,0.933,0.000
4.99,5.000,0.00313,0.939,0.000
5.02,5.100,0.00326,0.945,0.000
5.04,5.200,0.00342,0.949,0.000
5.07,5.300,0.00355,0.955,0.000
5.10,5.400,0.00371,0.961,0.000
5.11,5.500,0.00384,0.963,0.000
5.15,5.600,0.00400,0.969,0.000
5.17,5.700,0.00417,0.973,0.000
5.19,5.800,0.00434,0.977,0.000
5.22,5.900,0.00446,0.982,0.000
5.25,6.000,0.00463,0.988,0.000
5.27,6.100,0.00479,0.992,0.000
5.31,6.200,0.00496,1.000,0.000
5.34,6.300,0.00513,1.005,0.000
5.36,6.400,0.00529,1.009,0.000
5.39,6.500,0.00546,1.016,0.000
5.42,6.600,0.00562,1.021,0.000
5.47,6.700,0.00583,1.030,0.000
5.49,6.800,0.00600,1.034,0.000
5.55,6.900,0.00621,1.044,0.000
5.56,7.000,0.00641,1.047,0.000
5.60,7.100,0.00662,1.054,0.000
5.63,7.200,0.00683,1.060,0.000
5.67,7.300,0.00704,1.067,0.000
5.72,7.400,0.00724,1.077,0.000
5.75,7.500,0.00745,1.083,0.000
5.79,7.600,0.00766,1.090,0.000
5.83,7.700,0.00787,1.098,0.000
5.86,7.800,0.00808,1.104,0.000
5.89,7.900,0.00828,1.110,0.000
5.93,8.000,0.00849,1.116,0.000
5.96,8.100,0.00870,1.122,0.000
6.00,8.200,0.00887,1.130,0.000
6.02,8.300,0.00907,1.134,0.000
6.05,8.400,0.00924,1.138,0.000
6.10,8.500,0.00941,1.148,0.000
6.10,8.600,0.00957,1.148,0.000
6.13,8.700,0.00974,1.155,0.000
6.17,8.800,0.00990,1.162,0.000
6.18,8.900,0.01003,1.164,0.000
6.20,9.000,0.01020,1.167,0.000
6.23,9.100,0.01036,1.173,0.000
6.25,9.200,0.01049,1.178,0.000
6.28,9.300,0.01065,1.182,0.000
6.31,9.400,0.01078,1.188,0.000
6.32,9.500,0.01090,1.190,0.000
6.33,9.600,0.01107,1.192,0.000
6.37,9.700,0.01119,1.199,0.000
6.39,9.800,0.01132,1.203,0.000
6.41,9.900,0.01148,1.207,0.000
6.44,10.000,0.01161,1.213,0.000
6.47,10.100,0.01177,1.219,0.000
6.50,10.200,0.01190,1.224,0.000
6.52,10.300,0.01207,1.228,0.000
6.54,10.400,0.01219,1.231,0.000
6.57,10.500,0.01236,1.237,0.000
6.60,10.600,0.01248,1.243,0.000
6.62,10.700,0.01265,1.247,0.000
6.64,10.800,0.01281,1.250,0.000
6.67,10.900,0.01294,1.257,0.000
6.70,11.000,0.01310,1.262,0.000
6.72,11.100,0.01327,1.265,0.000
6.74,11.200,0.01344,1.270,0.000
6.77,11.300,0.01356,1.275,0.000
6.80,11.400,0.01373,1.281,0.000
6.82,11.500,0.01389,1.285,0.000
6.84,11.600,0.01406,1.288,0.000
6.87,11.700,0.01423,1.294,0.000
6.91,11.800,0.01435,1.302,0.000
6.93,11.900,0.01452,1.304,0.000
6.97,12.000,0.01473,1.312,0.000
7.00,12.100,0.01489,1.318,0.000
7.02,12.200,0.01506,1.322,0.000
7.06,12.300,0.01527,1.330,0.000
7.10,12.400,0.01543,1.337,0.000
7.13,12.500,0.01564,1.342,0.000
7.17,12.600,0.01581,1.350,0.000
7.20,12.700,0.01601,1.356,0.000
7.24,12.800,0.01622,1.364,0.000
7.27,12.900,0.01643,1.370,0.000
7.32,13.000,0.01664,1.378,0.000
7.37,13.100,0.01684,1.387,0.000
7.40,13.200,0.01709,1.394,0.000
7.44,13.300,0.01730,1.401,0.000
7.47,13.400,0.01747,1.406,0.000
7.50,13.500,0.01768,1.412,0.000
7.54,13.600,0.01788,1.419,0.000
7.57,13.700,0.01809,1.425,0.000
7.61,13.800,0.01830,1.433,0.000
7.62,13.900,0.01847,1.434,0.000
7.66,14.000,0.01863,1.442,0.000
7.67,14.100,0.01884,1.444,0.000
7.70,14.200,0.01901,1.450,0.000
7.73,14.300,0.01913,1.455,0.000
7.74,14.400,0.01930,1.458,0.000
7.76,14.500,0.01946,1.461,0.000
7.79,14.600,0.01959,1.467,0.000
7.81,14.700,0.01975,1.471,0.000
7.84,14.800,0.01992,1.476,0.000
7.85,14.900,0.02004,1.479,0.000
7.88,15.000,0.02017,1.484,0.000
7.91,15.100,0.02034,1.490,0.000
7.93,15.200,0.02046,1.494,0.000
7.95,15.300,0.02058,1.496,0.000
7.97,15.400,0.02075,1.500,0.000
8.00,15.500,0.02088,1.506,0.000
8.01,15.600,0.02100,1.508,0.000
8.03,15.700,0.02112,1.512,0.000
8.06,15.800,0.02129,1.518,0.000
8.09,15.900,0.02142,1.523,0.000
8.13,16.000,0.02158,1.530,0.000
8.14,16.100,0.02175,1.533,0.000
8.17,16.200,0.02187,1.538,0.000
8.20,16.300,0.02204,1.544,0.000
8.22,16.400,0.02216,1.548,0.000
8.24,16.500,0.02233,1.552,0.000
8.28,16.600,0.02245,1.558,0.000
8.30,16.700,0.02262,1.564,0.000
8.33,16.800,0.02279,1.568,0.000
8.34,16.900,0.02291,1.570,0.000
8.39,17.000,0.02308,1.579,0.000
8.40,17.100,0.02324,1.582,0.000
8.43,17.200,0.02341,1.587,0.000
8.46,17.300,0.02353,1.593,0.000
8.48,17.400,0.02370,1.596,0.000
8.49,17.500,0.02387,1.598,0.000
8.51,17.600,0.02403,1.603,0.000
8.55,17.700,0.02420,1.610,0.000
8.58,17.800,0.02437,1.615,0.000
8.61,17.900,0.02457,1.621,0.000
8.65,18.000,0.02474,1.629,0.000
8.70,18.100,0.02495,1.638,0.000
8.73,18.200,0.02511,1.644,0.000
8.79,18.300,0.02536,1.654,0.000
8.80,18.400,0.02557,1.657,0.001
8.85,18.500,0.02578,1.667,0.001
8.90,18.600,0.02599,1.676,0.001
8.94,18.700,0.02619,1.683,0.001
8.97,18.800,0.02640,1.689,0.001
9.01,18.900,0.02665,1.696,0.001
9.04,19.000,0.02686,1.702,0.001
9.09,19.100,0.02707,1.711,0.001
9.13,19.200,0.02727,1.719,0.001
9.16,19.300,0.02748,1.724,0.001
9.19,19.400,0.02765,1.731,0.001
9.21,19.500,0.02786,1.733,0.001
9.24,19.600,0.02802,1.740,0.001
9.25,19.700,0.02819,1.743,0.001
9.29,19.800,0.02836,1.749,0.001
9.32,19.900,0.02852,1.754,0.001
9.34,20.000,0.02869,1.758,0.001
9.36,20.100,0.02881,1.762,0.001
9.37,20.200,0.02898,1.765,0.001
9.38,20.300,0.02910,1.766,0.001
9.41,20.400,0.02927,1.772,0.001
9.45,20.500,0.02939,1.779,0.001
9.45,20.600,0.02956,1.780,0.001
9.46,20.700,0.02969,1.782,0.001
9.49,20.800,0.02981,1.787,0.001
9.52,20.900,0.02993,1.793,0.001
9.54,21.000,0.03010,1.796,0.001
9.56,21.100,0.03023,1.801,0.001
9.59,21.200,0.03035,1.806,0.001
9.62,21.300,0.03052,1.812,0.001
9.62,21.400,0.03064,1.811,0.001
9.67,21.500,0.03077,1.821,0.001
9.68,21.600,0.03093,1.823,0.001
9.72,21.700,0.03106,1.830,0.001
9.74,21.800,0.03122,1.833,0.001
9.77,21.900,0.03139,1.839,0.001
9.79,22.000,0.03151,1.844,0.001
9.83,22.100,0.03168,1.850,0.001
9.84,22.200,0.03180,1.853,0.001
9.89,22.300,0.03197,1.862,0.001
9.92,22.400,0.03214,1.867,0.001
9.94,22.500,0.03226,1.871,0.001
9.97,22.600,0.03243,1.877,0.001
10.00,22.700,0.03259,1.883,0.001
10.02,22.800,0.03272,1.888,0.001
10.06,22.900,0.03288,1.894,0.001
10.09,23.000,0.03305,1.899,0.001
10.11,23.100,0.03322,1.904,0.001
10.15,23.200,0.03338,1.912,0.001
10.17,23.300,0.03355,1.916,0.001
10.20,23.400,0.03372,1.921,0.001
10.25,23.500,0.03388,1.931,0.001
10.28,23.600,0.03405,1.936,0.001
10.32,23.700,0.03426,1.944,0.001
10.35,23.800,0.03446,1.948,0.001
10.39,23.900,0.03463,1.956,0.001
10.45,24.000,0.03484,1.967,0.001
10.47,24.100,0.03505,1.972,0.001
10.52,24.200,0.03525,1.980,0.001
10.56,24.300,0.03550,1.989,0.001
10.60,24.400,0.03571,1.996,0.001
10.63,24.500,0.03592,2.001,0.001
10.67,24.600,0.03613,2.009,0.001
10.71,24.700,0.03633,2.017,0.001
10.74,24.800,0.03654,2.022,0.001
10.77,24.900,0.03675,2.027,0.001
10.81,25.000,0.03692,2.036,0.001
10.85,25.100,0.03712,2.043,0.001
10.89,25.200,0.03733,2.050,0.001
10.91,25.300,0.03750,2.054,0.001
10.93,25.400,0.03766,2.059,0.001
10.97,25.500,0.03783,2.065,0.001
10.98,25.600,0.03800,2.068,0.001
11.00,25.700,0.03812,2.072,0.001
11.02,25.800,0.03829,2.076,0.001
11.03,25.900,0.03845,2.077,0.001
11.06,26.000,0.03858,2.083,0.001
11.08,26.100,0.03874,2.086,0.001
11.10,26.200,0.03887,2.090,0.001
11.13,26.300,0.03899,2.096,0.001
11.15,26.400,0.03916,2.099,0.001
11.18,26.500,0.03928,2.105,0.001
11.19,26.600,0.03941,2.107,0.001
11.22,26.700,0.03958,2.112,0.001
11.25,26.800,0.03970,2.118,0.001
11.27,26.900,0.03982,2.123,0.001
11.30,27.000,0.03995,2.127,0.001
11.30,27.100,0.04012,2.128,0.001
11.34,27.200,0.04024,2.136,0.001
11.37,27.300,0.04041,2.141,0.001
11.40,27.400,0.04053,2.147,0.001
11.43,27.500,0.04070,2.153,0.001
11.46,27.600,0.04082,2.158,0.001
11.49,27.700,0.04099,2.163,0.001
11.52,27.800,0.04115,2.170,0.001
11.56,27.900,0.04128,2.177,0.001
11.58,28.000,0.04145,2.181,0.001
11.61,28.100,0.04161,2.186,0.001
11.64,28.200,0.04174,2.191,0.001
11.67,28.300,0.04190,2.198,0.001
11.70,28.400,0.04207,2.202,0.001
11.73,28.500,0.04219,2.208,0.001
11.76,28.600,0.04236,2.214,0.001
11.81,28.700,0.04253,2.224,0.001
11.84,28.800,0.04269,2.230,0.001
11.86,28.900,0.04282,2.234,0.001
11.90,29.000,0.04298,2.242,0.001
11.94,29.100,0.04315,2.248,0.001
11.98,29.200,0.04332,2.255,0.001
12.01,29.300,0.04352,2.262,0.001
12.04,29.400,0.04369,2.268,0.001
12.09,29.500,0.04386,2.277,0.001
12.12,29.600,0.04406,2.283,0.001
12.16,29.700,0.04423,2.291,0.001
12.20,29.800,0.04444,2.297,0.001
12.24,29.900,0.04465,2.304,0.001
12.28,30.000,0.04485,2.312,0.001
12.31,30.100,0.04506,2.318,0.001
12.37,30.200,0.04527,2.329,0.001
12.40,30.300,0.04548,2.334,0.001
12.43,30.400,0.04564,2.340,0.001
12.46,30.500,0.04585,2.346,0.001
12.50,30.600,0.04606,2.353,0.001
12.53,30.700,0.04627,2.360,0.001
12.57,30.800,0.04643,2.367,0.001
12.61,30.900,0.04664,2.374,0.001
12.64,31.000,0.04681,2.380,0.001
12.67,31.100,0.04697,2.387,0.001
12.69,31.200,0.04714,2.390,0.001
12.72,31.300,0.04730,2.395,0.001
12.75,31.400,0.04747,2.400,0.001
12.76,31.500,0.04764,2.403,0.001
12.79,31.600,0.04780,2.409,0.001
12.83,31.700,0.04793,2.415,0.001
12.84,31.800,0.04809,2.418,0.001
12.87,31.900,0.04822,2.424,0.001
12.88,32.000,0.04834,2.425,0.001
12.91,32.100,0.04851,2.432,0.001
12.95,32.200,0.04863,2.439,0.001
12.98,32.300,0.04876,2.443,0.001
12.99,32.400,0.04893,2.446,0.001
13.02,32.500,0.04905,2.452,0.001
13.05,32.600,0.04917,2.458,0.001
13.07,32.700,0.04930,2.461,0.001
13.10,32.800,0.04947,2.468,0.001
13.13,32.900,0.04959,2.473,0.001
13.14,33.000,0.04972,2.474,0.001
13.18,33.100,0.04988,2.482,0.001
13.19,33.200,0.05001,2.484,0.001
13.23,33.300,0.05017,2.491,0.001
13.25,33.400,0.05030,2.496,0.001
13.28,33.500,0.05046,2.501,0.001
13.31,33.600,0.05059,2.507,0.001
13.34,33.700,0.05071,2.512,0.001
13.38,33.800,0.05088,2.519,0.001
13.41,33.900,0.05104,2.524,0.001
13.43,34.000,0.05117,2.530,0.001
13.46,34.100,0.05134,2.534,0.001
13.47,34.200,0.05146,2.537,0.001
13.51,34.300,0.05163,2.545,0.001
13.54,34.400,0.05175,2.549,0.001
13.56,34.500,0.05192,2.554,0.001
13.59,34.600,0.05208,2.560,0.001
13.63,34.700,0.05225,2.567,0.001
13.67,34.800,0.05237,2.575,0.001
13.70,34.900,0.05254,2.579,0.001
13.73,35.000,0.05271,2.585,0.001
13.78,35.100,0.05287,2.595,0.001
13.81,35.200,0.05308,2.600,0.001
13.85,35.300,0.05325,2.607,0.001
13.90,35.400,0.05346,2.618,0.001
13.94,35.500,0.05366,2.626,0.001
13.98,35.600,0.05387,2.633,0.001
14.03,35.700,0.05408,2.641,0.001
14.07,35.800,0.05429,2.649,0.001
14.10,35.900,0.05449,2.656,0.001
14.16,36.000,0.05470,2.667,0.001
14.20,36.100,0.05491,2.674,0.001
14.25,36.200,0.05512,2.683,0.001
14.29,36.300,0.05533,2.691,0.001
14.34,36.400,0.05553,2.701,0.001
14.37,36.500,0.05574,2.706,0.001
14.42,36.600,0.05591,2.715,0.001
14.44,36.700,0.05611,2.719,0.001
14.48,36.800,0.05628,2.726,0.001
14.51,36.900,0.05645,2.732,0.001
14.54,37.000,0.05665,2.738,0.001
14.56,37.100,0.05678,2.742,0.001
14.59,37.200,0.05695,2.747,0.001
14.61,37.300,0.05711,2.751,0.001
14.64,37.400,0.05724,2.757,0.001
14.66,37.500,0.05740,2.761,0.001
14.69,37.600,0.05753,2.767,0.001
14.72,37.700,0.05769,2.772,0.001
14.73,37.800,0.05782,2.774,0.001
14.75,37.900,0.05794,2.778,0.001
14.79,38.000,0.05807,2.785,0.001
14.81,38.100,0.05823,2.789,0.001
14.84,38.200,0.05836,2.795,0.001
14.86,38.300,0.05848,2.798,0.001
14.88,38.400,0.05865,2.802,0.001
14.90,38.500,0.05877,2.806,0.001
14.92,38.600,0.05890,2.810,0.001
14.97,38.700,0.05907,2.819,0.001
14.99,38.800,0.05919,2.823,0.001
15.01,38.900,0.05936,2.827,0.001
15.04,39.000,0.05948,2.832,0.001
15.06,39.100,0.05965,2.836,0.001
15.10,39.200,0.05977,2.843,0.001
15.13,39.300,0.05994,2.850,0.001
15.16,39.400,0.06006,2.855,0.001
15.20,39.500,0.06023,2.862,0.001
15.23,39.600,0.06039,2.868,0.001
15.27,39.700,0.06056,2.876,0.001
15.30,39.800,0.06069,2.881,0.001
15.33,39.900,0.06085,2.887,0.001
15.34,40.000,0.06102,2.889,0.001
15.38,40.100,0.06118,2.897,0.001
15.43,40.200,0.06131,2.905,0.001
15.46,40.300,0.06148,2.911,0.001
15.47,40.400,0.06164,2.913,0.001
15.53,40.500,0.06181,2.924,0.001
15.55,40.600,0.06197,2.928,0.001
15.59,40.700,0.06214,2.937,0.001
15.63,40.800,0.06231,2.943,0.001
15.67,40.900,0.06251,2.951,0.001
15.71,41.000,0.06268,2.959,0.001
15.75,41.100,0.06289,2.966,0.001
15.80,41.200,0.06310,2.975,0.001
15.85,41.300,0.06330,2.985,0.001
15.88,41.400,0.06351,2.991,0.001
15.93,41.500,0.06372,3.000,0.001
15.96,41.600,0.06393,3.006,0.001
16.01,41.700,0.06413,3.015,0.001
16.08,41.800,0.06438,3.028,0.001
16.12,41.900,0.06459,3.035,0.001
16.15,42.000,0.06480,3.042,0.001
16.20,42.100,0.06501,3.051,0.001
16.23,42.200,0.06517,3.057,0.001
16.28,42.300,0.06538,3.066,0.001
16.29,42.400,0.06555,3.068,0.001
16.33,42.500,0.06576,3.074,0.001
16.36,42.600,0.06592,3.082,0.001
16.40,42.700,0.06609,3.089,0.001
16.42,42.800,0.06625,3.093,0.001
16.45,42.900,0.06642,3.097,0.001
16.48,43.000,0.06659,3.104,0.001
16.52,43.100,0.06671,3.110,0.001
16.53,43.200,0.06688,3.112,0.001
16.55,43.300,0.06700,3.116,0.001
16.58,43.400,0.06717,3.121,0.001
16.60,43.500,0.06729,3.126,0.001
16.62,43.600,0.06742,3.130,0.001
16.65,43.700,0.06758,3.135,0.001
16.67,43.800,0.06771,3.139,0.001
16.70,43.900,0.06783,3.144,0.001
16.73,44.000,0.06800,3.151,0.001
16.75,44.100,0.06812,3.154,0.001
16.77,44.200,0.06825,3.158,0.001
16.81,44.300,0.06842,3.166,0.001
16.84,44.400,0.06854,3.172,0.001
16.86,44.500,0.06871,3.175,0.001
16.88,44.600,0.06883,3.179,0.001
16.93,44.700,0.06900,3.188,0.001
16.94,44.800,0.06912,3.190,0.001
16.98,44.900,0.06929,3.198,0.001
17.01,45.000,0.06945,3.204,0.001
17.05,45.100,0.06962,3.211,0.001
17.08,45.200,0.06974,3.216,0.001
17.10,45.300,0.06991,3.220,0.001
17.16,45.400,0.07008,3.231,0.001
17.18,45.500,0.07024,3.235,0.001
17.22,45.600,0.07037,3.243,0.001
17.26,45.700,0.07053,3.250,0.001
17.28,45.800,0.07070,3.253,0.001
17.32,45.900,0.07087,3.261,0.001
17.36,46.000,0.07099,3.268,0.001
17.40,46.100,0.07116,3.276,0.001
17.42,46.200,0.07132,3.280,0.001
17.46,46.300,0.07153,3.287,0.001
17.50,46.400,0.07170,3.295,0.001
17.53,46.500,0.07186,3.300,0.001
17.58,46.600,0.07207,3.310,0.001
17.62,46.700,0.07224,3.318,0.001
17.67,46.800,0.07245,3.327,0.001
17.72,46.900,0.07265,3.336,0.001
17.76,47.000,0.07286,3.345,0.001
17.82,47.100,0.07307,3.355,0.001
17.86,47.200,0.07328,3.363,0.001
17.90,47.300,0.07348,3.371,0.001
17.95,47.400,0.07369,3.380,0.001
17.99,47.500,0.07390,3.388,0.001
18.02,47.600,0.07411,3.394,0.001
18.07,47.700,0.07432,3.403,0.001
18.09,47.800,0.07452,3.407,0.001
18.13,47.900,0.07469,3.413,0.001
18.16,48.000,0.07490,3.419,0.001
18.21,48.100,0.07506,3.429,0.001
18.23,48.200,0.07523,3.432,0.001
18.26,48.300,0.07540,3.439,0.001
18.29,48.400,0.07560,3.445,0.001
18.32,48.500,0.07573,3.449,0.001
18.33,48.600,0.07590,3.453,0.001
18.36,48.700,0.07606,3.456,0.001
18.39,48.800,0.07623,3.462,0.002
18.40,48.900,0.07635,3.465,0.002
18.44,49.000,0.07652,3.473,0.002
18.47,49.100,0.07664,3.478,0.002
18.48,49.200,0.07681,3.480,0.002
18.51,49.300,0.07693,3.485,0.002
18.53,49.400,0.07710,3.489,0.002
18.55,49.500,0.07723,3.493,0.002
18.58,49.600,0.07735,3.499,0.002
18.61,49.700,0.07752,3.504,0.002
18.63,49.800,0.07764,3.509,0.002
18.67,49.900,0.07777,3.516,0.002
18.71,50.000,0.07793,3.522,0.002
18.73,50.100,0.07806,3.527,0.002
18.75,50.200,0.07818,3.531,0.002
18.79,50.300,0.07835,3.538,0.002
18.82,50.400,0.07847,3.544,0.002
18.84,50.500,0.07864,3.548,0.002
18.89,50.600,0.07876,3.556,0.002
18.91,50.700,0.07893,3.562,0.002
18.94,50.800,0.07910,3.567,0.002
18.98,50.900,0.07926,3.575,0.002
19.00,51.000,0.07939,3.579,0.002
19.04,51.100,0.07955,3.586,0.002
19.07,51.200,0.07972,3.591,0.002
19.11,51.300,0.07984,3.599,0.002
19.16,51.400,0.08001,3.608,0.002
19.18,51.500,0.08018,3.612,0.002
19.22,51.600,0.08034,3.620,0.002
19.24,51.700,0.08047,3.623,0.002
19.29,51.800,0.08063,3.632,0.002
19.32,51.900,0.08080,3.638,0.002
19.36,52.000,0.08097,3.645,0.002
19.40,52.100,0.08113,3.652,0.002
19.44,52.200,0.08134,3.660,0.002
19.49,52.300,0.08151,3.670,0.002
19.53,52.400,0.08171,3.677,0.002
19.57,52.500,0.08192,3.685,0.002
19.64,52.600,0.08213,3.698,0.002
19.68,52.700,0.08234,3.706,0.002
19.73,52.800,0.08254,3.715,0.002
19.77,52.900,0.08275,3.723,0.002
19.82,53.000,0.08296,3.733,0.002
19.87,53.100,0.08317,3.742,0.002
19.91,53.200,0.08342,3.749,0.002
19.97,53.300,0.08362,3.760,0.002
20.00,53.400,0.08383,3.766,0.002
20.04,53.500,0.08400,3.774,0.002
20.08,53.600,0.08421,3.781,0.002
20.10,53.700,0.08437,3.786,0.002
20.13,53.800,0.08458,3.791,0.002
20.18,53.900,0.08475,3.799,0.002
20.22,54.000,0.08491,3.808,0.002
20.25,54.100,0.08508,3.813,0.002
20.26,54.200,0.08525,3.815,0.002
20.29,54.300,0.08537,3.820,0.002
20.32,54.400,0.08554,3.826,0.002
20.35,54.500,0.08566,3.832,0.002
20.37,54.600,0.08583,3.835,0.002
20.40,54.700,0.08595,3.840,0.002
20.43,54.800,0.08612,3.847,0.002
20.45,54.900,0.08624,3.851,0.002
20.47,55.000,0.08637,3.855,0.002
20.50,55.100,0.08653,3.860,0.002
20.53,55.200,0.08666,3.866,0.002
20.56,55.300,0.08678,3.871,0.002
20.59,55.400,0.08691,3.877,0.002
20.60,55.500,0.08703,3.880,0.002
20.64,55.600,0.08716,3.886,0.002
20.69,55.700,0.08732,3.895,0.002
20.71,55.800,0.08745,3.899,0.002
20.75,55.900,0.08761,3.907,0.002
20.78,56.000,0.08774,3.913,0.002
20.74,56.100,0.08790,3.906,0.002
20.74,56.200,0.08803,3.906,0.002
20.76,56.300,0.08820,3.909,0.002
20.79,56.400,0.08832,3.915,0.002
20.83,56.500,0.08849,3.922,0.002
20.86,56.600,0.08861,3.928,0.002
20.89,56.700,0.08878,3.935,0.002
20.93,56.800,0.08894,3.941,0.002
20.97,56.900,0.08911,3.948,0.002
21.00,57.000,0.08923,3.954,0.002
21.04,57.100,0.08940,3.962,0.002
21.08,57.200,0.08957,3.969,0.002
21.11,57.300,0.08973,3.975,0.002
21.15,57.400,0.08990,3.982,0.002
21.19,57.500,0.09007,3.990,0.002
21.22,57.600,0.09023,3.995,0.002
21.26,57.700,0.09040,4.004,0.002
21.31,57.800,0.09056,4.012,0.002
21.36,57.900,0.09073,4.022,0.002
21.39,58.000,0.09090,4.029,0.002
21.45,58.100,0.09110,4.039,0.002
21.50,58.200,0.09131,4.049,0.002
21.55,58.300,0.09148,4.058,0.002
21.60,58.400,0.09169,4.068,0.002
21.66,58.500,0.09189,4.078,0.002
21.71,58.600,0.09214,4.089,0.002
21.77,58.700,0.09235,4.099,0.002
21.81,58.800,0.09256,4.106,0.002
21.86,58.900,0.09277,4.116,0.002
21.90,59.000,0.09297,4.124,0.002
21.96,59.100,0.09318,4.136,0.002
21.99,59.200,0.09335,4.140,0.002
22.03,59.300,0.09356,4.148,0.002
22.03,59.400,0.09376,4.148,0.002
22.06,59.500,0.09393,4.154,0.002
22.09,59.600,0.09414,4.160,0.002
22.11,59.700,0.09430,4.164,0.002
22.16,59.800,0.09447,4.173,0.002
22.18,59.900,0.09464,4.176,0.002
22.20,60.000,0.09476,4.181,0.002
22.25,60.100,0.09493,4.189,0.002
22.26,60.200,0.09509,4.191,0.002
22.30,60.300,0.09526,4.199,0.002
22.32,60.400,0.09538,4.203,0.002
22.36,60.500,0.09555,4.210,0.002
22.36,60.600,0.09568,4.211,0.002
22.40,60.700,0.09580,4.218,0.002
22.42,60.800,0.09593,4.222,0.002
22.44,60.900,0.09609,4.226,0.002
22.48,61.000,0.09622,4.234,0.002
22.49,61.100,0.09634,4.236,0.002
22.54,61.200,0.09647,4.244,0.002
22.55,61.300,0.09663,4.247,0.002
22.61,61.400,0.09676,4.257,0.002
22.61,61.500,0.09688,4.258,0.002
22.66,61.600,0.09705,4.266,0.002
22.69,61.700,0.09717,4.272,0.002
22.72,61.800,0.09734,4.278,0.002
22.75,61.900,0.09746,4.283,0.002
22.79,62.000,0.09763,4.292,0.002
22.83,62.100,0.09775,4.298,0.002
22.86,62.200,0.09792,4.305,0.002
22.88,62.300,0.09809,4.309,0.002
22.92,62.400,0.09821,4.316,0.002
22.95,62.500,0.09838,4.322,0.002
22.98,62.600,0.09854,4.328,0.002
23.02,62.700,0.09867,4.334,0.002
23.06,62.800,0.09883,4.343,0.002
23.09,62.900,0.09900,4.347,0.002
23.13,63.000,0.09917,4.355,0.002
23.16,63.100,0.09929,4.361,0.002
23.21,63.200,0.09946,4.371,0.002
23.23,63.300,0.09962,4.375,0.002
23.27,63.400,0.09979,4.382,0.002
23.32,63.500,0.09996,4.391,0.002
23.36,63.600,0.10016,4.398,0.002
23.39,63.700,0.10033,4.405,0.002
23.44,63.800,0.10054,4.414,0.002
23.49,63.900,0.10070,4.423,0.002
23.54,64.000,0.10091,4.433,0.002
23.58,64.100,0.10112,4.441,0.002
23.63,64.200,0.10133,4.449,0.002
23.68,64.300,0.10154,4.460,0.002
23.74,64.400,0.10174,4.470,0.002
23.78,64.500,0.10195,4.478,0.002
23.84,64.600,0.10216,4.490,0.002
23.89,64.700,0.10237,4.498,0.002
23.93,64.800,0.10257,4.506,0.002
23.97,64.900,0.10278,4.514,0.002
24.02,65.000,0.10295,4.523,0.002
24.07,65.100,0.10316,4.533,0.002
24.09,65.200,0.10332,4.537,0.002
24.13,65.300,0.10353,4.544,0.002
24.17,65.400,0.10370,4.551,0.002
24.19,65.500,0.10386,4.556,0.002
24.25,65.600,0.10403,4.567,0.002
24.27,65.700,0.10419,4.571,0.002
24.30,65.800,0.10432,4.576,0.002
24.34,65.900,0.10449,4.583,0.002
24.38,66.000,0.10465,4.590,0.002
24.40,66.100,0.10478,4.595,0.002
24.41,66.200,0.10494,4.597,0.002
24.45,66.300,0.10507,4.603,0.002
24.48,66.400,0.10519,4.609,0.002
24.50,66.500,0.10536,4.613,0.002
24.53,66.600,0.10548,4.620,0.002
24.55,66.700,0.10561,4.623,0.002
24.58,66.800,0.10573,4.629,0.002
24.62,66.900,0.10590,4.636,0.002
24.65,67.000,0.10602,4.641,0.002
24.69,67.100,0.10615,4.648,0.002
24.70,67.200,0.10631,4.652,0.002
24.74,67.300,0.10644,4.658,0.002
24.77,67.400,0.10656,4.664,0.002
24.80,67.500,0.10673,4.669,0.002
24.83,67.600,0.10685,4.676,0.002
24.89,67.700,0.10702,4.686,0.002
24.91,67.800,0.10719,4.691,0.002
24.96,67.900,0.10731,4.700,0.002
24.99,68.000,0.10748,4.706,0.002
25.01,68.100,0.10760,4.710,0.002
25.05,68.200,0.10777,4.718,0.002
25.09,68.300,0.10793,4.725,0.002
25.14,68.400,0.10806,4.734,0.002
25.16,68.500,0.10823,4.738,0.002
25.21,68.600,0.10839,4.746,0.002
25.24,68.700,0.10852,4.753,0.002
25.28,68.800,0.10868,4.760,0.002
25.31,68.900,0.10885,4.767,0.002
25.36,69.000,0.10902,4.775,0.002
25.40,69.100,0.10914,4.782,0.002
25.44,69.200,0.10931,4.790,0.002
25.50,69.300,0.10951,4.802,0.002
25.54,69.400,0.10968,4.810,0.002
25.59,69.500,0.10985,4.819,0.002
25.65,69.600,0.11005,4.831,0.002
25.72,69.700,0.11026,4.844,0.002
25.77,69.800,0.11047,4.853,0.002
25.82,69.900,0.11068,4.862,0.002
25.89,70.000,0.11089,4.874,0.002
25.94,70.100,0.11113,4.885,0.002
25.99,70.200,0.11134,4.895,0.002
26.04,70.300,0.11155,4.903,0.002
26.09,70.400,0.11176,4.913,0.002
26.15,70.500,0.11197,4.924,0.002
26.19,70.600,0.11217,4.931,0.002
26.23,70.700,0.11238,4.940,0.002
26.29,70.800,0.11255,4.950,0.002
26.33,70.900,0.11276,4.959,0.002
26.36,71.000,0.11292,4.965,0.002
26.39,71.100,0.11309,4.969,0.002
26.42,71.200,0.11325,4.974,0.002
26.46,71.300,0.11342,4.982,0.002
26.49,71.400,0.11359,4.988,0.002
26.53,71.500,0.11375,4.996,0.002
26.54,71.600,0.11388,4.997,0.002
26.57,71.700,0.11404,5.003,0.002
26.61,71.800,0.11417,5.010,0.002
26.63,71.900,0.11429,5.014,0.002
26.67,72.000,0.11446,5.022,0.002
26.68,72.100,0.11458,5.024,0.002
26.72,72.200,0.11475,5.031,0.002
26.75,72.300,0.11487,5.036,0.002
26.78,72.400,0.11500,5.042,0.002
26.81,72.500,0.11512,5.048,0.002
26.84,72.600,0.11529,5.054,0.002
26.87,72.700,0.11541,5.060,0.002
26.91,72.800,0.11554,5.068,0.002
26.95,72.900,0.11571,5.074,0.002
26.98,73.000,0.11583,5.080,0.002
27.01,73.100,0.11600,5.087,0.002
27.07,73.200,0.11612,5.097,0.002
27.09,73.300,0.11629,5.102,0.002
27.14,73.400,0.11645,5.110,0.002
27.16,73.500,0.11658,5.115,0.002
27.20,73.600,0.11674,5.121,0.002
27.25,73.700,0.11691,5.131,0.002
27.29,73.800,0.11708,5.138,0.002
27.32,73.900,0.11720,5.144,0.002
27.37,74.000,0.11737,5.153,0.002
27.40,74.100,0.11753,5.160,0.002
27.44,74.200,0.11770,5.167,0.002
27.47,74.300,0.11787,5.173,0.002
27.52,74.400,0.11803,5.183,0.002
27.56,74.500,0.11816,5.189,0.002
27.60,74.600,0.11832,5.198,0.002
27.64,74.700,0.11849,5.205,0.002
27.69,74.800,0.11866,5.214,0.002
27.72,74.900,0.11882,5.220,0.002
27.77,75.000,0.11903,5.229,0.002
27.81,75.100,0.11920,5.237,0.002
27.88,75.200,0.11940,5.249,0.002
27.92,75.300,0.11961,5.257,0.002
27.97,75.400,0.11982,5.267,0.002
28.00,75.500,0.12003,5.273,0.002
28.05,75.600,0.12024,5.283,0.002
28.12,75.700,0.12044,5.295,0.002
28.17,75.800,0.12069,5.304,0.002
28.19,75.900,0.12090,5.309,0.002
28.22,76.000,0.12111,5.313,0.002
28.26,76.100,0.12132,5.322,0.002
28.28,76.200,0.12152,5.326,0.002
28.29,76.300,0.12173,5.327,0.002
28.28,76.400,0.12194,5.325,0.002
28.27,76.500,0.12211,5.323,0.002
28.26,76.600,0.12231,5.322,0.002
28.25,76.700,0.12248,5.320,0.002
28.24,76.800,0.12265,5.318,0.002
28.23,76.900,0.12281,5.317,0.002
28.20,77.000,0.12298,5.311,0.002
28.17,77.100,0.12314,5.305,0.002
28.11,77.200,0.12331,5.294,0.002
28.04,77.300,0.12344,5.281,0.002
27.96,77.400,0.12360,5.265,0.002
27.82,77.500,0.12373,5.238,0.002
26.88,77.600,0.12389,5.061,0.002
26.38,77.700,0.12402,4.968,0.002
26.15,77.800,0.12418,4.924,0.002
25.96,77.900,0.12431,4.888,0.002
25.80,78.000,0.12443,4.858,0.002
25.67,78.100,0.12460,4.833,0.002
25.51,78.200,0.12472,4.804,0.002
25.33,78.300,0.12485,4.770,0.002
25.18,78.400,0.12501,4.742,0.002
25.09,78.500,0.12514,4.725,0.002
24.98,78.600,0.12531,4.704,0.002
24.86,78.700,0.12543,4.682,0.002
24.77,78.800,0.12560,4.664,0.002
24.70,78.900,0.12572,4.650,0.002
22.69,79.000,0.12589,4.273,0.002
13.67,79.100,0.12605,2.573,0.002
13.79,79.200,0.12618,2.597,0.002
13.84,79.300,0.12634,2.607,0.002
13.88,79.400,0.12651,2.614,0.002
13.94,79.500,0.12668,2.624,0.002
13.97,79.600,0.12684,2.631,0.002
14.02,79.700,0.12697,2.640,0.002
14.07,79.800,0.12713,2.649,0.003
14.11,79.900,0.12730,2.657,0.003
14.15,80.000,0.12747,2.665,0.003
14.20,80.100,0.12763,2.675,0.003
14.25,80.200,0.12780,2.683,0.003
14.28,80.300,0.12796,2.690,0.003
14.35,80.400,0.12813,2.701,0.003
14.39,80.500,0.12830,2.710,0.003
14.45,80.600,0.12846,2.722,0.003
14.48,80.700,0.12867,2.727,0.003
14.54,80.800,0.12884,2.738,0.003
14.60,80.900,0.12905,2.749,0.003
14.64,81.000,0.12925,2.757,0.003
14.69,81.100,0.12946,2.767,0.003
14.76,81.200,0.12967,2.779,0.003
14.82,81.300,0.12988,2.790,0.003
14.85,81.400,0.13008,2.796,0.003
14.89,81.500,0.13025,2.804,0.003
14.96,81.600,0.13046,2.817,0.003
14.98,81.700,0.13067,2.822,0.003
15.03,81.800,0.13087,2.831,0.003
15.09,81.900,0.13108,2.842,0.003
15.12,82.000,0.13129,2.847,0.003
15.16,82.100,0.13146,2.855,0.003
15.19,82.200,0.13166,2.861,0.003
15.23,82.300,0.13183,2.868,0.003
15.26,82.400,0.13200,2.873,0.003
15.29,82.500,0.13216,2.880,0.003
15.33,82.600,0.13233,2.887,0.003
15.35,82.700,0.13249,2.891,0.003
15.38,82.800,0.13266,2.896,0.003
15.40,82.900,0.13279,2.900,0.003
15.42,83.000,0.13295,2.904,0.003
15.45,83.100,0.13308,2.910,0.003
15.46,83.200,0.13324,2.912,0.003
15.50,83.300,0.13337,2.919,0.003
15.52,83.400,0.13353,2.922,0.003
15.53,83.500,0.13366,2.925,0.003
15.57,83.600,0.13378,2.933,0.003
15.58,83.700,0.13391,2.933,0.003
15.61,83.800,0.13407,2.939,0.003
15.62,83.900,0.13420,2.942,0.003
15.64,84.000,0.13432,2.946,0.003
15.67,84.100,0.13445,2.951,0.003
15.69,84.200,0.13461,2.955,0.003
15.73,84.300,0.13474,2.963,0.003
15.74,84.400,0.13486,2.964,0.003
15.76,84.500,0.13503,2.968,0.003
15.80,84.600,0.13515,2.976,0.003
15.82,84.700,0.13532,2.979,0.003
15.86,84.800,0.13544,2.987,0.003
15.88,84.900,0.13561,2.990,0.003
15.91,85.000,0.13578,2.996,0.003
15.93,85.100,0.13590,3.000,0.003
15.98,85.200,0.13607,3.009,0.003
16.01,85.300,0.13623,3.015,0.003
16.03,85.400,0.13636,3.018,0.003
16.05,85.500,0.13653,3.023,0.003
16.09,85.600,0.13669,3.029,0.003
16.10,85.700,0.13686,3.031,0.003
16.13,85.800,0.13702,3.037,0.003
16.14,85.900,0.13715,3.040,0.003
16.18,86.000,0.13736,3.047,0.003
16.21,86.100,0.13748,3.052,0.003
16.24,86.200,0.13769,3.058,0.003
16.26,86.300,0.13786,3.061,0.003
16.29,86.400,0.13802,3.067,0.003
16.32,86.500,0.13819,3.073,0.003
16.35,86.600,0.13835,3.078,0.003
16.37,86.700,0.13852,3.082,0.003
16.40,86.800,0.13873,3.087,0.003
16.44,86.900,0.13894,3.096,0.003
16.47,87.000,0.13910,3.101,0.003
16.49,87.100,0.13931,3.105,0.003
16.53,87.200,0.13952,3.112,0.003
16.57,87.300,0.13973,3.120,0.003
16.60,87.400,0.13993,3.126,0.003
16.63,87.500,0.14014,3.131,0.003
16.65,87.600,0.14031,3.136,0.003
16.69,87.700,0.14051,3.142,0.003
16.71,87.800,0.14072,3.147,0.003
16.74,87.900,0.14093,3.152,0.003
16.76,88.000,0.14110,3.155,0.003
16.80,88.100,0.14126,3.163,0.003
16.81,88.200,0.14147,3.165,0.003
16.80,88.300,0.14164,3.164,0.003
16.83,88.400,0.14176,3.170,0.003
16.86,88.500,0.14193,3.175,0.003
16.88,88.600,0.14209,3.178,0.003
16.88,88.700,0.14226,3.178,0.003
16.91,88.800,0.14238,3.185,0.003
16.91,88.900,0.14255,3.185,0.003
16.93,89.000,0.14268,3.189,0.003
16.97,89.100,0.14280,3.195,0.003
16.96,89.200,0.14297,3.194,0.003
16.98,89.300,0.14309,3.198,0.003
16.99,89.400,0.14322,3.200,0.003
17.02,89.500,0.14338,3.205,0.003
17.02,89.600,0.14351,3.206,0.003
17.03,89.700,0.14363,3.207,0.003
17.05,89.800,0.14376,3.211,0.003
17.07,89.900,0.14388,3.215,0.003
17.09,90.000,0.14405,3.218,0.003
17.12,90.100,0.14417,3.223,0.003
17.14,90.200,0.14430,3.227,0.003
17.16,90.300,0.14446,3.231,0.003
17.18,90.400,0.14463,3.236,0.003
17.20,90.500,0.14475,3.240,0.003
17.22,90.600,0.14492,3.242,0.003
17.24,90.700,0.14504,3.247,0.003
17.26,90.800,0.14521,3.251,0.003
17.30,90.900,0.14534,3.257,0.003
17.32,91.000,0.14550,3.262,0.003
17.34,91.100,0.14567,3.266,0.003
17.35,91.200,0.14579,3.267,0.003
17.39,91.300,0.14596,3.274,0.003
17.40,91.400,0.14612,3.277,0.003
17.41,91.500,0.14629,3.278,0.003
17.44,91.600,0.14646,3.284,0.003
17.47,91.700,0.14662,3.289,0.003
17.49,91.800,0.14679,3.294,0.003
17.51,91.900,0.14696,3.298,0.003
17.55,92.000,0.14712,3.304,0.003
17.57,92.100,0.14729,3.308,0.003
17.60,92.200,0.14750,3.315,0.003
17.62,92.300,0.14766,3.317,0.003
17.67,92.400,0.14787,3.328,0.003
17.69,92.500,0.14808,3.331,0.003
17.73,92.600,0.14829,3.338,0.003
17.75,92.700,0.14849,3.343,0.003
17.77,92.800,0.14870,3.346,0.003
17.81,92.900,0.14891,3.353,0.003
17.85,93.000,0.14912,3.361,0.003
17.88,93.100,0.14932,3.366,0.003
17.89,93.200,0.14957,3.369,0.003
17.93,93.300,0.14978,3.377,0.003
17.94,93.400,0.14995,3.378,0.003
17.97,93.500,0.15016,3.384,0.003
17.98,93.600,0.15036,3.386,0.003
18.01,93.700,0.15053,3.391,0.003
18.03,93.800,0.15074,3.394,0.003
18.04,93.900,0.15090,3.396,0.003
18.05,94.000,0.15107,3.400,0.003
18.06,94.100,0.15124,3.400,0.003
18.08,94.200,0.15140,3.404,0.003
18.10,94.300,0.15153,3.408,0.003
18.12,94.400,0.15169,3.412,0.003
18.12,94.500,0.15186,3.412,0.003
18.12,94.600,0.15198,3.412,0.003
18.15,94.700,0.15215,3.417,0.003
18.14,94.800,0.15227,3.416,0.003
18.15,94.900,0.15240,3.418,0.003
18.17,95.000,0.15257,3.421,0.003
18.17,95.100,0.15269,3.422,0.003
18.17,95.200,0.15282,3.421,0.003
18.18,95.300,0.15294,3.423,0.003
18.20,95.400,0.15311,3.428,0.003
18.23,95.500,0.15323,3.432,0.003
18.22,95.600,0.15340,3.432,0.003
18.25,95.700,0.15352,3.437,0.003
18.25,95.800,0.15365,3.437,0.003
18.27,95.900,0.15381,3.440,0.003
18.30,96.000,0.15394,3.445,0.003
18.31,96.100,0.15410,3.448,0.003
18.34,96.200,0.15423,3.453,0.003
18.36,96.300,0.15439,3.456,0.003
18.38,96.400,0.15456,3.462,0.003
18.39,96.500,0.15469,3.463,0.003
18.41,96.600,0.15485,3.466,0.003
18.43,96.700,0.15502,3.471,0.003
18.45,96.800,0.15514,3.474,0.003
18.47,96.900,0.15531,3.478,0.003
18.49,97.000,0.15547,3.482,0.003
18.50,97.100,0.15564,3.484,0.003
18.51,97.200,0.15581,3.486,0.003
18.54,97.300,0.15597,3.490,0.003
18.57,97.400,0.15614,3.498,0.003
18.59,97.500,0.15631,3.501,0.003
18.62,97.600,0.15643,3.505,0.003
18.65,97.700,0.15664,3.511,0.003
18.67,97.800,0.15680,3.517,0.003
18.70,97.900,0.15697,3.521,0.003
18.72,98.000,0.15718,3.526,0.003
18.76,98.100,0.15734,3.533,0.003
18.80,98.200,0.15755,3.539,0.003
18.84,98.300,0.15776,3.547,0.003
18.86,98.400,0.15797,3.551,0.003
18.89,98.500,0.15818,3.556,0.003
18.91,98.600,0.15838,3.560,0.003
18.95,98.700,0.15859,3.567,0.003
18.96,98.800,0.15880,3.570,0.003
18.99,98.900,0.15901,3.577,0.003
19.01,99.000,0.15921,3.580,0.003
19.00,99.100,0.15938,3.579,0.003
19.04,99.200,0.15959,3.585,0.003
19.06,99.300,0.15980,3.589,0.003
19.09,99.400,0.15996,3.594,0.003
19.09,99.500,0.16017,3.594,0.003
19.09,99.600,0.16034,3.595,0.003
19.09,99.700,0.16050,3.595,0.003
19.09,99.800,0.16067,3.595,0.003
19.11,99.900,0.16084,3.598,0.003
19.10,100.000,0.16096,3.596,0.003
19.11,100.100,0.16113,3.598,0.003
19.11,100.200,0.16125,3.599,0.003
19.12,100.300,0.16142,3.601,0.003
19.12,100.400,0.16154,3.600,0.003
19.13,100.500,0.16171,3.602,0.003
19.14,100.600,0.16183,3.603,0.003
19.13,100.700,0.16196,3.601,0.003
19.13,100.800,0.16212,3.601,0.003
19.12,100.900,0.16225,3.600,0.003
19.10,101.000,0.16237,3.597,0.003
19.09,101.100,0.16250,3.595,0.003
19.09,101.200,0.16266,3.594,0.003
19.05,101.300,0.16279,3.588,0.003
19.01,101.400,0.16291,3.580,0.003
18.97,101.500,0.16304,3.571,0.003
18.90,101.600,0.16320,3.560,0.003
18.80,101.700,0.16333,3.541,0.003
18.64,101.800,0.16349,3.510,0.003
18.46,101.900,0.16362,3.476,0.003
18.18,102.000,0.16379,3.424,0.003
17.86,102.100,0.16395,3.363,0.003
17.67,102.200,0.16408,3.327,0.003
17.55,102.300,0.16424,3.304,0.003
17.45,102.400,0.16437,3.286,0.003
17.40,102.500,0.16453,3.277,0.003
17.38,102.600,0.16470,3.272,0.003
12.70,102.700,0.16487,2.391,0.003
13.19,102.800,0.16499,2.483,0.003
13.22,102.900,0.16516,2.489,0.003
13.23,103.000,0.16532,2.491,0.003
13.23,103.100,0.16549,2.492,0.003
13.24,103.200,0.16566,2.494,0.003
13.27,103.300,0.16582,2.498,0.003
13.28,103.400,0.16599,2.501,0.003
13.29,103.500,0.16615,2.503,0.003
13.31,103.600,0.16632,2.507,0.003
13.32,103.700,0.16649,2.509,0.003
13.36,103.800,0.16669,2.516,0.003
13.39,103.900,0.16690,2.522,0.003
13.41,104.000,0.16707,2.525,0.003
13.42,104.100,0.16728,2.527,0.003
13.45,104.200,0.16748,2.533,0.003
13.46,104.300,0.16773,2.535,0.003
13.46,104.400,0.16794,2.535,0.003
13.45,104.500,0.16815,2.532,0.003
13.45,104.600,0.16836,2.533,0.003
13.39,104.700,0.16856,2.521,0.003
13.30,104.800,0.16877,2.504,0.003
13.19,104.900,0.16894,2.483,0.003
13.08,105.000,0.16915,2.463,0.003
12.95,105.100,0.16935,2.439,0.003
12.85,105.200,0.16952,2.419,0.003
12.73,105.300,0.16973,2.397,0.003
12.59,105.400,0.16989,2.370,0.003
12.42,105.500,0.17006,2.339,0.003
12.22,105.600,0.17023,2.301,0.003
12.00,105.700,0.17039,2.260,0.003
10.69,105.800,0.17056,2.013,0.003
7.61,105.900,0.17068,1.434,0.003
7.31,106.000,0.17081,1.377,0.003
7.15,106.100,0.17098,1.346,0.003
7.02,106.200,0.17114,1.323,0.003
6.92,106.300,0.17127,1.303,0.003
6.84,106.400,0.17139,1.287,0.003
6.75,106.500,0.17152,1.271,0.003
6.64,106.600,0.17168,1.250,0.003
6.55,106.700,0.17181,1.234,0.003
6.51,106.800,0.17193,1.226,0.003
6.48,106.900,0.17206,1.221,0.003
6.46,107.000,0.17222,1.217,0.003
6.45,107.100,0.17235,1.214,0.003
6.43,107.200,0.17247,1.212,0.003
6.43,107.300,0.17264,1.210,0.003
6.42,107.400,0.17276,1.209,0.003
6.41,107.500,0.17293,1.208,0.003
6.43,107.600,0.17305,1.210,0.003
6.40,107.700,0.17322,1.205,0.003
6.40,107.800,0.17339,1.205,0.003
6.40,107.900,0.17355,1.205,0.003
6.40,108.000,0.17368,1.206,0.003
6.40,108.100,0.17384,1.205,0.003
6.41,108.200,0.17401,1.207,0.003
6.39,108.300,0.17417,1.203,0.003
6.41,108.400,0.17434,1.206,0.003
6.38,108.500,0.17447,1.202,0.003
6.39,108.600,0.17463,1.204,0.003
6.39,108.700,0.17480,1.204,0.003
6.38,108.800,0.17496,1.202,0.003
6.38,108.900,0.17513,1.202,0.003
6.39,109.000,0.17530,1.203,0.003
6.40,109.100,0.17546,1.206,0.003
6.40,109.200,0.17567,1.205,0.003
6.41,109.300,0.17584,1.206,0.003
6.42,109.400,0.17604,1.209,0.003
6.41,109.500,0.17625,1.208,0.003
6.43,109.600,0.17642,1.211,0.003
6.43,109.700,0.17663,1.211,0.003
6.43,109.800,0.17683,1.210,0.003
6.44,109.900,0.17704,1.212,0.003
6.45,110.000,0.17725,1.215,0.003
6.45,110.100,0.17750,1.215,0.003
6.46,110.200,0.17771,1.216,0.003
6.46,110.300,0.17791,1.217,0.004
6.47,110.400,0.17812,1.218,0.004
6.47,110.500,0.17833,1.219,0.004
6.47,110.600,0.17854,1.218,0.004
6.47,110.700,0.17875,1.218,0.004
6.49,110.800,0.17895,1.222,0.004
6.47,110.900,0.17912,1.219,0.004
6.47,111.000,0.17933,1.218,0.004
6.46,111.100,0.17949,1.216,0.004
6.47,111.200,0.17966,1.218,0.004
6.46,111.300,0.17983,1.217,0.004
6.44,111.400,0.17999,1.213,0.004
6.45,111.500,0.18016,1.215,0.004
6.43,111.600,0.18028,1.211,0.004
6.43,111.700,0.18045,1.210,0.004
6.44,111.800,0.18057,1.212,0.004
6.44,111.900,0.18074,1.213,0.004
6.43,112.000,0.18087,1.211,0.004
6.43,112.100,0.18099,1.211,0.004
6.43,112.200,0.18116,1.211,0.004
6.41,112.300,0.18128,1.208,0.004
6.42,112.400,0.18141,1.209,0.004
6.42,112.500,0.18157,1.209,0.004
6.43,112.600,0.18170,1.210,0.004
6.42,112.700,0.18182,1.209,0.004
6.43,112.800,0.18199,1.211,0.004
6.43,112.900,0.18211,1.211,0.004
6.43,113.000,0.18228,1.211,0.004
6.44,113.100,0.18244,1.213,0.004
6.44,113.200,0.18257,1.213,0.004
6.46,113.300,0.18274,1.217,0.004
6.45,113.400,0.18290,1.214,0.004
6.47,113.500,0.18303,1.219,0.004
6.47,113.600,0.18319,1.219,0.004
6.47,113.700,0.18336,1.219,0.004
6.46,113.800,0.18352,1.216,0.004
6.49,113.900,0.18369,1.222,0.004
6.48,114.000,0.18382,1.221,0.004
6.48,114.100,0.18398,1.220,0.004
6.49,114.200,0.18415,1.222,0.004
6.50,114.300,0.18431,1.223,0.004
6.50,114.300,0.18431,1.223,0.004