File: data-files/CWRU/1100-05-35C.txt
""
"Test Method","Will_Huddleston_Disks.msm"
"Sample I. D.","100-5-35C.mss"
"Specimen Number","1"

"Load (N)","Time (s)","Extension (mm)","Stress (MPa)","Strain (mm/mm)"

2.16,0.200,-0.06441,0.408,-0.001
2.16,0.300,-0.06441,0.408,-0.001
2.17,0.400,-0.06441,0.409,-0.001
2.17,0.500,-0.06441,0.409,-0.001
2.16,0.600,-0.06437,0.408,-0.001
2.17,0.700,-0.06437,0.410,-0.001
2.15,0.800,-0.06437,0.407,-0.001
2.16,0.900,-0.06433,0.407,-0.001
2.16,1.000,-0.06433,0.408,-0.001
2.16,1.100,-0.06433,0.409,-0.001
2.15,1.200,-0.06429,0.406,-0.001
2.18,1.300,-0.06429,0.412,-0.001
2.20,1.400,-0.06429,0.415,-0.001
2.17,1.500,-0.06425,0.409,-0.001
2.18,1.600,-0.06425,0.411,-0.001
2.19,1.700,-0.06420,0.414,-0.001
2.20,1.800,-0.06416,0.415,-0.001
2.20,1.900,-0.06412,0.416,-0.001
2.25,2.000,-0.06404,0.425,-0.001
2.27,2.100,-0.06391,0.430,-0.001
2.29,2.200,-0.06379,0.433,-0.001
2.30,2.300,-0.06362,0.435,-0.001
2.32,2.400,-0.06346,0.439,-0.001
2.31,2.500,-0.06333,0.437,-0.001
2.31,2.600,-0.06317,0.437,-0.001
2.34,2.700,-0.06304,0.442,-0.001
2.33,2.800,-0.06287,0.440,-0.001
2.32,2.900,-0.06271,0.438,-0.001
2.34,3.000,-0.06258,0.443,-0.001
2.34,3.100,-0.06242,0.442,-0.001
2.33,3.200,-0.06225,0.440,-0.001
2.34,3.300,-0.06208,0.442,-0.001
2.33,3.400,-0.06192,0.441,-0.001
2.34,3.500,-0.06175,0.441,-0.001
2.36,3.600,-0.06154,0.445,-0.001
2.36,3.700,-0.06138,0.445,-0.001
2.36,3.800,-0.06117,0.446,-0.001
2.37,3.900,-0.06100,0.448,-0.001
2.37,4.000,-0.06080,0.448,-0.001
2.38,4.100,-0.06059,0.449,-0.001
2.39,4.200,-0.06038,0.451,-0.001
2.38,4.300,-0.06017,0.450,-0.001
2.38,4.400,-0.05997,0.449,-0.001
2.39,4.500,-0.05976,0.452,-0.001
2.40,4.600,-0.05959,0.453,-0.001
2.41,4.700,-0.05938,0.455,-0.001
2.40,4.800,-0.05918,0.454,-0.001
2.39,4.900,-0.05901,0.452,-0.001
2.40,5.000,-0.05884,0.452,-0.001
2.42,5.100,-0.05864,0.457,-0.001
2.38,5.200,-0.05847,0.450,-0.001
2.39,5.300,-0.05830,0.452,-0.001
2.40,5.400,-0.05814,0.454,-0.001
2.41,5.500,-0.05801,0.455,-0.001
2.40,5.600,-0.05785,0.453,-0.001
2.42,5.700,-0.05768,0.458,-0.001
2.40,5.800,-0.05756,0.453,-0.001
2.40,5.900,-0.05739,0.454,-0.001
2.42,6.000,-0.05726,0.458,-0.001
2.42,6.100,-0.05714,0.456,-0.001
2.42,6.200,-0.05697,0.457,-0.001
2.42,6.300,-0.05685,0.458,-0.001
2.43,6.400,-0.05672,0.459,-0.001
2.43,6.500,-0.05660,0.459,-0.001
2.42,6.600,-0.05643,0.456,-0.001
2.42,6.700,-0.05631,0.458,-0.001
2.42,6.800,-0.05618,0.458,-0.001
2.43,6.900,-0.05602,0.459,-0.001
2.43,7.000,-0.05589,0.459,-0.001
2.43,7.100,-0.05577,0.458,-0.001
2.44,7.200,-0.05560,0.460,-0.001
2.45,7.300,-0.05548,0.463,-0.001
2.45,7.400,-0.05531,0.463,-0.001
2.44,7.500,-0.05519,0.460,-0.001
2.45,7.600,-0.05502,0.462,-0.001
2.45,7.700,-0.05490,0.463,-0.001
2.44,7.800,-0.05473,0.462,-0.001
2.45,7.900,-0.05460,0.462,-0.001
2.45,8.000,-0.05444,0.464,-0.001
2.43,8.100,-0.05427,0.460,-0.001
2.44,8.200,-0.05411,0.462,-0.001
2.46,8.300,-0.05398,0.464,-0.001
2.45,8.400,-0.05382,0.462,-0.001
2.45,8.500,-0.05365,0.462,-0.001
2.47,8.600,-0.05352,0.467,-0.001
2.48,8.700,-0.05332,0.468,-0.001
2.47,8.800,-0.05319,0.466,-0.001
2.49,8.900,-0.05298,0.471,-0.001
2.48,9.000,-0.05282,0.469,-0.001
2.49,9.100,-0.05265,0.471,-0.001
2.49,9.200,-0.05244,0.470,-0.001
2.50,9.300,-0.05228,0.472,-0.001
2.49,9.400,-0.05211,0.470,-0.001
2.49,9.500,-0.05190,0.471,-0.001
2.50,9.600,-0.05170,0.472,-0.001
2.50,9.700,-0.05149,0.472,-0.001
2.50,9.800,-0.05128,0.472,-0.001
2.51,9.900,-0.05107,0.474,-0.001
2.50,10.000,-0.05086,0.473,-0.001
2.50,10.100,-0.05062,0.473,-0.001
2.52,10.200,-0.05041,0.476,-0.001
2.52,10.300,-0.05020,0.476,-0.001
2.51,10.400,-0.04999,0.475,-0.001
2.53,10.500,-0.04978,0.477,-0.001
2.52,10.600,-0.04962,0.476,-0.001
2.53,10.700,-0.04941,0.478,-0.001
2.51,10.800,-0.04924,0.474,-0.001
2.52,10.900,-0.04904,0.476,-0.001
2.52,11.000,-0.04887,0.476,-0.001
2.52,11.100,-0.04870,0.477,-0.001
2.53,11.200,-0.04858,0.478,-0.001
2.53,11.300,-0.04841,0.479,-0.001
2.53,11.400,-0.04829,0.478,-0.001
2.54,11.500,-0.04812,0.479,-0.001
2.54,11.600,-0.04800,0.480,-0.001
2.55,11.700,-0.04783,0.481,-0.001
2.55,11.800,-0.04771,0.483,-0.001
2.55,11.900,-0.04754,0.482,-0.001
2.57,12.000,-0.04742,0.486,-0.001
2.56,12.100,-0.04729,0.484,-0.001
2.56,12.200,-0.04717,0.484,-0.001
2.56,12.300,-0.04704,0.484,-0.001
2.58,12.400,-0.04688,0.487,-0.001
2.59,12.500,-0.04675,0.489,-0.001
2.60,12.600,-0.04663,0.492,-0.001
2.60,12.700,-0.04646,0.492,-0.001
2.60,12.800,-0.04634,0.490,-0.001
2.63,12.900,-0.04617,0.496,-0.001
2.63,13.000,-0.04604,0.496,-0.001
2.64,13.100,-0.04588,0.499,-0.001
2.63,13.200,-0.04575,0.497,-0.001
2.65,13.300,-0.04559,0.500,-0.001
2.66,13.400,-0.04542,0.503,-0.001
2.66,13.500,-0.04530,0.503,-0.001
2.67,13.600,-0.04513,0.504,-0.001
2.68,13.700,-0.04496,0.506,-0.001
2.70,13.800,-0.04484,0.510,-0.001
2.73,13.900,-0.04467,0.515,-0.001
2.72,14.000,-0.04451,0.514,-0.001
2.74,14.100,-0.04434,0.517,-0.001
2.76,14.200,-0.04417,0.520,-0.001
2.76,14.300,-0.04401,0.521,-0.001
2.79,14.400,-0.04384,0.527,-0.001
2.80,14.500,-0.04368,0.529,-0.001
2.82,14.600,-0.04351,0.533,-0.001
2.83,14.700,-0.04334,0.535,-0.001
2.86,14.800,-0.04314,0.539,-0.001
2.86,14.900,-0.04297,0.540,-0.001
2.88,15.000,-0.04276,0.544,-0.001
2.89,15.100,-0.04260,0.547,-0.001
2.91,15.200,-0.04239,0.550,-0.001
2.93,15.300,-0.04218,0.554,-0.001
2.94,15.400,-0.04197,0.554,-0.001
2.96,15.500,-0.04176,0.560,-0.001
2.98,15.600,-0.04156,0.563,-0.001
3.01,15.700,-0.04135,0.568,-0.001
3.01,15.800,-0.04114,0.569,-0.001
3.01,15.900,-0.04093,0.569,-0.001
3.05,16.000,-0.04073,0.575,-0.001
3.07,16.100,-0.04052,0.581,-0.001
3.07,16.200,-0.04031,0.580,-0.001
3.09,16.300,-0.04010,0.584,-0.001
3.10,16.400,-0.03994,0.586,-0.001
3.11,16.500,-0.03973,0.587,-0.001
3.15,16.600,-0.03956,0.595,-0.001
3.15,16.700,-0.03940,0.594,-0.001
3.15,16.800,-0.03923,0.596,-0.001
3.18,16.900,-0.03906,0.601,-0.001
3.18,17.000,-0.03894,0.601,-0.001
3.18,17.100,-0.03877,0.600,-0.001
3.23,17.200,-0.03861,0.609,-0.001
3.23,17.300,-0.03848,0.609,-0.001
3.23,17.400,-0.03831,0.610,-0.001
3.25,17.500,-0.03819,0.614,-0.001
3.27,17.600,-0.03807,0.617,-0.001
3.26,17.700,-0.03790,0.616,-0.001
3.28,17.800,-0.03777,0.619,-0.001
3.30,17.900,-0.03765,0.624,-0.001
3.33,18.000,-0.03748,0.628,-0.001
3.33,18.100,-0.03736,0.629,-0.001
3.34,18.200,-0.03723,0.631,-0.001
3.35,18.300,-0.03707,0.633,-0.001
3.36,18.400,-0.03694,0.635,-0.001
3.38,18.500,-0.03678,0.638,-0.001
3.40,18.600,-0.03665,0.642,-0.001
3.41,18.700,-0.03649,0.643,-0.001
3.40,18.800,-0.03636,0.642,-0.001
3.43,18.900,-0.03620,0.648,-0.001
3.44,19.000,-0.03603,0.650,-0.001
3.47,19.100,-0.03590,0.655,-0.001
3.48,19.200,-0.03574,0.658,-0.001
3.50,19.300,-0.03557,0.662,-0.001
3.50,19.400,-0.03541,0.661,-0.001
3.52,19.500,-0.03528,0.665,-0.001
3.53,19.600,-0.03512,0.667,-0.001
3.55,19.700,-0.03495,0.670,-0.001
3.55,19.800,-0.03478,0.671,-0.001
3.59,19.900,-0.03462,0.678,-0.001
3.60,20.000,-0.03449,0.679,-0.001
3.61,20.100,-0.03433,0.682,-0.001
3.64,20.200,-0.03416,0.688,-0.001
3.64,20.300,-0.03395,0.688,-0.001
3.66,20.400,-0.03379,0.692,-0.001
3.69,20.500,-0.03362,0.697,-0.001
3.72,20.600,-0.03341,0.703,-0.001
3.73,20.700,-0.03325,0.704,-0.001
3.75,20.800,-0.03304,0.708,-0.001
3.78,20.900,-0.03283,0.713,-0.001
3.80,21.000,-0.03262,0.718,-0.001
3.82,21.100,-0.03241,0.721,-0.001
3.86,21.200,-0.03221,0.728,-0.001
3.87,21.300,-0.03200,0.731,-0.001
3.88,21.400,-0.03179,0.733,-0.001
3.92,21.500,-0.03158,0.740,-0.001
3.93,21.600,-0.03138,0.742,-0.001
3.94,21.700,-0.03117,0.745,-0.001
3.97,21.800,-0.03096,0.750,-0.001
3.99,21.900,-0.03075,0.753,-0.001
3.99,22.000,-0.03059,0.754,-0.001
4.03,22.100,-0.03038,0.761,-0.001
4.04,22.200,-0.03021,0.763,-0.001
4.06,22.300,-0.03005,0.767,-0.001
4.07,22.400,-0.02988,0.768,-0.001
4.10,22.500,-0.02971,0.775,-0.001
4.11,22.600,-0.02955,0.777,-0.001
4.11,22.700,-0.02938,0.777,-0.001
4.14,22.800,-0.02926,0.782,-0.001
4.14,22.900,-0.02909,0.782,-0.001
4.16,23.000,-0.02896,0.785,-0.001
4.18,23.100,-0.02880,0.789,-0.001
4.21,23.200,-0.02867,0.794,-0.001
4.20,23.300,-0.02855,0.794,-0.001
4.22,23.400,-0.02838,0.798,-0.001
4.23,23.500,-0.02826,0.800,-0.001
4.23,23.600,-0.02813,0.799,-0.001
4.26,23.700,-0.02797,0.804,-0.001
4.27,23.800,-0.02784,0.807,-0.001
4.29,23.900,-0.02772,0.811,-0.001
4.32,24.000,-0.02755,0.816,-0.001
4.33,24.100,-0.02743,0.818,-0.001
4.34,24.200,-0.02726,0.819,-0.001
4.35,24.300,-0.02714,0.822,-0.001
4.36,24.400,-0.02697,0.824,-0.001
4.39,24.500,-0.02685,0.829,-0.001
4.41,24.600,-0.02668,0.834,-0.001
4.42,24.700,-0.02655,0.835,-0.001
4.44,24.800,-0.02639,0.839,-0.001
4.47,24.900,-0.02622,0.845,-0.001
4.48,25.000,-0.02610,0.846,-0.001
4.48,25.100,-0.02593,0.846,-0.001
4.51,25.200,-0.02577,0.852,-0.001
4.52,25.300,-0.02564,0.854,-0.001
4.54,25.400,-0.02547,0.857,-0.001
4.56,25.500,-0.02531,0.861,0.000
4.59,25.600,-0.02514,0.867,0.000
4.61,25.700,-0.02498,0.870,0.000
4.62,25.800,-0.02481,0.873,0.000
4.63,25.900,-0.02464,0.875,0.000
4.66,26.000,-0.02448,0.881,0.000
4.68,26.100,-0.02431,0.884,0.000
4.73,26.200,-0.02414,0.893,0.000
4.75,26.300,-0.02394,0.896,0.000
4.78,26.400,-0.02373,0.903,0.000
4.80,26.500,-0.02352,0.907,0.000
4.82,26.600,-0.02331,0.910,0.000
4.85,26.700,-0.02311,0.916,0.000
4.90,26.800,-0.02290,0.926,0.000
4.91,26.900,-0.02269,0.928,0.000
4.93,27.000,-0.02248,0.931,0.000
4.95,27.100,-0.02227,0.936,0.000
4.98,27.200,-0.02207,0.941,0.000
5.01,27.300,-0.02186,0.946,0.000
5.04,27.400,-0.02165,0.952,0.000
5.06,27.500,-0.02144,0.955,0.000
5.08,27.600,-0.02128,0.959,0.000
5.10,27.700,-0.02107,0.963,0.000
5.12,27.800,-0.02090,0.967,0.000
5.13,27.900,-0.02074,0.969,0.000
5.14,28.000,-0.02057,0.971,0.000
5.18,28.100,-0.02040,0.978,0.000
5.19,28.200,-0.02024,0.980,0.000
5.20,28.300,-0.02011,0.982,0.000
5.20,28.400,-0.01995,0.982,0.000
5.23,28.500,-0.01982,0.987,0.000
5.24,28.600,-0.01966,0.990,0.000
5.26,28.700,-0.01953,0.993,0.000
5.28,28.800,-0.01941,0.997,0.000
5.31,28.900,-0.01924,1.002,0.000
5.33,29.000,-0.01912,1.007,0.000
5.33,29.100,-0.01899,1.006,0.000
5.35,29.200,-0.01887,1.011,0.000
5.38,29.300,-0.01874,1.016,0.000
5.40,29.400,-0.01858,1.020,0.000
5.44,29.500,-0.01845,1.028,0.000
5.46,29.600,-0.01833,1.031,0.000
5.48,29.700,-0.01816,1.035,0.000
5.50,29.800,-0.01804,1.039,0.000
5.53,29.900,-0.01787,1.044,0.000
5.55,30.000,-0.01774,1.048,0.000
5.58,30.100,-0.01758,1.055,0.000
5.62,30.200,-0.01741,1.062,0.000
5.63,30.300,-0.01729,1.064,0.000
5.67,30.400,-0.01712,1.071,0.000
5.69,30.500,-0.01696,1.075,0.000
5.72,30.600,-0.01683,1.081,0.000
5.75,30.700,-0.01666,1.086,0.000
5.78,30.800,-0.01650,1.092,0.000
5.81,30.900,-0.01637,1.097,0.000
5.84,31.000,-0.01621,1.102,0.000
5.87,31.100,-0.01604,1.109,0.000
5.90,31.200,-0.01587,1.114,0.000
5.93,31.300,-0.01575,1.121,0.000
5.97,31.400,-0.01558,1.127,0.000
6.00,31.500,-0.01542,1.133,0.000
6.03,31.600,-0.01525,1.140,0.000
6.06,31.700,-0.01509,1.145,0.000
6.10,31.800,-0.01488,1.152,0.000
6.14,31.900,-0.01471,1.159,0.000
6.18,32.000,-0.01450,1.167,0.000
6.21,32.100,-0.01430,1.173,0.000
6.26,32.200,-0.01409,1.182,0.000
6.30,32.300,-0.01388,1.191,0.000
6.35,32.400,-0.01367,1.199,0.000
6.38,32.500,-0.01346,1.206,0.000
6.42,32.600,-0.01326,1.213,0.000
6.45,32.700,-0.01305,1.219,0.000
6.50,32.800,-0.01284,1.228,0.000
6.54,32.900,-0.01263,1.235,0.000
6.57,33.000,-0.01243,1.240,0.000
6.60,33.100,-0.01222,1.247,0.000
6.65,33.200,-0.01201,1.255,0.000
6.68,33.300,-0.01184,1.262,0.000
6.72,33.400,-0.01164,1.269,0.000
6.74,33.500,-0.01147,1.273,0.000
6.77,33.600,-0.01130,1.279,0.000
6.80,33.700,-0.01114,1.284,0.000
6.84,33.800,-0.01097,1.293,0.000
6.87,33.900,-0.01080,1.298,0.000
6.89,34.000,-0.01068,1.302,0.000
6.91,34.100,-0.01051,1.305,0.000
6.94,34.200,-0.01035,1.311,0.000
6.98,34.300,-0.01022,1.318,0.000
7.01,34.400,-0.01006,1.324,0.000
7.02,34.500,-0.00993,1.325,0.000
7.06,34.600,-0.00981,1.333,0.000
7.08,34.700,-0.00964,1.338,0.000
7.11,34.800,-0.00952,1.344,0.000
7.13,34.900,-0.00939,1.346,0.000
7.16,35.000,-0.00927,1.352,0.000
7.20,35.100,-0.00910,1.359,0.000
7.21,35.200,-0.00898,1.362,0.000
7.23,35.300,-0.00885,1.365,0.000
7.26,35.400,-0.00869,1.372,0.000
7.30,35.500,-0.00856,1.378,0.000
7.32,35.600,-0.00839,1.383,0.000
7.36,35.700,-0.00827,1.391,0.000
7.40,35.800,-0.00810,1.397,0.000
7.41,35.900,-0.00798,1.400,0.000
7.45,36.000,-0.00781,1.407,0.000
7.48,36.100,-0.00769,1.413,0.000
7.51,36.200,-0.00752,1.418,0.000
7.54,36.300,-0.00736,1.423,0.000
7.57,36.400,-0.00723,1.429,0.000
7.59,36.500,-0.00706,1.434,0.000
7.62,36.600,-0.00690,1.439,0.000
7.65,36.700,-0.00677,1.444,0.000
7.71,36.800,-0.00661,1.455,0.000
7.74,36.900,-0.00644,1.462,0.000
7.79,37.000,-0.00632,1.472,0.000
7.81,37.100,-0.00615,1.475,0.000
7.83,37.200,-0.00598,1.480,0.000
7.87,37.300,-0.00582,1.486,0.000
7.91,37.400,-0.00565,1.495,0.000
7.96,37.500,-0.00549,1.503,0.000
7.98,37.600,-0.00528,1.508,0.000
8.04,37.700,-0.00511,1.518,0.000
8.07,37.800,-0.00490,1.525,0.000
8.12,37.900,-0.00474,1.534,0.000
8.17,38.000,-0.00453,1.542,0.000
8.22,38.100,-0.00432,1.552,0.000
8.27,38.200,-0.00411,1.562,0.000
8.32,38.300,-0.00391,1.572,0.000
8.36,38.400,-0.00370,1.580,0.000
8.40,38.500,-0.00349,1.586,0.000
8.45,38.600,-0.00332,1.595,0.000
8.49,38.700,-0.00312,1.603,0.000
8.53,38.800,-0.00291,1.611,0.000
8.57,38.900,-0.00270,1.618,0.000
8.61,39.000,-0.00249,1.626,0.000
8.65,39.100,-0.00233,1.633,0.000
8.69,39.200,-0.00212,1.641,0.000
8.73,39.300,-0.00195,1.649,0.000
8.76,39.400,-0.00179,1.654,0.000
8.80,39.500,-0.00162,1.662,0.000
8.83,39.600,-0.00145,1.668,0.000
8.87,39.700,-0.00129,1.675,0.000
8.91,39.800,-0.00116,1.682,0.000
8.94,39.900,-0.00100,1.689,0.000
8.97,40.000,-0.00083,1.694,0.000
9.01,40.100,-0.00071,1.702,0.000
9.05,40.200,-0.00054,1.709,0.000
9.07,40.300,-0.00042,1.714,0.000
9.10,40.400,-0.00029,1.718,0.000
9.14,40.500,-0.00013,1.726,0.000
9.16,40.600,0.00000,1.731,0.000
9.18,40.700,0.00012,1.733,0.000
9.22,40.800,0.00025,1.741,0.000
9.26,40.900,0.00042,1.749,0.000
9.30,41.000,0.00054,1.756,0.000
9.33,41.100,0.00066,1.761,0.000
9.35,41.200,0.00083,1.766,0.000
9.39,41.300,0.00096,1.773,0.000
9.43,41.400,0.00108,1.782,0.000
9.45,41.500,0.00125,1.786,0.000
9.49,41.600,0.00137,1.793,0.000
9.53,41.700,0.00154,1.800,0.000
9.57,41.800,0.00166,1.808,0.000
9.61,41.900,0.00183,1.815,0.000
9.64,42.000,0.00195,1.821,0.000
9.68,42.100,0.00212,1.828,0.000
9.72,42.200,0.00229,1.835,0.000
9.75,42.300,0.00241,1.842,0.000
9.78,42.400,0.00258,1.847,0.000
9.81,42.500,0.00274,1.854,0.000
9.86,42.600,0.00287,1.863,0.000
9.90,42.700,0.00303,1.869,0.000
9.92,42.800,0.00320,1.874,0.000
9.96,42.900,0.00332,1.881,0.000
10.00,43.000,0.00349,1.890,0.000
10.04,43.100,0.00366,1.897,0.000
10.08,43.200,0.00382,1.904,0.000
10.12,43.300,0.00399,1.911,0.000
10.17,43.400,0.00420,1.921,0.000
10.22,43.500,0.00440,1.930,0.000
10.28,43.600,0.00457,1.941,0.000
10.32,43.700,0.00478,1.949,0.000
10.38,43.800,0.00499,1.960,0.000
10.43,43.900,0.00519,1.969,0.000
10.50,44.000,0.00540,1.983,0.000
10.54,44.100,0.00561,1.991,0.000
10.60,44.200,0.00582,2.001,0.000
10.66,44.300,0.00607,2.014,0.000
10.71,44.400,0.00627,2.024,0.000
10.76,44.500,0.00648,2.033,0.000
10.82,44.600,0.00669,2.043,0.000
10.88,44.700,0.00690,2.055,0.000
10.91,44.800,0.00706,2.060,0.000
10.97,44.900,0.00727,2.072,0.000
11.01,45.000,0.00744,2.080,0.000
11.05,45.100,0.00765,2.086,0.000
11.10,45.200,0.00781,2.096,0.000
11.14,45.300,0.00798,2.104,0.000
11.17,45.400,0.00810,2.110,0.000
11.21,45.500,0.00827,2.117,0.000
11.24,45.600,0.00839,2.124,0.000
11.28,45.700,0.00856,2.131,0.000
11.31,45.800,0.00868,2.136,0.000
11.35,45.900,0.00885,2.143,0.000
11.39,46.000,0.00898,2.151,0.000
11.43,46.100,0.00910,2.158,0.000
11.45,46.200,0.00927,2.163,0.000
11.49,46.300,0.00939,2.170,0.000
11.52,46.400,0.00952,2.175,0.000
11.56,46.500,0.00968,2.184,0.000
11.60,46.600,0.00981,2.191,0.000
11.63,46.700,0.00993,2.197,0.000
11.67,46.800,0.01010,2.204,0.000
11.70,46.900,0.01022,2.210,0.000
11.75,47.000,0.01035,2.219,0.000
11.79,47.100,0.01051,2.226,0.000
11.82,47.200,0.01068,2.233,0.000
11.87,47.300,0.01080,2.242,0.000
11.90,47.400,0.01093,2.247,0.000
11.94,47.500,0.01109,2.255,0.000
11.98,47.600,0.01126,2.262,0.000
12.02,47.700,0.01143,2.271,0.000
12.06,47.800,0.01155,2.279,0.000
12.11,47.900,0.01172,2.287,0.000
12.14,48.000,0.01188,2.293,0.000
12.19,48.100,0.01205,2.303,0.000
12.23,48.200,0.01218,2.309,0.000
12.28,48.300,0.01234,2.319,0.000
12.31,48.400,0.01251,2.326,0.000
12.37,48.500,0.01267,2.336,0.000
12.40,48.600,0.01284,2.342,0.000
12.46,48.700,0.01301,2.353,0.000
12.49,48.800,0.01317,2.359,0.000
12.54,48.900,0.01334,2.369,0.000
12.59,49.000,0.01355,2.378,0.000
12.66,49.100,0.01371,2.391,0.000
12.71,49.200,0.01392,2.400,0.000
12.77,49.300,0.01413,2.412,0.000
12.82,49.400,0.01434,2.422,0.000
12.89,49.500,0.01454,2.435,0.000
12.95,49.600,0.01475,2.446,0.000
13.02,49.700,0.01496,2.459,0.000
13.08,49.800,0.01521,2.471,0.000
13.16,49.900,0.01542,2.486,0.000
13.20,50.000,0.01562,2.494,0.000
13.27,50.100,0.01583,2.507,0.000
13.33,50.200,0.01604,2.517,0.000
13.40,50.300,0.01629,2.530,0.000
13.46,50.400,0.01650,2.541,0.000
13.51,50.500,0.01671,2.551,0.000
13.56,50.600,0.01687,2.561,0.000
13.61,50.700,0.01704,2.571,0.000
13.65,50.800,0.01725,2.578,0.000
13.69,50.900,0.01741,2.587,0.000
13.74,51.000,0.01754,2.594,0.000
13.78,51.100,0.01770,2.603,0.000
13.82,51.200,0.01787,2.610,0.000
13.85,51.300,0.01803,2.616,0.000
13.90,51.400,0.01816,2.626,0.000
13.94,51.500,0.01833,2.633,0.000
13.98,51.600,0.01845,2.641,0.000
14.00,51.700,0.01862,2.645,0.000
14.05,51.800,0.01874,2.654,0.000
14.09,51.900,0.01887,2.662,0.000
14.12,52.000,0.01899,2.667,0.000
14.15,52.100,0.01916,2.673,0.000
14.19,52.200,0.01928,2.681,0.000
14.24,52.300,0.01945,2.689,0.000
14.26,52.400,0.01957,2.693,0.000
14.30,52.500,0.01970,2.701,0.000
14.35,52.600,0.01986,2.710,0.000
14.39,52.700,0.01999,2.718,0.000
14.43,52.800,0.02015,2.725,0.000
14.48,52.900,0.02028,2.734,0.000
14.50,53.000,0.02045,2.738,0.000
14.56,53.100,0.02061,2.750,0.000
14.61,53.200,0.02078,2.759,0.000
14.64,53.300,0.02090,2.766,0.000
14.68,53.400,0.02107,2.773,0.000
14.74,53.500,0.02123,2.784,0.000
14.78,53.600,0.02140,2.791,0.000
14.82,53.700,0.02153,2.799,0.000
14.87,53.800,0.02169,2.808,0.000
14.92,53.900,0.02186,2.817,0.000
14.99,54.000,0.02202,2.831,0.000
15.01,54.100,0.02219,2.835,0.000
15.07,54.200,0.02236,2.845,0.000
15.12,54.300,0.02252,2.855,0.000
15.18,54.400,0.02269,2.868,0.000
15.23,54.500,0.02286,2.877,0.000
15.28,54.600,0.02302,2.885,0.000
15.33,54.700,0.02323,2.896,0.000
15.40,54.800,0.02344,2.908,0.000
15.46,54.900,0.02360,2.920,0.000
15.53,55.000,0.02381,2.933,0.000
15.59,55.100,0.02402,2.944,0.000
15.65,55.200,0.02423,2.957,0.000
15.70,55.300,0.02443,2.965,0.000
15.77,55.400,0.02464,2.978,0.000
15.84,55.500,0.02485,2.993,0.000
15.89,55.600,0.02510,3.001,0.000
15.97,55.700,0.02527,3.016,0.000
16.02,55.800,0.02547,3.026,0.001
16.07,55.900,0.02568,3.036,0.001
16.13,56.000,0.02589,3.046,0.001
16.18,56.100,0.02606,3.055,0.001
16.24,56.200,0.02622,3.067,0.001
16.28,56.300,0.02643,3.075,0.001
16.34,56.400,0.02660,3.086,0.001
16.38,56.500,0.02676,3.094,0.001
16.42,56.600,0.02693,3.101,0.001
16.47,56.700,0.02709,3.111,0.001
16.52,56.800,0.02722,3.120,0.001
16.55,56.900,0.02738,3.126,0.001
16.59,57.000,0.02755,3.134,0.001
16.64,57.100,0.02768,3.143,0.001
16.68,57.200,0.02784,3.150,0.001
16.73,57.300,0.02797,3.160,0.001
16.76,57.400,0.02809,3.166,0.001
16.80,57.500,0.02826,3.174,0.001
16.83,57.600,0.02838,3.178,0.001
16.88,57.700,0.02851,3.189,0.001
16.92,57.800,0.02867,3.195,0.001
16.97,57.900,0.02880,3.205,0.001
17.01,58.000,0.02892,3.213,0.001
17.05,58.100,0.02905,3.221,0.001
17.09,58.200,0.02921,3.228,0.001
17.14,58.300,0.02934,3.237,0.001
17.18,58.400,0.02950,3.244,0.001
17.23,58.500,0.02963,3.254,0.001
17.28,58.600,0.02980,3.264,0.001
17.33,58.700,0.02992,3.272,0.001
17.38,58.800,0.03009,3.282,0.001
17.43,58.900,0.03021,3.292,0.001
17.47,59.000,0.03038,3.300,0.001
17.53,59.100,0.03054,3.310,0.001
17.58,59.200,0.03067,3.320,0.001
17.63,59.300,0.03083,3.331,0.001
17.69,59.400,0.03100,3.340,0.001
17.74,59.500,0.03117,3.351,0.001
17.78,59.600,0.03129,3.359,0.001
17.83,59.700,0.03146,3.367,0.001
17.88,59.800,0.03162,3.377,0.001
17.93,59.900,0.03179,3.386,0.001
17.99,60.000,0.03196,3.397,0.001
18.03,60.100,0.03212,3.406,0.001
18.09,60.200,0.03229,3.417,0.001
18.14,60.300,0.03245,3.426,0.001
18.21,60.400,0.03266,3.440,0.001
18.26,60.500,0.03283,3.450,0.001
18.33,60.600,0.03304,3.462,0.001
18.40,60.700,0.03324,3.476,0.001
18.49,60.800,0.03345,3.493,0.001
18.56,60.900,0.03370,3.505,0.001
18.64,61.000,0.03391,3.521,0.001
18.71,61.100,0.03412,3.534,0.001
18.77,61.200,0.03432,3.544,0.001
18.83,61.300,0.03457,3.556,0.001
18.92,61.400,0.03478,3.573,0.001
18.97,61.500,0.03499,3.582,0.001
19.03,61.600,0.03520,3.594,0.001
19.08,61.700,0.03536,3.604,0.001
19.15,61.800,0.03557,3.617,0.001
19.19,61.900,0.03574,3.625,0.001
19.26,62.000,0.03595,3.638,0.001
19.31,62.100,0.03611,3.647,0.001
19.36,62.200,0.03628,3.656,0.001
19.42,62.300,0.03644,3.668,0.001
19.45,62.400,0.03661,3.674,0.001
19.49,62.500,0.03673,3.681,0.001
19.54,62.600,0.03690,3.690,0.001
19.57,62.700,0.03703,3.697,0.001
19.63,62.800,0.03719,3.707,0.001
19.67,62.900,0.03732,3.715,0.001
19.72,63.000,0.03744,3.725,0.001
19.75,63.100,0.03761,3.730,0.001
19.79,63.200,0.03773,3.737,0.001
19.84,63.300,0.03786,3.748,0.001
19.86,63.400,0.03798,3.751,0.001
19.92,63.500,0.03815,3.763,0.001
19.96,63.600,0.03827,3.770,0.001
20.01,63.700,0.03840,3.780,0.001
20.07,63.800,0.03852,3.790,0.001
20.11,63.900,0.03869,3.799,0.001
20.16,64.000,0.03881,3.808,0.001
20.21,64.100,0.03898,3.818,0.001
20.27,64.200,0.03910,3.828,0.001
20.32,64.300,0.03927,3.839,0.001
20.38,64.400,0.03939,3.849,0.001
20.40,64.500,0.03956,3.853,0.001
20.48,64.600,0.03973,3.868,0.001
20.52,64.700,0.03985,3.876,0.001
20.59,64.800,0.04002,3.889,0.001
20.64,64.900,0.04018,3.898,0.001
20.68,65.000,0.04031,3.907,0.001
20.75,65.100,0.04047,3.919,0.001
20.80,65.200,0.04064,3.929,0.001
20.86,65.300,0.04081,3.940,0.001
20.91,65.400,0.04093,3.949,0.001
20.95,65.500,0.04110,3.958,0.001
21.01,65.600,0.04126,3.969,0.001
21.07,65.700,0.04143,3.979,0.001
21.13,65.800,0.04160,3.991,0.001
21.19,65.900,0.04176,4.002,0.001
21.28,66.000,0.04197,4.019,0.001
21.32,66.100,0.04214,4.027,0.001
21.39,66.200,0.04234,4.039,0.001
21.45,66.300,0.04255,4.051,0.001
21.54,66.400,0.04276,4.068,0.001
21.62,66.500,0.04297,4.084,0.001
21.70,66.600,0.04318,4.099,0.001
21.75,66.700,0.04338,4.109,0.001
21.84,66.800,0.04359,4.125,0.001
21.91,66.900,0.04380,4.138,0.001
21.98,67.000,0.04401,4.151,0.001
22.04,67.100,0.04422,4.163,0.001
22.13,67.200,0.04442,4.179,0.001
22.19,67.300,0.04463,4.191,0.001
22.25,67.400,0.04484,4.202,0.001
22.31,67.500,0.04500,4.213,0.001
22.37,67.600,0.04521,4.226,0.001
22.43,67.700,0.04538,4.237,0.001
22.50,67.800,0.04554,4.249,0.001
22.54,67.900,0.04571,4.258,0.001
22.59,68.000,0.04588,4.267,0.001
22.66,68.100,0.04604,4.280,0.001
22.71,68.200,0.04621,4.289,0.001
22.74,68.300,0.04633,4.295,0.001
22.79,68.400,0.04650,4.305,0.001
22.83,68.500,0.04663,4.312,0.001
22.90,68.600,0.04679,4.324,0.001
22.96,68.700,0.04692,4.336,0.001
22.99,68.800,0.04704,4.342,0.001
23.04,68.900,0.04717,4.351,0.001
23.07,69.000,0.04733,4.358,0.001
23.12,69.100,0.04746,4.367,0.001
23.16,69.200,0.04758,4.375,0.001
23.20,69.300,0.04775,4.383,0.001
23.26,69.400,0.04787,4.394,0.001
23.31,69.500,0.04800,4.403,0.001
23.36,69.600,0.04816,4.412,0.001
23.40,69.700,0.04829,4.421,0.001
23.46,69.800,0.04841,4.431,0.001
23.51,69.900,0.04858,4.441,0.001
23.56,70.000,0.04874,4.450,0.001
23.61,70.100,0.04887,4.460,0.001
23.68,70.200,0.04904,4.472,0.001
23.74,70.300,0.04920,4.483,0.001
23.78,70.400,0.04933,4.492,0.001
23.84,70.500,0.04949,4.504,0.001
23.89,70.600,0.04966,4.513,0.001
23.95,70.700,0.04983,4.524,0.001
23.99,70.800,0.04995,4.532,0.001
24.06,70.900,0.05012,4.545,0.001
24.11,71.000,0.05028,4.554,0.001
24.17,71.100,0.05045,4.564,0.001
24.21,71.200,0.05061,4.573,0.001
24.29,71.300,0.05078,4.588,0.001
24.34,71.400,0.05091,4.598,0.001
24.40,71.500,0.05107,4.609,0.001
24.47,71.600,0.05128,4.622,0.001
24.54,71.700,0.05145,4.635,0.001
24.62,71.800,0.05165,4.650,0.001
24.68,71.900,0.05182,4.662,0.001
24.76,72.000,0.05203,4.677,0.001
24.85,72.100,0.05224,4.694,0.001
24.93,72.200,0.05244,4.708,0.001
25.01,72.300,0.05265,4.723,0.001
25.10,72.400,0.05286,4.740,0.001
25.15,72.500,0.05307,4.750,0.001
25.23,72.600,0.05327,4.765,0.001
25.31,72.700,0.05348,4.781,0.001
25.38,72.800,0.05369,4.793,0.001
25.44,72.900,0.05390,4.805,0.001
25.54,73.000,0.05411,4.824,0.001
25.62,73.100,0.05431,4.838,0.001
25.68,73.200,0.05448,4.850,0.001
25.75,73.300,0.05469,4.863,0.001
25.81,73.400,0.05485,4.875,0.001
25.86,73.500,0.05502,4.884,0.001
25.93,73.600,0.05519,4.898,0.001
25.99,73.700,0.05535,4.908,0.001
26.05,73.800,0.05552,4.920,0.001
26.08,73.900,0.05568,4.927,0.001
26.15,74.000,0.05581,4.939,0.001
26.20,74.100,0.05598,4.948,0.001
26.24,74.200,0.05610,4.956,0.001
26.29,74.300,0.05627,4.967,0.001
26.35,74.400,0.05639,4.977,0.001
26.38,74.500,0.05652,4.982,0.001
26.44,74.600,0.05668,4.994,0.001
26.47,74.700,0.05681,5.000,0.001
26.53,74.800,0.05693,5.011,0.001
26.58,74.900,0.05706,5.021,0.001
26.64,75.000,0.05722,5.031,0.001
26.69,75.100,0.05735,5.041,0.001
26.74,75.200,0.05747,5.050,0.001
26.80,75.300,0.05764,5.062,0.001
26.84,75.400,0.05776,5.070,0.001
26.90,75.500,0.05793,5.081,0.001
26.96,75.600,0.05805,5.092,0.001
27.02,75.700,0.05818,5.103,0.001
27.06,75.800,0.05834,5.112,0.001
27.12,75.900,0.05851,5.123,0.001
27.18,76.000,0.05863,5.133,0.001
27.23,76.100,0.05880,5.143,0.001
27.29,76.200,0.05897,5.154,0.001
27.36,76.300,0.05909,5.168,0.001
27.40,76.400,0.05926,5.176,0.001
27.47,76.500,0.05942,5.188,0.001
27.54,76.600,0.05955,5.201,0.001
27.60,76.700,0.05972,5.212,0.001
27.64,76.800,0.05988,5.220,0.001
27.71,76.900,0.06005,5.234,0.001
27.76,77.000,0.06017,5.244,0.001
27.85,77.100,0.06034,5.260,0.001
27.91,77.200,0.06050,5.271,0.001
27.99,77.300,0.06071,5.286,0.001
28.05,77.400,0.06088,5.298,0.001
28.12,77.500,0.06105,5.312,0.001
28.23,77.600,0.06125,5.331,0.001
28.30,77.700,0.06146,5.346,0.001
28.39,77.800,0.06167,5.361,0.001
28.46,77.900,0.06188,5.376,0.001
28.57,78.000,0.06208,5.395,0.001
28.66,78.100,0.06229,5.413,0.001
28.76,78.200,0.06250,5.432,0.001
28.84,78.300,0.06271,5.447,0.001
28.93,78.400,0.06296,5.464,0.001
29.00,78.500,0.06312,5.478,0.001
29.09,78.600,0.06333,5.495,0.001
29.16,78.700,0.06354,5.507,0.001
29.24,78.800,0.06375,5.522,0.001
29.31,78.900,0.06391,5.536,0.001
29.37,79.000,0.06412,5.548,0.001
29.45,79.100,0.06429,5.563,0.001
29.51,79.200,0.06445,5.573,0.001
29.58,79.300,0.06462,5.587,0.001
29.62,79.400,0.06474,5.594,0.001
29.65,79.500,0.06491,5.601,0.001
29.72,79.600,0.06508,5.614,0.001
29.79,79.700,0.06520,5.626,0.001
29.83,79.800,0.06537,5.634,0.001
29.87,79.900,0.06549,5.642,0.001
29.93,80.000,0.06562,5.653,0.001
29.98,80.100,0.06578,5.663,0.001
30.02,80.200,0.06591,5.671,0.001
30.08,80.300,0.06603,5.682,0.001
30.12,80.400,0.06616,5.689,0.001
30.16,80.500,0.06632,5.697,0.001
30.23,80.600,0.06645,5.710,0.001
30.28,80.700,0.06657,5.719,0.001
30.32,80.800,0.06670,5.727,0.001
30.39,80.900,0.06686,5.740,0.001
30.45,81.000,0.06699,5.752,0.001
30.52,81.100,0.06715,5.764,0.001
30.56,81.200,0.06728,5.773,0.001
30.62,81.300,0.06740,5.784,0.001
30.68,81.400,0.06757,5.794,0.001
30.73,81.500,0.06774,5.804,0.001
30.81,81.600,0.06786,5.819,0.001
30.86,81.700,0.06803,5.829,0.001
30.92,81.800,0.06815,5.839,0.001
30.98,81.900,0.06832,5.852,0.001
31.05,82.000,0.06848,5.865,0.001
31.11,82.100,0.06865,5.875,0.001
31.17,82.200,0.06877,5.888,0.001
31.24,82.300,0.06894,5.901,0.001
31.30,82.400,0.06911,5.911,0.001
31.37,82.500,0.06927,5.925,0.001
31.44,82.600,0.06944,5.939,0.001
31.52,82.700,0.06961,5.953,0.001
31.57,82.800,0.06977,5.963,0.001
31.65,82.900,0.06994,5.978,0.001
31.73,83.000,0.07010,5.993,0.001
31.82,83.100,0.07027,6.009,0.001
31.90,83.200,0.07048,6.026,0.001
31.99,83.300,0.07069,6.041,0.001
32.07,83.400,0.07085,6.057,0.001
32.16,83.500,0.07106,6.075,0.001
32.25,83.600,0.07127,6.091,0.001
32.35,83.700,0.07152,6.110,0.001
32.45,83.800,0.07172,6.128,0.001
32.54,83.900,0.07193,6.147,0.001
32.64,84.000,0.07214,6.164,0.001
32.72,84.100,0.07239,6.180,0.001
32.81,84.200,0.07260,6.197,0.001
32.89,84.300,0.07281,6.213,0.001
32.98,84.400,0.07297,6.228,0.001
33.05,84.500,0.07318,6.242,0.001
33.13,84.600,0.07339,6.257,0.001
33.20,84.700,0.07355,6.271,0.001
33.27,84.800,0.07376,6.283,0.001
33.32,84.900,0.07393,6.294,0.001
33.39,85.000,0.07409,6.307,0.001
33.44,85.100,0.07426,6.316,0.001
33.50,85.200,0.07438,6.327,0.001
33.55,85.300,0.07455,6.337,0.001
33.63,85.400,0.07472,6.352,0.001
33.68,85.500,0.07484,6.361,0.001
33.73,85.600,0.07501,6.371,0.001
33.79,85.700,0.07513,6.382,0.001
33.85,85.800,0.07530,6.394,0.001
33.89,85.900,0.07542,6.401,0.001
33.95,86.000,0.07555,6.413,0.001
34.01,86.100,0.07567,6.423,0.001
34.05,86.200,0.07584,6.431,0.001
34.10,86.300,0.07596,6.441,0.001
34.15,86.400,0.07609,6.450,0.001
34.21,86.500,0.07625,6.461,0.002
34.27,86.600,0.07638,6.472,0.002
34.35,86.700,0.07655,6.488,0.002
34.41,86.800,0.07667,6.499,0.002
34.46,86.900,0.07684,6.508,0.002
34.53,87.000,0.07696,6.522,0.002
34.61,87.100,0.07713,6.537,0.002
34.67,87.200,0.07729,6.548,0.002
34.73,87.300,0.07746,6.560,0.002
34.82,87.400,0.07758,6.577,0.002
34.88,87.500,0.07775,6.587,0.002
34.95,87.600,0.07792,6.600,0.002
35.01,87.700,0.07804,6.612,0.002
35.07,87.800,0.07821,6.623,0.002
35.14,87.900,0.07837,6.638,0.002
35.22,88.000,0.07854,6.653,0.002
35.30,88.100,0.07871,6.668,0.002
35.37,88.200,0.07883,6.680,0.002
35.43,88.300,0.07900,6.691,0.002
35.51,88.400,0.07916,6.708,0.002
35.60,88.500,0.07933,6.724,0.002
35.67,88.600,0.07954,6.737,0.002
35.75,88.700,0.07970,6.753,0.002
35.83,88.800,0.07991,6.768,0.002
35.91,88.900,0.08008,6.783,0.002
36.00,89.000,0.08029,6.799,0.002
36.09,89.100,0.08045,6.817,0.002
36.19,89.200,0.08066,6.835,0.002
36.27,89.300,0.08087,6.850,0.002
36.37,89.400,0.08112,6.869,0.002
36.47,89.500,0.08132,6.889,0.002
36.56,89.600,0.08153,6.905,0.002
36.65,89.700,0.08174,6.922,0.002
36.74,89.800,0.08195,6.940,0.002
36.82,89.900,0.08216,6.954,0.002
36.91,90.000,0.08236,6.972,0.002
37.00,90.100,0.08253,6.989,0.002
37.10,90.200,0.08274,7.007,0.002
37.15,90.300,0.08290,7.017,0.002
37.24,90.400,0.08307,7.035,0.002
37.30,90.500,0.08328,7.044,0.002
37.36,90.600,0.08344,7.057,0.002
37.44,90.700,0.08361,7.071,0.002
37.50,90.800,0.08378,7.083,0.002
37.54,90.900,0.08390,7.090,0.002
37.62,91.000,0.08407,7.105,0.002
37.69,91.100,0.08423,7.118,0.002
37.75,91.200,0.08436,7.130,0.002
37.82,91.300,0.08452,7.144,0.002
37.86,91.400,0.08465,7.152,0.002
37.94,91.500,0.08482,7.166,0.002
37.97,91.600,0.08494,7.172,0.002
38.03,91.700,0.08506,7.183,0.002
38.10,91.800,0.08523,7.197,0.002
38.16,91.900,0.08536,7.208,0.002
38.23,92.000,0.08548,7.221,0.002
38.29,92.100,0.08560,7.231,0.002
38.34,92.200,0.08577,7.241,0.002
38.41,92.300,0.08590,7.254,0.002
38.47,92.400,0.08602,7.266,0.002
38.54,92.500,0.08619,7.280,0.002
38.62,92.600,0.08631,7.294,0.002
38.69,92.700,0.08648,7.308,0.002
38.75,92.800,0.08664,7.320,0.002
38.82,92.900,0.08677,7.332,0.002
38.89,93.000,0.08693,7.345,0.002
38.96,93.100,0.08710,7.358,0.002
39.03,93.200,0.08723,7.371,0.002
39.12,93.300,0.08739,7.388,0.002
39.18,93.400,0.08756,7.400,0.002
39.27,93.500,0.08772,7.417,0.002
39.31,93.600,0.08785,7.426,0.002
39.40,93.700,0.08801,7.442,0.002
39.46,93.800,0.08818,7.453,0.002
39.54,93.900,0.08835,7.469,0.002
39.61,94.000,0.08851,7.482,0.002
39.70,94.100,0.08868,7.498,0.002
39.77,94.200,0.08885,7.513,0.002
39.87,94.300,0.08901,7.530,0.002
39.95,94.400,0.08918,7.545,0.002
40.05,94.500,0.08939,7.564,0.002
40.12,94.600,0.08959,7.578,0.002
40.23,94.700,0.08976,7.599,0.002
40.33,94.800,0.08997,7.618,0.002
40.43,94.900,0.09018,7.636,0.002
40.52,95.000,0.09043,7.654,0.002
40.65,95.100,0.09063,7.677,0.002
40.76,95.200,0.09084,7.698,0.002
40.86,95.300,0.09109,7.718,0.002
40.96,95.400,0.09130,7.737,0.002
41.05,95.500,0.09151,7.754,0.002
41.14,95.600,0.09171,7.771,0.002
41.25,95.700,0.09192,7.790,0.002
41.33,95.800,0.09213,7.807,0.002
41.42,95.900,0.09234,7.824,0.002
41.50,96.000,0.09250,7.839,0.002
41.57,96.100,0.09267,7.852,0.002
41.65,96.200,0.09288,7.867,0.002
41.72,96.300,0.09300,7.880,0.002
41.79,96.400,0.09317,7.893,0.002
41.86,96.500,0.09333,7.906,0.002
41.93,96.600,0.09350,7.919,0.002
42.00,96.700,0.09362,7.934,0.002
42.05,96.800,0.09379,7.943,0.002
42.11,96.900,0.09392,7.954,0.002
42.18,97.000,0.09408,7.968,0.002
42.23,97.100,0.09421,7.976,0.002
42.28,97.200,0.09433,7.985,0.002
42.35,97.300,0.09446,7.999,0.002
42.43,97.400,0.09462,8.014,0.002
42.47,97.500,0.09475,8.022,0.002
42.52,97.600,0.09487,8.032,0.002
42.59,97.700,0.09504,8.044,0.002
42.65,97.800,0.09516,8.056,0.002
42.70,97.900,0.09533,8.066,0.002
42.77,98.000,0.09545,8.079,0.002
42.85,98.100,0.09562,8.093,0.002
42.93,98.200,0.09574,8.108,0.002
42.98,98.300,0.09591,8.118,0.002
43.06,98.400,0.09604,8.134,0.002
43.12,98.500,0.09620,8.144,0.002
43.14,98.600,0.09637,8.149,0.002
43.12,98.700,0.09649,8.144,0.002
42.94,98.800,0.09666,8.111,0.002
42.68,98.900,0.09682,8.062,0.002
42.41,99.000,0.09695,8.011,0.002
42.06,99.100,0.09712,7.944,0.002
41.62,99.200,0.09728,7.862,0.002
30.28,99.300,0.09745,5.720,0.002
29.97,99.400,0.09757,5.661,0.002
29.48,99.500,0.09774,5.569,0.002
28.94,99.600,0.09791,5.467,0.002
28.27,99.700,0.09807,5.340,0.002
27.36,99.800,0.09824,5.167,0.002
12.84,99.900,0.09840,2.425,0.002
13.91,100.000,0.09857,2.628,0.002
14.08,100.100,0.09874,2.660,0.002
14.21,100.200,0.09894,2.684,0.002
14.32,100.300,0.09911,2.705,0.002
14.44,100.400,0.09932,2.727,0.002
14.54,100.500,0.09953,2.746,0.002
14.64,100.600,0.09973,2.765,0.002
14.73,100.700,0.09994,2.782,0.002
14.82,100.800,0.10019,2.799,0.002
14.93,100.900,0.10040,2.820,0.002
15.00,101.000,0.10061,2.833,0.002
15.09,101.100,0.10081,2.849,0.002
15.13,101.200,0.10102,2.858,0.002
15.20,101.300,0.10123,2.871,0.002
15.26,101.400,0.10144,2.882,0.002
15.32,101.500,0.10165,2.894,0.002
15.36,101.600,0.10181,2.901,0.002
15.41,101.700,0.10202,2.911,0.002
15.46,101.800,0.10219,2.921,0.002
15.50,101.900,0.10235,2.927,0.002
15.53,102.000,0.10252,2.933,0.002
15.56,102.100,0.10268,2.938,0.002
15.58,102.200,0.10285,2.944,0.002
15.61,102.300,0.10297,2.949,0.002
15.65,102.400,0.10314,2.956,0.002
15.68,102.500,0.10327,2.962,0.002
15.70,102.600,0.10343,2.966,0.002
15.74,102.700,0.10356,2.973,0.002
15.79,102.800,0.10368,2.981,0.002
15.80,102.900,0.10385,2.984,0.002
15.83,103.000,0.10397,2.990,0.002
15.87,103.100,0.10410,2.997,0.002
15.87,103.200,0.10422,2.997,0.002
15.90,103.300,0.10439,3.004,0.002
15.94,103.400,0.10451,3.010,0.002
15.98,103.500,0.10464,3.018,0.002
16.00,103.600,0.10480,3.023,0.002
16.05,103.700,0.10493,3.032,0.002
16.07,103.800,0.10509,3.035,0.002
16.07,103.800,0.10509,3.035,0.002